<?xml version='1.0' encoding='UTF-8'?>
<robot name="arm">
  <material name="white">
    <color rgba="1.0 1.0 1.0 1.0" />
  </material>
  <link name="AR5_5_08R_W4C4A6_base">
    <visual>
      <geometry>
        <mesh filename="meshes/AR5_5_08R_W4C4A6_base.STL" scale="0.001 0.001 0.001" />
      </geometry>
      <origin rpy="1.5708 0 0" xyz="0.0 0.0 0.0" />
      <material name="white" />
    </visual>
    <collision>
      <geometry>
        <mesh filename="meshes/AR5_5_08R_W4C4A6_base.STL" scale="0.001 0.001 0.001" />
      </geometry>
      <origin rpy="1.5708 0 0" xyz="0.0 0.0 0.0" />
    </collision>
  </link>
  <link name="AR5_5_08R_W4C4A6_link1">
    <visual>
      <geometry>
        <mesh filename="meshes/AR5_5_08R_W4C4A6_link1.STL" scale="0.001 0.001 0.001" />
      </geometry>
      <origin rpy="0 0 0" xyz="0 0 0" />
      <material name="white" />
    </visual>
    <inertial>
      <mass value="2.166" />
      <inertia ixx="0.00329374" ixy="0.00000029" ixz="0.00000048" iyy="0.00258807" iyz="0.00001496" izz="0.00314817" />
      <origin rpy="0 0 0" xyz="0.000186 -0.001543 0.172784" />
    </inertial>
    <collision>
      <geometry>
        <mesh filename="meshes/AR5_5_08R_W4C4A6_link1.STL" scale="0.001 0.001 0.001" />
      </geometry>
      <origin rpy="0 0 0" xyz="0 0 0" />
    </collision>
  </link>
  <link name="AR5_5_08R_W4C4A6_link2">
    <visual>
      <geometry>
        <mesh filename="meshes/AR5_5_08R_W4C4A6_link2.STL" scale="0.001 0.001 0.001" />
      </geometry>
      <origin rpy="0 0 0" xyz="0 0 0" />
      <material name="white" />
    </visual>
    <inertial>
      <mass value="1.903" />
      <inertia ixx="0.00779827" ixy="0.00000248" ixz="0.00000226" iyy="0.00674843" iyz="0.00049284" izz="0.00305518" />
      <origin rpy="0 0 0" xyz="0.000017 -0.001795 0.106691" />
    </inertial>
    <collision>
      <geometry>
        <mesh filename="meshes/AR5_5_08R_W4C4A6_link2.STL" scale="0.001 0.001 0.001" />
      </geometry>
      <origin rpy="0 0 0" xyz="0 0 0" />
    </collision>
  </link>
  <link name="AR5_5_08R_W4C4A6_link3">
    <visual>
      <geometry>
        <mesh filename="meshes/AR5_5_08R_W4C4A6_link3.STL" scale="0.001 0.001 0.001" />
      </geometry>
      <origin rpy="0 0 0" xyz="0 0 0" />
      <material name="white" />
    </visual>
    <inertial>
      <mass value="1.845" />
      <inertia ixx="0.00635592" ixy="0.00001599" ixz="0.00029945" iyy="0.00581609" iyz="0.00004683" izz="0.00269115" />
      <origin rpy="0 0 0" xyz="0.009022 0.0009 -0.019936" />
    </inertial>
    <collision>
      <geometry>
        <mesh filename="meshes/AR5_5_08R_W4C4A6_link3.STL" scale="0.001 0.001 0.001" />
      </geometry>
      <origin rpy="0 0 0" xyz="0 0 0" />
    </collision>
  </link>
  <link name="AR5_5_08R_W4C4A6_link4">
    <visual>
      <geometry>
        <mesh filename="meshes/AR5_5_08R_W4C4A6_link4.STL" scale="0.001 0.001 0.001" />
      </geometry>
      <origin rpy="0 0 0" xyz="0 0 0" />
      <material name="white" />
    </visual>
    <inertial>
      <mass value="1.037" />
      <inertia ixx="0.00294610" ixy="0.00002481" ixz="-0.00011850" iyy="0.00244455" iyz="-0.00022011" izz="0.00140934" />
      <origin rpy="0 0 0" xyz="-0.009272 0.002169 0.084042" />
    </inertial>
    <collision>
      <geometry>
        <mesh filename="meshes/AR5_5_08R_W4C4A6_link4.STL" scale="0.001 0.001 0.001" />
      </geometry>
      <origin rpy="0 0 0" xyz="0 0 0" />
    </collision>
  </link>
  <link name="AR5_5_08R_W4C4A6_link5">
    <visual>
      <geometry>
        <mesh filename="meshes/AR5_5_08R_W4C4A6_link5.STL" scale="0.001 0.001 0.001" />
      </geometry>
      <origin rpy="0 0 0" xyz="0 0 0" />
      <material name="white" />
    </visual>
    <inertial>
      <mass value="1.279" />
      <inertia ixx="0.00240951" ixy="0.00004151" ixz="-0.00004311" iyy="0.00200115" iyz="-0.00006491" izz="0.00158266" />
      <origin rpy="0 0 0" xyz="-0.000776 -0.000804 -0.086734" />
    </inertial>
    <collision>
      <geometry>
        <mesh filename="meshes/AR5_5_08R_W4C4A6_link5.STL" scale="0.001 0.001 0.001" />
      </geometry>
      <origin rpy="0 0 0" xyz="0 0 0" />
    </collision>
  </link>
  <link name="AR5_5_08R_W4C4A6_link6">
    <visual>
      <geometry>
        <mesh filename="meshes/AR5_5_08R_W4C4A6_link6.STL" scale="0.001 0.001 0.001" />
      </geometry>
      <origin rpy="0 0 0" xyz="0 0 0" />
      <material name="white" />
    </visual>
    <inertial>
      <mass value="0.906" />
      <inertia ixx="0.00061487" ixy="0.00000092" ixz="-0.00000097" iyy="0.00074943" iyz="-0.00000047" izz="0.00076056" />
      <origin rpy="0 0 0" xyz="-0.005059 -0.00025 -0.000055" />
    </inertial>
    <collision>
      <geometry>
        <mesh filename="meshes/AR5_5_08R_W4C4A6_link6.STL" scale="0.001 0.001 0.001" />
      </geometry>
      <origin rpy="0 0 0" xyz="0 0 0" />
    </collision>
  </link>
  <link name="AR5_5_08R_W4C4A6_link7">
    <visual>
      <geometry>
        <mesh filename="meshes/AR5_5_08R_W4C4A6_link7.STL" scale="0.001 0.001 0.001" />
      </geometry>
      <origin rpy="0 0 0" xyz="0 0 0" />
      <material name="white" />
    </visual>
    <inertial>
      <mass value="0.33" />
      <inertia ixx="0.00046020" ixy="-0.00000266" ixz="0.00004064" iyy="0.00068698" iyz="0.00000424" izz="0.00043963" />
      <origin rpy="0 0 0" xyz="-0.00122 0.000673 0.053984" />
    </inertial>
    <collision>
      <geometry>
        <mesh filename="meshes/AR5_5_08R_W4C4A6_link7.STL" scale="0.001 0.001 0.001" />
      </geometry>
      <origin rpy="0 0 0" xyz="0 0 0" />
    </collision>
  </link>
  <link name="AR5_5_08R_W4C4A6_tcp">
    <visual>
      <origin xyz="0 0 0" rpy="0 0 0" />
      <geometry>
        <box size="0.0001 0.0001 0.0001" />
      </geometry>
      <material name="white" />
    </visual>
    <collision>
      <origin xyz="0 0 0" rpy="0 0 0" />
      <geometry>
        <box size="0.0001 0.0001 0.0001" />
      </geometry>
    </collision>
    <inertial>
      <mass value="0.0" />
      <inertia ixx="1e-6" ixy="0" ixz="0" iyy="1e-6" iyz="0" izz="1e-6" />
    </inertial>
  </link>
  <joint name="AR5_5_08R_W4C4A6_joint_1" type="revolute">
    <parent link="AR5_5_08R_W4C4A6_base" />
    <child link="AR5_5_08R_W4C4A6_link1" />
    <limit effort="108" lower="-3.1067" upper="3.1067" velocity="3.0543261909900763" />
    <axis xyz="0 0 1" />
    <origin rpy="1.5708 0 0" xyz="0.0 0.0 0.0" />
  </joint>
  <joint name="AR5_5_08R_W4C4A6_joint_2" type="revolute">
    <parent link="AR5_5_08R_W4C4A6_link1" />
    <child link="AR5_5_08R_W4C4A6_link2" />
    <limit effort="108" lower="-2.0944" upper="2.0944" velocity="3.0543261909900763" />
    <axis xyz="0 1 0" />
    <origin rpy="0 0 0" xyz="0.0 0.0 0.1745" />
  </joint>
  <joint name="AR5_5_08R_W4C4A6_joint_3" type="revolute">
    <parent link="AR5_5_08R_W4C4A6_link2" />
    <child link="AR5_5_08R_W4C4A6_link3" />
    <limit effort="66" lower="-3.1067" upper="3.1067" velocity="4.71238898038469" />
    <axis xyz="0 0 1" />
    <origin rpy="0 0 0" xyz="0.0 0.0 0.332" />
  </joint>
  <joint name="AR5_5_08R_W4C4A6_joint_4" type="revolute">
    <parent link="AR5_5_08R_W4C4A6_link3" />
    <child link="AR5_5_08R_W4C4A6_link4" />
    <limit effort="66" lower="-1.0472" upper="2.5307" velocity="5.235987755982989" />
    <axis xyz="0 1 0" />
    <origin rpy="0 0 0" xyz="0.0105 0.0 0.0" />
  </joint>
  <joint name="AR5_5_08R_W4C4A6_joint_5" type="revolute">
    <parent link="AR5_5_08R_W4C4A6_link4" />
    <child link="AR5_5_08R_W4C4A6_link5" />
    <limit effort="19" lower="-3.1067" upper="3.1067" velocity="4.1887902047863905" />
    <axis xyz="0 0 1" />
    <origin rpy="0 0 0" xyz="-0.0105 0.0 0.278" />
  </joint>
  <joint name="AR5_5_08R_W4C4A6_joint_6" type="revolute">
    <parent link="AR5_5_08R_W4C4A6_link5" />
    <child link="AR5_5_08R_W4C4A6_link6" />
    <limit effort="19" lower="-0.9599" upper="0.9599" velocity="4.1887902047863905" />
    <axis xyz="0 1 0" />
    <origin rpy="0 0 0" xyz="0.0 0.0 0.0" />
  </joint>
  <joint name="AR5_5_08R_W4C4A6_joint_7" type="revolute">
    <parent link="AR5_5_08R_W4C4A6_link6" />
    <child link="AR5_5_08R_W4C4A6_link7" />
    <limit effort="19" lower="-0.9599" upper="0.9599" velocity="4.1887902047863905" />
    <axis xyz="1 0 0" />
    <origin rpy="0 0 0" xyz="0.0 0.0 0.0" />
  </joint>
  <joint name="AR5_5_08R_W4C4A6_tcp_joint" type="fixed">
    <parent link="AR5_5_08R_W4C4A6_link7" />
    <child link="AR5_5_08R_W4C4A6_tcp" />
    <origin rpy="0 0 0" xyz="0.0 0.0 0.09" />
  </joint>
</robot>
