<mujoco model="ar5_08_left">
  <compiler meshdir="meshes" discardvisual="false" autolimits="true" angle="radian" eulerseq="XYZ"/>
  <option/>

  <default>
    <default class="arm_ar5_08_visual">
      <geom type="mesh" contype="0" conaffinity="0" group="1"/>
    </default>
    <default class="arm_ar5_08_collision">
      <geom type="mesh" contype="1" conaffinity="1" group="3"/>
    </default>
  </default>

  <asset>
    <mesh name="ar5_08_base"  file="AR5_5_08L_W4C4A6_base.STL"  scale="0.001 0.001 0.001"/>
    <mesh name="ar5_08_link1" file="AR5_5_08L_W4C4A6_link1.STL" scale="0.001 0.001 0.001"/>
    <mesh name="ar5_08_link2" file="AR5_5_08L_W4C4A6_link2.STL" scale="0.001 0.001 0.001"/>
    <mesh name="ar5_08_link3" file="AR5_5_08L_W4C4A6_link3.STL" scale="0.001 0.001 0.001"/>
    <mesh name="ar5_08_link4" file="AR5_5_08L_W4C4A6_link4.STL" scale="0.001 0.001 0.001"/>
    <mesh name="ar5_08_link5" file="AR5_5_08L_W4C4A6_link5.STL" scale="0.001 0.001 0.001"/>
    <mesh name="ar5_08_link6" file="AR5_5_08L_W4C4A6_link6.STL" scale="0.001 0.001 0.001"/>
    <mesh name="ar5_08_link7" file="AR5_5_08L_W4C4A6_link7.STL" scale="0.001 0.001 0.001"/>
  </asset>

  <worldbody>
    <body name="AR5_5_08L_W4C4A6_base" pos="0 0 0">
      <geom class="arm_ar5_08_visual" mesh="ar5_08_base" euler="-1.5708 0 0"/>
      <geom class="arm_ar5_08_collision" mesh="ar5_08_base" euler="-1.5708 0 0"/>
      <site name="base_mount" pos="0 0 0"/>

      <body name="AR5_5_08L_W4C4A6_link1" pos="0 0 0" euler="-1.5708 0 0">
        <inertial pos="-0.000184 0.001568 0.172804" mass="2.166"
                  fullinertia="0.00332249 0.00260904 0.00317691 0.00000032 -0.00000048 -0.00001486"/>
        <joint name="AR5_5_08L_W4C4A6_joint_1" type="hinge" axis="0 0 1"
               range="-3.1067 3.1067" damping="14.22378" frictionloss="0.0" armature="0.01"/>
        <geom class="arm_ar5_08_visual" mesh="ar5_08_link1"/>
        <geom class="arm_ar5_08_collision" mesh="ar5_08_link1"/>

        <body name="AR5_5_08L_W4C4A6_link2" pos="0 0 0.1745">
          <inertial pos="-0.000017 0.001795 0.106689" mass="1.903"
                    fullinertia="0.00779803 0.00674819 0.00305507 0.00000248 -0.00000226 -0.00049283"/>
          <joint name="AR5_5_08L_W4C4A6_joint_2" type="hinge" axis="0 1 0"
                 range="-2.0944 2.0944" damping="13.710972" frictionloss="0.0" armature="0.01"/>
          <geom class="arm_ar5_08_visual" mesh="ar5_08_link2"/>
          <geom class="arm_ar5_08_collision" mesh="ar5_08_link2"/>

          <body name="AR5_5_08L_W4C4A6_link3" pos="0 0 0.332">
            <inertial pos="0.008227 -0.001273 -0.020611" mass="1.845"
                      fullinertia="0.00641285 0.00591595 0.00276583 0.00000909 0.00034765 -0.00002314"/>
            <joint name="AR5_5_08L_W4C4A6_joint_3" type="hinge" axis="0 0 1"
                   range="-3.1067 3.1067" damping="3.791042" frictionloss="0.0" armature="0.01"/>
            <geom class="arm_ar5_08_visual" mesh="ar5_08_link3"/>
            <geom class="arm_ar5_08_collision" mesh="ar5_08_link3"/>

            <body name="AR5_5_08L_W4C4A6_link4" pos="0.0105 0 0">
              <inertial pos="-0.009242 -0.002172 0.084042" mass="1.037"
                        fullinertia="0.00294639 0.00244447 0.00140961 -0.00002418 -0.00012203 0.00022029"/>
              <joint name="AR5_5_08L_W4C4A6_joint_4" type="hinge" axis="0 1 0"
                     range="-1.0472 2.5307" damping="0.333154" frictionloss="0.0" armature="0.01"/>
              <geom class="arm_ar5_08_visual" mesh="ar5_08_link4"/>
              <geom class="arm_ar5_08_collision" mesh="ar5_08_link4"/>

              <body name="AR5_5_08L_W4C4A6_link5" pos="-0.0105 0 0.278">
                <inertial pos="-0.000756 0.000723 -0.086764" mass="1.279"
                          fullinertia="0.00241349 0.00200246 0.00158693 -0.00003807 -0.00004536 0.00006623"/>
                <joint name="AR5_5_08L_W4C4A6_joint_5" type="hinge" axis="0 0 1"
                       range="-3.1067 3.1067" damping="4.136716" frictionloss="0.0" armature="0.01"/>
                <geom class="arm_ar5_08_visual" mesh="ar5_08_link5"/>
                <geom class="arm_ar5_08_collision" mesh="ar5_08_link5"/>

                <body name="AR5_5_08L_W4C4A6_link6" pos="0 0 0">
                  <inertial pos="-0.005104 0.000251 0.000056" mass="0.906"
                            fullinertia="0.00061429 0.00074781 0.00075897 -0.00000088 0.00000104 -0.00000047"/>
                  <joint name="AR5_5_08L_W4C4A6_joint_6" type="hinge" axis="0 1 0"
                         range="-0.9599 0.9599" damping="4.748679" frictionloss="0.0" armature="0.01"/>
                  <geom class="arm_ar5_08_visual" mesh="ar5_08_link6"/>
                  <geom class="arm_ar5_08_collision" mesh="ar5_08_link6"/>

                  <body name="AR5_5_08L_W4C4A6_link7" pos="0 0 0">
                    <inertial pos="-0.001562 -0.000366 0.05392" mass="0.33"
                              fullinertia="0.00046062 0.00068652 0.00043943 0.00000269 0.00003859 -0.00000095"/>
                    <joint name="AR5_5_08L_W4C4A6_joint_7" type="hinge" axis="1 0 0"
                           range="-0.9599 0.9599" damping="3.667978" frictionloss="0.0" armature="0.01"/>
                    <geom class="arm_ar5_08_visual" mesh="ar5_08_link7"/>
                    <geom class="arm_ar5_08_collision" mesh="ar5_08_link7"/>

                    <body name="AR5_5_08L_W4C4A6_tcp" pos="0 0 0.09">
                      <site name="tool0" pos="0 0 0"/>
                    </body>
                  </body>
                </body>
              </body>
            </body>
          </body>
        </body>
      </body>
    </body>
  </worldbody>

  <actuator>
    <position name="AR5_5_08L_W4C4A6_joint_1_act" joint="AR5_5_08L_W4C4A6_joint_1" kp="1000" kv="4" ctrlrange="-3.1067 3.1067"/>
    <position name="AR5_5_08L_W4C4A6_joint_2_act" joint="AR5_5_08L_W4C4A6_joint_2" kp="1000" kv="4" ctrlrange="-2.0944 2.0944"/>
    <position name="AR5_5_08L_W4C4A6_joint_3_act" joint="AR5_5_08L_W4C4A6_joint_3" kp="1000" kv="4" ctrlrange="-3.1067 3.1067"/>
    <position name="AR5_5_08L_W4C4A6_joint_4_act" joint="AR5_5_08L_W4C4A6_joint_4" kp="1000" kv="4" ctrlrange="-1.0472 2.5307"/>
    <position name="AR5_5_08L_W4C4A6_joint_5_act" joint="AR5_5_08L_W4C4A6_joint_5" kp="1000" kv="4" ctrlrange="-3.1067 3.1067"/>
    <position name="AR5_5_08L_W4C4A6_joint_6_act" joint="AR5_5_08L_W4C4A6_joint_6" kp="1000" kv="4" ctrlrange="-0.9599 0.9599"/>
    <position name="AR5_5_08L_W4C4A6_joint_7_act" joint="AR5_5_08L_W4C4A6_joint_7" kp="1000" kv="4" ctrlrange="-0.9599 0.9599"/>
  </actuator>

  <contact>
    <exclude body1="AR5_5_08L_W4C4A6_base"  body2="AR5_5_08L_W4C4A6_link1"/>
    <exclude body1="AR5_5_08L_W4C4A6_link1" body2="AR5_5_08L_W4C4A6_link2"/>
    <exclude body1="AR5_5_08L_W4C4A6_link2" body2="AR5_5_08L_W4C4A6_link3"/>
    <exclude body1="AR5_5_08L_W4C4A6_link3" body2="AR5_5_08L_W4C4A6_link4"/>
    <exclude body1="AR5_5_08L_W4C4A6_link4" body2="AR5_5_08L_W4C4A6_link5"/>
    <exclude body1="AR5_5_08L_W4C4A6_link5" body2="AR5_5_08L_W4C4A6_link6"/>
    <exclude body1="AR5_5_08L_W4C4A6_link6" body2="AR5_5_08L_W4C4A6_link7"/>
    <exclude body1="AR5_5_08L_W4C4A6_link5" body2="AR5_5_08L_W4C4A6_link7"/>
  </contact>
</mujoco>
