<?xml version='1.0' encoding='UTF-8'?>
<robot name="arm">
  <material name="white">
    <color rgba="1.0 1.0 1.0 1.0" />
  </material>
  <link name="AR5_5_08L_W4C4A6_base">
    <visual>
      <geometry>
        <mesh filename="meshes/AR5_5_08L_W4C4A6_base.STL" scale="0.001 0.001 0.001" />
      </geometry>
      <origin rpy="-1.5708 0 0" xyz="0.0 0.0 0.0" />
      <material name="white" />
    </visual>
    <collision>
      <geometry>
        <mesh filename="meshes/AR5_5_08L_W4C4A6_base.STL" scale="0.001 0.001 0.001" />
      </geometry>
      <origin rpy="-1.5708 0 0" xyz="0.0 0.0 0.0" />
    </collision>
  </link>
  <link name="AR5_5_08L_W4C4A6_link1">
    <visual>
      <geometry>
        <mesh filename="meshes/AR5_5_08L_W4C4A6_link1.STL" scale="0.001 0.001 0.001" />
      </geometry>
      <origin rpy="0 0 0" xyz="0 0 0" />
      <material name="white" />
    </visual>
    <inertial>
      <mass value="2.166" />
      <inertia ixx="0.00332249" ixy="0.00000032" ixz="-0.00000048" iyy="0.00260904" iyz="-0.00001486" izz="0.00317691" />
      <origin rpy="0 0 0" xyz="-0.000184 0.001568 0.172804" />
    </inertial>
    <collision>
      <geometry>
        <mesh filename="meshes/AR5_5_08L_W4C4A6_link1.STL" scale="0.001 0.001 0.001" />
      </geometry>
      <origin rpy="0 0 0" xyz="0 0 0" />
    </collision>
  </link>
  <link name="AR5_5_08L_W4C4A6_link2">
    <visual>
      <geometry>
        <mesh filename="meshes/AR5_5_08L_W4C4A6_link2.STL" scale="0.001 0.001 0.001" />
      </geometry>
      <origin rpy="0 0 0" xyz="0 0 0" />
      <material name="white" />
    </visual>
    <inertial>
      <mass value="1.903" />
      <inertia ixx="0.00779803" ixy="0.00000248" ixz="-0.00000226" iyy="0.00674819" iyz="-0.00049283" izz="0.00305507" />
      <origin rpy="0 0 0" xyz="-0.000017 0.001795 0.106689" />
    </inertial>
    <collision>
      <geometry>
        <mesh filename="meshes/AR5_5_08L_W4C4A6_link2.STL" scale="0.001 0.001 0.001" />
      </geometry>
      <origin rpy="0 0 0" xyz="0 0 0" />
    </collision>
  </link>
  <link name="AR5_5_08L_W4C4A6_link3">
    <visual>
      <geometry>
        <mesh filename="meshes/AR5_5_08L_W4C4A6_link3.STL" scale="0.001 0.001 0.001" />
      </geometry>
      <origin rpy="0 0 0" xyz="0 0 0" />
      <material name="white" />
    </visual>
    <inertial>
      <mass value="1.845" />
      <inertia ixx="0.00641285" ixy="0.00000909" ixz="0.00034765" iyy="0.00591595" iyz="-0.00002314" izz="0.00276583" />
      <origin rpy="0 0 0" xyz="0.008227 -0.001273 -0.020611" />
    </inertial>
    <collision>
      <geometry>
        <mesh filename="meshes/AR5_5_08L_W4C4A6_link3.STL" scale="0.001 0.001 0.001" />
      </geometry>
      <origin rpy="0 0 0" xyz="0 0 0" />
    </collision>
  </link>
  <link name="AR5_5_08L_W4C4A6_link4">
    <visual>
      <geometry>
        <mesh filename="meshes/AR5_5_08L_W4C4A6_link4.STL" scale="0.001 0.001 0.001" />
      </geometry>
      <origin rpy="0 0 0" xyz="0 0 0" />
      <material name="white" />
    </visual>
    <inertial>
      <mass value="1.037" />
      <inertia ixx="0.00294639" ixy="-0.00002418" ixz="-0.00012203" iyy="0.00244447" iyz="0.00022029" izz="0.00140961" />
      <origin rpy="0 0 0" xyz="-0.009242 -0.002172 0.084042" />
    </inertial>
    <collision>
      <geometry>
        <mesh filename="meshes/AR5_5_08L_W4C4A6_link4.STL" scale="0.001 0.001 0.001" />
      </geometry>
      <origin rpy="0 0 0" xyz="0 0 0" />
    </collision>
  </link>
  <link name="AR5_5_08L_W4C4A6_link5">
    <visual>
      <geometry>
        <mesh filename="meshes/AR5_5_08L_W4C4A6_link5.STL" scale="0.001 0.001 0.001" />
      </geometry>
      <origin rpy="0 0 0" xyz="0 0 0" />
      <material name="white" />
    </visual>
    <inertial>
      <mass value="1.279" />
      <inertia ixx="0.00241349" ixy="-0.00003807" ixz="-0.00004536" iyy="0.00200246" iyz="0.00006623" izz="0.00158693" />
      <origin rpy="0 0 0" xyz="-0.000756 0.000723 -0.086764" />
    </inertial>
    <collision>
      <geometry>
        <mesh filename="meshes/AR5_5_08L_W4C4A6_link5.STL" scale="0.001 0.001 0.001" />
      </geometry>
      <origin rpy="0 0 0" xyz="0 0 0" />
    </collision>
  </link>
  <link name="AR5_5_08L_W4C4A6_link6">
    <visual>
      <geometry>
        <mesh filename="meshes/AR5_5_08L_W4C4A6_link6.STL" scale="0.001 0.001 0.001" />
      </geometry>
      <origin rpy="0 0 0" xyz="0 0 0" />
      <material name="white" />
    </visual>
    <inertial>
      <mass value="0.906" />
      <inertia ixx="0.00061429" ixy="-0.00000088" ixz="0.00000104" iyy="0.00074781" iyz="-0.00000047" izz="0.00075897" />
      <origin rpy="0 0 0" xyz="-0.005104 0.000251 0.000056" />
    </inertial>
    <collision>
      <geometry>
        <mesh filename="meshes/AR5_5_08L_W4C4A6_link6.STL" scale="0.001 0.001 0.001" />
      </geometry>
      <origin rpy="0 0 0" xyz="0 0 0" />
    </collision>
  </link>
  <link name="AR5_5_08L_W4C4A6_link7">
    <visual>
      <geometry>
        <mesh filename="meshes/AR5_5_08L_W4C4A6_link7.STL" scale="0.001 0.001 0.001" />
      </geometry>
      <origin rpy="0 0 0" xyz="0 0 0" />
      <material name="white" />
    </visual>
    <inertial>
      <mass value="0.33" />
      <inertia ixx="0.00046062" ixy="0.00000269" ixz="0.00003859" iyy="0.00068652" iyz="-0.00000095" izz="0.00043943" />
      <origin rpy="0 0 0" xyz="-0.001562 -0.000366 0.05392" />
    </inertial>
    <collision>
      <geometry>
        <mesh filename="meshes/AR5_5_08L_W4C4A6_link7.STL" scale="0.001 0.001 0.001" />
      </geometry>
      <origin rpy="0 0 0" xyz="0 0 0" />
    </collision>
  </link>
  <link name="AR5_5_08L_W4C4A6_tcp">
    <visual>
      <origin xyz="0 0 0" rpy="0 0 0" />
      <geometry>
        <box size="0.0001 0.0001 0.0001" />
      </geometry>
      <material name="white" />
    </visual>
    <collision>
      <origin xyz="0 0 0" rpy="0 0 0" />
      <geometry>
        <box size="0.0001 0.0001 0.0001" />
      </geometry>
    </collision>
    <inertial>
      <mass value="0.0" />
      <inertia ixx="1e-6" ixy="0" ixz="0" iyy="1e-6" iyz="0" izz="1e-6" />
    </inertial>
  </link>
  <joint name="AR5_5_08L_W4C4A6_joint_1" type="revolute">
    <parent link="AR5_5_08L_W4C4A6_base" />
    <child link="AR5_5_08L_W4C4A6_link1" />
    <limit effort="108" lower="-3.1067" upper="3.1067" velocity="3.0543261909900763" />
    <axis xyz="0 0 1" />
    <origin rpy="-1.5708 0 0" xyz="0.0 0.0 0.0" />
  </joint>
  <joint name="AR5_5_08L_W4C4A6_joint_2" type="revolute">
    <parent link="AR5_5_08L_W4C4A6_link1" />
    <child link="AR5_5_08L_W4C4A6_link2" />
    <limit effort="108" lower="-2.0944" upper="2.0944" velocity="3.0543261909900763" />
    <axis xyz="0 1 0" />
    <origin rpy="0 0 0" xyz="0.0 0.0 0.1745" />
  </joint>
  <joint name="AR5_5_08L_W4C4A6_joint_3" type="revolute">
    <parent link="AR5_5_08L_W4C4A6_link2" />
    <child link="AR5_5_08L_W4C4A6_link3" />
    <limit effort="66" lower="-3.1067" upper="3.1067" velocity="4.71238898038469" />
    <axis xyz="0 0 1" />
    <origin rpy="0 0 0" xyz="0.0 0.0 0.332" />
  </joint>
  <joint name="AR5_5_08L_W4C4A6_joint_4" type="revolute">
    <parent link="AR5_5_08L_W4C4A6_link3" />
    <child link="AR5_5_08L_W4C4A6_link4" />
    <limit effort="66" lower="-1.0472" upper="2.5307" velocity="5.235987755982989" />
    <axis xyz="0 1 0" />
    <origin rpy="0 0 0" xyz="0.0105 0.0 0.0" />
  </joint>
  <joint name="AR5_5_08L_W4C4A6_joint_5" type="revolute">
    <parent link="AR5_5_08L_W4C4A6_link4" />
    <child link="AR5_5_08L_W4C4A6_link5" />
    <limit effort="19" lower="-3.1067" upper="3.1067" velocity="4.1887902047863905" />
    <axis xyz="0 0 1" />
    <origin rpy="0 0 0" xyz="-0.0105 0.0 0.278" />
  </joint>
  <joint name="AR5_5_08L_W4C4A6_joint_6" type="revolute">
    <parent link="AR5_5_08L_W4C4A6_link5" />
    <child link="AR5_5_08L_W4C4A6_link6" />
    <limit effort="19" lower="-0.9599" upper="0.9599" velocity="4.1887902047863905" />
    <axis xyz="0 1 0" />
    <origin rpy="0 0 0" xyz="0.0 0.0 0.0" />
  </joint>
  <joint name="AR5_5_08L_W4C4A6_joint_7" type="revolute">
    <parent link="AR5_5_08L_W4C4A6_link6" />
    <child link="AR5_5_08L_W4C4A6_link7" />
    <limit effort="19" lower="-0.9599" upper="0.9599" velocity="4.1887902047863905" />
    <axis xyz="1 0 0" />
    <origin rpy="0 0 0" xyz="0.0 0.0 0.0" />
  </joint>
  <joint name="AR5_5_08L_W4C4A6_tcp_joint" type="fixed">
    <parent link="AR5_5_08L_W4C4A6_link7" />
    <child link="AR5_5_08L_W4C4A6_tcp" />
    <origin rpy="0 0 0" xyz="0.0 0.0 0.09" />
  </joint>
</robot>
