<?xml version="1.0" encoding="UTF-8"?>
<!-- Generated by linker_robot_assets.composer (version 0.1.0). Workstation: a7_lite_o6_dc. Recipe sha256: 163e81295e2fa80d7dac34a185e52da52e07342d06257984ebe7380ba956560e. Do not edit by hand; re-run `python -m linker_robot_assets.composer.compose <workstation>`. -->
<robot name="a7_lite_o6_dc">
  <link name="world" />
  <material name="hand_left_silver">
    <color rgba="0.5 0.5 0.52 1.0" />
  </material>
  <material name="hand_left_BlackAccent">
    <color rgba="0.15 0.15 0.15 1.0" />
  </material>
  <material name="hand_right_silver">
    <color rgba="0.5 0.5 0.52 1.0" />
  </material>
  <material name="hand_right_BlackAccent">
    <color rgba="0.15 0.15 0.15 1.0" />
  </material>
  <link name="base_torso_root" />
  <link name="base_base_link">
    <inertial>
      <origin xyz="0.0044493 9.5996e-07 -0.58827" rpy="0 0 0" />
      <mass value="8.6616" />
      <inertia ixx="0.19297" ixy="1.6977E-06" ixz="0.00086704" iyy="0.19297" iyz="4.1272E-08" izz="0.072594" />
    </inertial>
    <visual>
      <origin xyz="0 0 0" rpy="0 0 0" />
      <geometry>
        <mesh filename="../../components/bases/a7_lite_torso/variants/default/meshes/base_link.STL" />
      </geometry>
      <material name="base_a7_lite_torso_gray">
        <color rgba="0.75294 0.75294 0.75294 1" />
      </material>
    </visual>
    <collision>
      <origin xyz="0 0 0" rpy="0 0 0" />
      <geometry>
        <mesh filename="../../components/bases/a7_lite_torso/variants/default/meshes/base_link.STL" />
      </geometry>
    </collision>
  </link>
  <link name="base_arm_left_mount" />
  <link name="base_arm_right_mount" />
  <link name="arm_left_L_arm_root" />
  <link name="arm_left_L1_Link">
    <inertial>
      <origin xyz="0.0045974 0.067978 0.00066635" rpy="0 0 0" />
      <mass value="1.1899" />
      <inertia ixx="0.0016082" ixy="3.5266E-06" ixz="2.0532E-07" iyy="0.00086283" iyz="6.5642E-06" izz="0.00092662" />
    </inertial>
    <visual>
      <origin xyz="0 0 0" rpy="0 0 0" />
      <geometry>
        <mesh filename="../../components/arms/a7_lite/variants/left/meshes/L1_Link.STL" />
      </geometry>
      <material name="">
        <color rgba="0.75294 0.75294 0.75294 1" />
      </material>
    </visual>
    <collision>
      <origin xyz="0 0 0" rpy="0 0 0" />
      <geometry>
        <mesh filename="../../components/arms/a7_lite/variants/left/meshes/L1_Link.STL" />
      </geometry>
    </collision>
  </link>
  <link name="arm_left_L2_Link">
    <inertial>
      <origin xyz="-0.030894 9.2644e-05 -0.099437" rpy="0 0 0" />
      <mass value="1.0659" />
      <inertia ixx="0.001451" ixy="3.1371E-06" ixz="-1.519E-06" iyy="0.0012495" iyz="-1.1542E-05" izz="0.0010752" />
    </inertial>
    <visual>
      <origin xyz="0 0 0" rpy="0 0 0" />
      <geometry>
        <mesh filename="../../components/arms/a7_lite/variants/left/meshes/L2_Link.STL" />
      </geometry>
      <material name="">
        <color rgba="0.75294 0.75294 0.75294 1" />
      </material>
    </visual>
    <collision>
      <origin xyz="0 0 0" rpy="0 0 0" />
      <geometry>
        <mesh filename="../../components/arms/a7_lite/variants/left/meshes/L2_Link.STL" />
      </geometry>
    </collision>
  </link>
  <link name="arm_left_L3_Link">
    <inertial>
      <origin xyz="-5.9577e-05 0.001318 -0.078466" rpy="0 0 0" />
      <mass value="1.2763" />
      <inertia ixx="0.00078242" ixy="-2.9327E-07" ixz="7.1339E-06" iyy="0.0010444" iyz="-2.978E-07" izz="0.00063166" />
    </inertial>
    <visual>
      <origin xyz="0 0 0" rpy="0 0 0" />
      <geometry>
        <mesh filename="../../components/arms/a7_lite/variants/left/meshes/L3_Link.STL" />
      </geometry>
      <material name="">
        <color rgba="0.75294 0.75294 0.75294 1" />
      </material>
    </visual>
    <collision>
      <origin xyz="0 0 0" rpy="0 0 0" />
      <geometry>
        <mesh filename="../../components/arms/a7_lite/variants/left/meshes/L3_Link.STL" />
      </geometry>
    </collision>
  </link>
  <link name="arm_left_L4_Link">
    <inertial>
      <origin xyz="1.6127e-05 -0.027094 -0.086199" rpy="0 0 0" />
      <mass value="0.66812" />
      <inertia ixx="0.00039892" ixy="5.379E-08" ixz="1.7668E-06" iyy="0.00038456" iyz="1.0506E-06" izz="0.00041366" />
    </inertial>
    <visual>
      <origin xyz="0 0 0" rpy="0 0 0" />
      <geometry>
        <mesh filename="../../components/arms/a7_lite/variants/left/meshes/L4_Link.STL" />
      </geometry>
      <material name="">
        <color rgba="0.75294 0.75294 0.75294 1" />
      </material>
    </visual>
    <collision>
      <origin xyz="0 0 0" rpy="0 0 0" />
      <geometry>
        <mesh filename="../../components/arms/a7_lite/variants/left/meshes/L4_Link.STL" />
      </geometry>
    </collision>
  </link>
  <link name="arm_left_L5_Link">
    <inertial>
      <origin xyz="-0.00012977 0.0029474 -0.03886" rpy="0 0 0" />
      <mass value="0.4439" />
      <inertia ixx="0.00015511" ixy="-4.6133E-07" ixz="-2.6472E-06" iyy="0.00022136" iyz="-1.0454E-07" izz="0.00013737" />
    </inertial>
    <visual>
      <origin xyz="0 0 0" rpy="0 0 0" />
      <geometry>
        <mesh filename="../../components/arms/a7_lite/variants/left/meshes/L5_Link.STL" />
      </geometry>
      <material name="">
        <color rgba="0.75294 0.75294 0.75294 1" />
      </material>
    </visual>
    <collision>
      <origin xyz="0 0 0" rpy="0 0 0" />
      <geometry>
        <mesh filename="../../components/arms/a7_lite/variants/left/meshes/L5_Link.STL" />
      </geometry>
    </collision>
  </link>
  <link name="arm_left_L6_Link">
    <inertial>
      <origin xyz="0.0023746 -0.027691 -0.063927" rpy="0 0 0" />
      <mass value="0.5193" />
      <inertia ixx="0.00031746" ixy="-6.3455E-07" ixz="4.1005E-07" iyy="0.00024364" iyz="2.8635E-06" izz="0.00015858" />
    </inertial>
    <visual>
      <origin xyz="0 0 0" rpy="0 0 0" />
      <geometry>
        <mesh filename="../../components/arms/a7_lite/variants/left/meshes/L6_Link.STL" />
      </geometry>
      <material name="">
        <color rgba="0.75294 0.75294 0.75294 1" />
      </material>
    </visual>
    <collision>
      <origin xyz="0 0 0" rpy="0 0 0" />
      <geometry>
        <mesh filename="../../components/arms/a7_lite/variants/left/meshes/L6_Link.STL" />
      </geometry>
    </collision>
  </link>
  <link name="arm_left_L7_Link">
    <inertial>
      <origin xyz="-0.026398 -6.6336e-15 -0.025801" rpy="0 0 0" />
      <mass value="0.10175" />
      <inertia ixx="4.5036E-05" ixy="-4.7046E-12" ixz="2.2349E-07" iyy="3.8663E-05" iyz="-1.9234E-20" izz="3.0632E-05" />
    </inertial>
    <visual>
      <origin xyz="0 0 0" rpy="0 0 0" />
      <geometry>
        <mesh filename="../../components/arms/a7_lite/variants/left/meshes/L7_Link.STL" />
      </geometry>
      <material name="">
        <color rgba="0.75294 0.75294 0.75294 1" />
      </material>
    </visual>
    <collision>
      <origin xyz="0 0 0" rpy="0 0 0" />
      <geometry>
        <mesh filename="../../components/arms/a7_lite/variants/left/meshes/L7_Link.STL" />
      </geometry>
    </collision>
  </link>
  <link name="arm_right_R_arm_root" />
  <link name="arm_right_R1_Link">
    <inertial>
      <origin xyz="0.004598 -0.067915 0.00072736" rpy="0 0 0" />
      <mass value="1.1899" />
      <inertia ixx="0.0016082" ixy="-3.3435E-06" ixz="3.9187E-07" iyy="0.00086157" iyz="-6.5828E-06" izz="0.00092788" />
    </inertial>
    <visual>
      <origin xyz="0 0 0" rpy="0 0 0" />
      <geometry>
        <mesh filename="../../components/arms/a7_lite/variants/right/meshes/R1_Link.STL" />
      </geometry>
      <material name="">
        <color rgba="0.75294 0.75294 0.75294 1" />
      </material>
    </visual>
    <collision>
      <origin xyz="0 0 0" rpy="0 0 0" />
      <geometry>
        <mesh filename="../../components/arms/a7_lite/variants/right/meshes/R1_Link.STL" />
      </geometry>
    </collision>
  </link>
  <link name="arm_right_R2_Link">
    <inertial>
      <origin xyz="-0.031363 2.7784e-05 -0.099445" rpy="0 0 0" />
      <mass value="1.0663" />
      <inertia ixx="0.0014523" ixy="-8.9962E-07" ixz="-1.031E-06" iyy="0.0012484" iyz="1.1436E-05" izz="0.0010754" />
    </inertial>
    <visual>
      <origin xyz="0 0 0" rpy="0 0 0" />
      <geometry>
        <mesh filename="../../components/arms/a7_lite/variants/right/meshes/R2_Link.STL" />
      </geometry>
      <material name="">
        <color rgba="0.75294 0.75294 0.75294 1" />
      </material>
    </visual>
    <collision>
      <origin xyz="0 0 0" rpy="0 0 0" />
      <geometry>
        <mesh filename="../../components/arms/a7_lite/variants/right/meshes/R2_Link.STL" />
      </geometry>
    </collision>
  </link>
  <link name="arm_right_R3_Link">
    <inertial>
      <origin xyz="-2.2895e-05 -0.00123 -0.077166" rpy="0 0 0" />
      <mass value="1.3517" />
      <inertia ixx="0.00080502" ixy="2.8702E-07" ixz="7.1845E-06" iyy="0.0010686" iyz="-7.5659E-07" izz="0.00067469" />
    </inertial>
    <visual>
      <origin xyz="0 0 0" rpy="0 0 0" />
      <geometry>
        <mesh filename="../../components/arms/a7_lite/variants/right/meshes/R3_Link.STL" />
      </geometry>
      <material name="">
        <color rgba="0.75294 0.75294 0.75294 1" />
      </material>
    </visual>
    <collision>
      <origin xyz="0 0 0" rpy="0 0 0" />
      <geometry>
        <mesh filename="../../components/arms/a7_lite/variants/right/meshes/R3_Link.STL" />
      </geometry>
    </collision>
  </link>
  <link name="arm_right_R4_Link">
    <inertial>
      <origin xyz="1.2714e-05 0.024908 -0.082641" rpy="0 0 0" />
      <mass value="0.69691" />
      <inertia ixx="0.00041505" ixy="5.3251E-08" ixz="1.7254E-06" iyy="0.00041627" iyz="3.826E-07" izz="0.00043007" />
    </inertial>
    <visual>
      <origin xyz="0 0 0" rpy="0 0 0" />
      <geometry>
        <mesh filename="../../components/arms/a7_lite/variants/right/meshes/R4_Link.STL" />
      </geometry>
      <material name="">
        <color rgba="0.75294 0.75294 0.75294 1" />
      </material>
    </visual>
    <collision>
      <origin xyz="0 0 0" rpy="0 0 0" />
      <geometry>
        <mesh filename="../../components/arms/a7_lite/variants/right/meshes/R4_Link.STL" />
      </geometry>
    </collision>
  </link>
  <link name="arm_right_R5_Link">
    <inertial>
      <origin xyz="0.00029153 -0.0027009 -0.035875" rpy="0 0 0" />
      <mass value="0.48527" />
      <inertia ixx="0.00016555" ixy="-5.747E-07" ixz="-2.6985E-06" iyy="0.00022756" iyz="-9.211E-07" izz="0.00015289" />
    </inertial>
    <visual>
      <origin xyz="0 0 0" rpy="0 0 0" />
      <geometry>
        <mesh filename="../../components/arms/a7_lite/variants/right/meshes/R5_Link.STL" />
      </geometry>
      <material name="">
        <color rgba="0.75294 0.75294 0.75294 1" />
      </material>
    </visual>
    <collision>
      <origin xyz="0 0 0" rpy="0 0 0" />
      <geometry>
        <mesh filename="../../components/arms/a7_lite/variants/right/meshes/R5_Link.STL" />
      </geometry>
    </collision>
  </link>
  <link name="arm_right_R6_Link">
    <inertial>
      <origin xyz="0.0023746 0.027704 -0.063949" rpy="0 0 0" />
      <mass value="0.5193" />
      <inertia ixx="0.00031746" ixy="6.3467E-07" ixz="4.1001E-07" iyy="0.00024364" iyz="-2.8219E-06" izz="0.00015858" />
    </inertial>
    <visual>
      <origin xyz="0 0 0" rpy="0 0 0" />
      <geometry>
        <mesh filename="../../components/arms/a7_lite/variants/right/meshes/R6_Link.STL" />
      </geometry>
      <material name="">
        <color rgba="0.75294 0.75294 0.75294 1" />
      </material>
    </visual>
    <collision>
      <origin xyz="0 0 0" rpy="0 0 0" />
      <geometry>
        <mesh filename="../../components/arms/a7_lite/variants/right/meshes/R6_Link.STL" />
      </geometry>
    </collision>
  </link>
  <link name="arm_right_R7_Link">
    <inertial>
      <origin xyz="-0.026598 3.7248e-14 -0.025801" rpy="0 0 0" />
      <mass value="0.10175" />
      <inertia ixx="4.5036E-05" ixy="-4.7046E-12" ixz="2.2349E-07" iyy="3.8663E-05" iyz="-1.5968E-20" izz="3.0632E-05" />
    </inertial>
    <visual>
      <origin xyz="0 0 0" rpy="0 0 0" />
      <geometry>
        <mesh filename="../../components/arms/a7_lite/variants/right/meshes/R7_Link.STL" />
      </geometry>
      <material name="">
        <color rgba="0.75294 0.75294 0.75294 1" />
      </material>
    </visual>
    <collision>
      <origin xyz="0 0 0" rpy="0 0 0" />
      <geometry>
        <mesh filename="../../components/arms/a7_lite/variants/right/meshes/R7_Link.STL" />
      </geometry>
    </collision>
  </link>
  <link name="hand_left_lh_hand_base_link">
    <inertial>
      <origin xyz="-0.00157788568 -0.000348767259 0.053845222" rpy="0 0 0" />
      <mass value="0.0672935238166485" />
      <inertia ixx="5.22525212160954E-05" ixy="3.06955729584715E-07" ixz="-3.90341166950521E-07" iyy="3.33522349207724E-05" iyz="-7.76680063574627E-07" izz="2.28469461105385E-05" />
    </inertial>
    <visual>
      <origin xyz="0 0 0" rpy="0 0 0" />
      <geometry>
        <mesh filename="../../components/hands/linkerhand_o6/meshes/visual/lh_hand_base_link_vis.glb" />
      </geometry>
      <material name="hand_left_silver" />
    </visual>
    <collision>
      <origin xyz="0 0 0" rpy="0 0 0" />
      <geometry>
        <mesh filename="../../components/hands/linkerhand_o6/meshes/collision/lh_hand_base_link_col.obj" />
      </geometry>
    </collision>
  </link>
  <link name="hand_left_lh_thumb_metacarpals_base2">
    <inertial>
      <origin xyz="0.00162800681 -0.00276680172 -0.00184234439" rpy="0 0 0" />
      <mass value="0.00138588296544333" />
      <inertia ixx="5.26292160685909E-08" ixy="-3.92888681640568E-09" ixz="-2.43767371295222E-09" iyy="4.82620491570326E-08" iyz="3.71869784206147E-09" izz="2.88550286112821E-08" />
    </inertial>
    <visual>
      <origin xyz="0 0 0" rpy="0 0 0" />
      <geometry>
        <mesh filename="../../components/hands/linkerhand_o6/meshes/visual/lh_thumb_metacarpals_base2_vis.glb" />
      </geometry>
      <material name="hand_left_BlackAccent" />
    </visual>
    <collision>
      <origin xyz="0 0 0" rpy="0 0 0" />
      <geometry>
        <mesh filename="../../components/hands/linkerhand_o6/meshes/collision/lh_thumb_metacarpals_base2_col.obj" />
      </geometry>
    </collision>
  </link>
  <link name="hand_left_lh_thumb_metacarpals">
    <inertial>
      <origin xyz="4.24816205e-05 1.74183908e-05 0.0228341641" rpy="0 0 0" />
      <mass value="0.0123381586619931" />
      <inertia ixx="1.10292537368909E-06" ixy="-5.99642232777877E-10" ixz="-1.14233573940545E-07" iyy="1.76757772551884E-06" iyz="-4.03963570823777E-10" izz="9.36347792411098E-07" />
    </inertial>
    <visual>
      <origin xyz="0 0 0" rpy="0 0 0" />
      <geometry>
        <mesh filename="../../components/hands/linkerhand_o6/meshes/visual/lh_thumb_metacarpals_vis.glb" />
      </geometry>
      <material name="hand_left_silver" />
    </visual>
    <collision>
      <origin xyz="0 0 0" rpy="0 0 0" />
      <geometry>
        <mesh filename="../../components/hands/linkerhand_o6/meshes/collision/lh_thumb_metacarpals_col.obj" />
      </geometry>
    </collision>
  </link>
  <link name="hand_left_lh_thumb_distal">
    <inertial>
      <origin xyz="-0.00413725703 -5.9070452e-08 0.0230114016" rpy="0 0 0" />
      <mass value="0.00763332957284057" />
      <inertia ixx="1.3057487813702E-06" ixy="-1.19781508112714E-11" ixz="-7.19551697268541E-08" iyy="1.2248908905341E-06" iyz="4.55347974652679E-12" izz="2.77271910592615E-07" />
    </inertial>
    <visual>
      <origin xyz="0 0 0" rpy="0 0 0" />
      <geometry>
        <mesh filename="../../components/hands/linkerhand_o6/meshes/visual/lh_thumb_distal_vis.glb" />
      </geometry>
      <material name="hand_left_silver" />
    </visual>
    <collision>
      <origin xyz="0 0 0" rpy="0 0 0" />
      <geometry>
        <mesh filename="../../components/hands/linkerhand_o6/meshes/collision/lh_thumb_distal_col.obj" />
      </geometry>
    </collision>
  </link>
  <link name="hand_left_lh_index_proximal">
    <inertial>
      <origin xyz="-0.00208656556 2.53838713e-06 0.0172734942" rpy="0 0 0" />
      <mass value="0.00253174651934627" />
      <inertia ixx="2.65988714157799E-07" ixy="-1.67174578825824E-11" ixz="-4.31047725546034E-08" iyy="2.72914069166233E-07" iyz="1.8756709532167E-10" izz="8.56017305636748E-08" />
    </inertial>
    <visual>
      <origin xyz="0 0 0" rpy="0 0 0" />
      <geometry>
        <mesh filename="../../components/hands/linkerhand_o6/meshes/visual/lh_index_proximal_vis.glb" />
      </geometry>
      <material name="hand_left_silver" />
    </visual>
    <collision>
      <origin xyz="0 0 0" rpy="0 0 0" />
      <geometry>
        <mesh filename="../../components/hands/linkerhand_o6/meshes/collision/lh_index_proximal_col.obj" />
      </geometry>
    </collision>
  </link>
  <link name="hand_left_lh_index_distal">
    <inertial>
      <origin xyz="0.00658986616 5.13855642e-06 0.01943936" rpy="0 0 0" />
      <mass value="0.00376951085886838" />
      <inertia ixx="3.22347106085043E-07" ixy="1.3801788663582E-11" ixz="1.14352857317951E-07" iyy="3.65328133721509E-07" iyz="-2.11505011705634E-10" izz="1.24287996386442E-07" />
    </inertial>
    <visual>
      <origin xyz="0 0 0" rpy="0 0 0" />
      <geometry>
        <mesh filename="../../components/hands/linkerhand_o6/meshes/visual/lh_index_distal_vis.glb" />
      </geometry>
      <material name="hand_left_silver" />
    </visual>
    <collision>
      <origin xyz="0 0 0" rpy="0 0 0" />
      <geometry>
        <mesh filename="../../components/hands/linkerhand_o6/meshes/collision/lh_index_distal_col.obj" />
      </geometry>
    </collision>
  </link>
  <link name="hand_left_lh_middle_proximal">
    <inertial>
      <origin xyz="-0.00208660654 2.5691818e-06 0.0172735012" rpy="0 0 0" />
      <mass value="0.00253177375206983" />
      <inertia ixx="2.65989021304483E-07" ixy="-1.69816046635662E-11" ixz="-4.31046683215273E-08" iyy="2.72914402745606E-07" iyz="1.87484652324395E-10" izz="8.5602213431865E-08" />
    </inertial>
    <visual>
      <origin xyz="0 0 0" rpy="0 0 0" />
      <geometry>
        <mesh filename="../../components/hands/linkerhand_o6/meshes/visual/lh_middle_proximal_vis.glb" />
      </geometry>
      <material name="hand_left_silver" />
    </visual>
    <collision>
      <origin xyz="0 0 0" rpy="0 0 0" />
      <geometry>
        <mesh filename="../../components/hands/linkerhand_o6/meshes/collision/lh_middle_proximal_col.obj" />
      </geometry>
    </collision>
  </link>
  <link name="hand_left_lh_middle_distal">
    <inertial>
      <origin xyz="0.00658986516 5.10862924e-06 0.0194393316" rpy="0 0 0" />
      <mass value="0.00376952789210256" />
      <inertia ixx="3.22348591068053E-07" ixy="1.37122394856588E-11" ixz="1.1435291391668E-07" iyy="3.65329535087755E-07" iyz="-2.10453810291991E-10" izz="1.24288425862546E-07" />
    </inertial>
    <visual>
      <origin xyz="0 0 0" rpy="0 0 0" />
      <geometry>
        <mesh filename="../../components/hands/linkerhand_o6/meshes/visual/lh_middle_distal_vis.glb" />
      </geometry>
      <material name="hand_left_silver" />
    </visual>
    <collision>
      <origin xyz="0 0 0" rpy="0 0 0" />
      <geometry>
        <mesh filename="../../components/hands/linkerhand_o6/meshes/collision/lh_middle_distal_col.obj" />
      </geometry>
    </collision>
  </link>
  <link name="hand_left_lh_ring_proximal">
    <inertial>
      <origin xyz="-0.00208667931 2.63000419e-06 0.0172734926" rpy="0 0 0" />
      <mass value="0.00253182223645066" />
      <inertia ixx="2.65989756076584E-07" ixy="-1.74912952703656E-11" ixz="-4.31043325594253E-08" iyy="2.7291510093393E-07" iyz="1.87158326740895E-10" izz="8.56031522765909E-08" />
    </inertial>
    <visual>
      <origin xyz="0 0 0" rpy="0 0 0" />
      <geometry>
        <mesh filename="../../components/hands/linkerhand_o6/meshes/visual/lh_ring_proximal_vis.glb" />
      </geometry>
      <material name="hand_left_silver" />
    </visual>
    <collision>
      <origin xyz="0 0 0" rpy="0 0 0" />
      <geometry>
        <mesh filename="../../components/hands/linkerhand_o6/meshes/collision/lh_ring_proximal_col.obj" />
      </geometry>
    </collision>
  </link>
  <link name="hand_left_lh_ring_distal">
    <inertial>
      <origin xyz="0.00658986649 5.05883528e-06 0.0194393972" rpy="0 0 0" />
      <mass value="0.00376949588316609" />
      <inertia ixx="3.2234524157181E-07" ixy="1.35766976056011E-11" ixz="1.14353011012842E-07" iyy="3.65326570102147E-07" iyz="-2.08672149138738E-10" izz="1.24287770218135E-07" />
    </inertial>
    <visual>
      <origin xyz="0 0 0" rpy="0 0 0" />
      <geometry>
        <mesh filename="../../components/hands/linkerhand_o6/meshes/visual/lh_ring_distal_vis.glb" />
      </geometry>
      <material name="hand_left_silver" />
    </visual>
    <collision>
      <origin xyz="0 0 0" rpy="0 0 0" />
      <geometry>
        <mesh filename="../../components/hands/linkerhand_o6/meshes/collision/lh_ring_distal_col.obj" />
      </geometry>
    </collision>
  </link>
  <link name="hand_left_lh_pinky_proximal">
    <inertial>
      <origin xyz="-0.002086736 2.68062251e-06 0.0172734848" rpy="0 0 0" />
      <mass value="0.00253185993162408" />
      <inertia ixx="2.6599033687183E-07" ixy="-1.79030790016555E-11" ixz="-4.31040829565781E-08" iyy="2.72915617381577E-07" iyz="1.86906787420486E-10" izz="8.56039175034871E-08" />
    </inertial>
    <visual>
      <origin xyz="0 0 0" rpy="0 0 0" />
      <geometry>
        <mesh filename="../../components/hands/linkerhand_o6/meshes/visual/lh_pinky_proximal_vis.glb" />
      </geometry>
      <material name="hand_left_silver" />
    </visual>
    <collision>
      <origin xyz="0 0 0" rpy="0 0 0" />
      <geometry>
        <mesh filename="../../components/hands/linkerhand_o6/meshes/collision/lh_pinky_proximal_col.obj" />
      </geometry>
    </collision>
  </link>
  <link name="hand_left_lh_pinky_distal">
    <inertial>
      <origin xyz="0.00658987589 5.03087534e-06 0.0194394491" rpy="0 0 0" />
      <mass value="0.00376948071276134" />
      <inertia ixx="3.22343583730488E-07" ixy="1.35768173270357E-11" ixz="1.14353289593012E-07" iyy="3.65325180884183E-07" iyz="-2.0744198062439E-10" izz="1.24287567374229E-07" />
    </inertial>
    <visual>
      <origin xyz="0 0 0" rpy="0 0 0" />
      <geometry>
        <mesh filename="../../components/hands/linkerhand_o6/meshes/visual/lh_pinky_distal_vis.glb" />
      </geometry>
      <material name="hand_left_silver" />
    </visual>
    <collision>
      <origin xyz="0 0 0" rpy="0 0 0" />
      <geometry>
        <mesh filename="../../components/hands/linkerhand_o6/meshes/collision/lh_pinky_distal_col.obj" />
      </geometry>
    </collision>
  </link>
  <link name="hand_right_rh_hand_base_link">
    <inertial>
      <origin xyz="-0.00160320773 0.000358462699 0.0538002704" rpy="0 0 0" />
      <mass value="0.06740077960995" />
      <inertia ixx="5.22359941041901E-05" ixy="3.0391535852764E-07" ixz="3.88322215371643E-07" iyy="3.33473043513648E-05" iyz="-7.77555280794861E-07" izz="2.28342677422006E-05" />
    </inertial>
    <visual>
      <origin xyz="0 0 0" rpy="0 0 0" />
      <geometry>
        <mesh filename="../../components/hands/linkerhand_o6/meshes/visual/rh_hand_base_link_vis.glb" />
      </geometry>
      <material name="hand_right_silver" />
    </visual>
    <collision>
      <origin xyz="0 0 0" rpy="0 0 0" />
      <geometry>
        <mesh filename="../../components/hands/linkerhand_o6/meshes/collision/rh_hand_base_link_col.obj" />
      </geometry>
    </collision>
  </link>
  <link name="hand_right_rh_thumb_metacarpals_base2">
    <inertial>
      <origin xyz="0.00162795738 0.00276671978 -0.00184227726" rpy="0 0 0" />
      <mass value="0.00138591070212997" />
      <inertia ixx="5.26294625624223E-08" ixy="-3.9288013799604E-09" ixz="2.43766268199571E-09" iyy="4.82623724532942E-08" iyz="3.71867754115443E-09" izz="2.88555522060562E-08" />
    </inertial>
    <visual>
      <origin xyz="0 0 0" rpy="0 0 0" />
      <geometry>
        <mesh filename="../../components/hands/linkerhand_o6/meshes/visual/rh_thumb_metacarpals_base2_vis.glb" />
      </geometry>
      <material name="hand_right_BlackAccent" />
    </visual>
    <collision>
      <origin xyz="0 0 0" rpy="0 0 0" />
      <geometry>
        <mesh filename="../../components/hands/linkerhand_o6/meshes/collision/rh_thumb_metacarpals_base2_col.obj" />
      </geometry>
    </collision>
  </link>
  <link name="hand_right_rh_thumb_metacarpals">
    <inertial>
      <origin xyz="4.24920613e-05 -1.67885667e-05 0.0228341523" rpy="0 0 0" />
      <mass value="0.0123381607727595" />
      <inertia ixx="1.10292488693766E-06" ixy="-6.14241939151719E-10" ixz="1.14233108676795E-07" iyy="1.76757658485787E-06" iyz="-4.24576599367025E-10" izz="9.36348143657406E-07" />
    </inertial>
    <visual>
      <origin xyz="0 0 0" rpy="0 0 0" />
      <geometry>
        <mesh filename="../../components/hands/linkerhand_o6/meshes/visual/rh_thumb_metacarpals_vis.glb" />
      </geometry>
      <material name="hand_right_silver" />
    </visual>
    <collision>
      <origin xyz="0 0 0" rpy="0 0 0" />
      <geometry>
        <mesh filename="../../components/hands/linkerhand_o6/meshes/collision/rh_thumb_metacarpals_col.obj" />
      </geometry>
    </collision>
  </link>
  <link name="hand_right_rh_thumb_distal">
    <inertial>
      <origin xyz="-0.00413690727 -4.54842793e-07 0.0230097179" rpy="0 0 0" />
      <mass value="0.00763302603723749" />
      <inertia ixx="1.30546842791578E-06" ixy="-2.61617511029467E-12" ixz="7.19030685242407E-08" iyy="1.22457212713176E-06" iyz="1.66931068485225E-11" izz="2.7729897944409E-07" />
    </inertial>
    <visual>
      <origin xyz="0 0 0" rpy="0 0 0" />
      <geometry>
        <mesh filename="../../components/hands/linkerhand_o6/meshes/visual/rh_thumb_distal_vis.glb" />
      </geometry>
      <material name="hand_right_silver" />
    </visual>
    <collision>
      <origin xyz="0 0 0" rpy="0 0 0" />
      <geometry>
        <mesh filename="../../components/hands/linkerhand_o6/meshes/collision/rh_thumb_distal_col.obj" />
      </geometry>
    </collision>
  </link>
  <link name="hand_right_rh_index_proximal">
    <inertial>
      <origin xyz="-0.00208665596 -4.89649906e-06 0.0172736719" rpy="0 0 0" />
      <mass value="0.00253178529301663" />
      <inertia ixx="2.65990159539482E-07" ixy="-3.55165625722842E-11" ixz="4.31046335852167E-08" iyy="2.72915460277804E-07" iyz="1.75935978708959E-10" izz="8.56026306687528E-08" />
    </inertial>
    <visual>
      <origin xyz="0 0 0" rpy="0 0 0" />
      <geometry>
        <mesh filename="../../components/hands/linkerhand_o6/meshes/visual/rh_index_proximal_vis.glb" />
      </geometry>
      <material name="hand_right_silver" />
    </visual>
    <collision>
      <origin xyz="0 0 0" rpy="0 0 0" />
      <geometry>
        <mesh filename="../../components/hands/linkerhand_o6/meshes/collision/rh_index_proximal_col.obj" />
      </geometry>
    </collision>
  </link>
  <link name="hand_right_rh_index_distal">
    <inertial>
      <origin xyz="0.00658940012 -4.59976557e-06 0.0194434136" rpy="0 0 0" />
      <mass value="0.00376787129082313" />
      <inertia ixx="3.22116619426455E-07" ixy="1.03152735699049E-11" ixz="-1.14363506430985E-07" iyy="3.65131844686317E-07" iyz="-1.97263639269362E-10" izz="1.24256890612907E-07" />
    </inertial>
    <visual>
      <origin xyz="0 0 0" rpy="0 0 0" />
      <geometry>
        <mesh filename="../../components/hands/linkerhand_o6/meshes/visual/rh_index_distal_vis.glb" />
      </geometry>
      <material name="hand_right_silver" />
    </visual>
    <collision>
      <origin xyz="0 0 0" rpy="0 0 0" />
      <geometry>
        <mesh filename="../../components/hands/linkerhand_o6/meshes/collision/rh_index_distal_col.obj" />
      </geometry>
    </collision>
  </link>
  <link name="hand_right_rh_middle_proximal">
    <inertial>
      <origin xyz="-0.00208661082 -4.93451838e-06 0.0172736805" rpy="0 0 0" />
      <mass value="0.00253175497594429" />
      <inertia ixx="2.65989683690695E-07" ixy="-3.58343951791586E-11" ixz="4.31048601085216E-08" iyy="2.72915006047006E-07" iyz="1.75718024412593E-10" izz="8.56020467202518E-08" />
    </inertial>
    <visual>
      <origin xyz="0 0 0" rpy="0 0 0" />
      <geometry>
        <mesh filename="../../components/hands/linkerhand_o6/meshes/visual/rh_middle_proximal_vis.glb" />
      </geometry>
      <material name="hand_right_silver" />
    </visual>
    <collision>
      <origin xyz="0 0 0" rpy="0 0 0" />
      <geometry>
        <mesh filename="../../components/hands/linkerhand_o6/meshes/collision/rh_middle_proximal_col.obj" />
      </geometry>
    </collision>
  </link>
  <link name="hand_right_rh_middle_distal">
    <inertial>
      <origin xyz="0.00658940305 -4.58857436e-06 0.0194434523" rpy="0 0 0" />
      <mass value="0.00376786259758948" />
      <inertia ixx="3.221153658306E-07" ixy="1.02639617308432E-11" ixz="-1.14363547272711E-07" iyy="3.65130723083104E-07" iyz="-1.96904618797577E-10" izz="1.24256787913797E-07" />
    </inertial>
    <visual>
      <origin xyz="0 0 0" rpy="0 0 0" />
      <geometry>
        <mesh filename="../../components/hands/linkerhand_o6/meshes/visual/rh_middle_distal_vis.glb" />
      </geometry>
      <material name="hand_right_silver" />
    </visual>
    <collision>
      <origin xyz="0 0 0" rpy="0 0 0" />
      <geometry>
        <mesh filename="../../components/hands/linkerhand_o6/meshes/collision/rh_middle_distal_col.obj" />
      </geometry>
    </collision>
  </link>
  <link name="hand_right_rh_ring_proximal">
    <inertial>
      <origin xyz="-0.00208654311 -4.98538564e-06 0.0172736743" rpy="0 0 0" />
      <mass value="0.00253170963529411" />
      <inertia ixx="2.6598913795678E-07" ixy="-3.62757108675266E-11" ixz="4.31050611555507E-08" iyy="2.72914417061517E-07" iyz="1.75554984053478E-10" izz="8.56012458677515E-08" />
    </inertial>
    <visual>
      <origin xyz="0 0 0" rpy="0 0 0" />
      <geometry>
        <mesh filename="../../components/hands/linkerhand_o6/meshes/visual/rh_ring_proximal_vis.glb" />
      </geometry>
      <material name="hand_right_silver" />
    </visual>
    <collision>
      <origin xyz="0 0 0" rpy="0 0 0" />
      <geometry>
        <mesh filename="../../components/hands/linkerhand_o6/meshes/collision/rh_ring_proximal_col.obj" />
      </geometry>
    </collision>
  </link>
  <link name="hand_right_rh_ring_distal">
    <inertial>
      <origin xyz="0.00658940273 -4.56628864e-06 0.0194435006" rpy="0 0 0" />
      <mass value="0.0037678395356105" />
      <inertia ixx="3.22112632437858E-07" ixy="1.01848408913558E-11" ixz="-1.1436348915342E-07" iyy="3.65128262095686E-07" iyz="-1.96145632992445E-10" izz="1.24256284608064E-07" />
    </inertial>
    <visual>
      <origin xyz="0 0 0" rpy="0 0 0" />
      <geometry>
        <mesh filename="../../components/hands/linkerhand_o6/meshes/visual/rh_ring_distal_vis.glb" />
      </geometry>
      <material name="hand_right_silver" />
    </visual>
    <collision>
      <origin xyz="0 0 0" rpy="0 0 0" />
      <geometry>
        <mesh filename="../../components/hands/linkerhand_o6/meshes/collision/rh_ring_distal_col.obj" />
      </geometry>
    </collision>
  </link>
  <link name="hand_right_rh_pinky_proximal">
    <inertial>
      <origin xyz="-0.00208649034 -5.02314583e-06 0.0172736681" rpy="0 0 0" />
      <mass value="0.00253167400540778" />
      <inertia ixx="2.65988718820404E-07" ixy="-3.66012295280295E-11" ixz="4.31052220484445E-08" iyy="2.72913936904813E-07" iyz="1.75447396222308E-10" izz="8.56006424720129E-08" />
    </inertial>
    <visual>
      <origin xyz="0 0 0" rpy="0 0 0" />
      <geometry>
        <mesh filename="../../components/hands/linkerhand_o6/meshes/visual/rh_pinky_proximal_vis.glb" />
      </geometry>
      <material name="hand_right_silver" />
    </visual>
    <collision>
      <origin xyz="0 0 0" rpy="0 0 0" />
      <geometry>
        <mesh filename="../../components/hands/linkerhand_o6/meshes/collision/rh_pinky_proximal_col.obj" />
      </geometry>
    </collision>
  </link>
  <link name="hand_right_rh_pinky_distal">
    <inertial>
      <origin xyz="0.00658940432 -4.55268314e-06 0.0194435341" rpy="0 0 0" />
      <mass value="0.00376782669873412" />
      <inertia ixx="3.22111112339498E-07" ixy="1.01707985908333E-11" ixz="-1.14363524419061E-07" iyy="3.65126916899176E-07" iyz="-1.95589215866356E-10" izz="1.24256004854426E-07" />
    </inertial>
    <visual>
      <origin xyz="0 0 0" rpy="0 0 0" />
      <geometry>
        <mesh filename="../../components/hands/linkerhand_o6/meshes/visual/rh_pinky_distal_vis.glb" />
      </geometry>
      <material name="hand_right_silver" />
    </visual>
    <collision>
      <origin xyz="0 0 0" rpy="0 0 0" />
      <geometry>
        <mesh filename="../../components/hands/linkerhand_o6/meshes/collision/rh_pinky_distal_col.obj" />
      </geometry>
    </collision>
  </link>
  <joint name="base_torso_stand" type="fixed">
    <origin xyz="0 0 1.2" rpy="0 0 0" />
    <parent link="base_torso_root" />
    <child link="base_base_link" />
  </joint>
  <joint name="base_weld_arm_left_mount" type="fixed">
    <origin xyz="0.0062932 0.1505 -0.022706" rpy="0 0 0" />
    <parent link="base_base_link" />
    <child link="base_arm_left_mount" />
  </joint>
  <joint name="base_weld_arm_right_mount" type="fixed">
    <origin xyz="0.0062926 -0.1505 -0.022706" rpy="0 0 0" />
    <parent link="base_base_link" />
    <child link="base_arm_right_mount" />
  </joint>
  <joint name="arm_left_L1_Joint" type="revolute">
    <origin xyz="0 0 0" rpy="0 0 0" />
    <parent link="arm_left_L_arm_root" />
    <child link="arm_left_L1_Link" />
    <axis xyz="0 -1 0" />
    <limit lower="-2.18" upper="3.75" effort="60" velocity="18.84" />
  </joint>
  <joint name="arm_left_L2_Joint" type="revolute">
    <origin xyz="0.03125 0.0715 0" rpy="0 0 0" />
    <parent link="arm_left_L1_Link" />
    <child link="arm_left_L2_Link" />
    <axis xyz="-1 0 0" />
    <limit lower="-3.33" upper="0.19" effort="60" velocity="18.84" />
  </joint>
  <joint name="arm_left_L3_Joint" type="revolute">
    <origin xyz="-0.03125 0 -0.147" rpy="0 0 0" />
    <parent link="arm_left_L2_Link" />
    <child link="arm_left_L3_Link" />
    <axis xyz="0 0 1" />
    <limit lower="-2.26" upper="2.26" effort="17" velocity="137.68" />
  </joint>
  <joint name="arm_left_L4_Joint" type="revolute">
    <origin xyz="0 0.027 -0.126" rpy="0 0 0" />
    <parent link="arm_left_L3_Link" />
    <child link="arm_left_L4_Link" />
    <axis xyz="0 -1 0" />
    <limit lower="-0.78" upper="1.74" effort="36" velocity="10.47" />
  </joint>
  <joint name="arm_left_L5_Joint" type="revolute">
    <origin xyz="0 -0.027 -0.136" rpy="0 0 0" />
    <parent link="arm_left_L4_Link" />
    <child link="arm_left_L5_Link" />
    <axis xyz="0 0 1" />
    <limit lower="-2.96" upper="2.96" effort="14" velocity="27.21" />
  </joint>
  <joint name="arm_left_L6_Joint" type="revolute">
    <origin xyz="0 0.028 -0.0435" rpy="0 0 0" />
    <parent link="arm_left_L5_Link" />
    <child link="arm_left_L6_Link" />
    <axis xyz="0 -1 0" />
    <limit lower="-1.57" upper="1.57" effort="14" velocity="27.21" />
  </joint>
  <joint name="arm_left_L7_Joint" type="revolute">
    <origin xyz="0.028 -0.028 -0.075" rpy="0 0 0" />
    <parent link="arm_left_L6_Link" />
    <child link="arm_left_L7_Link" />
    <axis xyz="-1 0 0" />
    <limit lower="-1.57" upper="1.57" effort="14" velocity="27.21" />
  </joint>
  <joint name="arm_right_R1_Joint" type="revolute">
    <origin xyz="0 0 0" rpy="0 0 0" />
    <parent link="arm_right_R_arm_root" />
    <child link="arm_right_R1_Link" />
    <axis xyz="0 1 0" />
    <limit lower="-3.75" upper="2.18" effort="60" velocity="18.84" />
  </joint>
  <joint name="arm_right_R2_Joint" type="revolute">
    <origin xyz="0.03125 -0.0715 0" rpy="0 0 0" />
    <parent link="arm_right_R1_Link" />
    <child link="arm_right_R2_Link" />
    <axis xyz="-1 0 0" />
    <limit lower="-0.19" upper="3.33" effort="60" velocity="18.84" />
  </joint>
  <joint name="arm_right_R3_Joint" type="revolute">
    <origin xyz="-0.03125 0 -0.147" rpy="0 0 0" />
    <parent link="arm_right_R2_Link" />
    <child link="arm_right_R3_Link" />
    <axis xyz="0 0 1" />
    <limit lower="-2.26" upper="2.26" effort="17" velocity="37.68" />
  </joint>
  <joint name="arm_right_R4_Joint" type="revolute">
    <origin xyz="0 -0.027 -0.126" rpy="0 0 0" />
    <parent link="arm_right_R3_Link" />
    <child link="arm_right_R4_Link" />
    <axis xyz="0 1 0" />
    <limit lower="-1.74" upper="0.78" effort="36" velocity="10.47" />
  </joint>
  <joint name="arm_right_R5_Joint" type="revolute">
    <origin xyz="0 0.027 -0.136" rpy="0 0 0" />
    <parent link="arm_right_R4_Link" />
    <child link="arm_right_R5_Link" />
    <axis xyz="0 0 1" />
    <limit lower="-2.96" upper="2.96" effort="14" velocity="27.21" />
  </joint>
  <joint name="arm_right_R6_Joint" type="revolute">
    <origin xyz="0 -0.028 -0.0435" rpy="0 0 0" />
    <parent link="arm_right_R5_Link" />
    <child link="arm_right_R6_Link" />
    <axis xyz="0 1 0" />
    <limit lower="-1.57" upper="1.57" effort="14" velocity="27.21" />
  </joint>
  <joint name="arm_right_R7_Joint" type="revolute">
    <origin xyz="0.028 0.028 -0.075" rpy="0 0 0" />
    <parent link="arm_right_R6_Link" />
    <child link="arm_right_R7_Link" />
    <axis xyz="-1 0 0" />
    <limit lower="-1.57" upper="1.57" effort="14" velocity="27.21" />
  </joint>
  <joint name="hand_left_lh_thumb_cmc_yaw" type="revolute">
    <origin xyz="0.0115084536 -0.022975 0.030794" rpy="1.57079633 0 0" />
    <parent link="hand_left_lh_hand_base_link" />
    <child link="hand_left_lh_thumb_metacarpals_base2" />
    <axis xyz="0 1 0" />
    <limit lower="0" upper="1.3" effort="100" velocity="1" />
  </joint>
  <joint name="hand_left_lh_thumb_cmc_pitch" type="revolute">
    <origin xyz="0.00915604684 -0.00603785696 0.0158587383" rpy="-0.575786024 -0.407073695 -1.31922273" />
    <parent link="hand_left_lh_thumb_metacarpals_base2" />
    <child link="hand_left_lh_thumb_metacarpals" />
    <axis xyz="0 -1 0" />
    <limit lower="0" upper="0.58" effort="100" velocity="1" />
  </joint>
  <joint name="hand_left_lh_thumb_ip" type="revolute">
    <origin xyz="0 0 0.036812" rpy="0 0 0" />
    <parent link="hand_left_lh_thumb_metacarpals" />
    <child link="hand_left_lh_thumb_distal" />
    <axis xyz="0 -1 0" />
    <limit lower="0" upper="1.08" effort="100" velocity="1" />
    <mimic joint="hand_left_lh_thumb_cmc_pitch" multiplier="1.8788" offset="0" />
  </joint>
  <joint name="hand_left_lh_index_mcp_pitch" type="revolute">
    <origin xyz="0.0024758 -0.02419 0.098779" rpy="0.05236 0 0" />
    <parent link="hand_left_lh_hand_base_link" />
    <child link="hand_left_lh_index_proximal" />
    <axis xyz="0 1 0" />
    <limit lower="0" upper="1.60" effort="100" velocity="1" />
  </joint>
  <joint name="hand_left_lh_index_dip" type="revolute">
    <origin xyz="-0.0052516 0 0.036625" rpy="0 0 0" />
    <parent link="hand_left_lh_index_proximal" />
    <child link="hand_left_lh_index_distal" />
    <axis xyz="0 1 0" />
    <limit lower="0" upper="1.43" effort="100" velocity="1" />
    <mimic joint="hand_left_lh_index_mcp_pitch" multiplier="0.89" offset="0" />
  </joint>
  <joint name="hand_left_lh_middle_mcp_pitch" type="revolute">
    <origin xyz="0.00052576 -0.00634 0.1027" rpy="0 0 0" />
    <parent link="hand_left_lh_hand_base_link" />
    <child link="hand_left_lh_middle_proximal" />
    <axis xyz="0 1 0" />
    <limit lower="0" upper="1.60" effort="100" velocity="1" />
  </joint>
  <joint name="hand_left_lh_middle_dip" type="revolute">
    <origin xyz="-0.0052516 0 0.036625" rpy="0 0 0" />
    <parent link="hand_left_lh_middle_proximal" />
    <child link="hand_left_lh_middle_distal" />
    <axis xyz="0 1 0" />
    <limit lower="0" upper="1.43" effort="100" velocity="1" />
    <mimic joint="hand_left_lh_middle_mcp_pitch" multiplier="0.89" offset="0" />
  </joint>
  <joint name="hand_left_lh_ring_mcp_pitch" type="revolute">
    <origin xyz="0.0010258 0.011135 0.098767" rpy="-0.05236 0 0" />
    <parent link="hand_left_lh_hand_base_link" />
    <child link="hand_left_lh_ring_proximal" />
    <axis xyz="0 1 0" />
    <limit lower="0" upper="1.60" effort="100" velocity="1" />
  </joint>
  <joint name="hand_left_lh_ring_dip" type="revolute">
    <origin xyz="-0.0052516 0 0.036625" rpy="0 0 0" />
    <parent link="hand_left_lh_ring_proximal" />
    <child link="hand_left_lh_ring_distal" />
    <axis xyz="0 1 0" />
    <limit lower="0" upper="1.43" effort="100" velocity="1" />
    <mimic joint="hand_left_lh_ring_mcp_pitch" multiplier="0.89" offset="0" />
  </joint>
  <joint name="hand_left_lh_pinky_mcp_pitch" type="revolute">
    <origin xyz="0.0024758 0.028372 0.092741" rpy="-0.087266 0 0" />
    <parent link="hand_left_lh_hand_base_link" />
    <child link="hand_left_lh_pinky_proximal" />
    <axis xyz="0 1 0" />
    <limit lower="0" upper="1.60" effort="100" velocity="1" />
  </joint>
  <joint name="hand_left_lh_pinky_dip" type="revolute">
    <origin xyz="-0.0052516 0 0.036625" rpy="0 0 0" />
    <parent link="hand_left_lh_pinky_proximal" />
    <child link="hand_left_lh_pinky_distal" />
    <axis xyz="0 1 0" />
    <limit lower="0" upper="1.43" effort="100" velocity="1" />
    <mimic joint="hand_left_lh_pinky_mcp_pitch" multiplier="0.89" offset="0" />
  </joint>
  <joint name="hand_right_rh_thumb_cmc_yaw" type="revolute">
    <origin xyz="0.011508 0.022975 0.032794" rpy="0 0 0" />
    <parent link="hand_right_rh_hand_base_link" />
    <child link="hand_right_rh_thumb_metacarpals_base2" />
    <axis xyz="0 0 -1" />
    <limit lower="0" upper="1.36" effort="100" velocity="1" />
  </joint>
  <joint name="hand_right_rh_thumb_cmc_pitch" type="revolute">
    <origin xyz="0.0061649 0.010678 -0.004891" rpy="0 -1.1529 -2.0944" />
    <parent link="hand_right_rh_thumb_metacarpals_base2" />
    <child link="hand_right_rh_thumb_metacarpals" />
    <axis xyz="0 1 0" />
    <limit lower="0" upper="0.58" effort="100" velocity="1" />
  </joint>
  <joint name="hand_right_rh_thumb_ip" type="revolute">
    <origin xyz="0.0037776 0 0.045368" rpy="0 0 0" />
    <parent link="hand_right_rh_thumb_metacarpals" />
    <child link="hand_right_rh_thumb_distal" />
    <axis xyz="0 1 0" />
    <limit lower="0" upper="1.08" effort="100" velocity="1" />
    <mimic joint="hand_right_rh_thumb_cmc_pitch" multiplier="1.86" offset="0" />
  </joint>
  <joint name="hand_right_rh_index_mcp_pitch" type="revolute">
    <origin xyz="0.0024758 0.02419 0.098779" rpy="-0.05236 0 0" />
    <parent link="hand_right_rh_hand_base_link" />
    <child link="hand_right_rh_index_proximal" />
    <axis xyz="0 1 0" />
    <limit lower="0" upper="1.60" effort="100" velocity="1" />
  </joint>
  <joint name="hand_right_rh_index_dip" type="revolute">
    <origin xyz="-0.0052516 0 0.036625" rpy="0 0 0" />
    <parent link="hand_right_rh_index_proximal" />
    <child link="hand_right_rh_index_distal" />
    <axis xyz="0 1 0" />
    <limit lower="0" upper="1.43" effort="100" velocity="1" />
    <mimic joint="hand_right_rh_index_mcp_pitch" multiplier="0.89" offset="0" />
  </joint>
  <joint name="hand_right_rh_middle_mcp_pitch" type="revolute">
    <origin xyz="0.00052576 0.00634 0.1027" rpy="0 0 0" />
    <parent link="hand_right_rh_hand_base_link" />
    <child link="hand_right_rh_middle_proximal" />
    <axis xyz="0 1 0" />
    <limit lower="0" upper="1.60" effort="100" velocity="1" />
  </joint>
  <joint name="hand_right_rh_middle_dip" type="revolute">
    <origin xyz="-0.0052516 0 0.036625" rpy="0 0 0" />
    <parent link="hand_right_rh_middle_proximal" />
    <child link="hand_right_rh_middle_distal" />
    <axis xyz="0 1 0" />
    <limit lower="0" upper="1.43" effort="100" velocity="1" />
    <mimic joint="hand_right_rh_middle_mcp_pitch" multiplier="0.89" offset="0" />
  </joint>
  <joint name="hand_right_rh_ring_mcp_pitch" type="revolute">
    <origin xyz="0.0010258 -0.011135 0.098767" rpy="0.05236 0 0" />
    <parent link="hand_right_rh_hand_base_link" />
    <child link="hand_right_rh_ring_proximal" />
    <axis xyz="0 1 0" />
    <limit lower="0" upper="1.60" effort="100" velocity="1" />
  </joint>
  <joint name="hand_right_rh_ring_dip" type="revolute">
    <origin xyz="-0.0052516 0 0.036625" rpy="0 0 0" />
    <parent link="hand_right_rh_ring_proximal" />
    <child link="hand_right_rh_ring_distal" />
    <axis xyz="0 1 0" />
    <limit lower="0" upper="1.43" effort="100" velocity="1" />
    <mimic joint="hand_right_rh_ring_mcp_pitch" multiplier="0.89" offset="0" />
  </joint>
  <joint name="hand_right_rh_pinky_mcp_pitch" type="revolute">
    <origin xyz="0.0024758 -0.028372 0.092741" rpy="0.087266 0 0" />
    <parent link="hand_right_rh_hand_base_link" />
    <child link="hand_right_rh_pinky_proximal" />
    <axis xyz="0 1 0" />
    <limit lower="0" upper="1.60" effort="100" velocity="1" />
  </joint>
  <joint name="hand_right_rh_pinky_dip" type="revolute">
    <origin xyz="-0.0052516 0 0.036625" rpy="0 0 0" />
    <parent link="hand_right_rh_pinky_proximal" />
    <child link="hand_right_rh_pinky_distal" />
    <axis xyz="0 1 0" />
    <limit lower="0" upper="1.43" effort="100" velocity="1" />
    <mimic joint="hand_right_rh_pinky_mcp_pitch" multiplier="0.89" offset="0" />
  </joint>
  <joint name="mount_arm_left_to_base_base_mount" type="fixed">
    <origin xyz="0 0 0" rpy="0 0 0" />
    <parent link="base_arm_left_mount" />
    <child link="arm_left_L_arm_root" />
  </joint>
  <joint name="mount_arm_right_to_base_base_mount" type="fixed">
    <origin xyz="0 0 0" rpy="0 0 0" />
    <parent link="base_arm_right_mount" />
    <child link="arm_right_R_arm_root" />
  </joint>
  <joint name="mount_hand_left_to_arm_left_wrist_mount" type="fixed">
    <origin xyz="-0.028 0 -0.052" rpy="3.1416 0 -1.5708" />
    <parent link="arm_left_L7_Link" />
    <child link="hand_left_lh_hand_base_link" />
  </joint>
  <joint name="mount_hand_right_to_arm_right_wrist_mount" type="fixed">
    <origin xyz="-0.028 0 -0.052" rpy="3.1416 0 1.5708" />
    <parent link="arm_right_R7_Link" />
    <child link="hand_right_rh_hand_base_link" />
  </joint>
  <joint name="mount_world_to_base" type="fixed">
    <origin xyz="0 0 0" rpy="0 0 0" />
    <parent link="world" />
    <child link="base_torso_root" />
  </joint>
  <mujoco>
    <compiler meshdir="." balanceinertia="true" discardvisual="true" />
    <default>
      <joint armature="3.4707e-08" damping="5.0" frictionloss="0.5" />
    </default>
    <equality>
      <joint name="hand_left_lh_couple_thumb" joint1="hand_left_lh_thumb_ip" joint2="hand_left_lh_thumb_cmc_pitch" polycoef="0 1.8788 0 0 0 0" />
      <joint name="hand_left_lh_couple_index" joint1="hand_left_lh_index_dip" joint2="hand_left_lh_index_mcp_pitch" polycoef="0 0.89 0 0 0 0" />
      <joint name="hand_left_lh_couple_middle" joint1="hand_left_lh_middle_dip" joint2="hand_left_lh_middle_mcp_pitch" polycoef="0 0.89 0 0 0 0" />
      <joint name="hand_left_lh_couple_ring" joint1="hand_left_lh_ring_dip" joint2="hand_left_lh_ring_mcp_pitch" polycoef="0 0.89 0 0 0 0" />
      <joint name="hand_left_lh_couple_pinky" joint1="hand_left_lh_pinky_dip" joint2="hand_left_lh_pinky_mcp_pitch" polycoef="0 0.89 0 0 0 0" />
    </equality>
  </mujoco>
  <mujoco>
    <default>
      <joint armature="3.4707e-08" damping="5.0" frictionloss="0.5" />
    </default>
    <equality>
      <joint name="hand_right_rh_couple_thumb" joint1="hand_right_rh_thumb_ip" joint2="hand_right_rh_thumb_cmc_pitch" polycoef="0 1.86 0 0 0 0" />
      <joint name="hand_right_rh_couple_index" joint1="hand_right_rh_index_dip" joint2="hand_right_rh_index_mcp_pitch" polycoef="0 0.89 0 0 0 0" />
      <joint name="hand_right_rh_couple_middle" joint1="hand_right_rh_middle_dip" joint2="hand_right_rh_middle_mcp_pitch" polycoef="0 0.89 0 0 0 0" />
      <joint name="hand_right_rh_couple_ring" joint1="hand_right_rh_ring_dip" joint2="hand_right_rh_ring_mcp_pitch" polycoef="0 0.89 0 0 0 0" />
      <joint name="hand_right_rh_couple_pinky" joint1="hand_right_rh_pinky_dip" joint2="hand_right_rh_pinky_mcp_pitch" polycoef="0 0.89 0 0 0 0" />
    </equality>
  </mujoco>
</robot>
