<?xml version="1.0" encoding="UTF-8"?>
<!-- Generated by tools/composer (version 0.1.0). Workstation: a7_lite_o6_dc. Recipe sha256: b78d68fdfbce532308f1dd8cb431146ac9ee9a6ee5892ee386d18461e0c41083. Do not edit by hand; re-run `python -m tools.composer.compose <workstation>`. -->
<mujoco model="a7_lite_o6_dc">
  <compiler discardvisual="false" autolimits="true" angle="radian" eulerseq="XYZ" />
  <option />
  <default>
    <default class="base_base_a7_lite_torso_visual">
      <geom type="mesh" contype="0" conaffinity="0" group="1" />
    </default>
    <default class="base_base_a7_lite_torso_collision">
      <geom type="mesh" contype="1" conaffinity="1" group="3" />
    </default>
    <default class="arm_left_arm_a7_lite_visual">
      <geom type="mesh" contype="0" conaffinity="0" group="1" />
    </default>
    <default class="arm_left_arm_a7_lite_collision">
      <geom type="mesh" contype="1" conaffinity="1" group="3" />
    </default>
    <default class="arm_right_arm_a7_lite_visual">
      <geom type="mesh" contype="0" conaffinity="0" group="1" />
    </default>
    <default class="arm_right_arm_a7_lite_collision">
      <geom type="mesh" contype="1" conaffinity="1" group="3" />
    </default>
    <default class="hand_left_hand_linkerhand_o6_visual">
      <geom type="mesh" contype="0" conaffinity="0" group="1" />
    </default>
    <default class="hand_left_hand_linkerhand_o6_collision">
      <geom type="mesh" contype="1" conaffinity="1" group="3" />
    </default>
    <default class="hand_left_hand_linkerhand_o6_joint">
      <joint armature="3.4707e-08" damping="4.0" frictionloss="0.5" />
    </default>
    <default class="hand_right_hand_linkerhand_o6_visual">
      <geom type="mesh" contype="0" conaffinity="0" group="1" />
    </default>
    <default class="hand_right_hand_linkerhand_o6_collision">
      <geom type="mesh" contype="1" conaffinity="1" group="3" />
    </default>
    <default class="hand_right_hand_linkerhand_o6_joint">
      <joint armature="3.4707e-08" damping="4.0" frictionloss="0.5" />
    </default>
  </default>
  <asset>
    <mesh name="base_torso_base_link" file="../../components/bases/a7_lite_torso/variants/default/meshes/base_link.STL" />
    <mesh name="arm_left_L1" file="../../components/arms/a7_lite/variants/left/meshes/L1_Link.STL" />
    <mesh name="arm_left_L2" file="../../components/arms/a7_lite/variants/left/meshes/L2_Link.STL" />
    <mesh name="arm_left_L3" file="../../components/arms/a7_lite/variants/left/meshes/L3_Link.STL" />
    <mesh name="arm_left_L4" file="../../components/arms/a7_lite/variants/left/meshes/L4_Link.STL" />
    <mesh name="arm_left_L5" file="../../components/arms/a7_lite/variants/left/meshes/L5_Link.STL" />
    <mesh name="arm_left_L6" file="../../components/arms/a7_lite/variants/left/meshes/L6_Link.STL" />
    <mesh name="arm_left_L7" file="../../components/arms/a7_lite/variants/left/meshes/L7_Link.STL" />
    <mesh name="arm_right_R1" file="../../components/arms/a7_lite/variants/right/meshes/R1_Link.STL" />
    <mesh name="arm_right_R2" file="../../components/arms/a7_lite/variants/right/meshes/R2_Link.STL" />
    <mesh name="arm_right_R3" file="../../components/arms/a7_lite/variants/right/meshes/R3_Link.STL" />
    <mesh name="arm_right_R4" file="../../components/arms/a7_lite/variants/right/meshes/R4_Link.STL" />
    <mesh name="arm_right_R5" file="../../components/arms/a7_lite/variants/right/meshes/R5_Link.STL" />
    <mesh name="arm_right_R6" file="../../components/arms/a7_lite/variants/right/meshes/R6_Link.STL" />
    <mesh name="arm_right_R7" file="../../components/arms/a7_lite/variants/right/meshes/R7_Link.STL" />
    <mesh name="hand_left_hand_base" file="../../components/hands/linkerhand_o6/variants/left/meshes/hand_base_link.STL" />
    <mesh name="hand_left_thumb_metacarpals_base2" file="../../components/hands/linkerhand_o6/variants/left/meshes/thumb_metacarpals_base2.STL" />
    <mesh name="hand_left_thumb_metacarpals" file="../../components/hands/linkerhand_o6/variants/left/meshes/thumb_metacarpals.STL" />
    <mesh name="hand_left_thumb_distal" file="../../components/hands/linkerhand_o6/variants/left/meshes/thumb_distal.STL" />
    <mesh name="hand_left_index_proximal" file="../../components/hands/linkerhand_o6/variants/left/meshes/index_proximal.STL" />
    <mesh name="hand_left_index_distal" file="../../components/hands/linkerhand_o6/variants/left/meshes/index_distal.STL" />
    <mesh name="hand_left_middle_proximal" file="../../components/hands/linkerhand_o6/variants/left/meshes/middle_proximal.STL" />
    <mesh name="hand_left_middle_distal" file="../../components/hands/linkerhand_o6/variants/left/meshes/middle_distal.STL" />
    <mesh name="hand_left_ring_proximal" file="../../components/hands/linkerhand_o6/variants/left/meshes/ring_proximal.STL" />
    <mesh name="hand_left_ring_distal" file="../../components/hands/linkerhand_o6/variants/left/meshes/ring_distal.STL" />
    <mesh name="hand_left_pinky_proximal" file="../../components/hands/linkerhand_o6/variants/left/meshes/pinky_proximal.STL" />
    <mesh name="hand_left_pinky_distal" file="../../components/hands/linkerhand_o6/variants/left/meshes/pinky_distal.STL" />
    <mesh name="hand_right_hand_base" file="../../components/hands/linkerhand_o6/variants/right/meshes/hand_base_link.STL" />
    <mesh name="hand_right_thumb_metacarpals_base2" file="../../components/hands/linkerhand_o6/variants/right/meshes/thumb_metacarpals_base2.STL" />
    <mesh name="hand_right_thumb_metacarpals" file="../../components/hands/linkerhand_o6/variants/right/meshes/thumb_metacarpals.STL" />
    <mesh name="hand_right_thumb_distal" file="../../components/hands/linkerhand_o6/variants/right/meshes/thumb_distal.STL" />
    <mesh name="hand_right_index_proximal" file="../../components/hands/linkerhand_o6/variants/right/meshes/index_proximal.STL" />
    <mesh name="hand_right_index_distal" file="../../components/hands/linkerhand_o6/variants/right/meshes/index_distal.STL" />
    <mesh name="hand_right_middle_proximal" file="../../components/hands/linkerhand_o6/variants/right/meshes/middle_proximal.STL" />
    <mesh name="hand_right_middle_distal" file="../../components/hands/linkerhand_o6/variants/right/meshes/middle_distal.STL" />
    <mesh name="hand_right_ring_proximal" file="../../components/hands/linkerhand_o6/variants/right/meshes/ring_proximal.STL" />
    <mesh name="hand_right_ring_distal" file="../../components/hands/linkerhand_o6/variants/right/meshes/ring_distal.STL" />
    <mesh name="hand_right_pinky_proximal" file="../../components/hands/linkerhand_o6/variants/right/meshes/pinky_proximal.STL" />
    <mesh name="hand_right_pinky_distal" file="../../components/hands/linkerhand_o6/variants/right/meshes/pinky_distal.STL" />
  </asset>
  <worldbody>
    <body name="base_torso_root" pos="0 0 0">
      <body name="base_base_link" pos="0 0 1.2">
        <inertial pos="0.0044493 9.5996E-07 -0.58827" mass="8.6616" fullinertia="0.19297 0.19297 0.072594 1.6977E-06 0.00086704 4.1272E-08" />
        <geom class="base_base_a7_lite_torso_visual" mesh="base_torso_base_link" />
        <geom class="base_base_a7_lite_torso_collision" mesh="base_torso_base_link" />
        <body name="base_arm_left_mount" pos="0.0062932 0.1505 -0.022706">
          <site name="base_arm_left_mount" pos="0 0 0" />
          <body name="arm_left_L_arm_root" pos="0 0 0">
            <site name="arm_left_base_mount" pos="0 0 0" />
            <body name="arm_left_L1_Link" pos="0 0 0">
              <inertial pos="0.0045974 0.067978 0.00066635" mass="1.1899" fullinertia="0.0016082 0.00086283 0.00092662 3.5266E-06 2.0532E-07 6.5642E-06" />
              <joint name="arm_left_L1_Joint" type="hinge" axis="0 -1 0" range="-2.18 3.75" damping="20" frictionloss="0.0" armature="0.01" />
              <geom class="arm_left_arm_a7_lite_visual" mesh="arm_left_L1" />
              <geom class="arm_left_arm_a7_lite_collision" mesh="arm_left_L1" />
              <body name="arm_left_L2_Link" pos="0.03125 0.0715 0">
                <inertial pos="-0.030894 9.2644E-05 -0.099437" mass="1.0659" fullinertia="0.001451 0.0012495 0.0010752 3.1371E-06 -1.519E-06 -1.1542E-05" />
                <joint name="arm_left_L2_Joint" type="hinge" axis="-1 0 0" range="-3.33 0.19" damping="20" frictionloss="0.0" armature="0.01" />
                <geom class="arm_left_arm_a7_lite_visual" mesh="arm_left_L2" />
                <geom class="arm_left_arm_a7_lite_collision" mesh="arm_left_L2" />
                <body name="arm_left_L3_Link" pos="-0.03125 0 -0.147">
                  <inertial pos="-5.9577E-05 0.001318 -0.078466" mass="1.2763" fullinertia="0.00078242 0.0010444 0.00063166 -2.9327E-07 7.1339E-06 -2.978E-07" />
                  <joint name="arm_left_L3_Joint" type="hinge" axis="0 0 1" range="-2.26 2.26" damping="20" frictionloss="0.0" armature="0.01" />
                  <geom class="arm_left_arm_a7_lite_visual" mesh="arm_left_L3" />
                  <geom class="arm_left_arm_a7_lite_collision" mesh="arm_left_L3" />
                  <body name="arm_left_L4_Link" pos="0 0.027 -0.126">
                    <inertial pos="1.6127E-05 -0.027094 -0.086199" mass="0.66812" fullinertia="0.00039892 0.00038456 0.00041366 5.379E-08 1.7668E-06 1.0506E-06" />
                    <joint name="arm_left_L4_Joint" type="hinge" axis="0 -1 0" range="-0.78 1.74" damping="20" frictionloss="0.0" armature="0.01" />
                    <geom class="arm_left_arm_a7_lite_visual" mesh="arm_left_L4" />
                    <geom class="arm_left_arm_a7_lite_collision" mesh="arm_left_L4" />
                    <body name="arm_left_L5_Link" pos="0 -0.027 -0.136">
                      <inertial pos="-0.00012977 0.0029474 -0.03886" mass="0.4439" fullinertia="0.00015511 0.00022136 0.00013737 -4.6133E-07 -2.6472E-06 -1.0454E-07" />
                      <joint name="arm_left_L5_Joint" type="hinge" axis="0 0 1" range="-2.96 2.96" damping="20" frictionloss="0.0" armature="0.01" />
                      <geom class="arm_left_arm_a7_lite_visual" mesh="arm_left_L5" />
                      <geom class="arm_left_arm_a7_lite_collision" mesh="arm_left_L5" />
                      <body name="arm_left_L6_Link" pos="0 0.028 -0.0435">
                        <inertial pos="0.0023746 -0.027691 -0.063927" mass="0.5193" fullinertia="0.00031746 0.00024364 0.00015858 -6.3455E-07 4.1005E-07 2.8635E-06" />
                        <joint name="arm_left_L6_Joint" type="hinge" axis="0 -1 0" range="-1.57 1.57" damping="20" frictionloss="0.0" armature="0.01" />
                        <geom class="arm_left_arm_a7_lite_visual" mesh="arm_left_L6" />
                        <geom class="arm_left_arm_a7_lite_collision" mesh="arm_left_L6" />
                        <body name="arm_left_L7_Link" pos="0.028 -0.028 -0.075">
                          <inertial pos="-0.026398 -6.6336E-15 -0.025801" mass="0.10175" fullinertia="4.5036E-05 3.8663E-05 3.0632E-05 -4.7046E-12 2.2349E-07 -1.9234E-20" />
                          <joint name="arm_left_L7_Joint" type="hinge" axis="-1 0 0" range="-1.57 1.57" damping="20" frictionloss="0.0" armature="0.01" />
                          <geom class="arm_left_arm_a7_lite_visual" mesh="arm_left_L7" />
                          <geom class="arm_left_arm_a7_lite_collision" mesh="arm_left_L7" />
                          <site name="arm_left_tool0" pos="0 0 0" />
                          <body name="hand_left_lh_hand_base_link" pos="-0.028 0 -0.052" euler="3.1416 0 -1.5708">
                            <inertial pos="-0.00157788568070457 -0.00034876725935859 0.0538452219801211" mass="0.0672935238166485" fullinertia="5.22525212160954E-05 3.33522349207724E-05 2.28469461105385E-05 3.06955729584715E-07 -3.90341166950521E-07 -7.76680063574627E-07" />
                            <geom class="hand_left_hand_linkerhand_o6_visual" mesh="hand_left_hand_base" />
                            <geom class="hand_left_hand_linkerhand_o6_collision" mesh="hand_left_hand_base" />
                            <site name="hand_left_wrist_mount" pos="0 0 0" />
                            <body name="hand_left_lh_thumb_metacarpals_base2" pos="0.011508 -0.022975 0.032794">
                              <inertial pos="0.00162800681276937 -0.0027668017246415 -0.00184234438641236" mass="0.00138588296544333" fullinertia="5.26292160685909E-08 4.82620491570326E-08 2.88550286112821E-08 -3.92888681640568E-09 -2.43767371295222E-09 3.71869784206147E-09" />
                              <joint name="hand_left_lh_thumb_cmc_yaw" class="hand_left_hand_linkerhand_o6_joint" type="hinge" axis="0 0 1" range="0 1.3" />
                              <geom class="hand_left_hand_linkerhand_o6_visual" mesh="hand_left_thumb_metacarpals_base2" />
                              <geom class="hand_left_hand_linkerhand_o6_collision" mesh="hand_left_thumb_metacarpals_base2" />
                              <body name="hand_left_lh_thumb_metacarpals" pos="0.0061649 -0.010678 -0.004891" euler="0 -1.1529 2.0944">
                                <inertial pos="4.24816204999817E-05 1.74183907812875E-05 0.0228341640631254" mass="0.0123381586619931" fullinertia="1.10292537368909E-06 1.76757772551884E-06 9.36347792411098E-07 -5.99642232777877E-10 -1.14233573940545E-07 -4.03963570823777E-10" />
                                <joint name="hand_left_lh_thumb_cmc_pitch" class="hand_left_hand_linkerhand_o6_joint" type="hinge" axis="0 1 0" range="0 0.58" />
                                <geom class="hand_left_hand_linkerhand_o6_visual" mesh="hand_left_thumb_metacarpals" />
                                <geom class="hand_left_hand_linkerhand_o6_collision" mesh="hand_left_thumb_metacarpals" />
                                <body name="hand_left_lh_thumb_distal" pos="0.0037776 0 0.045368">
                                  <inertial pos="-0.00413725702921841 -5.90704520436747E-08 0.023011401589736" mass="0.00763332957284057" fullinertia="1.3057487813702E-06 1.2248908905341E-06 2.77271910592615E-07 -1.19781508112714E-11 -7.19551697268541E-08 4.55347974652679E-12" />
                                  <joint name="hand_left_lh_thumb_ip" class="hand_left_hand_linkerhand_o6_joint" type="hinge" axis="0 1 0" range="0 1.08" />
                                  <geom class="hand_left_hand_linkerhand_o6_visual" mesh="hand_left_thumb_distal" />
                                  <geom class="hand_left_hand_linkerhand_o6_collision" mesh="hand_left_thumb_distal" />
                                </body>
                              </body>
                            </body>
                            <body name="hand_left_lh_index_proximal" pos="0.0024758 -0.02419 0.098779" euler="0.05236 0 0">
                              <inertial pos="-0.00208656556336452 2.53838713251686E-06 0.0172734941980264" mass="0.00253174651934627" fullinertia="2.65988714157799E-07 2.72914069166233E-07 8.56017305636748E-08 -1.67174578825824E-11 -4.31047725546034E-08 1.8756709532167E-10" />
                              <joint name="hand_left_lh_index_mcp_pitch" class="hand_left_hand_linkerhand_o6_joint" type="hinge" axis="0 1 0" range="0 1.60" />
                              <geom class="hand_left_hand_linkerhand_o6_visual" mesh="hand_left_index_proximal" />
                              <geom class="hand_left_hand_linkerhand_o6_collision" mesh="hand_left_index_proximal" />
                              <body name="hand_left_lh_index_distal" pos="-0.0052516 0 0.036625">
                                <inertial pos="0.00658986616416549 5.13855642059191E-06 0.0194393600039178" mass="0.00376951085886838" fullinertia="3.22347106085043E-07 3.65328133721509E-07 1.24287996386442E-07 1.3801788663582E-11 1.14352857317951E-07 -2.11505011705634E-10" />
                                <joint name="hand_left_lh_index_dip" class="hand_left_hand_linkerhand_o6_joint" type="hinge" axis="0 1 0" range="0 1.43" />
                                <geom class="hand_left_hand_linkerhand_o6_visual" mesh="hand_left_index_distal" />
                                <geom class="hand_left_hand_linkerhand_o6_collision" mesh="hand_left_index_distal" />
                              </body>
                            </body>
                            <body name="hand_left_lh_middle_proximal" pos="0.00052576 -0.00634 0.1027">
                              <inertial pos="-0.00208660654138235 2.56918180119303E-06 0.0172735011723351" mass="0.00253177375206983" fullinertia="2.65989021304483E-07 2.72914402745606E-07 8.5602213431865E-08 -1.69816046635662E-11 -4.31046683215273E-08 1.87484652324395E-10" />
                              <joint name="hand_left_lh_middle_mcp_pitch" class="hand_left_hand_linkerhand_o6_joint" type="hinge" axis="0 1 0" range="0 1.60" />
                              <geom class="hand_left_hand_linkerhand_o6_visual" mesh="hand_left_middle_proximal" />
                              <geom class="hand_left_hand_linkerhand_o6_collision" mesh="hand_left_middle_proximal" />
                              <body name="hand_left_lh_middle_distal" pos="-0.0052516 0 0.036625">
                                <inertial pos="0.00658986516319194 5.10862924271716E-06 0.0194393315699782" mass="0.00376952789210256" fullinertia="3.22348591068053E-07 3.65329535087755E-07 1.24288425862546E-07 1.37122394856588E-11 1.1435291391668E-07 -2.10453810291991E-10" />
                                <joint name="hand_left_lh_middle_dip" class="hand_left_hand_linkerhand_o6_joint" type="hinge" axis="0 1 0" range="0 1.43" />
                                <geom class="hand_left_hand_linkerhand_o6_visual" mesh="hand_left_middle_distal" />
                                <geom class="hand_left_hand_linkerhand_o6_collision" mesh="hand_left_middle_distal" />
                              </body>
                            </body>
                            <body name="hand_left_lh_ring_proximal" pos="0.0010258 0.011135 0.098767" euler="-0.05236 0 0">
                              <inertial pos="-0.00208667931345812 2.63000419462034E-06 0.0172734926448377" mass="0.00253182223645066" fullinertia="2.65989756076584E-07 2.7291510093393E-07 8.56031522765909E-08 -1.74912952703656E-11 -4.31043325594253E-08 1.87158326740895E-10" />
                              <joint name="hand_left_lh_ring_mcp_pitch" class="hand_left_hand_linkerhand_o6_joint" type="hinge" axis="0 1 0" range="0 1.60" />
                              <geom class="hand_left_hand_linkerhand_o6_visual" mesh="hand_left_ring_proximal" />
                              <geom class="hand_left_hand_linkerhand_o6_collision" mesh="hand_left_ring_proximal" />
                              <body name="hand_left_lh_ring_distal" pos="-0.0052516 0 0.036625">
                                <inertial pos="0.00658986648895491 5.05883528165163E-06 0.019439397215532" mass="0.00376949588316609" fullinertia="3.2234524157181E-07 3.65326570102147E-07 1.24287770218135E-07 1.35766976056011E-11 1.14353011012842E-07 -2.08672149138738E-10" />
                                <joint name="hand_left_lh_ring_dip" class="hand_left_hand_linkerhand_o6_joint" type="hinge" axis="0 1 0" range="0 1.43" />
                                <geom class="hand_left_hand_linkerhand_o6_visual" mesh="hand_left_ring_distal" />
                                <geom class="hand_left_hand_linkerhand_o6_collision" mesh="hand_left_ring_distal" />
                              </body>
                            </body>
                            <body name="hand_left_lh_pinky_proximal" pos="0.0024758 0.028372 0.092741" euler="-0.087266 0 0">
                              <inertial pos="-0.00208673599799501 2.68062251165824E-06 0.0172734848131236" mass="0.00253185993162408" fullinertia="2.6599033687183E-07 2.72915617381577E-07 8.56039175034871E-08 -1.79030790016555E-11 -4.31040829565781E-08 1.86906787420486E-10" />
                              <joint name="hand_left_lh_pinky_mcp_pitch" class="hand_left_hand_linkerhand_o6_joint" type="hinge" axis="0 1 0" range="0 1.60" />
                              <geom class="hand_left_hand_linkerhand_o6_visual" mesh="hand_left_pinky_proximal" />
                              <geom class="hand_left_hand_linkerhand_o6_collision" mesh="hand_left_pinky_proximal" />
                              <body name="hand_left_lh_pinky_distal" pos="-0.0052516 0 0.036625">
                                <inertial pos="0.00658987588903027 5.03087534178825E-06 0.0194394491065091" mass="0.00376948071276134" fullinertia="3.22343583730488E-07 3.65325180884183E-07 1.24287567374229E-07 1.35768173270357E-11 1.14353289593012E-07 -2.0744198062439E-10" />
                                <joint name="hand_left_lh_pinky_dip" class="hand_left_hand_linkerhand_o6_joint" type="hinge" axis="0 1 0" range="0 1.43" />
                                <geom class="hand_left_hand_linkerhand_o6_visual" mesh="hand_left_pinky_distal" />
                                <geom class="hand_left_hand_linkerhand_o6_collision" mesh="hand_left_pinky_distal" />
                              </body>
                            </body>
                          </body>
                        </body>
                      </body>
                    </body>
                  </body>
                </body>
              </body>
            </body>
          </body>
        </body>
        <body name="base_arm_right_mount" pos="0.0062926 -0.1505 -0.022706">
          <site name="base_arm_right_mount" pos="0 0 0" />
          <body name="arm_right_R_arm_root" pos="0 0 0">
            <site name="arm_right_base_mount" pos="0 0 0" />
            <body name="arm_right_R1_Link" pos="0 0 0">
              <inertial pos="0.004598 -0.067915 0.00072736" mass="1.1899" fullinertia="0.0016082 0.00086157 0.00092788 -3.3435E-06 3.9187E-07 -6.5828E-06" />
              <joint name="arm_right_R1_Joint" type="hinge" axis="0 1 0" range="-3.75 2.18" damping="20" frictionloss="0.0" armature="0.01" />
              <geom class="arm_right_arm_a7_lite_visual" mesh="arm_right_R1" />
              <geom class="arm_right_arm_a7_lite_collision" mesh="arm_right_R1" />
              <body name="arm_right_R2_Link" pos="0.03125 -0.0715 0">
                <inertial pos="-0.031363 2.7784E-05 -0.099445" mass="1.0663" fullinertia="0.0014523 0.0012484 0.0010754 -8.9962E-07 -1.031E-06 1.1436E-05" />
                <joint name="arm_right_R2_Joint" type="hinge" axis="-1 0 0" range="-0.19 3.33" damping="20" frictionloss="0.0" armature="0.01" />
                <geom class="arm_right_arm_a7_lite_visual" mesh="arm_right_R2" />
                <geom class="arm_right_arm_a7_lite_collision" mesh="arm_right_R2" />
                <body name="arm_right_R3_Link" pos="-0.03125 0 -0.147">
                  <inertial pos="-2.2895E-05 -0.00123 -0.077166" mass="1.3517" fullinertia="0.00080502 0.0010686 0.00067469 2.8702E-07 7.1845E-06 -7.5659E-07" />
                  <joint name="arm_right_R3_Joint" type="hinge" axis="0 0 1" range="-2.26 2.26" damping="20" frictionloss="0.0" armature="0.01" />
                  <geom class="arm_right_arm_a7_lite_visual" mesh="arm_right_R3" />
                  <geom class="arm_right_arm_a7_lite_collision" mesh="arm_right_R3" />
                  <body name="arm_right_R4_Link" pos="0 -0.027 -0.126">
                    <inertial pos="1.2714E-05 0.024908 -0.082641" mass="0.69691" fullinertia="0.00041505 0.00041627 0.00043007 5.3251E-08 1.7254E-06 3.826E-07" />
                    <joint name="arm_right_R4_Joint" type="hinge" axis="0 1 0" range="-1.74 0.78" damping="20" frictionloss="0.0" armature="0.01" />
                    <geom class="arm_right_arm_a7_lite_visual" mesh="arm_right_R4" />
                    <geom class="arm_right_arm_a7_lite_collision" mesh="arm_right_R4" />
                    <body name="arm_right_R5_Link" pos="0 0.027 -0.136">
                      <inertial pos="0.00029153 -0.0027009 -0.035875" mass="0.48527" fullinertia="0.00016555 0.00022756 0.00015289 -5.747E-07 -2.6985E-06 -9.211E-07" />
                      <joint name="arm_right_R5_Joint" type="hinge" axis="0 0 1" range="-2.96 2.96" damping="20" frictionloss="0.0" armature="0.01" />
                      <geom class="arm_right_arm_a7_lite_visual" mesh="arm_right_R5" />
                      <geom class="arm_right_arm_a7_lite_collision" mesh="arm_right_R5" />
                      <body name="arm_right_R6_Link" pos="0 -0.028 -0.0435">
                        <inertial pos="0.0023746 0.027704 -0.063949" mass="0.5193" fullinertia="0.00031746 0.00024364 0.00015858 6.3467E-07 4.1001E-07 -2.8219E-06" />
                        <joint name="arm_right_R6_Joint" type="hinge" axis="0 1 0" range="-1.57 1.57" damping="20" frictionloss="0.0" armature="0.01" />
                        <geom class="arm_right_arm_a7_lite_visual" mesh="arm_right_R6" />
                        <geom class="arm_right_arm_a7_lite_collision" mesh="arm_right_R6" />
                        <body name="arm_right_R7_Link" pos="0.028 0.028 -0.075">
                          <inertial pos="-0.026598 3.7248E-14 -0.025801" mass="0.10175" fullinertia="4.5036E-05 3.8663E-05 3.0632E-05 -4.7046E-12 2.2349E-07 -1.5968E-20" />
                          <joint name="arm_right_R7_Joint" type="hinge" axis="-1 0 0" range="-1.57 1.57" damping="20" frictionloss="0.0" armature="0.01" />
                          <geom class="arm_right_arm_a7_lite_visual" mesh="arm_right_R7" />
                          <geom class="arm_right_arm_a7_lite_collision" mesh="arm_right_R7" />
                          <site name="arm_right_tool0" pos="0 0 0" />
                          <body name="hand_right_rh_hand_base_link" pos="-0.028 0 -0.052" euler="3.1416 0 1.5708">
                            <inertial pos="-0.00160320773490556 0.000358462699237561 0.0538002704027215" mass="0.06740077960995" fullinertia="5.22359941041901E-05 3.33473043513648E-05 2.28342677422006E-05 3.0391535852764E-07 3.88322215371643E-07 -7.77555280794861E-07" />
                            <geom class="hand_right_hand_linkerhand_o6_visual" mesh="hand_right_hand_base" />
                            <geom class="hand_right_hand_linkerhand_o6_collision" mesh="hand_right_hand_base" />
                            <site name="hand_right_wrist_mount" pos="0 0 0" />
                            <body name="hand_right_rh_thumb_metacarpals_base2" pos="0.011508 0.022975 0.032794">
                              <inertial pos="0.00162795738393507 0.00276671978336815 -0.00184227725602707" mass="0.00138591070212997" fullinertia="5.26294625624223E-08 4.82623724532942E-08 2.88555522060562E-08 -3.9288013799604E-09 2.43766268199571E-09 3.71867754115443E-09" />
                              <joint name="hand_right_rh_thumb_cmc_yaw" class="hand_right_hand_linkerhand_o6_joint" type="hinge" axis="0 0 -1" range="0 1.36" />
                              <geom class="hand_right_hand_linkerhand_o6_visual" mesh="hand_right_thumb_metacarpals_base2" />
                              <geom class="hand_right_hand_linkerhand_o6_collision" mesh="hand_right_thumb_metacarpals_base2" />
                              <body name="hand_right_rh_thumb_metacarpals" pos="0.0061649 0.010678 -0.004891" euler="0 -1.1529 -2.0944">
                                <inertial pos="4.24920612856275E-05 -1.67885666835232E-05 0.0228341522590467" mass="0.0123381607727595" fullinertia="1.10292488693766E-06 1.76757658485787E-06 9.36348143657406E-07 -6.14241939151719E-10 1.14233108676795E-07 -4.24576599367025E-10" />
                                <joint name="hand_right_rh_thumb_cmc_pitch" class="hand_right_hand_linkerhand_o6_joint" type="hinge" axis="0 1 0" range="0 0.58" />
                                <geom class="hand_right_hand_linkerhand_o6_visual" mesh="hand_right_thumb_metacarpals" />
                                <geom class="hand_right_hand_linkerhand_o6_collision" mesh="hand_right_thumb_metacarpals" />
                                <body name="hand_right_rh_thumb_distal" pos="0.0037776 0 0.045368">
                                  <inertial pos="-0.00413690727496815 -4.54842793429222E-07 0.0230097179163771" mass="0.00763302603723749" fullinertia="1.30546842791578E-06 1.22457212713176E-06 2.7729897944409E-07 -2.61617511029467E-12 7.19030685242407E-08 1.66931068485225E-11" />
                                  <joint name="hand_right_rh_thumb_ip" class="hand_right_hand_linkerhand_o6_joint" type="hinge" axis="0 1 0" range="0 1.08" />
                                  <geom class="hand_right_hand_linkerhand_o6_visual" mesh="hand_right_thumb_distal" />
                                  <geom class="hand_right_hand_linkerhand_o6_collision" mesh="hand_right_thumb_distal" />
                                </body>
                              </body>
                            </body>
                            <body name="hand_right_rh_index_proximal" pos="0.0024758 0.02419 0.098779" euler="-0.05236 0 0">
                              <inertial pos="-0.00208665596033792 -4.8964990644329E-06 0.0172736718900068" mass="0.00253178529301663" fullinertia="2.65990159539482E-07 2.72915460277804E-07 8.56026306687528E-08 -3.55165625722842E-11 4.31046335852167E-08 1.75935978708959E-10" />
                              <joint name="hand_right_rh_index_mcp_pitch" class="hand_right_hand_linkerhand_o6_joint" type="hinge" axis="0 1 0" range="0 1.60" />
                              <geom class="hand_right_hand_linkerhand_o6_visual" mesh="hand_right_index_proximal" />
                              <geom class="hand_right_hand_linkerhand_o6_collision" mesh="hand_right_index_proximal" />
                              <body name="hand_right_rh_index_distal" pos="-0.0052516 0 0.036625">
                                <inertial pos="0.00658940011630532 -4.59976557022623E-06 0.0194434136420913" mass="0.00376787129082313" fullinertia="3.22116619426455E-07 3.65131844686317E-07 1.24256890612907E-07 1.03152735699049E-11 -1.14363506430985E-07 -1.97263639269362E-10" />
                                <joint name="hand_right_rh_index_dip" class="hand_right_hand_linkerhand_o6_joint" type="hinge" axis="0 1 0" range="0 1.43" />
                                <geom class="hand_right_hand_linkerhand_o6_visual" mesh="hand_right_index_distal" />
                                <geom class="hand_right_hand_linkerhand_o6_collision" mesh="hand_right_index_distal" />
                              </body>
                            </body>
                            <body name="hand_right_rh_middle_proximal" pos="0.00052576 0.00634 0.1027">
                              <inertial pos="-0.00208661081773556 -4.93451838476378E-06 0.0172736805321904" mass="0.00253175497594429" fullinertia="2.65989683690695E-07 2.72915006047006E-07 8.56020467202518E-08 -3.58343951791586E-11 4.31048601085216E-08 1.75718024412593E-10" />
                              <joint name="hand_right_rh_middle_mcp_pitch" class="hand_right_hand_linkerhand_o6_joint" type="hinge" axis="0 1 0" range="0 1.60" />
                              <geom class="hand_right_hand_linkerhand_o6_visual" mesh="hand_right_middle_proximal" />
                              <geom class="hand_right_hand_linkerhand_o6_collision" mesh="hand_right_middle_proximal" />
                              <body name="hand_right_rh_middle_distal" pos="-0.0052516 0 0.036625">
                                <inertial pos="0.00658940304809306 -4.5885743593238E-06 0.0194434523296449" mass="0.00376786259758948" fullinertia="3.221153658306E-07 3.65130723083104E-07 1.24256787913797E-07 1.02639617308432E-11 -1.14363547272711E-07 -1.96904618797577E-10" />
                                <joint name="hand_right_rh_middle_dip" class="hand_right_hand_linkerhand_o6_joint" type="hinge" axis="0 1 0" range="0 1.43" />
                                <geom class="hand_right_hand_linkerhand_o6_visual" mesh="hand_right_middle_distal" />
                                <geom class="hand_right_hand_linkerhand_o6_collision" mesh="hand_right_middle_distal" />
                              </body>
                            </body>
                            <body name="hand_right_rh_ring_proximal" pos="0.0010258 -0.011135 0.098767" euler="0.05236 0 0">
                              <inertial pos="-0.00208654311325356 -4.98538564003281E-06 0.0172736743497407" mass="0.00253170963529411" fullinertia="2.6598913795678E-07 2.72914417061517E-07 8.56012458677515E-08 -3.62757108675266E-11 4.31050611555507E-08 1.75554984053478E-10" />
                              <joint name="hand_right_rh_ring_mcp_pitch" class="hand_right_hand_linkerhand_o6_joint" type="hinge" axis="0 1 0" range="0 1.60" />
                              <geom class="hand_right_hand_linkerhand_o6_visual" mesh="hand_right_ring_proximal" />
                              <geom class="hand_right_hand_linkerhand_o6_collision" mesh="hand_right_ring_proximal" />
                              <body name="hand_right_rh_ring_distal" pos="-0.0052516 0 0.036625">
                                <inertial pos="0.00658940273069729 -4.56628863591824E-06 0.0194435005686854" mass="0.0037678395356105" fullinertia="3.22112632437858E-07 3.65128262095686E-07 1.24256284608064E-07 1.01848408913558E-11 -1.1436348915342E-07 -1.96145632992445E-10" />
                                <joint name="hand_right_rh_ring_dip" class="hand_right_hand_linkerhand_o6_joint" type="hinge" axis="0 1 0" range="0 1.43" />
                                <geom class="hand_right_hand_linkerhand_o6_visual" mesh="hand_right_ring_distal" />
                                <geom class="hand_right_hand_linkerhand_o6_collision" mesh="hand_right_ring_distal" />
                              </body>
                            </body>
                            <body name="hand_right_rh_pinky_proximal" pos="0.0024758 -0.028372 0.092741" euler="0.087266 0 0">
                              <inertial pos="-0.00208649034130813 -5.02314582560837E-06 0.0172736680793697" mass="0.00253167400540778" fullinertia="2.65988718820404E-07 2.72913936904813E-07 8.56006424720129E-08 -3.66012295280295E-11 4.31052220484445E-08 1.75447396222308E-10" />
                              <joint name="hand_right_rh_pinky_mcp_pitch" class="hand_right_hand_linkerhand_o6_joint" type="hinge" axis="0 1 0" range="0 1.60" />
                              <geom class="hand_right_hand_linkerhand_o6_visual" mesh="hand_right_pinky_proximal" />
                              <geom class="hand_right_hand_linkerhand_o6_collision" mesh="hand_right_pinky_proximal" />
                              <body name="hand_right_rh_pinky_distal" pos="-0.0052516 0 0.036625">
                                <inertial pos="0.00658940431519205 -4.55268314210333E-06 0.0194435341098305" mass="0.00376782669873412" fullinertia="3.22111112339498E-07 3.65126916899176E-07 1.24256004854426E-07 1.01707985908333E-11 -1.14363524419061E-07 -1.95589215866356E-10" />
                                <joint name="hand_right_rh_pinky_dip" class="hand_right_hand_linkerhand_o6_joint" type="hinge" axis="0 1 0" range="0 1.43" />
                                <geom class="hand_right_hand_linkerhand_o6_visual" mesh="hand_right_pinky_distal" />
                                <geom class="hand_right_hand_linkerhand_o6_collision" mesh="hand_right_pinky_distal" />
                              </body>
                            </body>
                          </body>
                        </body>
                      </body>
                    </body>
                  </body>
                </body>
              </body>
            </body>
          </body>
        </body>
      </body>
    </body>
  </worldbody>
  <actuator>
    <position name="arm_left_L1_Joint_act" joint="arm_left_L1_Joint" kp="2000" kv="0" ctrlrange="-2.18 3.75" />
    <position name="arm_left_L2_Joint_act" joint="arm_left_L2_Joint" kp="2000" kv="0" ctrlrange="-3.33 0.19" />
    <position name="arm_left_L3_Joint_act" joint="arm_left_L3_Joint" kp="2000" kv="0" ctrlrange="-2.26 2.26" />
    <position name="arm_left_L4_Joint_act" joint="arm_left_L4_Joint" kp="2000" kv="0" ctrlrange="-0.78 1.74" />
    <position name="arm_left_L5_Joint_act" joint="arm_left_L5_Joint" kp="2000" kv="0" ctrlrange="-2.96 2.96" />
    <position name="arm_left_L6_Joint_act" joint="arm_left_L6_Joint" kp="2000" kv="0" ctrlrange="-1.57 1.57" />
    <position name="arm_left_L7_Joint_act" joint="arm_left_L7_Joint" kp="2000" kv="0" ctrlrange="-1.57 1.57" />
    <position name="arm_right_R1_Joint_act" joint="arm_right_R1_Joint" kp="2000" kv="0" ctrlrange="-3.75 2.18" />
    <position name="arm_right_R2_Joint_act" joint="arm_right_R2_Joint" kp="2000" kv="0" ctrlrange="-0.19 3.33" />
    <position name="arm_right_R3_Joint_act" joint="arm_right_R3_Joint" kp="2000" kv="0" ctrlrange="-2.26 2.26" />
    <position name="arm_right_R4_Joint_act" joint="arm_right_R4_Joint" kp="2000" kv="0" ctrlrange="-1.74 0.78" />
    <position name="arm_right_R5_Joint_act" joint="arm_right_R5_Joint" kp="2000" kv="0" ctrlrange="-2.96 2.96" />
    <position name="arm_right_R6_Joint_act" joint="arm_right_R6_Joint" kp="2000" kv="0" ctrlrange="-1.57 1.57" />
    <position name="arm_right_R7_Joint_act" joint="arm_right_R7_Joint" kp="2000" kv="0" ctrlrange="-1.57 1.57" />
    <position name="hand_left_lh_thumb_cmc_yaw_act" joint="hand_left_lh_thumb_cmc_yaw" kp="200" kv="0" ctrlrange="0 1.3" />
    <position name="hand_left_lh_thumb_cmc_pitch_act" joint="hand_left_lh_thumb_cmc_pitch" kp="200" kv="0" ctrlrange="0 0.58" />
    <position name="hand_left_lh_index_mcp_pitch_act" joint="hand_left_lh_index_mcp_pitch" kp="200" kv="0" ctrlrange="0 1.60" />
    <position name="hand_left_lh_middle_mcp_pitch_act" joint="hand_left_lh_middle_mcp_pitch" kp="200" kv="0" ctrlrange="0 1.60" />
    <position name="hand_left_lh_ring_mcp_pitch_act" joint="hand_left_lh_ring_mcp_pitch" kp="200" kv="0" ctrlrange="0 1.60" />
    <position name="hand_left_lh_pinky_mcp_pitch_act" joint="hand_left_lh_pinky_mcp_pitch" kp="200" kv="0" ctrlrange="0 1.60" />
    <position name="hand_right_rh_thumb_cmc_yaw_act" joint="hand_right_rh_thumb_cmc_yaw" kp="200" kv="0" ctrlrange="0 1.36" />
    <position name="hand_right_rh_thumb_cmc_pitch_act" joint="hand_right_rh_thumb_cmc_pitch" kp="200" kv="0" ctrlrange="0 0.58" />
    <position name="hand_right_rh_index_mcp_pitch_act" joint="hand_right_rh_index_mcp_pitch" kp="200" kv="0" ctrlrange="0 1.60" />
    <position name="hand_right_rh_middle_mcp_pitch_act" joint="hand_right_rh_middle_mcp_pitch" kp="200" kv="0" ctrlrange="0 1.60" />
    <position name="hand_right_rh_ring_mcp_pitch_act" joint="hand_right_rh_ring_mcp_pitch" kp="200" kv="0" ctrlrange="0 1.60" />
    <position name="hand_right_rh_pinky_mcp_pitch_act" joint="hand_right_rh_pinky_mcp_pitch" kp="200" kv="0" ctrlrange="0 1.60" />
  </actuator>
  <equality>
    <joint name="hand_left_lh_couple_thumb" joint1="hand_left_lh_thumb_ip" joint2="hand_left_lh_thumb_cmc_pitch" polycoef="0 2.29 0 0 0" />
    <joint name="hand_left_lh_couple_index" joint1="hand_left_lh_index_dip" joint2="hand_left_lh_index_mcp_pitch" polycoef="0 0.89 0 0 0" />
    <joint name="hand_left_lh_couple_middle" joint1="hand_left_lh_middle_dip" joint2="hand_left_lh_middle_mcp_pitch" polycoef="0 0.89 0 0 0" />
    <joint name="hand_left_lh_couple_ring" joint1="hand_left_lh_ring_dip" joint2="hand_left_lh_ring_mcp_pitch" polycoef="0 0.89 0 0 0" />
    <joint name="hand_left_lh_couple_pinky" joint1="hand_left_lh_pinky_dip" joint2="hand_left_lh_pinky_mcp_pitch" polycoef="0 0.89 0 0 0" />
    <joint name="hand_right_rh_couple_thumb" joint1="hand_right_rh_thumb_ip" joint2="hand_right_rh_thumb_cmc_pitch" polycoef="0 1.86 0 0 0" />
    <joint name="hand_right_rh_couple_index" joint1="hand_right_rh_index_dip" joint2="hand_right_rh_index_mcp_pitch" polycoef="0 0.89 0 0 0" />
    <joint name="hand_right_rh_couple_middle" joint1="hand_right_rh_middle_dip" joint2="hand_right_rh_middle_mcp_pitch" polycoef="0 0.89 0 0 0" />
    <joint name="hand_right_rh_couple_ring" joint1="hand_right_rh_ring_dip" joint2="hand_right_rh_ring_mcp_pitch" polycoef="0 0.89 0 0 0" />
    <joint name="hand_right_rh_couple_pinky" joint1="hand_right_rh_pinky_dip" joint2="hand_right_rh_pinky_mcp_pitch" polycoef="0 0.89 0 0 0" />
  </equality>
  <contact>
    <exclude body1="arm_left_L1_Link" body2="arm_left_L2_Link" />
    <exclude body1="arm_left_L2_Link" body2="arm_left_L3_Link" />
    <exclude body1="arm_left_L3_Link" body2="arm_left_L4_Link" />
    <exclude body1="arm_left_L4_Link" body2="arm_left_L5_Link" />
    <exclude body1="arm_left_L5_Link" body2="arm_left_L6_Link" />
    <exclude body1="arm_left_L6_Link" body2="arm_left_L7_Link" />
    <exclude body1="arm_right_R1_Link" body2="arm_right_R2_Link" />
    <exclude body1="arm_right_R2_Link" body2="arm_right_R3_Link" />
    <exclude body1="arm_right_R3_Link" body2="arm_right_R4_Link" />
    <exclude body1="arm_right_R4_Link" body2="arm_right_R5_Link" />
    <exclude body1="arm_right_R5_Link" body2="arm_right_R6_Link" />
    <exclude body1="arm_right_R6_Link" body2="arm_right_R7_Link" />
    <exclude body1="hand_left_lh_hand_base_link" body2="hand_left_lh_thumb_metacarpals_base2" />
    <exclude body1="hand_left_lh_thumb_metacarpals_base2" body2="hand_left_lh_thumb_metacarpals" />
    <exclude body1="hand_left_lh_thumb_metacarpals" body2="hand_left_lh_thumb_distal" />
    <exclude body1="hand_left_lh_hand_base_link" body2="hand_left_lh_index_proximal" />
    <exclude body1="hand_left_lh_index_proximal" body2="hand_left_lh_index_distal" />
    <exclude body1="hand_left_lh_hand_base_link" body2="hand_left_lh_middle_proximal" />
    <exclude body1="hand_left_lh_middle_proximal" body2="hand_left_lh_middle_distal" />
    <exclude body1="hand_left_lh_hand_base_link" body2="hand_left_lh_ring_proximal" />
    <exclude body1="hand_left_lh_ring_proximal" body2="hand_left_lh_ring_distal" />
    <exclude body1="hand_left_lh_hand_base_link" body2="hand_left_lh_pinky_proximal" />
    <exclude body1="hand_left_lh_pinky_proximal" body2="hand_left_lh_pinky_distal" />
    <exclude body1="hand_right_rh_hand_base_link" body2="hand_right_rh_thumb_metacarpals_base2" />
    <exclude body1="hand_right_rh_thumb_metacarpals_base2" body2="hand_right_rh_thumb_metacarpals" />
    <exclude body1="hand_right_rh_thumb_metacarpals" body2="hand_right_rh_thumb_distal" />
    <exclude body1="hand_right_rh_hand_base_link" body2="hand_right_rh_index_proximal" />
    <exclude body1="hand_right_rh_index_proximal" body2="hand_right_rh_index_distal" />
    <exclude body1="hand_right_rh_hand_base_link" body2="hand_right_rh_middle_proximal" />
    <exclude body1="hand_right_rh_middle_proximal" body2="hand_right_rh_middle_distal" />
    <exclude body1="hand_right_rh_hand_base_link" body2="hand_right_rh_ring_proximal" />
    <exclude body1="hand_right_rh_ring_proximal" body2="hand_right_rh_ring_distal" />
    <exclude body1="hand_right_rh_hand_base_link" body2="hand_right_rh_pinky_proximal" />
    <exclude body1="hand_right_rh_pinky_proximal" body2="hand_right_rh_pinky_distal" />
    <exclude body1="base_base_link" body2="arm_left_L1_Link" />
    <exclude body1="base_base_link" body2="arm_left_L2_Link" />
    <exclude body1="base_base_link" body2="arm_left_L3_Link" />
    <exclude body1="base_base_link" body2="arm_left_L4_Link" />
    <exclude body1="base_base_link" body2="arm_left_L5_Link" />
    <exclude body1="base_base_link" body2="arm_left_L6_Link" />
    <exclude body1="base_base_link" body2="arm_left_L7_Link" />
    <exclude body1="base_base_link" body2="arm_right_R1_Link" />
    <exclude body1="base_base_link" body2="arm_right_R2_Link" />
    <exclude body1="base_base_link" body2="arm_right_R3_Link" />
    <exclude body1="base_base_link" body2="arm_right_R4_Link" />
    <exclude body1="base_base_link" body2="arm_right_R5_Link" />
    <exclude body1="base_base_link" body2="arm_right_R6_Link" />
    <exclude body1="base_base_link" body2="arm_right_R7_Link" />
    <exclude body1="arm_left_L1_Link" body2="hand_left_lh_hand_base_link" />
    <exclude body1="arm_left_L1_Link" body2="hand_left_lh_thumb_metacarpals_base2" />
    <exclude body1="arm_left_L1_Link" body2="hand_left_lh_thumb_metacarpals" />
    <exclude body1="arm_left_L1_Link" body2="hand_left_lh_thumb_distal" />
    <exclude body1="arm_left_L1_Link" body2="hand_left_lh_index_proximal" />
    <exclude body1="arm_left_L1_Link" body2="hand_left_lh_index_distal" />
    <exclude body1="arm_left_L1_Link" body2="hand_left_lh_middle_proximal" />
    <exclude body1="arm_left_L1_Link" body2="hand_left_lh_middle_distal" />
    <exclude body1="arm_left_L1_Link" body2="hand_left_lh_ring_proximal" />
    <exclude body1="arm_left_L1_Link" body2="hand_left_lh_ring_distal" />
    <exclude body1="arm_left_L1_Link" body2="hand_left_lh_pinky_proximal" />
    <exclude body1="arm_left_L1_Link" body2="hand_left_lh_pinky_distal" />
    <exclude body1="arm_left_L2_Link" body2="hand_left_lh_hand_base_link" />
    <exclude body1="arm_left_L2_Link" body2="hand_left_lh_thumb_metacarpals_base2" />
    <exclude body1="arm_left_L2_Link" body2="hand_left_lh_thumb_metacarpals" />
    <exclude body1="arm_left_L2_Link" body2="hand_left_lh_thumb_distal" />
    <exclude body1="arm_left_L2_Link" body2="hand_left_lh_index_proximal" />
    <exclude body1="arm_left_L2_Link" body2="hand_left_lh_index_distal" />
    <exclude body1="arm_left_L2_Link" body2="hand_left_lh_middle_proximal" />
    <exclude body1="arm_left_L2_Link" body2="hand_left_lh_middle_distal" />
    <exclude body1="arm_left_L2_Link" body2="hand_left_lh_ring_proximal" />
    <exclude body1="arm_left_L2_Link" body2="hand_left_lh_ring_distal" />
    <exclude body1="arm_left_L2_Link" body2="hand_left_lh_pinky_proximal" />
    <exclude body1="arm_left_L2_Link" body2="hand_left_lh_pinky_distal" />
    <exclude body1="arm_left_L3_Link" body2="hand_left_lh_hand_base_link" />
    <exclude body1="arm_left_L3_Link" body2="hand_left_lh_thumb_metacarpals_base2" />
    <exclude body1="arm_left_L3_Link" body2="hand_left_lh_thumb_metacarpals" />
    <exclude body1="arm_left_L3_Link" body2="hand_left_lh_thumb_distal" />
    <exclude body1="arm_left_L3_Link" body2="hand_left_lh_index_proximal" />
    <exclude body1="arm_left_L3_Link" body2="hand_left_lh_index_distal" />
    <exclude body1="arm_left_L3_Link" body2="hand_left_lh_middle_proximal" />
    <exclude body1="arm_left_L3_Link" body2="hand_left_lh_middle_distal" />
    <exclude body1="arm_left_L3_Link" body2="hand_left_lh_ring_proximal" />
    <exclude body1="arm_left_L3_Link" body2="hand_left_lh_ring_distal" />
    <exclude body1="arm_left_L3_Link" body2="hand_left_lh_pinky_proximal" />
    <exclude body1="arm_left_L3_Link" body2="hand_left_lh_pinky_distal" />
    <exclude body1="arm_left_L4_Link" body2="hand_left_lh_hand_base_link" />
    <exclude body1="arm_left_L4_Link" body2="hand_left_lh_thumb_metacarpals_base2" />
    <exclude body1="arm_left_L4_Link" body2="hand_left_lh_thumb_metacarpals" />
    <exclude body1="arm_left_L4_Link" body2="hand_left_lh_thumb_distal" />
    <exclude body1="arm_left_L4_Link" body2="hand_left_lh_index_proximal" />
    <exclude body1="arm_left_L4_Link" body2="hand_left_lh_index_distal" />
    <exclude body1="arm_left_L4_Link" body2="hand_left_lh_middle_proximal" />
    <exclude body1="arm_left_L4_Link" body2="hand_left_lh_middle_distal" />
    <exclude body1="arm_left_L4_Link" body2="hand_left_lh_ring_proximal" />
    <exclude body1="arm_left_L4_Link" body2="hand_left_lh_ring_distal" />
    <exclude body1="arm_left_L4_Link" body2="hand_left_lh_pinky_proximal" />
    <exclude body1="arm_left_L4_Link" body2="hand_left_lh_pinky_distal" />
    <exclude body1="arm_left_L5_Link" body2="hand_left_lh_hand_base_link" />
    <exclude body1="arm_left_L5_Link" body2="hand_left_lh_thumb_metacarpals_base2" />
    <exclude body1="arm_left_L5_Link" body2="hand_left_lh_thumb_metacarpals" />
    <exclude body1="arm_left_L5_Link" body2="hand_left_lh_thumb_distal" />
    <exclude body1="arm_left_L5_Link" body2="hand_left_lh_index_proximal" />
    <exclude body1="arm_left_L5_Link" body2="hand_left_lh_index_distal" />
    <exclude body1="arm_left_L5_Link" body2="hand_left_lh_middle_proximal" />
    <exclude body1="arm_left_L5_Link" body2="hand_left_lh_middle_distal" />
    <exclude body1="arm_left_L5_Link" body2="hand_left_lh_ring_proximal" />
    <exclude body1="arm_left_L5_Link" body2="hand_left_lh_ring_distal" />
    <exclude body1="arm_left_L5_Link" body2="hand_left_lh_pinky_proximal" />
    <exclude body1="arm_left_L5_Link" body2="hand_left_lh_pinky_distal" />
    <exclude body1="arm_left_L6_Link" body2="hand_left_lh_hand_base_link" />
    <exclude body1="arm_left_L6_Link" body2="hand_left_lh_thumb_metacarpals_base2" />
    <exclude body1="arm_left_L6_Link" body2="hand_left_lh_thumb_metacarpals" />
    <exclude body1="arm_left_L6_Link" body2="hand_left_lh_thumb_distal" />
    <exclude body1="arm_left_L6_Link" body2="hand_left_lh_index_proximal" />
    <exclude body1="arm_left_L6_Link" body2="hand_left_lh_index_distal" />
    <exclude body1="arm_left_L6_Link" body2="hand_left_lh_middle_proximal" />
    <exclude body1="arm_left_L6_Link" body2="hand_left_lh_middle_distal" />
    <exclude body1="arm_left_L6_Link" body2="hand_left_lh_ring_proximal" />
    <exclude body1="arm_left_L6_Link" body2="hand_left_lh_ring_distal" />
    <exclude body1="arm_left_L6_Link" body2="hand_left_lh_pinky_proximal" />
    <exclude body1="arm_left_L6_Link" body2="hand_left_lh_pinky_distal" />
    <exclude body1="arm_left_L7_Link" body2="hand_left_lh_hand_base_link" />
    <exclude body1="arm_left_L7_Link" body2="hand_left_lh_thumb_metacarpals_base2" />
    <exclude body1="arm_left_L7_Link" body2="hand_left_lh_thumb_metacarpals" />
    <exclude body1="arm_left_L7_Link" body2="hand_left_lh_thumb_distal" />
    <exclude body1="arm_left_L7_Link" body2="hand_left_lh_index_proximal" />
    <exclude body1="arm_left_L7_Link" body2="hand_left_lh_index_distal" />
    <exclude body1="arm_left_L7_Link" body2="hand_left_lh_middle_proximal" />
    <exclude body1="arm_left_L7_Link" body2="hand_left_lh_middle_distal" />
    <exclude body1="arm_left_L7_Link" body2="hand_left_lh_ring_proximal" />
    <exclude body1="arm_left_L7_Link" body2="hand_left_lh_ring_distal" />
    <exclude body1="arm_left_L7_Link" body2="hand_left_lh_pinky_proximal" />
    <exclude body1="arm_left_L7_Link" body2="hand_left_lh_pinky_distal" />
    <exclude body1="base_base_link" body2="hand_left_lh_hand_base_link" />
    <exclude body1="base_base_link" body2="hand_left_lh_thumb_metacarpals_base2" />
    <exclude body1="base_base_link" body2="hand_left_lh_thumb_metacarpals" />
    <exclude body1="base_base_link" body2="hand_left_lh_thumb_distal" />
    <exclude body1="base_base_link" body2="hand_left_lh_index_proximal" />
    <exclude body1="base_base_link" body2="hand_left_lh_index_distal" />
    <exclude body1="base_base_link" body2="hand_left_lh_middle_proximal" />
    <exclude body1="base_base_link" body2="hand_left_lh_middle_distal" />
    <exclude body1="base_base_link" body2="hand_left_lh_ring_proximal" />
    <exclude body1="base_base_link" body2="hand_left_lh_ring_distal" />
    <exclude body1="base_base_link" body2="hand_left_lh_pinky_proximal" />
    <exclude body1="base_base_link" body2="hand_left_lh_pinky_distal" />
    <exclude body1="arm_right_R1_Link" body2="hand_right_rh_hand_base_link" />
    <exclude body1="arm_right_R1_Link" body2="hand_right_rh_thumb_metacarpals_base2" />
    <exclude body1="arm_right_R1_Link" body2="hand_right_rh_thumb_metacarpals" />
    <exclude body1="arm_right_R1_Link" body2="hand_right_rh_thumb_distal" />
    <exclude body1="arm_right_R1_Link" body2="hand_right_rh_index_proximal" />
    <exclude body1="arm_right_R1_Link" body2="hand_right_rh_index_distal" />
    <exclude body1="arm_right_R1_Link" body2="hand_right_rh_middle_proximal" />
    <exclude body1="arm_right_R1_Link" body2="hand_right_rh_middle_distal" />
    <exclude body1="arm_right_R1_Link" body2="hand_right_rh_ring_proximal" />
    <exclude body1="arm_right_R1_Link" body2="hand_right_rh_ring_distal" />
    <exclude body1="arm_right_R1_Link" body2="hand_right_rh_pinky_proximal" />
    <exclude body1="arm_right_R1_Link" body2="hand_right_rh_pinky_distal" />
    <exclude body1="arm_right_R2_Link" body2="hand_right_rh_hand_base_link" />
    <exclude body1="arm_right_R2_Link" body2="hand_right_rh_thumb_metacarpals_base2" />
    <exclude body1="arm_right_R2_Link" body2="hand_right_rh_thumb_metacarpals" />
    <exclude body1="arm_right_R2_Link" body2="hand_right_rh_thumb_distal" />
    <exclude body1="arm_right_R2_Link" body2="hand_right_rh_index_proximal" />
    <exclude body1="arm_right_R2_Link" body2="hand_right_rh_index_distal" />
    <exclude body1="arm_right_R2_Link" body2="hand_right_rh_middle_proximal" />
    <exclude body1="arm_right_R2_Link" body2="hand_right_rh_middle_distal" />
    <exclude body1="arm_right_R2_Link" body2="hand_right_rh_ring_proximal" />
    <exclude body1="arm_right_R2_Link" body2="hand_right_rh_ring_distal" />
    <exclude body1="arm_right_R2_Link" body2="hand_right_rh_pinky_proximal" />
    <exclude body1="arm_right_R2_Link" body2="hand_right_rh_pinky_distal" />
    <exclude body1="arm_right_R3_Link" body2="hand_right_rh_hand_base_link" />
    <exclude body1="arm_right_R3_Link" body2="hand_right_rh_thumb_metacarpals_base2" />
    <exclude body1="arm_right_R3_Link" body2="hand_right_rh_thumb_metacarpals" />
    <exclude body1="arm_right_R3_Link" body2="hand_right_rh_thumb_distal" />
    <exclude body1="arm_right_R3_Link" body2="hand_right_rh_index_proximal" />
    <exclude body1="arm_right_R3_Link" body2="hand_right_rh_index_distal" />
    <exclude body1="arm_right_R3_Link" body2="hand_right_rh_middle_proximal" />
    <exclude body1="arm_right_R3_Link" body2="hand_right_rh_middle_distal" />
    <exclude body1="arm_right_R3_Link" body2="hand_right_rh_ring_proximal" />
    <exclude body1="arm_right_R3_Link" body2="hand_right_rh_ring_distal" />
    <exclude body1="arm_right_R3_Link" body2="hand_right_rh_pinky_proximal" />
    <exclude body1="arm_right_R3_Link" body2="hand_right_rh_pinky_distal" />
    <exclude body1="arm_right_R4_Link" body2="hand_right_rh_hand_base_link" />
    <exclude body1="arm_right_R4_Link" body2="hand_right_rh_thumb_metacarpals_base2" />
    <exclude body1="arm_right_R4_Link" body2="hand_right_rh_thumb_metacarpals" />
    <exclude body1="arm_right_R4_Link" body2="hand_right_rh_thumb_distal" />
    <exclude body1="arm_right_R4_Link" body2="hand_right_rh_index_proximal" />
    <exclude body1="arm_right_R4_Link" body2="hand_right_rh_index_distal" />
    <exclude body1="arm_right_R4_Link" body2="hand_right_rh_middle_proximal" />
    <exclude body1="arm_right_R4_Link" body2="hand_right_rh_middle_distal" />
    <exclude body1="arm_right_R4_Link" body2="hand_right_rh_ring_proximal" />
    <exclude body1="arm_right_R4_Link" body2="hand_right_rh_ring_distal" />
    <exclude body1="arm_right_R4_Link" body2="hand_right_rh_pinky_proximal" />
    <exclude body1="arm_right_R4_Link" body2="hand_right_rh_pinky_distal" />
    <exclude body1="arm_right_R5_Link" body2="hand_right_rh_hand_base_link" />
    <exclude body1="arm_right_R5_Link" body2="hand_right_rh_thumb_metacarpals_base2" />
    <exclude body1="arm_right_R5_Link" body2="hand_right_rh_thumb_metacarpals" />
    <exclude body1="arm_right_R5_Link" body2="hand_right_rh_thumb_distal" />
    <exclude body1="arm_right_R5_Link" body2="hand_right_rh_index_proximal" />
    <exclude body1="arm_right_R5_Link" body2="hand_right_rh_index_distal" />
    <exclude body1="arm_right_R5_Link" body2="hand_right_rh_middle_proximal" />
    <exclude body1="arm_right_R5_Link" body2="hand_right_rh_middle_distal" />
    <exclude body1="arm_right_R5_Link" body2="hand_right_rh_ring_proximal" />
    <exclude body1="arm_right_R5_Link" body2="hand_right_rh_ring_distal" />
    <exclude body1="arm_right_R5_Link" body2="hand_right_rh_pinky_proximal" />
    <exclude body1="arm_right_R5_Link" body2="hand_right_rh_pinky_distal" />
    <exclude body1="arm_right_R6_Link" body2="hand_right_rh_hand_base_link" />
    <exclude body1="arm_right_R6_Link" body2="hand_right_rh_thumb_metacarpals_base2" />
    <exclude body1="arm_right_R6_Link" body2="hand_right_rh_thumb_metacarpals" />
    <exclude body1="arm_right_R6_Link" body2="hand_right_rh_thumb_distal" />
    <exclude body1="arm_right_R6_Link" body2="hand_right_rh_index_proximal" />
    <exclude body1="arm_right_R6_Link" body2="hand_right_rh_index_distal" />
    <exclude body1="arm_right_R6_Link" body2="hand_right_rh_middle_proximal" />
    <exclude body1="arm_right_R6_Link" body2="hand_right_rh_middle_distal" />
    <exclude body1="arm_right_R6_Link" body2="hand_right_rh_ring_proximal" />
    <exclude body1="arm_right_R6_Link" body2="hand_right_rh_ring_distal" />
    <exclude body1="arm_right_R6_Link" body2="hand_right_rh_pinky_proximal" />
    <exclude body1="arm_right_R6_Link" body2="hand_right_rh_pinky_distal" />
    <exclude body1="arm_right_R7_Link" body2="hand_right_rh_hand_base_link" />
    <exclude body1="arm_right_R7_Link" body2="hand_right_rh_thumb_metacarpals_base2" />
    <exclude body1="arm_right_R7_Link" body2="hand_right_rh_thumb_metacarpals" />
    <exclude body1="arm_right_R7_Link" body2="hand_right_rh_thumb_distal" />
    <exclude body1="arm_right_R7_Link" body2="hand_right_rh_index_proximal" />
    <exclude body1="arm_right_R7_Link" body2="hand_right_rh_index_distal" />
    <exclude body1="arm_right_R7_Link" body2="hand_right_rh_middle_proximal" />
    <exclude body1="arm_right_R7_Link" body2="hand_right_rh_middle_distal" />
    <exclude body1="arm_right_R7_Link" body2="hand_right_rh_ring_proximal" />
    <exclude body1="arm_right_R7_Link" body2="hand_right_rh_ring_distal" />
    <exclude body1="arm_right_R7_Link" body2="hand_right_rh_pinky_proximal" />
    <exclude body1="arm_right_R7_Link" body2="hand_right_rh_pinky_distal" />
    <exclude body1="base_base_link" body2="hand_right_rh_hand_base_link" />
    <exclude body1="base_base_link" body2="hand_right_rh_thumb_metacarpals_base2" />
    <exclude body1="base_base_link" body2="hand_right_rh_thumb_metacarpals" />
    <exclude body1="base_base_link" body2="hand_right_rh_thumb_distal" />
    <exclude body1="base_base_link" body2="hand_right_rh_index_proximal" />
    <exclude body1="base_base_link" body2="hand_right_rh_index_distal" />
    <exclude body1="base_base_link" body2="hand_right_rh_middle_proximal" />
    <exclude body1="base_base_link" body2="hand_right_rh_middle_distal" />
    <exclude body1="base_base_link" body2="hand_right_rh_ring_proximal" />
    <exclude body1="base_base_link" body2="hand_right_rh_ring_distal" />
    <exclude body1="base_base_link" body2="hand_right_rh_pinky_proximal" />
    <exclude body1="base_base_link" body2="hand_right_rh_pinky_distal" />
  </contact>
</mujoco>
