<mujoco model="lkls73_arm_left">
  <compiler meshdir="meshes" discardvisual="false" autolimits="true" angle="radian" eulerseq="XYZ"/>
  <option/>

  <default>
    <default class="arm_lkls73_arm_visual">
      <geom type="mesh" contype="0" conaffinity="0" group="1"/>
    </default>
    <default class="arm_lkls73_arm_collision">
      <geom type="mesh" contype="1" conaffinity="1" group="3"/>
    </default>
  </default>

  <asset>
    <mesh name="L1" file="L1_Link.STL"/>
    <mesh name="L2" file="L2_Link.STL"/>
    <mesh name="L3" file="L3_Link.STL"/>
    <mesh name="L4" file="L4_Link.STL"/>
    <mesh name="L5" file="L5_Link.STL"/>
    <mesh name="L6" file="L6_Link.STL"/>
    <mesh name="L7" file="L7_Link.STL"/>
    <mesh name="L8" file="L8_Link.STL"/>
  </asset>

  <worldbody>
    <body name="L_arm_root" pos="0 0 0">
      <site name="base_mount" pos="0 0 0"/>

      <body name="L1_Link" pos="0 0 0">
        <inertial pos="0.00235600060651345 0.0538143182293528 0.00010452198160641"
                  mass="1.3997199601261"
                  fullinertia="0.00114445383866051 0.000654874787984474 0.000691494366096022 -2.33503672142218E-06 -9.94413789148138E-09 1.05907637546798E-06"/>
        <joint name="L1_Joint" type="hinge" axis="0 -1 0"
               range="-2.91 2.91" damping="4" frictionloss="0.0" armature="0.01"/>
        <geom class="arm_lkls73_arm_visual" mesh="L1"/>
        <geom class="arm_lkls73_arm_collision" mesh="L1"/>

        <body name="L2_Link" pos="0 0.058 0">
          <inertial pos="0.001618419731441 8.17586538826021E-06 -0.0795739675465699"
                    mass="1.14210487960353"
                    fullinertia="0.000999259952314694 0.000929597687983869 0.000490873838603504 4.38390447469883E-06 -1.34113970553355E-06 2.7922699166407E-07"/>
          <joint name="L2_Joint" type="hinge" axis="-1 0 0"
                 range="-3.2 0.07" damping="4" frictionloss="0.0" armature="0.01"/>
          <geom class="arm_lkls73_arm_visual" mesh="L2"/>
          <geom class="arm_lkls73_arm_collision" mesh="L2"/>

          <body name="L3_Link" pos="-2.5018E-05 0 -0.123">
            <inertial pos="0.000181280975708543 0.0012493056236523 -0.128548942292033"
                      mass="1.2798435287888"
                      fullinertia="0.00158095142201815 0.00163152743924312 0.000344148864762278 7.74063763820645E-07 -8.68119829913453E-07 -2.41539579836192E-06"/>
            <joint name="L3_Joint" type="hinge" axis="0 0 1"
                   range="-2.69 2.69" damping="4" frictionloss="0.0" armature="0.01"/>
            <geom class="arm_lkls73_arm_visual" mesh="L3"/>
            <geom class="arm_lkls73_arm_collision" mesh="L3"/>

            <body name="L4_Link" pos="2.4267E-05 0 -0.1621">
              <inertial pos="-3.38229166406629E-06 0.00077842370454409 -0.08460011635447"
                        mass="0.935504485205333"
                        fullinertia="0.000508246005403967 0.000524130562919452 0.000333983371716017 -4.123494432482E-06 -1.601236457745E-07 -3.45757221458974E-07"/>
              <joint name="L4_Joint" type="hinge" axis="0 -1 0"
                     range="-2.05 2.05" damping="4" frictionloss="0.0" armature="0.01"/>
              <geom class="arm_lkls73_arm_visual" mesh="L4"/>
              <geom class="arm_lkls73_arm_collision" mesh="L4"/>

              <body name="L5_Link" pos="0 0 -0.124">
                <inertial pos="-7.8967109106414E-05 0.00127705818106172 -0.0361222642165061"
                          mass="0.298012293033296"
                          fullinertia="0.000356324975203863 0.000385006059216245 0.000101746640600842 8.49346343481351E-07 -1.06208641170066E-06 2.16302454958746E-06"/>
                <joint name="L5_Joint" type="hinge" axis="0 0 1"
                       range="-2.69 2.69" damping="4" frictionloss="0.0" armature="0.01"/>
                <geom class="arm_lkls73_arm_visual" mesh="L5"/>
                <geom class="arm_lkls73_arm_collision" mesh="L5"/>

                <body name="L6_Link" pos="0 0 -0.0881">
                  <inertial pos="0.00423270788750624 -0.00438646585481159 -0.0324823655341541"
                            mass="0.344326210144814"
                            fullinertia="0.000194396852170226 0.000233882186601331 0.000101458599044909 1.34053122918212E-06 9.47054882668167E-06 2.86885239016126E-07"/>
                  <joint name="L6_Joint" type="hinge" axis="0 -1 0"
                         range="-1.59 1.59" damping="4" frictionloss="0.0" armature="0.01"/>
                  <geom class="arm_lkls73_arm_visual" mesh="L6"/>
                  <geom class="arm_lkls73_arm_collision" mesh="L6"/>

                  <body name="L7_Link" pos="-2.6563E-05 0 -0.0655">
                    <inertial pos="-0.00330667550396703 2.7195733834362E-07 -0.0202430179985484"
                              mass="0.143310943627726"
                              fullinertia="6.98168229201036E-05 5.48675476764208E-05 4.4020607930097E-05 2.70503363331007E-07 -3.17975733412514E-08 1.01362000675163E-12"/>
                    <joint name="L7_Joint" type="hinge" axis="-1 0 0"
                           range="-1.59 1.59" damping="4" frictionloss="0.0" armature="0.01"/>
                    <geom class="arm_lkls73_arm_visual" mesh="L7"/>
                    <geom class="arm_lkls73_arm_collision" mesh="L7"/>

                    <body name="L8_Link" pos="2.5732E-05 0 -0.0455">
                      <inertial pos="1.08546552465473E-10 -1.13853898531247E-09 0.000500000000024592"
                                mass="6.05149284897746E-05"
                                fullinertia="8.49604381443617E-09 8.49604381442905E-09 1.69820018074357E-08 8.31968496153617E-22 -7.81277944440306E-15 -9.03653480952828E-16"/>
                      <geom class="arm_lkls73_arm_visual" mesh="L8"/>
                      <geom class="arm_lkls73_arm_collision" mesh="L8"/>
                      <site name="tool0" pos="0 0 0"/>
                    </body>
                  </body>
                </body>
              </body>
            </body>
          </body>
        </body>
      </body>
    </body>
  </worldbody>

  <actuator>
    <position name="L1_Joint_act" joint="L1_Joint" kp="1000" kv="0" ctrlrange="-2.91 2.91"/>
    <position name="L2_Joint_act" joint="L2_Joint" kp="1000" kv="0" ctrlrange="-3.2 0.07"/>
    <position name="L3_Joint_act" joint="L3_Joint" kp="1000" kv="0" ctrlrange="-2.69 2.69"/>
    <position name="L4_Joint_act" joint="L4_Joint" kp="1000" kv="0" ctrlrange="-2.05 2.05"/>
    <position name="L5_Joint_act" joint="L5_Joint" kp="1000" kv="0" ctrlrange="-2.69 2.69"/>
    <position name="L6_Joint_act" joint="L6_Joint" kp="1000" kv="0" ctrlrange="-1.59 1.59"/>
    <position name="L7_Joint_act" joint="L7_Joint" kp="1000" kv="0" ctrlrange="-1.59 1.59"/>
  </actuator>

  <contact>
    <exclude body1="L1_Link" body2="L2_Link"/>
    <exclude body1="L2_Link" body2="L3_Link"/>
    <exclude body1="L3_Link" body2="L4_Link"/>
    <exclude body1="L4_Link" body2="L5_Link"/>
    <exclude body1="L5_Link" body2="L6_Link"/>
    <exclude body1="L6_Link" body2="L7_Link"/>
    <exclude body1="L7_Link" body2="L8_Link"/>
  </contact>
</mujoco>
