<mujoco model="linkerhand_o6_left">
  <compiler meshdir="meshes" discardvisual="false" autolimits="true" angle="radian" eulerseq="XYZ"/>
  <option/>

  <default>
    <default class="hand_linkerhand_o6_visual">
      <geom type="mesh" contype="0" conaffinity="0" group="1"/>
    </default>
    <default class="hand_linkerhand_o6_collision">
      <geom type="mesh" contype="1" conaffinity="1" group="3"/>
    </default>
    <default class="hand_linkerhand_o6_joint">
      <joint armature="3.4707e-08" damping="4.0" frictionloss="0.5"/>
    </default>
  </default>

  <asset>
    <mesh name="hand_base"               file="hand_base_link.STL"/>
    <mesh name="thumb_metacarpals_base2" file="thumb_metacarpals_base2.STL"/>
    <mesh name="thumb_metacarpals"       file="thumb_metacarpals.STL"/>
    <mesh name="thumb_distal"            file="thumb_distal.STL"/>
    <mesh name="index_proximal"          file="index_proximal.STL"/>
    <mesh name="index_distal"            file="index_distal.STL"/>
    <mesh name="middle_proximal"         file="middle_proximal.STL"/>
    <mesh name="middle_distal"           file="middle_distal.STL"/>
    <mesh name="ring_proximal"           file="ring_proximal.STL"/>
    <mesh name="ring_distal"             file="ring_distal.STL"/>
    <mesh name="pinky_proximal"          file="pinky_proximal.STL"/>
    <mesh name="pinky_distal"            file="pinky_distal.STL"/>
  </asset>

  <worldbody>
    <body name="lh_hand_base_link" pos="0 0 0">
      <inertial pos="-0.00157788568070457 -0.00034876725935859 0.0538452219801211" mass="0.0672935238166485"
                fullinertia="5.22525212160954E-05 3.33522349207724E-05 2.28469461105385E-05 3.06955729584715E-07 -3.90341166950521E-07 -7.76680063574627E-07"/>
      <geom class="hand_linkerhand_o6_visual" mesh="hand_base"/>
      <geom class="hand_linkerhand_o6_collision" mesh="hand_base"/>
      <site name="wrist_mount" pos="0 0 0"/>

      <body name="lh_thumb_metacarpals_base2" pos="0.011508 -0.022975 0.032794">
        <inertial pos="0.00162800681276937 -0.0027668017246415 -0.00184234438641236" mass="0.00138588296544333"
                  fullinertia="5.26292160685909E-08 4.82620491570326E-08 2.88550286112821E-08 -3.92888681640568E-09 -2.43767371295222E-09 3.71869784206147E-09"/>
        <joint name="lh_thumb_cmc_yaw" class="hand_linkerhand_o6_joint" type="hinge" axis="0 0 1" range="0 1.3"/>
        <geom class="hand_linkerhand_o6_visual" mesh="thumb_metacarpals_base2"/>
        <geom class="hand_linkerhand_o6_collision" mesh="thumb_metacarpals_base2"/>

        <body name="lh_thumb_metacarpals" pos="0.0061649 -0.010678 -0.004891" euler="0 -1.1529 2.0944">
          <inertial pos="4.24816204999817E-05 1.74183907812875E-05 0.0228341640631254" mass="0.0123381586619931"
                    fullinertia="1.10292537368909E-06 1.76757772551884E-06 9.36347792411098E-07 -5.99642232777877E-10 -1.14233573940545E-07 -4.03963570823777E-10"/>
          <joint name="lh_thumb_cmc_pitch" class="hand_linkerhand_o6_joint" type="hinge" axis="0 1 0" range="0 0.58"/>
          <geom class="hand_linkerhand_o6_visual" mesh="thumb_metacarpals"/>
          <geom class="hand_linkerhand_o6_collision" mesh="thumb_metacarpals"/>

          <body name="lh_thumb_distal" pos="0.0037776 0 0.045368">
            <inertial pos="-0.00413725702921841 -5.90704520436747E-08 0.023011401589736" mass="0.00763332957284057"
                      fullinertia="1.3057487813702E-06 1.2248908905341E-06 2.77271910592615E-07 -1.19781508112714E-11 -7.19551697268541E-08 4.55347974652679E-12"/>
            <joint name="lh_thumb_ip" class="hand_linkerhand_o6_joint" type="hinge" axis="0 1 0" range="0 1.08"/>
            <geom class="hand_linkerhand_o6_visual" mesh="thumb_distal"/>
            <geom class="hand_linkerhand_o6_collision" mesh="thumb_distal"/>
          </body>
        </body>
      </body>

      <body name="lh_index_proximal" pos="0.0024758 -0.02419 0.098779" euler="0.05236 0 0">
        <inertial pos="-0.00208656556336452 2.53838713251686E-06 0.0172734941980264" mass="0.00253174651934627"
                  fullinertia="2.65988714157799E-07 2.72914069166233E-07 8.56017305636748E-08 -1.67174578825824E-11 -4.31047725546034E-08 1.8756709532167E-10"/>
        <joint name="lh_index_mcp_pitch" class="hand_linkerhand_o6_joint" type="hinge" axis="0 1 0" range="0 1.60"/>
        <geom class="hand_linkerhand_o6_visual" mesh="index_proximal"/>
        <geom class="hand_linkerhand_o6_collision" mesh="index_proximal"/>

        <body name="lh_index_distal" pos="-0.0052516 0 0.036625">
          <inertial pos="0.00658986616416549 5.13855642059191E-06 0.0194393600039178" mass="0.00376951085886838"
                    fullinertia="3.22347106085043E-07 3.65328133721509E-07 1.24287996386442E-07 1.3801788663582E-11 1.14352857317951E-07 -2.11505011705634E-10"/>
          <joint name="lh_index_dip" class="hand_linkerhand_o6_joint" type="hinge" axis="0 1 0" range="0 1.43"/>
          <geom class="hand_linkerhand_o6_visual" mesh="index_distal"/>
          <geom class="hand_linkerhand_o6_collision" mesh="index_distal"/>
        </body>
      </body>

      <body name="lh_middle_proximal" pos="0.00052576 -0.00634 0.1027">
        <inertial pos="-0.00208660654138235 2.56918180119303E-06 0.0172735011723351" mass="0.00253177375206983"
                  fullinertia="2.65989021304483E-07 2.72914402745606E-07 8.5602213431865E-08 -1.69816046635662E-11 -4.31046683215273E-08 1.87484652324395E-10"/>
        <joint name="lh_middle_mcp_pitch" class="hand_linkerhand_o6_joint" type="hinge" axis="0 1 0" range="0 1.60"/>
        <geom class="hand_linkerhand_o6_visual" mesh="middle_proximal"/>
        <geom class="hand_linkerhand_o6_collision" mesh="middle_proximal"/>

        <body name="lh_middle_distal" pos="-0.0052516 0 0.036625">
          <inertial pos="0.00658986516319194 5.10862924271716E-06 0.0194393315699782" mass="0.00376952789210256"
                    fullinertia="3.22348591068053E-07 3.65329535087755E-07 1.24288425862546E-07 1.37122394856588E-11 1.1435291391668E-07 -2.10453810291991E-10"/>
          <joint name="lh_middle_dip" class="hand_linkerhand_o6_joint" type="hinge" axis="0 1 0" range="0 1.43"/>
          <geom class="hand_linkerhand_o6_visual" mesh="middle_distal"/>
          <geom class="hand_linkerhand_o6_collision" mesh="middle_distal"/>
        </body>
      </body>

      <body name="lh_ring_proximal" pos="0.0010258 0.011135 0.098767" euler="-0.05236 0 0">
        <inertial pos="-0.00208667931345812 2.63000419462034E-06 0.0172734926448377" mass="0.00253182223645066"
                  fullinertia="2.65989756076584E-07 2.7291510093393E-07 8.56031522765909E-08 -1.74912952703656E-11 -4.31043325594253E-08 1.87158326740895E-10"/>
        <joint name="lh_ring_mcp_pitch" class="hand_linkerhand_o6_joint" type="hinge" axis="0 1 0" range="0 1.60"/>
        <geom class="hand_linkerhand_o6_visual" mesh="ring_proximal"/>
        <geom class="hand_linkerhand_o6_collision" mesh="ring_proximal"/>

        <body name="lh_ring_distal" pos="-0.0052516 0 0.036625">
          <inertial pos="0.00658986648895491 5.05883528165163E-06 0.019439397215532" mass="0.00376949588316609"
                    fullinertia="3.2234524157181E-07 3.65326570102147E-07 1.24287770218135E-07 1.35766976056011E-11 1.14353011012842E-07 -2.08672149138738E-10"/>
          <joint name="lh_ring_dip" class="hand_linkerhand_o6_joint" type="hinge" axis="0 1 0" range="0 1.43"/>
          <geom class="hand_linkerhand_o6_visual" mesh="ring_distal"/>
          <geom class="hand_linkerhand_o6_collision" mesh="ring_distal"/>
        </body>
      </body>

      <body name="lh_pinky_proximal" pos="0.0024758 0.028372 0.092741" euler="-0.087266 0 0">
        <inertial pos="-0.00208673599799501 2.68062251165824E-06 0.0172734848131236" mass="0.00253185993162408"
                  fullinertia="2.6599033687183E-07 2.72915617381577E-07 8.56039175034871E-08 -1.79030790016555E-11 -4.31040829565781E-08 1.86906787420486E-10"/>
        <joint name="lh_pinky_mcp_pitch" class="hand_linkerhand_o6_joint" type="hinge" axis="0 1 0" range="0 1.60"/>
        <geom class="hand_linkerhand_o6_visual" mesh="pinky_proximal"/>
        <geom class="hand_linkerhand_o6_collision" mesh="pinky_proximal"/>

        <body name="lh_pinky_distal" pos="-0.0052516 0 0.036625">
          <inertial pos="0.00658987588903027 5.03087534178825E-06 0.0194394491065091" mass="0.00376948071276134"
                    fullinertia="3.22343583730488E-07 3.65325180884183E-07 1.24287567374229E-07 1.35768173270357E-11 1.14353289593012E-07 -2.0744198062439E-10"/>
          <joint name="lh_pinky_dip" class="hand_linkerhand_o6_joint" type="hinge" axis="0 1 0" range="0 1.43"/>
          <geom class="hand_linkerhand_o6_visual" mesh="pinky_distal"/>
          <geom class="hand_linkerhand_o6_collision" mesh="pinky_distal"/>
        </body>
      </body>
    </body>
  </worldbody>

  <actuator>
    <position name="lh_thumb_cmc_yaw_act"    joint="lh_thumb_cmc_yaw"    kp="200" kv="0" ctrlrange="0 1.3"/>
    <position name="lh_thumb_cmc_pitch_act"  joint="lh_thumb_cmc_pitch"  kp="200" kv="0" ctrlrange="0 0.58"/>
    <position name="lh_index_mcp_pitch_act"  joint="lh_index_mcp_pitch"  kp="200" kv="0" ctrlrange="0 1.60"/>
    <position name="lh_middle_mcp_pitch_act" joint="lh_middle_mcp_pitch" kp="200" kv="0" ctrlrange="0 1.60"/>
    <position name="lh_ring_mcp_pitch_act"   joint="lh_ring_mcp_pitch"   kp="200" kv="0" ctrlrange="0 1.60"/>
    <position name="lh_pinky_mcp_pitch_act"  joint="lh_pinky_mcp_pitch"  kp="200" kv="0" ctrlrange="0 1.60"/>
  </actuator>

  <equality>
    <joint name="lh_couple_thumb"  joint1="lh_thumb_ip"     joint2="lh_thumb_cmc_pitch"  polycoef="0 2.29 0 0 0"/>
    <joint name="lh_couple_index"  joint1="lh_index_dip"    joint2="lh_index_mcp_pitch"  polycoef="0 0.89 0 0 0"/>
    <joint name="lh_couple_middle" joint1="lh_middle_dip"   joint2="lh_middle_mcp_pitch" polycoef="0 0.89 0 0 0"/>
    <joint name="lh_couple_ring"   joint1="lh_ring_dip"     joint2="lh_ring_mcp_pitch"   polycoef="0 0.89 0 0 0"/>
    <joint name="lh_couple_pinky"  joint1="lh_pinky_dip"    joint2="lh_pinky_mcp_pitch"  polycoef="0 0.89 0 0 0"/>
  </equality>

  <contact>
    <exclude body1="lh_hand_base_link"          body2="lh_thumb_metacarpals_base2"/>
    <exclude body1="lh_thumb_metacarpals_base2" body2="lh_thumb_metacarpals"/>
    <exclude body1="lh_thumb_metacarpals"       body2="lh_thumb_distal"/>
    <exclude body1="lh_hand_base_link"          body2="lh_index_proximal"/>
    <exclude body1="lh_index_proximal"          body2="lh_index_distal"/>
    <exclude body1="lh_hand_base_link"          body2="lh_middle_proximal"/>
    <exclude body1="lh_middle_proximal"         body2="lh_middle_distal"/>
    <exclude body1="lh_hand_base_link"          body2="lh_ring_proximal"/>
    <exclude body1="lh_ring_proximal"           body2="lh_ring_distal"/>
    <exclude body1="lh_hand_base_link"          body2="lh_pinky_proximal"/>
    <exclude body1="lh_pinky_proximal"          body2="lh_pinky_distal"/>
  </contact>
</mujoco>
