<?xml version="1.0" encoding="UTF-8"?>
<!-- Generated by tools/composer (version 0.1.0). Workstation: ar5_l6_bench. Recipe sha256: 4dc7320c419d25dc5447ccf7a90a9312135480fe1834b17d3c4b9f6a0c2fd7fa. Do not edit by hand; re-run `python -m tools.composer.compose <workstation>`. -->
<mujoco model="ar5_l6_bench">
  <compiler discardvisual="false" autolimits="true" angle="radian" eulerseq="XYZ" />
  <option />
  <default>
    <default class="base_base_bench_table_visual">
      <geom type="mesh" contype="0" conaffinity="0" group="1" />
    </default>
    <default class="base_base_bench_table_collision">
      <geom type="mesh" contype="1" conaffinity="1" group="3" />
    </default>
    <default class="arm_arm_ar5_visual">
      <geom type="mesh" contype="0" conaffinity="0" group="1" />
    </default>
    <default class="arm_arm_ar5_collision">
      <geom type="mesh" contype="1" conaffinity="1" group="3" />
    </default>
    <default class="hand_hand_linkerhand_l6_visual">
      <geom type="mesh" contype="0" conaffinity="0" group="1" />
    </default>
    <default class="hand_hand_linkerhand_l6_collision">
      <geom type="mesh" contype="1" conaffinity="1" group="3" />
    </default>
    <default class="hand_hand_linkerhand_l6_joint">
      <joint armature="3.4707e-08" damping="5.0" frictionloss="0.5" />
    </default>
  </default>
  <asset>
    <mesh name="base_workstation" file="../../components/bases/bench_table/variants/default/meshes/workstation.STL" />
    <mesh name="base_camera_base_link" file="../../components/bases/bench_table/variants/default/meshes/camera_base_link.STL" />
    <mesh name="base_camera" file="../../components/bases/bench_table/variants/default/meshes/camera.STL" />
    <mesh name="arm_ar5_base" file="../../components/arms/ar5/variants/left/meshes/AR5_5_07L_W4C4A2_base.stl" scale="0.001 0.001 0.001" />
    <mesh name="arm_ar5_link1" file="../../components/arms/ar5/variants/left/meshes/AR5_5_07L_W4C4A2_link1.stl" scale="0.001 0.001 0.001" />
    <mesh name="arm_ar5_link2" file="../../components/arms/ar5/variants/left/meshes/AR5_5_07L_W4C4A2_link2.stl" scale="0.001 0.001 0.001" />
    <mesh name="arm_ar5_link3" file="../../components/arms/ar5/variants/left/meshes/AR5_5_07L_W4C4A2_link3.stl" scale="0.001 0.001 0.001" />
    <mesh name="arm_ar5_link4" file="../../components/arms/ar5/variants/left/meshes/AR5_5_07L_W4C4A2_link4.stl" scale="0.001 0.001 0.001" />
    <mesh name="arm_ar5_link5" file="../../components/arms/ar5/variants/left/meshes/AR5_5_07L_W4C4A2_link5.stl" scale="0.001 0.001 0.001" />
    <mesh name="arm_ar5_link6" file="../../components/arms/ar5/variants/left/meshes/AR5_5_07L_W4C4A2_link6.stl" scale="0.001 0.001 0.001" />
    <mesh name="arm_ar5_link7" file="../../components/arms/ar5/variants/left/meshes/AR5_5_07L_W4C4A2_link7.stl" scale="0.001 0.001 0.001" />
    <mesh name="hand_hand_base" file="../../components/hands/linkerhand_l6/variants/left/meshes/hand_base_link.STL" />
    <mesh name="hand_thumb_metacarpals_base1" file="../../components/hands/linkerhand_l6/variants/left/meshes/thumb_metacarpals_base1.STL" />
    <mesh name="hand_thumb_metacarpals" file="../../components/hands/linkerhand_l6/variants/left/meshes/thumb_metacarpals.STL" />
    <mesh name="hand_thumb_distal" file="../../components/hands/linkerhand_l6/variants/left/meshes/thumb_distal.STL" />
    <mesh name="hand_index_proximal" file="../../components/hands/linkerhand_l6/variants/left/meshes/index_proximal.STL" />
    <mesh name="hand_index_distal" file="../../components/hands/linkerhand_l6/variants/left/meshes/index_distal.STL" />
    <mesh name="hand_middle_proximal" file="../../components/hands/linkerhand_l6/variants/left/meshes/middle_proximal.STL" />
    <mesh name="hand_middle_distal" file="../../components/hands/linkerhand_l6/variants/left/meshes/middle_distal.STL" />
    <mesh name="hand_ring_proximal" file="../../components/hands/linkerhand_l6/variants/left/meshes/ring_proximal.STL" />
    <mesh name="hand_ring_distal" file="../../components/hands/linkerhand_l6/variants/left/meshes/ring_distal.STL" />
    <mesh name="hand_pinky_proximal" file="../../components/hands/linkerhand_l6/variants/left/meshes/pinky_proximal.STL" />
    <mesh name="hand_pinky_distal" file="../../components/hands/linkerhand_l6/variants/left/meshes/pinky_distal.STL" />
  </asset>
  <worldbody>
    <body name="base_workstation_link" pos="0 0 0">
      <inertial pos="0 0 0" mass="50.0" fullinertia="1.0 1.0 1.0 0 0 0" />
      <geom class="base_base_bench_table_visual" mesh="base_workstation" />
      <geom class="base_base_bench_table_collision" mesh="base_workstation" />
      <body name="base_camera_base_link" pos="0.0335 0.67 1.2974" euler="-1.5708 0 -1.5708">
        <inertial pos="0.0538773695271655 0.0404431717089871 0.0338436903808578" mass="0.120253078965696" fullinertia="0.00024086634809874 0.000340317013404989 0.000187914824387855 1.11484097335586e-05 3.07915341770146e-05 -5.88336477049719e-05" />
        <geom class="base_base_bench_table_visual" mesh="base_camera_base_link" />
        <geom class="base_base_bench_table_collision" mesh="base_camera_base_link" />
        <site name="base_camera_mount" pos="0 0 0" />
        <body name="base_camera" pos="0.0801999999999972 0.193139853702623 -0.275851476149329" euler="-1.26599037580869 -0.643554017997773 -1.5707963267949">
          <inertial pos="0.435583906706681 -0.114517909806556 -0.00087379797028906" mass="0.170230158191785" fullinertia="0.000388607098441677 0.000353185511381015 6.42979907249093e-05 -3.21389374232659e-06 1.01075980515721e-06 -0.000100865226288639" />
          <geom class="base_base_bench_table_visual" mesh="base_camera" />
          <geom class="base_base_bench_table_collision" mesh="base_camera" />
        </body>
      </body>
      <body name="base_workstation_arm_left_mount" pos="0.0637 0.719 1.267" euler="0 1.57079633 1.57079633">
        <site name="base_arm_left_mount" pos="0 0 0" />
        <body name="arm_AR5_5_07L_W4C4A2_base" pos="0 0 0">
          <geom class="arm_arm_ar5_visual" mesh="arm_ar5_base" />
          <geom class="arm_arm_ar5_collision" mesh="arm_ar5_base" />
          <site name="arm_base_mount" pos="0 0 0" />
          <body name="arm_AR5_5_07L_W4C4A2_link1" pos="0 0 0">
            <inertial pos="1e-06 -0.000621 0.167909" mass="2.683" fullinertia="0.00493673 0.00452344 0.00432910 0.00000160 0.00000198 -0.00000020" />
            <joint name="arm_AR5_5_07L_W4C4A2_joint_1" type="hinge" axis="0 0 1" range="-3.1067 3.1067" damping="14.22378" frictionloss="0.0" armature="0.01" />
            <geom class="arm_arm_ar5_visual" mesh="arm_ar5_link1" />
            <geom class="arm_arm_ar5_collision" mesh="arm_ar5_link1" />
            <body name="arm_AR5_5_07L_W4C4A2_link2" pos="0 0 0.1745">
              <inertial pos="-2e-05 -0.003081 0.10298600000000001" mass="2.3" fullinertia="0.01151906 0.00993335 0.00435237 0.00000246 -0.00000055 0.00082477" />
              <joint name="arm_AR5_5_07L_W4C4A2_joint_2" type="hinge" axis="0 1 0" range="-2.0944 2.0944" damping="13.710972" frictionloss="0.0" armature="0.01" />
              <geom class="arm_arm_ar5_visual" mesh="arm_ar5_link2" />
              <geom class="arm_arm_ar5_collision" mesh="arm_ar5_link2" />
              <body name="arm_AR5_5_07L_W4C4A2_link3" pos="0 0 0.314">
                <inertial pos="0.007097 -0.0006590000000000001 -0.016530999999999997" mass="1.862" fullinertia="0.00519681 0.00470446 0.00266752 0.00001208 0.00035761 0.00003430" />
                <joint name="arm_AR5_5_07L_W4C4A2_joint_3" type="hinge" axis="0 0 1" range="-3.1067 3.1067" damping="3.791042" frictionloss="0.0" armature="0.01" />
                <geom class="arm_arm_ar5_visual" mesh="arm_ar5_link3" />
                <geom class="arm_arm_ar5_collision" mesh="arm_ar5_link3" />
                <body name="arm_AR5_5_07L_W4C4A2_link4" pos="0.01 0 0">
                  <inertial pos="-0.007826 -0.004207 0.073404" mass="1.234" fullinertia="0.00389590 0.00308657 0.00188364 -0.00004577 -0.00017280 0.00046679" />
                  <joint name="arm_AR5_5_07L_W4C4A2_joint_4" type="hinge" axis="0 1 0" range="-1.0472 2.5307" damping="0.333154" frictionloss="0.0" armature="0.01" />
                  <geom class="arm_arm_ar5_visual" mesh="arm_ar5_link4" />
                  <geom class="arm_arm_ar5_collision" mesh="arm_ar5_link4" />
                  <body name="arm_AR5_5_07L_W4C4A2_link5" pos="-0.01 0 0.272">
                    <inertial pos="0.00028399999999999996 0.0016510000000000001 -0.084133" mass="1.329" fullinertia="0.00281562 0.00221084 0.00182169 0.00001782 0.00001650 0.00002100" />
                    <joint name="arm_AR5_5_07L_W4C4A2_joint_5" type="hinge" axis="0 0 1" range="-3.1067 3.1067" damping="4.136716" frictionloss="0.0" armature="0.01" />
                    <geom class="arm_arm_ar5_visual" mesh="arm_ar5_link5" />
                    <geom class="arm_arm_ar5_collision" mesh="arm_ar5_link5" />
                    <body name="arm_AR5_5_07L_W4C4A2_link6" pos="0 0 0">
                      <inertial pos="0.005405999999999999 0.000612 -3.9e-05" mass="0.93" fullinertia="0.00072078 0.00085153 0.00090205 -0.00000217 0.00000108 0.00000048" />
                      <joint name="arm_AR5_5_07L_W4C4A2_joint_6" type="hinge" axis="0 1 0" range="-1.0472 1.0472" damping="4.748679" frictionloss="0.0" armature="0.01" />
                      <geom class="arm_arm_ar5_visual" mesh="arm_ar5_link6" />
                      <geom class="arm_arm_ar5_collision" mesh="arm_ar5_link6" />
                      <body name="arm_AR5_5_07L_W4C4A2_link7" pos="0 0 0">
                        <inertial pos="-0.00277 0.000316 0.054881" mass="0.33" fullinertia="0.00051942 0.00079132 0.00045886 -0.00000052 0.00003721 0.00000265" />
                        <joint name="arm_AR5_5_07L_W4C4A2_joint_7" type="hinge" axis="1 0 0" range="-1.0472 1.0472" damping="3.667978" frictionloss="0.0" armature="0.01" />
                        <geom class="arm_arm_ar5_visual" mesh="arm_ar5_link7" />
                        <geom class="arm_arm_ar5_collision" mesh="arm_ar5_link7" />
                        <body name="arm_AR5_5_07L_W4C4A2_tcp" pos="0 0 0.097">
                          <site name="arm_tool0" pos="0 0 0" />
                          <body name="hand_lh_hand_base_link" pos="0 0 0.03" euler="0 0 1.5708">
                            <inertial pos="0.00199 -0.00091 0.058381" mass="0.4185" fullinertia="0.0004998 0.0003567 0.0002301 0.000012853 -0.000008317 0.000010354" />
                            <geom class="hand_hand_linkerhand_l6_visual" mesh="hand_hand_base" />
                            <geom class="hand_hand_linkerhand_l6_collision" mesh="hand_hand_base" />
                            <site name="hand_wrist_mount" pos="0 0 0" />
                            <body name="hand_lh_thumb_metacarpals_base1" pos="0.0078133 -0.029898 0.026692" euler="-0.034907 0 0">
                              <inertial pos="0.0018663 -0.0066406 0.001533" mass="0.01" fullinertia="3.3724E-07 2.9457E-07 4.903E-07 1.11E-07 -3.6039E-08 5.7181E-08" />
                              <joint name="hand_lh_thumb_cmc_roll" class="hand_hand_linkerhand_l6_joint" type="hinge" axis="0 0 1" range="-0.087266 1.256637" />
                              <geom class="hand_hand_linkerhand_l6_visual" mesh="hand_thumb_metacarpals_base1" />
                              <geom class="hand_hand_linkerhand_l6_collision" mesh="hand_thumb_metacarpals_base1" />
                              <body name="hand_lh_thumb_metacarpals" pos="0.0057298 -0.01332 0.0027456" euler="1.1083 0 0.40143">
                                <inertial pos="0.00769270907060086 0.0859662184722988 0.0235283086675235" mass="0.065" fullinertia="8.407E-06 8.3899E-06 2.0091E-06 -1.1338E-09 1.1136E-08 3.1171E-07" />
                                <joint name="hand_lh_thumb_cmc_pitch" class="hand_hand_linkerhand_l6_joint" type="hinge" axis="-1 0 0" range="0 0.837758" />
                                <geom class="hand_hand_linkerhand_l6_visual" mesh="hand_thumb_metacarpals" />
                                <geom class="hand_hand_linkerhand_l6_collision" mesh="hand_thumb_metacarpals" />
                                <body name="hand_lh_thumb_distal" pos="0 0.0061 0.0827">
                                  <inertial pos="0.00769270907081708 0.0798662184721594 -0.0591716913325555" mass="0.018" fullinertia="1.5546E-06 1.7108E-06 9.1709E-07 2.4423E-09 2.8147E-09 -7.2756E-08" />
                                  <joint name="hand_lh_thumb_dip" class="hand_hand_linkerhand_l6_joint" type="hinge" axis="-1 0 0" range="0 0.963287" />
                                  <geom class="hand_hand_linkerhand_l6_visual" mesh="hand_thumb_distal" />
                                  <geom class="hand_hand_linkerhand_l6_collision" mesh="hand_thumb_distal" />
                                  <body name="hand_lh_thumb_tip" pos="0 0.0035 0.026" euler="0 0 1.5708">
                                    <inertial pos="0 0 0" mass="1e-06" fullinertia="1e-09 1e-09 1e-09 0 0 0" />
                                  </body>
                                </body>
                              </body>
                            </body>
                            <body name="hand_lh_index_proximal" pos="-0.00066821 -0.028967 0.11722">
                              <inertial pos="0.001776 -0.00011 0.012556" mass="0.008553" fullinertia="0.000000797543 0.000000800499 0.000000357001 -0.000000001275 0.000000138601 0.000000000939" />
                              <joint name="hand_lh_index_mcp_pitch" class="hand_hand_linkerhand_l6_joint" type="hinge" axis="0 1 0" range="0 1.134464" />
                              <geom class="hand_hand_linkerhand_l6_visual" mesh="hand_index_proximal" />
                              <geom class="hand_hand_linkerhand_l6_collision" mesh="hand_index_proximal" />
                              <body name="hand_lh_index_distal" pos="0.00093749 0 0.028002">
                                <inertial pos="0.0134 0.002262 0.016992" mass="0.018408" fullinertia="0.000002488712 0.000003723754 0.000001813582 0.000000008249 -0.000001523059 0.000000014019" />
                                <joint name="hand_lh_index_dip" class="hand_hand_linkerhand_l6_joint" type="hinge" axis="0 1 0" range="0 1.277039" />
                                <geom class="hand_hand_linkerhand_l6_visual" mesh="hand_index_distal" />
                                <geom class="hand_hand_linkerhand_l6_collision" mesh="hand_index_distal" />
                                <body name="hand_lh_index_tip" pos="0.0341 0 0.034">
                                  <inertial pos="0 0 0" mass="1e-06" fullinertia="1e-09 1e-09 1e-09 0 0 0" />
                                </body>
                              </body>
                            </body>
                            <body name="hand_lh_middle_proximal" pos="-0.00066821 -0.0089013 0.12322">
                              <inertial pos="0.001776 -0.00011 0.012556" mass="0.008553" fullinertia="0.000000797543 0.000000800499 0.000000357001 -0.000000001275 0.000000138601 0.000000000939" />
                              <joint name="hand_lh_middle_mcp_pitch" class="hand_hand_linkerhand_l6_joint" type="hinge" axis="0 1 0" range="0 1.134464" />
                              <geom class="hand_hand_linkerhand_l6_visual" mesh="hand_middle_proximal" />
                              <geom class="hand_hand_linkerhand_l6_collision" mesh="hand_middle_proximal" />
                              <body name="hand_lh_middle_distal" pos="0.00093749 0 0.028002">
                                <inertial pos="0.0134 0.002262 0.016992" mass="0.018408" fullinertia="0.000002488712 0.000003723754 0.000001813582 0.000000008249 -0.000001523059 0.000000014019" />
                                <joint name="hand_lh_middle_dip" class="hand_hand_linkerhand_l6_joint" type="hinge" axis="0 1 0" range="0 1.277039" />
                                <geom class="hand_hand_linkerhand_l6_visual" mesh="hand_middle_distal" />
                                <geom class="hand_hand_linkerhand_l6_collision" mesh="hand_middle_distal" />
                                <body name="hand_lh_middle_tip" pos="0.0341 0 0.034">
                                  <inertial pos="0 0 0" mass="1e-06" fullinertia="1e-09 1e-09 1e-09 0 0 0" />
                                </body>
                              </body>
                            </body>
                            <body name="hand_lh_ring_proximal" pos="-0.00067368 0.010717 0.11822">
                              <inertial pos="0.001776 -0.00011 0.012556" mass="0.008553" fullinertia="0.000000797543 0.000000800499 0.000000357001 -0.000000001275 0.000000138601 0.000000000939" />
                              <joint name="hand_lh_ring_mcp_pitch" class="hand_hand_linkerhand_l6_joint" type="hinge" axis="0 1 0" range="0 1.134464" />
                              <geom class="hand_hand_linkerhand_l6_visual" mesh="hand_ring_proximal" />
                              <geom class="hand_hand_linkerhand_l6_collision" mesh="hand_ring_proximal" />
                              <body name="hand_lh_ring_distal" pos="0.00093749 0 0.028002">
                                <inertial pos="0.0134 0.002262 0.016992" mass="0.018408" fullinertia="0.000002488712 0.000003723754 0.000001813582 0.000000008249 -0.000001523059 0.000000014019" />
                                <joint name="hand_lh_ring_dip" class="hand_hand_linkerhand_l6_joint" type="hinge" axis="0 1 0" range="0 1.277039" />
                                <geom class="hand_hand_linkerhand_l6_visual" mesh="hand_ring_distal" />
                                <geom class="hand_hand_linkerhand_l6_collision" mesh="hand_ring_distal" />
                                <body name="hand_lh_ring_tip" pos="0.0341 0 0.034">
                                  <inertial pos="0 0 0" mass="1e-06" fullinertia="1e-09 1e-09 1e-09 0 0 0" />
                                </body>
                              </body>
                            </body>
                            <body name="hand_lh_pinky_proximal" pos="-0.00067852 0.029814 0.11424">
                              <inertial pos="0.001776 -0.00011 0.012556" mass="0.008553" fullinertia="0.000000797543 0.000000800499 0.000000357001 -0.000000001275 0.000000138601 0.000000000939" />
                              <joint name="hand_lh_pinky_mcp_pitch" class="hand_hand_linkerhand_l6_joint" type="hinge" axis="0 1 0" range="0 1.134464" />
                              <geom class="hand_hand_linkerhand_l6_visual" mesh="hand_pinky_proximal" />
                              <geom class="hand_hand_linkerhand_l6_collision" mesh="hand_pinky_proximal" />
                              <body name="hand_lh_pinky_distal" pos="0.00093749 0 0.028002">
                                <inertial pos="0.0134 0.002262 0.016992" mass="0.018408" fullinertia="0.000002488712 0.000003723754 0.000001813582 0.000000008249 -0.000001523059 0.000000014019" />
                                <joint name="hand_lh_pinky_dip" class="hand_hand_linkerhand_l6_joint" type="hinge" axis="0 1 0" range="0 1.277039" />
                                <geom class="hand_hand_linkerhand_l6_visual" mesh="hand_pinky_distal" />
                                <geom class="hand_hand_linkerhand_l6_collision" mesh="hand_pinky_distal" />
                                <body name="hand_lh_pinky_tip" pos="0.0341 0 0.034">
                                  <inertial pos="0 0 0" mass="1e-06" fullinertia="1e-09 1e-09 1e-09 0 0 0" />
                                </body>
                              </body>
                            </body>
                          </body>
                        </body>
                      </body>
                    </body>
                  </body>
                </body>
              </body>
            </body>
          </body>
        </body>
      </body>
      <body name="base_workstation_arm_right_mount" pos="0.0637 0.536 1.267" euler="0 1.57079633 -1.57079633">
        <site name="base_arm_right_mount" pos="0 0 0" />
      </body>
    </body>
  </worldbody>
  <actuator>
    <position name="arm_AR5_5_07L_W4C4A2_joint_1_act" joint="arm_AR5_5_07L_W4C4A2_joint_1" kp="1000" kv="4" ctrlrange="-3.1067 3.1067" />
    <position name="arm_AR5_5_07L_W4C4A2_joint_2_act" joint="arm_AR5_5_07L_W4C4A2_joint_2" kp="1000" kv="4" ctrlrange="-2.0944 2.0944" />
    <position name="arm_AR5_5_07L_W4C4A2_joint_3_act" joint="arm_AR5_5_07L_W4C4A2_joint_3" kp="1000" kv="4" ctrlrange="-3.1067 3.1067" />
    <position name="arm_AR5_5_07L_W4C4A2_joint_4_act" joint="arm_AR5_5_07L_W4C4A2_joint_4" kp="1000" kv="4" ctrlrange="-1.0472 2.5307" />
    <position name="arm_AR5_5_07L_W4C4A2_joint_5_act" joint="arm_AR5_5_07L_W4C4A2_joint_5" kp="1000" kv="4" ctrlrange="-3.1067 3.1067" />
    <position name="arm_AR5_5_07L_W4C4A2_joint_6_act" joint="arm_AR5_5_07L_W4C4A2_joint_6" kp="1000" kv="4" ctrlrange="-1.0472 1.0472" />
    <position name="arm_AR5_5_07L_W4C4A2_joint_7_act" joint="arm_AR5_5_07L_W4C4A2_joint_7" kp="1000" kv="4" ctrlrange="-1.0472 1.0472" />
    <position name="hand_lh_thumb_cmc_roll_act" joint="hand_lh_thumb_cmc_roll" kp="20" kv="2" ctrlrange="-0.087266 1.256637" />
    <position name="hand_lh_thumb_cmc_pitch_act" joint="hand_lh_thumb_cmc_pitch" kp="20" kv="2" ctrlrange="0 0.837758" />
    <position name="hand_lh_index_mcp_pitch_act" joint="hand_lh_index_mcp_pitch" kp="20" kv="2" ctrlrange="0 1.134464" />
    <position name="hand_lh_middle_mcp_pitch_act" joint="hand_lh_middle_mcp_pitch" kp="20" kv="2" ctrlrange="0 1.134464" />
    <position name="hand_lh_ring_mcp_pitch_act" joint="hand_lh_ring_mcp_pitch" kp="20" kv="2" ctrlrange="0 1.134464" />
    <position name="hand_lh_pinky_mcp_pitch_act" joint="hand_lh_pinky_mcp_pitch" kp="20" kv="2" ctrlrange="0 1.134464" />
  </actuator>
  <equality>
    <joint name="hand_lh_couple_index" joint1="hand_lh_index_dip" joint2="hand_lh_index_mcp_pitch" polycoef="0 1.125676 0 0 0" />
    <joint name="hand_lh_couple_middle" joint1="hand_lh_middle_dip" joint2="hand_lh_middle_mcp_pitch" polycoef="0 1.125676 0 0 0" />
    <joint name="hand_lh_couple_ring" joint1="hand_lh_ring_dip" joint2="hand_lh_ring_mcp_pitch" polycoef="0 1.125676 0 0 0" />
    <joint name="hand_lh_couple_pinky" joint1="hand_lh_pinky_dip" joint2="hand_lh_pinky_mcp_pitch" polycoef="0 1.125676 0 0 0" />
    <joint name="hand_lh_couple_thumb" joint1="hand_lh_thumb_dip" joint2="hand_lh_thumb_cmc_pitch" polycoef="0 1.226495 0 0 0" />
  </equality>
  <contact>
    <exclude body1="arm_AR5_5_07L_W4C4A2_base" body2="arm_AR5_5_07L_W4C4A2_link1" />
    <exclude body1="arm_AR5_5_07L_W4C4A2_link1" body2="arm_AR5_5_07L_W4C4A2_link2" />
    <exclude body1="arm_AR5_5_07L_W4C4A2_link2" body2="arm_AR5_5_07L_W4C4A2_link3" />
    <exclude body1="arm_AR5_5_07L_W4C4A2_link3" body2="arm_AR5_5_07L_W4C4A2_link4" />
    <exclude body1="arm_AR5_5_07L_W4C4A2_link4" body2="arm_AR5_5_07L_W4C4A2_link5" />
    <exclude body1="arm_AR5_5_07L_W4C4A2_link5" body2="arm_AR5_5_07L_W4C4A2_link6" />
    <exclude body1="arm_AR5_5_07L_W4C4A2_link6" body2="arm_AR5_5_07L_W4C4A2_link7" />
    <exclude body1="arm_AR5_5_07L_W4C4A2_link5" body2="arm_AR5_5_07L_W4C4A2_link7" />
    <exclude body1="hand_lh_hand_base_link" body2="hand_lh_thumb_metacarpals_base1" />
    <exclude body1="hand_lh_thumb_metacarpals_base1" body2="hand_lh_thumb_metacarpals" />
    <exclude body1="hand_lh_thumb_metacarpals" body2="hand_lh_thumb_distal" />
    <exclude body1="hand_lh_hand_base_link" body2="hand_lh_index_proximal" />
    <exclude body1="hand_lh_index_proximal" body2="hand_lh_index_distal" />
    <exclude body1="hand_lh_hand_base_link" body2="hand_lh_middle_proximal" />
    <exclude body1="hand_lh_middle_proximal" body2="hand_lh_middle_distal" />
    <exclude body1="hand_lh_hand_base_link" body2="hand_lh_ring_proximal" />
    <exclude body1="hand_lh_ring_proximal" body2="hand_lh_ring_distal" />
    <exclude body1="hand_lh_hand_base_link" body2="hand_lh_pinky_proximal" />
    <exclude body1="hand_lh_pinky_proximal" body2="hand_lh_pinky_distal" />
    <exclude body1="base_workstation_link" body2="arm_AR5_5_07L_W4C4A2_base" />
    <exclude body1="base_workstation_link" body2="arm_AR5_5_07L_W4C4A2_link1" />
    <exclude body1="base_workstation_link" body2="arm_AR5_5_07L_W4C4A2_link2" />
    <exclude body1="base_workstation_link" body2="arm_AR5_5_07L_W4C4A2_link3" />
    <exclude body1="base_workstation_link" body2="arm_AR5_5_07L_W4C4A2_link4" />
    <exclude body1="base_workstation_link" body2="arm_AR5_5_07L_W4C4A2_link5" />
    <exclude body1="base_workstation_link" body2="arm_AR5_5_07L_W4C4A2_link6" />
    <exclude body1="base_workstation_link" body2="arm_AR5_5_07L_W4C4A2_link7" />
    <exclude body1="base_camera_base_link" body2="arm_AR5_5_07L_W4C4A2_base" />
    <exclude body1="base_camera_base_link" body2="arm_AR5_5_07L_W4C4A2_link1" />
    <exclude body1="base_camera_base_link" body2="arm_AR5_5_07L_W4C4A2_link2" />
    <exclude body1="base_camera_base_link" body2="arm_AR5_5_07L_W4C4A2_link3" />
    <exclude body1="base_camera_base_link" body2="arm_AR5_5_07L_W4C4A2_link4" />
    <exclude body1="base_camera_base_link" body2="arm_AR5_5_07L_W4C4A2_link5" />
    <exclude body1="base_camera_base_link" body2="arm_AR5_5_07L_W4C4A2_link6" />
    <exclude body1="base_camera_base_link" body2="arm_AR5_5_07L_W4C4A2_link7" />
    <exclude body1="base_camera" body2="arm_AR5_5_07L_W4C4A2_base" />
    <exclude body1="base_camera" body2="arm_AR5_5_07L_W4C4A2_link1" />
    <exclude body1="base_camera" body2="arm_AR5_5_07L_W4C4A2_link2" />
    <exclude body1="base_camera" body2="arm_AR5_5_07L_W4C4A2_link3" />
    <exclude body1="base_camera" body2="arm_AR5_5_07L_W4C4A2_link4" />
    <exclude body1="base_camera" body2="arm_AR5_5_07L_W4C4A2_link5" />
    <exclude body1="base_camera" body2="arm_AR5_5_07L_W4C4A2_link6" />
    <exclude body1="base_camera" body2="arm_AR5_5_07L_W4C4A2_link7" />
    <exclude body1="arm_AR5_5_07L_W4C4A2_base" body2="hand_lh_hand_base_link" />
    <exclude body1="arm_AR5_5_07L_W4C4A2_base" body2="hand_lh_thumb_metacarpals_base1" />
    <exclude body1="arm_AR5_5_07L_W4C4A2_base" body2="hand_lh_thumb_metacarpals" />
    <exclude body1="arm_AR5_5_07L_W4C4A2_base" body2="hand_lh_thumb_distal" />
    <exclude body1="arm_AR5_5_07L_W4C4A2_base" body2="hand_lh_index_proximal" />
    <exclude body1="arm_AR5_5_07L_W4C4A2_base" body2="hand_lh_index_distal" />
    <exclude body1="arm_AR5_5_07L_W4C4A2_base" body2="hand_lh_middle_proximal" />
    <exclude body1="arm_AR5_5_07L_W4C4A2_base" body2="hand_lh_middle_distal" />
    <exclude body1="arm_AR5_5_07L_W4C4A2_base" body2="hand_lh_ring_proximal" />
    <exclude body1="arm_AR5_5_07L_W4C4A2_base" body2="hand_lh_ring_distal" />
    <exclude body1="arm_AR5_5_07L_W4C4A2_base" body2="hand_lh_pinky_proximal" />
    <exclude body1="arm_AR5_5_07L_W4C4A2_base" body2="hand_lh_pinky_distal" />
    <exclude body1="arm_AR5_5_07L_W4C4A2_link1" body2="hand_lh_hand_base_link" />
    <exclude body1="arm_AR5_5_07L_W4C4A2_link1" body2="hand_lh_thumb_metacarpals_base1" />
    <exclude body1="arm_AR5_5_07L_W4C4A2_link1" body2="hand_lh_thumb_metacarpals" />
    <exclude body1="arm_AR5_5_07L_W4C4A2_link1" body2="hand_lh_thumb_distal" />
    <exclude body1="arm_AR5_5_07L_W4C4A2_link1" body2="hand_lh_index_proximal" />
    <exclude body1="arm_AR5_5_07L_W4C4A2_link1" body2="hand_lh_index_distal" />
    <exclude body1="arm_AR5_5_07L_W4C4A2_link1" body2="hand_lh_middle_proximal" />
    <exclude body1="arm_AR5_5_07L_W4C4A2_link1" body2="hand_lh_middle_distal" />
    <exclude body1="arm_AR5_5_07L_W4C4A2_link1" body2="hand_lh_ring_proximal" />
    <exclude body1="arm_AR5_5_07L_W4C4A2_link1" body2="hand_lh_ring_distal" />
    <exclude body1="arm_AR5_5_07L_W4C4A2_link1" body2="hand_lh_pinky_proximal" />
    <exclude body1="arm_AR5_5_07L_W4C4A2_link1" body2="hand_lh_pinky_distal" />
    <exclude body1="arm_AR5_5_07L_W4C4A2_link2" body2="hand_lh_hand_base_link" />
    <exclude body1="arm_AR5_5_07L_W4C4A2_link2" body2="hand_lh_thumb_metacarpals_base1" />
    <exclude body1="arm_AR5_5_07L_W4C4A2_link2" body2="hand_lh_thumb_metacarpals" />
    <exclude body1="arm_AR5_5_07L_W4C4A2_link2" body2="hand_lh_thumb_distal" />
    <exclude body1="arm_AR5_5_07L_W4C4A2_link2" body2="hand_lh_index_proximal" />
    <exclude body1="arm_AR5_5_07L_W4C4A2_link2" body2="hand_lh_index_distal" />
    <exclude body1="arm_AR5_5_07L_W4C4A2_link2" body2="hand_lh_middle_proximal" />
    <exclude body1="arm_AR5_5_07L_W4C4A2_link2" body2="hand_lh_middle_distal" />
    <exclude body1="arm_AR5_5_07L_W4C4A2_link2" body2="hand_lh_ring_proximal" />
    <exclude body1="arm_AR5_5_07L_W4C4A2_link2" body2="hand_lh_ring_distal" />
    <exclude body1="arm_AR5_5_07L_W4C4A2_link2" body2="hand_lh_pinky_proximal" />
    <exclude body1="arm_AR5_5_07L_W4C4A2_link2" body2="hand_lh_pinky_distal" />
    <exclude body1="arm_AR5_5_07L_W4C4A2_link3" body2="hand_lh_hand_base_link" />
    <exclude body1="arm_AR5_5_07L_W4C4A2_link3" body2="hand_lh_thumb_metacarpals_base1" />
    <exclude body1="arm_AR5_5_07L_W4C4A2_link3" body2="hand_lh_thumb_metacarpals" />
    <exclude body1="arm_AR5_5_07L_W4C4A2_link3" body2="hand_lh_thumb_distal" />
    <exclude body1="arm_AR5_5_07L_W4C4A2_link3" body2="hand_lh_index_proximal" />
    <exclude body1="arm_AR5_5_07L_W4C4A2_link3" body2="hand_lh_index_distal" />
    <exclude body1="arm_AR5_5_07L_W4C4A2_link3" body2="hand_lh_middle_proximal" />
    <exclude body1="arm_AR5_5_07L_W4C4A2_link3" body2="hand_lh_middle_distal" />
    <exclude body1="arm_AR5_5_07L_W4C4A2_link3" body2="hand_lh_ring_proximal" />
    <exclude body1="arm_AR5_5_07L_W4C4A2_link3" body2="hand_lh_ring_distal" />
    <exclude body1="arm_AR5_5_07L_W4C4A2_link3" body2="hand_lh_pinky_proximal" />
    <exclude body1="arm_AR5_5_07L_W4C4A2_link3" body2="hand_lh_pinky_distal" />
    <exclude body1="arm_AR5_5_07L_W4C4A2_link4" body2="hand_lh_hand_base_link" />
    <exclude body1="arm_AR5_5_07L_W4C4A2_link4" body2="hand_lh_thumb_metacarpals_base1" />
    <exclude body1="arm_AR5_5_07L_W4C4A2_link4" body2="hand_lh_thumb_metacarpals" />
    <exclude body1="arm_AR5_5_07L_W4C4A2_link4" body2="hand_lh_thumb_distal" />
    <exclude body1="arm_AR5_5_07L_W4C4A2_link4" body2="hand_lh_index_proximal" />
    <exclude body1="arm_AR5_5_07L_W4C4A2_link4" body2="hand_lh_index_distal" />
    <exclude body1="arm_AR5_5_07L_W4C4A2_link4" body2="hand_lh_middle_proximal" />
    <exclude body1="arm_AR5_5_07L_W4C4A2_link4" body2="hand_lh_middle_distal" />
    <exclude body1="arm_AR5_5_07L_W4C4A2_link4" body2="hand_lh_ring_proximal" />
    <exclude body1="arm_AR5_5_07L_W4C4A2_link4" body2="hand_lh_ring_distal" />
    <exclude body1="arm_AR5_5_07L_W4C4A2_link4" body2="hand_lh_pinky_proximal" />
    <exclude body1="arm_AR5_5_07L_W4C4A2_link4" body2="hand_lh_pinky_distal" />
    <exclude body1="arm_AR5_5_07L_W4C4A2_link5" body2="hand_lh_hand_base_link" />
    <exclude body1="arm_AR5_5_07L_W4C4A2_link5" body2="hand_lh_thumb_metacarpals_base1" />
    <exclude body1="arm_AR5_5_07L_W4C4A2_link5" body2="hand_lh_thumb_metacarpals" />
    <exclude body1="arm_AR5_5_07L_W4C4A2_link5" body2="hand_lh_thumb_distal" />
    <exclude body1="arm_AR5_5_07L_W4C4A2_link5" body2="hand_lh_index_proximal" />
    <exclude body1="arm_AR5_5_07L_W4C4A2_link5" body2="hand_lh_index_distal" />
    <exclude body1="arm_AR5_5_07L_W4C4A2_link5" body2="hand_lh_middle_proximal" />
    <exclude body1="arm_AR5_5_07L_W4C4A2_link5" body2="hand_lh_middle_distal" />
    <exclude body1="arm_AR5_5_07L_W4C4A2_link5" body2="hand_lh_ring_proximal" />
    <exclude body1="arm_AR5_5_07L_W4C4A2_link5" body2="hand_lh_ring_distal" />
    <exclude body1="arm_AR5_5_07L_W4C4A2_link5" body2="hand_lh_pinky_proximal" />
    <exclude body1="arm_AR5_5_07L_W4C4A2_link5" body2="hand_lh_pinky_distal" />
    <exclude body1="arm_AR5_5_07L_W4C4A2_link6" body2="hand_lh_hand_base_link" />
    <exclude body1="arm_AR5_5_07L_W4C4A2_link6" body2="hand_lh_thumb_metacarpals_base1" />
    <exclude body1="arm_AR5_5_07L_W4C4A2_link6" body2="hand_lh_thumb_metacarpals" />
    <exclude body1="arm_AR5_5_07L_W4C4A2_link6" body2="hand_lh_thumb_distal" />
    <exclude body1="arm_AR5_5_07L_W4C4A2_link6" body2="hand_lh_index_proximal" />
    <exclude body1="arm_AR5_5_07L_W4C4A2_link6" body2="hand_lh_index_distal" />
    <exclude body1="arm_AR5_5_07L_W4C4A2_link6" body2="hand_lh_middle_proximal" />
    <exclude body1="arm_AR5_5_07L_W4C4A2_link6" body2="hand_lh_middle_distal" />
    <exclude body1="arm_AR5_5_07L_W4C4A2_link6" body2="hand_lh_ring_proximal" />
    <exclude body1="arm_AR5_5_07L_W4C4A2_link6" body2="hand_lh_ring_distal" />
    <exclude body1="arm_AR5_5_07L_W4C4A2_link6" body2="hand_lh_pinky_proximal" />
    <exclude body1="arm_AR5_5_07L_W4C4A2_link6" body2="hand_lh_pinky_distal" />
    <exclude body1="arm_AR5_5_07L_W4C4A2_link7" body2="hand_lh_hand_base_link" />
    <exclude body1="arm_AR5_5_07L_W4C4A2_link7" body2="hand_lh_thumb_metacarpals_base1" />
    <exclude body1="arm_AR5_5_07L_W4C4A2_link7" body2="hand_lh_thumb_metacarpals" />
    <exclude body1="arm_AR5_5_07L_W4C4A2_link7" body2="hand_lh_thumb_distal" />
    <exclude body1="arm_AR5_5_07L_W4C4A2_link7" body2="hand_lh_index_proximal" />
    <exclude body1="arm_AR5_5_07L_W4C4A2_link7" body2="hand_lh_index_distal" />
    <exclude body1="arm_AR5_5_07L_W4C4A2_link7" body2="hand_lh_middle_proximal" />
    <exclude body1="arm_AR5_5_07L_W4C4A2_link7" body2="hand_lh_middle_distal" />
    <exclude body1="arm_AR5_5_07L_W4C4A2_link7" body2="hand_lh_ring_proximal" />
    <exclude body1="arm_AR5_5_07L_W4C4A2_link7" body2="hand_lh_ring_distal" />
    <exclude body1="arm_AR5_5_07L_W4C4A2_link7" body2="hand_lh_pinky_proximal" />
    <exclude body1="arm_AR5_5_07L_W4C4A2_link7" body2="hand_lh_pinky_distal" />
    <exclude body1="base_workstation_link" body2="hand_lh_hand_base_link" />
    <exclude body1="base_workstation_link" body2="hand_lh_thumb_metacarpals_base1" />
    <exclude body1="base_workstation_link" body2="hand_lh_thumb_metacarpals" />
    <exclude body1="base_workstation_link" body2="hand_lh_thumb_distal" />
    <exclude body1="base_workstation_link" body2="hand_lh_index_proximal" />
    <exclude body1="base_workstation_link" body2="hand_lh_index_distal" />
    <exclude body1="base_workstation_link" body2="hand_lh_middle_proximal" />
    <exclude body1="base_workstation_link" body2="hand_lh_middle_distal" />
    <exclude body1="base_workstation_link" body2="hand_lh_ring_proximal" />
    <exclude body1="base_workstation_link" body2="hand_lh_ring_distal" />
    <exclude body1="base_workstation_link" body2="hand_lh_pinky_proximal" />
    <exclude body1="base_workstation_link" body2="hand_lh_pinky_distal" />
    <exclude body1="base_camera_base_link" body2="hand_lh_hand_base_link" />
    <exclude body1="base_camera_base_link" body2="hand_lh_thumb_metacarpals_base1" />
    <exclude body1="base_camera_base_link" body2="hand_lh_thumb_metacarpals" />
    <exclude body1="base_camera_base_link" body2="hand_lh_thumb_distal" />
    <exclude body1="base_camera_base_link" body2="hand_lh_index_proximal" />
    <exclude body1="base_camera_base_link" body2="hand_lh_index_distal" />
    <exclude body1="base_camera_base_link" body2="hand_lh_middle_proximal" />
    <exclude body1="base_camera_base_link" body2="hand_lh_middle_distal" />
    <exclude body1="base_camera_base_link" body2="hand_lh_ring_proximal" />
    <exclude body1="base_camera_base_link" body2="hand_lh_ring_distal" />
    <exclude body1="base_camera_base_link" body2="hand_lh_pinky_proximal" />
    <exclude body1="base_camera_base_link" body2="hand_lh_pinky_distal" />
    <exclude body1="base_camera" body2="hand_lh_hand_base_link" />
    <exclude body1="base_camera" body2="hand_lh_thumb_metacarpals_base1" />
    <exclude body1="base_camera" body2="hand_lh_thumb_metacarpals" />
    <exclude body1="base_camera" body2="hand_lh_thumb_distal" />
    <exclude body1="base_camera" body2="hand_lh_index_proximal" />
    <exclude body1="base_camera" body2="hand_lh_index_distal" />
    <exclude body1="base_camera" body2="hand_lh_middle_proximal" />
    <exclude body1="base_camera" body2="hand_lh_middle_distal" />
    <exclude body1="base_camera" body2="hand_lh_ring_proximal" />
    <exclude body1="base_camera" body2="hand_lh_ring_distal" />
    <exclude body1="base_camera" body2="hand_lh_pinky_proximal" />
    <exclude body1="base_camera" body2="hand_lh_pinky_distal" />
  </contact>
</mujoco>
