<?xml version="1.0" encoding="UTF-8"?>
<!-- Generated by tools/composer (version 0.1.0). Workstation: ar5_l6_bench. Recipe sha256: 4dc7320c419d25dc5447ccf7a90a9312135480fe1834b17d3c4b9f6a0c2fd7fa. Do not edit by hand; re-run `python -m tools.composer.compose <workstation>`. -->
<robot name="ar5_l6_bench">
  <link name="world" />
  <material name="arm_black">
    <color rgba="0.0 0.0 0.0 1.0" />
  </material>
  <material name="arm_blue">
    <color rgba="0.0 0.0 0.8 1.0" />
  </material>
  <material name="arm_green">
    <color rgba="0.0 0.8 0.0 1.0" />
  </material>
  <material name="arm_grey">
    <color rgba="0.2 0.2 0.2 1.0" />
  </material>
  <material name="arm_orange">
    <color rgba="1.0 0.423529411765 0.0392156862745 1.0" />
  </material>
  <material name="arm_brown">
    <color rgba="0.870588235294 0.811764705882 0.764705882353 1.0" />
  </material>
  <material name="arm_red">
    <color rgba="0.8 0.0 0.0 1.0" />
  </material>
  <material name="arm_white">
    <color rgba="1.0 1.0 1.0 1.0" />
  </material>
  <material name="arm_Beige">
    <color rgba="1.0 0.784 0.5765 1.0" />
  </material>
  <material name="hand_black">
    <color rgba="0.0 0.0 0.0 1.0" />
  </material>
  <material name="hand_blue">
    <color rgba="0.0 0.0 0.8 1.0" />
  </material>
  <material name="hand_green">
    <color rgba="0.0 0.8 0.0 1.0" />
  </material>
  <material name="hand_grey">
    <color rgba="0.2 0.2 0.2 1.0" />
  </material>
  <material name="hand_orange">
    <color rgba="1.0 0.423529411765 0.0392156862745 1.0" />
  </material>
  <material name="hand_brown">
    <color rgba="0.870588235294 0.811764705882 0.764705882353 1.0" />
  </material>
  <material name="hand_red">
    <color rgba="0.8 0.0 0.0 1.0" />
  </material>
  <material name="hand_white">
    <color rgba="1.0 1.0 1.0 1.0" />
  </material>
  <material name="hand_Beige">
    <color rgba="1.0 0.784 0.5765 1.0" />
  </material>
  <link name="base_workstation_link">
    <visual>
      <origin xyz="0 0 0" rpy="0 0 0" />
      <geometry>
        <mesh filename="../../components/bases/bench_table/variants/default/meshes/workstation.STL" />
      </geometry>
      <material name="base_workstation_gray">
        <color rgba="0.6 0.6 0.6 1.0" />
      </material>
    </visual>
    <collision>
      <origin xyz="0 0 0" rpy="0 0 0" />
      <geometry>
        <mesh filename="../../components/bases/bench_table/variants/default/meshes/workstation.STL" />
      </geometry>
    </collision>
    <inertial>
      <origin xyz="0 0 0" rpy="0 0 0" />
      <mass value="50.0" />
      <inertia ixx="1.0" ixy="0.0" ixz="0.0" iyy="1.0" iyz="0.0" izz="1.0" />
    </inertial>
  </link>
  <link name="base_camera_base_link">
    <inertial>
      <origin xyz="0.0538773695 0.0404431717 0.0338436904" rpy="0 0 0" />
      <mass value="0.120253078965696" />
      <inertia ixx="0.00024086634809874" ixy="1.11484097335586E-05" ixz="3.07915341770146E-05" iyy="0.000340317013404989" iyz="-5.88336477049719E-05" izz="0.000187914824387855" />
    </inertial>
    <visual>
      <origin xyz="0 0 0" rpy="0 0 0" />
      <geometry>
        <mesh filename="../../components/bases/bench_table/variants/default/meshes/camera_base_link.STL" />
      </geometry>
      <material name="">
        <color rgba="0.792156862745098 0.819607843137255 0.933333333333333 1" />
      </material>
    </visual>
    <collision>
      <origin xyz="0 0 0" rpy="0 0 0" />
      <geometry>
        <mesh filename="../../components/bases/bench_table/variants/default/meshes/camera_base_link.STL" />
      </geometry>
    </collision>
  </link>
  <link name="base_camera">
    <inertial>
      <origin xyz="0.435583907 -0.11451791 -0.00087379797" rpy="0 0 0" />
      <mass value="0.170230158191785" />
      <inertia ixx="0.000388607098441677" ixy="-3.21389374232659E-06" ixz="1.01075980515721E-06" iyy="0.000353185511381015" iyz="-0.000100865226288639" izz="6.42979907249093E-05" />
    </inertial>
    <visual>
      <origin xyz="0 0 0" rpy="0 0 0" />
      <geometry>
        <mesh filename="../../components/bases/bench_table/variants/default/meshes/camera.STL" />
      </geometry>
      <material name="">
        <color rgba="0.792156862745098 0.819607843137255 0.933333333333333 1" />
      </material>
    </visual>
    <collision>
      <origin xyz="0 0 0" rpy="0 0 0" />
      <geometry>
        <mesh filename="../../components/bases/bench_table/variants/default/meshes/camera.STL" />
      </geometry>
    </collision>
  </link>
  <link name="base_workstation_arm_left_mount" />
  <link name="base_workstation_arm_right_mount" />
  <link name="arm_AR5_5_07L_W4C4A2_base">
    <visual>
      <geometry>
        <mesh filename="../../components/arms/ar5/variants/left/meshes/AR5_5_07L_W4C4A2_base.stl" scale="0.001 0.001 0.001" />
      </geometry>
      <origin rpy="0 0 0" xyz="0 0 0" />
      <material name="arm_white" />
    </visual>
    <collision>
      <geometry>
        <mesh filename="../../components/arms/ar5/variants/left/meshes/AR5_5_07L_W4C4A2_base.stl" scale="0.001 0.001 0.001" />
      </geometry>
      <origin rpy="0 0 0" xyz="0 0 0" />
    </collision>
  </link>
  <link name="arm_AR5_5_07L_W4C4A2_link1">
    <visual>
      <geometry>
        <mesh filename="../../components/arms/ar5/variants/left/meshes/AR5_5_07L_W4C4A2_link1.stl" scale="0.001 0.001 0.001" />
      </geometry>
      <origin rpy="0 0 0" xyz="0 0 0" />
      <material name="arm_white" />
    </visual>
    <inertial>
      <mass value="2.683" />
      <inertia ixx="0.00493673" ixy="0.00000160" ixz="0.00000198" iyy="0.00452344" iyz="-0.00000020" izz="0.00432910" />
      <origin rpy="0 0 0" xyz="1e-06 -0.000621 0.167909" />
    </inertial>
    <collision>
      <geometry>
        <mesh filename="../../components/arms/ar5/variants/left/meshes/AR5_5_07L_W4C4A2_link1.stl" scale="0.001 0.001 0.001" />
      </geometry>
      <origin rpy="0 0 0" xyz="0 0 0" />
    </collision>
  </link>
  <link name="arm_AR5_5_07L_W4C4A2_link2">
    <visual>
      <geometry>
        <mesh filename="../../components/arms/ar5/variants/left/meshes/AR5_5_07L_W4C4A2_link2.stl" scale="0.001 0.001 0.001" />
      </geometry>
      <origin rpy="0 0 0" xyz="0 0 0" />
      <material name="arm_white" />
    </visual>
    <inertial>
      <mass value="2.3" />
      <inertia ixx="0.01151906" ixy="0.00000246" ixz="-0.00000055" iyy="0.00993335" iyz="0.00082477" izz="0.00435237" />
      <origin rpy="0 0 0" xyz="-2e-05 -0.003081 0.102986" />
    </inertial>
    <collision>
      <geometry>
        <mesh filename="../../components/arms/ar5/variants/left/meshes/AR5_5_07L_W4C4A2_link2.stl" scale="0.001 0.001 0.001" />
      </geometry>
      <origin rpy="0 0 0" xyz="0 0 0" />
    </collision>
  </link>
  <link name="arm_AR5_5_07L_W4C4A2_link3">
    <visual>
      <geometry>
        <mesh filename="../../components/arms/ar5/variants/left/meshes/AR5_5_07L_W4C4A2_link3.stl" scale="0.001 0.001 0.001" />
      </geometry>
      <origin rpy="0 0 0" xyz="0 0 0" />
      <material name="arm_white" />
    </visual>
    <inertial>
      <mass value="1.862" />
      <inertia ixx="0.00519681" ixy="0.00001208" ixz="0.00035761" iyy="0.00470446" iyz="0.00003430" izz="0.00266752" />
      <origin rpy="0 0 0" xyz="0.007097 -0.000659 -0.016531" />
    </inertial>
    <collision>
      <geometry>
        <mesh filename="../../components/arms/ar5/variants/left/meshes/AR5_5_07L_W4C4A2_link3.stl" scale="0.001 0.001 0.001" />
      </geometry>
      <origin rpy="0 0 0" xyz="0 0 0" />
    </collision>
  </link>
  <link name="arm_AR5_5_07L_W4C4A2_link4">
    <visual>
      <geometry>
        <mesh filename="../../components/arms/ar5/variants/left/meshes/AR5_5_07L_W4C4A2_link4.stl" scale="0.001 0.001 0.001" />
      </geometry>
      <origin rpy="0 0 0" xyz="0 0 0" />
      <material name="arm_white" />
    </visual>
    <inertial>
      <mass value="1.234" />
      <inertia ixx="0.00389590" ixy="-0.00004577" ixz="-0.00017280" iyy="0.00308657" iyz="0.00046679" izz="0.00188364" />
      <origin rpy="0 0 0" xyz="-0.007826 -0.004207 0.073404" />
    </inertial>
    <collision>
      <geometry>
        <mesh filename="../../components/arms/ar5/variants/left/meshes/AR5_5_07L_W4C4A2_link4.stl" scale="0.001 0.001 0.001" />
      </geometry>
      <origin rpy="0 0 0" xyz="0 0 0" />
    </collision>
  </link>
  <link name="arm_AR5_5_07L_W4C4A2_link5">
    <visual>
      <geometry>
        <mesh filename="../../components/arms/ar5/variants/left/meshes/AR5_5_07L_W4C4A2_link5.stl" scale="0.001 0.001 0.001" />
      </geometry>
      <origin rpy="0 0 0" xyz="0 0 0" />
      <material name="arm_white" />
    </visual>
    <inertial>
      <mass value="1.329" />
      <inertia ixx="0.00281562" ixy="0.00001782" ixz="0.00001650" iyy="0.00221084" iyz="0.00002100" izz="0.00182169" />
      <origin rpy="0 0 0" xyz="0.000284 0.001651 -0.084133" />
    </inertial>
    <collision>
      <geometry>
        <mesh filename="../../components/arms/ar5/variants/left/meshes/AR5_5_07L_W4C4A2_link5.stl" scale="0.001 0.001 0.001" />
      </geometry>
      <origin rpy="0 0 0" xyz="0 0 0" />
    </collision>
  </link>
  <link name="arm_AR5_5_07L_W4C4A2_link6">
    <visual>
      <geometry>
        <mesh filename="../../components/arms/ar5/variants/left/meshes/AR5_5_07L_W4C4A2_link6.stl" scale="0.001 0.001 0.001" />
      </geometry>
      <origin rpy="0 0 0" xyz="0 0 0" />
      <material name="arm_white" />
    </visual>
    <inertial>
      <mass value="0.93" />
      <inertia ixx="0.00072078" ixy="-0.00000217" ixz="0.00000108" iyy="0.00085153" iyz="0.00000048" izz="0.00090205" />
      <origin rpy="0 0 0" xyz="0.005406 0.000612 -3.9e-05" />
    </inertial>
    <collision>
      <geometry>
        <mesh filename="../../components/arms/ar5/variants/left/meshes/AR5_5_07L_W4C4A2_link6.stl" scale="0.001 0.001 0.001" />
      </geometry>
      <origin rpy="0 0 0" xyz="0 0 0" />
    </collision>
  </link>
  <link name="arm_AR5_5_07L_W4C4A2_link7">
    <visual>
      <geometry>
        <mesh filename="../../components/arms/ar5/variants/left/meshes/AR5_5_07L_W4C4A2_link7.stl" scale="0.001 0.001 0.001" />
      </geometry>
      <origin rpy="0 0 0" xyz="0 0 0" />
      <material name="arm_white" />
    </visual>
    <inertial>
      <mass value="0.33" />
      <inertia ixx="0.00051942" ixy="-0.00000052" ixz="0.00003721" iyy="0.00079132" iyz="0.00000265" izz="0.00045886" />
      <origin rpy="0 0 0" xyz="-0.00277 0.000316 0.054881" />
    </inertial>
    <collision>
      <geometry>
        <mesh filename="../../components/arms/ar5/variants/left/meshes/AR5_5_07L_W4C4A2_link7.stl" scale="0.001 0.001 0.001" />
      </geometry>
      <origin rpy="0 0 0" xyz="0 0 0" />
    </collision>
  </link>
  <link name="arm_AR5_5_07L_W4C4A2_tcp">
    <visual>
      <origin xyz="0 0 0" rpy="0 0 0" />
      <geometry>
        <box size="0.0001 0.0001 0.0001" />
      </geometry>
      <material name="arm_white" />
    </visual>
    <collision>
      <origin xyz="0 0 0" rpy="0 0 0" />
      <geometry>
        <box size="0.0001 0.0001 0.0001" />
      </geometry>
    </collision>
    <inertial>
      <mass value="0.0" />
      <inertia ixx="1e-6" ixy="0" ixz="0" iyy="1e-6" iyz="0" izz="1e-6" />
    </inertial>
  </link>
  <link name="hand_lh_hand_base_link">
    <inertial>
      <origin xyz="0.00199 -0.00091 0.058381" rpy="0 0 0" />
      <mass value="0.4185" />
      <inertia ixx="0.0004998" ixy="0.000012853" ixz="-0.000008317" iyy="0.0003567" iyz="0.000010354" izz="0.0002301" />
    </inertial>
    <visual>
      <origin xyz="0 0 0" rpy="0 0 0" />
      <geometry>
        <mesh filename="../../components/hands/linkerhand_l6/variants/left/meshes/hand_base_link.STL" />
      </geometry>
      <material name="">
        <color rgba="0.796078431372549 0.823529411764706 0.937254901960784 1" />
      </material>
    </visual>
    <collision>
      <origin xyz="0 0 0" rpy="0 0 0" />
      <geometry>
        <mesh filename="../../components/hands/linkerhand_l6/variants/left/meshes/hand_base_link.STL" />
      </geometry>
    </collision>
  </link>
  <link name="hand_lh_thumb_metacarpals_base1">
    <inertial>
      <origin xyz="0.0018663 -0.0066406 0.001533" rpy="0 0 0" />
      <mass value="0.01" />
      <inertia ixx="3.3724E-07" ixy="1.11E-07" ixz="-3.6039E-08" iyy="2.9457E-07" iyz="5.7181E-08" izz="4.903E-07" />
    </inertial>
    <visual>
      <origin xyz="0 0 0" rpy="0 0 0" />
      <geometry>
        <mesh filename="../../components/hands/linkerhand_l6/variants/left/meshes/thumb_metacarpals_base1.STL" />
      </geometry>
      <material name="">
        <color rgba="0.796078431372549 0.823529411764706 0.937254901960784 1" />
      </material>
    </visual>
    <collision>
      <origin xyz="0 0 0" rpy="0 0 0" />
      <geometry>
        <mesh filename="../../components/hands/linkerhand_l6/variants/left/meshes/thumb_metacarpals_base1.STL" />
      </geometry>
    </collision>
  </link>
  <link name="hand_lh_thumb_metacarpals">
    <inertial>
      <origin xyz="0.00769270907 0.0859662185 0.0235283087" rpy="0 0 0" />
      <mass value="0.065" />
      <inertia ixx="8.407E-06" ixy="-1.1338E-09" ixz="1.1136E-08" iyy="8.3899E-06" iyz="3.1171E-07" izz="2.0091E-06" />
    </inertial>
    <visual>
      <origin xyz="0 0 0" rpy="0 0 0" />
      <geometry>
        <mesh filename="../../components/hands/linkerhand_l6/variants/left/meshes/thumb_metacarpals.STL" />
      </geometry>
      <material name="">
        <color rgba="0.796078431372549 0.823529411764706 0.937254901960784 1" />
      </material>
    </visual>
    <collision>
      <origin xyz="0 0 0" rpy="0 0 0" />
      <geometry>
        <mesh filename="../../components/hands/linkerhand_l6/variants/left/meshes/thumb_metacarpals.STL" />
      </geometry>
    </collision>
  </link>
  <link name="hand_lh_thumb_distal">
    <inertial>
      <origin xyz="0.00769270907 0.0798662185 -0.0591716913" rpy="0 0 0" />
      <mass value="0.018" />
      <inertia ixx="1.5546E-06" ixy="2.4423E-09" ixz="2.8147E-09" iyy="1.7108E-06" iyz="-7.2756E-08" izz="9.1709E-07" />
    </inertial>
    <visual>
      <origin xyz="0 0 0" rpy="0 0 0" />
      <geometry>
        <mesh filename="../../components/hands/linkerhand_l6/variants/left/meshes/thumb_distal.STL" />
      </geometry>
      <material name="">
        <color rgba="0.796078431372549 0.823529411764706 0.937254901960784 1" />
      </material>
    </visual>
    <collision>
      <origin xyz="0 0 0" rpy="0 0 0" />
      <geometry>
        <mesh filename="../../components/hands/linkerhand_l6/variants/left/meshes/thumb_distal.STL" />
      </geometry>
    </collision>
  </link>
  <link name="hand_lh_thumb_tip">
    <visual>
      <origin xyz="0 0 0" rpy="0 0 0" />
      <geometry>
        <box size="0.0001 0.0001 0.0001" />
      </geometry>
      <material name="hand_white" />
    </visual>
    <collision>
      <origin xyz="0 0 0" rpy="0 0 0" />
      <geometry>
        <box size="0.0001 0.0001 0.0001" />
      </geometry>
    </collision>
    <inertial>
      <origin xyz="0 0 0" rpy="0 0 0" />
      <mass value="1e-06" />
      <inertia ixx="1e-09" ixy="0" ixz="0" iyy="1e-09" iyz="0" izz="1e-09" />
    </inertial>
  </link>
  <link name="hand_lh_index_proximal">
    <inertial>
      <origin xyz="0.001776 -0.00011 0.012556" rpy="0 0 0" />
      <mass value="0.008553" />
      <inertia ixx="0.000000797543" ixy="-0.000000001275" ixz="0.000000138601" iyy="0.000000800499" iyz="0.000000000939" izz="0.000000357001" />
    </inertial>
    <visual>
      <origin xyz="0 0 0" rpy="0 0 0" />
      <geometry>
        <mesh filename="../../components/hands/linkerhand_l6/variants/left/meshes/index_proximal.STL" />
      </geometry>
      <material name="">
        <color rgba="0.796078431372549 0.823529411764706 0.937254901960784 1" />
      </material>
    </visual>
    <collision>
      <origin xyz="0 0 0" rpy="0 0 0" />
      <geometry>
        <mesh filename="../../components/hands/linkerhand_l6/variants/left/meshes/index_proximal.STL" />
      </geometry>
    </collision>
  </link>
  <link name="hand_lh_index_distal">
    <inertial>
      <origin xyz="0.0134 0.002262 0.016992" rpy="0 0 0" />
      <mass value="0.018408" />
      <inertia ixx="0.000002488712" ixy="0.000000008249" ixz="-0.000001523059" iyy="0.000003723754" iyz="0.000000014019" izz="0.000001813582" />
    </inertial>
    <visual>
      <origin xyz="0 0 0" rpy="0 0 0" />
      <geometry>
        <mesh filename="../../components/hands/linkerhand_l6/variants/left/meshes/index_distal.STL" />
      </geometry>
      <material name="">
        <color rgba="0.796078431372549 0.823529411764706 0.937254901960784 1" />
      </material>
    </visual>
    <collision>
      <origin xyz="0 0 0" rpy="0 0 0" />
      <geometry>
        <mesh filename="../../components/hands/linkerhand_l6/variants/left/meshes/index_distal.STL" />
      </geometry>
    </collision>
  </link>
  <link name="hand_lh_index_tip">
    <visual>
      <origin xyz="0 0 0" rpy="0 0 0" />
      <geometry>
        <box size="0.0001 0.0001 0.0001" />
      </geometry>
      <material name="hand_white" />
    </visual>
    <collision>
      <origin xyz="0 0 0" rpy="0 0 0" />
      <geometry>
        <box size="0.0001 0.0001 0.0001" />
      </geometry>
    </collision>
    <inertial>
      <origin xyz="0 0 0" rpy="0 0 0" />
      <mass value="1e-06" />
      <inertia ixx="1e-09" ixy="0" ixz="0" iyy="1e-09" iyz="0" izz="1e-09" />
    </inertial>
  </link>
  <link name="hand_lh_middle_proximal">
    <inertial>
      <origin xyz="0.001776 -0.00011 0.012556" rpy="0 0 0" />
      <mass value="0.008553" />
      <inertia ixx="0.000000797543" ixy="-0.000000001275" ixz="0.000000138601" iyy="0.000000800499" iyz="0.000000000939" izz="0.000000357001" />
    </inertial>
    <visual>
      <origin xyz="0 0 0" rpy="0 0 0" />
      <geometry>
        <mesh filename="../../components/hands/linkerhand_l6/variants/left/meshes/middle_proximal.STL" />
      </geometry>
      <material name="">
        <color rgba="0.796078431372549 0.823529411764706 0.937254901960784 1" />
      </material>
    </visual>
    <collision>
      <origin xyz="0 0 0" rpy="0 0 0" />
      <geometry>
        <mesh filename="../../components/hands/linkerhand_l6/variants/left/meshes/middle_proximal.STL" />
      </geometry>
    </collision>
  </link>
  <link name="hand_lh_middle_distal">
    <inertial>
      <origin xyz="0.0134 0.002262 0.016992" rpy="0 0 0" />
      <mass value="0.018408" />
      <inertia ixx="0.000002488712" ixy="0.000000008249" ixz="-0.000001523059" iyy="0.000003723754" iyz="0.000000014019" izz="0.000001813582" />
    </inertial>
    <visual>
      <origin xyz="0 0 0" rpy="0 0 0" />
      <geometry>
        <mesh filename="../../components/hands/linkerhand_l6/variants/left/meshes/middle_distal.STL" />
      </geometry>
      <material name="">
        <color rgba="0.796078431372549 0.823529411764706 0.937254901960784 1" />
      </material>
    </visual>
    <collision>
      <origin xyz="0 0 0" rpy="0 0 0" />
      <geometry>
        <mesh filename="../../components/hands/linkerhand_l6/variants/left/meshes/middle_distal.STL" />
      </geometry>
    </collision>
  </link>
  <link name="hand_lh_middle_tip">
    <visual>
      <origin xyz="0 0 0" rpy="0 0 0" />
      <geometry>
        <box size="0.0001 0.0001 0.0001" />
      </geometry>
      <material name="hand_white" />
    </visual>
    <collision>
      <origin xyz="0 0 0" rpy="0 0 0" />
      <geometry>
        <box size="0.0001 0.0001 0.0001" />
      </geometry>
    </collision>
    <inertial>
      <origin xyz="0 0 0" rpy="0 0 0" />
      <mass value="1e-06" />
      <inertia ixx="1e-09" ixy="0" ixz="0" iyy="1e-09" iyz="0" izz="1e-09" />
    </inertial>
  </link>
  <link name="hand_lh_ring_proximal">
    <inertial>
      <origin xyz="0.001776 -0.00011 0.012556" rpy="0 0 0" />
      <mass value="0.008553" />
      <inertia ixx="0.000000797543" ixy="-0.000000001275" ixz="0.000000138601" iyy="0.000000800499" iyz="0.000000000939" izz="0.000000357001" />
    </inertial>
    <visual>
      <origin xyz="0 0 0" rpy="0 0 0" />
      <geometry>
        <mesh filename="../../components/hands/linkerhand_l6/variants/left/meshes/ring_proximal.STL" />
      </geometry>
      <material name="">
        <color rgba="0.796078431372549 0.823529411764706 0.937254901960784 1" />
      </material>
    </visual>
    <collision>
      <origin xyz="0 0 0" rpy="0 0 0" />
      <geometry>
        <mesh filename="../../components/hands/linkerhand_l6/variants/left/meshes/ring_proximal.STL" />
      </geometry>
    </collision>
  </link>
  <link name="hand_lh_ring_distal">
    <inertial>
      <origin xyz="0.0134 0.002262 0.016992" rpy="0 0 0" />
      <mass value="0.018408" />
      <inertia ixx="0.000002488712" ixy="0.000000008249" ixz="-0.000001523059" iyy="0.000003723754" iyz="0.000000014019" izz="0.000001813582" />
    </inertial>
    <visual>
      <origin xyz="0 0 0" rpy="0 0 0" />
      <geometry>
        <mesh filename="../../components/hands/linkerhand_l6/variants/left/meshes/ring_distal.STL" />
      </geometry>
      <material name="">
        <color rgba="0.796078431372549 0.823529411764706 0.937254901960784 1" />
      </material>
    </visual>
    <collision>
      <origin xyz="0 0 0" rpy="0 0 0" />
      <geometry>
        <mesh filename="../../components/hands/linkerhand_l6/variants/left/meshes/ring_distal.STL" />
      </geometry>
    </collision>
  </link>
  <link name="hand_lh_ring_tip">
    <visual>
      <origin xyz="0 0 0" rpy="0 0 0" />
      <geometry>
        <box size="0.0001 0.0001 0.0001" />
      </geometry>
      <material name="hand_white" />
    </visual>
    <collision>
      <origin xyz="0 0 0" rpy="0 0 0" />
      <geometry>
        <box size="0.0001 0.0001 0.0001" />
      </geometry>
    </collision>
    <inertial>
      <origin xyz="0 0 0" rpy="0 0 0" />
      <mass value="1e-06" />
      <inertia ixx="1e-09" ixy="0" ixz="0" iyy="1e-09" iyz="0" izz="1e-09" />
    </inertial>
  </link>
  <link name="hand_lh_pinky_proximal">
    <inertial>
      <origin xyz="0.001776 -0.00011 0.012556" rpy="0 0 0" />
      <mass value="0.008553" />
      <inertia ixx="0.000000797543" ixy="-0.000000001275" ixz="0.000000138601" iyy="0.000000800499" iyz="0.000000000939" izz="0.000000357001" />
    </inertial>
    <visual>
      <origin xyz="0 0 0" rpy="0 0 0" />
      <geometry>
        <mesh filename="../../components/hands/linkerhand_l6/variants/left/meshes/pinky_proximal.STL" />
      </geometry>
      <material name="">
        <color rgba="0.796078431372549 0.823529411764706 0.937254901960784 1" />
      </material>
    </visual>
    <collision>
      <origin xyz="0 0 0" rpy="0 0 0" />
      <geometry>
        <mesh filename="../../components/hands/linkerhand_l6/variants/left/meshes/pinky_proximal.STL" />
      </geometry>
    </collision>
  </link>
  <link name="hand_lh_pinky_distal">
    <inertial>
      <origin xyz="0.0134 0.002262 0.016992" rpy="0 0 0" />
      <mass value="0.018408" />
      <inertia ixx="0.000002488712" ixy="0.000000008249" ixz="-0.000001523059" iyy="0.000003723754" iyz="0.000000014019" izz="0.000001813582" />
    </inertial>
    <visual>
      <origin xyz="0 0 0" rpy="0 0 0" />
      <geometry>
        <mesh filename="../../components/hands/linkerhand_l6/variants/left/meshes/pinky_distal.STL" />
      </geometry>
      <material name="">
        <color rgba="0.796078431372549 0.823529411764706 0.937254901960784 1" />
      </material>
    </visual>
    <collision>
      <origin xyz="0 0 0" rpy="0 0 0" />
      <geometry>
        <mesh filename="../../components/hands/linkerhand_l6/variants/left/meshes/pinky_distal.STL" />
      </geometry>
    </collision>
  </link>
  <link name="hand_lh_pinky_tip">
    <visual>
      <origin xyz="0 0 0" rpy="0 0 0" />
      <geometry>
        <box size="0.0001 0.0001 0.0001" />
      </geometry>
      <material name="hand_white" />
    </visual>
    <collision>
      <origin xyz="0 0 0" rpy="0 0 0" />
      <geometry>
        <box size="0.0001 0.0001 0.0001" />
      </geometry>
    </collision>
    <inertial>
      <origin xyz="0 0 0" rpy="0 0 0" />
      <mass value="1e-06" />
      <inertia ixx="1e-09" ixy="0" ixz="0" iyy="1e-09" iyz="0" izz="1e-09" />
    </inertial>
  </link>
  <joint name="base_cameraBase" type="fixed">
    <origin xyz="0.0335 0.67 1.2974" rpy="-1.5708 0 -1.5708" />
    <parent link="base_workstation_link" />
    <child link="base_camera_base_link" />
    <axis xyz="0 0 0" />
  </joint>
  <joint name="base_cameraJoint" type="fixed">
    <origin xyz="0.0802 0.193139854 -0.275851476" rpy="-1.26599038 -0.643554018 -1.57079633" />
    <parent link="base_camera_base_link" />
    <child link="base_camera" />
    <axis xyz="0 0 0" />
  </joint>
  <joint name="base_weld_workstation_arm_left_mount" type="fixed">
    <origin xyz="0.0637 0.719 1.267" rpy="0 1.57079633 1.57079633" />
    <parent link="base_workstation_link" />
    <child link="base_workstation_arm_left_mount" />
  </joint>
  <joint name="base_weld_workstation_arm_right_mount" type="fixed">
    <origin xyz="0.0637 0.536 1.267" rpy="0 1.57079633 -1.57079633" />
    <parent link="base_workstation_link" />
    <child link="base_workstation_arm_right_mount" />
  </joint>
  <joint name="arm_AR5_5_07L_W4C4A2_joint_1" type="revolute">
    <parent link="arm_AR5_5_07L_W4C4A2_base" />
    <child link="arm_AR5_5_07L_W4C4A2_link1" />
    <limit effort="108" lower="-3.1067" upper="3.1067" velocity="3.0543261909900763" />
    <dynamics damping="14.22378" friction="1.234293" />
    <axis xyz="0 0 1" />
    <origin rpy="0 0 0" xyz="0 0 0" />
  </joint>
  <joint name="arm_AR5_5_07L_W4C4A2_joint_2" type="revolute">
    <parent link="arm_AR5_5_07L_W4C4A2_link1" />
    <child link="arm_AR5_5_07L_W4C4A2_link2" />
    <limit effort="108" lower="-2.0944" upper="2.0944" velocity="3.0543261909900763" />
    <dynamics damping="13.710972" friction="3.073299" />
    <axis xyz="0 1 0" />
    <origin rpy="0 0 0" xyz="0 0 0.1745" />
  </joint>
  <joint name="arm_AR5_5_07L_W4C4A2_joint_3" type="revolute">
    <parent link="arm_AR5_5_07L_W4C4A2_link2" />
    <child link="arm_AR5_5_07L_W4C4A2_link3" />
    <limit effort="66" lower="-3.1067" upper="3.1067" velocity="4.71238898038469" />
    <dynamics damping="3.791042" friction="0.352159" />
    <axis xyz="0 0 1" />
    <origin rpy="0 0 0" xyz="0 0 0.314" />
  </joint>
  <joint name="arm_AR5_5_07L_W4C4A2_joint_4" type="revolute">
    <parent link="arm_AR5_5_07L_W4C4A2_link3" />
    <child link="arm_AR5_5_07L_W4C4A2_link4" />
    <limit effort="66" lower="-1.0472" upper="2.5307" velocity="5.235987755982989" />
    <dynamics damping="0.333154" friction="1.926179" />
    <axis xyz="0 1 0" />
    <origin rpy="0 0 0" xyz="0.01 0 0" />
  </joint>
  <joint name="arm_AR5_5_07L_W4C4A2_joint_5" type="revolute">
    <parent link="arm_AR5_5_07L_W4C4A2_link4" />
    <child link="arm_AR5_5_07L_W4C4A2_link5" />
    <limit effort="19" lower="-3.1067" upper="3.1067" velocity="4.1887902047863905" />
    <dynamics damping="4.136716" friction="0.295156" />
    <axis xyz="0 0 1" />
    <origin rpy="0 0 0" xyz="-0.01 0 0.272" />
  </joint>
  <joint name="arm_AR5_5_07L_W4C4A2_joint_6" type="revolute">
    <parent link="arm_AR5_5_07L_W4C4A2_link5" />
    <child link="arm_AR5_5_07L_W4C4A2_link6" />
    <limit effort="19" lower="-1.0472" upper="1.0472" velocity="4.1887902047863905" />
    <dynamics damping="4.748679" friction="1.322494" />
    <axis xyz="0 1 0" />
    <origin rpy="0 0 0" xyz="0 0 0" />
  </joint>
  <joint name="arm_AR5_5_07L_W4C4A2_joint_7" type="revolute">
    <parent link="arm_AR5_5_07L_W4C4A2_link6" />
    <child link="arm_AR5_5_07L_W4C4A2_link7" />
    <limit effort="19" lower="-1.0472" upper="1.0472" velocity="4.1887902047863905" />
    <dynamics damping="3.667978" friction="0.926051" />
    <axis xyz="1 0 0" />
    <origin rpy="0 0 0" xyz="0 0 0" />
  </joint>
  <joint name="arm_AR5_5_07L_W4C4A2_tcp_joint" type="fixed">
    <parent link="arm_AR5_5_07L_W4C4A2_link7" />
    <child link="arm_AR5_5_07L_W4C4A2_tcp" />
    <origin rpy="0 0 0" xyz="0 0 0.097" />
  </joint>
  <joint name="hand_lh_thumb_cmc_roll" type="revolute">
    <origin xyz="0.0078133 -0.029898 0.026692" rpy="-0.034907 0 0" />
    <parent link="hand_lh_hand_base_link" />
    <child link="hand_lh_thumb_metacarpals_base1" />
    <axis xyz="0 0 1" />
    <limit lower="-0.087266" upper="1.256637" effort="0.588" velocity="5.95" />
    <dynamics damping="0.02" friction="0.05416667" />
  </joint>
  <joint name="hand_lh_thumb_cmc_pitch" type="revolute">
    <origin xyz="0.0057298 -0.01332 0.0027456" rpy="1.1083 0 0.40143" />
    <parent link="hand_lh_thumb_metacarpals_base1" />
    <child link="hand_lh_thumb_metacarpals" />
    <axis xyz="-1 0 0" />
    <limit lower="0" upper="0.837758" effort="1.008" velocity="3.47" />
    <dynamics damping="0.02" friction="0.0375" />
  </joint>
  <joint name="hand_lh_thumb_tip_fixed" type="fixed">
    <origin xyz="0 0.0035 0.026" rpy="0 0 1.5708" />
    <parent link="hand_lh_thumb_distal" />
    <child link="hand_lh_thumb_tip" />
  </joint>
  <joint name="hand_lh_thumb_dip" type="revolute">
    <origin xyz="0 0.0061 0.0827" rpy="0 0 0" />
    <parent link="hand_lh_thumb_metacarpals" />
    <child link="hand_lh_thumb_distal" />
    <axis xyz="-1 0 0" />
    <limit lower="0" upper="0.963287" effort="0" velocity="1.7" />
    <mimic joint="hand_lh_thumb_cmc_pitch" multiplier="1.226495" offset="0" />
  </joint>
  <joint name="hand_lh_index_mcp_pitch" type="revolute">
    <origin xyz="-0.00066821 -0.028967 0.11722" rpy="0 0 0" />
    <parent link="hand_lh_hand_base_link" />
    <child link="hand_lh_index_proximal" />
    <axis xyz="0 1 0" />
    <limit lower="0" upper="1.134464" effort="0.574" velocity="6.10" />
    <dynamics damping="0.01" friction="0.04" />
  </joint>
  <joint name="hand_lh_index_tip_fixed" type="fixed">
    <origin xyz="0.0341 0 0.034" rpy="0 0 0" />
    <parent link="hand_lh_index_distal" />
    <child link="hand_lh_index_tip" />
  </joint>
  <joint name="hand_lh_index_dip" type="revolute">
    <origin xyz="0.00093749 0 0.028002" rpy="0 0 0" />
    <parent link="hand_lh_index_proximal" />
    <child link="hand_lh_index_distal" />
    <axis xyz="0 1 0" />
    <limit lower="0" upper="1.277039" effort="0" velocity="3.1" />
    <mimic joint="hand_lh_index_mcp_pitch" multiplier="1.125676" offset="0" />
  </joint>
  <joint name="hand_lh_middle_mcp_pitch" type="revolute">
    <origin xyz="-0.00066821 -0.0089013 0.12322" rpy="0 0 0" />
    <parent link="hand_lh_hand_base_link" />
    <child link="hand_lh_middle_proximal" />
    <axis xyz="0 1 0" />
    <limit lower="0" upper="1.134464" effort="0.574" velocity="6.10" />
    <dynamics damping="0.01" friction="0.02708333" />
  </joint>
  <joint name="hand_lh_middle_tip_fixed" type="fixed">
    <origin xyz="0.0341 0 0.034" rpy="0 0 0" />
    <parent link="hand_lh_middle_distal" />
    <child link="hand_lh_middle_tip" />
  </joint>
  <joint name="hand_lh_middle_dip" type="revolute">
    <origin xyz="0.00093749 0 0.028002" rpy="0 0 0" />
    <parent link="hand_lh_middle_proximal" />
    <child link="hand_lh_middle_distal" />
    <axis xyz="0 1 0" />
    <limit lower="0" upper="1.277039" effort="0" velocity="3.1" />
    <mimic joint="hand_lh_middle_mcp_pitch" multiplier="1.125676" offset="0" />
  </joint>
  <joint name="hand_lh_ring_mcp_pitch" type="revolute">
    <origin xyz="-0.00067368 0.010717 0.11822" rpy="0 0 0" />
    <parent link="hand_lh_hand_base_link" />
    <child link="hand_lh_ring_proximal" />
    <axis xyz="0 1 0" />
    <limit lower="0" upper="1.134464" effort="0.574" velocity="6.10" />
    <dynamics damping="0.01" friction="0.02291667" />
  </joint>
  <joint name="hand_lh_ring_tip_fixed" type="fixed">
    <origin xyz="0.0341 0 0.034" rpy="0 0 0" />
    <parent link="hand_lh_ring_distal" />
    <child link="hand_lh_ring_tip" />
  </joint>
  <joint name="hand_lh_ring_dip" type="revolute">
    <origin xyz="0.00093749 0 0.028002" rpy="0 0 0" />
    <parent link="hand_lh_ring_proximal" />
    <child link="hand_lh_ring_distal" />
    <axis xyz="0 1 0" />
    <limit lower="0" upper="1.277039" effort="0" velocity="3.1" />
    <mimic joint="hand_lh_ring_mcp_pitch" multiplier="1.125676" offset="0" />
  </joint>
  <joint name="hand_lh_pinky_mcp_pitch" type="revolute">
    <origin xyz="-0.00067852 0.029814 0.11424" rpy="0 0 0" />
    <parent link="hand_lh_hand_base_link" />
    <child link="hand_lh_pinky_proximal" />
    <axis xyz="0 1 0" />
    <limit lower="0" upper="1.134464" effort="0.574" velocity="6.10" />
    <dynamics damping="0.01" friction="0.01" />
  </joint>
  <joint name="hand_lh_pinky_tip_fixed" type="fixed">
    <origin xyz="0.0341 0 0.034" rpy="0 0 0" />
    <parent link="hand_lh_pinky_distal" />
    <child link="hand_lh_pinky_tip" />
  </joint>
  <joint name="hand_lh_pinky_dip" type="revolute">
    <origin xyz="0.00093749 0 0.028002" rpy="0 0 0" />
    <parent link="hand_lh_pinky_proximal" />
    <child link="hand_lh_pinky_distal" />
    <axis xyz="0 1 0" />
    <limit lower="0" upper="1.277039" effort="0" velocity="3.1" />
    <mimic joint="hand_lh_pinky_mcp_pitch" multiplier="1.125676" offset="0" />
  </joint>
  <transmission name="arm_tran1">
    <type>transmission_interface/SimpleTransmission</type>
    <joint name="arm_AR5_5_07L_W4C4A2_joint_8">
      <hardwareInterface>EffortJointInterface</hardwareInterface>
    </joint>
    <actuator name="motor1">
      <hardwareInterface>EffortJointInterface</hardwareInterface>
      <mechanicalReduction>1</mechanicalReduction>
    </actuator>
  </transmission>
  <transmission name="arm_tran2">
    <type>transmission_interface/SimpleTransmission</type>
    <joint name="arm_xmate_joint_2">
      <hardwareInterface>EffortJointInterface</hardwareInterface>
    </joint>
    <actuator name="motor2">
      <hardwareInterface>EffortJointInterface</hardwareInterface>
      <mechanicalReduction>1</mechanicalReduction>
    </actuator>
  </transmission>
  <transmission name="arm_tran3">
    <type>transmission_interface/SimpleTransmission</type>
    <joint name="arm_xmate_joint_3">
      <hardwareInterface>EffortJointInterface</hardwareInterface>
    </joint>
    <actuator name="motor3">
      <hardwareInterface>EffortJointInterface</hardwareInterface>
      <mechanicalReduction>1</mechanicalReduction>
    </actuator>
  </transmission>
  <transmission name="arm_tran4">
    <type>transmission_interface/SimpleTransmission</type>
    <joint name="arm_xmate_joint_4">
      <hardwareInterface>EffortJointInterface</hardwareInterface>
    </joint>
    <actuator name="motor4">
      <hardwareInterface>EffortJointInterface</hardwareInterface>
      <mechanicalReduction>1</mechanicalReduction>
    </actuator>
  </transmission>
  <transmission name="arm_tran5">
    <type>transmission_interface/SimpleTransmission</type>
    <joint name="arm_xmate_joint_5">
      <hardwareInterface>EffortJointInterface</hardwareInterface>
    </joint>
    <actuator name="motor5">
      <hardwareInterface>EffortJointInterface</hardwareInterface>
      <mechanicalReduction>1</mechanicalReduction>
    </actuator>
  </transmission>
  <transmission name="arm_tran6">
    <type>transmission_interface/SimpleTransmission</type>
    <joint name="arm_xmate_joint_6">
      <hardwareInterface>EffortJointInterface</hardwareInterface>
    </joint>
    <actuator name="motor6">
      <hardwareInterface>EffortJointInterface</hardwareInterface>
      <mechanicalReduction>1</mechanicalReduction>
    </actuator>
  </transmission>
  <transmission name="arm_tran7">
    <type>transmission_interface/SimpleTransmission</type>
    <joint name="arm_xmate_joint_7">
      <hardwareInterface>EffortJointInterface</hardwareInterface>
    </joint>
    <actuator name="motor7">
      <hardwareInterface>EffortJointInterface</hardwareInterface>
      <mechanicalReduction>1</mechanicalReduction>
    </actuator>
  </transmission>
  <transmission name="hand_trans_thumb_cmc_roll">
    <type>transmission_interface/SimpleTransmission</type>
    <joint name="hand_lh_thumb_cmc_roll">
      <hardwareInterface>hardware_interface/EffortJointInterface</hardwareInterface>
    </joint>
    <actuator name="motor_thumb_cmc_roll">
      <hardwareInterface>hardware_interface/EffortJointInterface</hardwareInterface>
      <mechanicalReduction>0.0084</mechanicalReduction>
    </actuator>
  </transmission>
  <transmission name="hand_trans_index_mcp_pitch">
    <type>transmission_interface/SimpleTransmission</type>
    <joint name="hand_lh_index_mcp_pitch">
      <hardwareInterface>hardware_interface/EffortJointInterface</hardwareInterface>
    </joint>
    <actuator name="motor_index_mcp_pitch">
      <hardwareInterface>hardware_interface/EffortJointInterface</hardwareInterface>
      <mechanicalReduction>0.0082</mechanicalReduction>
    </actuator>
  </transmission>
  <transmission name="hand_trans_middle_mcp_pitch">
    <type>transmission_interface/SimpleTransmission</type>
    <joint name="hand_lh_middle_mcp_pitch">
      <hardwareInterface>hardware_interface/EffortJointInterface</hardwareInterface>
    </joint>
    <actuator name="motor_middle_mcp_pitch">
      <hardwareInterface>hardware_interface/EffortJointInterface</hardwareInterface>
      <mechanicalReduction>0.0082</mechanicalReduction>
    </actuator>
  </transmission>
  <transmission name="hand_trans_ring_mcp_pitch">
    <type>transmission_interface/SimpleTransmission</type>
    <joint name="hand_lh_ring_mcp_pitch">
      <hardwareInterface>hardware_interface/EffortJointInterface</hardwareInterface>
    </joint>
    <actuator name="motor_ring_mcp_pitch">
      <hardwareInterface>hardware_interface/EffortJointInterface</hardwareInterface>
      <mechanicalReduction>0.0082</mechanicalReduction>
    </actuator>
  </transmission>
  <transmission name="hand_trans_pinky_mcp_pitch">
    <type>transmission_interface/SimpleTransmission</type>
    <joint name="hand_lh_pinky_mcp_pitch">
      <hardwareInterface>hardware_interface/EffortJointInterface</hardwareInterface>
    </joint>
    <actuator name="motor_pinky_mcp_pitch">
      <hardwareInterface>hardware_interface/EffortJointInterface</hardwareInterface>
      <mechanicalReduction>0.0082</mechanicalReduction>
    </actuator>
  </transmission>
  <transmission name="hand_trans_thumb_cmc_pitch">
    <type>transmission_interface/SimpleTransmission</type>
    <joint name="hand_lh_thumb_cmc_pitch">
      <hardwareInterface>hardware_interface/EffortJointInterface</hardwareInterface>
    </joint>
    <actuator name="motor_thumb_cmc_pitch">
      <hardwareInterface>hardware_interface/EffortJointInterface</hardwareInterface>
      <mechanicalReduction>0.0144</mechanicalReduction>
    </actuator>
  </transmission>
  <joint name="mount_arm_to_base_base_mount" type="fixed">
    <origin xyz="0 0 0" rpy="0 0 0" />
    <parent link="base_workstation_arm_left_mount" />
    <child link="arm_AR5_5_07L_W4C4A2_base" />
  </joint>
  <joint name="mount_hand_to_arm_wrist_mount" type="fixed">
    <origin xyz="0 0 0.03" rpy="0 0 1.5708" />
    <parent link="arm_AR5_5_07L_W4C4A2_tcp" />
    <child link="hand_lh_hand_base_link" />
  </joint>
  <joint name="mount_world_to_base" type="fixed">
    <origin xyz="0 0 0" rpy="0 0 0" />
    <parent link="world" />
    <child link="base_workstation_link" />
  </joint>
  <mujoco>
    <compiler meshdir="meshes/" balanceinertia="true" discardvisual="false" />
    <default>
      <joint armature="3.4707e-08" damping="5.0" frictionloss="0.5" />
    </default>
    <equality>
      <joint name="hand_lh_couple_index" joint1="hand_lh_index_dip" joint2="hand_lh_index_mcp_pitch" polycoef="0 1.125676 0 0 0 0" />
      <joint name="hand_lh_couple_middle" joint1="hand_lh_middle_dip" joint2="hand_lh_middle_mcp_pitch" polycoef="0 1.125676 0 0 0 0" />
      <joint name="hand_lh_couple_ring" joint1="hand_lh_ring_dip" joint2="hand_lh_ring_mcp_pitch" polycoef="0 1.125676 0 0 0 0" />
      <joint name="hand_lh_couple_pinky" joint1="hand_lh_pinky_dip" joint2="hand_lh_pinky_mcp_pitch" polycoef="0 1.125676 0 0 0 0" />
      <joint name="hand_lh_couple_thumb" joint1="hand_lh_thumb_dip" joint2="hand_lh_thumb_cmc_pitch" polycoef="0 1.226495 0 0 0 0" />
    </equality>
  </mujoco>
</robot>
