<mujoco model="linkerhand_o6_right">
  <compiler meshdir="meshes" discardvisual="false" autolimits="true" angle="radian" eulerseq="XYZ"/>
  <option/>

  <default>
    <default class="hand_linkerhand_o6_visual">
      <geom type="mesh" contype="0" conaffinity="0" group="1"/>
    </default>
    <default class="hand_linkerhand_o6_collision">
      <geom type="mesh" contype="1" conaffinity="1" group="3"/>
    </default>
    <default class="hand_linkerhand_o6_joint">
      <joint armature="3.4707e-08" damping="5.0" frictionloss="0.5"/>
    </default>
  </default>

  <asset>
    <mesh name="hand_base"               file="hand_base_link.STL"/>
    <mesh name="thumb_metacarpals_base2" file="thumb_metacarpals_base2.STL"/>
    <mesh name="thumb_metacarpals"       file="thumb_metacarpals.STL"/>
    <mesh name="thumb_distal"            file="thumb_distal.STL"/>
    <mesh name="index_proximal"          file="index_proximal.STL"/>
    <mesh name="index_distal"            file="index_distal.STL"/>
    <mesh name="middle_proximal"         file="middle_proximal.STL"/>
    <mesh name="middle_distal"           file="middle_distal.STL"/>
    <mesh name="ring_proximal"           file="ring_proximal.STL"/>
    <mesh name="ring_distal"             file="ring_distal.STL"/>
    <mesh name="pinky_proximal"          file="pinky_proximal.STL"/>
    <mesh name="pinky_distal"            file="pinky_distal.STL"/>
  </asset>

  <worldbody>
    <body name="rh_hand_base_link" pos="0 0 0">
      <inertial pos="-0.00160320773490556 0.000358462699237561 0.0538002704027215" mass="0.06740077960995"
                fullinertia="5.22359941041901E-05 3.33473043513648E-05 2.28342677422006E-05 3.0391535852764E-07 3.88322215371643E-07 -7.77555280794861E-07"/>
      <geom class="hand_linkerhand_o6_visual" mesh="hand_base"/>
      <geom class="hand_linkerhand_o6_collision" mesh="hand_base"/>
      <site name="wrist_mount" pos="0 0 0"/>

      <body name="rh_thumb_metacarpals_base2" pos="0.011508 0.022975 0.032794">
        <inertial pos="0.00162795738393507 0.00276671978336815 -0.00184227725602707" mass="0.00138591070212997"
                  fullinertia="5.26294625624223E-08 4.82623724532942E-08 2.88555522060562E-08 -3.9288013799604E-09 2.43766268199571E-09 3.71867754115443E-09"/>
        <joint name="rh_thumb_cmc_yaw" class="hand_linkerhand_o6_joint" type="hinge" axis="0 0 -1" range="0 1.36"/>
        <geom class="hand_linkerhand_o6_visual" mesh="thumb_metacarpals_base2"/>
        <geom class="hand_linkerhand_o6_collision" mesh="thumb_metacarpals_base2"/>

        <body name="rh_thumb_metacarpals" pos="0.0061649 0.010678 -0.004891" euler="0 -1.1529 -2.0944">
          <inertial pos="4.24920612856275E-05 -1.67885666835232E-05 0.0228341522590467" mass="0.0123381607727595"
                    fullinertia="1.10292488693766E-06 1.76757658485787E-06 9.36348143657406E-07 -6.14241939151719E-10 1.14233108676795E-07 -4.24576599367025E-10"/>
          <joint name="rh_thumb_cmc_pitch" class="hand_linkerhand_o6_joint" type="hinge" axis="0 1 0" range="0 0.58"/>
          <geom class="hand_linkerhand_o6_visual" mesh="thumb_metacarpals"/>
          <geom class="hand_linkerhand_o6_collision" mesh="thumb_metacarpals"/>

          <body name="rh_thumb_distal" pos="0.0037776 0 0.045368">
            <inertial pos="-0.00413690727496815 -4.54842793429222E-07 0.0230097179163771" mass="0.00763302603723749"
                      fullinertia="1.30546842791578E-06 1.22457212713176E-06 2.7729897944409E-07 -2.61617511029467E-12 7.19030685242407E-08 1.66931068485225E-11"/>
            <joint name="rh_thumb_ip" class="hand_linkerhand_o6_joint" type="hinge" axis="0 1 0" range="0 1.08"/>
            <geom class="hand_linkerhand_o6_visual" mesh="thumb_distal"/>
            <geom class="hand_linkerhand_o6_collision" mesh="thumb_distal"/>
          </body>
        </body>
      </body>

      <body name="rh_index_proximal" pos="0.0024758 0.02419 0.098779" euler="-0.05236 0 0">
        <inertial pos="-0.00208665596033792 -4.8964990644329E-06 0.0172736718900068" mass="0.00253178529301663"
                  fullinertia="2.65990159539482E-07 2.72915460277804E-07 8.56026306687528E-08 -3.55165625722842E-11 4.31046335852167E-08 1.75935978708959E-10"/>
        <joint name="rh_index_mcp_pitch" class="hand_linkerhand_o6_joint" type="hinge" axis="0 1 0" range="0 1.60"/>
        <geom class="hand_linkerhand_o6_visual" mesh="index_proximal"/>
        <geom class="hand_linkerhand_o6_collision" mesh="index_proximal"/>

        <body name="rh_index_distal" pos="-0.0052516 0 0.036625">
          <inertial pos="0.00658940011630532 -4.59976557022623E-06 0.0194434136420913" mass="0.00376787129082313"
                    fullinertia="3.22116619426455E-07 3.65131844686317E-07 1.24256890612907E-07 1.03152735699049E-11 -1.14363506430985E-07 -1.97263639269362E-10"/>
          <joint name="rh_index_dip" class="hand_linkerhand_o6_joint" type="hinge" axis="0 1 0" range="0 1.43"/>
          <geom class="hand_linkerhand_o6_visual" mesh="index_distal"/>
          <geom class="hand_linkerhand_o6_collision" mesh="index_distal"/>
        </body>
      </body>

      <body name="rh_middle_proximal" pos="0.00052576 0.00634 0.1027">
        <inertial pos="-0.00208661081773556 -4.93451838476378E-06 0.0172736805321904" mass="0.00253175497594429"
                  fullinertia="2.65989683690695E-07 2.72915006047006E-07 8.56020467202518E-08 -3.58343951791586E-11 4.31048601085216E-08 1.75718024412593E-10"/>
        <joint name="rh_middle_mcp_pitch" class="hand_linkerhand_o6_joint" type="hinge" axis="0 1 0" range="0 1.60"/>
        <geom class="hand_linkerhand_o6_visual" mesh="middle_proximal"/>
        <geom class="hand_linkerhand_o6_collision" mesh="middle_proximal"/>

        <body name="rh_middle_distal" pos="-0.0052516 0 0.036625">
          <inertial pos="0.00658940304809306 -4.5885743593238E-06 0.0194434523296449" mass="0.00376786259758948"
                    fullinertia="3.221153658306E-07 3.65130723083104E-07 1.24256787913797E-07 1.02639617308432E-11 -1.14363547272711E-07 -1.96904618797577E-10"/>
          <joint name="rh_middle_dip" class="hand_linkerhand_o6_joint" type="hinge" axis="0 1 0" range="0 1.43"/>
          <geom class="hand_linkerhand_o6_visual" mesh="middle_distal"/>
          <geom class="hand_linkerhand_o6_collision" mesh="middle_distal"/>
        </body>
      </body>

      <body name="rh_ring_proximal" pos="0.0010258 -0.011135 0.098767" euler="0.05236 0 0">
        <inertial pos="-0.00208654311325356 -4.98538564003281E-06 0.0172736743497407" mass="0.00253170963529411"
                  fullinertia="2.6598913795678E-07 2.72914417061517E-07 8.56012458677515E-08 -3.62757108675266E-11 4.31050611555507E-08 1.75554984053478E-10"/>
        <joint name="rh_ring_mcp_pitch" class="hand_linkerhand_o6_joint" type="hinge" axis="0 1 0" range="0 1.60"/>
        <geom class="hand_linkerhand_o6_visual" mesh="ring_proximal"/>
        <geom class="hand_linkerhand_o6_collision" mesh="ring_proximal"/>

        <body name="rh_ring_distal" pos="-0.0052516 0 0.036625">
          <inertial pos="0.00658940273069729 -4.56628863591824E-06 0.0194435005686854" mass="0.0037678395356105"
                    fullinertia="3.22112632437858E-07 3.65128262095686E-07 1.24256284608064E-07 1.01848408913558E-11 -1.1436348915342E-07 -1.96145632992445E-10"/>
          <joint name="rh_ring_dip" class="hand_linkerhand_o6_joint" type="hinge" axis="0 1 0" range="0 1.43"/>
          <geom class="hand_linkerhand_o6_visual" mesh="ring_distal"/>
          <geom class="hand_linkerhand_o6_collision" mesh="ring_distal"/>
        </body>
      </body>

      <body name="rh_pinky_proximal" pos="0.0024758 -0.028372 0.092741" euler="0.087266 0 0">
        <inertial pos="-0.00208649034130813 -5.02314582560837E-06 0.0172736680793697" mass="0.00253167400540778"
                  fullinertia="2.65988718820404E-07 2.72913936904813E-07 8.56006424720129E-08 -3.66012295280295E-11 4.31052220484445E-08 1.75447396222308E-10"/>
        <joint name="rh_pinky_mcp_pitch" class="hand_linkerhand_o6_joint" type="hinge" axis="0 1 0" range="0 1.60"/>
        <geom class="hand_linkerhand_o6_visual" mesh="pinky_proximal"/>
        <geom class="hand_linkerhand_o6_collision" mesh="pinky_proximal"/>

        <body name="rh_pinky_distal" pos="-0.0052516 0 0.036625">
          <inertial pos="0.00658940431519205 -4.55268314210333E-06 0.0194435341098305" mass="0.00376782669873412"
                    fullinertia="3.22111112339498E-07 3.65126916899176E-07 1.24256004854426E-07 1.01707985908333E-11 -1.14363524419061E-07 -1.95589215866356E-10"/>
          <joint name="rh_pinky_dip" class="hand_linkerhand_o6_joint" type="hinge" axis="0 1 0" range="0 1.43"/>
          <geom class="hand_linkerhand_o6_visual" mesh="pinky_distal"/>
          <geom class="hand_linkerhand_o6_collision" mesh="pinky_distal"/>
        </body>
      </body>
    </body>
  </worldbody>

  <actuator>
    <position name="rh_thumb_cmc_yaw_act"    joint="rh_thumb_cmc_yaw"    kp="20" kv="2" ctrlrange="0 1.36"/>
    <position name="rh_thumb_cmc_pitch_act"  joint="rh_thumb_cmc_pitch"  kp="20" kv="2" ctrlrange="0 0.58"/>
    <position name="rh_index_mcp_pitch_act"  joint="rh_index_mcp_pitch"  kp="20" kv="2" ctrlrange="0 1.60"/>
    <position name="rh_middle_mcp_pitch_act" joint="rh_middle_mcp_pitch" kp="20" kv="2" ctrlrange="0 1.60"/>
    <position name="rh_ring_mcp_pitch_act"   joint="rh_ring_mcp_pitch"   kp="20" kv="2" ctrlrange="0 1.60"/>
    <position name="rh_pinky_mcp_pitch_act"  joint="rh_pinky_mcp_pitch"  kp="20" kv="2" ctrlrange="0 1.60"/>
  </actuator>

  <equality>
    <joint name="rh_couple_thumb"  joint1="rh_thumb_ip"     joint2="rh_thumb_cmc_pitch"  polycoef="0 1.86 0 0 0"/>
    <joint name="rh_couple_index"  joint1="rh_index_dip"    joint2="rh_index_mcp_pitch"  polycoef="0 0.89 0 0 0"/>
    <joint name="rh_couple_middle" joint1="rh_middle_dip"   joint2="rh_middle_mcp_pitch" polycoef="0 0.89 0 0 0"/>
    <joint name="rh_couple_ring"   joint1="rh_ring_dip"     joint2="rh_ring_mcp_pitch"   polycoef="0 0.89 0 0 0"/>
    <joint name="rh_couple_pinky"  joint1="rh_pinky_dip"    joint2="rh_pinky_mcp_pitch"  polycoef="0 0.89 0 0 0"/>
  </equality>

  <contact>
    <exclude body1="rh_hand_base_link"          body2="rh_thumb_metacarpals_base2"/>
    <exclude body1="rh_thumb_metacarpals_base2" body2="rh_thumb_metacarpals"/>
    <exclude body1="rh_thumb_metacarpals"       body2="rh_thumb_distal"/>
    <exclude body1="rh_hand_base_link"          body2="rh_index_proximal"/>
    <exclude body1="rh_index_proximal"          body2="rh_index_distal"/>
    <exclude body1="rh_hand_base_link"          body2="rh_middle_proximal"/>
    <exclude body1="rh_middle_proximal"         body2="rh_middle_distal"/>
    <exclude body1="rh_hand_base_link"          body2="rh_ring_proximal"/>
    <exclude body1="rh_ring_proximal"           body2="rh_ring_distal"/>
    <exclude body1="rh_hand_base_link"          body2="rh_pinky_proximal"/>
    <exclude body1="rh_pinky_proximal"          body2="rh_pinky_distal"/>
  </contact>
</mujoco>
