<mujoco model="linkerhand_l25_right">
  <compiler meshdir="meshes" discardvisual="false" autolimits="true" angle="radian" eulerseq="XYZ"/>
  <option/>

  <default>
    <default class="hand_linkerhand_l25_visual">
      <geom type="mesh" contype="0" conaffinity="0" group="1"/>
    </default>
    <default class="hand_linkerhand_l25_collision">
      <geom type="mesh" contype="1" conaffinity="1" group="3"/>
    </default>
    <default class="hand_linkerhand_l25_joint">
      <joint armature="3.4707e-08" damping="4.0" frictionloss="0.5"/>
    </default>
  </default>

  <asset>
    <mesh name="hand_base_link" file="hand_base_link.STL"/>
    <mesh name="thumb_metacarpals_base1" file="thumb_metacarpals_base1.STL"/>
    <mesh name="thumb_metacarpals_base2" file="thumb_metacarpals_base2.STL"/>
    <mesh name="thumb_metacarpals" file="thumb_metacarpals.STL"/>
    <mesh name="thumb_proximal" file="thumb_proximal.STL"/>
    <mesh name="thumb_distal" file="thumb_distal.STL"/>
    <mesh name="index_metacarpals" file="index_metacarpals.STL"/>
    <mesh name="index_proximal" file="index_proximal.STL"/>
    <mesh name="index_middle" file="index_middle.STL"/>
    <mesh name="index_distal" file="index_distal.STL"/>
    <mesh name="middle_metacarpals" file="middle_metacarpals.STL"/>
    <mesh name="middle_proximal" file="middle_proximal.STL"/>
    <mesh name="middle_middle" file="middle_middle.STL"/>
    <mesh name="middle_distal" file="middle_distal.STL"/>
    <mesh name="ring_metacarpals" file="ring_metacarpals.STL"/>
    <mesh name="ring_proximal" file="ring_proximal.STL"/>
    <mesh name="ring_middle" file="ring_middle.STL"/>
    <mesh name="ring_distal" file="ring_distal.STL"/>
    <mesh name="pinky_metacarpals" file="pinky_metacarpals.STL"/>
    <mesh name="pinky_proximal" file="pinky_proximal.STL"/>
    <mesh name="pinky_middle" file="pinky_middle.STL"/>
    <mesh name="pinky_distal" file="pinky_distal.STL"/>
  </asset>

  <worldbody>
    <body name="rh_hand_base_link" pos="0 0 0">
      <inertial pos="-0.0023553326597099 -0.000476950676809626 0.0840274681191193" mass="0.130043890829375" fullinertia="0.000269869493590648 0.000164906210534713 0.000118834524369526 -5.66836728555976e-07 1.0791938448155e-06 4.94586055862009e-06"/>
      <geom class="hand_linkerhand_l25_visual" mesh="hand_base_link"/>
      <geom class="hand_linkerhand_l25_collision" mesh="hand_base_link"/>
      <site name="wrist_mount" pos="0 0 0"/>
      <body name="rh_thumb_metacarpals_base1" pos="0.01916 0.01 0.0436">
        <inertial pos="0.0121300685642492 -0.00368626401900367 0.000253013805235423" mass="0.0173128324517923" fullinertia="4.04974890264239e-06 2.43513754798381e-06 2.09347392894973e-06 -1.31074266242452e-07 -7.53905165403527e-09 1.46366596393199e-07"/>
        <joint name="rh_thumb_cmc_roll" class="hand_linkerhand_l25_joint" type="hinge" axis="1 0 0" range="0 1.309"/>
        <geom class="hand_linkerhand_l25_visual" mesh="thumb_metacarpals_base1"/>
        <geom class="hand_linkerhand_l25_collision" mesh="thumb_metacarpals_base1"/>
        <body name="rh_thumb_metacarpals_base2" pos="0.019845 0 0" euler="-0.77165 0 0">
          <inertial pos="0.00274804892423072 0.00768600825377847 0.00362008971119372" mass="0.0129293097380942" fullinertia="1.760752912378147e-06 7.758748827283011e-07 1.450608374471467e-06 3.5029507180292e-07 -1.32342776895603e-07 -3.69293599975358e-07"/>
          <joint name="rh_thumb_cmc_yaw" class="hand_linkerhand_l25_joint" type="hinge" axis="0 0 -1" range="0 1.5882"/>
          <geom class="hand_linkerhand_l25_visual" mesh="thumb_metacarpals_base2"/>
          <geom class="hand_linkerhand_l25_collision" mesh="thumb_metacarpals_base2"/>
          <body name="rh_thumb_metacarpals" pos="0.0088264 0.024243 0.0005" euler="0 -0.91 -1.9199">
            <inertial pos="0.00680467489235993 -0.000348945978923473 0.0329029974283304" mass="0.0311449727019751" fullinertia="1.14965619264847e-05 1.37913772817647e-05 3.56917509196916e-06 -1.14093661337383e-08 5.08562599330683e-08 2.39355105126118e-08"/>
            <joint name="rh_thumb_cmc_pitch" class="hand_linkerhand_l25_joint" type="hinge" axis="0 1 0" range="0 0.7854"/>
            <geom class="hand_linkerhand_l25_visual" mesh="thumb_metacarpals"/>
            <geom class="hand_linkerhand_l25_collision" mesh="thumb_metacarpals"/>
            <body name="rh_thumb_proximal" pos="0.012702 0 0.062726">
              <inertial pos="-0.00268743345276515 0.000568290980153867 0.0118503606835096" mass="0.00549015851204037" fullinertia="4.78349857032437e-07 6.23171205283375e-07 2.34919130274949e-07 4.61712014179472e-11 5.4113877466635e-08 5.11556682719536e-09"/>
              <joint name="rh_thumb_mcp" class="hand_linkerhand_l25_joint" type="hinge" axis="0 1 0" range="0 1.2217"/>
              <geom class="hand_linkerhand_l25_visual" mesh="thumb_proximal"/>
              <geom class="hand_linkerhand_l25_collision" mesh="thumb_proximal"/>
              <body name="rh_thumb_distal" pos="-0.0048365 0 0.034223">
                <inertial pos="-0.000650482106033023 2.41300573138245e-05 0.0111942838051236" mass="0.00585464206993151" fullinertia="3.37157269656711e-07 4.37703462647265e-07 1.85639673847353e-07 3.69307135027908e-10 -1.12308316041907e-07 -9.3624675389561e-10"/>
                <joint name="rh_thumb_dip" class="hand_linkerhand_l25_joint" type="hinge" axis="0 1 0" range="0 1.2392"/>
                <geom class="hand_linkerhand_l25_visual" mesh="thumb_distal"/>
                <geom class="hand_linkerhand_l25_collision" mesh="thumb_distal"/>
              </body>
            </body>
          </body>
        </body>
      </body>
      <body name="rh_index_metacarpals" pos="0.0038 0.03525 0.1481">
        <inertial pos="-0.00794297216778595 3.01910607593964e-07 0.00220112291424343" mass="0.000895533942236676" fullinertia="3.46286808249453e-08 2.85439868980493e-08 4.38105935701441e-08 5.20721113539202e-13 5.91055676999344e-09 6.15915602928681e-13"/>
        <joint name="rh_index_mcp_roll" class="hand_linkerhand_l25_joint" type="hinge" axis="-1 0 0" range="-0.2269 0.2269"/>
        <geom class="hand_linkerhand_l25_visual" mesh="index_metacarpals"/>
        <geom class="hand_linkerhand_l25_collision" mesh="index_metacarpals"/>
        <body name="rh_index_proximal" pos="-0.0021302 0 0">
          <inertial pos="-0.00114165889805229 -3.47779025311364e-05 0.0228930740987338" mass="0.00450935628154297" fullinertia="6.66693338335738e-07 6.74214594716538e-07 1.3576088799113e-07 1.00781853152623e-11 -2.53156876802064e-08 1.59197443844205e-10"/>
          <joint name="rh_index_mcp_pitch" class="hand_linkerhand_l25_joint" type="hinge" axis="0 1 0" range="0 1.2217"/>
          <geom class="hand_linkerhand_l25_visual" mesh="index_proximal"/>
          <geom class="hand_linkerhand_l25_collision" mesh="index_proximal"/>
          <body name="rh_index_middle" pos="-0.0041946 0 0.044819">
            <inertial pos="-0.000206830314670474 -2.69762827288106e-06 0.0167055565294545" mass="0.00237861824163327" fullinertia="2.29584431475404e-07 1.76802239049368e-07 9.62875380319572e-08 -3.79527882007371e-12 -1.47269516053005e-08 3.59871792473524e-13"/>
            <joint name="rh_index_pip" class="hand_linkerhand_l25_joint" type="hinge" axis="0 1 0" range="0 1.7279"/>
            <geom class="hand_linkerhand_l25_visual" mesh="index_middle"/>
            <geom class="hand_linkerhand_l25_collision" mesh="index_middle"/>
            <body name="rh_index_distal" pos="0.0028245 0 0.031696">
              <inertial pos="-0.00816260402461631 -2.26721604493323e-05 0.00811819722869647" mass="0.00334176238570705" fullinertia="1.59568900399119e-07 1.78096631602274e-07 1.34139906914153e-07 -1.52271643281661e-10 -5.94266141046017e-08 1.23981970768957e-10"/>
              <joint name="rh_index_dip" class="hand_linkerhand_l25_joint" type="hinge" axis="0 1 0" range="0 1.3614"/>
              <geom class="hand_linkerhand_l25_visual" mesh="index_distal"/>
              <geom class="hand_linkerhand_l25_collision" mesh="index_distal"/>
            </body>
          </body>
        </body>
      </body>
      <body name="rh_middle_metacarpals" pos="0.0038 0.01175 0.1526">
        <inertial pos="-0.00794297217144934 3.01910607571412e-07 0.00220112291424346" mass="0.000895533942236672" fullinertia="3.46286808249452e-08 2.85439868980493e-08 4.3810593570144e-08 5.20721113361698e-13 5.91055676999347e-09 6.15915602825396e-13"/>
        <joint name="rh_middle_mcp_roll" class="hand_linkerhand_l25_joint" type="hinge" axis="-1 0 0" range="-0.23 0.23"/>
        <geom class="hand_linkerhand_l25_visual" mesh="middle_metacarpals"/>
        <geom class="hand_linkerhand_l25_collision" mesh="middle_metacarpals"/>
        <body name="rh_middle_proximal" pos="-0.0021302 0 0">
          <inertial pos="-0.00114165889805231 -3.47779025311071e-05 0.0228930740987338" mass="0.00450935628154299" fullinertia="6.66693338335741e-07 6.74214594716535e-07 1.35760887991121e-07 1.00781853158879e-11 -2.53156876802067e-08 1.59197443844791e-10"/>
          <joint name="rh_middle_mcp_pitch" class="hand_linkerhand_l25_joint" type="hinge" axis="0 1 0" range="0 1.2217"/>
          <geom class="hand_linkerhand_l25_visual" mesh="middle_proximal"/>
          <geom class="hand_linkerhand_l25_collision" mesh="middle_proximal"/>
          <body name="rh_middle_middle" pos="-0.0041946 0 0.044819">
            <inertial pos="-0.000206830311076763 -2.69763200638285e-06 0.0167055565392871" mass="0.00237861824399121" fullinertia="2.2958443176697e-07 1.76802239346606e-07 9.62875381090068e-08 -3.79531728857531e-12 -1.47269515025648e-08 3.59776198217398e-13"/>
            <joint name="rh_middle_pip" class="hand_linkerhand_l25_joint" type="hinge" axis="0 1 0" range="0 1.7279"/>
            <geom class="hand_linkerhand_l25_visual" mesh="middle_middle"/>
            <geom class="hand_linkerhand_l25_collision" mesh="middle_middle"/>
            <body name="rh_middle_distal" pos="0.0028245 0 0.031696">
              <inertial pos="-0.00816260402458386 -2.26721612610642e-05 0.00811819722943347" mass="0.0033417623857295" fullinertia="1.59568900407287e-07 1.78096631550001e-07 1.34139906932954e-07 -1.52271672185911e-10 -5.94266141070478e-08 1.23981962913402e-10"/>
              <joint name="rh_middle_dip" class="hand_linkerhand_l25_joint" type="hinge" axis="0 1 0" range="0 1.3614"/>
              <geom class="hand_linkerhand_l25_visual" mesh="middle_distal"/>
              <geom class="hand_linkerhand_l25_collision" mesh="middle_distal"/>
            </body>
          </body>
        </body>
      </body>
      <body name="rh_ring_metacarpals" pos="0.0038 -0.01175 0.1481">
        <inertial pos="-0.00794297217511273 3.01910607531514e-07 0.00220112291424343" mass="0.00089553394223667" fullinertia="3.4628680824945e-08 2.8543986898049e-08 4.38105935701438e-08 5.2072111337213e-13 5.91055676999336e-09 6.15915602738524e-13"/>
        <joint name="rh_ring_mcp_roll" class="hand_linkerhand_l25_joint" type="hinge" axis="-1 0 0" range="-0.23 0.23"/>
        <geom class="hand_linkerhand_l25_visual" mesh="ring_metacarpals"/>
        <geom class="hand_linkerhand_l25_collision" mesh="ring_metacarpals"/>
        <body name="rh_ring_proximal" pos="-0.0021302 0 0">
          <inertial pos="-0.00114165889805229 -3.47779025311641e-05 0.0228930740987337" mass="0.00450935628154299" fullinertia="6.66693338335738e-07 6.74214594716548e-07 1.3576088799114e-07 1.00781853170701e-11 -2.53156876802064e-08 1.59197443843837e-10"/>
          <joint name="rh_ring_mcp_pitch" class="hand_linkerhand_l25_joint" type="hinge" axis="0 1 0" range="0 1.2217"/>
          <geom class="hand_linkerhand_l25_visual" mesh="ring_proximal"/>
          <geom class="hand_linkerhand_l25_collision" mesh="ring_proximal"/>
          <body name="rh_ring_middle" pos="-0.0041946 0 0.044819">
            <inertial pos="-0.000206830314670712 -2.69762827293657e-06 0.0167055565294543" mass="0.00237861824163314" fullinertia="2.29584431475388e-07 1.76802239049448e-07 9.62875380320043e-08 -3.79527881056473e-12 -1.47269516053097e-08 3.59871797815951e-13"/>
            <joint name="rh_ring_pip" class="hand_linkerhand_l25_joint" type="hinge" axis="0 1 0" range="0 1.7279"/>
            <geom class="hand_linkerhand_l25_visual" mesh="ring_middle"/>
            <geom class="hand_linkerhand_l25_collision" mesh="ring_middle"/>
            <body name="rh_ring_distal" pos="0.0028245 0 0.031696">
              <inertial pos="-0.00816260402385198 -2.26723442381116e-05 0.00811819722787116" mass="0.00334176238553782" fullinertia="1.59568900413529e-07 1.78096631554275e-07 1.34139906897543e-07 -1.5226555011147e-10 -5.9426614092103e-08 1.23978578539056e-10"/>
              <joint name="rh_ring_dip" class="hand_linkerhand_l25_joint" type="hinge" axis="0 1 0" range="0 1.3614"/>
              <geom class="hand_linkerhand_l25_visual" mesh="ring_distal"/>
              <geom class="hand_linkerhand_l25_collision" mesh="ring_distal"/>
            </body>
          </body>
        </body>
      </body>
      <body name="rh_pinky_metacarpals" pos="0.0038 -0.03525 0.1436">
        <inertial pos="-0.00794297217877612 3.019106075558e-07 0.00220112291424343" mass="0.000895533942236661" fullinertia="3.46286808249448e-08 2.85439868980489e-08 4.38105935701437e-08 5.20721113385638e-13 5.91055676999334e-09 6.15915602787648e-13"/>
        <joint name="rh_pinky_mcp_roll" class="hand_linkerhand_l25_joint" type="hinge" axis="-1 0 0" range="-0.23 0.23"/>
        <geom class="hand_linkerhand_l25_visual" mesh="pinky_metacarpals"/>
        <geom class="hand_linkerhand_l25_collision" mesh="pinky_metacarpals"/>
        <body name="rh_pinky_proximal" pos="-0.0021302 0 0">
          <inertial pos="-0.00114165890216106 -3.47779084241967e-05 0.0228930741124087" mass="0.00450935627773312" fullinertia="6.6669333754323e-07 6.74214593816853e-07 1.35760887844139e-07 1.00781372651744e-11 -2.53156873668278e-08 1.59197565505674e-10"/>
          <joint name="rh_pinky_mcp_pitch" class="hand_linkerhand_l25_joint" type="hinge" axis="0 1 0" range="0 1.2217"/>
          <geom class="hand_linkerhand_l25_visual" mesh="pinky_proximal"/>
          <geom class="hand_linkerhand_l25_collision" mesh="pinky_proximal"/>
          <body name="rh_pinky_middle" pos="-0.0041946 0 0.044819">
            <inertial pos="-0.000206830314670489 -2.69762827287412e-06 0.0167055565294545" mass="0.0023786182416333" fullinertia="2.29584431475459e-07 1.76802239049466e-07 9.62875380320415e-08 -3.79527884680841e-12 -1.47269516053079e-08 3.5987180643017e-13"/>
            <joint name="rh_pinky_pip" class="hand_linkerhand_l25_joint" type="hinge" axis="0 1 0" range="0 1.7279"/>
            <geom class="hand_linkerhand_l25_visual" mesh="pinky_middle"/>
            <geom class="hand_linkerhand_l25_collision" mesh="pinky_middle"/>
            <body name="rh_pinky_distal" pos="0.0028245 0 0.031696">
              <inertial pos="-0.00816260391299546 -2.26722056161019e-05 0.00811819704290559" mass="0.00334176233214274" fullinertia="1.59568898336975e-07 1.78096625944569e-07 1.3413990252827e-07 -1.52270106341856e-10 -5.94266114992739e-08 1.23981107883524e-10"/>
              <joint name="rh_pinky_dip" class="hand_linkerhand_l25_joint" type="hinge" axis="0 1 0" range="0 1.3614"/>
              <geom class="hand_linkerhand_l25_visual" mesh="pinky_distal"/>
              <geom class="hand_linkerhand_l25_collision" mesh="pinky_distal"/>
            </body>
          </body>
        </body>
      </body>
    </body>
  </worldbody>

  <actuator>
    <position name="rh_thumb_cmc_roll_act" joint="rh_thumb_cmc_roll" kp="200" kv="0" ctrlrange="0 1.309"/>
    <position name="rh_thumb_cmc_yaw_act" joint="rh_thumb_cmc_yaw" kp="200" kv="0" ctrlrange="0 1.5882"/>
    <position name="rh_thumb_cmc_pitch_act" joint="rh_thumb_cmc_pitch" kp="200" kv="0" ctrlrange="0 0.7854"/>
    <position name="rh_thumb_mcp_act" joint="rh_thumb_mcp" kp="200" kv="0" ctrlrange="0 1.2217"/>
    <position name="rh_index_mcp_roll_act" joint="rh_index_mcp_roll" kp="200" kv="0" ctrlrange="-0.2269 0.2269"/>
    <position name="rh_index_mcp_pitch_act" joint="rh_index_mcp_pitch" kp="200" kv="0" ctrlrange="0 1.2217"/>
    <position name="rh_index_pip_act" joint="rh_index_pip" kp="200" kv="0" ctrlrange="0 1.7279"/>
    <position name="rh_middle_mcp_roll_act" joint="rh_middle_mcp_roll" kp="200" kv="0" ctrlrange="-0.23 0.23"/>
    <position name="rh_middle_mcp_pitch_act" joint="rh_middle_mcp_pitch" kp="200" kv="0" ctrlrange="0 1.2217"/>
    <position name="rh_middle_pip_act" joint="rh_middle_pip" kp="200" kv="0" ctrlrange="0 1.7279"/>
    <position name="rh_ring_mcp_roll_act" joint="rh_ring_mcp_roll" kp="200" kv="0" ctrlrange="-0.23 0.23"/>
    <position name="rh_ring_mcp_pitch_act" joint="rh_ring_mcp_pitch" kp="200" kv="0" ctrlrange="0 1.2217"/>
    <position name="rh_ring_pip_act" joint="rh_ring_pip" kp="200" kv="0" ctrlrange="0 1.7279"/>
    <position name="rh_pinky_mcp_roll_act" joint="rh_pinky_mcp_roll" kp="200" kv="0" ctrlrange="-0.23 0.23"/>
    <position name="rh_pinky_mcp_pitch_act" joint="rh_pinky_mcp_pitch" kp="200" kv="0" ctrlrange="0 1.2217"/>
    <position name="rh_pinky_pip_act" joint="rh_pinky_pip" kp="200" kv="0" ctrlrange="0 1.7279"/>
  </actuator>

  <equality>
    <joint name="rh_couple_thumb_dip" joint1="rh_thumb_dip" joint2="rh_thumb_mcp" polycoef="0 1.0142 0 0 0"/>
    <joint name="rh_couple_index_dip" joint1="rh_index_dip" joint2="rh_index_pip" polycoef="0 0.7879 0 0 0"/>
    <joint name="rh_couple_middle_dip" joint1="rh_middle_dip" joint2="rh_middle_pip" polycoef="0 0.7879 0 0 0"/>
    <joint name="rh_couple_ring_dip" joint1="rh_ring_dip" joint2="rh_ring_pip" polycoef="0 0.7879 0 0 0"/>
    <joint name="rh_couple_pinky_dip" joint1="rh_pinky_dip" joint2="rh_pinky_pip" polycoef="0 0.7879 0 0 0"/>
  </equality>

  <contact>
    <exclude body1="rh_hand_base_link" body2="rh_thumb_metacarpals_base1"/>
    <exclude body1="rh_thumb_metacarpals_base1" body2="rh_thumb_metacarpals_base2"/>
    <exclude body1="rh_thumb_metacarpals_base2" body2="rh_thumb_metacarpals"/>
    <exclude body1="rh_thumb_metacarpals" body2="rh_thumb_proximal"/>
    <exclude body1="rh_thumb_proximal" body2="rh_thumb_distal"/>
    <exclude body1="rh_hand_base_link" body2="rh_index_metacarpals"/>
    <exclude body1="rh_index_metacarpals" body2="rh_index_proximal"/>
    <exclude body1="rh_index_proximal" body2="rh_index_middle"/>
    <exclude body1="rh_index_middle" body2="rh_index_distal"/>
    <exclude body1="rh_hand_base_link" body2="rh_middle_metacarpals"/>
    <exclude body1="rh_middle_metacarpals" body2="rh_middle_proximal"/>
    <exclude body1="rh_middle_proximal" body2="rh_middle_middle"/>
    <exclude body1="rh_middle_middle" body2="rh_middle_distal"/>
    <exclude body1="rh_hand_base_link" body2="rh_ring_metacarpals"/>
    <exclude body1="rh_ring_metacarpals" body2="rh_ring_proximal"/>
    <exclude body1="rh_ring_proximal" body2="rh_ring_middle"/>
    <exclude body1="rh_ring_middle" body2="rh_ring_distal"/>
    <exclude body1="rh_hand_base_link" body2="rh_pinky_metacarpals"/>
    <exclude body1="rh_pinky_metacarpals" body2="rh_pinky_proximal"/>
    <exclude body1="rh_pinky_proximal" body2="rh_pinky_middle"/>
    <exclude body1="rh_pinky_middle" body2="rh_pinky_distal"/>
    <exclude body1="rh_hand_base_link" body2="rh_index_proximal"/>
    <exclude body1="rh_hand_base_link" body2="rh_middle_proximal"/>
    <exclude body1="rh_hand_base_link" body2="rh_ring_proximal"/>
    <exclude body1="rh_hand_base_link" body2="rh_pinky_proximal"/>
    <exclude body1="rh_hand_base_link" body2="rh_thumb_metacarpals_base2"/>
    <exclude body1="rh_hand_base_link" body2="rh_thumb_metacarpals"/>
    <exclude body1="rh_thumb_metacarpals" body2="rh_thumb_metacarpals_base1"/>
  </contact>
</mujoco>
