<?xml version="1.0" encoding="UTF-8"?>
<!-- Generated by tools/composer (version 0.1.0). Workstation: a7_lite_dc. Recipe sha256: 1d0545c920f13ff11eb30906cf5e63a190738f9091b38806258c37c74a686c5d. Do not edit by hand; re-run `python -m tools.composer.compose <workstation>`. -->
<mujoco model="a7_lite_dc">
  <compiler discardvisual="false" autolimits="true" angle="radian" eulerseq="XYZ" />
  <option />
  <default>
    <default class="base_base_a7_lite_torso_visual">
      <geom type="mesh" contype="0" conaffinity="0" group="1" />
    </default>
    <default class="base_base_a7_lite_torso_collision">
      <geom type="mesh" contype="1" conaffinity="1" group="3" />
    </default>
    <default class="arm_left_arm_a7_lite_visual">
      <geom type="mesh" contype="0" conaffinity="0" group="1" />
    </default>
    <default class="arm_left_arm_a7_lite_collision">
      <geom type="mesh" contype="1" conaffinity="1" group="3" />
    </default>
    <default class="arm_right_arm_a7_lite_visual">
      <geom type="mesh" contype="0" conaffinity="0" group="1" />
    </default>
    <default class="arm_right_arm_a7_lite_collision">
      <geom type="mesh" contype="1" conaffinity="1" group="3" />
    </default>
    <default class="hand_left_hand_linkerhand_l6_visual">
      <geom type="mesh" contype="0" conaffinity="0" group="1" />
    </default>
    <default class="hand_left_hand_linkerhand_l6_collision">
      <geom type="mesh" contype="1" conaffinity="1" group="3" />
    </default>
    <default class="hand_left_hand_linkerhand_l6_joint">
      <joint armature="3.4707e-08" damping="5.0" frictionloss="0.5" />
    </default>
    <default class="hand_right_hand_linkerhand_l6_visual">
      <geom type="mesh" contype="0" conaffinity="0" group="1" />
    </default>
    <default class="hand_right_hand_linkerhand_l6_collision">
      <geom type="mesh" contype="1" conaffinity="1" group="3" />
    </default>
    <default class="hand_right_hand_linkerhand_l6_joint">
      <joint armature="3.4707e-08" damping="5.0" frictionloss="0.5" />
    </default>
  </default>
  <asset>
    <mesh name="base_torso_base_link" file="../../components/bases/a7_lite_torso/variants/default/meshes/base_link.STL" />
    <mesh name="arm_left_L1" file="../../components/arms/a7_lite/variants/left/meshes/L1_Link.STL" />
    <mesh name="arm_left_L2" file="../../components/arms/a7_lite/variants/left/meshes/L2_Link.STL" />
    <mesh name="arm_left_L3" file="../../components/arms/a7_lite/variants/left/meshes/L3_Link.STL" />
    <mesh name="arm_left_L4" file="../../components/arms/a7_lite/variants/left/meshes/L4_Link.STL" />
    <mesh name="arm_left_L5" file="../../components/arms/a7_lite/variants/left/meshes/L5_Link.STL" />
    <mesh name="arm_left_L6" file="../../components/arms/a7_lite/variants/left/meshes/L6_Link.STL" />
    <mesh name="arm_left_L7" file="../../components/arms/a7_lite/variants/left/meshes/L7_Link.STL" />
    <mesh name="arm_right_R1" file="../../components/arms/a7_lite/variants/right/meshes/R1_Link.STL" />
    <mesh name="arm_right_R2" file="../../components/arms/a7_lite/variants/right/meshes/R2_Link.STL" />
    <mesh name="arm_right_R3" file="../../components/arms/a7_lite/variants/right/meshes/R3_Link.STL" />
    <mesh name="arm_right_R4" file="../../components/arms/a7_lite/variants/right/meshes/R4_Link.STL" />
    <mesh name="arm_right_R5" file="../../components/arms/a7_lite/variants/right/meshes/R5_Link.STL" />
    <mesh name="arm_right_R6" file="../../components/arms/a7_lite/variants/right/meshes/R6_Link.STL" />
    <mesh name="arm_right_R7" file="../../components/arms/a7_lite/variants/right/meshes/R7_Link.STL" />
    <mesh name="hand_left_hand_base" file="../../components/hands/linkerhand_l6/variants/left/meshes/hand_base_link.STL" />
    <mesh name="hand_left_thumb_metacarpals_base1" file="../../components/hands/linkerhand_l6/variants/left/meshes/thumb_metacarpals_base1.STL" />
    <mesh name="hand_left_thumb_metacarpals" file="../../components/hands/linkerhand_l6/variants/left/meshes/thumb_metacarpals.STL" />
    <mesh name="hand_left_thumb_distal" file="../../components/hands/linkerhand_l6/variants/left/meshes/thumb_distal.STL" />
    <mesh name="hand_left_index_proximal" file="../../components/hands/linkerhand_l6/variants/left/meshes/index_proximal.STL" />
    <mesh name="hand_left_index_distal" file="../../components/hands/linkerhand_l6/variants/left/meshes/index_distal.STL" />
    <mesh name="hand_left_middle_proximal" file="../../components/hands/linkerhand_l6/variants/left/meshes/middle_proximal.STL" />
    <mesh name="hand_left_middle_distal" file="../../components/hands/linkerhand_l6/variants/left/meshes/middle_distal.STL" />
    <mesh name="hand_left_ring_proximal" file="../../components/hands/linkerhand_l6/variants/left/meshes/ring_proximal.STL" />
    <mesh name="hand_left_ring_distal" file="../../components/hands/linkerhand_l6/variants/left/meshes/ring_distal.STL" />
    <mesh name="hand_left_pinky_proximal" file="../../components/hands/linkerhand_l6/variants/left/meshes/pinky_proximal.STL" />
    <mesh name="hand_left_pinky_distal" file="../../components/hands/linkerhand_l6/variants/left/meshes/pinky_distal.STL" />
    <mesh name="hand_right_hand_base" file="../../components/hands/linkerhand_l6/variants/right/meshes/hand_base_link.STL" />
    <mesh name="hand_right_thumb_metacarpals_base1" file="../../components/hands/linkerhand_l6/variants/right/meshes/thumb_metacarpals_base1.STL" />
    <mesh name="hand_right_thumb_metacarpals" file="../../components/hands/linkerhand_l6/variants/right/meshes/thumb_metacarpals.STL" />
    <mesh name="hand_right_thumb_distal" file="../../components/hands/linkerhand_l6/variants/right/meshes/thumb_distal.STL" />
    <mesh name="hand_right_index_proximal" file="../../components/hands/linkerhand_l6/variants/right/meshes/index_proximal.STL" />
    <mesh name="hand_right_index_distal" file="../../components/hands/linkerhand_l6/variants/right/meshes/index_distal.STL" />
    <mesh name="hand_right_middle_proximal" file="../../components/hands/linkerhand_l6/variants/right/meshes/middle_proximal.STL" />
    <mesh name="hand_right_middle_distal" file="../../components/hands/linkerhand_l6/variants/right/meshes/middle_distal.STL" />
    <mesh name="hand_right_ring_proximal" file="../../components/hands/linkerhand_l6/variants/right/meshes/ring_proximal.STL" />
    <mesh name="hand_right_ring_distal" file="../../components/hands/linkerhand_l6/variants/right/meshes/ring_distal.STL" />
    <mesh name="hand_right_pinky_proximal" file="../../components/hands/linkerhand_l6/variants/right/meshes/pinky_proximal.STL" />
    <mesh name="hand_right_pinky_distal" file="../../components/hands/linkerhand_l6/variants/right/meshes/pinky_distal.STL" />
  </asset>
  <worldbody>
    <body name="base_torso_root" pos="0 0 0">
      <body name="base_base_link" pos="0 0 1.2">
        <inertial pos="0.0044493 9.5996E-07 -0.58827" mass="8.6616" fullinertia="0.19297 0.19297 0.072594 1.6977E-06 0.00086704 4.1272E-08" />
        <geom class="base_base_a7_lite_torso_visual" mesh="base_torso_base_link" />
        <geom class="base_base_a7_lite_torso_collision" mesh="base_torso_base_link" />
        <body name="base_arm_left_mount" pos="0.0062932 0.1505 -0.022706">
          <site name="base_arm_left_mount" pos="0 0 0" />
          <body name="arm_left_L_arm_root" pos="0 0 0">
            <site name="arm_left_base_mount" pos="0 0 0" />
            <body name="arm_left_L1_Link" pos="0 0 0">
              <inertial pos="0.0045974 0.067978 0.00066635" mass="1.1899" fullinertia="0.0016082 0.00086283 0.00092662 3.5266E-06 2.0532E-07 6.5642E-06" />
              <joint name="arm_left_L1_Joint" type="hinge" axis="0 -1 0" range="-2.18 3.75" damping="20" frictionloss="0.0" armature="0.01" />
              <geom class="arm_left_arm_a7_lite_visual" mesh="arm_left_L1" />
              <geom class="arm_left_arm_a7_lite_collision" mesh="arm_left_L1" />
              <body name="arm_left_L2_Link" pos="0.03125 0.0715 0">
                <inertial pos="-0.030894 9.2644E-05 -0.099437" mass="1.0659" fullinertia="0.001451 0.0012495 0.0010752 3.1371E-06 -1.519E-06 -1.1542E-05" />
                <joint name="arm_left_L2_Joint" type="hinge" axis="-1 0 0" range="-3.33 0.19" damping="20" frictionloss="0.0" armature="0.01" />
                <geom class="arm_left_arm_a7_lite_visual" mesh="arm_left_L2" />
                <geom class="arm_left_arm_a7_lite_collision" mesh="arm_left_L2" />
                <body name="arm_left_L3_Link" pos="-0.03125 0 -0.147">
                  <inertial pos="-5.9577E-05 0.001318 -0.078466" mass="1.2763" fullinertia="0.00078242 0.0010444 0.00063166 -2.9327E-07 7.1339E-06 -2.978E-07" />
                  <joint name="arm_left_L3_Joint" type="hinge" axis="0 0 1" range="-2.26 2.26" damping="20" frictionloss="0.0" armature="0.01" />
                  <geom class="arm_left_arm_a7_lite_visual" mesh="arm_left_L3" />
                  <geom class="arm_left_arm_a7_lite_collision" mesh="arm_left_L3" />
                  <body name="arm_left_L4_Link" pos="0 0.027 -0.126">
                    <inertial pos="1.6127E-05 -0.027094 -0.086199" mass="0.66812" fullinertia="0.00039892 0.00038456 0.00041366 5.379E-08 1.7668E-06 1.0506E-06" />
                    <joint name="arm_left_L4_Joint" type="hinge" axis="0 -1 0" range="-0.78 1.74" damping="20" frictionloss="0.0" armature="0.01" />
                    <geom class="arm_left_arm_a7_lite_visual" mesh="arm_left_L4" />
                    <geom class="arm_left_arm_a7_lite_collision" mesh="arm_left_L4" />
                    <body name="arm_left_L5_Link" pos="0 -0.027 -0.136">
                      <inertial pos="-0.00012977 0.0029474 -0.03886" mass="0.4439" fullinertia="0.00015511 0.00022136 0.00013737 -4.6133E-07 -2.6472E-06 -1.0454E-07" />
                      <joint name="arm_left_L5_Joint" type="hinge" axis="0 0 1" range="-2.96 2.96" damping="20" frictionloss="0.0" armature="0.01" />
                      <geom class="arm_left_arm_a7_lite_visual" mesh="arm_left_L5" />
                      <geom class="arm_left_arm_a7_lite_collision" mesh="arm_left_L5" />
                      <body name="arm_left_L6_Link" pos="0 0.028 -0.0435">
                        <inertial pos="0.0023746 -0.027691 -0.063927" mass="0.5193" fullinertia="0.00031746 0.00024364 0.00015858 -6.3455E-07 4.1005E-07 2.8635E-06" />
                        <joint name="arm_left_L6_Joint" type="hinge" axis="0 -1 0" range="-1.57 1.57" damping="20" frictionloss="0.0" armature="0.01" />
                        <geom class="arm_left_arm_a7_lite_visual" mesh="arm_left_L6" />
                        <geom class="arm_left_arm_a7_lite_collision" mesh="arm_left_L6" />
                        <body name="arm_left_L7_Link" pos="0.028 -0.028 -0.075">
                          <inertial pos="-0.026398 -6.6336E-15 -0.025801" mass="0.10175" fullinertia="4.5036E-05 3.8663E-05 3.0632E-05 -4.7046E-12 2.2349E-07 -1.9234E-20" />
                          <joint name="arm_left_L7_Joint" type="hinge" axis="-1 0 0" range="-1.57 1.57" damping="20" frictionloss="0.0" armature="0.01" />
                          <geom class="arm_left_arm_a7_lite_visual" mesh="arm_left_L7" />
                          <geom class="arm_left_arm_a7_lite_collision" mesh="arm_left_L7" />
                          <site name="arm_left_tool0" pos="0 0 0" />
                          <body name="hand_left_lh_hand_base_link" pos="0 0 0" euler="3.1416 0 -1.5708">
                            <inertial pos="0.00199 -0.00091 0.058381" mass="0.4185" fullinertia="0.0004998 0.0003567 0.0002301 0.000012853 -0.000008317 0.000010354" />
                            <geom class="hand_left_hand_linkerhand_l6_visual" mesh="hand_left_hand_base" />
                            <geom class="hand_left_hand_linkerhand_l6_collision" mesh="hand_left_hand_base" />
                            <site name="hand_left_wrist_mount" pos="0 0 0" />
                            <body name="hand_left_lh_thumb_metacarpals_base1" pos="0.0078133 -0.029898 0.026692" euler="-0.034907 0 0">
                              <inertial pos="0.0018663 -0.0066406 0.001533" mass="0.01" fullinertia="3.3724E-07 2.9457E-07 4.903E-07 1.11E-07 -3.6039E-08 5.7181E-08" />
                              <joint name="hand_left_lh_thumb_cmc_roll" class="hand_left_hand_linkerhand_l6_joint" type="hinge" axis="0 0 1" range="-0.087266 1.256637" />
                              <geom class="hand_left_hand_linkerhand_l6_visual" mesh="hand_left_thumb_metacarpals_base1" />
                              <geom class="hand_left_hand_linkerhand_l6_collision" mesh="hand_left_thumb_metacarpals_base1" />
                              <body name="hand_left_lh_thumb_metacarpals" pos="0.0057298 -0.01332 0.0027456" euler="1.1083 0 0.40143">
                                <inertial pos="0.00769270907060086 0.0859662184722988 0.0235283086675235" mass="0.065" fullinertia="8.407E-06 8.3899E-06 2.0091E-06 -1.1338E-09 1.1136E-08 3.1171E-07" />
                                <joint name="hand_left_lh_thumb_cmc_pitch" class="hand_left_hand_linkerhand_l6_joint" type="hinge" axis="-1 0 0" range="0 0.837758" />
                                <geom class="hand_left_hand_linkerhand_l6_visual" mesh="hand_left_thumb_metacarpals" />
                                <geom class="hand_left_hand_linkerhand_l6_collision" mesh="hand_left_thumb_metacarpals" />
                                <body name="hand_left_lh_thumb_distal" pos="0 0.0061 0.0827">
                                  <inertial pos="0.00769270907081708 0.0798662184721594 -0.0591716913325555" mass="0.018" fullinertia="1.5546E-06 1.7108E-06 9.1709E-07 2.4423E-09 2.8147E-09 -7.2756E-08" />
                                  <joint name="hand_left_lh_thumb_dip" class="hand_left_hand_linkerhand_l6_joint" type="hinge" axis="-1 0 0" range="0 0.963287" />
                                  <geom class="hand_left_hand_linkerhand_l6_visual" mesh="hand_left_thumb_distal" />
                                  <geom class="hand_left_hand_linkerhand_l6_collision" mesh="hand_left_thumb_distal" />
                                  <body name="hand_left_lh_thumb_tip" pos="0 0.0035 0.026" euler="0 0 1.5708">
                                    <inertial pos="0 0 0" mass="1e-06" fullinertia="1e-09 1e-09 1e-09 0 0 0" />
                                  </body>
                                </body>
                              </body>
                            </body>
                            <body name="hand_left_lh_index_proximal" pos="-0.00066821 -0.028967 0.11722">
                              <inertial pos="0.001776 -0.00011 0.012556" mass="0.008553" fullinertia="0.000000797543 0.000000800499 0.000000357001 -0.000000001275 0.000000138601 0.000000000939" />
                              <joint name="hand_left_lh_index_mcp_pitch" class="hand_left_hand_linkerhand_l6_joint" type="hinge" axis="0 1 0" range="0 1.134464" />
                              <geom class="hand_left_hand_linkerhand_l6_visual" mesh="hand_left_index_proximal" />
                              <geom class="hand_left_hand_linkerhand_l6_collision" mesh="hand_left_index_proximal" />
                              <body name="hand_left_lh_index_distal" pos="0.00093749 0 0.028002">
                                <inertial pos="0.0134 0.002262 0.016992" mass="0.018408" fullinertia="0.000002488712 0.000003723754 0.000001813582 0.000000008249 -0.000001523059 0.000000014019" />
                                <joint name="hand_left_lh_index_dip" class="hand_left_hand_linkerhand_l6_joint" type="hinge" axis="0 1 0" range="0 1.277039" />
                                <geom class="hand_left_hand_linkerhand_l6_visual" mesh="hand_left_index_distal" />
                                <geom class="hand_left_hand_linkerhand_l6_collision" mesh="hand_left_index_distal" />
                                <body name="hand_left_lh_index_tip" pos="0.0341 0 0.034">
                                  <inertial pos="0 0 0" mass="1e-06" fullinertia="1e-09 1e-09 1e-09 0 0 0" />
                                </body>
                              </body>
                            </body>
                            <body name="hand_left_lh_middle_proximal" pos="-0.00066821 -0.0089013 0.12322">
                              <inertial pos="0.001776 -0.00011 0.012556" mass="0.008553" fullinertia="0.000000797543 0.000000800499 0.000000357001 -0.000000001275 0.000000138601 0.000000000939" />
                              <joint name="hand_left_lh_middle_mcp_pitch" class="hand_left_hand_linkerhand_l6_joint" type="hinge" axis="0 1 0" range="0 1.134464" />
                              <geom class="hand_left_hand_linkerhand_l6_visual" mesh="hand_left_middle_proximal" />
                              <geom class="hand_left_hand_linkerhand_l6_collision" mesh="hand_left_middle_proximal" />
                              <body name="hand_left_lh_middle_distal" pos="0.00093749 0 0.028002">
                                <inertial pos="0.0134 0.002262 0.016992" mass="0.018408" fullinertia="0.000002488712 0.000003723754 0.000001813582 0.000000008249 -0.000001523059 0.000000014019" />
                                <joint name="hand_left_lh_middle_dip" class="hand_left_hand_linkerhand_l6_joint" type="hinge" axis="0 1 0" range="0 1.277039" />
                                <geom class="hand_left_hand_linkerhand_l6_visual" mesh="hand_left_middle_distal" />
                                <geom class="hand_left_hand_linkerhand_l6_collision" mesh="hand_left_middle_distal" />
                                <body name="hand_left_lh_middle_tip" pos="0.0341 0 0.034">
                                  <inertial pos="0 0 0" mass="1e-06" fullinertia="1e-09 1e-09 1e-09 0 0 0" />
                                </body>
                              </body>
                            </body>
                            <body name="hand_left_lh_ring_proximal" pos="-0.00067368 0.010717 0.11822">
                              <inertial pos="0.001776 -0.00011 0.012556" mass="0.008553" fullinertia="0.000000797543 0.000000800499 0.000000357001 -0.000000001275 0.000000138601 0.000000000939" />
                              <joint name="hand_left_lh_ring_mcp_pitch" class="hand_left_hand_linkerhand_l6_joint" type="hinge" axis="0 1 0" range="0 1.134464" />
                              <geom class="hand_left_hand_linkerhand_l6_visual" mesh="hand_left_ring_proximal" />
                              <geom class="hand_left_hand_linkerhand_l6_collision" mesh="hand_left_ring_proximal" />
                              <body name="hand_left_lh_ring_distal" pos="0.00093749 0 0.028002">
                                <inertial pos="0.0134 0.002262 0.016992" mass="0.018408" fullinertia="0.000002488712 0.000003723754 0.000001813582 0.000000008249 -0.000001523059 0.000000014019" />
                                <joint name="hand_left_lh_ring_dip" class="hand_left_hand_linkerhand_l6_joint" type="hinge" axis="0 1 0" range="0 1.277039" />
                                <geom class="hand_left_hand_linkerhand_l6_visual" mesh="hand_left_ring_distal" />
                                <geom class="hand_left_hand_linkerhand_l6_collision" mesh="hand_left_ring_distal" />
                                <body name="hand_left_lh_ring_tip" pos="0.0341 0 0.034">
                                  <inertial pos="0 0 0" mass="1e-06" fullinertia="1e-09 1e-09 1e-09 0 0 0" />
                                </body>
                              </body>
                            </body>
                            <body name="hand_left_lh_pinky_proximal" pos="-0.00067852 0.029814 0.11424">
                              <inertial pos="0.001776 -0.00011 0.012556" mass="0.008553" fullinertia="0.000000797543 0.000000800499 0.000000357001 -0.000000001275 0.000000138601 0.000000000939" />
                              <joint name="hand_left_lh_pinky_mcp_pitch" class="hand_left_hand_linkerhand_l6_joint" type="hinge" axis="0 1 0" range="0 1.134464" />
                              <geom class="hand_left_hand_linkerhand_l6_visual" mesh="hand_left_pinky_proximal" />
                              <geom class="hand_left_hand_linkerhand_l6_collision" mesh="hand_left_pinky_proximal" />
                              <body name="hand_left_lh_pinky_distal" pos="0.00093749 0 0.028002">
                                <inertial pos="0.0134 0.002262 0.016992" mass="0.018408" fullinertia="0.000002488712 0.000003723754 0.000001813582 0.000000008249 -0.000001523059 0.000000014019" />
                                <joint name="hand_left_lh_pinky_dip" class="hand_left_hand_linkerhand_l6_joint" type="hinge" axis="0 1 0" range="0 1.277039" />
                                <geom class="hand_left_hand_linkerhand_l6_visual" mesh="hand_left_pinky_distal" />
                                <geom class="hand_left_hand_linkerhand_l6_collision" mesh="hand_left_pinky_distal" />
                                <body name="hand_left_lh_pinky_tip" pos="0.0341 0 0.034">
                                  <inertial pos="0 0 0" mass="1e-06" fullinertia="1e-09 1e-09 1e-09 0 0 0" />
                                </body>
                              </body>
                            </body>
                          </body>
                        </body>
                      </body>
                    </body>
                  </body>
                </body>
              </body>
            </body>
          </body>
        </body>
        <body name="base_arm_right_mount" pos="0.0062926 -0.1505 -0.022706">
          <site name="base_arm_right_mount" pos="0 0 0" />
          <body name="arm_right_R_arm_root" pos="0 0 0">
            <site name="arm_right_base_mount" pos="0 0 0" />
            <body name="arm_right_R1_Link" pos="0 0 0">
              <inertial pos="0.004598 -0.067915 0.00072736" mass="1.1899" fullinertia="0.0016082 0.00086157 0.00092788 -3.3435E-06 3.9187E-07 -6.5828E-06" />
              <joint name="arm_right_R1_Joint" type="hinge" axis="0 1 0" range="-3.75 2.18" damping="20" frictionloss="0.0" armature="0.01" />
              <geom class="arm_right_arm_a7_lite_visual" mesh="arm_right_R1" />
              <geom class="arm_right_arm_a7_lite_collision" mesh="arm_right_R1" />
              <body name="arm_right_R2_Link" pos="0.03125 -0.0715 0">
                <inertial pos="-0.031363 2.7784E-05 -0.099445" mass="1.0663" fullinertia="0.0014523 0.0012484 0.0010754 -8.9962E-07 -1.031E-06 1.1436E-05" />
                <joint name="arm_right_R2_Joint" type="hinge" axis="-1 0 0" range="-0.19 3.33" damping="20" frictionloss="0.0" armature="0.01" />
                <geom class="arm_right_arm_a7_lite_visual" mesh="arm_right_R2" />
                <geom class="arm_right_arm_a7_lite_collision" mesh="arm_right_R2" />
                <body name="arm_right_R3_Link" pos="-0.03125 0 -0.147">
                  <inertial pos="-2.2895E-05 -0.00123 -0.077166" mass="1.3517" fullinertia="0.00080502 0.0010686 0.00067469 2.8702E-07 7.1845E-06 -7.5659E-07" />
                  <joint name="arm_right_R3_Joint" type="hinge" axis="0 0 1" range="-2.26 2.26" damping="20" frictionloss="0.0" armature="0.01" />
                  <geom class="arm_right_arm_a7_lite_visual" mesh="arm_right_R3" />
                  <geom class="arm_right_arm_a7_lite_collision" mesh="arm_right_R3" />
                  <body name="arm_right_R4_Link" pos="0 -0.027 -0.126">
                    <inertial pos="1.2714E-05 0.024908 -0.082641" mass="0.69691" fullinertia="0.00041505 0.00041627 0.00043007 5.3251E-08 1.7254E-06 3.826E-07" />
                    <joint name="arm_right_R4_Joint" type="hinge" axis="0 1 0" range="-1.74 0.78" damping="20" frictionloss="0.0" armature="0.01" />
                    <geom class="arm_right_arm_a7_lite_visual" mesh="arm_right_R4" />
                    <geom class="arm_right_arm_a7_lite_collision" mesh="arm_right_R4" />
                    <body name="arm_right_R5_Link" pos="0 0.027 -0.136">
                      <inertial pos="0.00029153 -0.0027009 -0.035875" mass="0.48527" fullinertia="0.00016555 0.00022756 0.00015289 -5.747E-07 -2.6985E-06 -9.211E-07" />
                      <joint name="arm_right_R5_Joint" type="hinge" axis="0 0 1" range="-2.96 2.96" damping="20" frictionloss="0.0" armature="0.01" />
                      <geom class="arm_right_arm_a7_lite_visual" mesh="arm_right_R5" />
                      <geom class="arm_right_arm_a7_lite_collision" mesh="arm_right_R5" />
                      <body name="arm_right_R6_Link" pos="0 -0.028 -0.0435">
                        <inertial pos="0.0023746 0.027704 -0.063949" mass="0.5193" fullinertia="0.00031746 0.00024364 0.00015858 6.3467E-07 4.1001E-07 -2.8219E-06" />
                        <joint name="arm_right_R6_Joint" type="hinge" axis="0 1 0" range="-1.57 1.57" damping="20" frictionloss="0.0" armature="0.01" />
                        <geom class="arm_right_arm_a7_lite_visual" mesh="arm_right_R6" />
                        <geom class="arm_right_arm_a7_lite_collision" mesh="arm_right_R6" />
                        <body name="arm_right_R7_Link" pos="0.028 0.028 -0.075">
                          <inertial pos="-0.026598 3.7248E-14 -0.025801" mass="0.10175" fullinertia="4.5036E-05 3.8663E-05 3.0632E-05 -4.7046E-12 2.2349E-07 -1.5968E-20" />
                          <joint name="arm_right_R7_Joint" type="hinge" axis="-1 0 0" range="-1.57 1.57" damping="20" frictionloss="0.0" armature="0.01" />
                          <geom class="arm_right_arm_a7_lite_visual" mesh="arm_right_R7" />
                          <geom class="arm_right_arm_a7_lite_collision" mesh="arm_right_R7" />
                          <site name="arm_right_tool0" pos="0 0 0" />
                          <body name="hand_right_rh_hand_base_link" pos="0 0 0" euler="3.1416 0 1.5708">
                            <inertial pos="0.0019900000 0.0009100000 0.0583810000" mass="0.4185" fullinertia="0.0004998 0.0003567 0.0002301 -1.2853e-05 -8.317e-06 -1.0354e-05" />
                            <geom class="hand_right_hand_linkerhand_l6_visual" mesh="hand_right_hand_base" />
                            <geom class="hand_right_hand_linkerhand_l6_collision" mesh="hand_right_hand_base" />
                            <site name="hand_right_wrist_mount" pos="0 0 0" />
                            <body name="hand_right_rh_thumb_metacarpals_base1" pos="0.0078133 0.030812 0.025678" euler="-0.034907 0 0">
                              <inertial pos="0.0018663000 0.0066406000 0.0015330000" mass="0.01" fullinertia="3.3724e-07 2.9457e-07 4.903e-07 -1.11e-07 -3.6039e-08 -5.7181e-08" />
                              <joint name="hand_right_rh_thumb_cmc_roll" class="hand_right_hand_linkerhand_l6_joint" type="hinge" axis="0 0.034899 -0.99939" range="-0.087266 1.256637" />
                              <geom class="hand_right_hand_linkerhand_l6_visual" mesh="hand_right_thumb_metacarpals_base1" />
                              <geom class="hand_right_hand_linkerhand_l6_collision" mesh="hand_right_thumb_metacarpals_base1" />
                              <body name="hand_right_rh_thumb_metacarpals" pos="0.0054997 0.013314 0.0032166" euler="-1.0762 0.013637 -0.40121">
                                <inertial pos="0.0076927091 -0.0859662185 0.0235283087" mass="0.065" fullinertia="8.407e-06 8.3899e-06 2.0091e-06 1.1338e-09 1.1136e-08 -3.1171e-07" />
                                <joint name="hand_right_rh_thumb_cmc_pitch" class="hand_right_hand_linkerhand_l6_joint" type="hinge" axis="1 0 0" range="0 0.837758" />
                                <geom class="hand_right_hand_linkerhand_l6_visual" mesh="hand_right_thumb_metacarpals" />
                                <geom class="hand_right_hand_linkerhand_l6_collision" mesh="hand_right_thumb_metacarpals" />
                                <body name="hand_right_rh_thumb_distal" pos="0 -0.0061 0.0827">
                                  <inertial pos="0.0076927091 -0.0798662185 -0.0591716913" mass="0.018" fullinertia="1.5546e-06 1.7108e-06 9.1709e-07 -2.4423e-09 2.8147e-09 7.2756e-08" />
                                  <joint name="hand_right_rh_thumb_dip" class="hand_right_hand_linkerhand_l6_joint" type="hinge" axis="1 0 0" range="0 0.963287" />
                                  <geom class="hand_right_hand_linkerhand_l6_visual" mesh="hand_right_thumb_distal" />
                                  <geom class="hand_right_hand_linkerhand_l6_collision" mesh="hand_right_thumb_distal" />
                                  <body name="hand_right_rh_thumb_tip" pos="0 -0.0035 0.026" euler="0 0 -1.5708">
                                    <inertial pos="0 0 0" mass="1e-06" fullinertia="1e-09 1e-09 1e-09 0 0 0" />
                                  </body>
                                </body>
                              </body>
                            </body>
                            <body name="hand_right_rh_index_proximal" pos="-0.00066821 0.033467 0.11622" euler="-0.087266 0 0">
                              <inertial pos="0.0017760000 0.0001100000 0.0125560000" mass="0.008553" fullinertia="7.97543e-07 8.00499e-07 3.57001e-07 1.275e-09 1.38601e-07 -9.39e-10" />
                              <joint name="hand_right_rh_index_mcp_pitch" class="hand_right_hand_linkerhand_l6_joint" type="hinge" axis="0 1 0" range="0 1.134464" />
                              <geom class="hand_right_hand_linkerhand_l6_visual" mesh="hand_right_index_proximal" />
                              <geom class="hand_right_hand_linkerhand_l6_collision" mesh="hand_right_index_proximal" />
                              <body name="hand_right_rh_index_distal" pos="0.0009359 0 0.028002">
                                <inertial pos="0.0134000000 -0.0022620000 0.0169920000" mass="0.018408" fullinertia="2.488712e-06 3.723754e-06 1.813582e-06 -8.249e-09 -1.523059e-06 -1.4019e-08" />
                                <joint name="hand_right_rh_index_dip" class="hand_right_hand_linkerhand_l6_joint" type="hinge" axis="0 1 0" range="0 1.277039" />
                                <geom class="hand_right_hand_linkerhand_l6_visual" mesh="hand_right_index_distal" />
                                <geom class="hand_right_hand_linkerhand_l6_collision" mesh="hand_right_index_distal" />
                                <body name="hand_right_rh_index_tip" pos="0.0341 0 0.034">
                                  <inertial pos="0 0 0" mass="1e-06" fullinertia="1e-09 1e-09 1e-09 0 0 0" />
                                </body>
                              </body>
                            </body>
                            <body name="hand_right_rh_middle_proximal" pos="-0.00066821 0.0134013 0.12272" euler="-0.034907 0 0">
                              <inertial pos="0.0017760000 0.0001100000 0.0125560000" mass="0.008553" fullinertia="7.97543e-07 8.00499e-07 3.57001e-07 1.275e-09 1.38601e-07 -9.39e-10" />
                              <joint name="hand_right_rh_middle_mcp_pitch" class="hand_right_hand_linkerhand_l6_joint" type="hinge" axis="0 1 0" range="0 1.134464" />
                              <geom class="hand_right_hand_linkerhand_l6_visual" mesh="hand_right_middle_proximal" />
                              <geom class="hand_right_hand_linkerhand_l6_collision" mesh="hand_right_middle_proximal" />
                              <body name="hand_right_rh_middle_distal" pos="0.0009359 0 0.028002">
                                <inertial pos="0.0134000000 -0.0022620000 0.0169920000" mass="0.018408" fullinertia="2.488712e-06 3.723754e-06 1.813582e-06 -8.249e-09 -1.523059e-06 -1.4019e-08" />
                                <joint name="hand_right_rh_middle_dip" class="hand_right_hand_linkerhand_l6_joint" type="hinge" axis="0 1 0" range="0 1.277039" />
                                <geom class="hand_right_hand_linkerhand_l6_visual" mesh="hand_right_middle_distal" />
                                <geom class="hand_right_hand_linkerhand_l6_collision" mesh="hand_right_middle_distal" />
                                <body name="hand_right_rh_middle_tip" pos="0.0341 0 0.034">
                                  <inertial pos="0 0 0" mass="1e-06" fullinertia="1e-09 1e-09 1e-09 0 0 0" />
                                </body>
                              </body>
                            </body>
                            <body name="hand_right_rh_ring_proximal" pos="-0.00067368 -0.006217 0.11872" euler="0.017453 0 0">
                              <inertial pos="0.0017760000 0.0001100000 0.0125560000" mass="0.008553" fullinertia="7.97543e-07 8.00499e-07 3.57001e-07 1.275e-09 1.38601e-07 -9.39e-10" />
                              <joint name="hand_right_rh_ring_mcp_pitch" class="hand_right_hand_linkerhand_l6_joint" type="hinge" axis="0 1 0" range="0 1.134464" />
                              <geom class="hand_right_hand_linkerhand_l6_visual" mesh="hand_right_ring_proximal" />
                              <geom class="hand_right_hand_linkerhand_l6_collision" mesh="hand_right_ring_proximal" />
                              <body name="hand_right_rh_ring_distal" pos="0.0009359 0 0.028002">
                                <inertial pos="0.0134000000 -0.0022620000 0.0169920000" mass="0.018408" fullinertia="2.488712e-06 3.723754e-06 1.813582e-06 -8.249e-09 -1.523059e-06 -1.4019e-08" />
                                <joint name="hand_right_rh_ring_dip" class="hand_right_hand_linkerhand_l6_joint" type="hinge" axis="0 1 0" range="0 1.277039" />
                                <geom class="hand_right_hand_linkerhand_l6_visual" mesh="hand_right_ring_distal" />
                                <geom class="hand_right_hand_linkerhand_l6_collision" mesh="hand_right_ring_distal" />
                                <body name="hand_right_rh_ring_tip" pos="0.0341 0 0.034">
                                  <inertial pos="0 0 0" mass="1e-06" fullinertia="1e-09 1e-09 1e-09 0 0 0" />
                                </body>
                              </body>
                            </body>
                            <body name="hand_right_rh_pinky_proximal" pos="-0.00067852 -0.025314 0.11474" euler="0.05236 0 0">
                              <inertial pos="0.0017760000 0.0001100000 0.0125560000" mass="0.008553" fullinertia="7.97543e-07 8.00499e-07 3.57001e-07 1.275e-09 1.38601e-07 -9.39e-10" />
                              <joint name="hand_right_rh_pinky_mcp_pitch" class="hand_right_hand_linkerhand_l6_joint" type="hinge" axis="0 1 0" range="0 1.134464" />
                              <geom class="hand_right_hand_linkerhand_l6_visual" mesh="hand_right_pinky_proximal" />
                              <geom class="hand_right_hand_linkerhand_l6_collision" mesh="hand_right_pinky_proximal" />
                              <body name="hand_right_rh_pinky_distal" pos="0.0009359 0 0.028002">
                                <inertial pos="0.0134000000 -0.0022620000 0.0169920000" mass="0.018408" fullinertia="2.488712e-06 3.723754e-06 1.813582e-06 -8.249e-09 -1.523059e-06 -1.4019e-08" />
                                <joint name="hand_right_rh_pinky_dip" class="hand_right_hand_linkerhand_l6_joint" type="hinge" axis="0 1 0" range="0 1.277039" />
                                <geom class="hand_right_hand_linkerhand_l6_visual" mesh="hand_right_pinky_distal" />
                                <geom class="hand_right_hand_linkerhand_l6_collision" mesh="hand_right_pinky_distal" />
                                <body name="hand_right_rh_pinky_tip" pos="0.0341 0 0.034">
                                  <inertial pos="0 0 0" mass="1e-06" fullinertia="1e-09 1e-09 1e-09 0 0 0" />
                                </body>
                              </body>
                            </body>
                          </body>
                        </body>
                      </body>
                    </body>
                  </body>
                </body>
              </body>
            </body>
          </body>
        </body>
      </body>
    </body>
  </worldbody>
  <actuator>
    <position name="arm_left_L1_Joint_act" joint="arm_left_L1_Joint" kp="2000" kv="0" ctrlrange="-2.18 3.75" />
    <position name="arm_left_L2_Joint_act" joint="arm_left_L2_Joint" kp="2000" kv="0" ctrlrange="-3.33 0.19" />
    <position name="arm_left_L3_Joint_act" joint="arm_left_L3_Joint" kp="2000" kv="0" ctrlrange="-2.26 2.26" />
    <position name="arm_left_L4_Joint_act" joint="arm_left_L4_Joint" kp="2000" kv="0" ctrlrange="-0.78 1.74" />
    <position name="arm_left_L5_Joint_act" joint="arm_left_L5_Joint" kp="2000" kv="0" ctrlrange="-2.96 2.96" />
    <position name="arm_left_L6_Joint_act" joint="arm_left_L6_Joint" kp="2000" kv="0" ctrlrange="-1.57 1.57" />
    <position name="arm_left_L7_Joint_act" joint="arm_left_L7_Joint" kp="2000" kv="0" ctrlrange="-1.57 1.57" />
    <position name="arm_right_R1_Joint_act" joint="arm_right_R1_Joint" kp="2000" kv="0" ctrlrange="-3.75 2.18" />
    <position name="arm_right_R2_Joint_act" joint="arm_right_R2_Joint" kp="2000" kv="0" ctrlrange="-0.19 3.33" />
    <position name="arm_right_R3_Joint_act" joint="arm_right_R3_Joint" kp="2000" kv="0" ctrlrange="-2.26 2.26" />
    <position name="arm_right_R4_Joint_act" joint="arm_right_R4_Joint" kp="2000" kv="0" ctrlrange="-1.74 0.78" />
    <position name="arm_right_R5_Joint_act" joint="arm_right_R5_Joint" kp="2000" kv="0" ctrlrange="-2.96 2.96" />
    <position name="arm_right_R6_Joint_act" joint="arm_right_R6_Joint" kp="2000" kv="0" ctrlrange="-1.57 1.57" />
    <position name="arm_right_R7_Joint_act" joint="arm_right_R7_Joint" kp="2000" kv="0" ctrlrange="-1.57 1.57" />
    <position name="hand_left_lh_thumb_cmc_roll_act" joint="hand_left_lh_thumb_cmc_roll" kp="20" kv="2" ctrlrange="-0.087266 1.256637" />
    <position name="hand_left_lh_thumb_cmc_pitch_act" joint="hand_left_lh_thumb_cmc_pitch" kp="20" kv="2" ctrlrange="0 0.837758" />
    <position name="hand_left_lh_index_mcp_pitch_act" joint="hand_left_lh_index_mcp_pitch" kp="20" kv="2" ctrlrange="0 1.134464" />
    <position name="hand_left_lh_middle_mcp_pitch_act" joint="hand_left_lh_middle_mcp_pitch" kp="20" kv="2" ctrlrange="0 1.134464" />
    <position name="hand_left_lh_ring_mcp_pitch_act" joint="hand_left_lh_ring_mcp_pitch" kp="20" kv="2" ctrlrange="0 1.134464" />
    <position name="hand_left_lh_pinky_mcp_pitch_act" joint="hand_left_lh_pinky_mcp_pitch" kp="20" kv="2" ctrlrange="0 1.134464" />
    <position name="hand_right_rh_thumb_cmc_roll_act" joint="hand_right_rh_thumb_cmc_roll" kp="20" kv="2" ctrlrange="-0.087266 1.256637" />
    <position name="hand_right_rh_thumb_cmc_pitch_act" joint="hand_right_rh_thumb_cmc_pitch" kp="20" kv="2" ctrlrange="0 0.837758" />
    <position name="hand_right_rh_index_mcp_pitch_act" joint="hand_right_rh_index_mcp_pitch" kp="20" kv="2" ctrlrange="0 1.134464" />
    <position name="hand_right_rh_middle_mcp_pitch_act" joint="hand_right_rh_middle_mcp_pitch" kp="20" kv="2" ctrlrange="0 1.134464" />
    <position name="hand_right_rh_ring_mcp_pitch_act" joint="hand_right_rh_ring_mcp_pitch" kp="20" kv="2" ctrlrange="0 1.134464" />
    <position name="hand_right_rh_pinky_mcp_pitch_act" joint="hand_right_rh_pinky_mcp_pitch" kp="20" kv="2" ctrlrange="0 1.134464" />
  </actuator>
  <equality>
    <joint name="hand_left_lh_couple_index" joint1="hand_left_lh_index_dip" joint2="hand_left_lh_index_mcp_pitch" polycoef="0 1.125676 0 0 0" />
    <joint name="hand_left_lh_couple_middle" joint1="hand_left_lh_middle_dip" joint2="hand_left_lh_middle_mcp_pitch" polycoef="0 1.125676 0 0 0" />
    <joint name="hand_left_lh_couple_ring" joint1="hand_left_lh_ring_dip" joint2="hand_left_lh_ring_mcp_pitch" polycoef="0 1.125676 0 0 0" />
    <joint name="hand_left_lh_couple_pinky" joint1="hand_left_lh_pinky_dip" joint2="hand_left_lh_pinky_mcp_pitch" polycoef="0 1.125676 0 0 0" />
    <joint name="hand_left_lh_couple_thumb" joint1="hand_left_lh_thumb_dip" joint2="hand_left_lh_thumb_cmc_pitch" polycoef="0 1.226495 0 0 0" />
    <joint name="hand_right_rh_couple_index" joint1="hand_right_rh_index_dip" joint2="hand_right_rh_index_mcp_pitch" polycoef="0 1.125676 0 0 0" />
    <joint name="hand_right_rh_couple_middle" joint1="hand_right_rh_middle_dip" joint2="hand_right_rh_middle_mcp_pitch" polycoef="0 1.125676 0 0 0" />
    <joint name="hand_right_rh_couple_ring" joint1="hand_right_rh_ring_dip" joint2="hand_right_rh_ring_mcp_pitch" polycoef="0 1.125676 0 0 0" />
    <joint name="hand_right_rh_couple_pinky" joint1="hand_right_rh_pinky_dip" joint2="hand_right_rh_pinky_mcp_pitch" polycoef="0 1.125676 0 0 0" />
    <joint name="hand_right_rh_couple_thumb" joint1="hand_right_rh_thumb_dip" joint2="hand_right_rh_thumb_cmc_pitch" polycoef="0 1.226495 0 0 0" />
  </equality>
  <contact>
    <exclude body1="arm_left_L1_Link" body2="arm_left_L2_Link" />
    <exclude body1="arm_left_L2_Link" body2="arm_left_L3_Link" />
    <exclude body1="arm_left_L3_Link" body2="arm_left_L4_Link" />
    <exclude body1="arm_left_L4_Link" body2="arm_left_L5_Link" />
    <exclude body1="arm_left_L5_Link" body2="arm_left_L6_Link" />
    <exclude body1="arm_left_L6_Link" body2="arm_left_L7_Link" />
    <exclude body1="arm_right_R1_Link" body2="arm_right_R2_Link" />
    <exclude body1="arm_right_R2_Link" body2="arm_right_R3_Link" />
    <exclude body1="arm_right_R3_Link" body2="arm_right_R4_Link" />
    <exclude body1="arm_right_R4_Link" body2="arm_right_R5_Link" />
    <exclude body1="arm_right_R5_Link" body2="arm_right_R6_Link" />
    <exclude body1="arm_right_R6_Link" body2="arm_right_R7_Link" />
    <exclude body1="hand_left_lh_hand_base_link" body2="hand_left_lh_thumb_metacarpals_base1" />
    <exclude body1="hand_left_lh_thumb_metacarpals_base1" body2="hand_left_lh_thumb_metacarpals" />
    <exclude body1="hand_left_lh_thumb_metacarpals" body2="hand_left_lh_thumb_distal" />
    <exclude body1="hand_left_lh_hand_base_link" body2="hand_left_lh_index_proximal" />
    <exclude body1="hand_left_lh_index_proximal" body2="hand_left_lh_index_distal" />
    <exclude body1="hand_left_lh_hand_base_link" body2="hand_left_lh_middle_proximal" />
    <exclude body1="hand_left_lh_middle_proximal" body2="hand_left_lh_middle_distal" />
    <exclude body1="hand_left_lh_hand_base_link" body2="hand_left_lh_ring_proximal" />
    <exclude body1="hand_left_lh_ring_proximal" body2="hand_left_lh_ring_distal" />
    <exclude body1="hand_left_lh_hand_base_link" body2="hand_left_lh_pinky_proximal" />
    <exclude body1="hand_left_lh_pinky_proximal" body2="hand_left_lh_pinky_distal" />
    <exclude body1="hand_right_rh_hand_base_link" body2="hand_right_rh_thumb_metacarpals_base1" />
    <exclude body1="hand_right_rh_thumb_metacarpals_base1" body2="hand_right_rh_thumb_metacarpals" />
    <exclude body1="hand_right_rh_thumb_metacarpals" body2="hand_right_rh_thumb_distal" />
    <exclude body1="hand_right_rh_hand_base_link" body2="hand_right_rh_index_proximal" />
    <exclude body1="hand_right_rh_index_proximal" body2="hand_right_rh_index_distal" />
    <exclude body1="hand_right_rh_hand_base_link" body2="hand_right_rh_middle_proximal" />
    <exclude body1="hand_right_rh_middle_proximal" body2="hand_right_rh_middle_distal" />
    <exclude body1="hand_right_rh_hand_base_link" body2="hand_right_rh_ring_proximal" />
    <exclude body1="hand_right_rh_ring_proximal" body2="hand_right_rh_ring_distal" />
    <exclude body1="hand_right_rh_hand_base_link" body2="hand_right_rh_pinky_proximal" />
    <exclude body1="hand_right_rh_pinky_proximal" body2="hand_right_rh_pinky_distal" />
    <exclude body1="base_base_link" body2="arm_left_L1_Link" />
    <exclude body1="base_base_link" body2="arm_left_L2_Link" />
    <exclude body1="base_base_link" body2="arm_left_L3_Link" />
    <exclude body1="base_base_link" body2="arm_left_L4_Link" />
    <exclude body1="base_base_link" body2="arm_left_L5_Link" />
    <exclude body1="base_base_link" body2="arm_left_L6_Link" />
    <exclude body1="base_base_link" body2="arm_left_L7_Link" />
    <exclude body1="base_base_link" body2="arm_right_R1_Link" />
    <exclude body1="base_base_link" body2="arm_right_R2_Link" />
    <exclude body1="base_base_link" body2="arm_right_R3_Link" />
    <exclude body1="base_base_link" body2="arm_right_R4_Link" />
    <exclude body1="base_base_link" body2="arm_right_R5_Link" />
    <exclude body1="base_base_link" body2="arm_right_R6_Link" />
    <exclude body1="base_base_link" body2="arm_right_R7_Link" />
    <exclude body1="arm_left_L1_Link" body2="hand_left_lh_hand_base_link" />
    <exclude body1="arm_left_L1_Link" body2="hand_left_lh_thumb_metacarpals_base1" />
    <exclude body1="arm_left_L1_Link" body2="hand_left_lh_thumb_metacarpals" />
    <exclude body1="arm_left_L1_Link" body2="hand_left_lh_thumb_distal" />
    <exclude body1="arm_left_L1_Link" body2="hand_left_lh_index_proximal" />
    <exclude body1="arm_left_L1_Link" body2="hand_left_lh_index_distal" />
    <exclude body1="arm_left_L1_Link" body2="hand_left_lh_middle_proximal" />
    <exclude body1="arm_left_L1_Link" body2="hand_left_lh_middle_distal" />
    <exclude body1="arm_left_L1_Link" body2="hand_left_lh_ring_proximal" />
    <exclude body1="arm_left_L1_Link" body2="hand_left_lh_ring_distal" />
    <exclude body1="arm_left_L1_Link" body2="hand_left_lh_pinky_proximal" />
    <exclude body1="arm_left_L1_Link" body2="hand_left_lh_pinky_distal" />
    <exclude body1="arm_left_L2_Link" body2="hand_left_lh_hand_base_link" />
    <exclude body1="arm_left_L2_Link" body2="hand_left_lh_thumb_metacarpals_base1" />
    <exclude body1="arm_left_L2_Link" body2="hand_left_lh_thumb_metacarpals" />
    <exclude body1="arm_left_L2_Link" body2="hand_left_lh_thumb_distal" />
    <exclude body1="arm_left_L2_Link" body2="hand_left_lh_index_proximal" />
    <exclude body1="arm_left_L2_Link" body2="hand_left_lh_index_distal" />
    <exclude body1="arm_left_L2_Link" body2="hand_left_lh_middle_proximal" />
    <exclude body1="arm_left_L2_Link" body2="hand_left_lh_middle_distal" />
    <exclude body1="arm_left_L2_Link" body2="hand_left_lh_ring_proximal" />
    <exclude body1="arm_left_L2_Link" body2="hand_left_lh_ring_distal" />
    <exclude body1="arm_left_L2_Link" body2="hand_left_lh_pinky_proximal" />
    <exclude body1="arm_left_L2_Link" body2="hand_left_lh_pinky_distal" />
    <exclude body1="arm_left_L3_Link" body2="hand_left_lh_hand_base_link" />
    <exclude body1="arm_left_L3_Link" body2="hand_left_lh_thumb_metacarpals_base1" />
    <exclude body1="arm_left_L3_Link" body2="hand_left_lh_thumb_metacarpals" />
    <exclude body1="arm_left_L3_Link" body2="hand_left_lh_thumb_distal" />
    <exclude body1="arm_left_L3_Link" body2="hand_left_lh_index_proximal" />
    <exclude body1="arm_left_L3_Link" body2="hand_left_lh_index_distal" />
    <exclude body1="arm_left_L3_Link" body2="hand_left_lh_middle_proximal" />
    <exclude body1="arm_left_L3_Link" body2="hand_left_lh_middle_distal" />
    <exclude body1="arm_left_L3_Link" body2="hand_left_lh_ring_proximal" />
    <exclude body1="arm_left_L3_Link" body2="hand_left_lh_ring_distal" />
    <exclude body1="arm_left_L3_Link" body2="hand_left_lh_pinky_proximal" />
    <exclude body1="arm_left_L3_Link" body2="hand_left_lh_pinky_distal" />
    <exclude body1="arm_left_L4_Link" body2="hand_left_lh_hand_base_link" />
    <exclude body1="arm_left_L4_Link" body2="hand_left_lh_thumb_metacarpals_base1" />
    <exclude body1="arm_left_L4_Link" body2="hand_left_lh_thumb_metacarpals" />
    <exclude body1="arm_left_L4_Link" body2="hand_left_lh_thumb_distal" />
    <exclude body1="arm_left_L4_Link" body2="hand_left_lh_index_proximal" />
    <exclude body1="arm_left_L4_Link" body2="hand_left_lh_index_distal" />
    <exclude body1="arm_left_L4_Link" body2="hand_left_lh_middle_proximal" />
    <exclude body1="arm_left_L4_Link" body2="hand_left_lh_middle_distal" />
    <exclude body1="arm_left_L4_Link" body2="hand_left_lh_ring_proximal" />
    <exclude body1="arm_left_L4_Link" body2="hand_left_lh_ring_distal" />
    <exclude body1="arm_left_L4_Link" body2="hand_left_lh_pinky_proximal" />
    <exclude body1="arm_left_L4_Link" body2="hand_left_lh_pinky_distal" />
    <exclude body1="arm_left_L5_Link" body2="hand_left_lh_hand_base_link" />
    <exclude body1="arm_left_L5_Link" body2="hand_left_lh_thumb_metacarpals_base1" />
    <exclude body1="arm_left_L5_Link" body2="hand_left_lh_thumb_metacarpals" />
    <exclude body1="arm_left_L5_Link" body2="hand_left_lh_thumb_distal" />
    <exclude body1="arm_left_L5_Link" body2="hand_left_lh_index_proximal" />
    <exclude body1="arm_left_L5_Link" body2="hand_left_lh_index_distal" />
    <exclude body1="arm_left_L5_Link" body2="hand_left_lh_middle_proximal" />
    <exclude body1="arm_left_L5_Link" body2="hand_left_lh_middle_distal" />
    <exclude body1="arm_left_L5_Link" body2="hand_left_lh_ring_proximal" />
    <exclude body1="arm_left_L5_Link" body2="hand_left_lh_ring_distal" />
    <exclude body1="arm_left_L5_Link" body2="hand_left_lh_pinky_proximal" />
    <exclude body1="arm_left_L5_Link" body2="hand_left_lh_pinky_distal" />
    <exclude body1="arm_left_L6_Link" body2="hand_left_lh_hand_base_link" />
    <exclude body1="arm_left_L6_Link" body2="hand_left_lh_thumb_metacarpals_base1" />
    <exclude body1="arm_left_L6_Link" body2="hand_left_lh_thumb_metacarpals" />
    <exclude body1="arm_left_L6_Link" body2="hand_left_lh_thumb_distal" />
    <exclude body1="arm_left_L6_Link" body2="hand_left_lh_index_proximal" />
    <exclude body1="arm_left_L6_Link" body2="hand_left_lh_index_distal" />
    <exclude body1="arm_left_L6_Link" body2="hand_left_lh_middle_proximal" />
    <exclude body1="arm_left_L6_Link" body2="hand_left_lh_middle_distal" />
    <exclude body1="arm_left_L6_Link" body2="hand_left_lh_ring_proximal" />
    <exclude body1="arm_left_L6_Link" body2="hand_left_lh_ring_distal" />
    <exclude body1="arm_left_L6_Link" body2="hand_left_lh_pinky_proximal" />
    <exclude body1="arm_left_L6_Link" body2="hand_left_lh_pinky_distal" />
    <exclude body1="arm_left_L7_Link" body2="hand_left_lh_hand_base_link" />
    <exclude body1="arm_left_L7_Link" body2="hand_left_lh_thumb_metacarpals_base1" />
    <exclude body1="arm_left_L7_Link" body2="hand_left_lh_thumb_metacarpals" />
    <exclude body1="arm_left_L7_Link" body2="hand_left_lh_thumb_distal" />
    <exclude body1="arm_left_L7_Link" body2="hand_left_lh_index_proximal" />
    <exclude body1="arm_left_L7_Link" body2="hand_left_lh_index_distal" />
    <exclude body1="arm_left_L7_Link" body2="hand_left_lh_middle_proximal" />
    <exclude body1="arm_left_L7_Link" body2="hand_left_lh_middle_distal" />
    <exclude body1="arm_left_L7_Link" body2="hand_left_lh_ring_proximal" />
    <exclude body1="arm_left_L7_Link" body2="hand_left_lh_ring_distal" />
    <exclude body1="arm_left_L7_Link" body2="hand_left_lh_pinky_proximal" />
    <exclude body1="arm_left_L7_Link" body2="hand_left_lh_pinky_distal" />
    <exclude body1="base_base_link" body2="hand_left_lh_hand_base_link" />
    <exclude body1="base_base_link" body2="hand_left_lh_thumb_metacarpals_base1" />
    <exclude body1="base_base_link" body2="hand_left_lh_thumb_metacarpals" />
    <exclude body1="base_base_link" body2="hand_left_lh_thumb_distal" />
    <exclude body1="base_base_link" body2="hand_left_lh_index_proximal" />
    <exclude body1="base_base_link" body2="hand_left_lh_index_distal" />
    <exclude body1="base_base_link" body2="hand_left_lh_middle_proximal" />
    <exclude body1="base_base_link" body2="hand_left_lh_middle_distal" />
    <exclude body1="base_base_link" body2="hand_left_lh_ring_proximal" />
    <exclude body1="base_base_link" body2="hand_left_lh_ring_distal" />
    <exclude body1="base_base_link" body2="hand_left_lh_pinky_proximal" />
    <exclude body1="base_base_link" body2="hand_left_lh_pinky_distal" />
    <exclude body1="arm_right_R1_Link" body2="hand_right_rh_hand_base_link" />
    <exclude body1="arm_right_R1_Link" body2="hand_right_rh_thumb_metacarpals_base1" />
    <exclude body1="arm_right_R1_Link" body2="hand_right_rh_thumb_metacarpals" />
    <exclude body1="arm_right_R1_Link" body2="hand_right_rh_thumb_distal" />
    <exclude body1="arm_right_R1_Link" body2="hand_right_rh_index_proximal" />
    <exclude body1="arm_right_R1_Link" body2="hand_right_rh_index_distal" />
    <exclude body1="arm_right_R1_Link" body2="hand_right_rh_middle_proximal" />
    <exclude body1="arm_right_R1_Link" body2="hand_right_rh_middle_distal" />
    <exclude body1="arm_right_R1_Link" body2="hand_right_rh_ring_proximal" />
    <exclude body1="arm_right_R1_Link" body2="hand_right_rh_ring_distal" />
    <exclude body1="arm_right_R1_Link" body2="hand_right_rh_pinky_proximal" />
    <exclude body1="arm_right_R1_Link" body2="hand_right_rh_pinky_distal" />
    <exclude body1="arm_right_R2_Link" body2="hand_right_rh_hand_base_link" />
    <exclude body1="arm_right_R2_Link" body2="hand_right_rh_thumb_metacarpals_base1" />
    <exclude body1="arm_right_R2_Link" body2="hand_right_rh_thumb_metacarpals" />
    <exclude body1="arm_right_R2_Link" body2="hand_right_rh_thumb_distal" />
    <exclude body1="arm_right_R2_Link" body2="hand_right_rh_index_proximal" />
    <exclude body1="arm_right_R2_Link" body2="hand_right_rh_index_distal" />
    <exclude body1="arm_right_R2_Link" body2="hand_right_rh_middle_proximal" />
    <exclude body1="arm_right_R2_Link" body2="hand_right_rh_middle_distal" />
    <exclude body1="arm_right_R2_Link" body2="hand_right_rh_ring_proximal" />
    <exclude body1="arm_right_R2_Link" body2="hand_right_rh_ring_distal" />
    <exclude body1="arm_right_R2_Link" body2="hand_right_rh_pinky_proximal" />
    <exclude body1="arm_right_R2_Link" body2="hand_right_rh_pinky_distal" />
    <exclude body1="arm_right_R3_Link" body2="hand_right_rh_hand_base_link" />
    <exclude body1="arm_right_R3_Link" body2="hand_right_rh_thumb_metacarpals_base1" />
    <exclude body1="arm_right_R3_Link" body2="hand_right_rh_thumb_metacarpals" />
    <exclude body1="arm_right_R3_Link" body2="hand_right_rh_thumb_distal" />
    <exclude body1="arm_right_R3_Link" body2="hand_right_rh_index_proximal" />
    <exclude body1="arm_right_R3_Link" body2="hand_right_rh_index_distal" />
    <exclude body1="arm_right_R3_Link" body2="hand_right_rh_middle_proximal" />
    <exclude body1="arm_right_R3_Link" body2="hand_right_rh_middle_distal" />
    <exclude body1="arm_right_R3_Link" body2="hand_right_rh_ring_proximal" />
    <exclude body1="arm_right_R3_Link" body2="hand_right_rh_ring_distal" />
    <exclude body1="arm_right_R3_Link" body2="hand_right_rh_pinky_proximal" />
    <exclude body1="arm_right_R3_Link" body2="hand_right_rh_pinky_distal" />
    <exclude body1="arm_right_R4_Link" body2="hand_right_rh_hand_base_link" />
    <exclude body1="arm_right_R4_Link" body2="hand_right_rh_thumb_metacarpals_base1" />
    <exclude body1="arm_right_R4_Link" body2="hand_right_rh_thumb_metacarpals" />
    <exclude body1="arm_right_R4_Link" body2="hand_right_rh_thumb_distal" />
    <exclude body1="arm_right_R4_Link" body2="hand_right_rh_index_proximal" />
    <exclude body1="arm_right_R4_Link" body2="hand_right_rh_index_distal" />
    <exclude body1="arm_right_R4_Link" body2="hand_right_rh_middle_proximal" />
    <exclude body1="arm_right_R4_Link" body2="hand_right_rh_middle_distal" />
    <exclude body1="arm_right_R4_Link" body2="hand_right_rh_ring_proximal" />
    <exclude body1="arm_right_R4_Link" body2="hand_right_rh_ring_distal" />
    <exclude body1="arm_right_R4_Link" body2="hand_right_rh_pinky_proximal" />
    <exclude body1="arm_right_R4_Link" body2="hand_right_rh_pinky_distal" />
    <exclude body1="arm_right_R5_Link" body2="hand_right_rh_hand_base_link" />
    <exclude body1="arm_right_R5_Link" body2="hand_right_rh_thumb_metacarpals_base1" />
    <exclude body1="arm_right_R5_Link" body2="hand_right_rh_thumb_metacarpals" />
    <exclude body1="arm_right_R5_Link" body2="hand_right_rh_thumb_distal" />
    <exclude body1="arm_right_R5_Link" body2="hand_right_rh_index_proximal" />
    <exclude body1="arm_right_R5_Link" body2="hand_right_rh_index_distal" />
    <exclude body1="arm_right_R5_Link" body2="hand_right_rh_middle_proximal" />
    <exclude body1="arm_right_R5_Link" body2="hand_right_rh_middle_distal" />
    <exclude body1="arm_right_R5_Link" body2="hand_right_rh_ring_proximal" />
    <exclude body1="arm_right_R5_Link" body2="hand_right_rh_ring_distal" />
    <exclude body1="arm_right_R5_Link" body2="hand_right_rh_pinky_proximal" />
    <exclude body1="arm_right_R5_Link" body2="hand_right_rh_pinky_distal" />
    <exclude body1="arm_right_R6_Link" body2="hand_right_rh_hand_base_link" />
    <exclude body1="arm_right_R6_Link" body2="hand_right_rh_thumb_metacarpals_base1" />
    <exclude body1="arm_right_R6_Link" body2="hand_right_rh_thumb_metacarpals" />
    <exclude body1="arm_right_R6_Link" body2="hand_right_rh_thumb_distal" />
    <exclude body1="arm_right_R6_Link" body2="hand_right_rh_index_proximal" />
    <exclude body1="arm_right_R6_Link" body2="hand_right_rh_index_distal" />
    <exclude body1="arm_right_R6_Link" body2="hand_right_rh_middle_proximal" />
    <exclude body1="arm_right_R6_Link" body2="hand_right_rh_middle_distal" />
    <exclude body1="arm_right_R6_Link" body2="hand_right_rh_ring_proximal" />
    <exclude body1="arm_right_R6_Link" body2="hand_right_rh_ring_distal" />
    <exclude body1="arm_right_R6_Link" body2="hand_right_rh_pinky_proximal" />
    <exclude body1="arm_right_R6_Link" body2="hand_right_rh_pinky_distal" />
    <exclude body1="arm_right_R7_Link" body2="hand_right_rh_hand_base_link" />
    <exclude body1="arm_right_R7_Link" body2="hand_right_rh_thumb_metacarpals_base1" />
    <exclude body1="arm_right_R7_Link" body2="hand_right_rh_thumb_metacarpals" />
    <exclude body1="arm_right_R7_Link" body2="hand_right_rh_thumb_distal" />
    <exclude body1="arm_right_R7_Link" body2="hand_right_rh_index_proximal" />
    <exclude body1="arm_right_R7_Link" body2="hand_right_rh_index_distal" />
    <exclude body1="arm_right_R7_Link" body2="hand_right_rh_middle_proximal" />
    <exclude body1="arm_right_R7_Link" body2="hand_right_rh_middle_distal" />
    <exclude body1="arm_right_R7_Link" body2="hand_right_rh_ring_proximal" />
    <exclude body1="arm_right_R7_Link" body2="hand_right_rh_ring_distal" />
    <exclude body1="arm_right_R7_Link" body2="hand_right_rh_pinky_proximal" />
    <exclude body1="arm_right_R7_Link" body2="hand_right_rh_pinky_distal" />
    <exclude body1="base_base_link" body2="hand_right_rh_hand_base_link" />
    <exclude body1="base_base_link" body2="hand_right_rh_thumb_metacarpals_base1" />
    <exclude body1="base_base_link" body2="hand_right_rh_thumb_metacarpals" />
    <exclude body1="base_base_link" body2="hand_right_rh_thumb_distal" />
    <exclude body1="base_base_link" body2="hand_right_rh_index_proximal" />
    <exclude body1="base_base_link" body2="hand_right_rh_index_distal" />
    <exclude body1="base_base_link" body2="hand_right_rh_middle_proximal" />
    <exclude body1="base_base_link" body2="hand_right_rh_middle_distal" />
    <exclude body1="base_base_link" body2="hand_right_rh_ring_proximal" />
    <exclude body1="base_base_link" body2="hand_right_rh_ring_distal" />
    <exclude body1="base_base_link" body2="hand_right_rh_pinky_proximal" />
    <exclude body1="base_base_link" body2="hand_right_rh_pinky_distal" />
  </contact>
</mujoco>
