<?xml version='1.0' encoding='utf-8'?>
<robot name="hand">
  <link name="lh_hand_base_link">
    <inertial>
      <origin xyz="-0.000986417037198788 0.000268049028294054 0.0773798470852122" rpy="0 0 0" />
      <mass value="0.110373495507463" />
      <inertia ixx="0.000264402778830212" ixy="4.59263483005334e-07" ixz="1.32798258678817e-06" iyy="0.000159680177760236" iyz="-4.78660406501498e-06" izz="0.000118075546031988" />
    </inertial>
    <visual>
      <origin xyz="0 0 0" rpy="0 0 0" />
      <geometry><mesh filename="meshes/hand_base_link.STL" /></geometry>
      <material name=""><color rgba="1 1 1 1" /></material>
    </visual>
    <collision>
      <origin xyz="0 0 0" rpy="0 0 0" />
      <geometry><mesh filename="meshes/hand_base_link.STL" /></geometry>
    </collision>
  </link>
  <link name="lh_thumb_metacarpals_base1">
    <inertial>
      <origin xyz="0.0115155126192006 0.00398068846976699 0.000272888250745694" rpy="0 0 0" />
      <mass value="0.0160351802817401" />
      <inertia ixx="4.043875385429e-06" ixy="1.31113365770736e-07" ixz="-7.54220071752833e-09" iyy="2.42762975209742e-06" iyz="-1.4815076502312e-07" izz="2.08582778122043e-06" />
    </inertial>
    <visual>
      <origin xyz="0 0 0" rpy="0 0 0" />
      <geometry><mesh filename="meshes/thumb_metacarpals_base1.STL" /></geometry>
      <material name=""><color rgba="1 1 1 1" /></material>
    </visual>
    <collision>
      <origin xyz="0 0 0" rpy="0 0 0" />
      <geometry><mesh filename="meshes/thumb_metacarpals_base1.STL" /></geometry>
    </collision>
  </link>
  <link name="lh_thumb_metacarpals_base2">
    <inertial>
      <origin xyz="0.00286714610220221 -0.0061572653424441 0.00472605265322379" rpy="0 0 0" />
      <mass value="0.00183264554882498" />
      <inertia ixx="2.1115156606816047e-07" ixy="-4.9133152227129e-08" ixz="-1.35746007921721e-08" iyy="9.889251334189997e-08" iyz="4.75450167610941e-08" izz="1.8061586053999446e-07" />
    </inertial>
    <visual>
      <origin xyz="0 0 0" rpy="0 0 0" />
      <geometry><mesh filename="meshes/thumb_metacarpals_base2.STL" /></geometry>
      <material name=""><color rgba="1 1 1 1" /></material>
    </visual>
    <collision>
      <origin xyz="0 0 0" rpy="0 0 0" />
      <geometry><mesh filename="meshes/thumb_metacarpals_base2.STL" /></geometry>
    </collision>
  </link>
  <link name="lh_thumb_metacarpals">
    <inertial>
      <origin xyz="0.00670657874489922 8.60758971228653e-05 0.0331412930049483" rpy="0 0 0" />
      <mass value="0.0287160359417969" />
      <inertia ixx="1.13355944686632e-05" ixy="-1.18725063259997e-08" ixz="5.09011416528365e-08" iyy="1.3528651001113e-05" iyz="2.41236037965108e-08" izz="3.37809997040935e-06" />
    </inertial>
    <visual>
      <origin xyz="0 0 0" rpy="0 0 0" />
      <geometry><mesh filename="meshes/thumb_metacarpals.STL" /></geometry>
      <material name=""><color rgba="1 1 1 1" /></material>
    </visual>
    <collision>
      <origin xyz="0 0 0" rpy="0 0 0" />
      <geometry><mesh filename="meshes/thumb_metacarpals.STL" /></geometry>
    </collision>
  </link>
  <link name="lh_thumb_proximal">
    <inertial>
      <origin xyz="-0.00268734410969529 0.000568244522388137 0.0118501723044777" rpy="0 0 0" />
      <mass value="0.00549015507433734" />
      <inertia ixx="4.78372237673962e-07" ixy="4.56375652569348e-11" ixz="5.41461160604729e-08" iyy="6.23208954846975e-07" iyz="5.1129105291147e-09" izz="2.34934736039565e-07" />
    </inertial>
    <visual>
      <origin xyz="0 0 0" rpy="0 0 0" />
      <geometry><mesh filename="meshes/thumb_proximal.STL" /></geometry>
      <material name=""><color rgba="1 1 1 1" /></material>
    </visual>
    <collision>
      <origin xyz="0 0 0" rpy="0 0 0" />
      <geometry><mesh filename="meshes/thumb_proximal.STL" /></geometry>
    </collision>
  </link>
  <link name="lh_thumb_distal">
    <inertial>
      <origin xyz="-0.000710021799050622 -0.00267575921172081 0.0124762660846746" rpy="0 0 0" />
      <mass value="0.00382046638843239" />
      <inertia ixx="2.12120816159448e-07" ixy="-2.9588372102787e-09" ixz="-7.35950751454791e-08" iyy="2.67878295781821e-07" iyz="6.04616706384983e-09" izz="1.24571609570411e-07" />
    </inertial>
    <visual>
      <origin xyz="0 0 0" rpy="0 0 0" />
      <geometry><mesh filename="meshes/thumb_distal.STL" /></geometry>
      <material name=""><color rgba="1 1 1 1" /></material>
    </visual>
    <collision>
      <origin xyz="0 0 0" rpy="0 0 0" />
      <geometry><mesh filename="meshes/thumb_distal.STL" /></geometry>
    </collision>
  </link>
  <link name="lh_index_metacarpals">
    <inertial>
      <origin xyz="-0.00794299653637993 -2.93673969475883e-07 0.00220106027330236" rpy="0 0 0" />
      <mass value="0.000895516429792169" />
      <inertia ixx="3.46279728013563e-08" ixy="-3.91962517308058e-13" ixz="5.91029152662012e-09" iyy="2.85435471088518e-08" iyz="-5.30377507775974e-13" izz="4.38102133125935e-08" />
    </inertial>
    <visual>
      <origin xyz="0 0 0" rpy="0 0 0" />
      <geometry><mesh filename="meshes/index_metacarpals.STL" /></geometry>
      <material name=""><color rgba="1 1 1 1" /></material>
    </visual>
    <collision>
      <origin xyz="0 0 0" rpy="0 0 0" />
      <geometry><mesh filename="meshes/index_metacarpals.STL" /></geometry>
    </collision>
  </link>
  <link name="lh_index_proximal">
    <inertial>
      <origin xyz="-0.00114185484694667 3.47315751996757e-05 0.0228928405204552" rpy="0 0 0" />
      <mass value="0.00450921353606138" />
      <inertia ixx="6.66673080974796e-07" ixy="-1.07185172336921e-11" ixz="-2.53143396223457e-08" iyy="6.74195867168963e-07" iyz="-1.59054321114837e-10" izz="1.3575909170439e-07" />
    </inertial>
    <visual>
      <origin xyz="0 0 0" rpy="0 0 0" />
      <geometry><mesh filename="meshes/index_proximal.STL" /></geometry>
      <material name=""><color rgba="1 1 1 1" /></material>
    </visual>
    <collision>
      <origin xyz="0 0 0" rpy="0 0 0" />
      <geometry><mesh filename="meshes/index_proximal.STL" /></geometry>
    </collision>
  </link>
  <link name="lh_index_middle">
    <inertial>
      <origin xyz="-0.000206991936024691 2.60617060293677e-06 0.0167065328961797" rpy="0 0 0" />
      <mass value="0.00237827499847615" />
      <inertia ixx="2.2953872847051e-07" ixy="2.23609392315326e-12" ixz="-1.4734008024399e-08" iyy="1.76761332719485e-07" iyz="1.15917246584962e-11" izz="9.62798051827835e-08" />
    </inertial>
    <visual>
      <origin xyz="0 0 0" rpy="0 0 0" />
      <geometry><mesh filename="meshes/index_middle.STL" /></geometry>
      <material name=""><color rgba="1 1 1 1" /></material>
    </visual>
    <collision>
      <origin xyz="0 0 0" rpy="0 0 0" />
      <geometry><mesh filename="meshes/index_middle.STL" /></geometry>
    </collision>
  </link>
  <link name="lh_index_distal">
    <inertial>
      <origin xyz="-0.00816246517948334 2.27058913663258e-05 0.00811806505013066" rpy="0 0 0" />
      <mass value="0.00334170259772608" />
      <inertia ixx="1.59570744991572e-07" ixy="1.51458653099843e-10" ixz="-5.9429168549018e-08" iyy="1.78095631426193e-07" iyz="-1.24842727205631e-10" izz="1.34141383450165e-07" />
    </inertial>
    <visual>
      <origin xyz="0 0 0" rpy="0 0 0" />
      <geometry><mesh filename="meshes/index_distal.STL" /></geometry>
      <material name=""><color rgba="1 1 1 1" /></material>
    </visual>
    <collision>
      <origin xyz="0 0 0" rpy="0 0 0" />
      <geometry><mesh filename="meshes/index_distal.STL" /></geometry>
    </collision>
  </link>
  <link name="lh_middle_metacarpals">
    <inertial>
      <origin xyz="-0.00794299618184406 -2.93006659768391e-07 0.00220106329585604" rpy="0 0 0" />
      <mass value="0.000895516947435045" />
      <inertia ixx="3.46279958583857e-08" ixy="-3.91785866285381e-13" ixz="5.91029262290692e-09" iyy="2.85435605322585e-08" iyz="-5.27457529869591e-13" izz="4.38102218629515e-08" />
    </inertial>
    <visual>
      <origin xyz="0 0 0" rpy="0 0 0" />
      <geometry><mesh filename="meshes/middle_metacarpals.STL" /></geometry>
      <material name=""><color rgba="1 1 1 1" /></material>
    </visual>
    <collision>
      <origin xyz="0 0 0" rpy="0 0 0" />
      <geometry><mesh filename="meshes/middle_metacarpals.STL" /></geometry>
    </collision>
  </link>
  <link name="lh_middle_proximal">
    <inertial>
      <origin xyz="-0.00114185484818909 3.47315748623067e-05 0.0228928405191574" rpy="0 0 0" />
      <mass value="0.00450921353536659" />
      <inertia ixx="6.6667308094129e-07" ixy="-1.07185191777588e-11" ixz="-2.53143396278864e-08" iyy="6.74195867139795e-07" iyz="-1.59054330697635e-10" izz="1.3575909169764e-07" />
    </inertial>
    <visual>
      <origin xyz="0 0 0" rpy="0 0 0" />
      <geometry><mesh filename="meshes/middle_proximal.STL" /></geometry>
      <material name=""><color rgba="1 1 1 1" /></material>
    </visual>
    <collision>
      <origin xyz="0 0 0" rpy="0 0 0" />
      <geometry><mesh filename="meshes/middle_proximal.STL" /></geometry>
    </collision>
  </link>
  <link name="lh_middle_middle">
    <inertial>
      <origin xyz="-0.000206991893084203 2.60624978909441e-06 0.0167065331356697" rpy="0 0 0" />
      <mass value="0.00237827502274046" />
      <inertia ixx="2.29538732170979e-07" ixy="2.23722006830829e-12" ixz="-1.47340061868536e-08" iyy="1.7676133625496e-07" iyz="1.15938574397121e-11" izz="9.62798057458164e-08" />
    </inertial>
    <visual>
      <origin xyz="0 0 0" rpy="0 0 0" />
      <geometry><mesh filename="meshes/middle_middle.STL" /></geometry>
      <material name=""><color rgba="1 1 1 1" /></material>
    </visual>
    <collision>
      <origin xyz="0 0 0" rpy="0 0 0" />
      <geometry><mesh filename="meshes/middle_middle.STL" /></geometry>
    </collision>
  </link>
  <link name="lh_middle_distal">
    <inertial>
      <origin xyz="-0.00816246584707385 2.27058557035753e-05 0.00811806604834034" rpy="0 0 0" />
      <mass value="0.00334170288968694" />
      <inertia ixx="1.59570753478215e-07" ixy="1.51460233550071e-10" ixz="-5.94291827952622e-08" iyy="1.78095663702073e-07" iyz="-1.24843061161549e-10" izz="1.34141410190336e-07" />
    </inertial>
    <visual>
      <origin xyz="0 0 0" rpy="0 0 0" />
      <geometry><mesh filename="meshes/middle_distal.STL" /></geometry>
      <material name=""><color rgba="1 1 1 1" /></material>
    </visual>
    <collision>
      <origin xyz="0 0 0" rpy="0 0 0" />
      <geometry><mesh filename="meshes/middle_distal.STL" /></geometry>
    </collision>
  </link>
  <link name="lh_ring_metacarpals">
    <inertial>
      <origin xyz="-0.00794299637971868 -2.94513098575422e-07 0.00220106138372037" rpy="0 0 0" />
      <mass value="0.000895516612684195" />
      <inertia ixx="3.46279813761428e-08" ixy="-3.92590701616938e-13" ixz="5.91029201975386e-09" iyy="2.854355219638e-08" iyz="-5.34642787239736e-13" izz="4.38102164225122e-08" />
    </inertial>
    <visual>
      <origin xyz="0 0 0" rpy="0 0 0" />
      <geometry><mesh filename="meshes/ring_metacarpals.STL" /></geometry>
      <material name=""><color rgba="1 1 1 1" /></material>
    </visual>
    <collision>
      <origin xyz="0 0 0" rpy="0 0 0" />
      <geometry><mesh filename="meshes/ring_metacarpals.STL" /></geometry>
    </collision>
  </link>
  <link name="lh_ring_proximal">
    <inertial>
      <origin xyz="-0.00114185484356009 3.47315809493265e-05 0.0228928405060199" rpy="0 0 0" />
      <mass value="0.00450921353946778" />
      <inertia ixx="6.66673081759646e-07" ixy="-1.07184694208142e-11" ixz="-2.53143399406658e-08" iyy="6.74195868060947e-07" iyz="-1.59054446512071e-10" izz="1.3575909184966e-07" />
    </inertial>
    <visual>
      <origin xyz="0 0 0" rpy="0 0 0" />
      <geometry><mesh filename="meshes/ring_proximal.STL" /></geometry>
      <material name=""><color rgba="1 1 1 1" /></material>
    </visual>
    <collision>
      <origin xyz="0 0 0" rpy="0 0 0" />
      <geometry><mesh filename="meshes/ring_proximal.STL" /></geometry>
    </collision>
  </link>
  <link name="lh_ring_middle">
    <inertial>
      <origin xyz="-0.00020699321531438 2.60746916563859e-06 0.0167065326651803" rpy="0 0 0" />
      <mass value="0.00237827433282015" />
      <inertia ixx="2.29538714144179e-07" ixy="2.25259718797087e-12" ixz="-1.47340121880382e-08" iyy="1.76761312824203e-07" iyz="1.15994674932479e-11" izz="9.62797743780677e-08" />
    </inertial>
    <visual>
      <origin xyz="0 0 0" rpy="0 0 0" />
      <geometry><mesh filename="meshes/ring_middle.STL" /></geometry>
      <material name=""><color rgba="1 1 1 1" /></material>
    </visual>
    <collision>
      <origin xyz="0 0 0" rpy="0 0 0" />
      <geometry><mesh filename="meshes/ring_middle.STL" /></geometry>
    </collision>
  </link>
  <link name="lh_ring_distal">
    <inertial>
      <origin xyz="-0.0081624655153107 2.27057324615476e-05 0.00811806561376854" rpy="0 0 0" />
      <mass value="0.00334170280386792" />
      <inertia ixx="1.59570757957895e-07" ixy="1.51461030930522e-10" ixz="-5.94291750853635e-08" iyy="1.78095650648522e-07" iyz="-1.2484716714453e-10" izz="1.34141394018405e-07" />
    </inertial>
    <visual>
      <origin xyz="0 0 0" rpy="0 0 0" />
      <geometry><mesh filename="meshes/ring_distal.STL" /></geometry>
      <material name=""><color rgba="1 1 1 1" /></material>
    </visual>
    <collision>
      <origin xyz="0 0 0" rpy="0 0 0" />
      <geometry><mesh filename="meshes/ring_distal.STL" /></geometry>
    </collision>
  </link>
  <link name="lh_pinky_metacarpals">
    <inertial>
      <origin xyz="-0.00794299617469867 -2.9300686296696e-07 0.00220106329602079" rpy="0 0 0" />
      <mass value="0.000895516947513541" />
      <inertia ixx="3.46279958591138e-08" ixy="-3.91785473098584e-13" ixz="5.91029262259818e-09" iyy="2.85435605328821e-08" iyz="-5.27457876763101e-13" izz="4.38102218637476e-08" />
    </inertial>
    <visual>
      <origin xyz="0 0 0" rpy="0 0 0" />
      <geometry><mesh filename="meshes/pinky_metacarpals.STL" /></geometry>
      <material name=""><color rgba="1 1 1 1" /></material>
    </visual>
    <collision>
      <origin xyz="0 0 0" rpy="0 0 0" />
      <geometry><mesh filename="meshes/pinky_metacarpals.STL" /></geometry>
    </collision>
  </link>
  <link name="lh_pinky_proximal">
    <inertial>
      <origin xyz="-0.00114185484350746 3.47315809787474e-05 0.0228928405060759" rpy="0 0 0" />
      <mass value="0.00450921353949741" />
      <inertia ixx="6.66673081761478e-07" ixy="-1.07184692555283e-11" ixz="-2.53143399404374e-08" iyy="6.74195868062215e-07" iyz="-1.59054445649156e-10" izz="1.35759091850319e-07" />
    </inertial>
    <visual>
      <origin xyz="0 0 0" rpy="0 0 0" />
      <geometry><mesh filename="meshes/pinky_proximal.STL" /></geometry>
      <material name=""><color rgba="1 1 1 1" /></material>
    </visual>
    <collision>
      <origin xyz="0 0 0" rpy="0 0 0" />
      <geometry><mesh filename="meshes/pinky_proximal.STL" /></geometry>
    </collision>
  </link>
  <link name="lh_pinky_middle">
    <inertial>
      <origin xyz="-0.000206993248553502 2.60748984004522e-06 0.0167065326828462" rpy="0 0 0" />
      <mass value="0.00237827431921004" />
      <inertia ixx="2.29538713829186e-07" ixy="2.25292379523651e-12" ixz="-1.47340119230773e-08" iyy="1.76761312133621e-07" iyz="1.15993142153177e-11" izz="9.62797736254209e-08" />
    </inertial>
    <visual>
      <origin xyz="0 0 0" rpy="0 0 0" />
      <geometry><mesh filename="meshes/pinky_middle.STL" /></geometry>
      <material name=""><color rgba="1 1 1 1" /></material>
    </visual>
    <collision>
      <origin xyz="0 0 0" rpy="0 0 0" />
      <geometry><mesh filename="meshes/pinky_middle.STL" /></geometry>
    </collision>
  </link>
  <link name="lh_pinky_distal">
    <inertial>
      <origin xyz="-0.00816246615274486 2.27054189396725e-05 0.00811806634481432" rpy="0 0 0" />
      <mass value="0.00334170283969146" />
      <inertia ixx="1.59570758932551e-07" ixy="1.51458416419677e-10" ixz="-5.94291815262966e-08" iyy="1.7809566305509e-07" iyz="-1.24846982879422e-10" izz="1.34141398854287e-07" />
    </inertial>
    <visual>
      <origin xyz="0 0 0" rpy="0 0 0" />
      <geometry><mesh filename="meshes/pinky_distal.STL" /></geometry>
      <material name=""><color rgba="1 1 1 1" /></material>
    </visual>
    <collision>
      <origin xyz="0 0 0" rpy="0 0 0" />
      <geometry><mesh filename="meshes/pinky_distal.STL" /></geometry>
    </collision>
  </link>
  <joint name="lh_thumb_cmc_roll" type="revolute">
    <origin xyz="0.01916 -0.01 0.0436" rpy="0 0 0" />
    <parent link="lh_hand_base_link" />
    <child link="lh_thumb_metacarpals_base1" />
    <axis xyz="-1 0 0" />
    <limit lower="0" upper="1.309" effort="100" velocity="1" />
  </joint>
  <joint name="lh_thumb_cmc_yaw" type="revolute">
    <origin xyz="0.019845 0 0" rpy="0.77165 0 0" />
    <parent link="lh_thumb_metacarpals_base1" />
    <child link="lh_thumb_metacarpals_base2" />
    <axis xyz="0 0 1" />
    <limit lower="0" upper="1.5882" effort="100" velocity="1" />
  </joint>
  <joint name="lh_thumb_cmc_pitch" type="revolute">
    <origin xyz="0.0088218 -0.024245 0.0005" rpy="0 -0.91 1.9199" />
    <parent link="lh_thumb_metacarpals_base2" />
    <child link="lh_thumb_metacarpals" />
    <axis xyz="0 1 0" />
    <limit lower="0" upper="0.7854" effort="100" velocity="1" />
  </joint>
  <joint name="lh_thumb_mcp" type="revolute">
    <origin xyz="0.0127018248047608 0 0.0627256157349894" rpy="0 0 0" />
    <parent link="lh_thumb_metacarpals" />
    <child link="lh_thumb_proximal" />
    <axis xyz="0 1 0" />
    <limit lower="0" upper="1.2217" effort="100" velocity="1" />
  </joint>
  <joint name="lh_thumb_dip" type="revolute">
    <origin xyz="-0.00483652209209624 0 0.0342226492098615" rpy="0 0 0" />
    <parent link="lh_thumb_proximal" />
    <child link="lh_thumb_distal" />
    <axis xyz="0 1 0" />
    <limit lower="0" upper="1.2392" effort="100" velocity="1" />
    <mimic joint="lh_thumb_mcp" multiplier="1.0142" offset="0" />
  </joint>
  <joint name="lh_index_mcp_roll" type="revolute">
    <origin xyz="0.0038 -0.03525 0.1481" rpy="0 0 0" />
    <parent link="lh_hand_base_link" />
    <child link="lh_index_metacarpals" />
    <axis xyz="-1 0 0" />
    <limit lower="-0.2269" upper="0.2269" effort="100" velocity="1" />
  </joint>
  <joint name="lh_index_mcp_pitch" type="revolute">
    <origin xyz="-0.0021302 0 0" rpy="0 0 0" />
    <parent link="lh_index_metacarpals" />
    <child link="lh_index_proximal" />
    <axis xyz="0 1 0" />
    <limit lower="0" upper="1.2217" effort="100" velocity="1" />
  </joint>
  <joint name="lh_index_pip" type="revolute">
    <origin xyz="-0.0041946 0 0.044819" rpy="0 0 0" />
    <parent link="lh_index_proximal" />
    <child link="lh_index_middle" />
    <axis xyz="0 1 0" />
    <limit lower="0" upper="1.7279" effort="100" velocity="1" />
  </joint>
  <joint name="lh_index_dip" type="revolute">
    <origin xyz="0.0028245 0 0.031696" rpy="0 0 0" />
    <parent link="lh_index_middle" />
    <child link="lh_index_distal" />
    <axis xyz="0 1 0" />
    <limit lower="0" upper="1.3614" effort="100" velocity="1" />
    <mimic joint="lh_index_pip" multiplier="0.7879" offset="0" />
  </joint>
  <joint name="lh_middle_mcp_roll" type="revolute">
    <origin xyz="0.00379999999265848 -0.0117500000029305 0.1526" rpy="0 0 0" />
    <parent link="lh_hand_base_link" />
    <child link="lh_middle_metacarpals" />
    <axis xyz="-1 0 0" />
    <limit lower="-0.23" upper="0.23" effort="100" velocity="1" />
  </joint>
  <joint name="lh_middle_mcp_pitch" type="revolute">
    <origin xyz="-0.0021302 0 0" rpy="0 0 0" />
    <parent link="lh_middle_metacarpals" />
    <child link="lh_middle_proximal" />
    <axis xyz="0 1 0" />
    <limit lower="0" upper="1.2217" effort="100" velocity="1" />
  </joint>
  <joint name="lh_middle_pip" type="revolute">
    <origin xyz="-0.00419457745591796 0 0.0448194332262389" rpy="0 0 0" />
    <parent link="lh_middle_proximal" />
    <child link="lh_middle_middle" />
    <axis xyz="0 1 0" />
    <limit lower="0" upper="1.7279" effort="100" velocity="1" />
  </joint>
  <joint name="lh_middle_dip" type="revolute">
    <origin xyz="0.0028245 0 0.031696" rpy="0 0 0" />
    <parent link="lh_middle_middle" />
    <child link="lh_middle_distal" />
    <axis xyz="0 1 0" />
    <limit lower="0" upper="1.3614" effort="100" velocity="1" />
    <mimic joint="lh_middle_pip" multiplier="0.7879" offset="0" />
  </joint>
  <joint name="lh_ring_mcp_roll" type="revolute">
    <origin xyz="0.00379999999632174 0.0117499999970695 0.1481" rpy="0 0 0" />
    <parent link="lh_hand_base_link" />
    <child link="lh_ring_metacarpals" />
    <axis xyz="-1 0 0" />
    <limit lower="-0.23" upper="0.23" effort="100" velocity="1" />
  </joint>
  <joint name="lh_ring_mcp_pitch" type="revolute">
    <origin xyz="-0.0021302 0 0" rpy="0 0 0" />
    <parent link="lh_ring_metacarpals" />
    <child link="lh_ring_proximal" />
    <axis xyz="0 1 0" />
    <limit lower="0" upper="1.2217" effort="100" velocity="1" />
  </joint>
  <joint name="lh_ring_pip" type="revolute">
    <origin xyz="-0.00419457745591796 0 0.0448194332262389" rpy="0 0 0" />
    <parent link="lh_ring_proximal" />
    <child link="lh_ring_middle" />
    <axis xyz="0 1 0" />
    <limit lower="0" upper="1.7279" effort="100" velocity="1" />
  </joint>
  <joint name="lh_ring_dip" type="revolute">
    <origin xyz="0.0028245 0 0.031696" rpy="0 0 0" />
    <parent link="lh_ring_middle" />
    <child link="lh_ring_distal" />
    <axis xyz="0 1 0" />
    <limit lower="0" upper="1.3614" effort="100" velocity="1" />
    <mimic joint="lh_ring_pip" multiplier="0.7879" offset="0" />
  </joint>
  <joint name="lh_pinky_mcp_roll" type="revolute">
    <origin xyz="0.00379999999998499 0.0352499999970695 0.1436" rpy="0 0 0" />
    <parent link="lh_hand_base_link" />
    <child link="lh_pinky_metacarpals" />
    <axis xyz="-1 0 0" />
    <limit lower="-0.23" upper="0.23" effort="100" velocity="1" />
  </joint>
  <joint name="lh_pinky_mcp_pitch" type="revolute">
    <origin xyz="-0.0021302 0 0" rpy="0 0 0" />
    <parent link="lh_pinky_metacarpals" />
    <child link="lh_pinky_proximal" />
    <axis xyz="0 1 0" />
    <limit lower="0" upper="1.2217" effort="100" velocity="1" />
  </joint>
  <joint name="lh_pinky_pip" type="revolute">
    <origin xyz="-0.0041946 0 0.044819" rpy="0 0 0" />
    <parent link="lh_pinky_proximal" />
    <child link="lh_pinky_middle" />
    <axis xyz="0 1 0" />
    <limit lower="0" upper="1.7279" effort="100" velocity="1" />
  </joint>
  <joint name="lh_pinky_dip" type="revolute">
    <origin xyz="0.0028245 0 0.031696" rpy="0 0 0" />
    <parent link="lh_pinky_middle" />
    <child link="lh_pinky_distal" />
    <axis xyz="0 1 0" />
    <limit lower="0" upper="1.3614" effort="100" velocity="1" />
    <mimic joint="lh_pinky_pip" multiplier="0.7879" offset="0" />
  </joint>
</robot>
