<mujoco model="ar5_left">
  <compiler meshdir="meshes" discardvisual="false" autolimits="true" angle="radian" eulerseq="XYZ"/>
  <option/>

  <default>
    <default class="arm_ar5_visual">
      <geom type="mesh" contype="0" conaffinity="0" group="1"/>
    </default>
    <default class="arm_ar5_collision">
      <geom type="mesh" contype="1" conaffinity="1" group="3"/>
    </default>
  </default>

  <asset>
    <mesh name="ar5_base"  file="AR5_5_07L_W4C4A2_base.stl"  scale="0.001 0.001 0.001"/>
    <mesh name="ar5_link1" file="AR5_5_07L_W4C4A2_link1.stl" scale="0.001 0.001 0.001"/>
    <mesh name="ar5_link2" file="AR5_5_07L_W4C4A2_link2.stl" scale="0.001 0.001 0.001"/>
    <mesh name="ar5_link3" file="AR5_5_07L_W4C4A2_link3.stl" scale="0.001 0.001 0.001"/>
    <mesh name="ar5_link4" file="AR5_5_07L_W4C4A2_link4.stl" scale="0.001 0.001 0.001"/>
    <mesh name="ar5_link5" file="AR5_5_07L_W4C4A2_link5.stl" scale="0.001 0.001 0.001"/>
    <mesh name="ar5_link6" file="AR5_5_07L_W4C4A2_link6.stl" scale="0.001 0.001 0.001"/>
    <mesh name="ar5_link7" file="AR5_5_07L_W4C4A2_link7.stl" scale="0.001 0.001 0.001"/>
  </asset>

  <worldbody>
    <body name="AR5_5_07L_W4C4A2_base" pos="0 0 0">
      <geom class="arm_ar5_visual" mesh="ar5_base"/>
      <geom class="arm_ar5_collision" mesh="ar5_base"/>
      <site name="base_mount" pos="0 0 0"/>

      <body name="AR5_5_07L_W4C4A2_link1" pos="0 0 0">
        <inertial pos="1e-06 -0.000621 0.167909" mass="2.683"
                  fullinertia="0.00493673 0.00452344 0.00432910 0.00000160 0.00000198 -0.00000020"/>
        <joint name="AR5_5_07L_W4C4A2_joint_1" type="hinge" axis="0 0 1"
               range="-3.1067 3.1067" damping="14.22378" frictionloss="0.0" armature="0.01"/>
        <geom class="arm_ar5_visual" mesh="ar5_link1"/>
        <geom class="arm_ar5_collision" mesh="ar5_link1"/>

        <body name="AR5_5_07L_W4C4A2_link2" pos="0 0 0.1745">
          <inertial pos="-2e-05 -0.003081 0.10298600000000001" mass="2.3"
                    fullinertia="0.01151906 0.00993335 0.00435237 0.00000246 -0.00000055 0.00082477"/>
          <joint name="AR5_5_07L_W4C4A2_joint_2" type="hinge" axis="0 1 0"
                 range="-2.0944 2.0944" damping="13.710972" frictionloss="0.0" armature="0.01"/>
          <geom class="arm_ar5_visual" mesh="ar5_link2"/>
          <geom class="arm_ar5_collision" mesh="ar5_link2"/>

          <body name="AR5_5_07L_W4C4A2_link3" pos="0 0 0.314">
            <inertial pos="0.007097 -0.0006590000000000001 -0.016530999999999997" mass="1.862"
                      fullinertia="0.00519681 0.00470446 0.00266752 0.00001208 0.00035761 0.00003430"/>
            <joint name="AR5_5_07L_W4C4A2_joint_3" type="hinge" axis="0 0 1"
                   range="-3.1067 3.1067" damping="3.791042" frictionloss="0.0" armature="0.01"/>
            <geom class="arm_ar5_visual" mesh="ar5_link3"/>
            <geom class="arm_ar5_collision" mesh="ar5_link3"/>

            <body name="AR5_5_07L_W4C4A2_link4" pos="0.01 0 0">
              <inertial pos="-0.007826 -0.004207 0.073404" mass="1.234"
                        fullinertia="0.00389590 0.00308657 0.00188364 -0.00004577 -0.00017280 0.00046679"/>
              <joint name="AR5_5_07L_W4C4A2_joint_4" type="hinge" axis="0 1 0"
                     range="-1.0472 2.5307" damping="0.333154" frictionloss="0.0" armature="0.01"/>
              <geom class="arm_ar5_visual" mesh="ar5_link4"/>
              <geom class="arm_ar5_collision" mesh="ar5_link4"/>

              <body name="AR5_5_07L_W4C4A2_link5" pos="-0.01 0 0.272">
                <inertial pos="0.00028399999999999996 0.0016510000000000001 -0.084133" mass="1.329"
                          fullinertia="0.00281562 0.00221084 0.00182169 0.00001782 0.00001650 0.00002100"/>
                <joint name="AR5_5_07L_W4C4A2_joint_5" type="hinge" axis="0 0 1"
                       range="-3.1067 3.1067" damping="4.136716" frictionloss="0.0" armature="0.01"/>
                <geom class="arm_ar5_visual" mesh="ar5_link5"/>
                <geom class="arm_ar5_collision" mesh="ar5_link5"/>

                <body name="AR5_5_07L_W4C4A2_link6" pos="0 0 0">
                  <inertial pos="0.005405999999999999 0.000612 -3.9e-05" mass="0.93"
                            fullinertia="0.00072078 0.00085153 0.00090205 -0.00000217 0.00000108 0.00000048"/>
                  <joint name="AR5_5_07L_W4C4A2_joint_6" type="hinge" axis="0 1 0"
                         range="-1.0472 1.0472" damping="4.748679" frictionloss="0.0" armature="0.01"/>
                  <geom class="arm_ar5_visual" mesh="ar5_link6"/>
                  <geom class="arm_ar5_collision" mesh="ar5_link6"/>

                  <body name="AR5_5_07L_W4C4A2_link7" pos="0 0 0">
                    <inertial pos="-0.00277 0.000316 0.054881" mass="0.33"
                              fullinertia="0.00051942 0.00079132 0.00045886 -0.00000052 0.00003721 0.00000265"/>
                    <joint name="AR5_5_07L_W4C4A2_joint_7" type="hinge" axis="1 0 0"
                           range="-1.0472 1.0472" damping="3.667978" frictionloss="0.0" armature="0.01"/>
                    <geom class="arm_ar5_visual" mesh="ar5_link7"/>
                    <geom class="arm_ar5_collision" mesh="ar5_link7"/>

                    <body name="AR5_5_07L_W4C4A2_tcp" pos="0 0 0.097">
                      <site name="tool0" pos="0 0 0"/>
                    </body>
                  </body>
                </body>
              </body>
            </body>
          </body>
        </body>
      </body>
    </body>
  </worldbody>

  <actuator>
    <position name="AR5_5_07L_W4C4A2_joint_1_act" joint="AR5_5_07L_W4C4A2_joint_1" kp="1000" kv="4" ctrlrange="-3.1067 3.1067"/>
    <position name="AR5_5_07L_W4C4A2_joint_2_act" joint="AR5_5_07L_W4C4A2_joint_2" kp="1000" kv="4" ctrlrange="-2.0944 2.0944"/>
    <position name="AR5_5_07L_W4C4A2_joint_3_act" joint="AR5_5_07L_W4C4A2_joint_3" kp="1000" kv="4" ctrlrange="-3.1067 3.1067"/>
    <position name="AR5_5_07L_W4C4A2_joint_4_act" joint="AR5_5_07L_W4C4A2_joint_4" kp="1000" kv="4" ctrlrange="-1.0472 2.5307"/>
    <position name="AR5_5_07L_W4C4A2_joint_5_act" joint="AR5_5_07L_W4C4A2_joint_5" kp="1000" kv="4" ctrlrange="-3.1067 3.1067"/>
    <position name="AR5_5_07L_W4C4A2_joint_6_act" joint="AR5_5_07L_W4C4A2_joint_6" kp="1000" kv="4" ctrlrange="-1.0472 1.0472"/>
    <position name="AR5_5_07L_W4C4A2_joint_7_act" joint="AR5_5_07L_W4C4A2_joint_7" kp="1000" kv="4" ctrlrange="-1.0472 1.0472"/>
  </actuator>

  <contact>
    <exclude body1="AR5_5_07L_W4C4A2_base"  body2="AR5_5_07L_W4C4A2_link1"/>
    <exclude body1="AR5_5_07L_W4C4A2_link1" body2="AR5_5_07L_W4C4A2_link2"/>
    <exclude body1="AR5_5_07L_W4C4A2_link2" body2="AR5_5_07L_W4C4A2_link3"/>
    <exclude body1="AR5_5_07L_W4C4A2_link3" body2="AR5_5_07L_W4C4A2_link4"/>
    <exclude body1="AR5_5_07L_W4C4A2_link4" body2="AR5_5_07L_W4C4A2_link5"/>
    <exclude body1="AR5_5_07L_W4C4A2_link5" body2="AR5_5_07L_W4C4A2_link6"/>
    <exclude body1="AR5_5_07L_W4C4A2_link6" body2="AR5_5_07L_W4C4A2_link7"/>
    <exclude body1="AR5_5_07L_W4C4A2_link5" body2="AR5_5_07L_W4C4A2_link7"/>
  </contact>
</mujoco>
