<?xml version="1.0" encoding="UTF-8"?>
<!-- Generated by linker_robot_assets.composer (version 0.1.0). Workstation: lkls73_i1_l25_bimanual. Recipe sha256: b13bb8b60f41364573b4956b43acd7cb141d18f3e565a9a7606d4606cc612ff5. Do not edit by hand; re-run `python -m linker_robot_assets.composer.compose <workstation>`. -->
<mujoco model="lkls73_i1_l25_bimanual">
  <compiler discardvisual="false" autolimits="true" angle="radian" eulerseq="XYZ" />
  <option />
  <default>
    <default class="base_base_lkls73_torso_visual">
      <geom type="mesh" contype="0" conaffinity="0" group="1" />
    </default>
    <default class="base_base_lkls73_torso_collision">
      <geom type="mesh" contype="1" conaffinity="1" group="3" />
    </default>
    <default class="arm_left_arm_lkls73_arm_visual">
      <geom type="mesh" contype="0" conaffinity="0" group="1" />
    </default>
    <default class="arm_left_arm_lkls73_arm_collision">
      <geom type="mesh" contype="1" conaffinity="1" group="3" />
    </default>
    <default class="arm_right_arm_lkls73_arm_visual">
      <geom type="mesh" contype="0" conaffinity="0" group="1" />
    </default>
    <default class="arm_right_arm_lkls73_arm_collision">
      <geom type="mesh" contype="1" conaffinity="1" group="3" />
    </default>
    <default class="hand_left_hand_linkerhand_l25_visual">
      <geom type="mesh" contype="0" conaffinity="0" group="1" />
    </default>
    <default class="hand_left_hand_linkerhand_l25_collision">
      <geom type="mesh" contype="1" conaffinity="1" group="3" />
    </default>
    <default class="hand_left_hand_linkerhand_l25_joint">
      <joint armature="3.4707e-08" damping="4.0" frictionloss="0.5" />
    </default>
    <default class="hand_right_hand_linkerhand_l25_visual">
      <geom type="mesh" contype="0" conaffinity="0" group="1" />
    </default>
    <default class="hand_right_hand_linkerhand_l25_collision">
      <geom type="mesh" contype="1" conaffinity="1" group="3" />
    </default>
    <default class="hand_right_hand_linkerhand_l25_joint">
      <joint armature="3.4707e-08" damping="4.0" frictionloss="0.5" />
    </default>
  </default>
  <asset>
    <mesh name="base_torso_base_link" file="../../components/bases/lkls73_torso/variants/default/meshes/base_link.STL" />
    <mesh name="arm_left_L1" file="../../components/arms/lkls73_arm/variants/left/meshes/L1_Link.STL" />
    <mesh name="arm_left_L2" file="../../components/arms/lkls73_arm/variants/left/meshes/L2_Link.STL" />
    <mesh name="arm_left_L3" file="../../components/arms/lkls73_arm/variants/left/meshes/L3_Link.STL" />
    <mesh name="arm_left_L4" file="../../components/arms/lkls73_arm/variants/left/meshes/L4_Link.STL" />
    <mesh name="arm_left_L5" file="../../components/arms/lkls73_arm/variants/left/meshes/L5_Link.STL" />
    <mesh name="arm_left_L6" file="../../components/arms/lkls73_arm/variants/left/meshes/L6_Link.STL" />
    <mesh name="arm_left_L7" file="../../components/arms/lkls73_arm/variants/left/meshes/L7_Link.STL" />
    <mesh name="arm_left_L8" file="../../components/arms/lkls73_arm/variants/left/meshes/L8_Link.STL" />
    <mesh name="arm_right_R1" file="../../components/arms/lkls73_arm/variants/right/meshes/R1_Link.STL" />
    <mesh name="arm_right_R2" file="../../components/arms/lkls73_arm/variants/right/meshes/R2_Link.STL" />
    <mesh name="arm_right_R3" file="../../components/arms/lkls73_arm/variants/right/meshes/R3_Link.STL" />
    <mesh name="arm_right_R4" file="../../components/arms/lkls73_arm/variants/right/meshes/R4_Link.STL" />
    <mesh name="arm_right_R5" file="../../components/arms/lkls73_arm/variants/right/meshes/R5_Link.STL" />
    <mesh name="arm_right_R6" file="../../components/arms/lkls73_arm/variants/right/meshes/R6_Link.STL" />
    <mesh name="arm_right_R7" file="../../components/arms/lkls73_arm/variants/right/meshes/R7_Link.STL" />
    <mesh name="arm_right_R8" file="../../components/arms/lkls73_arm/variants/right/meshes/R8_Link.STL" />
    <mesh name="hand_left_hand_base_link" file="../../components/hands/linkerhand_l25/variants/left/meshes/hand_base_link.STL" />
    <mesh name="hand_left_thumb_metacarpals_base1" file="../../components/hands/linkerhand_l25/variants/left/meshes/thumb_metacarpals_base1.STL" />
    <mesh name="hand_left_thumb_metacarpals_base2" file="../../components/hands/linkerhand_l25/variants/left/meshes/thumb_metacarpals_base2.STL" />
    <mesh name="hand_left_thumb_metacarpals" file="../../components/hands/linkerhand_l25/variants/left/meshes/thumb_metacarpals.STL" />
    <mesh name="hand_left_thumb_proximal" file="../../components/hands/linkerhand_l25/variants/left/meshes/thumb_proximal.STL" />
    <mesh name="hand_left_thumb_distal" file="../../components/hands/linkerhand_l25/variants/left/meshes/thumb_distal.STL" />
    <mesh name="hand_left_index_metacarpals" file="../../components/hands/linkerhand_l25/variants/left/meshes/index_metacarpals.STL" />
    <mesh name="hand_left_index_proximal" file="../../components/hands/linkerhand_l25/variants/left/meshes/index_proximal.STL" />
    <mesh name="hand_left_index_middle" file="../../components/hands/linkerhand_l25/variants/left/meshes/index_middle.STL" />
    <mesh name="hand_left_index_distal" file="../../components/hands/linkerhand_l25/variants/left/meshes/index_distal.STL" />
    <mesh name="hand_left_middle_metacarpals" file="../../components/hands/linkerhand_l25/variants/left/meshes/middle_metacarpals.STL" />
    <mesh name="hand_left_middle_proximal" file="../../components/hands/linkerhand_l25/variants/left/meshes/middle_proximal.STL" />
    <mesh name="hand_left_middle_middle" file="../../components/hands/linkerhand_l25/variants/left/meshes/middle_middle.STL" />
    <mesh name="hand_left_middle_distal" file="../../components/hands/linkerhand_l25/variants/left/meshes/middle_distal.STL" />
    <mesh name="hand_left_ring_metacarpals" file="../../components/hands/linkerhand_l25/variants/left/meshes/ring_metacarpals.STL" />
    <mesh name="hand_left_ring_proximal" file="../../components/hands/linkerhand_l25/variants/left/meshes/ring_proximal.STL" />
    <mesh name="hand_left_ring_middle" file="../../components/hands/linkerhand_l25/variants/left/meshes/ring_middle.STL" />
    <mesh name="hand_left_ring_distal" file="../../components/hands/linkerhand_l25/variants/left/meshes/ring_distal.STL" />
    <mesh name="hand_left_pinky_metacarpals" file="../../components/hands/linkerhand_l25/variants/left/meshes/pinky_metacarpals.STL" />
    <mesh name="hand_left_pinky_proximal" file="../../components/hands/linkerhand_l25/variants/left/meshes/pinky_proximal.STL" />
    <mesh name="hand_left_pinky_middle" file="../../components/hands/linkerhand_l25/variants/left/meshes/pinky_middle.STL" />
    <mesh name="hand_left_pinky_distal" file="../../components/hands/linkerhand_l25/variants/left/meshes/pinky_distal.STL" />
    <mesh name="hand_right_hand_base_link" file="../../components/hands/linkerhand_l25/variants/right/meshes/hand_base_link.STL" />
    <mesh name="hand_right_thumb_metacarpals_base1" file="../../components/hands/linkerhand_l25/variants/right/meshes/thumb_metacarpals_base1.STL" />
    <mesh name="hand_right_thumb_metacarpals_base2" file="../../components/hands/linkerhand_l25/variants/right/meshes/thumb_metacarpals_base2.STL" />
    <mesh name="hand_right_thumb_metacarpals" file="../../components/hands/linkerhand_l25/variants/right/meshes/thumb_metacarpals.STL" />
    <mesh name="hand_right_thumb_proximal" file="../../components/hands/linkerhand_l25/variants/right/meshes/thumb_proximal.STL" />
    <mesh name="hand_right_thumb_distal" file="../../components/hands/linkerhand_l25/variants/right/meshes/thumb_distal.STL" />
    <mesh name="hand_right_index_metacarpals" file="../../components/hands/linkerhand_l25/variants/right/meshes/index_metacarpals.STL" />
    <mesh name="hand_right_index_proximal" file="../../components/hands/linkerhand_l25/variants/right/meshes/index_proximal.STL" />
    <mesh name="hand_right_index_middle" file="../../components/hands/linkerhand_l25/variants/right/meshes/index_middle.STL" />
    <mesh name="hand_right_index_distal" file="../../components/hands/linkerhand_l25/variants/right/meshes/index_distal.STL" />
    <mesh name="hand_right_middle_metacarpals" file="../../components/hands/linkerhand_l25/variants/right/meshes/middle_metacarpals.STL" />
    <mesh name="hand_right_middle_proximal" file="../../components/hands/linkerhand_l25/variants/right/meshes/middle_proximal.STL" />
    <mesh name="hand_right_middle_middle" file="../../components/hands/linkerhand_l25/variants/right/meshes/middle_middle.STL" />
    <mesh name="hand_right_middle_distal" file="../../components/hands/linkerhand_l25/variants/right/meshes/middle_distal.STL" />
    <mesh name="hand_right_ring_metacarpals" file="../../components/hands/linkerhand_l25/variants/right/meshes/ring_metacarpals.STL" />
    <mesh name="hand_right_ring_proximal" file="../../components/hands/linkerhand_l25/variants/right/meshes/ring_proximal.STL" />
    <mesh name="hand_right_ring_middle" file="../../components/hands/linkerhand_l25/variants/right/meshes/ring_middle.STL" />
    <mesh name="hand_right_ring_distal" file="../../components/hands/linkerhand_l25/variants/right/meshes/ring_distal.STL" />
    <mesh name="hand_right_pinky_metacarpals" file="../../components/hands/linkerhand_l25/variants/right/meshes/pinky_metacarpals.STL" />
    <mesh name="hand_right_pinky_proximal" file="../../components/hands/linkerhand_l25/variants/right/meshes/pinky_proximal.STL" />
    <mesh name="hand_right_pinky_middle" file="../../components/hands/linkerhand_l25/variants/right/meshes/pinky_middle.STL" />
    <mesh name="hand_right_pinky_distal" file="../../components/hands/linkerhand_l25/variants/right/meshes/pinky_distal.STL" />
  </asset>
  <worldbody>
    <body name="base_torso_root" pos="0 0 0">
      <body name="base_base_link" pos="0 0 1.2">
        <inertial pos="5.75109188383945E-05 1.44120839455095E-05 -0.489174317245241" mass="10.8067081992573" fullinertia="0.192527915393298 0.191539752328327 0.103049415034787 -1.67956043663548E-08 -3.68569447484118E-08 6.60319145138974E-08" />
        <geom class="base_base_lkls73_torso_visual" mesh="base_torso_base_link" />
        <geom class="base_base_lkls73_torso_collision" mesh="base_torso_base_link" />
        <body name="base_arm_left_mount" pos="0 0.164 0">
          <site name="base_arm_left_mount" pos="0 0 0" />
          <body name="arm_left_L_arm_root" pos="0 0 0">
            <site name="arm_left_base_mount" pos="0 0 0" />
            <body name="arm_left_L1_Link" pos="0 0 0">
              <inertial pos="0.00235600060651345 0.0538143182293528 0.00010452198160641" mass="1.3997199601261" fullinertia="0.00114445383866051 0.000654874787984474 0.000691494366096022 -2.33503672142218E-06 -9.94413789148138E-09 1.05907637546798E-06" />
              <joint name="arm_left_L1_Joint" type="hinge" axis="0 -1 0" range="-2.91 2.91" damping="20" frictionloss="0.0" armature="0.01" />
              <geom class="arm_left_arm_lkls73_arm_visual" mesh="arm_left_L1" />
              <geom class="arm_left_arm_lkls73_arm_collision" mesh="arm_left_L1" />
              <body name="arm_left_L2_Link" pos="0 0.058 0">
                <inertial pos="0.001618419731441 8.17586538826021E-06 -0.0795739675465699" mass="1.14210487960353" fullinertia="0.000999259952314694 0.000929597687983869 0.000490873838603504 4.38390447469883E-06 -1.34113970553355E-06 2.7922699166407E-07" />
                <joint name="arm_left_L2_Joint" type="hinge" axis="-1 0 0" range="-3.2 0.07" damping="20" frictionloss="0.0" armature="0.01" />
                <geom class="arm_left_arm_lkls73_arm_visual" mesh="arm_left_L2" />
                <geom class="arm_left_arm_lkls73_arm_collision" mesh="arm_left_L2" />
                <body name="arm_left_L3_Link" pos="-2.5018E-05 0 -0.123">
                  <inertial pos="0.000181280975708543 0.0012493056236523 -0.128548942292033" mass="1.2798435287888" fullinertia="0.00158095142201815 0.00163152743924312 0.000344148864762278 7.74063763820645E-07 -8.68119829913453E-07 -2.41539579836192E-06" />
                  <joint name="arm_left_L3_Joint" type="hinge" axis="0 0 1" range="-2.69 2.69" damping="20" frictionloss="0.0" armature="0.01" />
                  <geom class="arm_left_arm_lkls73_arm_visual" mesh="arm_left_L3" />
                  <geom class="arm_left_arm_lkls73_arm_collision" mesh="arm_left_L3" />
                  <body name="arm_left_L4_Link" pos="2.4267E-05 0 -0.1621">
                    <inertial pos="-3.38229166406629E-06 0.00077842370454409 -0.08460011635447" mass="0.935504485205333" fullinertia="0.000508246005403967 0.000524130562919452 0.000333983371716017 -4.123494432482E-06 -1.601236457745E-07 -3.45757221458974E-07" />
                    <joint name="arm_left_L4_Joint" type="hinge" axis="0 -1 0" range="-2.05 2.05" damping="20" frictionloss="0.0" armature="0.01" />
                    <geom class="arm_left_arm_lkls73_arm_visual" mesh="arm_left_L4" />
                    <geom class="arm_left_arm_lkls73_arm_collision" mesh="arm_left_L4" />
                    <body name="arm_left_L5_Link" pos="0 0 -0.124">
                      <inertial pos="-7.8967109106414E-05 0.00127705818106172 -0.0361222642165061" mass="0.298012293033296" fullinertia="0.000356324975203863 0.000385006059216245 0.000101746640600842 8.49346343481351E-07 -1.06208641170066E-06 2.16302454958746E-06" />
                      <joint name="arm_left_L5_Joint" type="hinge" axis="0 0 1" range="-2.69 2.69" damping="20" frictionloss="0.0" armature="0.01" />
                      <geom class="arm_left_arm_lkls73_arm_visual" mesh="arm_left_L5" />
                      <geom class="arm_left_arm_lkls73_arm_collision" mesh="arm_left_L5" />
                      <body name="arm_left_L6_Link" pos="0 0 -0.0881">
                        <inertial pos="0.00423270788750624 -0.00438646585481159 -0.0324823655341541" mass="0.344326210144814" fullinertia="0.000194396852170226 0.000233882186601331 0.000101458599044909 1.34053122918212E-06 9.47054882668167E-06 2.86885239016126E-07" />
                        <joint name="arm_left_L6_Joint" type="hinge" axis="0 -1 0" range="-1.59 1.59" damping="20" frictionloss="0.0" armature="0.01" />
                        <geom class="arm_left_arm_lkls73_arm_visual" mesh="arm_left_L6" />
                        <geom class="arm_left_arm_lkls73_arm_collision" mesh="arm_left_L6" />
                        <body name="arm_left_L7_Link" pos="-2.6563E-05 0 -0.0655">
                          <inertial pos="-0.00330667550396703 2.7195733834362E-07 -0.0202430179985484" mass="0.143310943627726" fullinertia="6.98168229201036E-05 5.48675476764208E-05 4.4020607930097E-05 2.70503363331007E-07 -3.17975733412514E-08 1.01362000675163E-12" />
                          <joint name="arm_left_L7_Joint" type="hinge" axis="-1 0 0" range="-1.59 1.59" damping="20" frictionloss="0.0" armature="0.01" />
                          <geom class="arm_left_arm_lkls73_arm_visual" mesh="arm_left_L7" />
                          <geom class="arm_left_arm_lkls73_arm_collision" mesh="arm_left_L7" />
                          <body name="arm_left_L8_Link" pos="2.5732E-05 0 -0.0455">
                            <inertial pos="1.08546552465473E-10 -1.13853898531247E-09 0.000500000000024592" mass="6.05149284897746E-05" fullinertia="8.49604381443617E-09 8.49604381442905E-09 1.69820018074357E-08 8.31968496153617E-22 -7.81277944440306E-15 -9.03653480952828E-16" />
                            <geom class="arm_left_arm_lkls73_arm_visual" mesh="arm_left_L8" />
                            <geom class="arm_left_arm_lkls73_arm_collision" mesh="arm_left_L8" />
                            <site name="arm_left_tool0" pos="0 0 0" />
                            <body name="hand_left_lh_hand_base_link" pos="0 0 0" euler="3.1416 0 -1.5708">
                              <inertial pos="-0.000986417037198788 0.000268049028294054 0.0773798470852122" mass="0.110373495507463" fullinertia="0.000264402778830212 0.000159680177760236 0.000118075546031988 4.59263483005334e-07 1.32798258678817e-06 -4.78660406501498e-06" />
                              <geom class="hand_left_hand_linkerhand_l25_visual" mesh="hand_left_hand_base_link" />
                              <geom class="hand_left_hand_linkerhand_l25_collision" mesh="hand_left_hand_base_link" />
                              <site name="hand_left_wrist_mount" pos="0 0 0" />
                              <body name="hand_left_lh_thumb_metacarpals_base1" pos="0.01916 -0.01 0.0436">
                                <inertial pos="0.0115155126192006 0.00398068846976699 0.000272888250745694" mass="0.0160351802817401" fullinertia="4.043875385429e-06 2.42762975209742e-06 2.08582778122043e-06 1.31113365770736e-07 -7.54220071752833e-09 -1.4815076502312e-07" />
                                <joint name="hand_left_lh_thumb_cmc_roll" class="hand_left_hand_linkerhand_l25_joint" type="hinge" axis="-1 0 0" range="0 1.309" />
                                <geom class="hand_left_hand_linkerhand_l25_visual" mesh="hand_left_thumb_metacarpals_base1" />
                                <geom class="hand_left_hand_linkerhand_l25_collision" mesh="hand_left_thumb_metacarpals_base1" />
                                <body name="hand_left_lh_thumb_metacarpals_base2" pos="0.019845 0 0" euler="0.77165 0 0">
                                  <inertial pos="0.00286714610220221 -0.0061572653424441 0.00472605265322379" mass="0.00183264554882498" fullinertia="2.1115156606816047e-07 9.889251334189997e-08 1.8061586053999446e-07 -4.9133152227129e-08 -1.35746007921721e-08 4.75450167610941e-08" />
                                  <joint name="hand_left_lh_thumb_cmc_yaw" class="hand_left_hand_linkerhand_l25_joint" type="hinge" axis="0 0 1" range="0 1.5882" />
                                  <geom class="hand_left_hand_linkerhand_l25_visual" mesh="hand_left_thumb_metacarpals_base2" />
                                  <geom class="hand_left_hand_linkerhand_l25_collision" mesh="hand_left_thumb_metacarpals_base2" />
                                  <body name="hand_left_lh_thumb_metacarpals" pos="0.0088218 -0.024245 0.0005" euler="0 -0.91 1.9199">
                                    <inertial pos="0.00670657874489922 8.60758971228653e-05 0.0331412930049483" mass="0.0287160359417969" fullinertia="1.13355944686632e-05 1.3528651001113e-05 3.37809997040935e-06 -1.18725063259997e-08 5.09011416528365e-08 2.41236037965108e-08" />
                                    <joint name="hand_left_lh_thumb_cmc_pitch" class="hand_left_hand_linkerhand_l25_joint" type="hinge" axis="0 1 0" range="0 0.7854" />
                                    <geom class="hand_left_hand_linkerhand_l25_visual" mesh="hand_left_thumb_metacarpals" />
                                    <geom class="hand_left_hand_linkerhand_l25_collision" mesh="hand_left_thumb_metacarpals" />
                                    <body name="hand_left_lh_thumb_proximal" pos="0.0127018248047608 0 0.0627256157349894">
                                      <inertial pos="-0.00268734410969529 0.000568244522388137 0.0118501723044777" mass="0.00549015507433734" fullinertia="4.78372237673962e-07 6.23208954846975e-07 2.34934736039565e-07 4.56375652569348e-11 5.41461160604729e-08 5.1129105291147e-09" />
                                      <joint name="hand_left_lh_thumb_mcp" class="hand_left_hand_linkerhand_l25_joint" type="hinge" axis="0 1 0" range="0 1.2217" />
                                      <geom class="hand_left_hand_linkerhand_l25_visual" mesh="hand_left_thumb_proximal" />
                                      <geom class="hand_left_hand_linkerhand_l25_collision" mesh="hand_left_thumb_proximal" />
                                      <body name="hand_left_lh_thumb_distal" pos="-0.00483652209209624 0 0.0342226492098615">
                                        <inertial pos="-0.000710021799050622 -0.00267575921172081 0.0124762660846746" mass="0.00382046638843239" fullinertia="2.12120816159448e-07 2.67878295781821e-07 1.24571609570411e-07 -2.9588372102787e-09 -7.35950751454791e-08 6.04616706384983e-09" />
                                        <joint name="hand_left_lh_thumb_dip" class="hand_left_hand_linkerhand_l25_joint" type="hinge" axis="0 1 0" range="0 1.2392" />
                                        <geom class="hand_left_hand_linkerhand_l25_visual" mesh="hand_left_thumb_distal" />
                                        <geom class="hand_left_hand_linkerhand_l25_collision" mesh="hand_left_thumb_distal" />
                                      </body>
                                    </body>
                                  </body>
                                </body>
                              </body>
                              <body name="hand_left_lh_index_metacarpals" pos="0.0038 -0.03525 0.1481">
                                <inertial pos="-0.00794299653637993 -2.93673969475883e-07 0.00220106027330236" mass="0.000895516429792169" fullinertia="3.46279728013563e-08 2.85435471088518e-08 4.38102133125935e-08 -3.91962517308058e-13 5.91029152662012e-09 -5.30377507775974e-13" />
                                <joint name="hand_left_lh_index_mcp_roll" class="hand_left_hand_linkerhand_l25_joint" type="hinge" axis="-1 0 0" range="-0.2269 0.2269" />
                                <geom class="hand_left_hand_linkerhand_l25_visual" mesh="hand_left_index_metacarpals" />
                                <geom class="hand_left_hand_linkerhand_l25_collision" mesh="hand_left_index_metacarpals" />
                                <body name="hand_left_lh_index_proximal" pos="-0.0021302 0 0">
                                  <inertial pos="-0.00114185484694667 3.47315751996757e-05 0.0228928405204552" mass="0.00450921353606138" fullinertia="6.66673080974796e-07 6.74195867168963e-07 1.3575909170439e-07 -1.07185172336921e-11 -2.53143396223457e-08 -1.59054321114837e-10" />
                                  <joint name="hand_left_lh_index_mcp_pitch" class="hand_left_hand_linkerhand_l25_joint" type="hinge" axis="0 1 0" range="0 1.2217" />
                                  <geom class="hand_left_hand_linkerhand_l25_visual" mesh="hand_left_index_proximal" />
                                  <geom class="hand_left_hand_linkerhand_l25_collision" mesh="hand_left_index_proximal" />
                                  <body name="hand_left_lh_index_middle" pos="-0.0041946 0 0.044819">
                                    <inertial pos="-0.000206991936024691 2.60617060293677e-06 0.0167065328961797" mass="0.00237827499847615" fullinertia="2.2953872847051e-07 1.76761332719485e-07 9.62798051827835e-08 2.23609392315326e-12 -1.4734008024399e-08 1.15917246584962e-11" />
                                    <joint name="hand_left_lh_index_pip" class="hand_left_hand_linkerhand_l25_joint" type="hinge" axis="0 1 0" range="0 1.7279" />
                                    <geom class="hand_left_hand_linkerhand_l25_visual" mesh="hand_left_index_middle" />
                                    <geom class="hand_left_hand_linkerhand_l25_collision" mesh="hand_left_index_middle" />
                                    <body name="hand_left_lh_index_distal" pos="0.0028245 0 0.031696">
                                      <inertial pos="-0.00816246517948334 2.27058913663258e-05 0.00811806505013066" mass="0.00334170259772608" fullinertia="1.59570744991572e-07 1.78095631426193e-07 1.34141383450165e-07 1.51458653099843e-10 -5.9429168549018e-08 -1.24842727205631e-10" />
                                      <joint name="hand_left_lh_index_dip" class="hand_left_hand_linkerhand_l25_joint" type="hinge" axis="0 1 0" range="0 1.3614" />
                                      <geom class="hand_left_hand_linkerhand_l25_visual" mesh="hand_left_index_distal" />
                                      <geom class="hand_left_hand_linkerhand_l25_collision" mesh="hand_left_index_distal" />
                                    </body>
                                  </body>
                                </body>
                              </body>
                              <body name="hand_left_lh_middle_metacarpals" pos="0.00379999999265848 -0.0117500000029305 0.1526">
                                <inertial pos="-0.00794299618184406 -2.93006659768391e-07 0.00220106329585604" mass="0.000895516947435045" fullinertia="3.46279958583857e-08 2.85435605322585e-08 4.38102218629515e-08 -3.91785866285381e-13 5.91029262290692e-09 -5.27457529869591e-13" />
                                <joint name="hand_left_lh_middle_mcp_roll" class="hand_left_hand_linkerhand_l25_joint" type="hinge" axis="-1 0 0" range="-0.23 0.23" />
                                <geom class="hand_left_hand_linkerhand_l25_visual" mesh="hand_left_middle_metacarpals" />
                                <geom class="hand_left_hand_linkerhand_l25_collision" mesh="hand_left_middle_metacarpals" />
                                <body name="hand_left_lh_middle_proximal" pos="-0.0021302 0 0">
                                  <inertial pos="-0.00114185484818909 3.47315748623067e-05 0.0228928405191574" mass="0.00450921353536659" fullinertia="6.6667308094129e-07 6.74195867139795e-07 1.3575909169764e-07 -1.07185191777588e-11 -2.53143396278864e-08 -1.59054330697635e-10" />
                                  <joint name="hand_left_lh_middle_mcp_pitch" class="hand_left_hand_linkerhand_l25_joint" type="hinge" axis="0 1 0" range="0 1.2217" />
                                  <geom class="hand_left_hand_linkerhand_l25_visual" mesh="hand_left_middle_proximal" />
                                  <geom class="hand_left_hand_linkerhand_l25_collision" mesh="hand_left_middle_proximal" />
                                  <body name="hand_left_lh_middle_middle" pos="-0.00419457745591796 0 0.0448194332262389">
                                    <inertial pos="-0.000206991893084203 2.60624978909441e-06 0.0167065331356697" mass="0.00237827502274046" fullinertia="2.29538732170979e-07 1.7676133625496e-07 9.62798057458164e-08 2.23722006830829e-12 -1.47340061868536e-08 1.15938574397121e-11" />
                                    <joint name="hand_left_lh_middle_pip" class="hand_left_hand_linkerhand_l25_joint" type="hinge" axis="0 1 0" range="0 1.7279" />
                                    <geom class="hand_left_hand_linkerhand_l25_visual" mesh="hand_left_middle_middle" />
                                    <geom class="hand_left_hand_linkerhand_l25_collision" mesh="hand_left_middle_middle" />
                                    <body name="hand_left_lh_middle_distal" pos="0.0028245 0 0.031696">
                                      <inertial pos="-0.00816246584707385 2.27058557035753e-05 0.00811806604834034" mass="0.00334170288968694" fullinertia="1.59570753478215e-07 1.78095663702073e-07 1.34141410190336e-07 1.51460233550071e-10 -5.94291827952622e-08 -1.24843061161549e-10" />
                                      <joint name="hand_left_lh_middle_dip" class="hand_left_hand_linkerhand_l25_joint" type="hinge" axis="0 1 0" range="0 1.3614" />
                                      <geom class="hand_left_hand_linkerhand_l25_visual" mesh="hand_left_middle_distal" />
                                      <geom class="hand_left_hand_linkerhand_l25_collision" mesh="hand_left_middle_distal" />
                                    </body>
                                  </body>
                                </body>
                              </body>
                              <body name="hand_left_lh_ring_metacarpals" pos="0.00379999999632174 0.0117499999970695 0.1481">
                                <inertial pos="-0.00794299637971868 -2.94513098575422e-07 0.00220106138372037" mass="0.000895516612684195" fullinertia="3.46279813761428e-08 2.854355219638e-08 4.38102164225122e-08 -3.92590701616938e-13 5.91029201975386e-09 -5.34642787239736e-13" />
                                <joint name="hand_left_lh_ring_mcp_roll" class="hand_left_hand_linkerhand_l25_joint" type="hinge" axis="-1 0 0" range="-0.23 0.23" />
                                <geom class="hand_left_hand_linkerhand_l25_visual" mesh="hand_left_ring_metacarpals" />
                                <geom class="hand_left_hand_linkerhand_l25_collision" mesh="hand_left_ring_metacarpals" />
                                <body name="hand_left_lh_ring_proximal" pos="-0.0021302 0 0">
                                  <inertial pos="-0.00114185484356009 3.47315809493265e-05 0.0228928405060199" mass="0.00450921353946778" fullinertia="6.66673081759646e-07 6.74195868060947e-07 1.3575909184966e-07 -1.07184694208142e-11 -2.53143399406658e-08 -1.59054446512071e-10" />
                                  <joint name="hand_left_lh_ring_mcp_pitch" class="hand_left_hand_linkerhand_l25_joint" type="hinge" axis="0 1 0" range="0 1.2217" />
                                  <geom class="hand_left_hand_linkerhand_l25_visual" mesh="hand_left_ring_proximal" />
                                  <geom class="hand_left_hand_linkerhand_l25_collision" mesh="hand_left_ring_proximal" />
                                  <body name="hand_left_lh_ring_middle" pos="-0.00419457745591796 0 0.0448194332262389">
                                    <inertial pos="-0.00020699321531438 2.60746916563859e-06 0.0167065326651803" mass="0.00237827433282015" fullinertia="2.29538714144179e-07 1.76761312824203e-07 9.62797743780677e-08 2.25259718797087e-12 -1.47340121880382e-08 1.15994674932479e-11" />
                                    <joint name="hand_left_lh_ring_pip" class="hand_left_hand_linkerhand_l25_joint" type="hinge" axis="0 1 0" range="0 1.7279" />
                                    <geom class="hand_left_hand_linkerhand_l25_visual" mesh="hand_left_ring_middle" />
                                    <geom class="hand_left_hand_linkerhand_l25_collision" mesh="hand_left_ring_middle" />
                                    <body name="hand_left_lh_ring_distal" pos="0.0028245 0 0.031696">
                                      <inertial pos="-0.0081624655153107 2.27057324615476e-05 0.00811806561376854" mass="0.00334170280386792" fullinertia="1.59570757957895e-07 1.78095650648522e-07 1.34141394018405e-07 1.51461030930522e-10 -5.94291750853635e-08 -1.2484716714453e-10" />
                                      <joint name="hand_left_lh_ring_dip" class="hand_left_hand_linkerhand_l25_joint" type="hinge" axis="0 1 0" range="0 1.3614" />
                                      <geom class="hand_left_hand_linkerhand_l25_visual" mesh="hand_left_ring_distal" />
                                      <geom class="hand_left_hand_linkerhand_l25_collision" mesh="hand_left_ring_distal" />
                                    </body>
                                  </body>
                                </body>
                              </body>
                              <body name="hand_left_lh_pinky_metacarpals" pos="0.00379999999998499 0.0352499999970695 0.1436">
                                <inertial pos="-0.00794299617469867 -2.9300686296696e-07 0.00220106329602079" mass="0.000895516947513541" fullinertia="3.46279958591138e-08 2.85435605328821e-08 4.38102218637476e-08 -3.91785473098584e-13 5.91029262259818e-09 -5.27457876763101e-13" />
                                <joint name="hand_left_lh_pinky_mcp_roll" class="hand_left_hand_linkerhand_l25_joint" type="hinge" axis="-1 0 0" range="-0.23 0.23" />
                                <geom class="hand_left_hand_linkerhand_l25_visual" mesh="hand_left_pinky_metacarpals" />
                                <geom class="hand_left_hand_linkerhand_l25_collision" mesh="hand_left_pinky_metacarpals" />
                                <body name="hand_left_lh_pinky_proximal" pos="-0.0021302 0 0">
                                  <inertial pos="-0.00114185484350746 3.47315809787474e-05 0.0228928405060759" mass="0.00450921353949741" fullinertia="6.66673081761478e-07 6.74195868062215e-07 1.35759091850319e-07 -1.07184692555283e-11 -2.53143399404374e-08 -1.59054445649156e-10" />
                                  <joint name="hand_left_lh_pinky_mcp_pitch" class="hand_left_hand_linkerhand_l25_joint" type="hinge" axis="0 1 0" range="0 1.2217" />
                                  <geom class="hand_left_hand_linkerhand_l25_visual" mesh="hand_left_pinky_proximal" />
                                  <geom class="hand_left_hand_linkerhand_l25_collision" mesh="hand_left_pinky_proximal" />
                                  <body name="hand_left_lh_pinky_middle" pos="-0.0041946 0 0.044819">
                                    <inertial pos="-0.000206993248553502 2.60748984004522e-06 0.0167065326828462" mass="0.00237827431921004" fullinertia="2.29538713829186e-07 1.76761312133621e-07 9.62797736254209e-08 2.25292379523651e-12 -1.47340119230773e-08 1.15993142153177e-11" />
                                    <joint name="hand_left_lh_pinky_pip" class="hand_left_hand_linkerhand_l25_joint" type="hinge" axis="0 1 0" range="0 1.7279" />
                                    <geom class="hand_left_hand_linkerhand_l25_visual" mesh="hand_left_pinky_middle" />
                                    <geom class="hand_left_hand_linkerhand_l25_collision" mesh="hand_left_pinky_middle" />
                                    <body name="hand_left_lh_pinky_distal" pos="0.0028245 0 0.031696">
                                      <inertial pos="-0.00816246615274486 2.27054189396725e-05 0.00811806634481432" mass="0.00334170283969146" fullinertia="1.59570758932551e-07 1.7809566305509e-07 1.34141398854287e-07 1.51458416419677e-10 -5.94291815262966e-08 -1.24846982879422e-10" />
                                      <joint name="hand_left_lh_pinky_dip" class="hand_left_hand_linkerhand_l25_joint" type="hinge" axis="0 1 0" range="0 1.3614" />
                                      <geom class="hand_left_hand_linkerhand_l25_visual" mesh="hand_left_pinky_distal" />
                                      <geom class="hand_left_hand_linkerhand_l25_collision" mesh="hand_left_pinky_distal" />
                                    </body>
                                  </body>
                                </body>
                              </body>
                            </body>
                          </body>
                        </body>
                      </body>
                    </body>
                  </body>
                </body>
              </body>
            </body>
          </body>
        </body>
        <body name="base_arm_right_mount" pos="3.32E-05 -0.164 0">
          <site name="base_arm_right_mount" pos="0 0 0" />
          <body name="arm_right_R_arm_root" pos="0 0 0">
            <site name="arm_right_base_mount" pos="0 0 0" />
            <body name="arm_right_R1_Link" pos="0 0 0">
              <inertial pos="-0.00238919607727967 -0.0538157456440336 0.00010452196048521" mass="1.39972022686362" fullinertia="0.00114445390268402 0.000654874566780468 0.000691494652521253 -2.33503672059843E-06 9.94413679130844E-09 -1.0590763545097E-06" />
              <joint name="arm_right_R1_Joint" type="hinge" axis="0 1 0" range="-2.91 2.91" damping="20" frictionloss="0.0" armature="0.01" />
              <geom class="arm_right_arm_lkls73_arm_visual" mesh="arm_right_R1" />
              <geom class="arm_right_arm_lkls73_arm_collision" mesh="arm_right_R1" />
              <body name="arm_right_R2_Link" pos="-3.32E-05 -0.058001 0">
                <inertial pos="-0.00161840435618426 -8.19852199768212E-06 -0.0795740266968583" mass="1.14210467744301" fullinertia="0.00099926032712546 0.000929597930299551 0.000490873969400915 4.38390428673455E-06 1.34112399215467E-06 -2.7915125849712E-07" />
                <joint name="arm_right_R2_Joint" type="hinge" axis="-1 0 0" range="-0.07 3.2" damping="20" frictionloss="0.0" armature="0.01" />
                <geom class="arm_right_arm_lkls73_arm_visual" mesh="arm_right_R2" />
                <geom class="arm_right_arm_lkls73_arm_collision" mesh="arm_right_R2" />
                <body name="arm_right_R3_Link" pos="2.5018E-05 0 -0.123">
                  <inertial pos="-0.000181281046893987 -0.00124930020984915 -0.128548942421424" mass="1.27984352653686" fullinertia="0.00158095142360156 0.00163152744277086 0.000344148863355523 7.74064683830126E-07 8.68119825601561E-07 2.41539423740222E-06" />
                  <joint name="arm_right_R3_Joint" type="hinge" axis="0 0 1" range="-2.69 2.69" damping="20" frictionloss="0.0" armature="0.01" />
                  <geom class="arm_right_arm_lkls73_arm_visual" mesh="arm_right_R3" />
                  <geom class="arm_right_arm_lkls73_arm_collision" mesh="arm_right_R3" />
                  <body name="arm_right_R4_Link" pos="-2.5308E-05 0 -0.1621">
                    <inertial pos="4.42383386005531E-06 -0.000778418113624724 -0.0846001182728231" mass="0.935504488206621" fullinertia="0.00050824600575807 0.000524130564978714 0.000333983373234424 -4.12349458829714E-06 1.60122816329668E-07 3.4575721962879E-07" />
                    <joint name="arm_right_R4_Joint" type="hinge" axis="0 1 0" range="-2.05 2.05" damping="20" frictionloss="0.0" armature="0.01" />
                    <geom class="arm_right_arm_lkls73_arm_visual" mesh="arm_right_R4" />
                    <geom class="arm_right_arm_lkls73_arm_collision" mesh="arm_right_R4" />
                    <body name="arm_right_R5_Link" pos="0 0 -0.124">
                      <inertial pos="7.89161129038714E-05 -0.00127720103461224 -0.0361226257678754" mass="0.298013716041534" fullinertia="0.000356325710016729 0.000385006832605378 0.000101746689163179 8.49345579615723E-07 1.06208408022809E-06 -2.16308499009301E-06" />
                      <joint name="arm_right_R5_Joint" type="hinge" axis="0 0 1" range="-2.69 2.69" damping="20" frictionloss="0.0" armature="0.01" />
                      <geom class="arm_right_arm_lkls73_arm_visual" mesh="arm_right_R5" />
                      <geom class="arm_right_arm_lkls73_arm_collision" mesh="arm_right_R5" />
                      <body name="arm_right_R6_Link" pos="0 0 -0.0881">
                        <inertial pos="-0.00423362800835291 0.00438647668797748 -0.0324823687491156" mass="0.344326135276304" fullinertia="0.000194396918256628 0.000233882313857475 0.00010145861997438 1.34060453386023E-06 -9.47065531650411E-06 -2.86903332334497E-07" />
                        <joint name="arm_right_R6_Joint" type="hinge" axis="0 1 0" range="-1.59 1.59" damping="20" frictionloss="0.0" armature="0.01" />
                        <geom class="arm_right_arm_lkls73_arm_visual" mesh="arm_right_R6" />
                        <geom class="arm_right_arm_lkls73_arm_collision" mesh="arm_right_R6" />
                        <body name="arm_right_R7_Link" pos="2.5631E-05 0 -0.0655">
                          <inertial pos="0.00330667550394679 -1.18809317478652E-06 -0.0202430179967651" mass="0.143310943627727" fullinertia="6.98168229201036E-05 5.48675476764227E-05 4.4020607930099E-05 2.70503363330993E-07 3.17975733407385E-08 -1.01361997649667E-12" />
                          <joint name="arm_right_R7_Joint" type="hinge" axis="-1 0 0" range="-1.59 1.59" damping="20" frictionloss="0.0" armature="0.01" />
                          <geom class="arm_right_arm_lkls73_arm_visual" mesh="arm_right_R7" />
                          <geom class="arm_right_arm_lkls73_arm_collision" mesh="arm_right_R7" />
                          <body name="arm_right_R8_Link" pos="-2.5732E-05 0 -0.0455">
                            <inertial pos="-1.03808180585258E-10 5.33808552916071E-11 0.000499999999999834" mass="6.05149284897743E-05" fullinertia="8.49604381443613E-09 8.49604381442903E-09 1.69820018074356E-08 8.31967629121856E-22 7.81277954468574E-15 9.03653481925555E-16" />
                            <geom class="arm_right_arm_lkls73_arm_visual" mesh="arm_right_R8" />
                            <geom class="arm_right_arm_lkls73_arm_collision" mesh="arm_right_R8" />
                            <site name="arm_right_tool0" pos="0 0 0" />
                            <body name="hand_right_rh_hand_base_link" pos="0 0 0" euler="3.1416 0 1.5708">
                              <inertial pos="-0.0023553326597099 -0.000476950676809626 0.0840274681191193" mass="0.130043890829375" fullinertia="0.000269869493590648 0.000164906210534713 0.000118834524369526 -5.66836728555976e-07 1.0791938448155e-06 4.94586055862009e-06" />
                              <geom class="hand_right_hand_linkerhand_l25_visual" mesh="hand_right_hand_base_link" />
                              <geom class="hand_right_hand_linkerhand_l25_collision" mesh="hand_right_hand_base_link" />
                              <site name="hand_right_wrist_mount" pos="0 0 0" />
                              <body name="hand_right_rh_thumb_metacarpals_base1" pos="0.01916 0.01 0.0436">
                                <inertial pos="0.0121300685642492 -0.00368626401900367 0.000253013805235423" mass="0.0173128324517923" fullinertia="4.04974890264239e-06 2.43513754798381e-06 2.09347392894973e-06 -1.31074266242452e-07 -7.53905165403527e-09 1.46366596393199e-07" />
                                <joint name="hand_right_rh_thumb_cmc_roll" class="hand_right_hand_linkerhand_l25_joint" type="hinge" axis="1 0 0" range="0 1.309" />
                                <geom class="hand_right_hand_linkerhand_l25_visual" mesh="hand_right_thumb_metacarpals_base1" />
                                <geom class="hand_right_hand_linkerhand_l25_collision" mesh="hand_right_thumb_metacarpals_base1" />
                                <body name="hand_right_rh_thumb_metacarpals_base2" pos="0.019845 0 0" euler="-0.77165 0 0">
                                  <inertial pos="0.00274804892423072 0.00768600825377847 0.00362008971119372" mass="0.0129293097380942" fullinertia="1.760752912378147e-06 7.758748827283011e-07 1.450608374471467e-06 3.5029507180292e-07 -1.32342776895603e-07 -3.69293599975358e-07" />
                                  <joint name="hand_right_rh_thumb_cmc_yaw" class="hand_right_hand_linkerhand_l25_joint" type="hinge" axis="0 0 -1" range="0 1.5882" />
                                  <geom class="hand_right_hand_linkerhand_l25_visual" mesh="hand_right_thumb_metacarpals_base2" />
                                  <geom class="hand_right_hand_linkerhand_l25_collision" mesh="hand_right_thumb_metacarpals_base2" />
                                  <body name="hand_right_rh_thumb_metacarpals" pos="0.0088264 0.024243 0.0005" euler="0 -0.91 -1.9199">
                                    <inertial pos="0.00680467489235993 -0.000348945978923473 0.0329029974283304" mass="0.0311449727019751" fullinertia="1.14965619264847e-05 1.37913772817647e-05 3.56917509196916e-06 -1.14093661337383e-08 5.08562599330683e-08 2.39355105126118e-08" />
                                    <joint name="hand_right_rh_thumb_cmc_pitch" class="hand_right_hand_linkerhand_l25_joint" type="hinge" axis="0 1 0" range="0 0.7854" />
                                    <geom class="hand_right_hand_linkerhand_l25_visual" mesh="hand_right_thumb_metacarpals" />
                                    <geom class="hand_right_hand_linkerhand_l25_collision" mesh="hand_right_thumb_metacarpals" />
                                    <body name="hand_right_rh_thumb_proximal" pos="0.012702 0 0.062726">
                                      <inertial pos="-0.00268743345276515 0.000568290980153867 0.0118503606835096" mass="0.00549015851204037" fullinertia="4.78349857032437e-07 6.23171205283375e-07 2.34919130274949e-07 4.61712014179472e-11 5.4113877466635e-08 5.11556682719536e-09" />
                                      <joint name="hand_right_rh_thumb_mcp" class="hand_right_hand_linkerhand_l25_joint" type="hinge" axis="0 1 0" range="0 1.2217" />
                                      <geom class="hand_right_hand_linkerhand_l25_visual" mesh="hand_right_thumb_proximal" />
                                      <geom class="hand_right_hand_linkerhand_l25_collision" mesh="hand_right_thumb_proximal" />
                                      <body name="hand_right_rh_thumb_distal" pos="-0.0048365 0 0.034223">
                                        <inertial pos="-0.000650482106033023 2.41300573138245e-05 0.0111942838051236" mass="0.00585464206993151" fullinertia="3.37157269656711e-07 4.37703462647265e-07 1.85639673847353e-07 3.69307135027908e-10 -1.12308316041907e-07 -9.3624675389561e-10" />
                                        <joint name="hand_right_rh_thumb_dip" class="hand_right_hand_linkerhand_l25_joint" type="hinge" axis="0 1 0" range="0 1.2392" />
                                        <geom class="hand_right_hand_linkerhand_l25_visual" mesh="hand_right_thumb_distal" />
                                        <geom class="hand_right_hand_linkerhand_l25_collision" mesh="hand_right_thumb_distal" />
                                      </body>
                                    </body>
                                  </body>
                                </body>
                              </body>
                              <body name="hand_right_rh_index_metacarpals" pos="0.0038 0.03525 0.1481">
                                <inertial pos="-0.00794297216778595 3.01910607593964e-07 0.00220112291424343" mass="0.000895533942236676" fullinertia="3.46286808249453e-08 2.85439868980493e-08 4.38105935701441e-08 5.20721113539202e-13 5.91055676999344e-09 6.15915602928681e-13" />
                                <joint name="hand_right_rh_index_mcp_roll" class="hand_right_hand_linkerhand_l25_joint" type="hinge" axis="-1 0 0" range="-0.2269 0.2269" />
                                <geom class="hand_right_hand_linkerhand_l25_visual" mesh="hand_right_index_metacarpals" />
                                <geom class="hand_right_hand_linkerhand_l25_collision" mesh="hand_right_index_metacarpals" />
                                <body name="hand_right_rh_index_proximal" pos="-0.0021302 0 0">
                                  <inertial pos="-0.00114165889805229 -3.47779025311364e-05 0.0228930740987338" mass="0.00450935628154297" fullinertia="6.66693338335738e-07 6.74214594716538e-07 1.3576088799113e-07 1.00781853152623e-11 -2.53156876802064e-08 1.59197443844205e-10" />
                                  <joint name="hand_right_rh_index_mcp_pitch" class="hand_right_hand_linkerhand_l25_joint" type="hinge" axis="0 1 0" range="0 1.2217" />
                                  <geom class="hand_right_hand_linkerhand_l25_visual" mesh="hand_right_index_proximal" />
                                  <geom class="hand_right_hand_linkerhand_l25_collision" mesh="hand_right_index_proximal" />
                                  <body name="hand_right_rh_index_middle" pos="-0.0041946 0 0.044819">
                                    <inertial pos="-0.000206830314670474 -2.69762827288106e-06 0.0167055565294545" mass="0.00237861824163327" fullinertia="2.29584431475404e-07 1.76802239049368e-07 9.62875380319572e-08 -3.79527882007371e-12 -1.47269516053005e-08 3.59871792473524e-13" />
                                    <joint name="hand_right_rh_index_pip" class="hand_right_hand_linkerhand_l25_joint" type="hinge" axis="0 1 0" range="0 1.7279" />
                                    <geom class="hand_right_hand_linkerhand_l25_visual" mesh="hand_right_index_middle" />
                                    <geom class="hand_right_hand_linkerhand_l25_collision" mesh="hand_right_index_middle" />
                                    <body name="hand_right_rh_index_distal" pos="0.0028245 0 0.031696">
                                      <inertial pos="-0.00816260402461631 -2.26721604493323e-05 0.00811819722869647" mass="0.00334176238570705" fullinertia="1.59568900399119e-07 1.78096631602274e-07 1.34139906914153e-07 -1.52271643281661e-10 -5.94266141046017e-08 1.23981970768957e-10" />
                                      <joint name="hand_right_rh_index_dip" class="hand_right_hand_linkerhand_l25_joint" type="hinge" axis="0 1 0" range="0 1.3614" />
                                      <geom class="hand_right_hand_linkerhand_l25_visual" mesh="hand_right_index_distal" />
                                      <geom class="hand_right_hand_linkerhand_l25_collision" mesh="hand_right_index_distal" />
                                    </body>
                                  </body>
                                </body>
                              </body>
                              <body name="hand_right_rh_middle_metacarpals" pos="0.0038 0.01175 0.1526">
                                <inertial pos="-0.00794297217144934 3.01910607571412e-07 0.00220112291424346" mass="0.000895533942236672" fullinertia="3.46286808249452e-08 2.85439868980493e-08 4.3810593570144e-08 5.20721113361698e-13 5.91055676999347e-09 6.15915602825396e-13" />
                                <joint name="hand_right_rh_middle_mcp_roll" class="hand_right_hand_linkerhand_l25_joint" type="hinge" axis="-1 0 0" range="-0.23 0.23" />
                                <geom class="hand_right_hand_linkerhand_l25_visual" mesh="hand_right_middle_metacarpals" />
                                <geom class="hand_right_hand_linkerhand_l25_collision" mesh="hand_right_middle_metacarpals" />
                                <body name="hand_right_rh_middle_proximal" pos="-0.0021302 0 0">
                                  <inertial pos="-0.00114165889805231 -3.47779025311071e-05 0.0228930740987338" mass="0.00450935628154299" fullinertia="6.66693338335741e-07 6.74214594716535e-07 1.35760887991121e-07 1.00781853158879e-11 -2.53156876802067e-08 1.59197443844791e-10" />
                                  <joint name="hand_right_rh_middle_mcp_pitch" class="hand_right_hand_linkerhand_l25_joint" type="hinge" axis="0 1 0" range="0 1.2217" />
                                  <geom class="hand_right_hand_linkerhand_l25_visual" mesh="hand_right_middle_proximal" />
                                  <geom class="hand_right_hand_linkerhand_l25_collision" mesh="hand_right_middle_proximal" />
                                  <body name="hand_right_rh_middle_middle" pos="-0.0041946 0 0.044819">
                                    <inertial pos="-0.000206830311076763 -2.69763200638285e-06 0.0167055565392871" mass="0.00237861824399121" fullinertia="2.2958443176697e-07 1.76802239346606e-07 9.62875381090068e-08 -3.79531728857531e-12 -1.47269515025648e-08 3.59776198217398e-13" />
                                    <joint name="hand_right_rh_middle_pip" class="hand_right_hand_linkerhand_l25_joint" type="hinge" axis="0 1 0" range="0 1.7279" />
                                    <geom class="hand_right_hand_linkerhand_l25_visual" mesh="hand_right_middle_middle" />
                                    <geom class="hand_right_hand_linkerhand_l25_collision" mesh="hand_right_middle_middle" />
                                    <body name="hand_right_rh_middle_distal" pos="0.0028245 0 0.031696">
                                      <inertial pos="-0.00816260402458386 -2.26721612610642e-05 0.00811819722943347" mass="0.0033417623857295" fullinertia="1.59568900407287e-07 1.78096631550001e-07 1.34139906932954e-07 -1.52271672185911e-10 -5.94266141070478e-08 1.23981962913402e-10" />
                                      <joint name="hand_right_rh_middle_dip" class="hand_right_hand_linkerhand_l25_joint" type="hinge" axis="0 1 0" range="0 1.3614" />
                                      <geom class="hand_right_hand_linkerhand_l25_visual" mesh="hand_right_middle_distal" />
                                      <geom class="hand_right_hand_linkerhand_l25_collision" mesh="hand_right_middle_distal" />
                                    </body>
                                  </body>
                                </body>
                              </body>
                              <body name="hand_right_rh_ring_metacarpals" pos="0.0038 -0.01175 0.1481">
                                <inertial pos="-0.00794297217511273 3.01910607531514e-07 0.00220112291424343" mass="0.00089553394223667" fullinertia="3.4628680824945e-08 2.8543986898049e-08 4.38105935701438e-08 5.2072111337213e-13 5.91055676999336e-09 6.15915602738524e-13" />
                                <joint name="hand_right_rh_ring_mcp_roll" class="hand_right_hand_linkerhand_l25_joint" type="hinge" axis="-1 0 0" range="-0.23 0.23" />
                                <geom class="hand_right_hand_linkerhand_l25_visual" mesh="hand_right_ring_metacarpals" />
                                <geom class="hand_right_hand_linkerhand_l25_collision" mesh="hand_right_ring_metacarpals" />
                                <body name="hand_right_rh_ring_proximal" pos="-0.0021302 0 0">
                                  <inertial pos="-0.00114165889805229 -3.47779025311641e-05 0.0228930740987337" mass="0.00450935628154299" fullinertia="6.66693338335738e-07 6.74214594716548e-07 1.3576088799114e-07 1.00781853170701e-11 -2.53156876802064e-08 1.59197443843837e-10" />
                                  <joint name="hand_right_rh_ring_mcp_pitch" class="hand_right_hand_linkerhand_l25_joint" type="hinge" axis="0 1 0" range="0 1.2217" />
                                  <geom class="hand_right_hand_linkerhand_l25_visual" mesh="hand_right_ring_proximal" />
                                  <geom class="hand_right_hand_linkerhand_l25_collision" mesh="hand_right_ring_proximal" />
                                  <body name="hand_right_rh_ring_middle" pos="-0.0041946 0 0.044819">
                                    <inertial pos="-0.000206830314670712 -2.69762827293657e-06 0.0167055565294543" mass="0.00237861824163314" fullinertia="2.29584431475388e-07 1.76802239049448e-07 9.62875380320043e-08 -3.79527881056473e-12 -1.47269516053097e-08 3.59871797815951e-13" />
                                    <joint name="hand_right_rh_ring_pip" class="hand_right_hand_linkerhand_l25_joint" type="hinge" axis="0 1 0" range="0 1.7279" />
                                    <geom class="hand_right_hand_linkerhand_l25_visual" mesh="hand_right_ring_middle" />
                                    <geom class="hand_right_hand_linkerhand_l25_collision" mesh="hand_right_ring_middle" />
                                    <body name="hand_right_rh_ring_distal" pos="0.0028245 0 0.031696">
                                      <inertial pos="-0.00816260402385198 -2.26723442381116e-05 0.00811819722787116" mass="0.00334176238553782" fullinertia="1.59568900413529e-07 1.78096631554275e-07 1.34139906897543e-07 -1.5226555011147e-10 -5.9426614092103e-08 1.23978578539056e-10" />
                                      <joint name="hand_right_rh_ring_dip" class="hand_right_hand_linkerhand_l25_joint" type="hinge" axis="0 1 0" range="0 1.3614" />
                                      <geom class="hand_right_hand_linkerhand_l25_visual" mesh="hand_right_ring_distal" />
                                      <geom class="hand_right_hand_linkerhand_l25_collision" mesh="hand_right_ring_distal" />
                                    </body>
                                  </body>
                                </body>
                              </body>
                              <body name="hand_right_rh_pinky_metacarpals" pos="0.0038 -0.03525 0.1436">
                                <inertial pos="-0.00794297217877612 3.019106075558e-07 0.00220112291424343" mass="0.000895533942236661" fullinertia="3.46286808249448e-08 2.85439868980489e-08 4.38105935701437e-08 5.20721113385638e-13 5.91055676999334e-09 6.15915602787648e-13" />
                                <joint name="hand_right_rh_pinky_mcp_roll" class="hand_right_hand_linkerhand_l25_joint" type="hinge" axis="-1 0 0" range="-0.23 0.23" />
                                <geom class="hand_right_hand_linkerhand_l25_visual" mesh="hand_right_pinky_metacarpals" />
                                <geom class="hand_right_hand_linkerhand_l25_collision" mesh="hand_right_pinky_metacarpals" />
                                <body name="hand_right_rh_pinky_proximal" pos="-0.0021302 0 0">
                                  <inertial pos="-0.00114165890216106 -3.47779084241967e-05 0.0228930741124087" mass="0.00450935627773312" fullinertia="6.6669333754323e-07 6.74214593816853e-07 1.35760887844139e-07 1.00781372651744e-11 -2.53156873668278e-08 1.59197565505674e-10" />
                                  <joint name="hand_right_rh_pinky_mcp_pitch" class="hand_right_hand_linkerhand_l25_joint" type="hinge" axis="0 1 0" range="0 1.2217" />
                                  <geom class="hand_right_hand_linkerhand_l25_visual" mesh="hand_right_pinky_proximal" />
                                  <geom class="hand_right_hand_linkerhand_l25_collision" mesh="hand_right_pinky_proximal" />
                                  <body name="hand_right_rh_pinky_middle" pos="-0.0041946 0 0.044819">
                                    <inertial pos="-0.000206830314670489 -2.69762827287412e-06 0.0167055565294545" mass="0.0023786182416333" fullinertia="2.29584431475459e-07 1.76802239049466e-07 9.62875380320415e-08 -3.79527884680841e-12 -1.47269516053079e-08 3.5987180643017e-13" />
                                    <joint name="hand_right_rh_pinky_pip" class="hand_right_hand_linkerhand_l25_joint" type="hinge" axis="0 1 0" range="0 1.7279" />
                                    <geom class="hand_right_hand_linkerhand_l25_visual" mesh="hand_right_pinky_middle" />
                                    <geom class="hand_right_hand_linkerhand_l25_collision" mesh="hand_right_pinky_middle" />
                                    <body name="hand_right_rh_pinky_distal" pos="0.0028245 0 0.031696">
                                      <inertial pos="-0.00816260391299546 -2.26722056161019e-05 0.00811819704290559" mass="0.00334176233214274" fullinertia="1.59568898336975e-07 1.78096625944569e-07 1.3413990252827e-07 -1.52270106341856e-10 -5.94266114992739e-08 1.23981107883524e-10" />
                                      <joint name="hand_right_rh_pinky_dip" class="hand_right_hand_linkerhand_l25_joint" type="hinge" axis="0 1 0" range="0 1.3614" />
                                      <geom class="hand_right_hand_linkerhand_l25_visual" mesh="hand_right_pinky_distal" />
                                      <geom class="hand_right_hand_linkerhand_l25_collision" mesh="hand_right_pinky_distal" />
                                    </body>
                                  </body>
                                </body>
                              </body>
                            </body>
                          </body>
                        </body>
                      </body>
                    </body>
                  </body>
                </body>
              </body>
            </body>
          </body>
        </body>
      </body>
    </body>
  </worldbody>
  <actuator>
    <position name="arm_left_L1_Joint_act" joint="arm_left_L1_Joint" kp="2000" kv="0" ctrlrange="-2.91 2.91" />
    <position name="arm_left_L2_Joint_act" joint="arm_left_L2_Joint" kp="2000" kv="0" ctrlrange="-3.2 0.07" />
    <position name="arm_left_L3_Joint_act" joint="arm_left_L3_Joint" kp="2000" kv="0" ctrlrange="-2.69 2.69" />
    <position name="arm_left_L4_Joint_act" joint="arm_left_L4_Joint" kp="2000" kv="0" ctrlrange="-2.05 2.05" />
    <position name="arm_left_L5_Joint_act" joint="arm_left_L5_Joint" kp="2000" kv="0" ctrlrange="-2.69 2.69" />
    <position name="arm_left_L6_Joint_act" joint="arm_left_L6_Joint" kp="2000" kv="0" ctrlrange="-1.59 1.59" />
    <position name="arm_left_L7_Joint_act" joint="arm_left_L7_Joint" kp="2000" kv="0" ctrlrange="-1.59 1.59" />
    <position name="arm_right_R1_Joint_act" joint="arm_right_R1_Joint" kp="2000" kv="0" ctrlrange="-2.91 2.91" />
    <position name="arm_right_R2_Joint_act" joint="arm_right_R2_Joint" kp="2000" kv="0" ctrlrange="-0.07 3.2" />
    <position name="arm_right_R3_Joint_act" joint="arm_right_R3_Joint" kp="2000" kv="0" ctrlrange="-2.69 2.69" />
    <position name="arm_right_R4_Joint_act" joint="arm_right_R4_Joint" kp="2000" kv="0" ctrlrange="-2.05 2.05" />
    <position name="arm_right_R5_Joint_act" joint="arm_right_R5_Joint" kp="2000" kv="0" ctrlrange="-2.69 2.69" />
    <position name="arm_right_R6_Joint_act" joint="arm_right_R6_Joint" kp="2000" kv="0" ctrlrange="-1.59 1.59" />
    <position name="arm_right_R7_Joint_act" joint="arm_right_R7_Joint" kp="2000" kv="0" ctrlrange="-1.59 1.59" />
    <position name="hand_left_lh_thumb_cmc_roll_act" joint="hand_left_lh_thumb_cmc_roll" kp="200" kv="0" ctrlrange="0 1.309" />
    <position name="hand_left_lh_thumb_cmc_yaw_act" joint="hand_left_lh_thumb_cmc_yaw" kp="200" kv="0" ctrlrange="0 1.5882" />
    <position name="hand_left_lh_thumb_cmc_pitch_act" joint="hand_left_lh_thumb_cmc_pitch" kp="200" kv="0" ctrlrange="0 0.7854" />
    <position name="hand_left_lh_thumb_mcp_act" joint="hand_left_lh_thumb_mcp" kp="200" kv="0" ctrlrange="0 1.2217" />
    <position name="hand_left_lh_index_mcp_roll_act" joint="hand_left_lh_index_mcp_roll" kp="200" kv="0" ctrlrange="-0.2269 0.2269" />
    <position name="hand_left_lh_index_mcp_pitch_act" joint="hand_left_lh_index_mcp_pitch" kp="200" kv="0" ctrlrange="0 1.2217" />
    <position name="hand_left_lh_index_pip_act" joint="hand_left_lh_index_pip" kp="200" kv="0" ctrlrange="0 1.7279" />
    <position name="hand_left_lh_middle_mcp_roll_act" joint="hand_left_lh_middle_mcp_roll" kp="200" kv="0" ctrlrange="-0.23 0.23" />
    <position name="hand_left_lh_middle_mcp_pitch_act" joint="hand_left_lh_middle_mcp_pitch" kp="200" kv="0" ctrlrange="0 1.2217" />
    <position name="hand_left_lh_middle_pip_act" joint="hand_left_lh_middle_pip" kp="200" kv="0" ctrlrange="0 1.7279" />
    <position name="hand_left_lh_ring_mcp_roll_act" joint="hand_left_lh_ring_mcp_roll" kp="200" kv="0" ctrlrange="-0.23 0.23" />
    <position name="hand_left_lh_ring_mcp_pitch_act" joint="hand_left_lh_ring_mcp_pitch" kp="200" kv="0" ctrlrange="0 1.2217" />
    <position name="hand_left_lh_ring_pip_act" joint="hand_left_lh_ring_pip" kp="200" kv="0" ctrlrange="0 1.7279" />
    <position name="hand_left_lh_pinky_mcp_roll_act" joint="hand_left_lh_pinky_mcp_roll" kp="200" kv="0" ctrlrange="-0.23 0.23" />
    <position name="hand_left_lh_pinky_mcp_pitch_act" joint="hand_left_lh_pinky_mcp_pitch" kp="200" kv="0" ctrlrange="0 1.2217" />
    <position name="hand_left_lh_pinky_pip_act" joint="hand_left_lh_pinky_pip" kp="200" kv="0" ctrlrange="0 1.7279" />
    <position name="hand_right_rh_thumb_cmc_roll_act" joint="hand_right_rh_thumb_cmc_roll" kp="200" kv="0" ctrlrange="0 1.309" />
    <position name="hand_right_rh_thumb_cmc_yaw_act" joint="hand_right_rh_thumb_cmc_yaw" kp="200" kv="0" ctrlrange="0 1.5882" />
    <position name="hand_right_rh_thumb_cmc_pitch_act" joint="hand_right_rh_thumb_cmc_pitch" kp="200" kv="0" ctrlrange="0 0.7854" />
    <position name="hand_right_rh_thumb_mcp_act" joint="hand_right_rh_thumb_mcp" kp="200" kv="0" ctrlrange="0 1.2217" />
    <position name="hand_right_rh_index_mcp_roll_act" joint="hand_right_rh_index_mcp_roll" kp="200" kv="0" ctrlrange="-0.2269 0.2269" />
    <position name="hand_right_rh_index_mcp_pitch_act" joint="hand_right_rh_index_mcp_pitch" kp="200" kv="0" ctrlrange="0 1.2217" />
    <position name="hand_right_rh_index_pip_act" joint="hand_right_rh_index_pip" kp="200" kv="0" ctrlrange="0 1.7279" />
    <position name="hand_right_rh_middle_mcp_roll_act" joint="hand_right_rh_middle_mcp_roll" kp="200" kv="0" ctrlrange="-0.23 0.23" />
    <position name="hand_right_rh_middle_mcp_pitch_act" joint="hand_right_rh_middle_mcp_pitch" kp="200" kv="0" ctrlrange="0 1.2217" />
    <position name="hand_right_rh_middle_pip_act" joint="hand_right_rh_middle_pip" kp="200" kv="0" ctrlrange="0 1.7279" />
    <position name="hand_right_rh_ring_mcp_roll_act" joint="hand_right_rh_ring_mcp_roll" kp="200" kv="0" ctrlrange="-0.23 0.23" />
    <position name="hand_right_rh_ring_mcp_pitch_act" joint="hand_right_rh_ring_mcp_pitch" kp="200" kv="0" ctrlrange="0 1.2217" />
    <position name="hand_right_rh_ring_pip_act" joint="hand_right_rh_ring_pip" kp="200" kv="0" ctrlrange="0 1.7279" />
    <position name="hand_right_rh_pinky_mcp_roll_act" joint="hand_right_rh_pinky_mcp_roll" kp="200" kv="0" ctrlrange="-0.23 0.23" />
    <position name="hand_right_rh_pinky_mcp_pitch_act" joint="hand_right_rh_pinky_mcp_pitch" kp="200" kv="0" ctrlrange="0 1.2217" />
    <position name="hand_right_rh_pinky_pip_act" joint="hand_right_rh_pinky_pip" kp="200" kv="0" ctrlrange="0 1.7279" />
  </actuator>
  <equality>
    <joint name="hand_left_lh_couple_thumb_dip" joint1="hand_left_lh_thumb_dip" joint2="hand_left_lh_thumb_mcp" polycoef="0 1.0142 0 0 0" />
    <joint name="hand_left_lh_couple_index_dip" joint1="hand_left_lh_index_dip" joint2="hand_left_lh_index_pip" polycoef="0 0.7879 0 0 0" />
    <joint name="hand_left_lh_couple_middle_dip" joint1="hand_left_lh_middle_dip" joint2="hand_left_lh_middle_pip" polycoef="0 0.7879 0 0 0" />
    <joint name="hand_left_lh_couple_ring_dip" joint1="hand_left_lh_ring_dip" joint2="hand_left_lh_ring_pip" polycoef="0 0.7879 0 0 0" />
    <joint name="hand_left_lh_couple_pinky_dip" joint1="hand_left_lh_pinky_dip" joint2="hand_left_lh_pinky_pip" polycoef="0 0.7879 0 0 0" />
    <joint name="hand_right_rh_couple_thumb_dip" joint1="hand_right_rh_thumb_dip" joint2="hand_right_rh_thumb_mcp" polycoef="0 1.0142 0 0 0" />
    <joint name="hand_right_rh_couple_index_dip" joint1="hand_right_rh_index_dip" joint2="hand_right_rh_index_pip" polycoef="0 0.7879 0 0 0" />
    <joint name="hand_right_rh_couple_middle_dip" joint1="hand_right_rh_middle_dip" joint2="hand_right_rh_middle_pip" polycoef="0 0.7879 0 0 0" />
    <joint name="hand_right_rh_couple_ring_dip" joint1="hand_right_rh_ring_dip" joint2="hand_right_rh_ring_pip" polycoef="0 0.7879 0 0 0" />
    <joint name="hand_right_rh_couple_pinky_dip" joint1="hand_right_rh_pinky_dip" joint2="hand_right_rh_pinky_pip" polycoef="0 0.7879 0 0 0" />
  </equality>
  <contact>
    <exclude body1="arm_left_L1_Link" body2="arm_left_L2_Link" />
    <exclude body1="arm_left_L2_Link" body2="arm_left_L3_Link" />
    <exclude body1="arm_left_L3_Link" body2="arm_left_L4_Link" />
    <exclude body1="arm_left_L4_Link" body2="arm_left_L5_Link" />
    <exclude body1="arm_left_L5_Link" body2="arm_left_L6_Link" />
    <exclude body1="arm_left_L6_Link" body2="arm_left_L7_Link" />
    <exclude body1="arm_left_L7_Link" body2="arm_left_L8_Link" />
    <exclude body1="arm_right_R1_Link" body2="arm_right_R2_Link" />
    <exclude body1="arm_right_R2_Link" body2="arm_right_R3_Link" />
    <exclude body1="arm_right_R3_Link" body2="arm_right_R4_Link" />
    <exclude body1="arm_right_R4_Link" body2="arm_right_R5_Link" />
    <exclude body1="arm_right_R5_Link" body2="arm_right_R6_Link" />
    <exclude body1="arm_right_R6_Link" body2="arm_right_R7_Link" />
    <exclude body1="arm_right_R7_Link" body2="arm_right_R8_Link" />
    <exclude body1="hand_left_lh_hand_base_link" body2="hand_left_lh_thumb_metacarpals_base1" />
    <exclude body1="hand_left_lh_thumb_metacarpals_base1" body2="hand_left_lh_thumb_metacarpals_base2" />
    <exclude body1="hand_left_lh_thumb_metacarpals_base2" body2="hand_left_lh_thumb_metacarpals" />
    <exclude body1="hand_left_lh_thumb_metacarpals" body2="hand_left_lh_thumb_proximal" />
    <exclude body1="hand_left_lh_thumb_proximal" body2="hand_left_lh_thumb_distal" />
    <exclude body1="hand_left_lh_hand_base_link" body2="hand_left_lh_index_metacarpals" />
    <exclude body1="hand_left_lh_index_metacarpals" body2="hand_left_lh_index_proximal" />
    <exclude body1="hand_left_lh_index_proximal" body2="hand_left_lh_index_middle" />
    <exclude body1="hand_left_lh_index_middle" body2="hand_left_lh_index_distal" />
    <exclude body1="hand_left_lh_hand_base_link" body2="hand_left_lh_middle_metacarpals" />
    <exclude body1="hand_left_lh_middle_metacarpals" body2="hand_left_lh_middle_proximal" />
    <exclude body1="hand_left_lh_middle_proximal" body2="hand_left_lh_middle_middle" />
    <exclude body1="hand_left_lh_middle_middle" body2="hand_left_lh_middle_distal" />
    <exclude body1="hand_left_lh_hand_base_link" body2="hand_left_lh_ring_metacarpals" />
    <exclude body1="hand_left_lh_ring_metacarpals" body2="hand_left_lh_ring_proximal" />
    <exclude body1="hand_left_lh_ring_proximal" body2="hand_left_lh_ring_middle" />
    <exclude body1="hand_left_lh_ring_middle" body2="hand_left_lh_ring_distal" />
    <exclude body1="hand_left_lh_hand_base_link" body2="hand_left_lh_pinky_metacarpals" />
    <exclude body1="hand_left_lh_pinky_metacarpals" body2="hand_left_lh_pinky_proximal" />
    <exclude body1="hand_left_lh_pinky_proximal" body2="hand_left_lh_pinky_middle" />
    <exclude body1="hand_left_lh_pinky_middle" body2="hand_left_lh_pinky_distal" />
    <exclude body1="hand_left_lh_hand_base_link" body2="hand_left_lh_index_proximal" />
    <exclude body1="hand_left_lh_hand_base_link" body2="hand_left_lh_middle_proximal" />
    <exclude body1="hand_left_lh_hand_base_link" body2="hand_left_lh_ring_proximal" />
    <exclude body1="hand_left_lh_hand_base_link" body2="hand_left_lh_pinky_proximal" />
    <exclude body1="hand_left_lh_hand_base_link" body2="hand_left_lh_thumb_metacarpals_base2" />
    <exclude body1="hand_left_lh_hand_base_link" body2="hand_left_lh_thumb_metacarpals" />
    <exclude body1="hand_left_lh_thumb_metacarpals" body2="hand_left_lh_thumb_metacarpals_base1" />
    <exclude body1="hand_right_rh_hand_base_link" body2="hand_right_rh_thumb_metacarpals_base1" />
    <exclude body1="hand_right_rh_thumb_metacarpals_base1" body2="hand_right_rh_thumb_metacarpals_base2" />
    <exclude body1="hand_right_rh_thumb_metacarpals_base2" body2="hand_right_rh_thumb_metacarpals" />
    <exclude body1="hand_right_rh_thumb_metacarpals" body2="hand_right_rh_thumb_proximal" />
    <exclude body1="hand_right_rh_thumb_proximal" body2="hand_right_rh_thumb_distal" />
    <exclude body1="hand_right_rh_hand_base_link" body2="hand_right_rh_index_metacarpals" />
    <exclude body1="hand_right_rh_index_metacarpals" body2="hand_right_rh_index_proximal" />
    <exclude body1="hand_right_rh_index_proximal" body2="hand_right_rh_index_middle" />
    <exclude body1="hand_right_rh_index_middle" body2="hand_right_rh_index_distal" />
    <exclude body1="hand_right_rh_hand_base_link" body2="hand_right_rh_middle_metacarpals" />
    <exclude body1="hand_right_rh_middle_metacarpals" body2="hand_right_rh_middle_proximal" />
    <exclude body1="hand_right_rh_middle_proximal" body2="hand_right_rh_middle_middle" />
    <exclude body1="hand_right_rh_middle_middle" body2="hand_right_rh_middle_distal" />
    <exclude body1="hand_right_rh_hand_base_link" body2="hand_right_rh_ring_metacarpals" />
    <exclude body1="hand_right_rh_ring_metacarpals" body2="hand_right_rh_ring_proximal" />
    <exclude body1="hand_right_rh_ring_proximal" body2="hand_right_rh_ring_middle" />
    <exclude body1="hand_right_rh_ring_middle" body2="hand_right_rh_ring_distal" />
    <exclude body1="hand_right_rh_hand_base_link" body2="hand_right_rh_pinky_metacarpals" />
    <exclude body1="hand_right_rh_pinky_metacarpals" body2="hand_right_rh_pinky_proximal" />
    <exclude body1="hand_right_rh_pinky_proximal" body2="hand_right_rh_pinky_middle" />
    <exclude body1="hand_right_rh_pinky_middle" body2="hand_right_rh_pinky_distal" />
    <exclude body1="hand_right_rh_hand_base_link" body2="hand_right_rh_index_proximal" />
    <exclude body1="hand_right_rh_hand_base_link" body2="hand_right_rh_middle_proximal" />
    <exclude body1="hand_right_rh_hand_base_link" body2="hand_right_rh_ring_proximal" />
    <exclude body1="hand_right_rh_hand_base_link" body2="hand_right_rh_pinky_proximal" />
    <exclude body1="hand_right_rh_hand_base_link" body2="hand_right_rh_thumb_metacarpals_base2" />
    <exclude body1="hand_right_rh_hand_base_link" body2="hand_right_rh_thumb_metacarpals" />
    <exclude body1="hand_right_rh_thumb_metacarpals" body2="hand_right_rh_thumb_metacarpals_base1" />
    <exclude body1="base_base_link" body2="arm_left_L1_Link" />
    <exclude body1="base_base_link" body2="arm_left_L2_Link" />
    <exclude body1="base_base_link" body2="arm_left_L3_Link" />
    <exclude body1="base_base_link" body2="arm_left_L4_Link" />
    <exclude body1="base_base_link" body2="arm_left_L5_Link" />
    <exclude body1="base_base_link" body2="arm_left_L6_Link" />
    <exclude body1="base_base_link" body2="arm_left_L7_Link" />
    <exclude body1="base_base_link" body2="arm_left_L8_Link" />
    <exclude body1="base_base_link" body2="arm_right_R1_Link" />
    <exclude body1="base_base_link" body2="arm_right_R2_Link" />
    <exclude body1="base_base_link" body2="arm_right_R3_Link" />
    <exclude body1="base_base_link" body2="arm_right_R4_Link" />
    <exclude body1="base_base_link" body2="arm_right_R5_Link" />
    <exclude body1="base_base_link" body2="arm_right_R6_Link" />
    <exclude body1="base_base_link" body2="arm_right_R7_Link" />
    <exclude body1="base_base_link" body2="arm_right_R8_Link" />
    <exclude body1="arm_left_L1_Link" body2="hand_left_lh_hand_base_link" />
    <exclude body1="arm_left_L1_Link" body2="hand_left_lh_thumb_metacarpals_base1" />
    <exclude body1="arm_left_L1_Link" body2="hand_left_lh_thumb_metacarpals_base2" />
    <exclude body1="arm_left_L1_Link" body2="hand_left_lh_thumb_metacarpals" />
    <exclude body1="arm_left_L1_Link" body2="hand_left_lh_thumb_proximal" />
    <exclude body1="arm_left_L1_Link" body2="hand_left_lh_thumb_distal" />
    <exclude body1="arm_left_L1_Link" body2="hand_left_lh_index_metacarpals" />
    <exclude body1="arm_left_L1_Link" body2="hand_left_lh_index_proximal" />
    <exclude body1="arm_left_L1_Link" body2="hand_left_lh_index_middle" />
    <exclude body1="arm_left_L1_Link" body2="hand_left_lh_index_distal" />
    <exclude body1="arm_left_L1_Link" body2="hand_left_lh_middle_metacarpals" />
    <exclude body1="arm_left_L1_Link" body2="hand_left_lh_middle_proximal" />
    <exclude body1="arm_left_L1_Link" body2="hand_left_lh_middle_middle" />
    <exclude body1="arm_left_L1_Link" body2="hand_left_lh_middle_distal" />
    <exclude body1="arm_left_L1_Link" body2="hand_left_lh_ring_metacarpals" />
    <exclude body1="arm_left_L1_Link" body2="hand_left_lh_ring_proximal" />
    <exclude body1="arm_left_L1_Link" body2="hand_left_lh_ring_middle" />
    <exclude body1="arm_left_L1_Link" body2="hand_left_lh_ring_distal" />
    <exclude body1="arm_left_L1_Link" body2="hand_left_lh_pinky_metacarpals" />
    <exclude body1="arm_left_L1_Link" body2="hand_left_lh_pinky_proximal" />
    <exclude body1="arm_left_L1_Link" body2="hand_left_lh_pinky_middle" />
    <exclude body1="arm_left_L1_Link" body2="hand_left_lh_pinky_distal" />
    <exclude body1="arm_left_L2_Link" body2="hand_left_lh_hand_base_link" />
    <exclude body1="arm_left_L2_Link" body2="hand_left_lh_thumb_metacarpals_base1" />
    <exclude body1="arm_left_L2_Link" body2="hand_left_lh_thumb_metacarpals_base2" />
    <exclude body1="arm_left_L2_Link" body2="hand_left_lh_thumb_metacarpals" />
    <exclude body1="arm_left_L2_Link" body2="hand_left_lh_thumb_proximal" />
    <exclude body1="arm_left_L2_Link" body2="hand_left_lh_thumb_distal" />
    <exclude body1="arm_left_L2_Link" body2="hand_left_lh_index_metacarpals" />
    <exclude body1="arm_left_L2_Link" body2="hand_left_lh_index_proximal" />
    <exclude body1="arm_left_L2_Link" body2="hand_left_lh_index_middle" />
    <exclude body1="arm_left_L2_Link" body2="hand_left_lh_index_distal" />
    <exclude body1="arm_left_L2_Link" body2="hand_left_lh_middle_metacarpals" />
    <exclude body1="arm_left_L2_Link" body2="hand_left_lh_middle_proximal" />
    <exclude body1="arm_left_L2_Link" body2="hand_left_lh_middle_middle" />
    <exclude body1="arm_left_L2_Link" body2="hand_left_lh_middle_distal" />
    <exclude body1="arm_left_L2_Link" body2="hand_left_lh_ring_metacarpals" />
    <exclude body1="arm_left_L2_Link" body2="hand_left_lh_ring_proximal" />
    <exclude body1="arm_left_L2_Link" body2="hand_left_lh_ring_middle" />
    <exclude body1="arm_left_L2_Link" body2="hand_left_lh_ring_distal" />
    <exclude body1="arm_left_L2_Link" body2="hand_left_lh_pinky_metacarpals" />
    <exclude body1="arm_left_L2_Link" body2="hand_left_lh_pinky_proximal" />
    <exclude body1="arm_left_L2_Link" body2="hand_left_lh_pinky_middle" />
    <exclude body1="arm_left_L2_Link" body2="hand_left_lh_pinky_distal" />
    <exclude body1="arm_left_L3_Link" body2="hand_left_lh_hand_base_link" />
    <exclude body1="arm_left_L3_Link" body2="hand_left_lh_thumb_metacarpals_base1" />
    <exclude body1="arm_left_L3_Link" body2="hand_left_lh_thumb_metacarpals_base2" />
    <exclude body1="arm_left_L3_Link" body2="hand_left_lh_thumb_metacarpals" />
    <exclude body1="arm_left_L3_Link" body2="hand_left_lh_thumb_proximal" />
    <exclude body1="arm_left_L3_Link" body2="hand_left_lh_thumb_distal" />
    <exclude body1="arm_left_L3_Link" body2="hand_left_lh_index_metacarpals" />
    <exclude body1="arm_left_L3_Link" body2="hand_left_lh_index_proximal" />
    <exclude body1="arm_left_L3_Link" body2="hand_left_lh_index_middle" />
    <exclude body1="arm_left_L3_Link" body2="hand_left_lh_index_distal" />
    <exclude body1="arm_left_L3_Link" body2="hand_left_lh_middle_metacarpals" />
    <exclude body1="arm_left_L3_Link" body2="hand_left_lh_middle_proximal" />
    <exclude body1="arm_left_L3_Link" body2="hand_left_lh_middle_middle" />
    <exclude body1="arm_left_L3_Link" body2="hand_left_lh_middle_distal" />
    <exclude body1="arm_left_L3_Link" body2="hand_left_lh_ring_metacarpals" />
    <exclude body1="arm_left_L3_Link" body2="hand_left_lh_ring_proximal" />
    <exclude body1="arm_left_L3_Link" body2="hand_left_lh_ring_middle" />
    <exclude body1="arm_left_L3_Link" body2="hand_left_lh_ring_distal" />
    <exclude body1="arm_left_L3_Link" body2="hand_left_lh_pinky_metacarpals" />
    <exclude body1="arm_left_L3_Link" body2="hand_left_lh_pinky_proximal" />
    <exclude body1="arm_left_L3_Link" body2="hand_left_lh_pinky_middle" />
    <exclude body1="arm_left_L3_Link" body2="hand_left_lh_pinky_distal" />
    <exclude body1="arm_left_L4_Link" body2="hand_left_lh_hand_base_link" />
    <exclude body1="arm_left_L4_Link" body2="hand_left_lh_thumb_metacarpals_base1" />
    <exclude body1="arm_left_L4_Link" body2="hand_left_lh_thumb_metacarpals_base2" />
    <exclude body1="arm_left_L4_Link" body2="hand_left_lh_thumb_metacarpals" />
    <exclude body1="arm_left_L4_Link" body2="hand_left_lh_thumb_proximal" />
    <exclude body1="arm_left_L4_Link" body2="hand_left_lh_thumb_distal" />
    <exclude body1="arm_left_L4_Link" body2="hand_left_lh_index_metacarpals" />
    <exclude body1="arm_left_L4_Link" body2="hand_left_lh_index_proximal" />
    <exclude body1="arm_left_L4_Link" body2="hand_left_lh_index_middle" />
    <exclude body1="arm_left_L4_Link" body2="hand_left_lh_index_distal" />
    <exclude body1="arm_left_L4_Link" body2="hand_left_lh_middle_metacarpals" />
    <exclude body1="arm_left_L4_Link" body2="hand_left_lh_middle_proximal" />
    <exclude body1="arm_left_L4_Link" body2="hand_left_lh_middle_middle" />
    <exclude body1="arm_left_L4_Link" body2="hand_left_lh_middle_distal" />
    <exclude body1="arm_left_L4_Link" body2="hand_left_lh_ring_metacarpals" />
    <exclude body1="arm_left_L4_Link" body2="hand_left_lh_ring_proximal" />
    <exclude body1="arm_left_L4_Link" body2="hand_left_lh_ring_middle" />
    <exclude body1="arm_left_L4_Link" body2="hand_left_lh_ring_distal" />
    <exclude body1="arm_left_L4_Link" body2="hand_left_lh_pinky_metacarpals" />
    <exclude body1="arm_left_L4_Link" body2="hand_left_lh_pinky_proximal" />
    <exclude body1="arm_left_L4_Link" body2="hand_left_lh_pinky_middle" />
    <exclude body1="arm_left_L4_Link" body2="hand_left_lh_pinky_distal" />
    <exclude body1="arm_left_L5_Link" body2="hand_left_lh_hand_base_link" />
    <exclude body1="arm_left_L5_Link" body2="hand_left_lh_thumb_metacarpals_base1" />
    <exclude body1="arm_left_L5_Link" body2="hand_left_lh_thumb_metacarpals_base2" />
    <exclude body1="arm_left_L5_Link" body2="hand_left_lh_thumb_metacarpals" />
    <exclude body1="arm_left_L5_Link" body2="hand_left_lh_thumb_proximal" />
    <exclude body1="arm_left_L5_Link" body2="hand_left_lh_thumb_distal" />
    <exclude body1="arm_left_L5_Link" body2="hand_left_lh_index_metacarpals" />
    <exclude body1="arm_left_L5_Link" body2="hand_left_lh_index_proximal" />
    <exclude body1="arm_left_L5_Link" body2="hand_left_lh_index_middle" />
    <exclude body1="arm_left_L5_Link" body2="hand_left_lh_index_distal" />
    <exclude body1="arm_left_L5_Link" body2="hand_left_lh_middle_metacarpals" />
    <exclude body1="arm_left_L5_Link" body2="hand_left_lh_middle_proximal" />
    <exclude body1="arm_left_L5_Link" body2="hand_left_lh_middle_middle" />
    <exclude body1="arm_left_L5_Link" body2="hand_left_lh_middle_distal" />
    <exclude body1="arm_left_L5_Link" body2="hand_left_lh_ring_metacarpals" />
    <exclude body1="arm_left_L5_Link" body2="hand_left_lh_ring_proximal" />
    <exclude body1="arm_left_L5_Link" body2="hand_left_lh_ring_middle" />
    <exclude body1="arm_left_L5_Link" body2="hand_left_lh_ring_distal" />
    <exclude body1="arm_left_L5_Link" body2="hand_left_lh_pinky_metacarpals" />
    <exclude body1="arm_left_L5_Link" body2="hand_left_lh_pinky_proximal" />
    <exclude body1="arm_left_L5_Link" body2="hand_left_lh_pinky_middle" />
    <exclude body1="arm_left_L5_Link" body2="hand_left_lh_pinky_distal" />
    <exclude body1="arm_left_L6_Link" body2="hand_left_lh_hand_base_link" />
    <exclude body1="arm_left_L6_Link" body2="hand_left_lh_thumb_metacarpals_base1" />
    <exclude body1="arm_left_L6_Link" body2="hand_left_lh_thumb_metacarpals_base2" />
    <exclude body1="arm_left_L6_Link" body2="hand_left_lh_thumb_metacarpals" />
    <exclude body1="arm_left_L6_Link" body2="hand_left_lh_thumb_proximal" />
    <exclude body1="arm_left_L6_Link" body2="hand_left_lh_thumb_distal" />
    <exclude body1="arm_left_L6_Link" body2="hand_left_lh_index_metacarpals" />
    <exclude body1="arm_left_L6_Link" body2="hand_left_lh_index_proximal" />
    <exclude body1="arm_left_L6_Link" body2="hand_left_lh_index_middle" />
    <exclude body1="arm_left_L6_Link" body2="hand_left_lh_index_distal" />
    <exclude body1="arm_left_L6_Link" body2="hand_left_lh_middle_metacarpals" />
    <exclude body1="arm_left_L6_Link" body2="hand_left_lh_middle_proximal" />
    <exclude body1="arm_left_L6_Link" body2="hand_left_lh_middle_middle" />
    <exclude body1="arm_left_L6_Link" body2="hand_left_lh_middle_distal" />
    <exclude body1="arm_left_L6_Link" body2="hand_left_lh_ring_metacarpals" />
    <exclude body1="arm_left_L6_Link" body2="hand_left_lh_ring_proximal" />
    <exclude body1="arm_left_L6_Link" body2="hand_left_lh_ring_middle" />
    <exclude body1="arm_left_L6_Link" body2="hand_left_lh_ring_distal" />
    <exclude body1="arm_left_L6_Link" body2="hand_left_lh_pinky_metacarpals" />
    <exclude body1="arm_left_L6_Link" body2="hand_left_lh_pinky_proximal" />
    <exclude body1="arm_left_L6_Link" body2="hand_left_lh_pinky_middle" />
    <exclude body1="arm_left_L6_Link" body2="hand_left_lh_pinky_distal" />
    <exclude body1="arm_left_L7_Link" body2="hand_left_lh_hand_base_link" />
    <exclude body1="arm_left_L7_Link" body2="hand_left_lh_thumb_metacarpals_base1" />
    <exclude body1="arm_left_L7_Link" body2="hand_left_lh_thumb_metacarpals_base2" />
    <exclude body1="arm_left_L7_Link" body2="hand_left_lh_thumb_metacarpals" />
    <exclude body1="arm_left_L7_Link" body2="hand_left_lh_thumb_proximal" />
    <exclude body1="arm_left_L7_Link" body2="hand_left_lh_thumb_distal" />
    <exclude body1="arm_left_L7_Link" body2="hand_left_lh_index_metacarpals" />
    <exclude body1="arm_left_L7_Link" body2="hand_left_lh_index_proximal" />
    <exclude body1="arm_left_L7_Link" body2="hand_left_lh_index_middle" />
    <exclude body1="arm_left_L7_Link" body2="hand_left_lh_index_distal" />
    <exclude body1="arm_left_L7_Link" body2="hand_left_lh_middle_metacarpals" />
    <exclude body1="arm_left_L7_Link" body2="hand_left_lh_middle_proximal" />
    <exclude body1="arm_left_L7_Link" body2="hand_left_lh_middle_middle" />
    <exclude body1="arm_left_L7_Link" body2="hand_left_lh_middle_distal" />
    <exclude body1="arm_left_L7_Link" body2="hand_left_lh_ring_metacarpals" />
    <exclude body1="arm_left_L7_Link" body2="hand_left_lh_ring_proximal" />
    <exclude body1="arm_left_L7_Link" body2="hand_left_lh_ring_middle" />
    <exclude body1="arm_left_L7_Link" body2="hand_left_lh_ring_distal" />
    <exclude body1="arm_left_L7_Link" body2="hand_left_lh_pinky_metacarpals" />
    <exclude body1="arm_left_L7_Link" body2="hand_left_lh_pinky_proximal" />
    <exclude body1="arm_left_L7_Link" body2="hand_left_lh_pinky_middle" />
    <exclude body1="arm_left_L7_Link" body2="hand_left_lh_pinky_distal" />
    <exclude body1="arm_left_L8_Link" body2="hand_left_lh_hand_base_link" />
    <exclude body1="arm_left_L8_Link" body2="hand_left_lh_thumb_metacarpals_base1" />
    <exclude body1="arm_left_L8_Link" body2="hand_left_lh_thumb_metacarpals_base2" />
    <exclude body1="arm_left_L8_Link" body2="hand_left_lh_thumb_metacarpals" />
    <exclude body1="arm_left_L8_Link" body2="hand_left_lh_thumb_proximal" />
    <exclude body1="arm_left_L8_Link" body2="hand_left_lh_thumb_distal" />
    <exclude body1="arm_left_L8_Link" body2="hand_left_lh_index_metacarpals" />
    <exclude body1="arm_left_L8_Link" body2="hand_left_lh_index_proximal" />
    <exclude body1="arm_left_L8_Link" body2="hand_left_lh_index_middle" />
    <exclude body1="arm_left_L8_Link" body2="hand_left_lh_index_distal" />
    <exclude body1="arm_left_L8_Link" body2="hand_left_lh_middle_metacarpals" />
    <exclude body1="arm_left_L8_Link" body2="hand_left_lh_middle_proximal" />
    <exclude body1="arm_left_L8_Link" body2="hand_left_lh_middle_middle" />
    <exclude body1="arm_left_L8_Link" body2="hand_left_lh_middle_distal" />
    <exclude body1="arm_left_L8_Link" body2="hand_left_lh_ring_metacarpals" />
    <exclude body1="arm_left_L8_Link" body2="hand_left_lh_ring_proximal" />
    <exclude body1="arm_left_L8_Link" body2="hand_left_lh_ring_middle" />
    <exclude body1="arm_left_L8_Link" body2="hand_left_lh_ring_distal" />
    <exclude body1="arm_left_L8_Link" body2="hand_left_lh_pinky_metacarpals" />
    <exclude body1="arm_left_L8_Link" body2="hand_left_lh_pinky_proximal" />
    <exclude body1="arm_left_L8_Link" body2="hand_left_lh_pinky_middle" />
    <exclude body1="arm_left_L8_Link" body2="hand_left_lh_pinky_distal" />
    <exclude body1="base_base_link" body2="hand_left_lh_hand_base_link" />
    <exclude body1="base_base_link" body2="hand_left_lh_thumb_metacarpals_base1" />
    <exclude body1="base_base_link" body2="hand_left_lh_thumb_metacarpals_base2" />
    <exclude body1="base_base_link" body2="hand_left_lh_thumb_metacarpals" />
    <exclude body1="base_base_link" body2="hand_left_lh_thumb_proximal" />
    <exclude body1="base_base_link" body2="hand_left_lh_thumb_distal" />
    <exclude body1="base_base_link" body2="hand_left_lh_index_metacarpals" />
    <exclude body1="base_base_link" body2="hand_left_lh_index_proximal" />
    <exclude body1="base_base_link" body2="hand_left_lh_index_middle" />
    <exclude body1="base_base_link" body2="hand_left_lh_index_distal" />
    <exclude body1="base_base_link" body2="hand_left_lh_middle_metacarpals" />
    <exclude body1="base_base_link" body2="hand_left_lh_middle_proximal" />
    <exclude body1="base_base_link" body2="hand_left_lh_middle_middle" />
    <exclude body1="base_base_link" body2="hand_left_lh_middle_distal" />
    <exclude body1="base_base_link" body2="hand_left_lh_ring_metacarpals" />
    <exclude body1="base_base_link" body2="hand_left_lh_ring_proximal" />
    <exclude body1="base_base_link" body2="hand_left_lh_ring_middle" />
    <exclude body1="base_base_link" body2="hand_left_lh_ring_distal" />
    <exclude body1="base_base_link" body2="hand_left_lh_pinky_metacarpals" />
    <exclude body1="base_base_link" body2="hand_left_lh_pinky_proximal" />
    <exclude body1="base_base_link" body2="hand_left_lh_pinky_middle" />
    <exclude body1="base_base_link" body2="hand_left_lh_pinky_distal" />
    <exclude body1="arm_right_R1_Link" body2="hand_right_rh_hand_base_link" />
    <exclude body1="arm_right_R1_Link" body2="hand_right_rh_thumb_metacarpals_base1" />
    <exclude body1="arm_right_R1_Link" body2="hand_right_rh_thumb_metacarpals_base2" />
    <exclude body1="arm_right_R1_Link" body2="hand_right_rh_thumb_metacarpals" />
    <exclude body1="arm_right_R1_Link" body2="hand_right_rh_thumb_proximal" />
    <exclude body1="arm_right_R1_Link" body2="hand_right_rh_thumb_distal" />
    <exclude body1="arm_right_R1_Link" body2="hand_right_rh_index_metacarpals" />
    <exclude body1="arm_right_R1_Link" body2="hand_right_rh_index_proximal" />
    <exclude body1="arm_right_R1_Link" body2="hand_right_rh_index_middle" />
    <exclude body1="arm_right_R1_Link" body2="hand_right_rh_index_distal" />
    <exclude body1="arm_right_R1_Link" body2="hand_right_rh_middle_metacarpals" />
    <exclude body1="arm_right_R1_Link" body2="hand_right_rh_middle_proximal" />
    <exclude body1="arm_right_R1_Link" body2="hand_right_rh_middle_middle" />
    <exclude body1="arm_right_R1_Link" body2="hand_right_rh_middle_distal" />
    <exclude body1="arm_right_R1_Link" body2="hand_right_rh_ring_metacarpals" />
    <exclude body1="arm_right_R1_Link" body2="hand_right_rh_ring_proximal" />
    <exclude body1="arm_right_R1_Link" body2="hand_right_rh_ring_middle" />
    <exclude body1="arm_right_R1_Link" body2="hand_right_rh_ring_distal" />
    <exclude body1="arm_right_R1_Link" body2="hand_right_rh_pinky_metacarpals" />
    <exclude body1="arm_right_R1_Link" body2="hand_right_rh_pinky_proximal" />
    <exclude body1="arm_right_R1_Link" body2="hand_right_rh_pinky_middle" />
    <exclude body1="arm_right_R1_Link" body2="hand_right_rh_pinky_distal" />
    <exclude body1="arm_right_R2_Link" body2="hand_right_rh_hand_base_link" />
    <exclude body1="arm_right_R2_Link" body2="hand_right_rh_thumb_metacarpals_base1" />
    <exclude body1="arm_right_R2_Link" body2="hand_right_rh_thumb_metacarpals_base2" />
    <exclude body1="arm_right_R2_Link" body2="hand_right_rh_thumb_metacarpals" />
    <exclude body1="arm_right_R2_Link" body2="hand_right_rh_thumb_proximal" />
    <exclude body1="arm_right_R2_Link" body2="hand_right_rh_thumb_distal" />
    <exclude body1="arm_right_R2_Link" body2="hand_right_rh_index_metacarpals" />
    <exclude body1="arm_right_R2_Link" body2="hand_right_rh_index_proximal" />
    <exclude body1="arm_right_R2_Link" body2="hand_right_rh_index_middle" />
    <exclude body1="arm_right_R2_Link" body2="hand_right_rh_index_distal" />
    <exclude body1="arm_right_R2_Link" body2="hand_right_rh_middle_metacarpals" />
    <exclude body1="arm_right_R2_Link" body2="hand_right_rh_middle_proximal" />
    <exclude body1="arm_right_R2_Link" body2="hand_right_rh_middle_middle" />
    <exclude body1="arm_right_R2_Link" body2="hand_right_rh_middle_distal" />
    <exclude body1="arm_right_R2_Link" body2="hand_right_rh_ring_metacarpals" />
    <exclude body1="arm_right_R2_Link" body2="hand_right_rh_ring_proximal" />
    <exclude body1="arm_right_R2_Link" body2="hand_right_rh_ring_middle" />
    <exclude body1="arm_right_R2_Link" body2="hand_right_rh_ring_distal" />
    <exclude body1="arm_right_R2_Link" body2="hand_right_rh_pinky_metacarpals" />
    <exclude body1="arm_right_R2_Link" body2="hand_right_rh_pinky_proximal" />
    <exclude body1="arm_right_R2_Link" body2="hand_right_rh_pinky_middle" />
    <exclude body1="arm_right_R2_Link" body2="hand_right_rh_pinky_distal" />
    <exclude body1="arm_right_R3_Link" body2="hand_right_rh_hand_base_link" />
    <exclude body1="arm_right_R3_Link" body2="hand_right_rh_thumb_metacarpals_base1" />
    <exclude body1="arm_right_R3_Link" body2="hand_right_rh_thumb_metacarpals_base2" />
    <exclude body1="arm_right_R3_Link" body2="hand_right_rh_thumb_metacarpals" />
    <exclude body1="arm_right_R3_Link" body2="hand_right_rh_thumb_proximal" />
    <exclude body1="arm_right_R3_Link" body2="hand_right_rh_thumb_distal" />
    <exclude body1="arm_right_R3_Link" body2="hand_right_rh_index_metacarpals" />
    <exclude body1="arm_right_R3_Link" body2="hand_right_rh_index_proximal" />
    <exclude body1="arm_right_R3_Link" body2="hand_right_rh_index_middle" />
    <exclude body1="arm_right_R3_Link" body2="hand_right_rh_index_distal" />
    <exclude body1="arm_right_R3_Link" body2="hand_right_rh_middle_metacarpals" />
    <exclude body1="arm_right_R3_Link" body2="hand_right_rh_middle_proximal" />
    <exclude body1="arm_right_R3_Link" body2="hand_right_rh_middle_middle" />
    <exclude body1="arm_right_R3_Link" body2="hand_right_rh_middle_distal" />
    <exclude body1="arm_right_R3_Link" body2="hand_right_rh_ring_metacarpals" />
    <exclude body1="arm_right_R3_Link" body2="hand_right_rh_ring_proximal" />
    <exclude body1="arm_right_R3_Link" body2="hand_right_rh_ring_middle" />
    <exclude body1="arm_right_R3_Link" body2="hand_right_rh_ring_distal" />
    <exclude body1="arm_right_R3_Link" body2="hand_right_rh_pinky_metacarpals" />
    <exclude body1="arm_right_R3_Link" body2="hand_right_rh_pinky_proximal" />
    <exclude body1="arm_right_R3_Link" body2="hand_right_rh_pinky_middle" />
    <exclude body1="arm_right_R3_Link" body2="hand_right_rh_pinky_distal" />
    <exclude body1="arm_right_R4_Link" body2="hand_right_rh_hand_base_link" />
    <exclude body1="arm_right_R4_Link" body2="hand_right_rh_thumb_metacarpals_base1" />
    <exclude body1="arm_right_R4_Link" body2="hand_right_rh_thumb_metacarpals_base2" />
    <exclude body1="arm_right_R4_Link" body2="hand_right_rh_thumb_metacarpals" />
    <exclude body1="arm_right_R4_Link" body2="hand_right_rh_thumb_proximal" />
    <exclude body1="arm_right_R4_Link" body2="hand_right_rh_thumb_distal" />
    <exclude body1="arm_right_R4_Link" body2="hand_right_rh_index_metacarpals" />
    <exclude body1="arm_right_R4_Link" body2="hand_right_rh_index_proximal" />
    <exclude body1="arm_right_R4_Link" body2="hand_right_rh_index_middle" />
    <exclude body1="arm_right_R4_Link" body2="hand_right_rh_index_distal" />
    <exclude body1="arm_right_R4_Link" body2="hand_right_rh_middle_metacarpals" />
    <exclude body1="arm_right_R4_Link" body2="hand_right_rh_middle_proximal" />
    <exclude body1="arm_right_R4_Link" body2="hand_right_rh_middle_middle" />
    <exclude body1="arm_right_R4_Link" body2="hand_right_rh_middle_distal" />
    <exclude body1="arm_right_R4_Link" body2="hand_right_rh_ring_metacarpals" />
    <exclude body1="arm_right_R4_Link" body2="hand_right_rh_ring_proximal" />
    <exclude body1="arm_right_R4_Link" body2="hand_right_rh_ring_middle" />
    <exclude body1="arm_right_R4_Link" body2="hand_right_rh_ring_distal" />
    <exclude body1="arm_right_R4_Link" body2="hand_right_rh_pinky_metacarpals" />
    <exclude body1="arm_right_R4_Link" body2="hand_right_rh_pinky_proximal" />
    <exclude body1="arm_right_R4_Link" body2="hand_right_rh_pinky_middle" />
    <exclude body1="arm_right_R4_Link" body2="hand_right_rh_pinky_distal" />
    <exclude body1="arm_right_R5_Link" body2="hand_right_rh_hand_base_link" />
    <exclude body1="arm_right_R5_Link" body2="hand_right_rh_thumb_metacarpals_base1" />
    <exclude body1="arm_right_R5_Link" body2="hand_right_rh_thumb_metacarpals_base2" />
    <exclude body1="arm_right_R5_Link" body2="hand_right_rh_thumb_metacarpals" />
    <exclude body1="arm_right_R5_Link" body2="hand_right_rh_thumb_proximal" />
    <exclude body1="arm_right_R5_Link" body2="hand_right_rh_thumb_distal" />
    <exclude body1="arm_right_R5_Link" body2="hand_right_rh_index_metacarpals" />
    <exclude body1="arm_right_R5_Link" body2="hand_right_rh_index_proximal" />
    <exclude body1="arm_right_R5_Link" body2="hand_right_rh_index_middle" />
    <exclude body1="arm_right_R5_Link" body2="hand_right_rh_index_distal" />
    <exclude body1="arm_right_R5_Link" body2="hand_right_rh_middle_metacarpals" />
    <exclude body1="arm_right_R5_Link" body2="hand_right_rh_middle_proximal" />
    <exclude body1="arm_right_R5_Link" body2="hand_right_rh_middle_middle" />
    <exclude body1="arm_right_R5_Link" body2="hand_right_rh_middle_distal" />
    <exclude body1="arm_right_R5_Link" body2="hand_right_rh_ring_metacarpals" />
    <exclude body1="arm_right_R5_Link" body2="hand_right_rh_ring_proximal" />
    <exclude body1="arm_right_R5_Link" body2="hand_right_rh_ring_middle" />
    <exclude body1="arm_right_R5_Link" body2="hand_right_rh_ring_distal" />
    <exclude body1="arm_right_R5_Link" body2="hand_right_rh_pinky_metacarpals" />
    <exclude body1="arm_right_R5_Link" body2="hand_right_rh_pinky_proximal" />
    <exclude body1="arm_right_R5_Link" body2="hand_right_rh_pinky_middle" />
    <exclude body1="arm_right_R5_Link" body2="hand_right_rh_pinky_distal" />
    <exclude body1="arm_right_R6_Link" body2="hand_right_rh_hand_base_link" />
    <exclude body1="arm_right_R6_Link" body2="hand_right_rh_thumb_metacarpals_base1" />
    <exclude body1="arm_right_R6_Link" body2="hand_right_rh_thumb_metacarpals_base2" />
    <exclude body1="arm_right_R6_Link" body2="hand_right_rh_thumb_metacarpals" />
    <exclude body1="arm_right_R6_Link" body2="hand_right_rh_thumb_proximal" />
    <exclude body1="arm_right_R6_Link" body2="hand_right_rh_thumb_distal" />
    <exclude body1="arm_right_R6_Link" body2="hand_right_rh_index_metacarpals" />
    <exclude body1="arm_right_R6_Link" body2="hand_right_rh_index_proximal" />
    <exclude body1="arm_right_R6_Link" body2="hand_right_rh_index_middle" />
    <exclude body1="arm_right_R6_Link" body2="hand_right_rh_index_distal" />
    <exclude body1="arm_right_R6_Link" body2="hand_right_rh_middle_metacarpals" />
    <exclude body1="arm_right_R6_Link" body2="hand_right_rh_middle_proximal" />
    <exclude body1="arm_right_R6_Link" body2="hand_right_rh_middle_middle" />
    <exclude body1="arm_right_R6_Link" body2="hand_right_rh_middle_distal" />
    <exclude body1="arm_right_R6_Link" body2="hand_right_rh_ring_metacarpals" />
    <exclude body1="arm_right_R6_Link" body2="hand_right_rh_ring_proximal" />
    <exclude body1="arm_right_R6_Link" body2="hand_right_rh_ring_middle" />
    <exclude body1="arm_right_R6_Link" body2="hand_right_rh_ring_distal" />
    <exclude body1="arm_right_R6_Link" body2="hand_right_rh_pinky_metacarpals" />
    <exclude body1="arm_right_R6_Link" body2="hand_right_rh_pinky_proximal" />
    <exclude body1="arm_right_R6_Link" body2="hand_right_rh_pinky_middle" />
    <exclude body1="arm_right_R6_Link" body2="hand_right_rh_pinky_distal" />
    <exclude body1="arm_right_R7_Link" body2="hand_right_rh_hand_base_link" />
    <exclude body1="arm_right_R7_Link" body2="hand_right_rh_thumb_metacarpals_base1" />
    <exclude body1="arm_right_R7_Link" body2="hand_right_rh_thumb_metacarpals_base2" />
    <exclude body1="arm_right_R7_Link" body2="hand_right_rh_thumb_metacarpals" />
    <exclude body1="arm_right_R7_Link" body2="hand_right_rh_thumb_proximal" />
    <exclude body1="arm_right_R7_Link" body2="hand_right_rh_thumb_distal" />
    <exclude body1="arm_right_R7_Link" body2="hand_right_rh_index_metacarpals" />
    <exclude body1="arm_right_R7_Link" body2="hand_right_rh_index_proximal" />
    <exclude body1="arm_right_R7_Link" body2="hand_right_rh_index_middle" />
    <exclude body1="arm_right_R7_Link" body2="hand_right_rh_index_distal" />
    <exclude body1="arm_right_R7_Link" body2="hand_right_rh_middle_metacarpals" />
    <exclude body1="arm_right_R7_Link" body2="hand_right_rh_middle_proximal" />
    <exclude body1="arm_right_R7_Link" body2="hand_right_rh_middle_middle" />
    <exclude body1="arm_right_R7_Link" body2="hand_right_rh_middle_distal" />
    <exclude body1="arm_right_R7_Link" body2="hand_right_rh_ring_metacarpals" />
    <exclude body1="arm_right_R7_Link" body2="hand_right_rh_ring_proximal" />
    <exclude body1="arm_right_R7_Link" body2="hand_right_rh_ring_middle" />
    <exclude body1="arm_right_R7_Link" body2="hand_right_rh_ring_distal" />
    <exclude body1="arm_right_R7_Link" body2="hand_right_rh_pinky_metacarpals" />
    <exclude body1="arm_right_R7_Link" body2="hand_right_rh_pinky_proximal" />
    <exclude body1="arm_right_R7_Link" body2="hand_right_rh_pinky_middle" />
    <exclude body1="arm_right_R7_Link" body2="hand_right_rh_pinky_distal" />
    <exclude body1="arm_right_R8_Link" body2="hand_right_rh_hand_base_link" />
    <exclude body1="arm_right_R8_Link" body2="hand_right_rh_thumb_metacarpals_base1" />
    <exclude body1="arm_right_R8_Link" body2="hand_right_rh_thumb_metacarpals_base2" />
    <exclude body1="arm_right_R8_Link" body2="hand_right_rh_thumb_metacarpals" />
    <exclude body1="arm_right_R8_Link" body2="hand_right_rh_thumb_proximal" />
    <exclude body1="arm_right_R8_Link" body2="hand_right_rh_thumb_distal" />
    <exclude body1="arm_right_R8_Link" body2="hand_right_rh_index_metacarpals" />
    <exclude body1="arm_right_R8_Link" body2="hand_right_rh_index_proximal" />
    <exclude body1="arm_right_R8_Link" body2="hand_right_rh_index_middle" />
    <exclude body1="arm_right_R8_Link" body2="hand_right_rh_index_distal" />
    <exclude body1="arm_right_R8_Link" body2="hand_right_rh_middle_metacarpals" />
    <exclude body1="arm_right_R8_Link" body2="hand_right_rh_middle_proximal" />
    <exclude body1="arm_right_R8_Link" body2="hand_right_rh_middle_middle" />
    <exclude body1="arm_right_R8_Link" body2="hand_right_rh_middle_distal" />
    <exclude body1="arm_right_R8_Link" body2="hand_right_rh_ring_metacarpals" />
    <exclude body1="arm_right_R8_Link" body2="hand_right_rh_ring_proximal" />
    <exclude body1="arm_right_R8_Link" body2="hand_right_rh_ring_middle" />
    <exclude body1="arm_right_R8_Link" body2="hand_right_rh_ring_distal" />
    <exclude body1="arm_right_R8_Link" body2="hand_right_rh_pinky_metacarpals" />
    <exclude body1="arm_right_R8_Link" body2="hand_right_rh_pinky_proximal" />
    <exclude body1="arm_right_R8_Link" body2="hand_right_rh_pinky_middle" />
    <exclude body1="arm_right_R8_Link" body2="hand_right_rh_pinky_distal" />
    <exclude body1="base_base_link" body2="hand_right_rh_hand_base_link" />
    <exclude body1="base_base_link" body2="hand_right_rh_thumb_metacarpals_base1" />
    <exclude body1="base_base_link" body2="hand_right_rh_thumb_metacarpals_base2" />
    <exclude body1="base_base_link" body2="hand_right_rh_thumb_metacarpals" />
    <exclude body1="base_base_link" body2="hand_right_rh_thumb_proximal" />
    <exclude body1="base_base_link" body2="hand_right_rh_thumb_distal" />
    <exclude body1="base_base_link" body2="hand_right_rh_index_metacarpals" />
    <exclude body1="base_base_link" body2="hand_right_rh_index_proximal" />
    <exclude body1="base_base_link" body2="hand_right_rh_index_middle" />
    <exclude body1="base_base_link" body2="hand_right_rh_index_distal" />
    <exclude body1="base_base_link" body2="hand_right_rh_middle_metacarpals" />
    <exclude body1="base_base_link" body2="hand_right_rh_middle_proximal" />
    <exclude body1="base_base_link" body2="hand_right_rh_middle_middle" />
    <exclude body1="base_base_link" body2="hand_right_rh_middle_distal" />
    <exclude body1="base_base_link" body2="hand_right_rh_ring_metacarpals" />
    <exclude body1="base_base_link" body2="hand_right_rh_ring_proximal" />
    <exclude body1="base_base_link" body2="hand_right_rh_ring_middle" />
    <exclude body1="base_base_link" body2="hand_right_rh_ring_distal" />
    <exclude body1="base_base_link" body2="hand_right_rh_pinky_metacarpals" />
    <exclude body1="base_base_link" body2="hand_right_rh_pinky_proximal" />
    <exclude body1="base_base_link" body2="hand_right_rh_pinky_middle" />
    <exclude body1="base_base_link" body2="hand_right_rh_pinky_distal" />
  </contact>
</mujoco>
