<?xml version="1.0" encoding="UTF-8"?>
<!-- Generated by linker_robot_assets.composer (version 0.1.0). Workstation: ar5_08_o6_bench_bimanual. Recipe sha256: b812535ce3c2ba9ce7c00176edea7c9a29a3a23791fb8026d9149a95cbff53a9. Do not edit by hand; re-run `python -m linker_robot_assets.composer.compose <workstation>`. -->
<mujoco model="ar5_08_o6_bench_bimanual">
  <compiler discardvisual="false" autolimits="true" angle="radian" eulerseq="XYZ" />
  <option />
  <default>
    <default class="base_base_bench_table_visual">
      <geom type="mesh" contype="0" conaffinity="0" group="1" />
    </default>
    <default class="base_base_bench_table_collision">
      <geom type="mesh" contype="1" conaffinity="1" group="3" />
    </default>
    <default class="arm_left_arm_ar5_08_visual">
      <geom type="mesh" contype="0" conaffinity="0" group="1" />
    </default>
    <default class="arm_left_arm_ar5_08_collision">
      <geom type="mesh" contype="1" conaffinity="1" group="3" />
    </default>
    <default class="arm_right_arm_ar5_08_visual">
      <geom type="mesh" contype="0" conaffinity="0" group="1" />
    </default>
    <default class="arm_right_arm_ar5_08_collision">
      <geom type="mesh" contype="1" conaffinity="1" group="3" />
    </default>
    <default class="hand_left_hand_linkerhand_o6_visual">
      <geom type="mesh" contype="0" conaffinity="0" group="1" />
    </default>
    <default class="hand_left_hand_linkerhand_o6_collision">
      <geom type="mesh" contype="1" conaffinity="1" group="3" />
    </default>
    <default class="hand_left_hand_linkerhand_o6_joint">
      <joint armature="3.4707e-08" damping="4.0" frictionloss="0.5" />
    </default>
    <default class="hand_right_hand_linkerhand_o6_visual">
      <geom type="mesh" contype="0" conaffinity="0" group="1" />
    </default>
    <default class="hand_right_hand_linkerhand_o6_collision">
      <geom type="mesh" contype="1" conaffinity="1" group="3" />
    </default>
    <default class="hand_right_hand_linkerhand_o6_joint">
      <joint armature="3.4707e-08" damping="4.0" frictionloss="0.5" />
    </default>
  </default>
  <asset>
    <mesh name="base_workstation" file="../../components/bases/bench_table/variants/default/meshes/workstation.STL" />
    <mesh name="base_camera_base_link" file="../../components/bases/bench_table/variants/default/meshes/camera_base_link.STL" />
    <mesh name="base_camera" file="../../components/bases/bench_table/variants/default/meshes/camera.STL" />
    <mesh name="arm_left_ar5_08_base" file="../../components/arms/ar5_08/variants/left/meshes/AR5_5_08L_W4C4A6_base.STL" scale="0.001 0.001 0.001" />
    <mesh name="arm_left_ar5_08_link1" file="../../components/arms/ar5_08/variants/left/meshes/AR5_5_08L_W4C4A6_link1.STL" scale="0.001 0.001 0.001" />
    <mesh name="arm_left_ar5_08_link2" file="../../components/arms/ar5_08/variants/left/meshes/AR5_5_08L_W4C4A6_link2.STL" scale="0.001 0.001 0.001" />
    <mesh name="arm_left_ar5_08_link3" file="../../components/arms/ar5_08/variants/left/meshes/AR5_5_08L_W4C4A6_link3.STL" scale="0.001 0.001 0.001" />
    <mesh name="arm_left_ar5_08_link4" file="../../components/arms/ar5_08/variants/left/meshes/AR5_5_08L_W4C4A6_link4.STL" scale="0.001 0.001 0.001" />
    <mesh name="arm_left_ar5_08_link5" file="../../components/arms/ar5_08/variants/left/meshes/AR5_5_08L_W4C4A6_link5.STL" scale="0.001 0.001 0.001" />
    <mesh name="arm_left_ar5_08_link6" file="../../components/arms/ar5_08/variants/left/meshes/AR5_5_08L_W4C4A6_link6.STL" scale="0.001 0.001 0.001" />
    <mesh name="arm_left_ar5_08_link7" file="../../components/arms/ar5_08/variants/left/meshes/AR5_5_08L_W4C4A6_link7.STL" scale="0.001 0.001 0.001" />
    <mesh name="arm_right_ar5_08_base" file="../../components/arms/ar5_08/variants/right/meshes/AR5_5_08R_W4C4A6_base.STL" scale="0.001 0.001 0.001" />
    <mesh name="arm_right_ar5_08_link1" file="../../components/arms/ar5_08/variants/right/meshes/AR5_5_08R_W4C4A6_link1.STL" scale="0.001 0.001 0.001" />
    <mesh name="arm_right_ar5_08_link2" file="../../components/arms/ar5_08/variants/right/meshes/AR5_5_08R_W4C4A6_link2.STL" scale="0.001 0.001 0.001" />
    <mesh name="arm_right_ar5_08_link3" file="../../components/arms/ar5_08/variants/right/meshes/AR5_5_08R_W4C4A6_link3.STL" scale="0.001 0.001 0.001" />
    <mesh name="arm_right_ar5_08_link4" file="../../components/arms/ar5_08/variants/right/meshes/AR5_5_08R_W4C4A6_link4.STL" scale="0.001 0.001 0.001" />
    <mesh name="arm_right_ar5_08_link5" file="../../components/arms/ar5_08/variants/right/meshes/AR5_5_08R_W4C4A6_link5.STL" scale="0.001 0.001 0.001" />
    <mesh name="arm_right_ar5_08_link6" file="../../components/arms/ar5_08/variants/right/meshes/AR5_5_08R_W4C4A6_link6.STL" scale="0.001 0.001 0.001" />
    <mesh name="arm_right_ar5_08_link7" file="../../components/arms/ar5_08/variants/right/meshes/AR5_5_08R_W4C4A6_link7.STL" scale="0.001 0.001 0.001" />
    <mesh name="hand_left_hand_base" file="../../components/hands/linkerhand_o6/variants/left/meshes/hand_base_link.STL" />
    <mesh name="hand_left_thumb_metacarpals_base2" file="../../components/hands/linkerhand_o6/variants/left/meshes/thumb_metacarpals_base2.STL" />
    <mesh name="hand_left_thumb_metacarpals" file="../../components/hands/linkerhand_o6/variants/left/meshes/thumb_metacarpals.STL" />
    <mesh name="hand_left_thumb_distal" file="../../components/hands/linkerhand_o6/variants/left/meshes/thumb_distal.STL" />
    <mesh name="hand_left_index_proximal" file="../../components/hands/linkerhand_o6/variants/left/meshes/index_proximal.STL" />
    <mesh name="hand_left_index_distal" file="../../components/hands/linkerhand_o6/variants/left/meshes/index_distal.STL" />
    <mesh name="hand_left_middle_proximal" file="../../components/hands/linkerhand_o6/variants/left/meshes/middle_proximal.STL" />
    <mesh name="hand_left_middle_distal" file="../../components/hands/linkerhand_o6/variants/left/meshes/middle_distal.STL" />
    <mesh name="hand_left_ring_proximal" file="../../components/hands/linkerhand_o6/variants/left/meshes/ring_proximal.STL" />
    <mesh name="hand_left_ring_distal" file="../../components/hands/linkerhand_o6/variants/left/meshes/ring_distal.STL" />
    <mesh name="hand_left_pinky_proximal" file="../../components/hands/linkerhand_o6/variants/left/meshes/pinky_proximal.STL" />
    <mesh name="hand_left_pinky_distal" file="../../components/hands/linkerhand_o6/variants/left/meshes/pinky_distal.STL" />
    <mesh name="hand_right_hand_base" file="../../components/hands/linkerhand_o6/variants/right/meshes/hand_base_link.STL" />
    <mesh name="hand_right_thumb_metacarpals_base2" file="../../components/hands/linkerhand_o6/variants/right/meshes/thumb_metacarpals_base2.STL" />
    <mesh name="hand_right_thumb_metacarpals" file="../../components/hands/linkerhand_o6/variants/right/meshes/thumb_metacarpals.STL" />
    <mesh name="hand_right_thumb_distal" file="../../components/hands/linkerhand_o6/variants/right/meshes/thumb_distal.STL" />
    <mesh name="hand_right_index_proximal" file="../../components/hands/linkerhand_o6/variants/right/meshes/index_proximal.STL" />
    <mesh name="hand_right_index_distal" file="../../components/hands/linkerhand_o6/variants/right/meshes/index_distal.STL" />
    <mesh name="hand_right_middle_proximal" file="../../components/hands/linkerhand_o6/variants/right/meshes/middle_proximal.STL" />
    <mesh name="hand_right_middle_distal" file="../../components/hands/linkerhand_o6/variants/right/meshes/middle_distal.STL" />
    <mesh name="hand_right_ring_proximal" file="../../components/hands/linkerhand_o6/variants/right/meshes/ring_proximal.STL" />
    <mesh name="hand_right_ring_distal" file="../../components/hands/linkerhand_o6/variants/right/meshes/ring_distal.STL" />
    <mesh name="hand_right_pinky_proximal" file="../../components/hands/linkerhand_o6/variants/right/meshes/pinky_proximal.STL" />
    <mesh name="hand_right_pinky_distal" file="../../components/hands/linkerhand_o6/variants/right/meshes/pinky_distal.STL" />
  </asset>
  <worldbody>
    <body name="base_workstation_link" pos="0 0 0">
      <inertial pos="0 0 0" mass="50.0" fullinertia="1.0 1.0 1.0 0 0 0" />
      <geom class="base_base_bench_table_visual" mesh="base_workstation" />
      <geom class="base_base_bench_table_collision" mesh="base_workstation" />
      <body name="base_camera_base_link" pos="0.0335 0.67 1.2974" euler="-1.5708 0 -1.5708">
        <inertial pos="0.0538773695271655 0.0404431717089871 0.0338436903808578" mass="0.120253078965696" fullinertia="0.00024086634809874 0.000340317013404989 0.000187914824387855 1.11484097335586e-05 3.07915341770146e-05 -5.88336477049719e-05" />
        <geom class="base_base_bench_table_visual" mesh="base_camera_base_link" />
        <geom class="base_base_bench_table_collision" mesh="base_camera_base_link" />
        <site name="base_camera_mount" pos="0 0 0" />
        <body name="base_camera" pos="0.0801999999999972 0.193139853702623 -0.275851476149329" euler="-1.26599037580869 -0.643554017997773 -1.5707963267949">
          <inertial pos="0.435583906706681 -0.114517909806556 -0.00087379797028906" mass="0.170230158191785" fullinertia="0.000388607098441677 0.000353185511381015 6.42979907249093e-05 -3.21389374232659e-06 1.01075980515721e-06 -0.000100865226288639" />
          <geom class="base_base_bench_table_visual" mesh="base_camera" />
          <geom class="base_base_bench_table_collision" mesh="base_camera" />
        </body>
      </body>
      <body name="base_workstation_arm_left_mount" pos="0.0637 0.719 1.267" euler="0 1.57079633 1.57079633">
        <site name="base_arm_left_mount" pos="0 0 0" />
        <body name="arm_left_AR5_5_08L_W4C4A6_base" pos="0 0 0" euler="1.5708 0 -1.5708">
          <geom class="arm_left_arm_ar5_08_visual" mesh="arm_left_ar5_08_base" euler="-1.5708 0 0" />
          <geom class="arm_left_arm_ar5_08_collision" mesh="arm_left_ar5_08_base" euler="-1.5708 0 0" />
          <site name="arm_left_base_mount" pos="0 0 0" />
          <body name="arm_left_AR5_5_08L_W4C4A6_link1" pos="0 0 0">
            <inertial pos="1e-06 -0.000621 0.167909" mass="2.683" fullinertia="0.00493673 0.00452344 0.00432910 0.00000160 0.00000198 -0.00000020" />
            <joint name="arm_left_AR5_5_08L_W4C4A6_joint_1" type="hinge" axis="0 1 0" range="-3.1067 3.1067" damping="14.22378" frictionloss="0.0" armature="0.01" />
            <geom class="arm_left_arm_ar5_08_visual" mesh="arm_left_ar5_08_link1" euler="-1.5708 -1.5708 0" />
            <geom class="arm_left_arm_ar5_08_collision" mesh="arm_left_ar5_08_link1" euler="-1.5708 -1.5708 0" />
            <body name="arm_left_AR5_5_08L_W4C4A6_link2" pos="0 0.1745 0">
              <inertial pos="-2e-05 -0.003081 0.10298600000000001" mass="2.3" fullinertia="0.01151906 0.00993335 0.00435237 0.00000246 -0.00000055 0.00082477" />
              <joint name="arm_left_AR5_5_08L_W4C4A6_joint_2" type="hinge" axis="1 0 0" range="-0.5236 3.6652" damping="13.710972" frictionloss="0.0" armature="0.01" />
              <geom class="arm_left_arm_ar5_08_visual" mesh="arm_left_ar5_08_link2" euler="-3.1416 0 -1.5708" />
              <geom class="arm_left_arm_ar5_08_collision" mesh="arm_left_ar5_08_link2" euler="-3.1416 0 -1.5708" />
              <body name="arm_left_AR5_5_08L_W4C4A6_link3" pos="0 0 -0.332">
                <inertial pos="0.007097 -0.0006590000000000001 -0.016530999999999997" mass="1.862" fullinertia="0.00519681 0.00470446 0.00266752 0.00001208 0.00035761 0.00003430" />
                <joint name="arm_left_AR5_5_08L_W4C4A6_joint_3" type="hinge" axis="0 0 -1" range="-3.1067 3.1067" damping="3.791042" frictionloss="0.0" armature="0.01" />
                <geom class="arm_left_arm_ar5_08_visual" mesh="arm_left_ar5_08_link3" euler="0 -3.1416 3.1416" />
                <geom class="arm_left_arm_ar5_08_collision" mesh="arm_left_ar5_08_link3" euler="0 -3.1416 3.1416" />
                <body name="arm_left_AR5_5_08L_W4C4A6_link4" pos="0.0105 0 0">
                  <inertial pos="-0.007826 -0.004207 0.073404" mass="1.234" fullinertia="0.00389590 0.00308657 0.00188364 -0.00004577 -0.00017280 0.00046679" />
                  <joint name="arm_left_AR5_5_08L_W4C4A6_joint_4" type="hinge" axis="0 -1 0" range="-1.0472 2.5307" damping="0.333154" frictionloss="0.0" armature="0.01" />
                  <geom class="arm_left_arm_ar5_08_visual" mesh="arm_left_ar5_08_link4" euler="0 -3.1416 3.1416" />
                  <geom class="arm_left_arm_ar5_08_collision" mesh="arm_left_ar5_08_link4" euler="0 -3.1416 3.1416" />
                  <body name="arm_left_AR5_5_08L_W4C4A6_link5" pos="-0.0105 0 -0.278">
                    <inertial pos="0.00028399999999999996 0.0016510000000000001 -0.084133" mass="1.329" fullinertia="0.00281562 0.00221084 0.00182169 0.00001782 0.00001650 0.00002100" />
                    <joint name="arm_left_AR5_5_08L_W4C4A6_joint_5" type="hinge" axis="0 0 -1" range="-3.1067 3.1067" damping="4.136716" frictionloss="0.0" armature="0.01" />
                    <geom class="arm_left_arm_ar5_08_visual" mesh="arm_left_ar5_08_link5" euler="0 -3.1416 0" />
                    <geom class="arm_left_arm_ar5_08_collision" mesh="arm_left_ar5_08_link5" euler="0 -3.1416 0" />
                    <body name="arm_left_AR5_5_08L_W4C4A6_link6" pos="0 0 0">
                      <inertial pos="0.005405999999999999 0.000612 -3.9e-05" mass="0.93" fullinertia="0.00072078 0.00085153 0.00090205 -0.00000217 0.00000108 0.00000048" />
                      <joint name="arm_left_AR5_5_08L_W4C4A6_joint_6" type="hinge" axis="0 -1 0" range="-0.9599 0.9599" damping="4.748679" frictionloss="0.0" armature="0.01" />
                      <geom class="arm_left_arm_ar5_08_visual" mesh="arm_left_ar5_08_link6" euler="0 -3.1416 0" />
                      <geom class="arm_left_arm_ar5_08_collision" mesh="arm_left_ar5_08_link6" euler="0 -3.1416 0" />
                      <body name="arm_left_AR5_5_08L_W4C4A6_link7" pos="0 0 0">
                        <inertial pos="-0.00277 0.000316 0.054881" mass="0.33" fullinertia="0.00051942 0.00079132 0.00045886 -0.00000052 0.00003721 0.00000265" />
                        <joint name="arm_left_AR5_5_08L_W4C4A6_joint_7" type="hinge" axis="1 0 0" range="-0.9599 0.9599" damping="3.667978" frictionloss="0.0" armature="0.01" />
                        <geom class="arm_left_arm_ar5_08_visual" mesh="arm_left_ar5_08_link7" euler="0 -3.1416 0" />
                        <geom class="arm_left_arm_ar5_08_collision" mesh="arm_left_ar5_08_link7" euler="0 -3.1416 0" />
                        <body name="arm_left_AR5_5_08L_W4C4A6_tcp" pos="0 0 -0.09">
                          <site name="arm_left_tool0" pos="0 0 0" />
                          <body name="hand_left_lh_hand_base_link" pos="0 0 -0.038" euler="3.1416 0 -1.5708">
                            <inertial pos="-0.00157788568070457 -0.00034876725935859 0.0538452219801211" mass="0.0672935238166485" fullinertia="5.22525212160954E-05 3.33522349207724E-05 2.28469461105385E-05 3.06955729584715E-07 -3.90341166950521E-07 -7.76680063574627E-07" />
                            <geom class="hand_left_hand_linkerhand_o6_visual" mesh="hand_left_hand_base" />
                            <geom class="hand_left_hand_linkerhand_o6_collision" mesh="hand_left_hand_base" />
                            <site name="hand_left_wrist_mount" pos="0 0 0" />
                            <body name="hand_left_lh_thumb_metacarpals_base2" pos="0.011508 -0.022975 0.032794">
                              <inertial pos="0.00162800681276937 -0.0027668017246415 -0.00184234438641236" mass="0.00138588296544333" fullinertia="5.26292160685909E-08 4.82620491570326E-08 2.88550286112821E-08 -3.92888681640568E-09 -2.43767371295222E-09 3.71869784206147E-09" />
                              <joint name="hand_left_lh_thumb_cmc_yaw" class="hand_left_hand_linkerhand_o6_joint" type="hinge" axis="0 0 1" range="0 1.3" />
                              <geom class="hand_left_hand_linkerhand_o6_visual" mesh="hand_left_thumb_metacarpals_base2" />
                              <geom class="hand_left_hand_linkerhand_o6_collision" mesh="hand_left_thumb_metacarpals_base2" />
                              <body name="hand_left_lh_thumb_metacarpals" pos="0.0061649 -0.010678 -0.004891" euler="0 -1.1529 2.0944">
                                <inertial pos="4.24816204999817E-05 1.74183907812875E-05 0.0228341640631254" mass="0.0123381586619931" fullinertia="1.10292537368909E-06 1.76757772551884E-06 9.36347792411098E-07 -5.99642232777877E-10 -1.14233573940545E-07 -4.03963570823777E-10" />
                                <joint name="hand_left_lh_thumb_cmc_pitch" class="hand_left_hand_linkerhand_o6_joint" type="hinge" axis="0 1 0" range="0 0.58" />
                                <geom class="hand_left_hand_linkerhand_o6_visual" mesh="hand_left_thumb_metacarpals" />
                                <geom class="hand_left_hand_linkerhand_o6_collision" mesh="hand_left_thumb_metacarpals" />
                                <body name="hand_left_lh_thumb_distal" pos="0.0037776 0 0.045368">
                                  <inertial pos="-0.00413725702921841 -5.90704520436747E-08 0.023011401589736" mass="0.00763332957284057" fullinertia="1.3057487813702E-06 1.2248908905341E-06 2.77271910592615E-07 -1.19781508112714E-11 -7.19551697268541E-08 4.55347974652679E-12" />
                                  <joint name="hand_left_lh_thumb_ip" class="hand_left_hand_linkerhand_o6_joint" type="hinge" axis="0 1 0" range="0 1.08" />
                                  <geom class="hand_left_hand_linkerhand_o6_visual" mesh="hand_left_thumb_distal" />
                                  <geom class="hand_left_hand_linkerhand_o6_collision" mesh="hand_left_thumb_distal" />
                                </body>
                              </body>
                            </body>
                            <body name="hand_left_lh_index_proximal" pos="0.0024758 -0.02419 0.098779" euler="0.05236 0 0">
                              <inertial pos="-0.00208656556336452 2.53838713251686E-06 0.0172734941980264" mass="0.00253174651934627" fullinertia="2.65988714157799E-07 2.72914069166233E-07 8.56017305636748E-08 -1.67174578825824E-11 -4.31047725546034E-08 1.8756709532167E-10" />
                              <joint name="hand_left_lh_index_mcp_pitch" class="hand_left_hand_linkerhand_o6_joint" type="hinge" axis="0 1 0" range="0 1.60" />
                              <geom class="hand_left_hand_linkerhand_o6_visual" mesh="hand_left_index_proximal" />
                              <geom class="hand_left_hand_linkerhand_o6_collision" mesh="hand_left_index_proximal" />
                              <body name="hand_left_lh_index_distal" pos="-0.0052516 0 0.036625">
                                <inertial pos="0.00658986616416549 5.13855642059191E-06 0.0194393600039178" mass="0.00376951085886838" fullinertia="3.22347106085043E-07 3.65328133721509E-07 1.24287996386442E-07 1.3801788663582E-11 1.14352857317951E-07 -2.11505011705634E-10" />
                                <joint name="hand_left_lh_index_dip" class="hand_left_hand_linkerhand_o6_joint" type="hinge" axis="0 1 0" range="0 1.43" />
                                <geom class="hand_left_hand_linkerhand_o6_visual" mesh="hand_left_index_distal" />
                                <geom class="hand_left_hand_linkerhand_o6_collision" mesh="hand_left_index_distal" />
                              </body>
                            </body>
                            <body name="hand_left_lh_middle_proximal" pos="0.00052576 -0.00634 0.1027">
                              <inertial pos="-0.00208660654138235 2.56918180119303E-06 0.0172735011723351" mass="0.00253177375206983" fullinertia="2.65989021304483E-07 2.72914402745606E-07 8.5602213431865E-08 -1.69816046635662E-11 -4.31046683215273E-08 1.87484652324395E-10" />
                              <joint name="hand_left_lh_middle_mcp_pitch" class="hand_left_hand_linkerhand_o6_joint" type="hinge" axis="0 1 0" range="0 1.60" />
                              <geom class="hand_left_hand_linkerhand_o6_visual" mesh="hand_left_middle_proximal" />
                              <geom class="hand_left_hand_linkerhand_o6_collision" mesh="hand_left_middle_proximal" />
                              <body name="hand_left_lh_middle_distal" pos="-0.0052516 0 0.036625">
                                <inertial pos="0.00658986516319194 5.10862924271716E-06 0.0194393315699782" mass="0.00376952789210256" fullinertia="3.22348591068053E-07 3.65329535087755E-07 1.24288425862546E-07 1.37122394856588E-11 1.1435291391668E-07 -2.10453810291991E-10" />
                                <joint name="hand_left_lh_middle_dip" class="hand_left_hand_linkerhand_o6_joint" type="hinge" axis="0 1 0" range="0 1.43" />
                                <geom class="hand_left_hand_linkerhand_o6_visual" mesh="hand_left_middle_distal" />
                                <geom class="hand_left_hand_linkerhand_o6_collision" mesh="hand_left_middle_distal" />
                              </body>
                            </body>
                            <body name="hand_left_lh_ring_proximal" pos="0.0010258 0.011135 0.098767" euler="-0.05236 0 0">
                              <inertial pos="-0.00208667931345812 2.63000419462034E-06 0.0172734926448377" mass="0.00253182223645066" fullinertia="2.65989756076584E-07 2.7291510093393E-07 8.56031522765909E-08 -1.74912952703656E-11 -4.31043325594253E-08 1.87158326740895E-10" />
                              <joint name="hand_left_lh_ring_mcp_pitch" class="hand_left_hand_linkerhand_o6_joint" type="hinge" axis="0 1 0" range="0 1.60" />
                              <geom class="hand_left_hand_linkerhand_o6_visual" mesh="hand_left_ring_proximal" />
                              <geom class="hand_left_hand_linkerhand_o6_collision" mesh="hand_left_ring_proximal" />
                              <body name="hand_left_lh_ring_distal" pos="-0.0052516 0 0.036625">
                                <inertial pos="0.00658986648895491 5.05883528165163E-06 0.019439397215532" mass="0.00376949588316609" fullinertia="3.2234524157181E-07 3.65326570102147E-07 1.24287770218135E-07 1.35766976056011E-11 1.14353011012842E-07 -2.08672149138738E-10" />
                                <joint name="hand_left_lh_ring_dip" class="hand_left_hand_linkerhand_o6_joint" type="hinge" axis="0 1 0" range="0 1.43" />
                                <geom class="hand_left_hand_linkerhand_o6_visual" mesh="hand_left_ring_distal" />
                                <geom class="hand_left_hand_linkerhand_o6_collision" mesh="hand_left_ring_distal" />
                              </body>
                            </body>
                            <body name="hand_left_lh_pinky_proximal" pos="0.0024758 0.028372 0.092741" euler="-0.087266 0 0">
                              <inertial pos="-0.00208673599799501 2.68062251165824E-06 0.0172734848131236" mass="0.00253185993162408" fullinertia="2.6599033687183E-07 2.72915617381577E-07 8.56039175034871E-08 -1.79030790016555E-11 -4.31040829565781E-08 1.86906787420486E-10" />
                              <joint name="hand_left_lh_pinky_mcp_pitch" class="hand_left_hand_linkerhand_o6_joint" type="hinge" axis="0 1 0" range="0 1.60" />
                              <geom class="hand_left_hand_linkerhand_o6_visual" mesh="hand_left_pinky_proximal" />
                              <geom class="hand_left_hand_linkerhand_o6_collision" mesh="hand_left_pinky_proximal" />
                              <body name="hand_left_lh_pinky_distal" pos="-0.0052516 0 0.036625">
                                <inertial pos="0.00658987588903027 5.03087534178825E-06 0.0194394491065091" mass="0.00376948071276134" fullinertia="3.22343583730488E-07 3.65325180884183E-07 1.24287567374229E-07 1.35768173270357E-11 1.14353289593012E-07 -2.0744198062439E-10" />
                                <joint name="hand_left_lh_pinky_dip" class="hand_left_hand_linkerhand_o6_joint" type="hinge" axis="0 1 0" range="0 1.43" />
                                <geom class="hand_left_hand_linkerhand_o6_visual" mesh="hand_left_pinky_distal" />
                                <geom class="hand_left_hand_linkerhand_o6_collision" mesh="hand_left_pinky_distal" />
                              </body>
                            </body>
                          </body>
                        </body>
                      </body>
                    </body>
                  </body>
                </body>
              </body>
            </body>
          </body>
        </body>
      </body>
      <body name="base_workstation_arm_right_mount" pos="0.0637 0.536 1.267" euler="0 1.57079633 -1.57079633">
        <site name="base_arm_right_mount" pos="0 0 0" />
        <body name="arm_right_AR5_5_08R_W4C4A6_base" pos="0 0 0" euler="-1.5708 0 1.5708">
          <geom class="arm_right_arm_ar5_08_visual" mesh="arm_right_ar5_08_base" euler="1.5708 0 0" />
          <geom class="arm_right_arm_ar5_08_collision" mesh="arm_right_ar5_08_base" euler="1.5708 0 0" />
          <site name="arm_right_base_mount" pos="0 0 0" />
          <body name="arm_right_AR5_5_08R_W4C4A6_link1" pos="0 0 0">
            <inertial pos="1e-06 -0.000621 0.167909" mass="2.683" fullinertia="0.00493673 0.00452344 0.00432910 0.00000160 0.00000198 -0.00000020" />
            <joint name="arm_right_AR5_5_08R_W4C4A6_joint_1" type="hinge" axis="0 -1 0" range="-3.1067 3.1067" damping="14.22378" frictionloss="0.0" armature="0.01" />
            <geom class="arm_right_arm_ar5_08_visual" mesh="arm_right_ar5_08_link1" euler="1.5708 -1.5708 0" />
            <geom class="arm_right_arm_ar5_08_collision" mesh="arm_right_ar5_08_link1" euler="1.5708 -1.5708 0" />
            <body name="arm_right_AR5_5_08R_W4C4A6_link2" pos="0 -0.1745 0">
              <inertial pos="-2e-05 -0.003081 0.10298600000000001" mass="2.3" fullinertia="0.01151906 0.00993335 0.00435237 0.00000246 -0.00000055 0.00082477" />
              <joint name="arm_right_AR5_5_08R_W4C4A6_joint_2" type="hinge" axis="1 0 0" range="-3.6652 0.5236" damping="13.710972" frictionloss="0.0" armature="0.01" />
              <geom class="arm_right_arm_ar5_08_visual" mesh="arm_right_ar5_08_link2" euler="-3.1416 0 -1.5708" />
              <geom class="arm_right_arm_ar5_08_collision" mesh="arm_right_ar5_08_link2" euler="-3.1416 0 -1.5708" />
              <body name="arm_right_AR5_5_08R_W4C4A6_link3" pos="0 0 -0.332">
                <inertial pos="0.007097 -0.0006590000000000001 -0.016530999999999997" mass="1.862" fullinertia="0.00519681 0.00470446 0.00266752 0.00001208 0.00035761 0.00003430" />
                <joint name="arm_right_AR5_5_08R_W4C4A6_joint_3" type="hinge" axis="0 0 -1" range="-3.1067 3.1067" damping="3.791042" frictionloss="0.0" armature="0.01" />
                <geom class="arm_right_arm_ar5_08_visual" mesh="arm_right_ar5_08_link3" euler="0 -3.1416 3.1416" />
                <geom class="arm_right_arm_ar5_08_collision" mesh="arm_right_ar5_08_link3" euler="0 -3.1416 3.1416" />
                <body name="arm_right_AR5_5_08R_W4C4A6_link4" pos="0.0105 0 0">
                  <inertial pos="-0.007826 -0.004207 0.073404" mass="1.234" fullinertia="0.00389590 0.00308657 0.00188364 -0.00004577 -0.00017280 0.00046679" />
                  <joint name="arm_right_AR5_5_08R_W4C4A6_joint_4" type="hinge" axis="0 -1 0" range="-1.0472 2.5307" damping="0.333154" frictionloss="0.0" armature="0.01" />
                  <geom class="arm_right_arm_ar5_08_visual" mesh="arm_right_ar5_08_link4" euler="0 -3.1416 3.1416" />
                  <geom class="arm_right_arm_ar5_08_collision" mesh="arm_right_ar5_08_link4" euler="0 -3.1416 3.1416" />
                  <body name="arm_right_AR5_5_08R_W4C4A6_link5" pos="-0.0105 0 -0.278">
                    <inertial pos="0.00028399999999999996 0.0016510000000000001 -0.084133" mass="1.329" fullinertia="0.00281562 0.00221084 0.00182169 0.00001782 0.00001650 0.00002100" />
                    <joint name="arm_right_AR5_5_08R_W4C4A6_joint_5" type="hinge" axis="0 0 -1" range="-3.1067 3.1067" damping="4.136716" frictionloss="0.0" armature="0.01" />
                    <geom class="arm_right_arm_ar5_08_visual" mesh="arm_right_ar5_08_link5" euler="0 -3.1416 0" />
                    <geom class="arm_right_arm_ar5_08_collision" mesh="arm_right_ar5_08_link5" euler="0 -3.1416 0" />
                    <body name="arm_right_AR5_5_08R_W4C4A6_link6" pos="0 0 0">
                      <inertial pos="0.005405999999999999 0.000612 -3.9e-05" mass="0.93" fullinertia="0.00072078 0.00085153 0.00090205 -0.00000217 0.00000108 0.00000048" />
                      <joint name="arm_right_AR5_5_08R_W4C4A6_joint_6" type="hinge" axis="0 -1 0" range="-0.9599 0.9599" damping="4.748679" frictionloss="0.0" armature="0.01" />
                      <geom class="arm_right_arm_ar5_08_visual" mesh="arm_right_ar5_08_link6" euler="0 -3.1416 0" />
                      <geom class="arm_right_arm_ar5_08_collision" mesh="arm_right_ar5_08_link6" euler="0 -3.1416 0" />
                      <body name="arm_right_AR5_5_08R_W4C4A6_link7" pos="0 0 0">
                        <inertial pos="-0.00277 0.000316 0.054881" mass="0.33" fullinertia="0.00051942 0.00079132 0.00045886 -0.00000052 0.00003721 0.00000265" />
                        <joint name="arm_right_AR5_5_08R_W4C4A6_joint_7" type="hinge" axis="1 0 0" range="-0.9599 0.9599" damping="3.667978" frictionloss="0.0" armature="0.01" />
                        <geom class="arm_right_arm_ar5_08_visual" mesh="arm_right_ar5_08_link7" euler="0 -3.1416 0" />
                        <geom class="arm_right_arm_ar5_08_collision" mesh="arm_right_ar5_08_link7" euler="0 -3.1416 0" />
                        <body name="arm_right_AR5_5_08R_W4C4A6_tcp" pos="0 0 -0.09">
                          <site name="arm_right_tool0" pos="0 0 0" />
                          <body name="hand_right_rh_hand_base_link" pos="0 0 -0.038" euler="3.1416 0 1.5708">
                            <inertial pos="-0.00160320773490556 0.000358462699237561 0.0538002704027215" mass="0.06740077960995" fullinertia="5.22359941041901E-05 3.33473043513648E-05 2.28342677422006E-05 3.0391535852764E-07 3.88322215371643E-07 -7.77555280794861E-07" />
                            <geom class="hand_right_hand_linkerhand_o6_visual" mesh="hand_right_hand_base" />
                            <geom class="hand_right_hand_linkerhand_o6_collision" mesh="hand_right_hand_base" />
                            <site name="hand_right_wrist_mount" pos="0 0 0" />
                            <body name="hand_right_rh_thumb_metacarpals_base2" pos="0.011508 0.022975 0.032794">
                              <inertial pos="0.00162795738393507 0.00276671978336815 -0.00184227725602707" mass="0.00138591070212997" fullinertia="5.26294625624223E-08 4.82623724532942E-08 2.88555522060562E-08 -3.9288013799604E-09 2.43766268199571E-09 3.71867754115443E-09" />
                              <joint name="hand_right_rh_thumb_cmc_yaw" class="hand_right_hand_linkerhand_o6_joint" type="hinge" axis="0 0 -1" range="0 1.36" />
                              <geom class="hand_right_hand_linkerhand_o6_visual" mesh="hand_right_thumb_metacarpals_base2" />
                              <geom class="hand_right_hand_linkerhand_o6_collision" mesh="hand_right_thumb_metacarpals_base2" />
                              <body name="hand_right_rh_thumb_metacarpals" pos="0.0061649 0.010678 -0.004891" euler="0 -1.1529 -2.0944">
                                <inertial pos="4.24920612856275E-05 -1.67885666835232E-05 0.0228341522590467" mass="0.0123381607727595" fullinertia="1.10292488693766E-06 1.76757658485787E-06 9.36348143657406E-07 -6.14241939151719E-10 1.14233108676795E-07 -4.24576599367025E-10" />
                                <joint name="hand_right_rh_thumb_cmc_pitch" class="hand_right_hand_linkerhand_o6_joint" type="hinge" axis="0 1 0" range="0 0.58" />
                                <geom class="hand_right_hand_linkerhand_o6_visual" mesh="hand_right_thumb_metacarpals" />
                                <geom class="hand_right_hand_linkerhand_o6_collision" mesh="hand_right_thumb_metacarpals" />
                                <body name="hand_right_rh_thumb_distal" pos="0.0037776 0 0.045368">
                                  <inertial pos="-0.00413690727496815 -4.54842793429222E-07 0.0230097179163771" mass="0.00763302603723749" fullinertia="1.30546842791578E-06 1.22457212713176E-06 2.7729897944409E-07 -2.61617511029467E-12 7.19030685242407E-08 1.66931068485225E-11" />
                                  <joint name="hand_right_rh_thumb_ip" class="hand_right_hand_linkerhand_o6_joint" type="hinge" axis="0 1 0" range="0 1.08" />
                                  <geom class="hand_right_hand_linkerhand_o6_visual" mesh="hand_right_thumb_distal" />
                                  <geom class="hand_right_hand_linkerhand_o6_collision" mesh="hand_right_thumb_distal" />
                                </body>
                              </body>
                            </body>
                            <body name="hand_right_rh_index_proximal" pos="0.0024758 0.02419 0.098779" euler="-0.05236 0 0">
                              <inertial pos="-0.00208665596033792 -4.8964990644329E-06 0.0172736718900068" mass="0.00253178529301663" fullinertia="2.65990159539482E-07 2.72915460277804E-07 8.56026306687528E-08 -3.55165625722842E-11 4.31046335852167E-08 1.75935978708959E-10" />
                              <joint name="hand_right_rh_index_mcp_pitch" class="hand_right_hand_linkerhand_o6_joint" type="hinge" axis="0 1 0" range="0 1.60" />
                              <geom class="hand_right_hand_linkerhand_o6_visual" mesh="hand_right_index_proximal" />
                              <geom class="hand_right_hand_linkerhand_o6_collision" mesh="hand_right_index_proximal" />
                              <body name="hand_right_rh_index_distal" pos="-0.0052516 0 0.036625">
                                <inertial pos="0.00658940011630532 -4.59976557022623E-06 0.0194434136420913" mass="0.00376787129082313" fullinertia="3.22116619426455E-07 3.65131844686317E-07 1.24256890612907E-07 1.03152735699049E-11 -1.14363506430985E-07 -1.97263639269362E-10" />
                                <joint name="hand_right_rh_index_dip" class="hand_right_hand_linkerhand_o6_joint" type="hinge" axis="0 1 0" range="0 1.43" />
                                <geom class="hand_right_hand_linkerhand_o6_visual" mesh="hand_right_index_distal" />
                                <geom class="hand_right_hand_linkerhand_o6_collision" mesh="hand_right_index_distal" />
                              </body>
                            </body>
                            <body name="hand_right_rh_middle_proximal" pos="0.00052576 0.00634 0.1027">
                              <inertial pos="-0.00208661081773556 -4.93451838476378E-06 0.0172736805321904" mass="0.00253175497594429" fullinertia="2.65989683690695E-07 2.72915006047006E-07 8.56020467202518E-08 -3.58343951791586E-11 4.31048601085216E-08 1.75718024412593E-10" />
                              <joint name="hand_right_rh_middle_mcp_pitch" class="hand_right_hand_linkerhand_o6_joint" type="hinge" axis="0 1 0" range="0 1.60" />
                              <geom class="hand_right_hand_linkerhand_o6_visual" mesh="hand_right_middle_proximal" />
                              <geom class="hand_right_hand_linkerhand_o6_collision" mesh="hand_right_middle_proximal" />
                              <body name="hand_right_rh_middle_distal" pos="-0.0052516 0 0.036625">
                                <inertial pos="0.00658940304809306 -4.5885743593238E-06 0.0194434523296449" mass="0.00376786259758948" fullinertia="3.221153658306E-07 3.65130723083104E-07 1.24256787913797E-07 1.02639617308432E-11 -1.14363547272711E-07 -1.96904618797577E-10" />
                                <joint name="hand_right_rh_middle_dip" class="hand_right_hand_linkerhand_o6_joint" type="hinge" axis="0 1 0" range="0 1.43" />
                                <geom class="hand_right_hand_linkerhand_o6_visual" mesh="hand_right_middle_distal" />
                                <geom class="hand_right_hand_linkerhand_o6_collision" mesh="hand_right_middle_distal" />
                              </body>
                            </body>
                            <body name="hand_right_rh_ring_proximal" pos="0.0010258 -0.011135 0.098767" euler="0.05236 0 0">
                              <inertial pos="-0.00208654311325356 -4.98538564003281E-06 0.0172736743497407" mass="0.00253170963529411" fullinertia="2.6598913795678E-07 2.72914417061517E-07 8.56012458677515E-08 -3.62757108675266E-11 4.31050611555507E-08 1.75554984053478E-10" />
                              <joint name="hand_right_rh_ring_mcp_pitch" class="hand_right_hand_linkerhand_o6_joint" type="hinge" axis="0 1 0" range="0 1.60" />
                              <geom class="hand_right_hand_linkerhand_o6_visual" mesh="hand_right_ring_proximal" />
                              <geom class="hand_right_hand_linkerhand_o6_collision" mesh="hand_right_ring_proximal" />
                              <body name="hand_right_rh_ring_distal" pos="-0.0052516 0 0.036625">
                                <inertial pos="0.00658940273069729 -4.56628863591824E-06 0.0194435005686854" mass="0.0037678395356105" fullinertia="3.22112632437858E-07 3.65128262095686E-07 1.24256284608064E-07 1.01848408913558E-11 -1.1436348915342E-07 -1.96145632992445E-10" />
                                <joint name="hand_right_rh_ring_dip" class="hand_right_hand_linkerhand_o6_joint" type="hinge" axis="0 1 0" range="0 1.43" />
                                <geom class="hand_right_hand_linkerhand_o6_visual" mesh="hand_right_ring_distal" />
                                <geom class="hand_right_hand_linkerhand_o6_collision" mesh="hand_right_ring_distal" />
                              </body>
                            </body>
                            <body name="hand_right_rh_pinky_proximal" pos="0.0024758 -0.028372 0.092741" euler="0.087266 0 0">
                              <inertial pos="-0.00208649034130813 -5.02314582560837E-06 0.0172736680793697" mass="0.00253167400540778" fullinertia="2.65988718820404E-07 2.72913936904813E-07 8.56006424720129E-08 -3.66012295280295E-11 4.31052220484445E-08 1.75447396222308E-10" />
                              <joint name="hand_right_rh_pinky_mcp_pitch" class="hand_right_hand_linkerhand_o6_joint" type="hinge" axis="0 1 0" range="0 1.60" />
                              <geom class="hand_right_hand_linkerhand_o6_visual" mesh="hand_right_pinky_proximal" />
                              <geom class="hand_right_hand_linkerhand_o6_collision" mesh="hand_right_pinky_proximal" />
                              <body name="hand_right_rh_pinky_distal" pos="-0.0052516 0 0.036625">
                                <inertial pos="0.00658940431519205 -4.55268314210333E-06 0.0194435341098305" mass="0.00376782669873412" fullinertia="3.22111112339498E-07 3.65126916899176E-07 1.24256004854426E-07 1.01707985908333E-11 -1.14363524419061E-07 -1.95589215866356E-10" />
                                <joint name="hand_right_rh_pinky_dip" class="hand_right_hand_linkerhand_o6_joint" type="hinge" axis="0 1 0" range="0 1.43" />
                                <geom class="hand_right_hand_linkerhand_o6_visual" mesh="hand_right_pinky_distal" />
                                <geom class="hand_right_hand_linkerhand_o6_collision" mesh="hand_right_pinky_distal" />
                              </body>
                            </body>
                          </body>
                        </body>
                      </body>
                    </body>
                  </body>
                </body>
              </body>
            </body>
          </body>
        </body>
      </body>
    </body>
  </worldbody>
  <actuator>
    <position name="arm_left_AR5_5_08L_W4C4A6_joint_1_act" joint="arm_left_AR5_5_08L_W4C4A6_joint_1" kp="1000" kv="4" ctrlrange="-3.1067 3.1067" />
    <position name="arm_left_AR5_5_08L_W4C4A6_joint_2_act" joint="arm_left_AR5_5_08L_W4C4A6_joint_2" kp="1000" kv="4" ctrlrange="-0.5236 3.6652" />
    <position name="arm_left_AR5_5_08L_W4C4A6_joint_3_act" joint="arm_left_AR5_5_08L_W4C4A6_joint_3" kp="1000" kv="4" ctrlrange="-3.1067 3.1067" />
    <position name="arm_left_AR5_5_08L_W4C4A6_joint_4_act" joint="arm_left_AR5_5_08L_W4C4A6_joint_4" kp="1000" kv="4" ctrlrange="-1.0472 2.5307" />
    <position name="arm_left_AR5_5_08L_W4C4A6_joint_5_act" joint="arm_left_AR5_5_08L_W4C4A6_joint_5" kp="1000" kv="4" ctrlrange="-3.1067 3.1067" />
    <position name="arm_left_AR5_5_08L_W4C4A6_joint_6_act" joint="arm_left_AR5_5_08L_W4C4A6_joint_6" kp="1000" kv="4" ctrlrange="-0.9599 0.9599" />
    <position name="arm_left_AR5_5_08L_W4C4A6_joint_7_act" joint="arm_left_AR5_5_08L_W4C4A6_joint_7" kp="1000" kv="4" ctrlrange="-0.9599 0.9599" />
    <position name="arm_right_AR5_5_08R_W4C4A6_joint_1_act" joint="arm_right_AR5_5_08R_W4C4A6_joint_1" kp="1000" kv="4" ctrlrange="-3.1067 3.1067" />
    <position name="arm_right_AR5_5_08R_W4C4A6_joint_2_act" joint="arm_right_AR5_5_08R_W4C4A6_joint_2" kp="1000" kv="4" ctrlrange="-3.6652 0.5236" />
    <position name="arm_right_AR5_5_08R_W4C4A6_joint_3_act" joint="arm_right_AR5_5_08R_W4C4A6_joint_3" kp="1000" kv="4" ctrlrange="-3.1067 3.1067" />
    <position name="arm_right_AR5_5_08R_W4C4A6_joint_4_act" joint="arm_right_AR5_5_08R_W4C4A6_joint_4" kp="1000" kv="4" ctrlrange="-1.0472 2.5307" />
    <position name="arm_right_AR5_5_08R_W4C4A6_joint_5_act" joint="arm_right_AR5_5_08R_W4C4A6_joint_5" kp="1000" kv="4" ctrlrange="-3.1067 3.1067" />
    <position name="arm_right_AR5_5_08R_W4C4A6_joint_6_act" joint="arm_right_AR5_5_08R_W4C4A6_joint_6" kp="1000" kv="4" ctrlrange="-0.9599 0.9599" />
    <position name="arm_right_AR5_5_08R_W4C4A6_joint_7_act" joint="arm_right_AR5_5_08R_W4C4A6_joint_7" kp="1000" kv="4" ctrlrange="-0.9599 0.9599" />
    <position name="hand_left_lh_thumb_cmc_yaw_act" joint="hand_left_lh_thumb_cmc_yaw" kp="200" kv="0" ctrlrange="0 1.3" />
    <position name="hand_left_lh_thumb_cmc_pitch_act" joint="hand_left_lh_thumb_cmc_pitch" kp="200" kv="0" ctrlrange="0 0.58" />
    <position name="hand_left_lh_index_mcp_pitch_act" joint="hand_left_lh_index_mcp_pitch" kp="200" kv="0" ctrlrange="0 1.60" />
    <position name="hand_left_lh_middle_mcp_pitch_act" joint="hand_left_lh_middle_mcp_pitch" kp="200" kv="0" ctrlrange="0 1.60" />
    <position name="hand_left_lh_ring_mcp_pitch_act" joint="hand_left_lh_ring_mcp_pitch" kp="200" kv="0" ctrlrange="0 1.60" />
    <position name="hand_left_lh_pinky_mcp_pitch_act" joint="hand_left_lh_pinky_mcp_pitch" kp="200" kv="0" ctrlrange="0 1.60" />
    <position name="hand_right_rh_thumb_cmc_yaw_act" joint="hand_right_rh_thumb_cmc_yaw" kp="200" kv="0" ctrlrange="0 1.36" />
    <position name="hand_right_rh_thumb_cmc_pitch_act" joint="hand_right_rh_thumb_cmc_pitch" kp="200" kv="0" ctrlrange="0 0.58" />
    <position name="hand_right_rh_index_mcp_pitch_act" joint="hand_right_rh_index_mcp_pitch" kp="200" kv="0" ctrlrange="0 1.60" />
    <position name="hand_right_rh_middle_mcp_pitch_act" joint="hand_right_rh_middle_mcp_pitch" kp="200" kv="0" ctrlrange="0 1.60" />
    <position name="hand_right_rh_ring_mcp_pitch_act" joint="hand_right_rh_ring_mcp_pitch" kp="200" kv="0" ctrlrange="0 1.60" />
    <position name="hand_right_rh_pinky_mcp_pitch_act" joint="hand_right_rh_pinky_mcp_pitch" kp="200" kv="0" ctrlrange="0 1.60" />
  </actuator>
  <equality>
    <joint name="hand_left_lh_couple_thumb" joint1="hand_left_lh_thumb_ip" joint2="hand_left_lh_thumb_cmc_pitch" polycoef="0 2.29 0 0 0" />
    <joint name="hand_left_lh_couple_index" joint1="hand_left_lh_index_dip" joint2="hand_left_lh_index_mcp_pitch" polycoef="0 0.89 0 0 0" />
    <joint name="hand_left_lh_couple_middle" joint1="hand_left_lh_middle_dip" joint2="hand_left_lh_middle_mcp_pitch" polycoef="0 0.89 0 0 0" />
    <joint name="hand_left_lh_couple_ring" joint1="hand_left_lh_ring_dip" joint2="hand_left_lh_ring_mcp_pitch" polycoef="0 0.89 0 0 0" />
    <joint name="hand_left_lh_couple_pinky" joint1="hand_left_lh_pinky_dip" joint2="hand_left_lh_pinky_mcp_pitch" polycoef="0 0.89 0 0 0" />
    <joint name="hand_right_rh_couple_thumb" joint1="hand_right_rh_thumb_ip" joint2="hand_right_rh_thumb_cmc_pitch" polycoef="0 1.86 0 0 0" />
    <joint name="hand_right_rh_couple_index" joint1="hand_right_rh_index_dip" joint2="hand_right_rh_index_mcp_pitch" polycoef="0 0.89 0 0 0" />
    <joint name="hand_right_rh_couple_middle" joint1="hand_right_rh_middle_dip" joint2="hand_right_rh_middle_mcp_pitch" polycoef="0 0.89 0 0 0" />
    <joint name="hand_right_rh_couple_ring" joint1="hand_right_rh_ring_dip" joint2="hand_right_rh_ring_mcp_pitch" polycoef="0 0.89 0 0 0" />
    <joint name="hand_right_rh_couple_pinky" joint1="hand_right_rh_pinky_dip" joint2="hand_right_rh_pinky_mcp_pitch" polycoef="0 0.89 0 0 0" />
  </equality>
  <contact>
    <exclude body1="arm_left_AR5_5_08L_W4C4A6_base" body2="arm_left_AR5_5_08L_W4C4A6_link1" />
    <exclude body1="arm_left_AR5_5_08L_W4C4A6_link1" body2="arm_left_AR5_5_08L_W4C4A6_link2" />
    <exclude body1="arm_left_AR5_5_08L_W4C4A6_link2" body2="arm_left_AR5_5_08L_W4C4A6_link3" />
    <exclude body1="arm_left_AR5_5_08L_W4C4A6_link3" body2="arm_left_AR5_5_08L_W4C4A6_link4" />
    <exclude body1="arm_left_AR5_5_08L_W4C4A6_link4" body2="arm_left_AR5_5_08L_W4C4A6_link5" />
    <exclude body1="arm_left_AR5_5_08L_W4C4A6_link5" body2="arm_left_AR5_5_08L_W4C4A6_link6" />
    <exclude body1="arm_left_AR5_5_08L_W4C4A6_link6" body2="arm_left_AR5_5_08L_W4C4A6_link7" />
    <exclude body1="arm_left_AR5_5_08L_W4C4A6_link5" body2="arm_left_AR5_5_08L_W4C4A6_link7" />
    <exclude body1="arm_right_AR5_5_08R_W4C4A6_base" body2="arm_right_AR5_5_08R_W4C4A6_link1" />
    <exclude body1="arm_right_AR5_5_08R_W4C4A6_link1" body2="arm_right_AR5_5_08R_W4C4A6_link2" />
    <exclude body1="arm_right_AR5_5_08R_W4C4A6_link2" body2="arm_right_AR5_5_08R_W4C4A6_link3" />
    <exclude body1="arm_right_AR5_5_08R_W4C4A6_link3" body2="arm_right_AR5_5_08R_W4C4A6_link4" />
    <exclude body1="arm_right_AR5_5_08R_W4C4A6_link4" body2="arm_right_AR5_5_08R_W4C4A6_link5" />
    <exclude body1="arm_right_AR5_5_08R_W4C4A6_link5" body2="arm_right_AR5_5_08R_W4C4A6_link6" />
    <exclude body1="arm_right_AR5_5_08R_W4C4A6_link6" body2="arm_right_AR5_5_08R_W4C4A6_link7" />
    <exclude body1="arm_right_AR5_5_08R_W4C4A6_link5" body2="arm_right_AR5_5_08R_W4C4A6_link7" />
    <exclude body1="hand_left_lh_hand_base_link" body2="hand_left_lh_thumb_metacarpals_base2" />
    <exclude body1="hand_left_lh_thumb_metacarpals_base2" body2="hand_left_lh_thumb_metacarpals" />
    <exclude body1="hand_left_lh_thumb_metacarpals" body2="hand_left_lh_thumb_distal" />
    <exclude body1="hand_left_lh_hand_base_link" body2="hand_left_lh_index_proximal" />
    <exclude body1="hand_left_lh_index_proximal" body2="hand_left_lh_index_distal" />
    <exclude body1="hand_left_lh_hand_base_link" body2="hand_left_lh_middle_proximal" />
    <exclude body1="hand_left_lh_middle_proximal" body2="hand_left_lh_middle_distal" />
    <exclude body1="hand_left_lh_hand_base_link" body2="hand_left_lh_ring_proximal" />
    <exclude body1="hand_left_lh_ring_proximal" body2="hand_left_lh_ring_distal" />
    <exclude body1="hand_left_lh_hand_base_link" body2="hand_left_lh_pinky_proximal" />
    <exclude body1="hand_left_lh_pinky_proximal" body2="hand_left_lh_pinky_distal" />
    <exclude body1="hand_right_rh_hand_base_link" body2="hand_right_rh_thumb_metacarpals_base2" />
    <exclude body1="hand_right_rh_thumb_metacarpals_base2" body2="hand_right_rh_thumb_metacarpals" />
    <exclude body1="hand_right_rh_thumb_metacarpals" body2="hand_right_rh_thumb_distal" />
    <exclude body1="hand_right_rh_hand_base_link" body2="hand_right_rh_index_proximal" />
    <exclude body1="hand_right_rh_index_proximal" body2="hand_right_rh_index_distal" />
    <exclude body1="hand_right_rh_hand_base_link" body2="hand_right_rh_middle_proximal" />
    <exclude body1="hand_right_rh_middle_proximal" body2="hand_right_rh_middle_distal" />
    <exclude body1="hand_right_rh_hand_base_link" body2="hand_right_rh_ring_proximal" />
    <exclude body1="hand_right_rh_ring_proximal" body2="hand_right_rh_ring_distal" />
    <exclude body1="hand_right_rh_hand_base_link" body2="hand_right_rh_pinky_proximal" />
    <exclude body1="hand_right_rh_pinky_proximal" body2="hand_right_rh_pinky_distal" />
    <exclude body1="base_workstation_link" body2="arm_left_AR5_5_08L_W4C4A6_base" />
    <exclude body1="base_workstation_link" body2="arm_left_AR5_5_08L_W4C4A6_link1" />
    <exclude body1="base_workstation_link" body2="arm_left_AR5_5_08L_W4C4A6_link2" />
    <exclude body1="base_workstation_link" body2="arm_left_AR5_5_08L_W4C4A6_link3" />
    <exclude body1="base_workstation_link" body2="arm_left_AR5_5_08L_W4C4A6_link4" />
    <exclude body1="base_workstation_link" body2="arm_left_AR5_5_08L_W4C4A6_link5" />
    <exclude body1="base_workstation_link" body2="arm_left_AR5_5_08L_W4C4A6_link6" />
    <exclude body1="base_workstation_link" body2="arm_left_AR5_5_08L_W4C4A6_link7" />
    <exclude body1="base_camera_base_link" body2="arm_left_AR5_5_08L_W4C4A6_base" />
    <exclude body1="base_camera_base_link" body2="arm_left_AR5_5_08L_W4C4A6_link1" />
    <exclude body1="base_camera_base_link" body2="arm_left_AR5_5_08L_W4C4A6_link2" />
    <exclude body1="base_camera_base_link" body2="arm_left_AR5_5_08L_W4C4A6_link3" />
    <exclude body1="base_camera_base_link" body2="arm_left_AR5_5_08L_W4C4A6_link4" />
    <exclude body1="base_camera_base_link" body2="arm_left_AR5_5_08L_W4C4A6_link5" />
    <exclude body1="base_camera_base_link" body2="arm_left_AR5_5_08L_W4C4A6_link6" />
    <exclude body1="base_camera_base_link" body2="arm_left_AR5_5_08L_W4C4A6_link7" />
    <exclude body1="base_camera" body2="arm_left_AR5_5_08L_W4C4A6_base" />
    <exclude body1="base_camera" body2="arm_left_AR5_5_08L_W4C4A6_link1" />
    <exclude body1="base_camera" body2="arm_left_AR5_5_08L_W4C4A6_link2" />
    <exclude body1="base_camera" body2="arm_left_AR5_5_08L_W4C4A6_link3" />
    <exclude body1="base_camera" body2="arm_left_AR5_5_08L_W4C4A6_link4" />
    <exclude body1="base_camera" body2="arm_left_AR5_5_08L_W4C4A6_link5" />
    <exclude body1="base_camera" body2="arm_left_AR5_5_08L_W4C4A6_link6" />
    <exclude body1="base_camera" body2="arm_left_AR5_5_08L_W4C4A6_link7" />
    <exclude body1="base_workstation_link" body2="arm_right_AR5_5_08R_W4C4A6_base" />
    <exclude body1="base_workstation_link" body2="arm_right_AR5_5_08R_W4C4A6_link1" />
    <exclude body1="base_workstation_link" body2="arm_right_AR5_5_08R_W4C4A6_link2" />
    <exclude body1="base_workstation_link" body2="arm_right_AR5_5_08R_W4C4A6_link3" />
    <exclude body1="base_workstation_link" body2="arm_right_AR5_5_08R_W4C4A6_link4" />
    <exclude body1="base_workstation_link" body2="arm_right_AR5_5_08R_W4C4A6_link5" />
    <exclude body1="base_workstation_link" body2="arm_right_AR5_5_08R_W4C4A6_link6" />
    <exclude body1="base_workstation_link" body2="arm_right_AR5_5_08R_W4C4A6_link7" />
    <exclude body1="base_camera_base_link" body2="arm_right_AR5_5_08R_W4C4A6_base" />
    <exclude body1="base_camera_base_link" body2="arm_right_AR5_5_08R_W4C4A6_link1" />
    <exclude body1="base_camera_base_link" body2="arm_right_AR5_5_08R_W4C4A6_link2" />
    <exclude body1="base_camera_base_link" body2="arm_right_AR5_5_08R_W4C4A6_link3" />
    <exclude body1="base_camera_base_link" body2="arm_right_AR5_5_08R_W4C4A6_link4" />
    <exclude body1="base_camera_base_link" body2="arm_right_AR5_5_08R_W4C4A6_link5" />
    <exclude body1="base_camera_base_link" body2="arm_right_AR5_5_08R_W4C4A6_link6" />
    <exclude body1="base_camera_base_link" body2="arm_right_AR5_5_08R_W4C4A6_link7" />
    <exclude body1="base_camera" body2="arm_right_AR5_5_08R_W4C4A6_base" />
    <exclude body1="base_camera" body2="arm_right_AR5_5_08R_W4C4A6_link1" />
    <exclude body1="base_camera" body2="arm_right_AR5_5_08R_W4C4A6_link2" />
    <exclude body1="base_camera" body2="arm_right_AR5_5_08R_W4C4A6_link3" />
    <exclude body1="base_camera" body2="arm_right_AR5_5_08R_W4C4A6_link4" />
    <exclude body1="base_camera" body2="arm_right_AR5_5_08R_W4C4A6_link5" />
    <exclude body1="base_camera" body2="arm_right_AR5_5_08R_W4C4A6_link6" />
    <exclude body1="base_camera" body2="arm_right_AR5_5_08R_W4C4A6_link7" />
    <exclude body1="arm_left_AR5_5_08L_W4C4A6_base" body2="hand_left_lh_hand_base_link" />
    <exclude body1="arm_left_AR5_5_08L_W4C4A6_base" body2="hand_left_lh_thumb_metacarpals_base2" />
    <exclude body1="arm_left_AR5_5_08L_W4C4A6_base" body2="hand_left_lh_thumb_metacarpals" />
    <exclude body1="arm_left_AR5_5_08L_W4C4A6_base" body2="hand_left_lh_thumb_distal" />
    <exclude body1="arm_left_AR5_5_08L_W4C4A6_base" body2="hand_left_lh_index_proximal" />
    <exclude body1="arm_left_AR5_5_08L_W4C4A6_base" body2="hand_left_lh_index_distal" />
    <exclude body1="arm_left_AR5_5_08L_W4C4A6_base" body2="hand_left_lh_middle_proximal" />
    <exclude body1="arm_left_AR5_5_08L_W4C4A6_base" body2="hand_left_lh_middle_distal" />
    <exclude body1="arm_left_AR5_5_08L_W4C4A6_base" body2="hand_left_lh_ring_proximal" />
    <exclude body1="arm_left_AR5_5_08L_W4C4A6_base" body2="hand_left_lh_ring_distal" />
    <exclude body1="arm_left_AR5_5_08L_W4C4A6_base" body2="hand_left_lh_pinky_proximal" />
    <exclude body1="arm_left_AR5_5_08L_W4C4A6_base" body2="hand_left_lh_pinky_distal" />
    <exclude body1="arm_left_AR5_5_08L_W4C4A6_link1" body2="hand_left_lh_hand_base_link" />
    <exclude body1="arm_left_AR5_5_08L_W4C4A6_link1" body2="hand_left_lh_thumb_metacarpals_base2" />
    <exclude body1="arm_left_AR5_5_08L_W4C4A6_link1" body2="hand_left_lh_thumb_metacarpals" />
    <exclude body1="arm_left_AR5_5_08L_W4C4A6_link1" body2="hand_left_lh_thumb_distal" />
    <exclude body1="arm_left_AR5_5_08L_W4C4A6_link1" body2="hand_left_lh_index_proximal" />
    <exclude body1="arm_left_AR5_5_08L_W4C4A6_link1" body2="hand_left_lh_index_distal" />
    <exclude body1="arm_left_AR5_5_08L_W4C4A6_link1" body2="hand_left_lh_middle_proximal" />
    <exclude body1="arm_left_AR5_5_08L_W4C4A6_link1" body2="hand_left_lh_middle_distal" />
    <exclude body1="arm_left_AR5_5_08L_W4C4A6_link1" body2="hand_left_lh_ring_proximal" />
    <exclude body1="arm_left_AR5_5_08L_W4C4A6_link1" body2="hand_left_lh_ring_distal" />
    <exclude body1="arm_left_AR5_5_08L_W4C4A6_link1" body2="hand_left_lh_pinky_proximal" />
    <exclude body1="arm_left_AR5_5_08L_W4C4A6_link1" body2="hand_left_lh_pinky_distal" />
    <exclude body1="arm_left_AR5_5_08L_W4C4A6_link2" body2="hand_left_lh_hand_base_link" />
    <exclude body1="arm_left_AR5_5_08L_W4C4A6_link2" body2="hand_left_lh_thumb_metacarpals_base2" />
    <exclude body1="arm_left_AR5_5_08L_W4C4A6_link2" body2="hand_left_lh_thumb_metacarpals" />
    <exclude body1="arm_left_AR5_5_08L_W4C4A6_link2" body2="hand_left_lh_thumb_distal" />
    <exclude body1="arm_left_AR5_5_08L_W4C4A6_link2" body2="hand_left_lh_index_proximal" />
    <exclude body1="arm_left_AR5_5_08L_W4C4A6_link2" body2="hand_left_lh_index_distal" />
    <exclude body1="arm_left_AR5_5_08L_W4C4A6_link2" body2="hand_left_lh_middle_proximal" />
    <exclude body1="arm_left_AR5_5_08L_W4C4A6_link2" body2="hand_left_lh_middle_distal" />
    <exclude body1="arm_left_AR5_5_08L_W4C4A6_link2" body2="hand_left_lh_ring_proximal" />
    <exclude body1="arm_left_AR5_5_08L_W4C4A6_link2" body2="hand_left_lh_ring_distal" />
    <exclude body1="arm_left_AR5_5_08L_W4C4A6_link2" body2="hand_left_lh_pinky_proximal" />
    <exclude body1="arm_left_AR5_5_08L_W4C4A6_link2" body2="hand_left_lh_pinky_distal" />
    <exclude body1="arm_left_AR5_5_08L_W4C4A6_link3" body2="hand_left_lh_hand_base_link" />
    <exclude body1="arm_left_AR5_5_08L_W4C4A6_link3" body2="hand_left_lh_thumb_metacarpals_base2" />
    <exclude body1="arm_left_AR5_5_08L_W4C4A6_link3" body2="hand_left_lh_thumb_metacarpals" />
    <exclude body1="arm_left_AR5_5_08L_W4C4A6_link3" body2="hand_left_lh_thumb_distal" />
    <exclude body1="arm_left_AR5_5_08L_W4C4A6_link3" body2="hand_left_lh_index_proximal" />
    <exclude body1="arm_left_AR5_5_08L_W4C4A6_link3" body2="hand_left_lh_index_distal" />
    <exclude body1="arm_left_AR5_5_08L_W4C4A6_link3" body2="hand_left_lh_middle_proximal" />
    <exclude body1="arm_left_AR5_5_08L_W4C4A6_link3" body2="hand_left_lh_middle_distal" />
    <exclude body1="arm_left_AR5_5_08L_W4C4A6_link3" body2="hand_left_lh_ring_proximal" />
    <exclude body1="arm_left_AR5_5_08L_W4C4A6_link3" body2="hand_left_lh_ring_distal" />
    <exclude body1="arm_left_AR5_5_08L_W4C4A6_link3" body2="hand_left_lh_pinky_proximal" />
    <exclude body1="arm_left_AR5_5_08L_W4C4A6_link3" body2="hand_left_lh_pinky_distal" />
    <exclude body1="arm_left_AR5_5_08L_W4C4A6_link4" body2="hand_left_lh_hand_base_link" />
    <exclude body1="arm_left_AR5_5_08L_W4C4A6_link4" body2="hand_left_lh_thumb_metacarpals_base2" />
    <exclude body1="arm_left_AR5_5_08L_W4C4A6_link4" body2="hand_left_lh_thumb_metacarpals" />
    <exclude body1="arm_left_AR5_5_08L_W4C4A6_link4" body2="hand_left_lh_thumb_distal" />
    <exclude body1="arm_left_AR5_5_08L_W4C4A6_link4" body2="hand_left_lh_index_proximal" />
    <exclude body1="arm_left_AR5_5_08L_W4C4A6_link4" body2="hand_left_lh_index_distal" />
    <exclude body1="arm_left_AR5_5_08L_W4C4A6_link4" body2="hand_left_lh_middle_proximal" />
    <exclude body1="arm_left_AR5_5_08L_W4C4A6_link4" body2="hand_left_lh_middle_distal" />
    <exclude body1="arm_left_AR5_5_08L_W4C4A6_link4" body2="hand_left_lh_ring_proximal" />
    <exclude body1="arm_left_AR5_5_08L_W4C4A6_link4" body2="hand_left_lh_ring_distal" />
    <exclude body1="arm_left_AR5_5_08L_W4C4A6_link4" body2="hand_left_lh_pinky_proximal" />
    <exclude body1="arm_left_AR5_5_08L_W4C4A6_link4" body2="hand_left_lh_pinky_distal" />
    <exclude body1="arm_left_AR5_5_08L_W4C4A6_link5" body2="hand_left_lh_hand_base_link" />
    <exclude body1="arm_left_AR5_5_08L_W4C4A6_link5" body2="hand_left_lh_thumb_metacarpals_base2" />
    <exclude body1="arm_left_AR5_5_08L_W4C4A6_link5" body2="hand_left_lh_thumb_metacarpals" />
    <exclude body1="arm_left_AR5_5_08L_W4C4A6_link5" body2="hand_left_lh_thumb_distal" />
    <exclude body1="arm_left_AR5_5_08L_W4C4A6_link5" body2="hand_left_lh_index_proximal" />
    <exclude body1="arm_left_AR5_5_08L_W4C4A6_link5" body2="hand_left_lh_index_distal" />
    <exclude body1="arm_left_AR5_5_08L_W4C4A6_link5" body2="hand_left_lh_middle_proximal" />
    <exclude body1="arm_left_AR5_5_08L_W4C4A6_link5" body2="hand_left_lh_middle_distal" />
    <exclude body1="arm_left_AR5_5_08L_W4C4A6_link5" body2="hand_left_lh_ring_proximal" />
    <exclude body1="arm_left_AR5_5_08L_W4C4A6_link5" body2="hand_left_lh_ring_distal" />
    <exclude body1="arm_left_AR5_5_08L_W4C4A6_link5" body2="hand_left_lh_pinky_proximal" />
    <exclude body1="arm_left_AR5_5_08L_W4C4A6_link5" body2="hand_left_lh_pinky_distal" />
    <exclude body1="arm_left_AR5_5_08L_W4C4A6_link6" body2="hand_left_lh_hand_base_link" />
    <exclude body1="arm_left_AR5_5_08L_W4C4A6_link6" body2="hand_left_lh_thumb_metacarpals_base2" />
    <exclude body1="arm_left_AR5_5_08L_W4C4A6_link6" body2="hand_left_lh_thumb_metacarpals" />
    <exclude body1="arm_left_AR5_5_08L_W4C4A6_link6" body2="hand_left_lh_thumb_distal" />
    <exclude body1="arm_left_AR5_5_08L_W4C4A6_link6" body2="hand_left_lh_index_proximal" />
    <exclude body1="arm_left_AR5_5_08L_W4C4A6_link6" body2="hand_left_lh_index_distal" />
    <exclude body1="arm_left_AR5_5_08L_W4C4A6_link6" body2="hand_left_lh_middle_proximal" />
    <exclude body1="arm_left_AR5_5_08L_W4C4A6_link6" body2="hand_left_lh_middle_distal" />
    <exclude body1="arm_left_AR5_5_08L_W4C4A6_link6" body2="hand_left_lh_ring_proximal" />
    <exclude body1="arm_left_AR5_5_08L_W4C4A6_link6" body2="hand_left_lh_ring_distal" />
    <exclude body1="arm_left_AR5_5_08L_W4C4A6_link6" body2="hand_left_lh_pinky_proximal" />
    <exclude body1="arm_left_AR5_5_08L_W4C4A6_link6" body2="hand_left_lh_pinky_distal" />
    <exclude body1="arm_left_AR5_5_08L_W4C4A6_link7" body2="hand_left_lh_hand_base_link" />
    <exclude body1="arm_left_AR5_5_08L_W4C4A6_link7" body2="hand_left_lh_thumb_metacarpals_base2" />
    <exclude body1="arm_left_AR5_5_08L_W4C4A6_link7" body2="hand_left_lh_thumb_metacarpals" />
    <exclude body1="arm_left_AR5_5_08L_W4C4A6_link7" body2="hand_left_lh_thumb_distal" />
    <exclude body1="arm_left_AR5_5_08L_W4C4A6_link7" body2="hand_left_lh_index_proximal" />
    <exclude body1="arm_left_AR5_5_08L_W4C4A6_link7" body2="hand_left_lh_index_distal" />
    <exclude body1="arm_left_AR5_5_08L_W4C4A6_link7" body2="hand_left_lh_middle_proximal" />
    <exclude body1="arm_left_AR5_5_08L_W4C4A6_link7" body2="hand_left_lh_middle_distal" />
    <exclude body1="arm_left_AR5_5_08L_W4C4A6_link7" body2="hand_left_lh_ring_proximal" />
    <exclude body1="arm_left_AR5_5_08L_W4C4A6_link7" body2="hand_left_lh_ring_distal" />
    <exclude body1="arm_left_AR5_5_08L_W4C4A6_link7" body2="hand_left_lh_pinky_proximal" />
    <exclude body1="arm_left_AR5_5_08L_W4C4A6_link7" body2="hand_left_lh_pinky_distal" />
    <exclude body1="base_workstation_link" body2="hand_left_lh_hand_base_link" />
    <exclude body1="base_workstation_link" body2="hand_left_lh_thumb_metacarpals_base2" />
    <exclude body1="base_workstation_link" body2="hand_left_lh_thumb_metacarpals" />
    <exclude body1="base_workstation_link" body2="hand_left_lh_thumb_distal" />
    <exclude body1="base_workstation_link" body2="hand_left_lh_index_proximal" />
    <exclude body1="base_workstation_link" body2="hand_left_lh_index_distal" />
    <exclude body1="base_workstation_link" body2="hand_left_lh_middle_proximal" />
    <exclude body1="base_workstation_link" body2="hand_left_lh_middle_distal" />
    <exclude body1="base_workstation_link" body2="hand_left_lh_ring_proximal" />
    <exclude body1="base_workstation_link" body2="hand_left_lh_ring_distal" />
    <exclude body1="base_workstation_link" body2="hand_left_lh_pinky_proximal" />
    <exclude body1="base_workstation_link" body2="hand_left_lh_pinky_distal" />
    <exclude body1="base_camera_base_link" body2="hand_left_lh_hand_base_link" />
    <exclude body1="base_camera_base_link" body2="hand_left_lh_thumb_metacarpals_base2" />
    <exclude body1="base_camera_base_link" body2="hand_left_lh_thumb_metacarpals" />
    <exclude body1="base_camera_base_link" body2="hand_left_lh_thumb_distal" />
    <exclude body1="base_camera_base_link" body2="hand_left_lh_index_proximal" />
    <exclude body1="base_camera_base_link" body2="hand_left_lh_index_distal" />
    <exclude body1="base_camera_base_link" body2="hand_left_lh_middle_proximal" />
    <exclude body1="base_camera_base_link" body2="hand_left_lh_middle_distal" />
    <exclude body1="base_camera_base_link" body2="hand_left_lh_ring_proximal" />
    <exclude body1="base_camera_base_link" body2="hand_left_lh_ring_distal" />
    <exclude body1="base_camera_base_link" body2="hand_left_lh_pinky_proximal" />
    <exclude body1="base_camera_base_link" body2="hand_left_lh_pinky_distal" />
    <exclude body1="base_camera" body2="hand_left_lh_hand_base_link" />
    <exclude body1="base_camera" body2="hand_left_lh_thumb_metacarpals_base2" />
    <exclude body1="base_camera" body2="hand_left_lh_thumb_metacarpals" />
    <exclude body1="base_camera" body2="hand_left_lh_thumb_distal" />
    <exclude body1="base_camera" body2="hand_left_lh_index_proximal" />
    <exclude body1="base_camera" body2="hand_left_lh_index_distal" />
    <exclude body1="base_camera" body2="hand_left_lh_middle_proximal" />
    <exclude body1="base_camera" body2="hand_left_lh_middle_distal" />
    <exclude body1="base_camera" body2="hand_left_lh_ring_proximal" />
    <exclude body1="base_camera" body2="hand_left_lh_ring_distal" />
    <exclude body1="base_camera" body2="hand_left_lh_pinky_proximal" />
    <exclude body1="base_camera" body2="hand_left_lh_pinky_distal" />
    <exclude body1="arm_right_AR5_5_08R_W4C4A6_base" body2="hand_right_rh_hand_base_link" />
    <exclude body1="arm_right_AR5_5_08R_W4C4A6_base" body2="hand_right_rh_thumb_metacarpals_base2" />
    <exclude body1="arm_right_AR5_5_08R_W4C4A6_base" body2="hand_right_rh_thumb_metacarpals" />
    <exclude body1="arm_right_AR5_5_08R_W4C4A6_base" body2="hand_right_rh_thumb_distal" />
    <exclude body1="arm_right_AR5_5_08R_W4C4A6_base" body2="hand_right_rh_index_proximal" />
    <exclude body1="arm_right_AR5_5_08R_W4C4A6_base" body2="hand_right_rh_index_distal" />
    <exclude body1="arm_right_AR5_5_08R_W4C4A6_base" body2="hand_right_rh_middle_proximal" />
    <exclude body1="arm_right_AR5_5_08R_W4C4A6_base" body2="hand_right_rh_middle_distal" />
    <exclude body1="arm_right_AR5_5_08R_W4C4A6_base" body2="hand_right_rh_ring_proximal" />
    <exclude body1="arm_right_AR5_5_08R_W4C4A6_base" body2="hand_right_rh_ring_distal" />
    <exclude body1="arm_right_AR5_5_08R_W4C4A6_base" body2="hand_right_rh_pinky_proximal" />
    <exclude body1="arm_right_AR5_5_08R_W4C4A6_base" body2="hand_right_rh_pinky_distal" />
    <exclude body1="arm_right_AR5_5_08R_W4C4A6_link1" body2="hand_right_rh_hand_base_link" />
    <exclude body1="arm_right_AR5_5_08R_W4C4A6_link1" body2="hand_right_rh_thumb_metacarpals_base2" />
    <exclude body1="arm_right_AR5_5_08R_W4C4A6_link1" body2="hand_right_rh_thumb_metacarpals" />
    <exclude body1="arm_right_AR5_5_08R_W4C4A6_link1" body2="hand_right_rh_thumb_distal" />
    <exclude body1="arm_right_AR5_5_08R_W4C4A6_link1" body2="hand_right_rh_index_proximal" />
    <exclude body1="arm_right_AR5_5_08R_W4C4A6_link1" body2="hand_right_rh_index_distal" />
    <exclude body1="arm_right_AR5_5_08R_W4C4A6_link1" body2="hand_right_rh_middle_proximal" />
    <exclude body1="arm_right_AR5_5_08R_W4C4A6_link1" body2="hand_right_rh_middle_distal" />
    <exclude body1="arm_right_AR5_5_08R_W4C4A6_link1" body2="hand_right_rh_ring_proximal" />
    <exclude body1="arm_right_AR5_5_08R_W4C4A6_link1" body2="hand_right_rh_ring_distal" />
    <exclude body1="arm_right_AR5_5_08R_W4C4A6_link1" body2="hand_right_rh_pinky_proximal" />
    <exclude body1="arm_right_AR5_5_08R_W4C4A6_link1" body2="hand_right_rh_pinky_distal" />
    <exclude body1="arm_right_AR5_5_08R_W4C4A6_link2" body2="hand_right_rh_hand_base_link" />
    <exclude body1="arm_right_AR5_5_08R_W4C4A6_link2" body2="hand_right_rh_thumb_metacarpals_base2" />
    <exclude body1="arm_right_AR5_5_08R_W4C4A6_link2" body2="hand_right_rh_thumb_metacarpals" />
    <exclude body1="arm_right_AR5_5_08R_W4C4A6_link2" body2="hand_right_rh_thumb_distal" />
    <exclude body1="arm_right_AR5_5_08R_W4C4A6_link2" body2="hand_right_rh_index_proximal" />
    <exclude body1="arm_right_AR5_5_08R_W4C4A6_link2" body2="hand_right_rh_index_distal" />
    <exclude body1="arm_right_AR5_5_08R_W4C4A6_link2" body2="hand_right_rh_middle_proximal" />
    <exclude body1="arm_right_AR5_5_08R_W4C4A6_link2" body2="hand_right_rh_middle_distal" />
    <exclude body1="arm_right_AR5_5_08R_W4C4A6_link2" body2="hand_right_rh_ring_proximal" />
    <exclude body1="arm_right_AR5_5_08R_W4C4A6_link2" body2="hand_right_rh_ring_distal" />
    <exclude body1="arm_right_AR5_5_08R_W4C4A6_link2" body2="hand_right_rh_pinky_proximal" />
    <exclude body1="arm_right_AR5_5_08R_W4C4A6_link2" body2="hand_right_rh_pinky_distal" />
    <exclude body1="arm_right_AR5_5_08R_W4C4A6_link3" body2="hand_right_rh_hand_base_link" />
    <exclude body1="arm_right_AR5_5_08R_W4C4A6_link3" body2="hand_right_rh_thumb_metacarpals_base2" />
    <exclude body1="arm_right_AR5_5_08R_W4C4A6_link3" body2="hand_right_rh_thumb_metacarpals" />
    <exclude body1="arm_right_AR5_5_08R_W4C4A6_link3" body2="hand_right_rh_thumb_distal" />
    <exclude body1="arm_right_AR5_5_08R_W4C4A6_link3" body2="hand_right_rh_index_proximal" />
    <exclude body1="arm_right_AR5_5_08R_W4C4A6_link3" body2="hand_right_rh_index_distal" />
    <exclude body1="arm_right_AR5_5_08R_W4C4A6_link3" body2="hand_right_rh_middle_proximal" />
    <exclude body1="arm_right_AR5_5_08R_W4C4A6_link3" body2="hand_right_rh_middle_distal" />
    <exclude body1="arm_right_AR5_5_08R_W4C4A6_link3" body2="hand_right_rh_ring_proximal" />
    <exclude body1="arm_right_AR5_5_08R_W4C4A6_link3" body2="hand_right_rh_ring_distal" />
    <exclude body1="arm_right_AR5_5_08R_W4C4A6_link3" body2="hand_right_rh_pinky_proximal" />
    <exclude body1="arm_right_AR5_5_08R_W4C4A6_link3" body2="hand_right_rh_pinky_distal" />
    <exclude body1="arm_right_AR5_5_08R_W4C4A6_link4" body2="hand_right_rh_hand_base_link" />
    <exclude body1="arm_right_AR5_5_08R_W4C4A6_link4" body2="hand_right_rh_thumb_metacarpals_base2" />
    <exclude body1="arm_right_AR5_5_08R_W4C4A6_link4" body2="hand_right_rh_thumb_metacarpals" />
    <exclude body1="arm_right_AR5_5_08R_W4C4A6_link4" body2="hand_right_rh_thumb_distal" />
    <exclude body1="arm_right_AR5_5_08R_W4C4A6_link4" body2="hand_right_rh_index_proximal" />
    <exclude body1="arm_right_AR5_5_08R_W4C4A6_link4" body2="hand_right_rh_index_distal" />
    <exclude body1="arm_right_AR5_5_08R_W4C4A6_link4" body2="hand_right_rh_middle_proximal" />
    <exclude body1="arm_right_AR5_5_08R_W4C4A6_link4" body2="hand_right_rh_middle_distal" />
    <exclude body1="arm_right_AR5_5_08R_W4C4A6_link4" body2="hand_right_rh_ring_proximal" />
    <exclude body1="arm_right_AR5_5_08R_W4C4A6_link4" body2="hand_right_rh_ring_distal" />
    <exclude body1="arm_right_AR5_5_08R_W4C4A6_link4" body2="hand_right_rh_pinky_proximal" />
    <exclude body1="arm_right_AR5_5_08R_W4C4A6_link4" body2="hand_right_rh_pinky_distal" />
    <exclude body1="arm_right_AR5_5_08R_W4C4A6_link5" body2="hand_right_rh_hand_base_link" />
    <exclude body1="arm_right_AR5_5_08R_W4C4A6_link5" body2="hand_right_rh_thumb_metacarpals_base2" />
    <exclude body1="arm_right_AR5_5_08R_W4C4A6_link5" body2="hand_right_rh_thumb_metacarpals" />
    <exclude body1="arm_right_AR5_5_08R_W4C4A6_link5" body2="hand_right_rh_thumb_distal" />
    <exclude body1="arm_right_AR5_5_08R_W4C4A6_link5" body2="hand_right_rh_index_proximal" />
    <exclude body1="arm_right_AR5_5_08R_W4C4A6_link5" body2="hand_right_rh_index_distal" />
    <exclude body1="arm_right_AR5_5_08R_W4C4A6_link5" body2="hand_right_rh_middle_proximal" />
    <exclude body1="arm_right_AR5_5_08R_W4C4A6_link5" body2="hand_right_rh_middle_distal" />
    <exclude body1="arm_right_AR5_5_08R_W4C4A6_link5" body2="hand_right_rh_ring_proximal" />
    <exclude body1="arm_right_AR5_5_08R_W4C4A6_link5" body2="hand_right_rh_ring_distal" />
    <exclude body1="arm_right_AR5_5_08R_W4C4A6_link5" body2="hand_right_rh_pinky_proximal" />
    <exclude body1="arm_right_AR5_5_08R_W4C4A6_link5" body2="hand_right_rh_pinky_distal" />
    <exclude body1="arm_right_AR5_5_08R_W4C4A6_link6" body2="hand_right_rh_hand_base_link" />
    <exclude body1="arm_right_AR5_5_08R_W4C4A6_link6" body2="hand_right_rh_thumb_metacarpals_base2" />
    <exclude body1="arm_right_AR5_5_08R_W4C4A6_link6" body2="hand_right_rh_thumb_metacarpals" />
    <exclude body1="arm_right_AR5_5_08R_W4C4A6_link6" body2="hand_right_rh_thumb_distal" />
    <exclude body1="arm_right_AR5_5_08R_W4C4A6_link6" body2="hand_right_rh_index_proximal" />
    <exclude body1="arm_right_AR5_5_08R_W4C4A6_link6" body2="hand_right_rh_index_distal" />
    <exclude body1="arm_right_AR5_5_08R_W4C4A6_link6" body2="hand_right_rh_middle_proximal" />
    <exclude body1="arm_right_AR5_5_08R_W4C4A6_link6" body2="hand_right_rh_middle_distal" />
    <exclude body1="arm_right_AR5_5_08R_W4C4A6_link6" body2="hand_right_rh_ring_proximal" />
    <exclude body1="arm_right_AR5_5_08R_W4C4A6_link6" body2="hand_right_rh_ring_distal" />
    <exclude body1="arm_right_AR5_5_08R_W4C4A6_link6" body2="hand_right_rh_pinky_proximal" />
    <exclude body1="arm_right_AR5_5_08R_W4C4A6_link6" body2="hand_right_rh_pinky_distal" />
    <exclude body1="arm_right_AR5_5_08R_W4C4A6_link7" body2="hand_right_rh_hand_base_link" />
    <exclude body1="arm_right_AR5_5_08R_W4C4A6_link7" body2="hand_right_rh_thumb_metacarpals_base2" />
    <exclude body1="arm_right_AR5_5_08R_W4C4A6_link7" body2="hand_right_rh_thumb_metacarpals" />
    <exclude body1="arm_right_AR5_5_08R_W4C4A6_link7" body2="hand_right_rh_thumb_distal" />
    <exclude body1="arm_right_AR5_5_08R_W4C4A6_link7" body2="hand_right_rh_index_proximal" />
    <exclude body1="arm_right_AR5_5_08R_W4C4A6_link7" body2="hand_right_rh_index_distal" />
    <exclude body1="arm_right_AR5_5_08R_W4C4A6_link7" body2="hand_right_rh_middle_proximal" />
    <exclude body1="arm_right_AR5_5_08R_W4C4A6_link7" body2="hand_right_rh_middle_distal" />
    <exclude body1="arm_right_AR5_5_08R_W4C4A6_link7" body2="hand_right_rh_ring_proximal" />
    <exclude body1="arm_right_AR5_5_08R_W4C4A6_link7" body2="hand_right_rh_ring_distal" />
    <exclude body1="arm_right_AR5_5_08R_W4C4A6_link7" body2="hand_right_rh_pinky_proximal" />
    <exclude body1="arm_right_AR5_5_08R_W4C4A6_link7" body2="hand_right_rh_pinky_distal" />
    <exclude body1="base_workstation_link" body2="hand_right_rh_hand_base_link" />
    <exclude body1="base_workstation_link" body2="hand_right_rh_thumb_metacarpals_base2" />
    <exclude body1="base_workstation_link" body2="hand_right_rh_thumb_metacarpals" />
    <exclude body1="base_workstation_link" body2="hand_right_rh_thumb_distal" />
    <exclude body1="base_workstation_link" body2="hand_right_rh_index_proximal" />
    <exclude body1="base_workstation_link" body2="hand_right_rh_index_distal" />
    <exclude body1="base_workstation_link" body2="hand_right_rh_middle_proximal" />
    <exclude body1="base_workstation_link" body2="hand_right_rh_middle_distal" />
    <exclude body1="base_workstation_link" body2="hand_right_rh_ring_proximal" />
    <exclude body1="base_workstation_link" body2="hand_right_rh_ring_distal" />
    <exclude body1="base_workstation_link" body2="hand_right_rh_pinky_proximal" />
    <exclude body1="base_workstation_link" body2="hand_right_rh_pinky_distal" />
    <exclude body1="base_camera_base_link" body2="hand_right_rh_hand_base_link" />
    <exclude body1="base_camera_base_link" body2="hand_right_rh_thumb_metacarpals_base2" />
    <exclude body1="base_camera_base_link" body2="hand_right_rh_thumb_metacarpals" />
    <exclude body1="base_camera_base_link" body2="hand_right_rh_thumb_distal" />
    <exclude body1="base_camera_base_link" body2="hand_right_rh_index_proximal" />
    <exclude body1="base_camera_base_link" body2="hand_right_rh_index_distal" />
    <exclude body1="base_camera_base_link" body2="hand_right_rh_middle_proximal" />
    <exclude body1="base_camera_base_link" body2="hand_right_rh_middle_distal" />
    <exclude body1="base_camera_base_link" body2="hand_right_rh_ring_proximal" />
    <exclude body1="base_camera_base_link" body2="hand_right_rh_ring_distal" />
    <exclude body1="base_camera_base_link" body2="hand_right_rh_pinky_proximal" />
    <exclude body1="base_camera_base_link" body2="hand_right_rh_pinky_distal" />
    <exclude body1="base_camera" body2="hand_right_rh_hand_base_link" />
    <exclude body1="base_camera" body2="hand_right_rh_thumb_metacarpals_base2" />
    <exclude body1="base_camera" body2="hand_right_rh_thumb_metacarpals" />
    <exclude body1="base_camera" body2="hand_right_rh_thumb_distal" />
    <exclude body1="base_camera" body2="hand_right_rh_index_proximal" />
    <exclude body1="base_camera" body2="hand_right_rh_index_distal" />
    <exclude body1="base_camera" body2="hand_right_rh_middle_proximal" />
    <exclude body1="base_camera" body2="hand_right_rh_middle_distal" />
    <exclude body1="base_camera" body2="hand_right_rh_ring_proximal" />
    <exclude body1="base_camera" body2="hand_right_rh_ring_distal" />
    <exclude body1="base_camera" body2="hand_right_rh_pinky_proximal" />
    <exclude body1="base_camera" body2="hand_right_rh_pinky_distal" />
  </contact>
</mujoco>
