<?xml version="1.0" encoding="UTF-8"?>
<!-- Generated by linker_robot_assets.composer (version 0.1.0). Workstation: ar5_08_o6_bench_bimanual. Recipe sha256: b812535ce3c2ba9ce7c00176edea7c9a29a3a23791fb8026d9149a95cbff53a9. Do not edit by hand; re-run `python -m linker_robot_assets.composer.compose <workstation>`. -->
<robot name="ar5_08_o6_bench_bimanual">
  <link name="world" />
  <material name="arm_left_white">
    <color rgba="1.0 1.0 1.0 1.0" />
  </material>
  <material name="arm_right_white">
    <color rgba="1.0 1.0 1.0 1.0" />
  </material>
  <material name="hand_left_silver">
    <color rgba="0.5 0.5 0.52 1.0" />
  </material>
  <material name="hand_left_BlackAccent">
    <color rgba="0.15 0.15 0.15 1.0" />
  </material>
  <material name="hand_right_silver">
    <color rgba="0.5 0.5 0.52 1.0" />
  </material>
  <material name="hand_right_BlackAccent">
    <color rgba="0.15 0.15 0.15 1.0" />
  </material>
  <link name="base_workstation_link">
    <visual>
      <origin xyz="0 0 0" rpy="0 0 0" />
      <geometry>
        <mesh filename="../../components/bases/bench_table/variants/default/meshes/workstation.STL" />
      </geometry>
      <material name="base_workstation_gray">
        <color rgba="0.6 0.6 0.6 1.0" />
      </material>
    </visual>
    <collision>
      <origin xyz="0 0 0" rpy="0 0 0" />
      <geometry>
        <mesh filename="../../components/bases/bench_table/variants/default/meshes/workstation.STL" />
      </geometry>
    </collision>
    <inertial>
      <origin xyz="0 0 0" rpy="0 0 0" />
      <mass value="50.0" />
      <inertia ixx="1.0" ixy="0.0" ixz="0.0" iyy="1.0" iyz="0.0" izz="1.0" />
    </inertial>
  </link>
  <link name="base_camera_base_link">
    <inertial>
      <origin xyz="0.0538773695 0.0404431717 0.0338436904" rpy="0 0 0" />
      <mass value="0.120253078965696" />
      <inertia ixx="0.00024086634809874" ixy="1.11484097335586E-05" ixz="3.07915341770146E-05" iyy="0.000340317013404989" iyz="-5.88336477049719E-05" izz="0.000187914824387855" />
    </inertial>
    <visual>
      <origin xyz="0 0 0" rpy="0 0 0" />
      <geometry>
        <mesh filename="../../components/bases/bench_table/variants/default/meshes/camera_base_link.STL" />
      </geometry>
      <material name="">
        <color rgba="0.792156862745098 0.819607843137255 0.933333333333333 1" />
      </material>
    </visual>
    <collision>
      <origin xyz="0 0 0" rpy="0 0 0" />
      <geometry>
        <mesh filename="../../components/bases/bench_table/variants/default/meshes/camera_base_link.STL" />
      </geometry>
    </collision>
  </link>
  <link name="base_camera">
    <inertial>
      <origin xyz="0.435583907 -0.11451791 -0.00087379797" rpy="0 0 0" />
      <mass value="0.170230158191785" />
      <inertia ixx="0.000388607098441677" ixy="-3.21389374232659E-06" ixz="1.01075980515721E-06" iyy="0.000353185511381015" iyz="-0.000100865226288639" izz="6.42979907249093E-05" />
    </inertial>
    <visual>
      <origin xyz="0 0 0" rpy="0 0 0" />
      <geometry>
        <mesh filename="../../components/bases/bench_table/variants/default/meshes/camera.STL" />
      </geometry>
      <material name="">
        <color rgba="0.792156862745098 0.819607843137255 0.933333333333333 1" />
      </material>
    </visual>
    <collision>
      <origin xyz="0 0 0" rpy="0 0 0" />
      <geometry>
        <mesh filename="../../components/bases/bench_table/variants/default/meshes/camera.STL" />
      </geometry>
    </collision>
  </link>
  <link name="base_workstation_arm_left_mount" />
  <link name="base_workstation_arm_right_mount" />
  <link name="arm_left_AR5_5_08L_W4C4A6_base">
    <visual>
      <geometry>
        <mesh filename="../../components/arms/ar5_08/variants/left/meshes/AR5_5_08L_W4C4A6_base.STL" scale="0.001 0.001 0.001" />
      </geometry>
      <origin rpy="-1.5708 0 0" xyz="0 0 0" />
      <material name="arm_left_white" />
    </visual>
    <collision>
      <geometry>
        <mesh filename="../../components/arms/ar5_08/variants/left/meshes/AR5_5_08L_W4C4A6_base.STL" scale="0.001 0.001 0.001" />
      </geometry>
      <origin rpy="-1.5708 0 0" xyz="0 0 0" />
    </collision>
  </link>
  <link name="arm_left_AR5_5_08L_W4C4A6_link1">
    <visual>
      <geometry>
        <mesh filename="../../components/arms/ar5_08/variants/left/meshes/AR5_5_08L_W4C4A6_link1.STL" scale="0.001 0.001 0.001" />
      </geometry>
      <origin rpy="0 0 0" xyz="0 0 0" />
      <material name="arm_left_white" />
    </visual>
    <inertial>
      <mass value="2.166" />
      <inertia ixx="0.00332249" ixy="0.00000032" ixz="-0.00000048" iyy="0.00260904" iyz="-0.00001486" izz="0.00317691" />
      <origin rpy="0 0 0" xyz="-0.000184 0.001568 0.172804" />
    </inertial>
    <collision>
      <geometry>
        <mesh filename="../../components/arms/ar5_08/variants/left/meshes/AR5_5_08L_W4C4A6_link1.STL" scale="0.001 0.001 0.001" />
      </geometry>
      <origin rpy="0 0 0" xyz="0 0 0" />
    </collision>
  </link>
  <link name="arm_left_AR5_5_08L_W4C4A6_link2">
    <visual>
      <geometry>
        <mesh filename="../../components/arms/ar5_08/variants/left/meshes/AR5_5_08L_W4C4A6_link2.STL" scale="0.001 0.001 0.001" />
      </geometry>
      <origin rpy="0 0 0" xyz="0 0 0" />
      <material name="arm_left_white" />
    </visual>
    <inertial>
      <mass value="1.903" />
      <inertia ixx="0.00779803" ixy="0.00000248" ixz="-0.00000226" iyy="0.00674819" iyz="-0.00049283" izz="0.00305507" />
      <origin rpy="0 0 0" xyz="-1.7e-05 0.001795 0.106689" />
    </inertial>
    <collision>
      <geometry>
        <mesh filename="../../components/arms/ar5_08/variants/left/meshes/AR5_5_08L_W4C4A6_link2.STL" scale="0.001 0.001 0.001" />
      </geometry>
      <origin rpy="0 0 0" xyz="0 0 0" />
    </collision>
  </link>
  <link name="arm_left_AR5_5_08L_W4C4A6_link3">
    <visual>
      <geometry>
        <mesh filename="../../components/arms/ar5_08/variants/left/meshes/AR5_5_08L_W4C4A6_link3.STL" scale="0.001 0.001 0.001" />
      </geometry>
      <origin rpy="0 0 0" xyz="0 0 0" />
      <material name="arm_left_white" />
    </visual>
    <inertial>
      <mass value="1.845" />
      <inertia ixx="0.00641285" ixy="0.00000909" ixz="0.00034765" iyy="0.00591595" iyz="-0.00002314" izz="0.00276583" />
      <origin rpy="0 0 0" xyz="0.008227 -0.001273 -0.020611" />
    </inertial>
    <collision>
      <geometry>
        <mesh filename="../../components/arms/ar5_08/variants/left/meshes/AR5_5_08L_W4C4A6_link3.STL" scale="0.001 0.001 0.001" />
      </geometry>
      <origin rpy="0 0 0" xyz="0 0 0" />
    </collision>
  </link>
  <link name="arm_left_AR5_5_08L_W4C4A6_link4">
    <visual>
      <geometry>
        <mesh filename="../../components/arms/ar5_08/variants/left/meshes/AR5_5_08L_W4C4A6_link4.STL" scale="0.001 0.001 0.001" />
      </geometry>
      <origin rpy="0 0 0" xyz="0 0 0" />
      <material name="arm_left_white" />
    </visual>
    <inertial>
      <mass value="1.037" />
      <inertia ixx="0.00294639" ixy="-0.00002418" ixz="-0.00012203" iyy="0.00244447" iyz="0.00022029" izz="0.00140961" />
      <origin rpy="0 0 0" xyz="-0.009242 -0.002172 0.084042" />
    </inertial>
    <collision>
      <geometry>
        <mesh filename="../../components/arms/ar5_08/variants/left/meshes/AR5_5_08L_W4C4A6_link4.STL" scale="0.001 0.001 0.001" />
      </geometry>
      <origin rpy="0 0 0" xyz="0 0 0" />
    </collision>
  </link>
  <link name="arm_left_AR5_5_08L_W4C4A6_link5">
    <visual>
      <geometry>
        <mesh filename="../../components/arms/ar5_08/variants/left/meshes/AR5_5_08L_W4C4A6_link5.STL" scale="0.001 0.001 0.001" />
      </geometry>
      <origin rpy="0 0 0" xyz="0 0 0" />
      <material name="arm_left_white" />
    </visual>
    <inertial>
      <mass value="1.279" />
      <inertia ixx="0.00241349" ixy="-0.00003807" ixz="-0.00004536" iyy="0.00200246" iyz="0.00006623" izz="0.00158693" />
      <origin rpy="0 0 0" xyz="-0.000756 0.000723 -0.086764" />
    </inertial>
    <collision>
      <geometry>
        <mesh filename="../../components/arms/ar5_08/variants/left/meshes/AR5_5_08L_W4C4A6_link5.STL" scale="0.001 0.001 0.001" />
      </geometry>
      <origin rpy="0 0 0" xyz="0 0 0" />
    </collision>
  </link>
  <link name="arm_left_AR5_5_08L_W4C4A6_link6">
    <visual>
      <geometry>
        <mesh filename="../../components/arms/ar5_08/variants/left/meshes/AR5_5_08L_W4C4A6_link6.STL" scale="0.001 0.001 0.001" />
      </geometry>
      <origin rpy="0 0 0" xyz="0 0 0" />
      <material name="arm_left_white" />
    </visual>
    <inertial>
      <mass value="0.906" />
      <inertia ixx="0.00061429" ixy="-0.00000088" ixz="0.00000104" iyy="0.00074781" iyz="-0.00000047" izz="0.00075897" />
      <origin rpy="0 0 0" xyz="-0.005104 0.000251 5.6e-05" />
    </inertial>
    <collision>
      <geometry>
        <mesh filename="../../components/arms/ar5_08/variants/left/meshes/AR5_5_08L_W4C4A6_link6.STL" scale="0.001 0.001 0.001" />
      </geometry>
      <origin rpy="0 0 0" xyz="0 0 0" />
    </collision>
  </link>
  <link name="arm_left_AR5_5_08L_W4C4A6_link7">
    <visual>
      <geometry>
        <mesh filename="../../components/arms/ar5_08/variants/left/meshes/AR5_5_08L_W4C4A6_link7.STL" scale="0.001 0.001 0.001" />
      </geometry>
      <origin rpy="0 0 0" xyz="0 0 0" />
      <material name="arm_left_white" />
    </visual>
    <inertial>
      <mass value="0.33" />
      <inertia ixx="0.00046062" ixy="0.00000269" ixz="0.00003859" iyy="0.00068652" iyz="-0.00000095" izz="0.00043943" />
      <origin rpy="0 0 0" xyz="-0.001562 -0.000366 0.05392" />
    </inertial>
    <collision>
      <geometry>
        <mesh filename="../../components/arms/ar5_08/variants/left/meshes/AR5_5_08L_W4C4A6_link7.STL" scale="0.001 0.001 0.001" />
      </geometry>
      <origin rpy="0 0 0" xyz="0 0 0" />
    </collision>
  </link>
  <link name="arm_left_AR5_5_08L_W4C4A6_tcp">
    <visual>
      <origin xyz="0 0 0" rpy="0 0 0" />
      <geometry>
        <box size="0.0001 0.0001 0.0001" />
      </geometry>
      <material name="arm_left_white" />
    </visual>
    <collision>
      <origin xyz="0 0 0" rpy="0 0 0" />
      <geometry>
        <box size="0.0001 0.0001 0.0001" />
      </geometry>
    </collision>
    <inertial>
      <mass value="0.0" />
      <inertia ixx="1e-6" ixy="0" ixz="0" iyy="1e-6" iyz="0" izz="1e-6" />
    </inertial>
  </link>
  <link name="arm_right_AR5_5_08R_W4C4A6_base">
    <visual>
      <geometry>
        <mesh filename="../../components/arms/ar5_08/variants/right/meshes/AR5_5_08R_W4C4A6_base.STL" scale="0.001 0.001 0.001" />
      </geometry>
      <origin rpy="1.5708 0 0" xyz="0 0 0" />
      <material name="arm_right_white" />
    </visual>
    <collision>
      <geometry>
        <mesh filename="../../components/arms/ar5_08/variants/right/meshes/AR5_5_08R_W4C4A6_base.STL" scale="0.001 0.001 0.001" />
      </geometry>
      <origin rpy="1.5708 0 0" xyz="0 0 0" />
    </collision>
  </link>
  <link name="arm_right_AR5_5_08R_W4C4A6_link1">
    <visual>
      <geometry>
        <mesh filename="../../components/arms/ar5_08/variants/right/meshes/AR5_5_08R_W4C4A6_link1.STL" scale="0.001 0.001 0.001" />
      </geometry>
      <origin rpy="0 0 0" xyz="0 0 0" />
      <material name="arm_right_white" />
    </visual>
    <inertial>
      <mass value="2.166" />
      <inertia ixx="0.00329374" ixy="0.00000029" ixz="0.00000048" iyy="0.00258807" iyz="0.00001496" izz="0.00314817" />
      <origin rpy="0 0 0" xyz="0.000186 -0.001543 0.172784" />
    </inertial>
    <collision>
      <geometry>
        <mesh filename="../../components/arms/ar5_08/variants/right/meshes/AR5_5_08R_W4C4A6_link1.STL" scale="0.001 0.001 0.001" />
      </geometry>
      <origin rpy="0 0 0" xyz="0 0 0" />
    </collision>
  </link>
  <link name="arm_right_AR5_5_08R_W4C4A6_link2">
    <visual>
      <geometry>
        <mesh filename="../../components/arms/ar5_08/variants/right/meshes/AR5_5_08R_W4C4A6_link2.STL" scale="0.001 0.001 0.001" />
      </geometry>
      <origin rpy="0 0 0" xyz="0 0 0" />
      <material name="arm_right_white" />
    </visual>
    <inertial>
      <mass value="1.903" />
      <inertia ixx="0.00779827" ixy="0.00000248" ixz="0.00000226" iyy="0.00674843" iyz="0.00049284" izz="0.00305518" />
      <origin rpy="0 0 0" xyz="1.7e-05 -0.001795 0.106691" />
    </inertial>
    <collision>
      <geometry>
        <mesh filename="../../components/arms/ar5_08/variants/right/meshes/AR5_5_08R_W4C4A6_link2.STL" scale="0.001 0.001 0.001" />
      </geometry>
      <origin rpy="0 0 0" xyz="0 0 0" />
    </collision>
  </link>
  <link name="arm_right_AR5_5_08R_W4C4A6_link3">
    <visual>
      <geometry>
        <mesh filename="../../components/arms/ar5_08/variants/right/meshes/AR5_5_08R_W4C4A6_link3.STL" scale="0.001 0.001 0.001" />
      </geometry>
      <origin rpy="0 0 0" xyz="0 0 0" />
      <material name="arm_right_white" />
    </visual>
    <inertial>
      <mass value="1.845" />
      <inertia ixx="0.00635592" ixy="0.00001599" ixz="0.00029945" iyy="0.00581609" iyz="0.00004683" izz="0.00269115" />
      <origin rpy="0 0 0" xyz="0.009022 0.0009 -0.019936" />
    </inertial>
    <collision>
      <geometry>
        <mesh filename="../../components/arms/ar5_08/variants/right/meshes/AR5_5_08R_W4C4A6_link3.STL" scale="0.001 0.001 0.001" />
      </geometry>
      <origin rpy="0 0 0" xyz="0 0 0" />
    </collision>
  </link>
  <link name="arm_right_AR5_5_08R_W4C4A6_link4">
    <visual>
      <geometry>
        <mesh filename="../../components/arms/ar5_08/variants/right/meshes/AR5_5_08R_W4C4A6_link4.STL" scale="0.001 0.001 0.001" />
      </geometry>
      <origin rpy="0 0 0" xyz="0 0 0" />
      <material name="arm_right_white" />
    </visual>
    <inertial>
      <mass value="1.037" />
      <inertia ixx="0.00294610" ixy="0.00002481" ixz="-0.00011850" iyy="0.00244455" iyz="-0.00022011" izz="0.00140934" />
      <origin rpy="0 0 0" xyz="-0.009272 0.002169 0.084042" />
    </inertial>
    <collision>
      <geometry>
        <mesh filename="../../components/arms/ar5_08/variants/right/meshes/AR5_5_08R_W4C4A6_link4.STL" scale="0.001 0.001 0.001" />
      </geometry>
      <origin rpy="0 0 0" xyz="0 0 0" />
    </collision>
  </link>
  <link name="arm_right_AR5_5_08R_W4C4A6_link5">
    <visual>
      <geometry>
        <mesh filename="../../components/arms/ar5_08/variants/right/meshes/AR5_5_08R_W4C4A6_link5.STL" scale="0.001 0.001 0.001" />
      </geometry>
      <origin rpy="0 0 0" xyz="0 0 0" />
      <material name="arm_right_white" />
    </visual>
    <inertial>
      <mass value="1.279" />
      <inertia ixx="0.00240951" ixy="0.00004151" ixz="-0.00004311" iyy="0.00200115" iyz="-0.00006491" izz="0.00158266" />
      <origin rpy="0 0 0" xyz="-0.000776 -0.000804 -0.086734" />
    </inertial>
    <collision>
      <geometry>
        <mesh filename="../../components/arms/ar5_08/variants/right/meshes/AR5_5_08R_W4C4A6_link5.STL" scale="0.001 0.001 0.001" />
      </geometry>
      <origin rpy="0 0 0" xyz="0 0 0" />
    </collision>
  </link>
  <link name="arm_right_AR5_5_08R_W4C4A6_link6">
    <visual>
      <geometry>
        <mesh filename="../../components/arms/ar5_08/variants/right/meshes/AR5_5_08R_W4C4A6_link6.STL" scale="0.001 0.001 0.001" />
      </geometry>
      <origin rpy="0 0 0" xyz="0 0 0" />
      <material name="arm_right_white" />
    </visual>
    <inertial>
      <mass value="0.906" />
      <inertia ixx="0.00061487" ixy="0.00000092" ixz="-0.00000097" iyy="0.00074943" iyz="-0.00000047" izz="0.00076056" />
      <origin rpy="0 0 0" xyz="-0.005059 -0.00025 -5.5e-05" />
    </inertial>
    <collision>
      <geometry>
        <mesh filename="../../components/arms/ar5_08/variants/right/meshes/AR5_5_08R_W4C4A6_link6.STL" scale="0.001 0.001 0.001" />
      </geometry>
      <origin rpy="0 0 0" xyz="0 0 0" />
    </collision>
  </link>
  <link name="arm_right_AR5_5_08R_W4C4A6_link7">
    <visual>
      <geometry>
        <mesh filename="../../components/arms/ar5_08/variants/right/meshes/AR5_5_08R_W4C4A6_link7.STL" scale="0.001 0.001 0.001" />
      </geometry>
      <origin rpy="0 0 0" xyz="0 0 0" />
      <material name="arm_right_white" />
    </visual>
    <inertial>
      <mass value="0.33" />
      <inertia ixx="0.00046020" ixy="-0.00000266" ixz="0.00004064" iyy="0.00068698" iyz="0.00000424" izz="0.00043963" />
      <origin rpy="0 0 0" xyz="-0.00122 0.000673 0.053984" />
    </inertial>
    <collision>
      <geometry>
        <mesh filename="../../components/arms/ar5_08/variants/right/meshes/AR5_5_08R_W4C4A6_link7.STL" scale="0.001 0.001 0.001" />
      </geometry>
      <origin rpy="0 0 0" xyz="0 0 0" />
    </collision>
  </link>
  <link name="arm_right_AR5_5_08R_W4C4A6_tcp">
    <visual>
      <origin xyz="0 0 0" rpy="0 0 0" />
      <geometry>
        <box size="0.0001 0.0001 0.0001" />
      </geometry>
      <material name="arm_right_white" />
    </visual>
    <collision>
      <origin xyz="0 0 0" rpy="0 0 0" />
      <geometry>
        <box size="0.0001 0.0001 0.0001" />
      </geometry>
    </collision>
    <inertial>
      <mass value="0.0" />
      <inertia ixx="1e-6" ixy="0" ixz="0" iyy="1e-6" iyz="0" izz="1e-6" />
    </inertial>
  </link>
  <link name="hand_left_lh_hand_base_link">
    <inertial>
      <origin xyz="-0.00157788568 -0.000348767259 0.053845222" rpy="0 0 0" />
      <mass value="0.0672935238166485" />
      <inertia ixx="5.22525212160954E-05" ixy="3.06955729584715E-07" ixz="-3.90341166950521E-07" iyy="3.33522349207724E-05" iyz="-7.76680063574627E-07" izz="2.28469461105385E-05" />
    </inertial>
    <visual>
      <origin xyz="0 0 0" rpy="0 0 0" />
      <geometry>
        <mesh filename="../../components/hands/linkerhand_o6/meshes/visual/lh_hand_base_link_vis.glb" />
      </geometry>
      <material name="hand_left_silver" />
    </visual>
    <collision>
      <origin xyz="0 0 0" rpy="0 0 0" />
      <geometry>
        <mesh filename="../../components/hands/linkerhand_o6/meshes/collision/lh_hand_base_link_col.obj" />
      </geometry>
    </collision>
  </link>
  <link name="hand_left_lh_thumb_metacarpals_base2">
    <inertial>
      <origin xyz="0.00162800681 -0.00276680172 -0.00184234439" rpy="0 0 0" />
      <mass value="0.00138588296544333" />
      <inertia ixx="5.26292160685909E-08" ixy="-3.92888681640568E-09" ixz="-2.43767371295222E-09" iyy="4.82620491570326E-08" iyz="3.71869784206147E-09" izz="2.88550286112821E-08" />
    </inertial>
    <visual>
      <origin xyz="0 0 0" rpy="0 0 0" />
      <geometry>
        <mesh filename="../../components/hands/linkerhand_o6/meshes/visual/lh_thumb_metacarpals_base2_vis.glb" />
      </geometry>
      <material name="hand_left_BlackAccent" />
    </visual>
    <collision>
      <origin xyz="0 0 0" rpy="0 0 0" />
      <geometry>
        <mesh filename="../../components/hands/linkerhand_o6/meshes/collision/lh_thumb_metacarpals_base2_col.obj" />
      </geometry>
    </collision>
  </link>
  <link name="hand_left_lh_thumb_metacarpals">
    <inertial>
      <origin xyz="4.24816205e-05 1.74183908e-05 0.0228341641" rpy="0 0 0" />
      <mass value="0.0123381586619931" />
      <inertia ixx="1.10292537368909E-06" ixy="-5.99642232777877E-10" ixz="-1.14233573940545E-07" iyy="1.76757772551884E-06" iyz="-4.03963570823777E-10" izz="9.36347792411098E-07" />
    </inertial>
    <visual>
      <origin xyz="0 0 0" rpy="0 0 0" />
      <geometry>
        <mesh filename="../../components/hands/linkerhand_o6/meshes/visual/lh_thumb_metacarpals_vis.glb" />
      </geometry>
      <material name="hand_left_silver" />
    </visual>
    <collision>
      <origin xyz="0 0 0" rpy="0 0 0" />
      <geometry>
        <mesh filename="../../components/hands/linkerhand_o6/meshes/collision/lh_thumb_metacarpals_col.obj" />
      </geometry>
    </collision>
  </link>
  <link name="hand_left_lh_thumb_distal">
    <inertial>
      <origin xyz="-0.00413725703 -5.9070452e-08 0.0230114016" rpy="0 0 0" />
      <mass value="0.00763332957284057" />
      <inertia ixx="1.3057487813702E-06" ixy="-1.19781508112714E-11" ixz="-7.19551697268541E-08" iyy="1.2248908905341E-06" iyz="4.55347974652679E-12" izz="2.77271910592615E-07" />
    </inertial>
    <visual>
      <origin xyz="0 0 0" rpy="0 0 0" />
      <geometry>
        <mesh filename="../../components/hands/linkerhand_o6/meshes/visual/lh_thumb_distal_vis.glb" />
      </geometry>
      <material name="hand_left_silver" />
    </visual>
    <collision>
      <origin xyz="0 0 0" rpy="0 0 0" />
      <geometry>
        <mesh filename="../../components/hands/linkerhand_o6/meshes/collision/lh_thumb_distal_col.obj" />
      </geometry>
    </collision>
  </link>
  <link name="hand_left_lh_index_proximal">
    <inertial>
      <origin xyz="-0.00208656556 2.53838713e-06 0.0172734942" rpy="0 0 0" />
      <mass value="0.00253174651934627" />
      <inertia ixx="2.65988714157799E-07" ixy="-1.67174578825824E-11" ixz="-4.31047725546034E-08" iyy="2.72914069166233E-07" iyz="1.8756709532167E-10" izz="8.56017305636748E-08" />
    </inertial>
    <visual>
      <origin xyz="0 0 0" rpy="0 0 0" />
      <geometry>
        <mesh filename="../../components/hands/linkerhand_o6/meshes/visual/lh_index_proximal_vis.glb" />
      </geometry>
      <material name="hand_left_silver" />
    </visual>
    <collision>
      <origin xyz="0 0 0" rpy="0 0 0" />
      <geometry>
        <mesh filename="../../components/hands/linkerhand_o6/meshes/collision/lh_index_proximal_col.obj" />
      </geometry>
    </collision>
  </link>
  <link name="hand_left_lh_index_distal">
    <inertial>
      <origin xyz="0.00658986616 5.13855642e-06 0.01943936" rpy="0 0 0" />
      <mass value="0.00376951085886838" />
      <inertia ixx="3.22347106085043E-07" ixy="1.3801788663582E-11" ixz="1.14352857317951E-07" iyy="3.65328133721509E-07" iyz="-2.11505011705634E-10" izz="1.24287996386442E-07" />
    </inertial>
    <visual>
      <origin xyz="0 0 0" rpy="0 0 0" />
      <geometry>
        <mesh filename="../../components/hands/linkerhand_o6/meshes/visual/lh_index_distal_vis.glb" />
      </geometry>
      <material name="hand_left_silver" />
    </visual>
    <collision>
      <origin xyz="0 0 0" rpy="0 0 0" />
      <geometry>
        <mesh filename="../../components/hands/linkerhand_o6/meshes/collision/lh_index_distal_col.obj" />
      </geometry>
    </collision>
  </link>
  <link name="hand_left_lh_middle_proximal">
    <inertial>
      <origin xyz="-0.00208660654 2.5691818e-06 0.0172735012" rpy="0 0 0" />
      <mass value="0.00253177375206983" />
      <inertia ixx="2.65989021304483E-07" ixy="-1.69816046635662E-11" ixz="-4.31046683215273E-08" iyy="2.72914402745606E-07" iyz="1.87484652324395E-10" izz="8.5602213431865E-08" />
    </inertial>
    <visual>
      <origin xyz="0 0 0" rpy="0 0 0" />
      <geometry>
        <mesh filename="../../components/hands/linkerhand_o6/meshes/visual/lh_middle_proximal_vis.glb" />
      </geometry>
      <material name="hand_left_silver" />
    </visual>
    <collision>
      <origin xyz="0 0 0" rpy="0 0 0" />
      <geometry>
        <mesh filename="../../components/hands/linkerhand_o6/meshes/collision/lh_middle_proximal_col.obj" />
      </geometry>
    </collision>
  </link>
  <link name="hand_left_lh_middle_distal">
    <inertial>
      <origin xyz="0.00658986516 5.10862924e-06 0.0194393316" rpy="0 0 0" />
      <mass value="0.00376952789210256" />
      <inertia ixx="3.22348591068053E-07" ixy="1.37122394856588E-11" ixz="1.1435291391668E-07" iyy="3.65329535087755E-07" iyz="-2.10453810291991E-10" izz="1.24288425862546E-07" />
    </inertial>
    <visual>
      <origin xyz="0 0 0" rpy="0 0 0" />
      <geometry>
        <mesh filename="../../components/hands/linkerhand_o6/meshes/visual/lh_middle_distal_vis.glb" />
      </geometry>
      <material name="hand_left_silver" />
    </visual>
    <collision>
      <origin xyz="0 0 0" rpy="0 0 0" />
      <geometry>
        <mesh filename="../../components/hands/linkerhand_o6/meshes/collision/lh_middle_distal_col.obj" />
      </geometry>
    </collision>
  </link>
  <link name="hand_left_lh_ring_proximal">
    <inertial>
      <origin xyz="-0.00208667931 2.63000419e-06 0.0172734926" rpy="0 0 0" />
      <mass value="0.00253182223645066" />
      <inertia ixx="2.65989756076584E-07" ixy="-1.74912952703656E-11" ixz="-4.31043325594253E-08" iyy="2.7291510093393E-07" iyz="1.87158326740895E-10" izz="8.56031522765909E-08" />
    </inertial>
    <visual>
      <origin xyz="0 0 0" rpy="0 0 0" />
      <geometry>
        <mesh filename="../../components/hands/linkerhand_o6/meshes/visual/lh_ring_proximal_vis.glb" />
      </geometry>
      <material name="hand_left_silver" />
    </visual>
    <collision>
      <origin xyz="0 0 0" rpy="0 0 0" />
      <geometry>
        <mesh filename="../../components/hands/linkerhand_o6/meshes/collision/lh_ring_proximal_col.obj" />
      </geometry>
    </collision>
  </link>
  <link name="hand_left_lh_ring_distal">
    <inertial>
      <origin xyz="0.00658986649 5.05883528e-06 0.0194393972" rpy="0 0 0" />
      <mass value="0.00376949588316609" />
      <inertia ixx="3.2234524157181E-07" ixy="1.35766976056011E-11" ixz="1.14353011012842E-07" iyy="3.65326570102147E-07" iyz="-2.08672149138738E-10" izz="1.24287770218135E-07" />
    </inertial>
    <visual>
      <origin xyz="0 0 0" rpy="0 0 0" />
      <geometry>
        <mesh filename="../../components/hands/linkerhand_o6/meshes/visual/lh_ring_distal_vis.glb" />
      </geometry>
      <material name="hand_left_silver" />
    </visual>
    <collision>
      <origin xyz="0 0 0" rpy="0 0 0" />
      <geometry>
        <mesh filename="../../components/hands/linkerhand_o6/meshes/collision/lh_ring_distal_col.obj" />
      </geometry>
    </collision>
  </link>
  <link name="hand_left_lh_pinky_proximal">
    <inertial>
      <origin xyz="-0.002086736 2.68062251e-06 0.0172734848" rpy="0 0 0" />
      <mass value="0.00253185993162408" />
      <inertia ixx="2.6599033687183E-07" ixy="-1.79030790016555E-11" ixz="-4.31040829565781E-08" iyy="2.72915617381577E-07" iyz="1.86906787420486E-10" izz="8.56039175034871E-08" />
    </inertial>
    <visual>
      <origin xyz="0 0 0" rpy="0 0 0" />
      <geometry>
        <mesh filename="../../components/hands/linkerhand_o6/meshes/visual/lh_pinky_proximal_vis.glb" />
      </geometry>
      <material name="hand_left_silver" />
    </visual>
    <collision>
      <origin xyz="0 0 0" rpy="0 0 0" />
      <geometry>
        <mesh filename="../../components/hands/linkerhand_o6/meshes/collision/lh_pinky_proximal_col.obj" />
      </geometry>
    </collision>
  </link>
  <link name="hand_left_lh_pinky_distal">
    <inertial>
      <origin xyz="0.00658987589 5.03087534e-06 0.0194394491" rpy="0 0 0" />
      <mass value="0.00376948071276134" />
      <inertia ixx="3.22343583730488E-07" ixy="1.35768173270357E-11" ixz="1.14353289593012E-07" iyy="3.65325180884183E-07" iyz="-2.0744198062439E-10" izz="1.24287567374229E-07" />
    </inertial>
    <visual>
      <origin xyz="0 0 0" rpy="0 0 0" />
      <geometry>
        <mesh filename="../../components/hands/linkerhand_o6/meshes/visual/lh_pinky_distal_vis.glb" />
      </geometry>
      <material name="hand_left_silver" />
    </visual>
    <collision>
      <origin xyz="0 0 0" rpy="0 0 0" />
      <geometry>
        <mesh filename="../../components/hands/linkerhand_o6/meshes/collision/lh_pinky_distal_col.obj" />
      </geometry>
    </collision>
  </link>
  <link name="hand_right_rh_hand_base_link">
    <inertial>
      <origin xyz="-0.00160320773 0.000358462699 0.0538002704" rpy="0 0 0" />
      <mass value="0.06740077960995" />
      <inertia ixx="5.22359941041901E-05" ixy="3.0391535852764E-07" ixz="3.88322215371643E-07" iyy="3.33473043513648E-05" iyz="-7.77555280794861E-07" izz="2.28342677422006E-05" />
    </inertial>
    <visual>
      <origin xyz="0 0 0" rpy="0 0 0" />
      <geometry>
        <mesh filename="../../components/hands/linkerhand_o6/meshes/visual/rh_hand_base_link_vis.glb" />
      </geometry>
      <material name="hand_right_silver" />
    </visual>
    <collision>
      <origin xyz="0 0 0" rpy="0 0 0" />
      <geometry>
        <mesh filename="../../components/hands/linkerhand_o6/meshes/collision/rh_hand_base_link_col.obj" />
      </geometry>
    </collision>
  </link>
  <link name="hand_right_rh_thumb_metacarpals_base2">
    <inertial>
      <origin xyz="0.00162795738 0.00276671978 -0.00184227726" rpy="0 0 0" />
      <mass value="0.00138591070212997" />
      <inertia ixx="5.26294625624223E-08" ixy="-3.9288013799604E-09" ixz="2.43766268199571E-09" iyy="4.82623724532942E-08" iyz="3.71867754115443E-09" izz="2.88555522060562E-08" />
    </inertial>
    <visual>
      <origin xyz="0 0 0" rpy="0 0 0" />
      <geometry>
        <mesh filename="../../components/hands/linkerhand_o6/meshes/visual/rh_thumb_metacarpals_base2_vis.glb" />
      </geometry>
      <material name="hand_right_BlackAccent" />
    </visual>
    <collision>
      <origin xyz="0 0 0" rpy="0 0 0" />
      <geometry>
        <mesh filename="../../components/hands/linkerhand_o6/meshes/collision/rh_thumb_metacarpals_base2_col.obj" />
      </geometry>
    </collision>
  </link>
  <link name="hand_right_rh_thumb_metacarpals">
    <inertial>
      <origin xyz="4.24920613e-05 -1.67885667e-05 0.0228341523" rpy="0 0 0" />
      <mass value="0.0123381607727595" />
      <inertia ixx="1.10292488693766E-06" ixy="-6.14241939151719E-10" ixz="1.14233108676795E-07" iyy="1.76757658485787E-06" iyz="-4.24576599367025E-10" izz="9.36348143657406E-07" />
    </inertial>
    <visual>
      <origin xyz="0 0 0" rpy="0 0 0" />
      <geometry>
        <mesh filename="../../components/hands/linkerhand_o6/meshes/visual/rh_thumb_metacarpals_vis.glb" />
      </geometry>
      <material name="hand_right_silver" />
    </visual>
    <collision>
      <origin xyz="0 0 0" rpy="0 0 0" />
      <geometry>
        <mesh filename="../../components/hands/linkerhand_o6/meshes/collision/rh_thumb_metacarpals_col.obj" />
      </geometry>
    </collision>
  </link>
  <link name="hand_right_rh_thumb_distal">
    <inertial>
      <origin xyz="-0.00413690727 -4.54842793e-07 0.0230097179" rpy="0 0 0" />
      <mass value="0.00763302603723749" />
      <inertia ixx="1.30546842791578E-06" ixy="-2.61617511029467E-12" ixz="7.19030685242407E-08" iyy="1.22457212713176E-06" iyz="1.66931068485225E-11" izz="2.7729897944409E-07" />
    </inertial>
    <visual>
      <origin xyz="0 0 0" rpy="0 0 0" />
      <geometry>
        <mesh filename="../../components/hands/linkerhand_o6/meshes/visual/rh_thumb_distal_vis.glb" />
      </geometry>
      <material name="hand_right_silver" />
    </visual>
    <collision>
      <origin xyz="0 0 0" rpy="0 0 0" />
      <geometry>
        <mesh filename="../../components/hands/linkerhand_o6/meshes/collision/rh_thumb_distal_col.obj" />
      </geometry>
    </collision>
  </link>
  <link name="hand_right_rh_index_proximal">
    <inertial>
      <origin xyz="-0.00208665596 -4.89649906e-06 0.0172736719" rpy="0 0 0" />
      <mass value="0.00253178529301663" />
      <inertia ixx="2.65990159539482E-07" ixy="-3.55165625722842E-11" ixz="4.31046335852167E-08" iyy="2.72915460277804E-07" iyz="1.75935978708959E-10" izz="8.56026306687528E-08" />
    </inertial>
    <visual>
      <origin xyz="0 0 0" rpy="0 0 0" />
      <geometry>
        <mesh filename="../../components/hands/linkerhand_o6/meshes/visual/rh_index_proximal_vis.glb" />
      </geometry>
      <material name="hand_right_silver" />
    </visual>
    <collision>
      <origin xyz="0 0 0" rpy="0 0 0" />
      <geometry>
        <mesh filename="../../components/hands/linkerhand_o6/meshes/collision/rh_index_proximal_col.obj" />
      </geometry>
    </collision>
  </link>
  <link name="hand_right_rh_index_distal">
    <inertial>
      <origin xyz="0.00658940012 -4.59976557e-06 0.0194434136" rpy="0 0 0" />
      <mass value="0.00376787129082313" />
      <inertia ixx="3.22116619426455E-07" ixy="1.03152735699049E-11" ixz="-1.14363506430985E-07" iyy="3.65131844686317E-07" iyz="-1.97263639269362E-10" izz="1.24256890612907E-07" />
    </inertial>
    <visual>
      <origin xyz="0 0 0" rpy="0 0 0" />
      <geometry>
        <mesh filename="../../components/hands/linkerhand_o6/meshes/visual/rh_index_distal_vis.glb" />
      </geometry>
      <material name="hand_right_silver" />
    </visual>
    <collision>
      <origin xyz="0 0 0" rpy="0 0 0" />
      <geometry>
        <mesh filename="../../components/hands/linkerhand_o6/meshes/collision/rh_index_distal_col.obj" />
      </geometry>
    </collision>
  </link>
  <link name="hand_right_rh_middle_proximal">
    <inertial>
      <origin xyz="-0.00208661082 -4.93451838e-06 0.0172736805" rpy="0 0 0" />
      <mass value="0.00253175497594429" />
      <inertia ixx="2.65989683690695E-07" ixy="-3.58343951791586E-11" ixz="4.31048601085216E-08" iyy="2.72915006047006E-07" iyz="1.75718024412593E-10" izz="8.56020467202518E-08" />
    </inertial>
    <visual>
      <origin xyz="0 0 0" rpy="0 0 0" />
      <geometry>
        <mesh filename="../../components/hands/linkerhand_o6/meshes/visual/rh_middle_proximal_vis.glb" />
      </geometry>
      <material name="hand_right_silver" />
    </visual>
    <collision>
      <origin xyz="0 0 0" rpy="0 0 0" />
      <geometry>
        <mesh filename="../../components/hands/linkerhand_o6/meshes/collision/rh_middle_proximal_col.obj" />
      </geometry>
    </collision>
  </link>
  <link name="hand_right_rh_middle_distal">
    <inertial>
      <origin xyz="0.00658940305 -4.58857436e-06 0.0194434523" rpy="0 0 0" />
      <mass value="0.00376786259758948" />
      <inertia ixx="3.221153658306E-07" ixy="1.02639617308432E-11" ixz="-1.14363547272711E-07" iyy="3.65130723083104E-07" iyz="-1.96904618797577E-10" izz="1.24256787913797E-07" />
    </inertial>
    <visual>
      <origin xyz="0 0 0" rpy="0 0 0" />
      <geometry>
        <mesh filename="../../components/hands/linkerhand_o6/meshes/visual/rh_middle_distal_vis.glb" />
      </geometry>
      <material name="hand_right_silver" />
    </visual>
    <collision>
      <origin xyz="0 0 0" rpy="0 0 0" />
      <geometry>
        <mesh filename="../../components/hands/linkerhand_o6/meshes/collision/rh_middle_distal_col.obj" />
      </geometry>
    </collision>
  </link>
  <link name="hand_right_rh_ring_proximal">
    <inertial>
      <origin xyz="-0.00208654311 -4.98538564e-06 0.0172736743" rpy="0 0 0" />
      <mass value="0.00253170963529411" />
      <inertia ixx="2.6598913795678E-07" ixy="-3.62757108675266E-11" ixz="4.31050611555507E-08" iyy="2.72914417061517E-07" iyz="1.75554984053478E-10" izz="8.56012458677515E-08" />
    </inertial>
    <visual>
      <origin xyz="0 0 0" rpy="0 0 0" />
      <geometry>
        <mesh filename="../../components/hands/linkerhand_o6/meshes/visual/rh_ring_proximal_vis.glb" />
      </geometry>
      <material name="hand_right_silver" />
    </visual>
    <collision>
      <origin xyz="0 0 0" rpy="0 0 0" />
      <geometry>
        <mesh filename="../../components/hands/linkerhand_o6/meshes/collision/rh_ring_proximal_col.obj" />
      </geometry>
    </collision>
  </link>
  <link name="hand_right_rh_ring_distal">
    <inertial>
      <origin xyz="0.00658940273 -4.56628864e-06 0.0194435006" rpy="0 0 0" />
      <mass value="0.0037678395356105" />
      <inertia ixx="3.22112632437858E-07" ixy="1.01848408913558E-11" ixz="-1.1436348915342E-07" iyy="3.65128262095686E-07" iyz="-1.96145632992445E-10" izz="1.24256284608064E-07" />
    </inertial>
    <visual>
      <origin xyz="0 0 0" rpy="0 0 0" />
      <geometry>
        <mesh filename="../../components/hands/linkerhand_o6/meshes/visual/rh_ring_distal_vis.glb" />
      </geometry>
      <material name="hand_right_silver" />
    </visual>
    <collision>
      <origin xyz="0 0 0" rpy="0 0 0" />
      <geometry>
        <mesh filename="../../components/hands/linkerhand_o6/meshes/collision/rh_ring_distal_col.obj" />
      </geometry>
    </collision>
  </link>
  <link name="hand_right_rh_pinky_proximal">
    <inertial>
      <origin xyz="-0.00208649034 -5.02314583e-06 0.0172736681" rpy="0 0 0" />
      <mass value="0.00253167400540778" />
      <inertia ixx="2.65988718820404E-07" ixy="-3.66012295280295E-11" ixz="4.31052220484445E-08" iyy="2.72913936904813E-07" iyz="1.75447396222308E-10" izz="8.56006424720129E-08" />
    </inertial>
    <visual>
      <origin xyz="0 0 0" rpy="0 0 0" />
      <geometry>
        <mesh filename="../../components/hands/linkerhand_o6/meshes/visual/rh_pinky_proximal_vis.glb" />
      </geometry>
      <material name="hand_right_silver" />
    </visual>
    <collision>
      <origin xyz="0 0 0" rpy="0 0 0" />
      <geometry>
        <mesh filename="../../components/hands/linkerhand_o6/meshes/collision/rh_pinky_proximal_col.obj" />
      </geometry>
    </collision>
  </link>
  <link name="hand_right_rh_pinky_distal">
    <inertial>
      <origin xyz="0.00658940432 -4.55268314e-06 0.0194435341" rpy="0 0 0" />
      <mass value="0.00376782669873412" />
      <inertia ixx="3.22111112339498E-07" ixy="1.01707985908333E-11" ixz="-1.14363524419061E-07" iyy="3.65126916899176E-07" iyz="-1.95589215866356E-10" izz="1.24256004854426E-07" />
    </inertial>
    <visual>
      <origin xyz="0 0 0" rpy="0 0 0" />
      <geometry>
        <mesh filename="../../components/hands/linkerhand_o6/meshes/visual/rh_pinky_distal_vis.glb" />
      </geometry>
      <material name="hand_right_silver" />
    </visual>
    <collision>
      <origin xyz="0 0 0" rpy="0 0 0" />
      <geometry>
        <mesh filename="../../components/hands/linkerhand_o6/meshes/collision/rh_pinky_distal_col.obj" />
      </geometry>
    </collision>
  </link>
  <joint name="base_cameraBase" type="fixed">
    <origin xyz="0.0335 0.67 1.2974" rpy="-1.5708 0 -1.5708" />
    <parent link="base_workstation_link" />
    <child link="base_camera_base_link" />
    <axis xyz="0 0 0" />
  </joint>
  <joint name="base_cameraJoint" type="fixed">
    <origin xyz="0.0802 0.193139854 -0.275851476" rpy="-1.26599038 -0.643554018 -1.57079633" />
    <parent link="base_camera_base_link" />
    <child link="base_camera" />
    <axis xyz="0 0 0" />
  </joint>
  <joint name="base_weld_workstation_arm_left_mount" type="fixed">
    <origin xyz="0.0637 0.719 1.267" rpy="0 1.57079633 1.57079633" />
    <parent link="base_workstation_link" />
    <child link="base_workstation_arm_left_mount" />
  </joint>
  <joint name="base_weld_workstation_arm_right_mount" type="fixed">
    <origin xyz="0.0637 0.536 1.267" rpy="0 1.57079633 -1.57079633" />
    <parent link="base_workstation_link" />
    <child link="base_workstation_arm_right_mount" />
  </joint>
  <joint name="arm_left_AR5_5_08L_W4C4A6_joint_1" type="revolute">
    <parent link="arm_left_AR5_5_08L_W4C4A6_base" />
    <child link="arm_left_AR5_5_08L_W4C4A6_link1" />
    <limit effort="108" lower="-3.1067" upper="3.1067" velocity="3.0543261909900763" />
    <axis xyz="0 0 1" />
    <origin rpy="-1.5708 0 0" xyz="0 0 0" />
  </joint>
  <joint name="arm_left_AR5_5_08L_W4C4A6_joint_2" type="revolute">
    <parent link="arm_left_AR5_5_08L_W4C4A6_link1" />
    <child link="arm_left_AR5_5_08L_W4C4A6_link2" />
    <limit effort="108" lower="-2.0944" upper="2.0944" velocity="3.0543261909900763" />
    <axis xyz="0 1 0" />
    <origin rpy="0 0 0" xyz="0 0 0.1745" />
  </joint>
  <joint name="arm_left_AR5_5_08L_W4C4A6_joint_3" type="revolute">
    <parent link="arm_left_AR5_5_08L_W4C4A6_link2" />
    <child link="arm_left_AR5_5_08L_W4C4A6_link3" />
    <limit effort="66" lower="-3.1067" upper="3.1067" velocity="4.71238898038469" />
    <axis xyz="0 0 1" />
    <origin rpy="0 0 0" xyz="0 0 0.332" />
  </joint>
  <joint name="arm_left_AR5_5_08L_W4C4A6_joint_4" type="revolute">
    <parent link="arm_left_AR5_5_08L_W4C4A6_link3" />
    <child link="arm_left_AR5_5_08L_W4C4A6_link4" />
    <limit effort="66" lower="-1.0472" upper="2.5307" velocity="5.235987755982989" />
    <axis xyz="0 1 0" />
    <origin rpy="0 0 0" xyz="0.0105 0 0" />
  </joint>
  <joint name="arm_left_AR5_5_08L_W4C4A6_joint_5" type="revolute">
    <parent link="arm_left_AR5_5_08L_W4C4A6_link4" />
    <child link="arm_left_AR5_5_08L_W4C4A6_link5" />
    <limit effort="19" lower="-3.1067" upper="3.1067" velocity="4.1887902047863905" />
    <axis xyz="0 0 1" />
    <origin rpy="0 0 0" xyz="-0.0105 0 0.278" />
  </joint>
  <joint name="arm_left_AR5_5_08L_W4C4A6_joint_6" type="revolute">
    <parent link="arm_left_AR5_5_08L_W4C4A6_link5" />
    <child link="arm_left_AR5_5_08L_W4C4A6_link6" />
    <limit effort="19" lower="-0.9599" upper="0.9599" velocity="4.1887902047863905" />
    <axis xyz="0 1 0" />
    <origin rpy="0 0 0" xyz="0 0 0" />
  </joint>
  <joint name="arm_left_AR5_5_08L_W4C4A6_joint_7" type="revolute">
    <parent link="arm_left_AR5_5_08L_W4C4A6_link6" />
    <child link="arm_left_AR5_5_08L_W4C4A6_link7" />
    <limit effort="19" lower="-0.9599" upper="0.9599" velocity="4.1887902047863905" />
    <axis xyz="1 0 0" />
    <origin rpy="0 0 0" xyz="0 0 0" />
  </joint>
  <joint name="arm_left_AR5_5_08L_W4C4A6_tcp_joint" type="fixed">
    <parent link="arm_left_AR5_5_08L_W4C4A6_link7" />
    <child link="arm_left_AR5_5_08L_W4C4A6_tcp" />
    <origin rpy="0 0 0" xyz="0 0 0.09" />
  </joint>
  <joint name="arm_right_AR5_5_08R_W4C4A6_joint_1" type="revolute">
    <parent link="arm_right_AR5_5_08R_W4C4A6_base" />
    <child link="arm_right_AR5_5_08R_W4C4A6_link1" />
    <limit effort="108" lower="-3.1067" upper="3.1067" velocity="3.0543261909900763" />
    <axis xyz="0 0 1" />
    <origin rpy="1.5708 0 0" xyz="0 0 0" />
  </joint>
  <joint name="arm_right_AR5_5_08R_W4C4A6_joint_2" type="revolute">
    <parent link="arm_right_AR5_5_08R_W4C4A6_link1" />
    <child link="arm_right_AR5_5_08R_W4C4A6_link2" />
    <limit effort="108" lower="-2.0944" upper="2.0944" velocity="3.0543261909900763" />
    <axis xyz="0 1 0" />
    <origin rpy="0 0 0" xyz="0 0 0.1745" />
  </joint>
  <joint name="arm_right_AR5_5_08R_W4C4A6_joint_3" type="revolute">
    <parent link="arm_right_AR5_5_08R_W4C4A6_link2" />
    <child link="arm_right_AR5_5_08R_W4C4A6_link3" />
    <limit effort="66" lower="-3.1067" upper="3.1067" velocity="4.71238898038469" />
    <axis xyz="0 0 1" />
    <origin rpy="0 0 0" xyz="0 0 0.332" />
  </joint>
  <joint name="arm_right_AR5_5_08R_W4C4A6_joint_4" type="revolute">
    <parent link="arm_right_AR5_5_08R_W4C4A6_link3" />
    <child link="arm_right_AR5_5_08R_W4C4A6_link4" />
    <limit effort="66" lower="-1.0472" upper="2.5307" velocity="5.235987755982989" />
    <axis xyz="0 1 0" />
    <origin rpy="0 0 0" xyz="0.0105 0 0" />
  </joint>
  <joint name="arm_right_AR5_5_08R_W4C4A6_joint_5" type="revolute">
    <parent link="arm_right_AR5_5_08R_W4C4A6_link4" />
    <child link="arm_right_AR5_5_08R_W4C4A6_link5" />
    <limit effort="19" lower="-3.1067" upper="3.1067" velocity="4.1887902047863905" />
    <axis xyz="0 0 1" />
    <origin rpy="0 0 0" xyz="-0.0105 0 0.278" />
  </joint>
  <joint name="arm_right_AR5_5_08R_W4C4A6_joint_6" type="revolute">
    <parent link="arm_right_AR5_5_08R_W4C4A6_link5" />
    <child link="arm_right_AR5_5_08R_W4C4A6_link6" />
    <limit effort="19" lower="-0.9599" upper="0.9599" velocity="4.1887902047863905" />
    <axis xyz="0 1 0" />
    <origin rpy="0 0 0" xyz="0 0 0" />
  </joint>
  <joint name="arm_right_AR5_5_08R_W4C4A6_joint_7" type="revolute">
    <parent link="arm_right_AR5_5_08R_W4C4A6_link6" />
    <child link="arm_right_AR5_5_08R_W4C4A6_link7" />
    <limit effort="19" lower="-0.9599" upper="0.9599" velocity="4.1887902047863905" />
    <axis xyz="1 0 0" />
    <origin rpy="0 0 0" xyz="0 0 0" />
  </joint>
  <joint name="arm_right_AR5_5_08R_W4C4A6_tcp_joint" type="fixed">
    <parent link="arm_right_AR5_5_08R_W4C4A6_link7" />
    <child link="arm_right_AR5_5_08R_W4C4A6_tcp" />
    <origin rpy="0 0 0" xyz="0 0 0.09" />
  </joint>
  <joint name="hand_left_lh_thumb_cmc_yaw" type="revolute">
    <origin xyz="0.0115084536 -0.022975 0.030794" rpy="1.57079633 0 0" />
    <parent link="hand_left_lh_hand_base_link" />
    <child link="hand_left_lh_thumb_metacarpals_base2" />
    <axis xyz="0 1 0" />
    <limit lower="0" upper="1.3" effort="100" velocity="1" />
  </joint>
  <joint name="hand_left_lh_thumb_cmc_pitch" type="revolute">
    <origin xyz="0.00915604684 -0.00603785696 0.0158587383" rpy="-0.575786024 -0.407073695 -1.31922273" />
    <parent link="hand_left_lh_thumb_metacarpals_base2" />
    <child link="hand_left_lh_thumb_metacarpals" />
    <axis xyz="0 -1 0" />
    <limit lower="0" upper="0.58" effort="100" velocity="1" />
  </joint>
  <joint name="hand_left_lh_thumb_ip" type="revolute">
    <origin xyz="0 0 0.036812" rpy="0 0 0" />
    <parent link="hand_left_lh_thumb_metacarpals" />
    <child link="hand_left_lh_thumb_distal" />
    <axis xyz="0 -1 0" />
    <limit lower="0" upper="1.08" effort="100" velocity="1" />
    <mimic joint="hand_left_lh_thumb_cmc_pitch" multiplier="1.8788" offset="0" />
  </joint>
  <joint name="hand_left_lh_index_mcp_pitch" type="revolute">
    <origin xyz="0.0024758 -0.02419 0.098779" rpy="0.05236 0 0" />
    <parent link="hand_left_lh_hand_base_link" />
    <child link="hand_left_lh_index_proximal" />
    <axis xyz="0 1 0" />
    <limit lower="0" upper="1.60" effort="100" velocity="1" />
  </joint>
  <joint name="hand_left_lh_index_dip" type="revolute">
    <origin xyz="-0.0052516 0 0.036625" rpy="0 0 0" />
    <parent link="hand_left_lh_index_proximal" />
    <child link="hand_left_lh_index_distal" />
    <axis xyz="0 1 0" />
    <limit lower="0" upper="1.43" effort="100" velocity="1" />
    <mimic joint="hand_left_lh_index_mcp_pitch" multiplier="0.89" offset="0" />
  </joint>
  <joint name="hand_left_lh_middle_mcp_pitch" type="revolute">
    <origin xyz="0.00052576 -0.00634 0.1027" rpy="0 0 0" />
    <parent link="hand_left_lh_hand_base_link" />
    <child link="hand_left_lh_middle_proximal" />
    <axis xyz="0 1 0" />
    <limit lower="0" upper="1.60" effort="100" velocity="1" />
  </joint>
  <joint name="hand_left_lh_middle_dip" type="revolute">
    <origin xyz="-0.0052516 0 0.036625" rpy="0 0 0" />
    <parent link="hand_left_lh_middle_proximal" />
    <child link="hand_left_lh_middle_distal" />
    <axis xyz="0 1 0" />
    <limit lower="0" upper="1.43" effort="100" velocity="1" />
    <mimic joint="hand_left_lh_middle_mcp_pitch" multiplier="0.89" offset="0" />
  </joint>
  <joint name="hand_left_lh_ring_mcp_pitch" type="revolute">
    <origin xyz="0.0010258 0.011135 0.098767" rpy="-0.05236 0 0" />
    <parent link="hand_left_lh_hand_base_link" />
    <child link="hand_left_lh_ring_proximal" />
    <axis xyz="0 1 0" />
    <limit lower="0" upper="1.60" effort="100" velocity="1" />
  </joint>
  <joint name="hand_left_lh_ring_dip" type="revolute">
    <origin xyz="-0.0052516 0 0.036625" rpy="0 0 0" />
    <parent link="hand_left_lh_ring_proximal" />
    <child link="hand_left_lh_ring_distal" />
    <axis xyz="0 1 0" />
    <limit lower="0" upper="1.43" effort="100" velocity="1" />
    <mimic joint="hand_left_lh_ring_mcp_pitch" multiplier="0.89" offset="0" />
  </joint>
  <joint name="hand_left_lh_pinky_mcp_pitch" type="revolute">
    <origin xyz="0.0024758 0.028372 0.092741" rpy="-0.087266 0 0" />
    <parent link="hand_left_lh_hand_base_link" />
    <child link="hand_left_lh_pinky_proximal" />
    <axis xyz="0 1 0" />
    <limit lower="0" upper="1.60" effort="100" velocity="1" />
  </joint>
  <joint name="hand_left_lh_pinky_dip" type="revolute">
    <origin xyz="-0.0052516 0 0.036625" rpy="0 0 0" />
    <parent link="hand_left_lh_pinky_proximal" />
    <child link="hand_left_lh_pinky_distal" />
    <axis xyz="0 1 0" />
    <limit lower="0" upper="1.43" effort="100" velocity="1" />
    <mimic joint="hand_left_lh_pinky_mcp_pitch" multiplier="0.89" offset="0" />
  </joint>
  <joint name="hand_right_rh_thumb_cmc_yaw" type="revolute">
    <origin xyz="0.011508 0.022975 0.032794" rpy="0 0 0" />
    <parent link="hand_right_rh_hand_base_link" />
    <child link="hand_right_rh_thumb_metacarpals_base2" />
    <axis xyz="0 0 -1" />
    <limit lower="0" upper="1.36" effort="100" velocity="1" />
  </joint>
  <joint name="hand_right_rh_thumb_cmc_pitch" type="revolute">
    <origin xyz="0.0061649 0.010678 -0.004891" rpy="0 -1.1529 -2.0944" />
    <parent link="hand_right_rh_thumb_metacarpals_base2" />
    <child link="hand_right_rh_thumb_metacarpals" />
    <axis xyz="0 1 0" />
    <limit lower="0" upper="0.58" effort="100" velocity="1" />
  </joint>
  <joint name="hand_right_rh_thumb_ip" type="revolute">
    <origin xyz="0.0037776 0 0.045368" rpy="0 0 0" />
    <parent link="hand_right_rh_thumb_metacarpals" />
    <child link="hand_right_rh_thumb_distal" />
    <axis xyz="0 1 0" />
    <limit lower="0" upper="1.08" effort="100" velocity="1" />
    <mimic joint="hand_right_rh_thumb_cmc_pitch" multiplier="1.86" offset="0" />
  </joint>
  <joint name="hand_right_rh_index_mcp_pitch" type="revolute">
    <origin xyz="0.0024758 0.02419 0.098779" rpy="-0.05236 0 0" />
    <parent link="hand_right_rh_hand_base_link" />
    <child link="hand_right_rh_index_proximal" />
    <axis xyz="0 1 0" />
    <limit lower="0" upper="1.60" effort="100" velocity="1" />
  </joint>
  <joint name="hand_right_rh_index_dip" type="revolute">
    <origin xyz="-0.0052516 0 0.036625" rpy="0 0 0" />
    <parent link="hand_right_rh_index_proximal" />
    <child link="hand_right_rh_index_distal" />
    <axis xyz="0 1 0" />
    <limit lower="0" upper="1.43" effort="100" velocity="1" />
    <mimic joint="hand_right_rh_index_mcp_pitch" multiplier="0.89" offset="0" />
  </joint>
  <joint name="hand_right_rh_middle_mcp_pitch" type="revolute">
    <origin xyz="0.00052576 0.00634 0.1027" rpy="0 0 0" />
    <parent link="hand_right_rh_hand_base_link" />
    <child link="hand_right_rh_middle_proximal" />
    <axis xyz="0 1 0" />
    <limit lower="0" upper="1.60" effort="100" velocity="1" />
  </joint>
  <joint name="hand_right_rh_middle_dip" type="revolute">
    <origin xyz="-0.0052516 0 0.036625" rpy="0 0 0" />
    <parent link="hand_right_rh_middle_proximal" />
    <child link="hand_right_rh_middle_distal" />
    <axis xyz="0 1 0" />
    <limit lower="0" upper="1.43" effort="100" velocity="1" />
    <mimic joint="hand_right_rh_middle_mcp_pitch" multiplier="0.89" offset="0" />
  </joint>
  <joint name="hand_right_rh_ring_mcp_pitch" type="revolute">
    <origin xyz="0.0010258 -0.011135 0.098767" rpy="0.05236 0 0" />
    <parent link="hand_right_rh_hand_base_link" />
    <child link="hand_right_rh_ring_proximal" />
    <axis xyz="0 1 0" />
    <limit lower="0" upper="1.60" effort="100" velocity="1" />
  </joint>
  <joint name="hand_right_rh_ring_dip" type="revolute">
    <origin xyz="-0.0052516 0 0.036625" rpy="0 0 0" />
    <parent link="hand_right_rh_ring_proximal" />
    <child link="hand_right_rh_ring_distal" />
    <axis xyz="0 1 0" />
    <limit lower="0" upper="1.43" effort="100" velocity="1" />
    <mimic joint="hand_right_rh_ring_mcp_pitch" multiplier="0.89" offset="0" />
  </joint>
  <joint name="hand_right_rh_pinky_mcp_pitch" type="revolute">
    <origin xyz="0.0024758 -0.028372 0.092741" rpy="0.087266 0 0" />
    <parent link="hand_right_rh_hand_base_link" />
    <child link="hand_right_rh_pinky_proximal" />
    <axis xyz="0 1 0" />
    <limit lower="0" upper="1.60" effort="100" velocity="1" />
  </joint>
  <joint name="hand_right_rh_pinky_dip" type="revolute">
    <origin xyz="-0.0052516 0 0.036625" rpy="0 0 0" />
    <parent link="hand_right_rh_pinky_proximal" />
    <child link="hand_right_rh_pinky_distal" />
    <axis xyz="0 1 0" />
    <limit lower="0" upper="1.43" effort="100" velocity="1" />
    <mimic joint="hand_right_rh_pinky_mcp_pitch" multiplier="0.89" offset="0" />
  </joint>
  <joint name="mount_arm_left_to_base_base_mount" type="fixed">
    <origin xyz="0 0 0" rpy="1.5708 0 -1.5708" />
    <parent link="base_workstation_arm_left_mount" />
    <child link="arm_left_AR5_5_08L_W4C4A6_base" />
  </joint>
  <joint name="mount_arm_right_to_base_base_mount" type="fixed">
    <origin xyz="0 0 0" rpy="-1.5708 0 1.5708" />
    <parent link="base_workstation_arm_right_mount" />
    <child link="arm_right_AR5_5_08R_W4C4A6_base" />
  </joint>
  <joint name="mount_hand_left_to_arm_left_wrist_mount" type="fixed">
    <origin xyz="0 0 -0.038" rpy="3.1416 0 -1.5708" />
    <parent link="arm_left_AR5_5_08L_W4C4A6_tcp" />
    <child link="hand_left_lh_hand_base_link" />
  </joint>
  <joint name="mount_hand_right_to_arm_right_wrist_mount" type="fixed">
    <origin xyz="0 0 -0.038" rpy="3.1416 0 1.5708" />
    <parent link="arm_right_AR5_5_08R_W4C4A6_tcp" />
    <child link="hand_right_rh_hand_base_link" />
  </joint>
  <joint name="mount_world_to_base" type="fixed">
    <origin xyz="0 0 0" rpy="0 0 0" />
    <parent link="world" />
    <child link="base_workstation_link" />
  </joint>
  <mujoco>
    <compiler meshdir="." balanceinertia="true" discardvisual="true" />
    <default>
      <joint armature="3.4707e-08" damping="5.0" frictionloss="0.5" />
    </default>
    <equality>
      <joint name="hand_left_lh_couple_thumb" joint1="hand_left_lh_thumb_ip" joint2="hand_left_lh_thumb_cmc_pitch" polycoef="0 1.8788 0 0 0 0" />
      <joint name="hand_left_lh_couple_index" joint1="hand_left_lh_index_dip" joint2="hand_left_lh_index_mcp_pitch" polycoef="0 0.89 0 0 0 0" />
      <joint name="hand_left_lh_couple_middle" joint1="hand_left_lh_middle_dip" joint2="hand_left_lh_middle_mcp_pitch" polycoef="0 0.89 0 0 0 0" />
      <joint name="hand_left_lh_couple_ring" joint1="hand_left_lh_ring_dip" joint2="hand_left_lh_ring_mcp_pitch" polycoef="0 0.89 0 0 0 0" />
      <joint name="hand_left_lh_couple_pinky" joint1="hand_left_lh_pinky_dip" joint2="hand_left_lh_pinky_mcp_pitch" polycoef="0 0.89 0 0 0 0" />
    </equality>
  </mujoco>
  <mujoco>
    <default>
      <joint armature="3.4707e-08" damping="5.0" frictionloss="0.5" />
    </default>
    <equality>
      <joint name="hand_right_rh_couple_thumb" joint1="hand_right_rh_thumb_ip" joint2="hand_right_rh_thumb_cmc_pitch" polycoef="0 1.86 0 0 0 0" />
      <joint name="hand_right_rh_couple_index" joint1="hand_right_rh_index_dip" joint2="hand_right_rh_index_mcp_pitch" polycoef="0 0.89 0 0 0 0" />
      <joint name="hand_right_rh_couple_middle" joint1="hand_right_rh_middle_dip" joint2="hand_right_rh_middle_mcp_pitch" polycoef="0 0.89 0 0 0 0" />
      <joint name="hand_right_rh_couple_ring" joint1="hand_right_rh_ring_dip" joint2="hand_right_rh_ring_mcp_pitch" polycoef="0 0.89 0 0 0 0" />
      <joint name="hand_right_rh_couple_pinky" joint1="hand_right_rh_pinky_dip" joint2="hand_right_rh_pinky_mcp_pitch" polycoef="0 0.89 0 0 0 0" />
    </equality>
  </mujoco>
</robot>
