<?xml version="1.0" encoding="UTF-8"?>
<!-- Generated by linker_robot_assets.composer (version 0.1.0). Workstation: a7_lite_l20lite_dc. Recipe sha256: 20d6c79abaefa963c01c961b9b7b879762da657f8e1bda6956e7199befc812b5. Do not edit by hand; re-run `python -m linker_robot_assets.composer.compose <workstation>`. -->
<robot name="a7_lite_l20lite_dc">
  <link name="world" />
  <link name="base_torso_root" />
  <link name="base_base_link">
    <inertial>
      <origin xyz="0.0044493 9.5996e-07 -0.58827" rpy="0 0 0" />
      <mass value="8.6616" />
      <inertia ixx="0.19297" ixy="1.6977E-06" ixz="0.00086704" iyy="0.19297" iyz="4.1272E-08" izz="0.072594" />
    </inertial>
    <visual>
      <origin xyz="0 0 0" rpy="0 0 0" />
      <geometry>
        <mesh filename="../../components/bases/a7_lite_torso/variants/default/meshes/base_link.STL" />
      </geometry>
      <material name="base_a7_lite_torso_gray">
        <color rgba="0.75294 0.75294 0.75294 1" />
      </material>
    </visual>
    <collision>
      <origin xyz="0 0 0" rpy="0 0 0" />
      <geometry>
        <mesh filename="../../components/bases/a7_lite_torso/variants/default/meshes/base_link.STL" />
      </geometry>
    </collision>
  </link>
  <link name="base_arm_left_mount" />
  <link name="base_arm_right_mount" />
  <link name="arm_left_L_arm_root" />
  <link name="arm_left_L1_Link">
    <inertial>
      <origin xyz="0.0045974 0.067978 0.00066635" rpy="0 0 0" />
      <mass value="1.1899" />
      <inertia ixx="0.0016082" ixy="3.5266E-06" ixz="2.0532E-07" iyy="0.00086283" iyz="6.5642E-06" izz="0.00092662" />
    </inertial>
    <visual>
      <origin xyz="0 0 0" rpy="0 0 0" />
      <geometry>
        <mesh filename="../../components/arms/a7_lite/variants/left/meshes/L1_Link.STL" />
      </geometry>
      <material name="">
        <color rgba="0.75294 0.75294 0.75294 1" />
      </material>
    </visual>
    <collision>
      <origin xyz="0 0 0" rpy="0 0 0" />
      <geometry>
        <mesh filename="../../components/arms/a7_lite/variants/left/meshes/L1_Link.STL" />
      </geometry>
    </collision>
  </link>
  <link name="arm_left_L2_Link">
    <inertial>
      <origin xyz="-0.030894 9.2644e-05 -0.099437" rpy="0 0 0" />
      <mass value="1.0659" />
      <inertia ixx="0.001451" ixy="3.1371E-06" ixz="-1.519E-06" iyy="0.0012495" iyz="-1.1542E-05" izz="0.0010752" />
    </inertial>
    <visual>
      <origin xyz="0 0 0" rpy="0 0 0" />
      <geometry>
        <mesh filename="../../components/arms/a7_lite/variants/left/meshes/L2_Link.STL" />
      </geometry>
      <material name="">
        <color rgba="0.75294 0.75294 0.75294 1" />
      </material>
    </visual>
    <collision>
      <origin xyz="0 0 0" rpy="0 0 0" />
      <geometry>
        <mesh filename="../../components/arms/a7_lite/variants/left/meshes/L2_Link.STL" />
      </geometry>
    </collision>
  </link>
  <link name="arm_left_L3_Link">
    <inertial>
      <origin xyz="-5.9577e-05 0.001318 -0.078466" rpy="0 0 0" />
      <mass value="1.2763" />
      <inertia ixx="0.00078242" ixy="-2.9327E-07" ixz="7.1339E-06" iyy="0.0010444" iyz="-2.978E-07" izz="0.00063166" />
    </inertial>
    <visual>
      <origin xyz="0 0 0" rpy="0 0 0" />
      <geometry>
        <mesh filename="../../components/arms/a7_lite/variants/left/meshes/L3_Link.STL" />
      </geometry>
      <material name="">
        <color rgba="0.75294 0.75294 0.75294 1" />
      </material>
    </visual>
    <collision>
      <origin xyz="0 0 0" rpy="0 0 0" />
      <geometry>
        <mesh filename="../../components/arms/a7_lite/variants/left/meshes/L3_Link.STL" />
      </geometry>
    </collision>
  </link>
  <link name="arm_left_L4_Link">
    <inertial>
      <origin xyz="1.6127e-05 -0.027094 -0.086199" rpy="0 0 0" />
      <mass value="0.66812" />
      <inertia ixx="0.00039892" ixy="5.379E-08" ixz="1.7668E-06" iyy="0.00038456" iyz="1.0506E-06" izz="0.00041366" />
    </inertial>
    <visual>
      <origin xyz="0 0 0" rpy="0 0 0" />
      <geometry>
        <mesh filename="../../components/arms/a7_lite/variants/left/meshes/L4_Link.STL" />
      </geometry>
      <material name="">
        <color rgba="0.75294 0.75294 0.75294 1" />
      </material>
    </visual>
    <collision>
      <origin xyz="0 0 0" rpy="0 0 0" />
      <geometry>
        <mesh filename="../../components/arms/a7_lite/variants/left/meshes/L4_Link.STL" />
      </geometry>
    </collision>
  </link>
  <link name="arm_left_L5_Link">
    <inertial>
      <origin xyz="-0.00012977 0.0029474 -0.03886" rpy="0 0 0" />
      <mass value="0.4439" />
      <inertia ixx="0.00015511" ixy="-4.6133E-07" ixz="-2.6472E-06" iyy="0.00022136" iyz="-1.0454E-07" izz="0.00013737" />
    </inertial>
    <visual>
      <origin xyz="0 0 0" rpy="0 0 0" />
      <geometry>
        <mesh filename="../../components/arms/a7_lite/variants/left/meshes/L5_Link.STL" />
      </geometry>
      <material name="">
        <color rgba="0.75294 0.75294 0.75294 1" />
      </material>
    </visual>
    <collision>
      <origin xyz="0 0 0" rpy="0 0 0" />
      <geometry>
        <mesh filename="../../components/arms/a7_lite/variants/left/meshes/L5_Link.STL" />
      </geometry>
    </collision>
  </link>
  <link name="arm_left_L6_Link">
    <inertial>
      <origin xyz="0.0023746 -0.027691 -0.063927" rpy="0 0 0" />
      <mass value="0.5193" />
      <inertia ixx="0.00031746" ixy="-6.3455E-07" ixz="4.1005E-07" iyy="0.00024364" iyz="2.8635E-06" izz="0.00015858" />
    </inertial>
    <visual>
      <origin xyz="0 0 0" rpy="0 0 0" />
      <geometry>
        <mesh filename="../../components/arms/a7_lite/variants/left/meshes/L6_Link.STL" />
      </geometry>
      <material name="">
        <color rgba="0.75294 0.75294 0.75294 1" />
      </material>
    </visual>
    <collision>
      <origin xyz="0 0 0" rpy="0 0 0" />
      <geometry>
        <mesh filename="../../components/arms/a7_lite/variants/left/meshes/L6_Link.STL" />
      </geometry>
    </collision>
  </link>
  <link name="arm_left_L7_Link">
    <inertial>
      <origin xyz="-0.026398 -6.6336e-15 -0.025801" rpy="0 0 0" />
      <mass value="0.10175" />
      <inertia ixx="4.5036E-05" ixy="-4.7046E-12" ixz="2.2349E-07" iyy="3.8663E-05" iyz="-1.9234E-20" izz="3.0632E-05" />
    </inertial>
    <visual>
      <origin xyz="0 0 0" rpy="0 0 0" />
      <geometry>
        <mesh filename="../../components/arms/a7_lite/variants/left/meshes/L7_Link.STL" />
      </geometry>
      <material name="">
        <color rgba="0.75294 0.75294 0.75294 1" />
      </material>
    </visual>
    <collision>
      <origin xyz="0 0 0" rpy="0 0 0" />
      <geometry>
        <mesh filename="../../components/arms/a7_lite/variants/left/meshes/L7_Link.STL" />
      </geometry>
    </collision>
  </link>
  <link name="arm_right_R_arm_root" />
  <link name="arm_right_R1_Link">
    <inertial>
      <origin xyz="0.004598 -0.067915 0.00072736" rpy="0 0 0" />
      <mass value="1.1899" />
      <inertia ixx="0.0016082" ixy="-3.3435E-06" ixz="3.9187E-07" iyy="0.00086157" iyz="-6.5828E-06" izz="0.00092788" />
    </inertial>
    <visual>
      <origin xyz="0 0 0" rpy="0 0 0" />
      <geometry>
        <mesh filename="../../components/arms/a7_lite/variants/right/meshes/R1_Link.STL" />
      </geometry>
      <material name="">
        <color rgba="0.75294 0.75294 0.75294 1" />
      </material>
    </visual>
    <collision>
      <origin xyz="0 0 0" rpy="0 0 0" />
      <geometry>
        <mesh filename="../../components/arms/a7_lite/variants/right/meshes/R1_Link.STL" />
      </geometry>
    </collision>
  </link>
  <link name="arm_right_R2_Link">
    <inertial>
      <origin xyz="-0.031363 2.7784e-05 -0.099445" rpy="0 0 0" />
      <mass value="1.0663" />
      <inertia ixx="0.0014523" ixy="-8.9962E-07" ixz="-1.031E-06" iyy="0.0012484" iyz="1.1436E-05" izz="0.0010754" />
    </inertial>
    <visual>
      <origin xyz="0 0 0" rpy="0 0 0" />
      <geometry>
        <mesh filename="../../components/arms/a7_lite/variants/right/meshes/R2_Link.STL" />
      </geometry>
      <material name="">
        <color rgba="0.75294 0.75294 0.75294 1" />
      </material>
    </visual>
    <collision>
      <origin xyz="0 0 0" rpy="0 0 0" />
      <geometry>
        <mesh filename="../../components/arms/a7_lite/variants/right/meshes/R2_Link.STL" />
      </geometry>
    </collision>
  </link>
  <link name="arm_right_R3_Link">
    <inertial>
      <origin xyz="-2.2895e-05 -0.00123 -0.077166" rpy="0 0 0" />
      <mass value="1.3517" />
      <inertia ixx="0.00080502" ixy="2.8702E-07" ixz="7.1845E-06" iyy="0.0010686" iyz="-7.5659E-07" izz="0.00067469" />
    </inertial>
    <visual>
      <origin xyz="0 0 0" rpy="0 0 0" />
      <geometry>
        <mesh filename="../../components/arms/a7_lite/variants/right/meshes/R3_Link.STL" />
      </geometry>
      <material name="">
        <color rgba="0.75294 0.75294 0.75294 1" />
      </material>
    </visual>
    <collision>
      <origin xyz="0 0 0" rpy="0 0 0" />
      <geometry>
        <mesh filename="../../components/arms/a7_lite/variants/right/meshes/R3_Link.STL" />
      </geometry>
    </collision>
  </link>
  <link name="arm_right_R4_Link">
    <inertial>
      <origin xyz="1.2714e-05 0.024908 -0.082641" rpy="0 0 0" />
      <mass value="0.69691" />
      <inertia ixx="0.00041505" ixy="5.3251E-08" ixz="1.7254E-06" iyy="0.00041627" iyz="3.826E-07" izz="0.00043007" />
    </inertial>
    <visual>
      <origin xyz="0 0 0" rpy="0 0 0" />
      <geometry>
        <mesh filename="../../components/arms/a7_lite/variants/right/meshes/R4_Link.STL" />
      </geometry>
      <material name="">
        <color rgba="0.75294 0.75294 0.75294 1" />
      </material>
    </visual>
    <collision>
      <origin xyz="0 0 0" rpy="0 0 0" />
      <geometry>
        <mesh filename="../../components/arms/a7_lite/variants/right/meshes/R4_Link.STL" />
      </geometry>
    </collision>
  </link>
  <link name="arm_right_R5_Link">
    <inertial>
      <origin xyz="0.00029153 -0.0027009 -0.035875" rpy="0 0 0" />
      <mass value="0.48527" />
      <inertia ixx="0.00016555" ixy="-5.747E-07" ixz="-2.6985E-06" iyy="0.00022756" iyz="-9.211E-07" izz="0.00015289" />
    </inertial>
    <visual>
      <origin xyz="0 0 0" rpy="0 0 0" />
      <geometry>
        <mesh filename="../../components/arms/a7_lite/variants/right/meshes/R5_Link.STL" />
      </geometry>
      <material name="">
        <color rgba="0.75294 0.75294 0.75294 1" />
      </material>
    </visual>
    <collision>
      <origin xyz="0 0 0" rpy="0 0 0" />
      <geometry>
        <mesh filename="../../components/arms/a7_lite/variants/right/meshes/R5_Link.STL" />
      </geometry>
    </collision>
  </link>
  <link name="arm_right_R6_Link">
    <inertial>
      <origin xyz="0.0023746 0.027704 -0.063949" rpy="0 0 0" />
      <mass value="0.5193" />
      <inertia ixx="0.00031746" ixy="6.3467E-07" ixz="4.1001E-07" iyy="0.00024364" iyz="-2.8219E-06" izz="0.00015858" />
    </inertial>
    <visual>
      <origin xyz="0 0 0" rpy="0 0 0" />
      <geometry>
        <mesh filename="../../components/arms/a7_lite/variants/right/meshes/R6_Link.STL" />
      </geometry>
      <material name="">
        <color rgba="0.75294 0.75294 0.75294 1" />
      </material>
    </visual>
    <collision>
      <origin xyz="0 0 0" rpy="0 0 0" />
      <geometry>
        <mesh filename="../../components/arms/a7_lite/variants/right/meshes/R6_Link.STL" />
      </geometry>
    </collision>
  </link>
  <link name="arm_right_R7_Link">
    <inertial>
      <origin xyz="-0.026598 3.7248e-14 -0.025801" rpy="0 0 0" />
      <mass value="0.10175" />
      <inertia ixx="4.5036E-05" ixy="-4.7046E-12" ixz="2.2349E-07" iyy="3.8663E-05" iyz="-1.5968E-20" izz="3.0632E-05" />
    </inertial>
    <visual>
      <origin xyz="0 0 0" rpy="0 0 0" />
      <geometry>
        <mesh filename="../../components/arms/a7_lite/variants/right/meshes/R7_Link.STL" />
      </geometry>
      <material name="">
        <color rgba="0.75294 0.75294 0.75294 1" />
      </material>
    </visual>
    <collision>
      <origin xyz="0 0 0" rpy="0 0 0" />
      <geometry>
        <mesh filename="../../components/arms/a7_lite/variants/right/meshes/R7_Link.STL" />
      </geometry>
    </collision>
  </link>
  <link name="hand_left_lh_hand_base_link">
    <inertial>
      <origin xyz="-0.00378861347 0.00082020445 0.0805686616" rpy="0 0 0" />
      <mass value="0.103652479414672" />
      <inertia ixx="0.000193076183440551" ixy="1.28622350247875e-06" ixz="-2.06064564153793e-07" iyy="0.000129262885172737" iyz="-2.33887125894354e-06" izz="7.7154522927273e-05" />
    </inertial>
    <visual>
      <origin xyz="0 0 0" rpy="0 0 0" />
      <geometry>
        <mesh filename="../../components/hands/linkerhand_l20lite/variants/left/meshes/hand_base_link.STL" />
      </geometry>
      <material name="">
        <color rgba="1 1 1 1" />
      </material>
    </visual>
    <collision>
      <origin xyz="0 0 0" rpy="0 0 0" />
      <geometry>
        <mesh filename="../../components/hands/linkerhand_l20lite/variants/left/meshes/hand_base_link.STL" />
      </geometry>
    </collision>
  </link>
  <link name="hand_left_lh_thumb_metacarpals_base1">
    <inertial>
      <origin xyz="0.0284841419 0.00323280531 1.27102542e-05" rpy="0 0 0" />
      <mass value="0.00840514828448049" />
      <inertia ixx="1.40225690783513e-06" ixy="1.196162690714e-07" ixz="7.34629714950971e-09" iyy="9.92532738625187e-07" iyz="-4.63982709938509e-08" izz="7.25924523731736e-07" />
    </inertial>
    <visual>
      <origin xyz="0 0 0" rpy="0 0 0" />
      <geometry>
        <mesh filename="../../components/hands/linkerhand_l20lite/variants/left/meshes/thumb_metacarpals_base1.STL" />
      </geometry>
      <material name="">
        <color rgba="1 1 1 1" />
      </material>
    </visual>
    <collision>
      <origin xyz="0 0 0" rpy="0 0 0" />
      <geometry>
        <mesh filename="../../components/hands/linkerhand_l20lite/variants/left/meshes/thumb_metacarpals_base1.STL" />
      </geometry>
    </collision>
  </link>
  <link name="hand_left_lh_thumb_metacarpals_base2">
    <inertial>
      <origin xyz="0.00149333647 -0.00615813218 -0.000273768129" rpy="0 0 0" />
      <mass value="0.00244725656099355" />
      <inertia ixx="1.15757169903916e-07" ixy="-4.50060051446398e-09" ixz="-9.19744539328016e-10" iyy="9.88121769947347e-08" iyz="3.81969206030993e-09" izz="6.88506418885536e-08" />
    </inertial>
    <visual>
      <origin xyz="0 0 0" rpy="0 0 0" />
      <geometry>
        <mesh filename="../../components/hands/linkerhand_l20lite/variants/left/meshes/thumb_metacarpals_base2.STL" />
      </geometry>
      <material name="">
        <color rgba="1 1 1 1" />
      </material>
    </visual>
    <collision>
      <origin xyz="0 0 0" rpy="0 0 0" />
      <geometry>
        <mesh filename="../../components/hands/linkerhand_l20lite/variants/left/meshes/thumb_metacarpals_base2.STL" />
      </geometry>
    </collision>
  </link>
  <link name="hand_left_lh_thumb_metacarpals">
    <inertial>
      <origin xyz="0.0018366373 3.46162461e-06 0.0269904122" rpy="0 0 0" />
      <mass value="0.0152011788694593" />
      <inertia ixx="2.95369587925714e-06" ixy="4.74536745194236e-11" ixz="-1.58087239939667e-07" iyy="3.84770419198789e-06" iyz="4.13672896569864e-10" izz="1.32008560539723e-06" />
    </inertial>
    <visual>
      <origin xyz="0 0 0" rpy="0 0 0" />
      <geometry>
        <mesh filename="../../components/hands/linkerhand_l20lite/variants/left/meshes/thumb_metacarpals.STL" />
      </geometry>
      <material name="">
        <color rgba="1 1 1 1" />
      </material>
    </visual>
    <collision>
      <origin xyz="0 0 0" rpy="0 0 0" />
      <geometry>
        <mesh filename="../../components/hands/linkerhand_l20lite/variants/left/meshes/thumb_metacarpals.STL" />
      </geometry>
    </collision>
  </link>
  <link name="hand_left_lh_thumb_proximal">
    <inertial>
      <origin xyz="0.00159260267 4.28988977e-06 0.0151572309" rpy="0 0 0" />
      <mass value="0.00662225085289633" />
      <inertia ixx="1.01526328949763e-06" ixy="-7.87460584199835e-12" ixz="-4.4224308859969e-08" iyy="9.10425089721739e-07" iyz="2.81833762972893e-11" izz="4.47462917464685e-07" />
    </inertial>
    <visual>
      <origin xyz="0 0 0" rpy="0 0 0" />
      <geometry>
        <mesh filename="../../components/hands/linkerhand_l20lite/variants/left/meshes/thumb_proximal.STL" />
      </geometry>
      <material name="">
        <color rgba="1 1 1 1" />
      </material>
    </visual>
    <collision>
      <origin xyz="0 0 0" rpy="0 0 0" />
      <geometry>
        <mesh filename="../../components/hands/linkerhand_l20lite/variants/left/meshes/thumb_proximal.STL" />
      </geometry>
    </collision>
  </link>
  <link name="hand_left_lh_thumb_distal">
    <inertial>
      <origin xyz="-0.00138833979 -1.92768111e-06 0.0115764513" rpy="0 0 0" />
      <mass value="0.00512798334000111" />
      <inertia ixx="3.30808161248092e-07" ixy="-3.43833611720834e-10" ixz="-1.04696624534012e-07" iyy="3.2363078244428e-07" iyz="-1.18697138701936e-10" izz="2.48875198442135e-07" />
    </inertial>
    <visual>
      <origin xyz="0 0 0" rpy="0 0 0" />
      <geometry>
        <mesh filename="../../components/hands/linkerhand_l20lite/variants/left/meshes/thumb_distal.STL" />
      </geometry>
      <material name="">
        <color rgba="1 1 1 1" />
      </material>
    </visual>
    <collision>
      <origin xyz="0 0 0" rpy="0 0 0" />
      <geometry>
        <mesh filename="../../components/hands/linkerhand_l20lite/variants/left/meshes/thumb_distal.STL" />
      </geometry>
    </collision>
  </link>
  <link name="hand_left_lh_index_metacarpals">
    <inertial>
      <origin xyz="-0.00143091455 2.56878017e-07 0.0107040529" rpy="0 0 0" />
      <mass value="0.0038877126435198" />
      <inertia ixx="1.87149599832498e-07" ixy="3.67335498441413e-11" ixz="1.3415127653338e-08" iyy="2.75278147668716e-07" iyz="2.44762951204078e-11" izz="2.06866317113344e-07" />
    </inertial>
    <visual>
      <origin xyz="0 0 0" rpy="0 0 0" />
      <geometry>
        <mesh filename="../../components/hands/linkerhand_l20lite/variants/left/meshes/index_metacarpals.STL" />
      </geometry>
      <material name="">
        <color rgba="1 1 1 1" />
      </material>
    </visual>
    <collision>
      <origin xyz="0 0 0" rpy="0 0 0" />
      <geometry>
        <mesh filename="../../components/hands/linkerhand_l20lite/variants/left/meshes/index_metacarpals.STL" />
      </geometry>
    </collision>
  </link>
  <link name="hand_left_lh_index_proximal">
    <inertial>
      <origin xyz="-0.00122347617 -2.04121171e-06 0.0182409893" rpy="0 0 0" />
      <mass value="0.00316246584579941" />
      <inertia ixx="3.57135128024094e-07" ixy="1.42036124901073e-11" ixz="-4.14209968733606e-08" iyy="3.51905870436209e-07" iyz="-1.08557233942923e-10" izz="1.40872561400322e-07" />
    </inertial>
    <visual>
      <origin xyz="0 0 0" rpy="0 0 0" />
      <geometry>
        <mesh filename="../../components/hands/linkerhand_l20lite/variants/left/meshes/index_proximal.STL" />
      </geometry>
      <material name="">
        <color rgba="1 1 1 1" />
      </material>
    </visual>
    <collision>
      <origin xyz="0 0 0" rpy="0 0 0" />
      <geometry>
        <mesh filename="../../components/hands/linkerhand_l20lite/variants/left/meshes/index_proximal.STL" />
      </geometry>
    </collision>
  </link>
  <link name="hand_left_lh_index_middle">
    <inertial>
      <origin xyz="-0.00250309204 2.18945385e-06 0.0110397391" rpy="0 0 0" />
      <mass value="0.00283043921422803" />
      <inertia ixx="2.61037133593912e-07" ixy="5.76197451786318e-11" ixz="-4.0011060525121e-08" iyy="2.33077518995487e-07" iyz="-2.86979503467821e-11" izz="1.26543797445814e-07" />
    </inertial>
    <visual>
      <origin xyz="0 0 0" rpy="0 0 0" />
      <geometry>
        <mesh filename="../../components/hands/linkerhand_l20lite/variants/left/meshes/index_middle.STL" />
      </geometry>
      <material name="">
        <color rgba="1 1 1 1" />
      </material>
    </visual>
    <collision>
      <origin xyz="0 0 0" rpy="0 0 0" />
      <geometry>
        <mesh filename="../../components/hands/linkerhand_l20lite/variants/left/meshes/index_middle.STL" />
      </geometry>
    </collision>
  </link>
  <link name="hand_left_lh_index_distal">
    <inertial>
      <origin xyz="-0.000604509917 -4.77400033e-06 0.0121511112" rpy="0 0 0" />
      <mass value="0.0031445375098231" />
      <inertia ixx="1.64070673729839e-07" ixy="1.88963511473794e-11" ixz="-4.27776869144244e-08" iyy="1.48362830813358e-07" iyz="-1.9734013143508e-10" izz="9.7804088657243e-08" />
    </inertial>
    <visual>
      <origin xyz="0 0 0" rpy="0 0 0" />
      <geometry>
        <mesh filename="../../components/hands/linkerhand_l20lite/variants/left/meshes/index_distal.STL" />
      </geometry>
      <material name="">
        <color rgba="1 1 1 1" />
      </material>
    </visual>
    <collision>
      <origin xyz="0 0 0" rpy="0 0 0" />
      <geometry>
        <mesh filename="../../components/hands/linkerhand_l20lite/variants/left/meshes/index_distal.STL" />
      </geometry>
    </collision>
  </link>
  <link name="hand_left_lh_middle_proximal">
    <inertial>
      <origin xyz="-0.00123185151 -2.04476499e-06 0.0182404194" rpy="0 0 0" />
      <mass value="0.00316246719662224" />
      <inertia ixx="3.57097075648345e-07" ixy="1.43002807788619e-11" ixz="-4.15201646947523e-08" iyy="3.51905920397223e-07" iyz="-1.08488557665733e-10" izz="1.4091067749978e-07" />
    </inertial>
    <visual>
      <origin xyz="0 0 0" rpy="0 0 0" />
      <geometry>
        <mesh filename="../../components/hands/linkerhand_l20lite/variants/left/meshes/middle_proximal.STL" />
      </geometry>
      <material name="">
        <color rgba="1 1 1 1" />
      </material>
    </visual>
    <collision>
      <origin xyz="0 0 0" rpy="0 0 0" />
      <geometry>
        <mesh filename="../../components/hands/linkerhand_l20lite/variants/left/meshes/middle_proximal.STL" />
      </geometry>
    </collision>
  </link>
  <link name="hand_left_lh_middle_middle">
    <inertial>
      <origin xyz="-0.0025207973 2.18964489e-06 0.0110357094" rpy="0 0 0" />
      <mass value="0.00283043921858529" />
      <inertia ixx="2.60908423355366e-07" ixy="5.76720293661014e-11" ixz="-4.02265908644236e-08" iyy="2.33077520740401e-07" iyz="-2.86057758459882e-11" izz="1.26672514044425e-07" />
    </inertial>
    <visual>
      <origin xyz="0 0 0" rpy="0 0 0" />
      <geometry>
        <mesh filename="../../components/hands/linkerhand_l20lite/variants/left/meshes/middle_middle.STL" />
      </geometry>
      <material name="">
        <color rgba="1 1 1 1" />
      </material>
    </visual>
    <collision>
      <origin xyz="0 0 0" rpy="0 0 0" />
      <geometry>
        <mesh filename="../../components/hands/linkerhand_l20lite/variants/left/meshes/middle_middle.STL" />
      </geometry>
    </collision>
  </link>
  <link name="hand_left_lh_middle_distal">
    <inertial>
      <origin xyz="-0.000622397826 -4.7556975e-06 0.0121501714" rpy="0 0 0" />
      <mass value="0.00314452092964384" />
      <inertia ixx="1.63942838563309e-07" ixy="1.9526841627913e-11" ixz="-4.28753645610842e-08" iyy="1.48361296215111e-07" iyz="-1.96949597957508e-10" izz="9.7929884595885e-08" />
    </inertial>
    <visual>
      <origin xyz="0 0 0" rpy="0 0 0" />
      <geometry>
        <mesh filename="../../components/hands/linkerhand_l20lite/variants/left/meshes/middle_distal.STL" />
      </geometry>
      <material name="">
        <color rgba="1 1 1 1" />
      </material>
    </visual>
    <collision>
      <origin xyz="0 0 0" rpy="0 0 0" />
      <geometry>
        <mesh filename="../../components/hands/linkerhand_l20lite/variants/left/meshes/middle_distal.STL" />
      </geometry>
    </collision>
  </link>
  <link name="hand_left_lh_ring_metacarpals">
    <inertial>
      <origin xyz="-0.00143091449 6.05495226e-07 0.0107040523" rpy="0 0 0" />
      <mass value="0.00388771255966599" />
      <inertia ixx="1.87149578481638e-07" ixy="1.52642675041227e-11" ixz="1.34151349601248e-08" iyy="2.75278155094349e-07" iyz="2.12062463357117e-11" izz="2.06866318930306e-07" />
    </inertial>
    <visual>
      <origin xyz="0 0 0" rpy="0 0 0" />
      <geometry>
        <mesh filename="../../components/hands/linkerhand_l20lite/variants/left/meshes/ring_metacarpals.STL" />
      </geometry>
      <material name="">
        <color rgba="1 1 1 1" />
      </material>
    </visual>
    <collision>
      <origin xyz="0 0 0" rpy="0 0 0" />
      <geometry>
        <mesh filename="../../components/hands/linkerhand_l20lite/variants/left/meshes/ring_metacarpals.STL" />
      </geometry>
    </collision>
  </link>
  <link name="hand_left_lh_ring_proximal">
    <inertial>
      <origin xyz="-0.00122347652 -2.04234074e-06 0.0182409875" rpy="0 0 0" />
      <mass value="0.00316246660225829" />
      <inertia ixx="3.5713512847731e-07" ixy="1.42130904393983e-11" ixz="-4.14209983311065e-08" iyy="3.51905881089114e-07" iyz="-1.08576103054512e-10" izz="1.40872582931496e-07" />
    </inertial>
    <visual>
      <origin xyz="0 0 0" rpy="0 0 0" />
      <geometry>
        <mesh filename="../../components/hands/linkerhand_l20lite/variants/left/meshes/ring_proximal.STL" />
      </geometry>
      <material name="">
        <color rgba="1 1 1 1" />
      </material>
    </visual>
    <collision>
      <origin xyz="0 0 0" rpy="0 0 0" />
      <geometry>
        <mesh filename="../../components/hands/linkerhand_l20lite/variants/left/meshes/ring_proximal.STL" />
      </geometry>
    </collision>
  </link>
  <link name="hand_left_lh_ring_middle">
    <inertial>
      <origin xyz="-0.0025030919 2.18959036e-06 0.0110397386" rpy="0 0 0" />
      <mass value="0.00283043920090097" />
      <inertia ixx="2.61037130501287e-07" ixy="5.76216047828233e-11" ixz="-4.00110582573436e-08" iyy="2.33077521207674e-07" iyz="-2.86985395311388e-11" izz="1.26543807918808e-07" />
    </inertial>
    <visual>
      <origin xyz="0 0 0" rpy="0 0 0" />
      <geometry>
        <mesh filename="../../components/hands/linkerhand_l20lite/variants/left/meshes/ring_middle.STL" />
      </geometry>
      <material name="">
        <color rgba="1 1 1 1" />
      </material>
    </visual>
    <collision>
      <origin xyz="0 0 0" rpy="0 0 0" />
      <geometry>
        <mesh filename="../../components/hands/linkerhand_l20lite/variants/left/meshes/ring_middle.STL" />
      </geometry>
    </collision>
  </link>
  <link name="hand_left_lh_ring_distal">
    <inertial>
      <origin xyz="-0.00060449765 -4.73100652e-06 0.0121511264" rpy="0 0 0" />
      <mass value="0.00314454943731604" />
      <inertia ixx="1.64071049652571e-07" ixy="1.94791513771428e-11" ixz="-4.27777374237679e-08" iyy="1.48363091013624e-07" iyz="-1.96468435398403e-10" izz="9.78042601257212e-08" />
    </inertial>
    <visual>
      <origin xyz="0 0 0" rpy="0 0 0" />
      <geometry>
        <mesh filename="../../components/hands/linkerhand_l20lite/variants/left/meshes/ring_distal.STL" />
      </geometry>
      <material name="">
        <color rgba="1 1 1 1" />
      </material>
    </visual>
    <collision>
      <origin xyz="0 0 0" rpy="0 0 0" />
      <geometry>
        <mesh filename="../../components/hands/linkerhand_l20lite/variants/left/meshes/ring_distal.STL" />
      </geometry>
    </collision>
  </link>
  <link name="hand_left_lh_pinky_metacarpals">
    <inertial>
      <origin xyz="-0.00143091631 6.05311374e-07 0.0107040499" rpy="0 0 0" />
      <mass value="0.00388771229554929" />
      <inertia ixx="1.87149536268889e-07" ixy="1.52679681737727e-11" ixz="1.34151204706615e-08" iyy="2.75278106047772e-07" iyz="2.11967245454867e-11" izz="2.06866328803883e-07" />
    </inertial>
    <visual>
      <origin xyz="0 0 0" rpy="0 0 0" />
      <geometry>
        <mesh filename="../../components/hands/linkerhand_l20lite/variants/left/meshes/pinky_metacarpals.STL" />
      </geometry>
      <material name="">
        <color rgba="1 1 1 1" />
      </material>
    </visual>
    <collision>
      <origin xyz="0 0 0" rpy="0 0 0" />
      <geometry>
        <mesh filename="../../components/hands/linkerhand_l20lite/variants/left/meshes/pinky_metacarpals.STL" />
      </geometry>
    </collision>
  </link>
  <link name="hand_left_lh_pinky_proximal">
    <inertial>
      <origin xyz="-0.00122347805 -2.04329569e-06 0.0182409919" rpy="0 0 0" />
      <mass value="0.00316246781629033" />
      <inertia ixx="3.57135263144139e-07" ixy="1.42286998987323e-11" ixz="-4.14209901998364e-08" iyy="3.5190602349514e-07" iyz="-1.08636442666922e-10" izz="1.40872647811026e-07" />
    </inertial>
    <visual>
      <origin xyz="0 0 0" rpy="0 0 0" />
      <geometry>
        <mesh filename="../../components/hands/linkerhand_l20lite/variants/left/meshes/pinky_proximal.STL" />
      </geometry>
      <material name="">
        <color rgba="1 1 1 1" />
      </material>
    </visual>
    <collision>
      <origin xyz="0 0 0" rpy="0 0 0" />
      <geometry>
        <mesh filename="../../components/hands/linkerhand_l20lite/variants/left/meshes/pinky_proximal.STL" />
      </geometry>
    </collision>
  </link>
  <link name="hand_left_lh_pinky_middle">
    <inertial>
      <origin xyz="-0.00250309214 2.1894783e-06 0.0110397383" rpy="0 0 0" />
      <mass value="0.00283043906989622" />
      <inertia ixx="2.61037124783617e-07" ixy="5.7617222079153e-11" ixz="-4.00110565109454e-08" iyy="2.33077513229909e-07" iyz="-2.86988443315275e-11" izz="1.2654380297458e-07" />
    </inertial>
    <visual>
      <origin xyz="0 0 0" rpy="0 0 0" />
      <geometry>
        <mesh filename="../../components/hands/linkerhand_l20lite/variants/left/meshes/pinky_middle.STL" />
      </geometry>
      <material name="">
        <color rgba="1 1 1 1" />
      </material>
    </visual>
    <collision>
      <origin xyz="0 0 0" rpy="0 0 0" />
      <geometry>
        <mesh filename="../../components/hands/linkerhand_l20lite/variants/left/meshes/pinky_middle.STL" />
      </geometry>
    </collision>
  </link>
  <link name="hand_left_lh_pinky_distal">
    <inertial>
      <origin xyz="-0.000604492896 -4.7526368e-06 0.0121511379" rpy="0 0 0" />
      <mass value="0.00314455887032079" />
      <inertia ixx="1.64071496633017e-07" ixy="1.95563986835622e-11" ixz="-4.27779200959899e-08" iyy="1.48363675410427e-07" iyz="-1.9679860568024e-10" izz="9.78043717695209e-08" />
    </inertial>
    <visual>
      <origin xyz="0 0 0" rpy="0 0 0" />
      <geometry>
        <mesh filename="../../components/hands/linkerhand_l20lite/variants/left/meshes/pinky_distal.STL" />
      </geometry>
      <material name="">
        <color rgba="1 1 1 1" />
      </material>
    </visual>
    <collision>
      <origin xyz="0 0 0" rpy="0 0 0" />
      <geometry>
        <mesh filename="../../components/hands/linkerhand_l20lite/variants/left/meshes/pinky_distal.STL" />
      </geometry>
    </collision>
  </link>
  <link name="hand_right_rh_hand_base_link">
    <inertial>
      <origin xyz="-0.00378572993 -0.000415839049 0.0836392884" rpy="0 0 0" />
      <mass value="0.108844276105116" />
      <inertia ixx="0.000193454839560416" ixy="-1.28842682703635e-06" ixz="-1.97005632027442e-07" iyy="0.000129793182936331" iyz="2.34961034039848e-06" izz="7.75126657491833e-05" />
    </inertial>
    <visual>
      <origin xyz="0 0 0" rpy="0 0 0" />
      <geometry>
        <mesh filename="../../components/hands/linkerhand_l20lite/variants/right/meshes/hand_base_link.STL" />
      </geometry>
      <material name="">
        <color rgba="1 1 1 1" />
      </material>
    </visual>
    <collision>
      <origin xyz="0 0 0" rpy="0 0 0" />
      <geometry>
        <mesh filename="../../components/hands/linkerhand_l20lite/variants/right/meshes/hand_base_link.STL" />
      </geometry>
    </collision>
  </link>
  <link name="hand_right_rh_thumb_metacarpals_base1">
    <inertial>
      <origin xyz="0.0284798869 -0.00318431295 1.02719477e-05" rpy="0 0 0" />
      <mass value="0.0084581547726202" />
      <inertia ixx="1.40243836130246e-06" ixy="-1.19619722062239e-07" ixz="7.34394052250468e-09" iyy="9.92829395244375e-07" iyz="4.64162077403213e-08" izz="7.26110349167423e-07" />
    </inertial>
    <visual>
      <origin xyz="0 0 0" rpy="0 0 0" />
      <geometry>
        <mesh filename="../../components/hands/linkerhand_l20lite/variants/right/meshes/thumb_metacarpals_base1.STL" />
      </geometry>
      <material name="">
        <color rgba="1 1 1 1" />
      </material>
    </visual>
    <collision>
      <origin xyz="0 0 0" rpy="0 0 0" />
      <geometry>
        <mesh filename="../../components/hands/linkerhand_l20lite/variants/right/meshes/thumb_metacarpals_base1.STL" />
      </geometry>
    </collision>
  </link>
  <link name="hand_right_rh_thumb_metacarpals_base2">
    <inertial>
      <origin xyz="0.00174090958 0.0072148259 -0.000263313052" rpy="0 0 0" />
      <mass value="0.00582711245702963" />
      <inertia ixx="3.17303010997568e-07" ixy="1.12913904502057e-08" ixz="-2.63903919763792e-09" iyy="2.73232268452871e-07" iyz="-1.09223121289568e-08" izz="1.76908306988949e-07" />
    </inertial>
    <visual>
      <origin xyz="0 0 0" rpy="0 0 0" />
      <geometry>
        <mesh filename="../../components/hands/linkerhand_l20lite/variants/right/meshes/thumb_metacarpals_base2.STL" />
      </geometry>
      <material name="">
        <color rgba="1 1 1 1" />
      </material>
    </visual>
    <collision>
      <origin xyz="0 0 0" rpy="0 0 0" />
      <geometry>
        <mesh filename="../../components/hands/linkerhand_l20lite/variants/right/meshes/thumb_metacarpals_base2.STL" />
      </geometry>
    </collision>
  </link>
  <link name="hand_right_rh_thumb_metacarpals">
    <inertial>
      <origin xyz="0.00183662401 -2.80439601e-06 0.0269904281" rpy="0 0 0" />
      <mass value="0.0152012256765109" />
      <inertia ixx="2.95371260447027e-06" ixy="-6.21178551021653e-11" ixz="-1.58082424321764e-07" iyy="3.8477229500142e-06" iyz="-4.14758708520733e-10" izz="1.32007940012866e-06" />
    </inertial>
    <visual>
      <origin xyz="0 0 0" rpy="0 0 0" />
      <geometry>
        <mesh filename="../../components/hands/linkerhand_l20lite/variants/right/meshes/thumb_metacarpals.STL" />
      </geometry>
      <material name="">
        <color rgba="1 1 1 1" />
      </material>
    </visual>
    <collision>
      <origin xyz="0 0 0" rpy="0 0 0" />
      <geometry>
        <mesh filename="../../components/hands/linkerhand_l20lite/variants/right/meshes/thumb_metacarpals.STL" />
      </geometry>
    </collision>
  </link>
  <link name="hand_right_rh_thumb_proximal">
    <inertial>
      <origin xyz="0.00159268253 -4.43643671e-06 0.0151573638" rpy="0 0 0" />
      <mass value="0.00662231923284161" />
      <inertia ixx="1.01527279135723e-06" ixy="3.86298144933713e-12" ixz="-4.42245334725163e-08" iyy="9.10434608488902e-07" iyz="-2.76864906314695e-11" izz="4.47464440479559e-07" />
    </inertial>
    <visual>
      <origin xyz="0 0 0" rpy="0 0 0" />
      <geometry>
        <mesh filename="../../components/hands/linkerhand_l20lite/variants/right/meshes/thumb_proximal.STL" />
      </geometry>
      <material name="">
        <color rgba="1 1 1 1" />
      </material>
    </visual>
    <collision>
      <origin xyz="0 0 0" rpy="0 0 0" />
      <geometry>
        <mesh filename="../../components/hands/linkerhand_l20lite/variants/right/meshes/thumb_proximal.STL" />
      </geometry>
    </collision>
  </link>
  <link name="hand_right_rh_thumb_distal">
    <inertial>
      <origin xyz="-0.00138929853 1.78258724e-06 0.0115789166" rpy="0 0 0" />
      <mass value="0.00512919991432349" />
      <inertia ixx="3.30966764284813e-07" ixy="3.4874903065333e-10" ixz="-1.0473713688836e-07" iyy="3.23803379547457e-07" iyz="8.38797000457644e-11" izz="2.48897458436709e-07" />
    </inertial>
    <visual>
      <origin xyz="0 0 0" rpy="0 0 0" />
      <geometry>
        <mesh filename="../../components/hands/linkerhand_l20lite/variants/right/meshes/thumb_distal.STL" />
      </geometry>
      <material name="">
        <color rgba="1 1 1 1" />
      </material>
    </visual>
    <collision>
      <origin xyz="0 0 0" rpy="0 0 0" />
      <geometry>
        <mesh filename="../../components/hands/linkerhand_l20lite/variants/right/meshes/thumb_distal.STL" />
      </geometry>
    </collision>
  </link>
  <link name="hand_right_rh_index_metacarpals">
    <inertial>
      <origin xyz="-0.000394044301 -6.96524768e-07 0.00909446181" rpy="0 0 0" />
      <mass value="0.00903700329493157" />
      <inertia ixx="4.89554250283515e-07" ixy="-3.94697795521512e-11" ixz="2.73097237930781e-08" iyy="7.37380385682221e-07" iyz="-6.33508384593073e-11" izz="5.52862732336676e-07" />
    </inertial>
    <visual>
      <origin xyz="0 0 0" rpy="0 0 0" />
      <geometry>
        <mesh filename="../../components/hands/linkerhand_l20lite/variants/right/meshes/index_metacarpals.STL" />
      </geometry>
      <material name="">
        <color rgba="1 1 1 1" />
      </material>
    </visual>
    <collision>
      <origin xyz="0 0 0" rpy="0 0 0" />
      <geometry>
        <mesh filename="../../components/hands/linkerhand_l20lite/variants/right/meshes/index_metacarpals.STL" />
      </geometry>
    </collision>
  </link>
  <link name="hand_right_rh_index_proximal">
    <inertial>
      <origin xyz="-0.000129944381 1.17196172e-06 0.0104816956" rpy="0 0 0" />
      <mass value="0.00654982235507964" />
      <inertia ixx="4.43901400960209e-07" ixy="3.44400810155697e-12" ixz="-2.4814971446792e-08" iyy="4.58697731369085e-07" iyz="8.51406115918214e-11" izz="1.74205815221237e-07" />
    </inertial>
    <visual>
      <origin xyz="0 0 0" rpy="0 0 0" />
      <geometry>
        <mesh filename="../../components/hands/linkerhand_l20lite/variants/right/meshes/index_proximal.STL" />
      </geometry>
      <material name="">
        <color rgba="1 1 1 1" />
      </material>
    </visual>
    <collision>
      <origin xyz="0 0 0" rpy="0 0 0" />
      <geometry>
        <mesh filename="../../components/hands/linkerhand_l20lite/variants/right/meshes/index_proximal.STL" />
      </geometry>
    </collision>
  </link>
  <link name="hand_right_rh_index_middle">
    <inertial>
      <origin xyz="-0.00250308175 -2.09528009e-06 0.0110397399" rpy="0 0 0" />
      <mass value="0.00283043630937165" />
      <inertia ixx="2.61037002532157e-07" ixy="-5.76553826316728e-11" ixz="-4.00111847827091e-08" iyy="2.33077671005604e-07" iyz="2.97012055424732e-11" izz="1.2654386429984e-07" />
    </inertial>
    <visual>
      <origin xyz="0 0 0" rpy="0 0 0" />
      <geometry>
        <mesh filename="../../components/hands/linkerhand_l20lite/variants/right/meshes/index_middle.STL" />
      </geometry>
      <material name="">
        <color rgba="1 1 1 1" />
      </material>
    </visual>
    <collision>
      <origin xyz="0 0 0" rpy="0 0 0" />
      <geometry>
        <mesh filename="../../components/hands/linkerhand_l20lite/variants/right/meshes/index_middle.STL" />
      </geometry>
    </collision>
  </link>
  <link name="hand_right_rh_index_distal">
    <inertial>
      <origin xyz="-0.000604588907 5.26099433e-06 0.0121514585" rpy="0 0 0" />
      <mass value="0.0031446130611452" />
      <inertia ixx="1.64075846532352e-07" ixy="-1.75219464852339e-11" ixz="-4.27797730478817e-08" iyy="1.48367877966466e-07" iyz="2.03355501606508e-10" izz="9.78063887942514e-08" />
    </inertial>
    <visual>
      <origin xyz="0 0 0" rpy="0 0 0" />
      <geometry>
        <mesh filename="../../components/hands/linkerhand_l20lite/variants/right/meshes/index_distal.STL" />
      </geometry>
      <material name="">
        <color rgba="1 1 1 1" />
      </material>
    </visual>
    <collision>
      <origin xyz="0 0 0" rpy="0 0 0" />
      <geometry>
        <mesh filename="../../components/hands/linkerhand_l20lite/variants/right/meshes/index_distal.STL" />
      </geometry>
    </collision>
  </link>
  <link name="hand_right_rh_middle_proximal">
    <inertial>
      <origin xyz="-0.000226219981 1.17216483e-06 0.0104800581" rpy="0 0 0" />
      <mass value="0.00654982478226949" />
      <inertia ixx="4.43422823045882e-07" ixy="2.65801609334198e-12" ixz="-2.72879331079685e-08" iyy="4.58697754707373e-07" iyz="8.52654749038393e-11" izz="1.746844667607e-07" />
    </inertial>
    <visual>
      <origin xyz="0 0 0" rpy="0 0 0" />
      <geometry>
        <mesh filename="../../components/hands/linkerhand_l20lite/variants/right/meshes/middle_proximal.STL" />
      </geometry>
      <material name="">
        <color rgba="1 1 1 1" />
      </material>
    </visual>
    <collision>
      <origin xyz="0 0 0" rpy="0 0 0" />
      <geometry>
        <mesh filename="../../components/hands/linkerhand_l20lite/variants/right/meshes/middle_proximal.STL" />
      </geometry>
    </collision>
  </link>
  <link name="hand_right_rh_middle_middle">
    <inertial>
      <origin xyz="-0.00261699473 -2.09526685e-06 0.0110132928" rpy="0 0 0" />
      <mass value="0.00283043635504842" />
      <inertia ixx="2.60196021834948e-07" ixy="-5.79547865424222e-11" ixz="-4.13919583593881e-08" iyy="2.33077669434872e-07" iyz="2.9104841260857e-11" izz="1.27384845266404e-07" />
    </inertial>
    <visual>
      <origin xyz="0 0 0" rpy="0 0 0" />
      <geometry>
        <mesh filename="../../components/hands/linkerhand_l20lite/variants/right/meshes/middle_middle.STL" />
      </geometry>
      <material name="">
        <color rgba="1 1 1 1" />
      </material>
    </visual>
    <collision>
      <origin xyz="0 0 0" rpy="0 0 0" />
      <geometry>
        <mesh filename="../../components/hands/linkerhand_l20lite/variants/right/meshes/middle_middle.STL" />
      </geometry>
    </collision>
  </link>
  <link name="hand_right_rh_middle_distal">
    <inertial>
      <origin xyz="-0.000728492686 5.23463093e-06 0.0121446078" rpy="0 0 0" />
      <mass value="0.00314458659113992" />
      <inertia ixx="1.63194300204967e-07" ixy="-1.99064062210326e-11" ixz="-4.34469141576056e-08" iyy="1.48366133401819e-07" iyz="2.02741720954809e-10" izz="9.8685363448972e-08" />
    </inertial>
    <visual>
      <origin xyz="0 0 0" rpy="0 0 0" />
      <geometry>
        <mesh filename="../../components/hands/linkerhand_l20lite/variants/right/meshes/middle_distal.STL" />
      </geometry>
      <material name="">
        <color rgba="1 1 1 1" />
      </material>
    </visual>
    <collision>
      <origin xyz="0 0 0" rpy="0 0 0" />
      <geometry>
        <mesh filename="../../components/hands/linkerhand_l20lite/variants/right/meshes/middle_distal.STL" />
      </geometry>
    </collision>
  </link>
  <link name="hand_right_rh_ring_metacarpals">
    <inertial>
      <origin xyz="-0.000394044454 -6.96464269e-07 0.00909446164" rpy="0 0 0" />
      <mass value="0.00903700335356623" />
      <inertia ixx="4.89554245950771e-07" ixy="-3.94741777907138e-11" ixz="2.73097253166787e-08" iyy="7.37380377611045e-07" iyz="-6.33493307330511e-11" izz="5.52862742016819e-07" />
    </inertial>
    <visual>
      <origin xyz="0 0 0" rpy="0 0 0" />
      <geometry>
        <mesh filename="../../components/hands/linkerhand_l20lite/variants/right/meshes/ring_metacarpals.STL" />
      </geometry>
      <material name="">
        <color rgba="1 1 1 1" />
      </material>
    </visual>
    <collision>
      <origin xyz="0 0 0" rpy="0 0 0" />
      <geometry>
        <mesh filename="../../components/hands/linkerhand_l20lite/variants/right/meshes/ring_metacarpals.STL" />
      </geometry>
    </collision>
  </link>
  <link name="hand_right_rh_ring_proximal">
    <inertial>
      <origin xyz="-0.000129951742 1.17052694e-06 0.0104816759" rpy="0 0 0" />
      <mass value="0.00654983629670871" />
      <inertia ixx="4.43901586303392e-07" ixy="3.50295306689535e-12" ixz="-2.48148215954452e-08" iyy="4.58698142287549e-07" iyz="8.52333703161162e-11" izz="1.74206152792307e-07" />
    </inertial>
    <visual>
      <origin xyz="0 0 0" rpy="0 0 0" />
      <geometry>
        <mesh filename="../../components/hands/linkerhand_l20lite/variants/right/meshes/ring_proximal.STL" />
      </geometry>
      <material name="">
        <color rgba="1 1 1 1" />
      </material>
    </visual>
    <collision>
      <origin xyz="0 0 0" rpy="0 0 0" />
      <geometry>
        <mesh filename="../../components/hands/linkerhand_l20lite/variants/right/meshes/ring_proximal.STL" />
      </geometry>
    </collision>
  </link>
  <link name="hand_right_rh_ring_middle">
    <inertial>
      <origin xyz="-0.00250308201 -2.09549543e-06 0.0110397403" rpy="0 0 0" />
      <mass value="0.0028304363455826" />
      <inertia ixx="2.610370084214e-07" ixy="-5.76575489930258e-11" ixz="-4.00111860002357e-08" iyy="2.3307766580208e-07" iyz="2.97027542466601e-11" izz="1.26543852008426e-07" />
    </inertial>
    <visual>
      <origin xyz="0 0 0" rpy="0 0 0" />
      <geometry>
        <mesh filename="../../components/hands/linkerhand_l20lite/variants/right/meshes/ring_middle.STL" />
      </geometry>
      <material name="">
        <color rgba="1 1 1 1" />
      </material>
    </visual>
    <collision>
      <origin xyz="0 0 0" rpy="0 0 0" />
      <geometry>
        <mesh filename="../../components/hands/linkerhand_l20lite/variants/right/meshes/ring_middle.STL" />
      </geometry>
    </collision>
  </link>
  <link name="hand_right_rh_ring_distal">
    <inertial>
      <origin xyz="-0.000604592861 5.09148089e-06 0.0121514428" rpy="0 0 0" />
      <mass value="0.00314460631735109" />
      <inertia ixx="1.64075455538032e-07" ixy="-2.1468512857682e-11" ixz="-4.27798116117893e-08" iyy="1.48367698956355e-07" iyz="1.93419127705868e-10" izz="9.78062648939272e-08" />
    </inertial>
    <visual>
      <origin xyz="0 0 0" rpy="0 0 0" />
      <geometry>
        <mesh filename="../../components/hands/linkerhand_l20lite/variants/right/meshes/ring_distal.STL" />
      </geometry>
      <material name="">
        <color rgba="1 1 1 1" />
      </material>
    </visual>
    <collision>
      <origin xyz="0 0 0" rpy="0 0 0" />
      <geometry>
        <mesh filename="../../components/hands/linkerhand_l20lite/variants/right/meshes/ring_distal.STL" />
      </geometry>
    </collision>
  </link>
  <link name="hand_right_rh_pinky_metacarpals">
    <inertial>
      <origin xyz="-0.000394045227 -6.96240701e-07 0.00909446059" rpy="0 0 0" />
      <mass value="0.00903700307878998" />
      <inertia ixx="4.89554195779539e-07" ixy="-3.94817181132792e-11" ixz="2.7309708213456e-08" iyy="7.37380317460272e-07" iyz="-6.33317017267926e-11" izz="5.5286276236961e-07" />
    </inertial>
    <visual>
      <origin xyz="0 0 0" rpy="0 0 0" />
      <geometry>
        <mesh filename="../../components/hands/linkerhand_l20lite/variants/right/meshes/pinky_metacarpals.STL" />
      </geometry>
      <material name="">
        <color rgba="1 1 1 1" />
      </material>
    </visual>
    <collision>
      <origin xyz="0 0 0" rpy="0 0 0" />
      <geometry>
        <mesh filename="../../components/hands/linkerhand_l20lite/variants/right/meshes/pinky_metacarpals.STL" />
      </geometry>
    </collision>
  </link>
  <link name="hand_right_rh_pinky_proximal">
    <inertial>
      <origin xyz="-0.000129949532 1.17230681e-06 0.0104816808" rpy="0 0 0" />
      <mass value="0.00654983474179372" />
      <inertia ixx="4.43901730245286e-07" ixy="3.4507527836803e-12" ixz="-2.48149152090791e-08" iyy="4.58698159687316e-07" iyz="8.52432689792127e-11" izz="1.74206088330646e-07" />
    </inertial>
    <visual>
      <origin xyz="0 0 0" rpy="0 0 0" />
      <geometry>
        <mesh filename="../../components/hands/linkerhand_l20lite/variants/right/meshes/pinky_proximal.STL" />
      </geometry>
      <material name="">
        <color rgba="1 1 1 1" />
      </material>
    </visual>
    <collision>
      <origin xyz="0 0 0" rpy="0 0 0" />
      <geometry>
        <mesh filename="../../components/hands/linkerhand_l20lite/variants/right/meshes/pinky_proximal.STL" />
      </geometry>
    </collision>
  </link>
  <link name="hand_right_rh_pinky_middle">
    <inertial>
      <origin xyz="-0.00250308415 -2.09612031e-06 0.0110397422" rpy="0 0 0" />
      <mass value="0.00283043670305552" />
      <inertia ixx="2.6103697292473e-07" ixy="-5.76245409160896e-11" ixz="-4.00111424508735e-08" iyy="2.33077589871973e-07" iyz="2.96769001441938e-11" izz="1.26543829688383e-07" />
    </inertial>
    <visual>
      <origin xyz="0 0 0" rpy="0 0 0" />
      <geometry>
        <mesh filename="../../components/hands/linkerhand_l20lite/variants/right/meshes/pinky_middle.STL" />
      </geometry>
      <material name="">
        <color rgba="1 1 1 1" />
      </material>
    </visual>
    <collision>
      <origin xyz="0 0 0" rpy="0 0 0" />
      <geometry>
        <mesh filename="../../components/hands/linkerhand_l20lite/variants/right/meshes/pinky_middle.STL" />
      </geometry>
    </collision>
  </link>
  <link name="hand_right_rh_pinky_distal">
    <inertial>
      <origin xyz="-0.000604482989 5.27153358e-06 0.012151243" rpy="0 0 0" />
      <mass value="0.00314457409502053" />
      <inertia ixx="1.64068754964363e-07" ixy="-1.90437996173564e-11" ixz="-4.27789862984836e-08" iyy="1.48361079085349e-07" iyz="2.05110113267167e-10" izz="9.78068531228973e-08" />
    </inertial>
    <visual>
      <origin xyz="0 0 0" rpy="0 0 0" />
      <geometry>
        <mesh filename="../../components/hands/linkerhand_l20lite/variants/right/meshes/pinky_distal.STL" />
      </geometry>
      <material name="">
        <color rgba="1 1 1 1" />
      </material>
    </visual>
    <collision>
      <origin xyz="0 0 0" rpy="0 0 0" />
      <geometry>
        <mesh filename="../../components/hands/linkerhand_l20lite/variants/right/meshes/pinky_distal.STL" />
      </geometry>
    </collision>
  </link>
  <joint name="base_torso_stand" type="fixed">
    <origin xyz="0 0 1.2" rpy="0 0 0" />
    <parent link="base_torso_root" />
    <child link="base_base_link" />
  </joint>
  <joint name="base_weld_arm_left_mount" type="fixed">
    <origin xyz="0.0062932 0.1505 -0.022706" rpy="0 0 0" />
    <parent link="base_base_link" />
    <child link="base_arm_left_mount" />
  </joint>
  <joint name="base_weld_arm_right_mount" type="fixed">
    <origin xyz="0.0062926 -0.1505 -0.022706" rpy="0 0 0" />
    <parent link="base_base_link" />
    <child link="base_arm_right_mount" />
  </joint>
  <joint name="arm_left_L1_Joint" type="revolute">
    <origin xyz="0 0 0" rpy="0 0 0" />
    <parent link="arm_left_L_arm_root" />
    <child link="arm_left_L1_Link" />
    <axis xyz="0 -1 0" />
    <limit lower="-2.18" upper="3.75" effort="60" velocity="18.84" />
  </joint>
  <joint name="arm_left_L2_Joint" type="revolute">
    <origin xyz="0.03125 0.0715 0" rpy="0 0 0" />
    <parent link="arm_left_L1_Link" />
    <child link="arm_left_L2_Link" />
    <axis xyz="-1 0 0" />
    <limit lower="-3.33" upper="0.19" effort="60" velocity="18.84" />
  </joint>
  <joint name="arm_left_L3_Joint" type="revolute">
    <origin xyz="-0.03125 0 -0.147" rpy="0 0 0" />
    <parent link="arm_left_L2_Link" />
    <child link="arm_left_L3_Link" />
    <axis xyz="0 0 1" />
    <limit lower="-2.26" upper="2.26" effort="17" velocity="137.68" />
  </joint>
  <joint name="arm_left_L4_Joint" type="revolute">
    <origin xyz="0 0.027 -0.126" rpy="0 0 0" />
    <parent link="arm_left_L3_Link" />
    <child link="arm_left_L4_Link" />
    <axis xyz="0 -1 0" />
    <limit lower="-0.78" upper="1.74" effort="36" velocity="10.47" />
  </joint>
  <joint name="arm_left_L5_Joint" type="revolute">
    <origin xyz="0 -0.027 -0.136" rpy="0 0 0" />
    <parent link="arm_left_L4_Link" />
    <child link="arm_left_L5_Link" />
    <axis xyz="0 0 1" />
    <limit lower="-2.96" upper="2.96" effort="14" velocity="27.21" />
  </joint>
  <joint name="arm_left_L6_Joint" type="revolute">
    <origin xyz="0 0.028 -0.0435" rpy="0 0 0" />
    <parent link="arm_left_L5_Link" />
    <child link="arm_left_L6_Link" />
    <axis xyz="0 -1 0" />
    <limit lower="-1.57" upper="1.57" effort="14" velocity="27.21" />
  </joint>
  <joint name="arm_left_L7_Joint" type="revolute">
    <origin xyz="0.028 -0.028 -0.075" rpy="0 0 0" />
    <parent link="arm_left_L6_Link" />
    <child link="arm_left_L7_Link" />
    <axis xyz="-1 0 0" />
    <limit lower="-1.57" upper="1.57" effort="14" velocity="27.21" />
  </joint>
  <joint name="arm_right_R1_Joint" type="revolute">
    <origin xyz="0 0 0" rpy="0 0 0" />
    <parent link="arm_right_R_arm_root" />
    <child link="arm_right_R1_Link" />
    <axis xyz="0 1 0" />
    <limit lower="-3.75" upper="2.18" effort="60" velocity="18.84" />
  </joint>
  <joint name="arm_right_R2_Joint" type="revolute">
    <origin xyz="0.03125 -0.0715 0" rpy="0 0 0" />
    <parent link="arm_right_R1_Link" />
    <child link="arm_right_R2_Link" />
    <axis xyz="-1 0 0" />
    <limit lower="-0.19" upper="3.33" effort="60" velocity="18.84" />
  </joint>
  <joint name="arm_right_R3_Joint" type="revolute">
    <origin xyz="-0.03125 0 -0.147" rpy="0 0 0" />
    <parent link="arm_right_R2_Link" />
    <child link="arm_right_R3_Link" />
    <axis xyz="0 0 1" />
    <limit lower="-2.26" upper="2.26" effort="17" velocity="37.68" />
  </joint>
  <joint name="arm_right_R4_Joint" type="revolute">
    <origin xyz="0 -0.027 -0.126" rpy="0 0 0" />
    <parent link="arm_right_R3_Link" />
    <child link="arm_right_R4_Link" />
    <axis xyz="0 1 0" />
    <limit lower="-1.74" upper="0.78" effort="36" velocity="10.47" />
  </joint>
  <joint name="arm_right_R5_Joint" type="revolute">
    <origin xyz="0 0.027 -0.136" rpy="0 0 0" />
    <parent link="arm_right_R4_Link" />
    <child link="arm_right_R5_Link" />
    <axis xyz="0 0 1" />
    <limit lower="-2.96" upper="2.96" effort="14" velocity="27.21" />
  </joint>
  <joint name="arm_right_R6_Joint" type="revolute">
    <origin xyz="0 -0.028 -0.0435" rpy="0 0 0" />
    <parent link="arm_right_R5_Link" />
    <child link="arm_right_R6_Link" />
    <axis xyz="0 1 0" />
    <limit lower="-1.57" upper="1.57" effort="14" velocity="27.21" />
  </joint>
  <joint name="arm_right_R7_Joint" type="revolute">
    <origin xyz="0.028 0.028 -0.075" rpy="0 0 0" />
    <parent link="arm_right_R6_Link" />
    <child link="arm_right_R7_Link" />
    <axis xyz="-1 0 0" />
    <limit lower="-1.57" upper="1.57" effort="14" velocity="27.21" />
  </joint>
  <joint name="hand_left_lh_thumb_cmc_roll" type="revolute">
    <origin xyz="-0.013419 -0.012551 0.060602" rpy="0 0 0" />
    <parent link="hand_left_lh_hand_base_link" />
    <child link="hand_left_lh_thumb_metacarpals_base1" />
    <axis xyz="-0.99996 0 -0.0087265" />
    <limit lower="0" upper="1.03" effort="4.8" velocity="1" />
  </joint>
  <joint name="hand_left_lh_thumb_cmc_yaw" type="revolute">
    <origin xyz="0.035797 0.00065879 0.00045944" rpy="0.13232 -0.0087266 0" />
    <parent link="hand_left_lh_thumb_metacarpals_base1" />
    <child link="hand_left_lh_thumb_metacarpals_base2" />
    <axis xyz="0 0.087156 0.99619" />
    <limit lower="0" upper="1.4" effort="4.8" velocity="1" />
  </joint>
  <joint name="hand_left_lh_thumb_cmc_pitch" type="revolute">
    <origin xyz="0.0036974 -0.015398 -0.0019891" rpy="0 -0.9163 1.8064" />
    <parent link="hand_left_lh_thumb_metacarpals_base2" />
    <child link="hand_left_lh_thumb_metacarpals" />
    <axis xyz="0 1 0" />
    <limit lower="0" upper="0.52" effort="4.8" velocity="1" />
  </joint>
  <joint name="hand_left_lh_thumb_mcp" type="revolute">
    <origin xyz="0.0061722 0 0.047968" rpy="0 0 0" />
    <parent link="hand_left_lh_thumb_metacarpals" />
    <child link="hand_left_lh_thumb_proximal" />
    <axis xyz="0 1 0" />
    <limit lower="0" upper="0.72" effort="3.7" velocity="1" />
    <mimic joint="hand_left_lh_thumb_cmc_pitch" multiplier="1.38" offset="0" />
  </joint>
  <joint name="hand_left_lh_thumb_ip" type="revolute">
    <origin xyz="-0.00017064 0 0.038665" rpy="0 0 0" />
    <parent link="hand_left_lh_thumb_proximal" />
    <child link="hand_left_lh_thumb_distal" />
    <axis xyz="0 1 0" />
    <limit lower="0" upper="0.78" effort="3.36" velocity="1" />
    <mimic joint="hand_left_lh_thumb_cmc_pitch" multiplier="1.49" offset="0" />
  </joint>
  <joint name="hand_left_lh_index_mcp_roll" type="revolute">
    <origin xyz="-0.0021643 -0.026654 0.13253" rpy="0.027927 -0.0087198 -0.00024358" />
    <parent link="hand_left_lh_hand_base_link" />
    <child link="hand_left_lh_index_metacarpals" />
    <axis xyz="1 0.00024367 0" />
    <limit lower="0" upper="0.19" effort="4.29" velocity="1" />
  </joint>
  <joint name="hand_left_lh_index_mcp_pitch" type="revolute">
    <origin xyz="0.0022097 0 0.015275" rpy="0 0 0.00024367" />
    <parent link="hand_left_lh_index_metacarpals" />
    <child link="hand_left_lh_index_proximal" />
    <axis xyz="0 1 0" />
    <limit lower="0" upper="1.36" effort="4.8" velocity="1" />
  </joint>
  <joint name="hand_left_lh_index_pip" type="revolute">
    <origin xyz="-0.0010697 0 0.035634" rpy="0 0 0" />
    <parent link="hand_left_lh_index_proximal" />
    <child link="hand_left_lh_index_middle" />
    <axis xyz="0 1 0" />
    <limit lower="0" upper="1.78" effort="3.7" velocity="1" />
    <mimic joint="hand_left_lh_index_mcp_pitch" multiplier="1.3" offset="0" />
  </joint>
  <joint name="hand_left_lh_index_dip" type="revolute">
    <origin xyz="-0.0052444 0 0.025711" rpy="0 0 0" />
    <parent link="hand_left_lh_index_middle" />
    <child link="hand_left_lh_index_distal" />
    <axis xyz="0 1 0" />
    <limit lower="0" upper="0.62" effort="10.43" velocity="1" />
    <mimic joint="hand_left_lh_index_mcp_pitch" multiplier="0.46" offset="0" />
  </joint>
  <joint name="hand_left_lh_middle_mcp_pitch" type="revolute">
    <origin xyz="-0.0021316 -0.0076542 0.15281" rpy="0 -0.0087266 0" />
    <parent link="hand_left_lh_hand_base_link" />
    <child link="hand_left_lh_middle_proximal" />
    <axis xyz="0 1 0" />
    <limit lower="0" upper="1.36" effort="4.8" velocity="1" />
  </joint>
  <joint name="hand_left_lh_middle_pip" type="revolute">
    <origin xyz="-0.0010861 0 0.035634" rpy="0 0 0" />
    <parent link="hand_left_lh_middle_proximal" />
    <child link="hand_left_lh_middle_middle" />
    <axis xyz="0 1 0" />
    <limit lower="0" upper="1.78" effort="3.7" velocity="1" />
    <mimic joint="hand_left_lh_middle_mcp_pitch" multiplier="1.3" offset="0" />
  </joint>
  <joint name="hand_left_lh_middle_dip" type="revolute">
    <origin xyz="-0.0052857 0 0.025703" rpy="0 0 0" />
    <parent link="hand_left_lh_middle_middle" />
    <child link="hand_left_lh_middle_distal" />
    <axis xyz="0 1 0" />
    <limit lower="0" upper="0.62" effort="10.43" velocity="1" />
    <mimic joint="hand_left_lh_middle_mcp_pitch" multiplier="0.46" offset="0" />
  </joint>
  <joint name="hand_left_lh_ring_mcp_roll" type="revolute">
    <origin xyz="-0.0021643 0.011346 0.13253" rpy="-0.024435 -0.0087266 0" />
    <parent link="hand_left_lh_hand_base_link" />
    <child link="hand_left_lh_ring_metacarpals" />
    <axis xyz="-1 0 0" />
    <limit lower="0" upper="0.2" effort="4.29" velocity="1" />
  </joint>
  <joint name="hand_left_lh_ring_mcp_pitch" type="revolute">
    <origin xyz="0.0022097 0 0.015275" rpy="0 0 0" />
    <parent link="hand_left_lh_ring_metacarpals" />
    <child link="hand_left_lh_ring_proximal" />
    <axis xyz="0 1 0" />
    <limit lower="0" upper="1.36" effort="4.8" velocity="1" />
  </joint>
  <joint name="hand_left_lh_ring_pip" type="revolute">
    <origin xyz="-0.0010697 0 0.035634" rpy="0 0 0" />
    <parent link="hand_left_lh_ring_proximal" />
    <child link="hand_left_lh_ring_middle" />
    <axis xyz="0 1 0" />
    <limit lower="0" upper="1.78" effort="3.7" velocity="1" />
    <mimic joint="hand_left_lh_ring_mcp_pitch" multiplier="1.3" offset="0" />
  </joint>
  <joint name="hand_left_lh_ring_dip" type="revolute">
    <origin xyz="-0.0052444 0 0.025711" rpy="0 0 0" />
    <parent link="hand_left_lh_ring_middle" />
    <child link="hand_left_lh_ring_distal" />
    <axis xyz="0 1 0" />
    <limit lower="0" upper="0.62" effort="10.43" velocity="1" />
    <mimic joint="hand_left_lh_ring_mcp_pitch" multiplier="0.46" offset="0" />
  </joint>
  <joint name="hand_left_lh_pinky_mcp_roll" type="revolute">
    <origin xyz="-0.00012074 0.030346 0.12755" rpy="-0.057596 -0.0087266 0" />
    <parent link="hand_left_lh_hand_base_link" />
    <child link="hand_left_lh_pinky_metacarpals" />
    <axis xyz="-1 0 0" />
    <limit lower="0" upper="0.3" effort="4.29" velocity="1" />
  </joint>
  <joint name="hand_left_lh_pinky_mcp_pitch" type="revolute">
    <origin xyz="0.0022097 0 0.015275" rpy="0 0 0" />
    <parent link="hand_left_lh_pinky_metacarpals" />
    <child link="hand_left_lh_pinky_proximal" />
    <axis xyz="0 1 0" />
    <limit lower="0" upper="1.36" effort="4.8" velocity="1" />
  </joint>
  <joint name="hand_left_lh_pinky_pip" type="revolute">
    <origin xyz="-0.0010697 0 0.035634" rpy="0 0 0" />
    <parent link="hand_left_lh_pinky_proximal" />
    <child link="hand_left_lh_pinky_middle" />
    <axis xyz="0 1 0" />
    <limit lower="0" upper="1.78" effort="3.7" velocity="1" />
    <mimic joint="hand_left_lh_pinky_mcp_pitch" multiplier="1.3" offset="0" />
  </joint>
  <joint name="hand_left_lh_pinky_dip" type="revolute">
    <origin xyz="-0.0052444 0 0.025711" rpy="0 0 0" />
    <parent link="hand_left_lh_pinky_middle" />
    <child link="hand_left_lh_pinky_distal" />
    <axis xyz="0 1 0" />
    <limit lower="0" upper="0.62" effort="10.43" velocity="1" />
    <mimic joint="hand_left_lh_pinky_mcp_pitch" multiplier="0.46" offset="0" />
  </joint>
  <joint name="hand_right_rh_thumb_cmc_roll" type="revolute">
    <origin xyz="-0.013419 0.012551 0.060602" rpy="0 0 0" />
    <parent link="hand_right_rh_hand_base_link" />
    <child link="hand_right_rh_thumb_metacarpals_base1" />
    <axis xyz="0.99996 0 -0.0087265" />
    <limit lower="0" upper="1.03" effort="4.8" velocity="1" />
  </joint>
  <joint name="hand_right_rh_thumb_cmc_yaw" type="revolute">
    <origin xyz="0.035798 -0.0006691 0.00040146" rpy="-0.13233 -0.0085747 0.0011413" />
    <parent link="hand_right_rh_thumb_metacarpals_base1" />
    <child link="hand_right_rh_thumb_metacarpals_base2" />
    <axis xyz="0 0 -1" />
    <limit lower="0" upper="1.4" effort="4.8" velocity="1" />
  </joint>
  <joint name="hand_right_rh_thumb_cmc_pitch" type="revolute">
    <origin xyz="0.0037151 0.015396 -0.0019302" rpy="0 -0.9163 -1.8076" />
    <parent link="hand_right_rh_thumb_metacarpals_base2" />
    <child link="hand_right_rh_thumb_metacarpals" />
    <axis xyz="0 1 0" />
    <limit lower="0" upper="0.52" effort="4.8" velocity="1" />
  </joint>
  <joint name="hand_right_rh_thumb_mcp" type="revolute">
    <origin xyz="0.0061722 0 0.047968" rpy="0 0 0" />
    <parent link="hand_right_rh_thumb_metacarpals" />
    <child link="hand_right_rh_thumb_proximal" />
    <axis xyz="0 1 0" />
    <limit lower="0" upper="0.72" effort="3.7" velocity="1" />
    <mimic joint="hand_right_rh_thumb_cmc_pitch" multiplier="1.38" offset="0" />
  </joint>
  <joint name="hand_right_rh_thumb_ip" type="revolute">
    <origin xyz="-0.00017064 0 0.038665" rpy="0 0 0" />
    <parent link="hand_right_rh_thumb_proximal" />
    <child link="hand_right_rh_thumb_distal" />
    <axis xyz="0 1 0" />
    <limit lower="0" upper="0.78" effort="3.36" velocity="1" />
    <mimic joint="hand_right_rh_thumb_cmc_pitch" multiplier="1.49" offset="0" />
  </joint>
  <joint name="hand_right_rh_index_mcp_roll" type="revolute">
    <origin xyz="-0.0021643 0.026654 0.13253" rpy="-0.027925 -0.0087266 0" />
    <parent link="hand_right_rh_hand_base_link" />
    <child link="hand_right_rh_index_metacarpals" />
    <axis xyz="-1 0 0" />
    <limit lower="0" upper="0.19" effort="100" velocity="1" />
  </joint>
  <joint name="hand_right_rh_index_mcp_pitch" type="revolute">
    <origin xyz="0.00220968332 0 0.0152749793" rpy="0 0 0" />
    <parent link="hand_right_rh_index_metacarpals" />
    <child link="hand_right_rh_index_proximal" />
    <axis xyz="0 1 0" />
    <limit lower="0" upper="1.36" effort="4.8" velocity="1" />
  </joint>
  <joint name="hand_right_rh_index_pip" type="revolute">
    <origin xyz="-0.0010697 0 0.035634" rpy="0 0 0" />
    <parent link="hand_right_rh_index_proximal" />
    <child link="hand_right_rh_index_middle" />
    <axis xyz="0 1 0" />
    <limit lower="0" upper="1.78" effort="3.7" velocity="1" />
    <mimic joint="hand_right_rh_index_mcp_pitch" multiplier="1.3" offset="0" />
  </joint>
  <joint name="hand_right_rh_index_dip" type="revolute">
    <origin xyz="-0.0052444 0 0.025711" rpy="0 0 0" />
    <parent link="hand_right_rh_index_middle" />
    <child link="hand_right_rh_index_distal" />
    <axis xyz="0 1 0" />
    <limit lower="0" upper="0.62" effort="10.43" velocity="1" />
    <mimic joint="hand_right_rh_index_mcp_pitch" multiplier="0.46" offset="0" />
  </joint>
  <joint name="hand_right_rh_middle_mcp_pitch" type="revolute">
    <origin xyz="-0.00213155528 0.00765417738 0.152810108" rpy="0 0 0" />
    <parent link="hand_right_rh_hand_base_link" />
    <child link="hand_right_rh_middle_proximal" />
    <axis xyz="0 1 0" />
    <limit lower="0" upper="1.36" effort="100" velocity="1" />
  </joint>
  <joint name="hand_right_rh_middle_pip" type="revolute">
    <origin xyz="-0.00139702428 0 0.035623083" rpy="0 0 0" />
    <parent link="hand_right_rh_middle_proximal" />
    <child link="hand_right_rh_middle_middle" />
    <axis xyz="0 1 0" />
    <limit lower="0" upper="1.78" effort="3.7" velocity="1" />
    <mimic joint="hand_right_rh_middle_mcp_pitch" multiplier="1.3" offset="0" />
  </joint>
  <joint name="hand_right_rh_middle_dip" type="revolute">
    <origin xyz="-0.0055098 0 0.025656" rpy="0 0 0" />
    <parent link="hand_right_rh_middle_middle" />
    <child link="hand_right_rh_middle_distal" />
    <axis xyz="0 1 0" />
    <limit lower="0" upper="0.62" effort="10.43" velocity="1" />
    <mimic joint="hand_right_rh_middle_mcp_pitch" multiplier="0.46" offset="0" />
  </joint>
  <joint name="hand_right_rh_ring_mcp_roll" type="revolute">
    <origin xyz="-0.0021643003 -0.0113458226 0.132534071" rpy="0.0244346095 -0.00872664626 0" />
    <parent link="hand_right_rh_hand_base_link" />
    <child link="hand_right_rh_ring_metacarpals" />
    <axis xyz="1 0 0" />
    <limit lower="0" upper="0.2" effort="4.29" velocity="1" />
  </joint>
  <joint name="hand_right_rh_ring_mcp_pitch" type="revolute">
    <origin xyz="0.0022097 0 0.015275" rpy="0 0 0" />
    <parent link="hand_right_rh_ring_metacarpals" />
    <child link="hand_right_rh_ring_proximal" />
    <axis xyz="0 1 0" />
    <limit lower="0" upper="1.36" effort="4.8" velocity="1" />
  </joint>
  <joint name="hand_right_rh_ring_pip" type="revolute">
    <origin xyz="-0.00106974956 0 0.0356344125" rpy="0 0 0" />
    <parent link="hand_right_rh_ring_proximal" />
    <child link="hand_right_rh_ring_middle" />
    <axis xyz="0 1 0" />
    <limit lower="0" upper="1.78" effort="3.7" velocity="1" />
    <mimic joint="hand_right_rh_ring_mcp_pitch" multiplier="1.34" offset="0" />
  </joint>
  <joint name="hand_right_rh_ring_dip" type="revolute">
    <origin xyz="-0.0052444326 0 0.0257114126" rpy="0 0 -0.000213216385" />
    <parent link="hand_right_rh_ring_middle" />
    <child link="hand_right_rh_ring_distal" />
    <axis xyz="0.000213099161 0.999450193 -0.0331551784" />
    <limit lower="0" upper="0.62" effort="10.43" velocity="1" />
    <mimic joint="hand_right_rh_ring_mcp_pitch" multiplier="0.46" offset="0" />
  </joint>
  <joint name="hand_right_rh_pinky_mcp_roll" type="revolute">
    <origin xyz="-0.00012074 -0.030346 0.12755" rpy="0.057596 -0.0087266 0" />
    <parent link="hand_right_rh_hand_base_link" />
    <child link="hand_right_rh_pinky_metacarpals" />
    <axis xyz="1 0 0" />
    <limit lower="0" upper="0.3" effort="4.29" velocity="1" />
  </joint>
  <joint name="hand_right_rh_pinky_mcp_pitch" type="revolute">
    <origin xyz="0.0022097 0 0.015275" rpy="0 0 0" />
    <parent link="hand_right_rh_pinky_metacarpals" />
    <child link="hand_right_rh_pinky_proximal" />
    <axis xyz="0 1 0" />
    <limit lower="0" upper="1.36" effort="4.8" velocity="1" />
  </joint>
  <joint name="hand_right_rh_pinky_pip" type="revolute">
    <origin xyz="-0.0010697 0 0.035634" rpy="0 0 0" />
    <parent link="hand_right_rh_pinky_proximal" />
    <child link="hand_right_rh_pinky_middle" />
    <axis xyz="0 1 0" />
    <limit lower="0" upper="1.78" effort="3.7" velocity="1" />
    <mimic joint="hand_right_rh_pinky_mcp_pitch" multiplier="1.34" offset="0" />
  </joint>
  <joint name="hand_right_rh_pinky_dip" type="revolute">
    <origin xyz="-0.0052444 0 0.025711" rpy="0 0 0" />
    <parent link="hand_right_rh_pinky_middle" />
    <child link="hand_right_rh_pinky_distal" />
    <axis xyz="0 1 0" />
    <limit lower="0" upper="0.62" effort="10.43" velocity="1" />
    <mimic joint="hand_right_rh_pinky_mcp_pitch" multiplier="0.46" offset="0" />
  </joint>
  <joint name="mount_arm_left_to_base_base_mount" type="fixed">
    <origin xyz="0 0 0" rpy="0 0 0" />
    <parent link="base_arm_left_mount" />
    <child link="arm_left_L_arm_root" />
  </joint>
  <joint name="mount_arm_right_to_base_base_mount" type="fixed">
    <origin xyz="0 0 0" rpy="0 0 0" />
    <parent link="base_arm_right_mount" />
    <child link="arm_right_R_arm_root" />
  </joint>
  <joint name="mount_hand_left_to_arm_left_wrist_mount" type="fixed">
    <origin xyz="-0.028 0 -0.052" rpy="3.1416 0 -1.5708" />
    <parent link="arm_left_L7_Link" />
    <child link="hand_left_lh_hand_base_link" />
  </joint>
  <joint name="mount_hand_right_to_arm_right_wrist_mount" type="fixed">
    <origin xyz="-0.028 0 -0.052" rpy="3.1416 0 1.5708" />
    <parent link="arm_right_R7_Link" />
    <child link="hand_right_rh_hand_base_link" />
  </joint>
  <joint name="mount_world_to_base" type="fixed">
    <origin xyz="0 0 0" rpy="0 0 0" />
    <parent link="world" />
    <child link="base_torso_root" />
  </joint>
</robot>
