<?xml version="1.0" encoding="UTF-8"?>
<!-- Generated by linker_robot_assets.composer (version 0.1.0). Workstation: a7_lite_l20lite_dc. Recipe sha256: 20d6c79abaefa963c01c961b9b7b879762da657f8e1bda6956e7199befc812b5. Do not edit by hand; re-run `python -m linker_robot_assets.composer.compose <workstation>`. -->
<mujoco model="a7_lite_l20lite_dc">
  <compiler discardvisual="false" autolimits="true" angle="radian" eulerseq="XYZ" />
  <option />
  <default>
    <default class="base_base_a7_lite_torso_visual">
      <geom type="mesh" contype="0" conaffinity="0" group="1" />
    </default>
    <default class="base_base_a7_lite_torso_collision">
      <geom type="mesh" contype="1" conaffinity="1" group="3" />
    </default>
    <default class="arm_left_arm_a7_lite_visual">
      <geom type="mesh" contype="0" conaffinity="0" group="1" />
    </default>
    <default class="arm_left_arm_a7_lite_collision">
      <geom type="mesh" contype="1" conaffinity="1" group="3" />
    </default>
    <default class="arm_right_arm_a7_lite_visual">
      <geom type="mesh" contype="0" conaffinity="0" group="1" />
    </default>
    <default class="arm_right_arm_a7_lite_collision">
      <geom type="mesh" contype="1" conaffinity="1" group="3" />
    </default>
    <default class="hand_left_hand_linkerhand_l20lite_visual">
      <geom type="mesh" contype="0" conaffinity="0" group="1" />
    </default>
    <default class="hand_left_hand_linkerhand_l20lite_collision">
      <geom type="mesh" contype="1" conaffinity="1" group="3" />
    </default>
    <default class="hand_left_hand_linkerhand_l20lite_joint">
      <joint armature="3.4707e-08" damping="4.0" frictionloss="0.5" />
    </default>
    <default class="hand_right_hand_linkerhand_l20lite_visual">
      <geom type="mesh" contype="0" conaffinity="0" group="1" />
    </default>
    <default class="hand_right_hand_linkerhand_l20lite_collision">
      <geom type="mesh" contype="1" conaffinity="1" group="3" />
    </default>
    <default class="hand_right_hand_linkerhand_l20lite_joint">
      <joint armature="3.4707e-08" damping="4.0" frictionloss="0.5" />
    </default>
  </default>
  <asset>
    <mesh name="base_torso_base_link" file="../../components/bases/a7_lite_torso/variants/default/meshes/base_link.STL" />
    <mesh name="arm_left_L1" file="../../components/arms/a7_lite/variants/left/meshes/L1_Link.STL" />
    <mesh name="arm_left_L2" file="../../components/arms/a7_lite/variants/left/meshes/L2_Link.STL" />
    <mesh name="arm_left_L3" file="../../components/arms/a7_lite/variants/left/meshes/L3_Link.STL" />
    <mesh name="arm_left_L4" file="../../components/arms/a7_lite/variants/left/meshes/L4_Link.STL" />
    <mesh name="arm_left_L5" file="../../components/arms/a7_lite/variants/left/meshes/L5_Link.STL" />
    <mesh name="arm_left_L6" file="../../components/arms/a7_lite/variants/left/meshes/L6_Link.STL" />
    <mesh name="arm_left_L7" file="../../components/arms/a7_lite/variants/left/meshes/L7_Link.STL" />
    <mesh name="arm_right_R1" file="../../components/arms/a7_lite/variants/right/meshes/R1_Link.STL" />
    <mesh name="arm_right_R2" file="../../components/arms/a7_lite/variants/right/meshes/R2_Link.STL" />
    <mesh name="arm_right_R3" file="../../components/arms/a7_lite/variants/right/meshes/R3_Link.STL" />
    <mesh name="arm_right_R4" file="../../components/arms/a7_lite/variants/right/meshes/R4_Link.STL" />
    <mesh name="arm_right_R5" file="../../components/arms/a7_lite/variants/right/meshes/R5_Link.STL" />
    <mesh name="arm_right_R6" file="../../components/arms/a7_lite/variants/right/meshes/R6_Link.STL" />
    <mesh name="arm_right_R7" file="../../components/arms/a7_lite/variants/right/meshes/R7_Link.STL" />
    <mesh name="hand_left_hand_base_link" file="../../components/hands/linkerhand_l20lite/variants/left/meshes/hand_base_link.STL" />
    <mesh name="hand_left_thumb_metacarpals_base1" file="../../components/hands/linkerhand_l20lite/variants/left/meshes/thumb_metacarpals_base1.STL" />
    <mesh name="hand_left_thumb_metacarpals_base2" file="../../components/hands/linkerhand_l20lite/variants/left/meshes/thumb_metacarpals_base2.STL" />
    <mesh name="hand_left_thumb_metacarpals" file="../../components/hands/linkerhand_l20lite/variants/left/meshes/thumb_metacarpals.STL" />
    <mesh name="hand_left_thumb_proximal" file="../../components/hands/linkerhand_l20lite/variants/left/meshes/thumb_proximal.STL" />
    <mesh name="hand_left_thumb_distal" file="../../components/hands/linkerhand_l20lite/variants/left/meshes/thumb_distal.STL" />
    <mesh name="hand_left_index_metacarpals" file="../../components/hands/linkerhand_l20lite/variants/left/meshes/index_metacarpals.STL" />
    <mesh name="hand_left_index_proximal" file="../../components/hands/linkerhand_l20lite/variants/left/meshes/index_proximal.STL" />
    <mesh name="hand_left_index_middle" file="../../components/hands/linkerhand_l20lite/variants/left/meshes/index_middle.STL" />
    <mesh name="hand_left_index_distal" file="../../components/hands/linkerhand_l20lite/variants/left/meshes/index_distal.STL" />
    <mesh name="hand_left_middle_proximal" file="../../components/hands/linkerhand_l20lite/variants/left/meshes/middle_proximal.STL" />
    <mesh name="hand_left_middle_middle" file="../../components/hands/linkerhand_l20lite/variants/left/meshes/middle_middle.STL" />
    <mesh name="hand_left_middle_distal" file="../../components/hands/linkerhand_l20lite/variants/left/meshes/middle_distal.STL" />
    <mesh name="hand_left_ring_metacarpals" file="../../components/hands/linkerhand_l20lite/variants/left/meshes/ring_metacarpals.STL" />
    <mesh name="hand_left_ring_proximal" file="../../components/hands/linkerhand_l20lite/variants/left/meshes/ring_proximal.STL" />
    <mesh name="hand_left_ring_middle" file="../../components/hands/linkerhand_l20lite/variants/left/meshes/ring_middle.STL" />
    <mesh name="hand_left_ring_distal" file="../../components/hands/linkerhand_l20lite/variants/left/meshes/ring_distal.STL" />
    <mesh name="hand_left_pinky_metacarpals" file="../../components/hands/linkerhand_l20lite/variants/left/meshes/pinky_metacarpals.STL" />
    <mesh name="hand_left_pinky_proximal" file="../../components/hands/linkerhand_l20lite/variants/left/meshes/pinky_proximal.STL" />
    <mesh name="hand_left_pinky_middle" file="../../components/hands/linkerhand_l20lite/variants/left/meshes/pinky_middle.STL" />
    <mesh name="hand_left_pinky_distal" file="../../components/hands/linkerhand_l20lite/variants/left/meshes/pinky_distal.STL" />
    <mesh name="hand_right_hand_base_link" file="../../components/hands/linkerhand_l20lite/variants/right/meshes/hand_base_link.STL" />
    <mesh name="hand_right_thumb_metacarpals_base1" file="../../components/hands/linkerhand_l20lite/variants/right/meshes/thumb_metacarpals_base1.STL" />
    <mesh name="hand_right_thumb_metacarpals_base2" file="../../components/hands/linkerhand_l20lite/variants/right/meshes/thumb_metacarpals_base2.STL" />
    <mesh name="hand_right_thumb_metacarpals" file="../../components/hands/linkerhand_l20lite/variants/right/meshes/thumb_metacarpals.STL" />
    <mesh name="hand_right_thumb_proximal" file="../../components/hands/linkerhand_l20lite/variants/right/meshes/thumb_proximal.STL" />
    <mesh name="hand_right_thumb_distal" file="../../components/hands/linkerhand_l20lite/variants/right/meshes/thumb_distal.STL" />
    <mesh name="hand_right_index_metacarpals" file="../../components/hands/linkerhand_l20lite/variants/right/meshes/index_metacarpals.STL" />
    <mesh name="hand_right_index_proximal" file="../../components/hands/linkerhand_l20lite/variants/right/meshes/index_proximal.STL" />
    <mesh name="hand_right_index_middle" file="../../components/hands/linkerhand_l20lite/variants/right/meshes/index_middle.STL" />
    <mesh name="hand_right_index_distal" file="../../components/hands/linkerhand_l20lite/variants/right/meshes/index_distal.STL" />
    <mesh name="hand_right_middle_proximal" file="../../components/hands/linkerhand_l20lite/variants/right/meshes/middle_proximal.STL" />
    <mesh name="hand_right_middle_middle" file="../../components/hands/linkerhand_l20lite/variants/right/meshes/middle_middle.STL" />
    <mesh name="hand_right_middle_distal" file="../../components/hands/linkerhand_l20lite/variants/right/meshes/middle_distal.STL" />
    <mesh name="hand_right_ring_metacarpals" file="../../components/hands/linkerhand_l20lite/variants/right/meshes/ring_metacarpals.STL" />
    <mesh name="hand_right_ring_proximal" file="../../components/hands/linkerhand_l20lite/variants/right/meshes/ring_proximal.STL" />
    <mesh name="hand_right_ring_middle" file="../../components/hands/linkerhand_l20lite/variants/right/meshes/ring_middle.STL" />
    <mesh name="hand_right_ring_distal" file="../../components/hands/linkerhand_l20lite/variants/right/meshes/ring_distal.STL" />
    <mesh name="hand_right_pinky_metacarpals" file="../../components/hands/linkerhand_l20lite/variants/right/meshes/pinky_metacarpals.STL" />
    <mesh name="hand_right_pinky_proximal" file="../../components/hands/linkerhand_l20lite/variants/right/meshes/pinky_proximal.STL" />
    <mesh name="hand_right_pinky_middle" file="../../components/hands/linkerhand_l20lite/variants/right/meshes/pinky_middle.STL" />
    <mesh name="hand_right_pinky_distal" file="../../components/hands/linkerhand_l20lite/variants/right/meshes/pinky_distal.STL" />
  </asset>
  <worldbody>
    <body name="base_torso_root" pos="0 0 0">
      <body name="base_base_link" pos="0 0 1.2">
        <inertial pos="0.0044493 9.5996E-07 -0.58827" mass="8.6616" fullinertia="0.19297 0.19297 0.072594 1.6977E-06 0.00086704 4.1272E-08" />
        <geom class="base_base_a7_lite_torso_visual" mesh="base_torso_base_link" />
        <geom class="base_base_a7_lite_torso_collision" mesh="base_torso_base_link" />
        <body name="base_arm_left_mount" pos="0.0062932 0.1505 -0.022706">
          <site name="base_arm_left_mount" pos="0 0 0" />
          <body name="arm_left_L_arm_root" pos="0 0 0">
            <site name="arm_left_base_mount" pos="0 0 0" />
            <body name="arm_left_L1_Link" pos="0 0 0">
              <inertial pos="0.0045974 0.067978 0.00066635" mass="1.1899" fullinertia="0.0016082 0.00086283 0.00092662 3.5266E-06 2.0532E-07 6.5642E-06" />
              <joint name="arm_left_L1_Joint" type="hinge" axis="0 -1 0" range="-2.18 3.75" damping="20" frictionloss="0.0" armature="0.01" />
              <geom class="arm_left_arm_a7_lite_visual" mesh="arm_left_L1" />
              <geom class="arm_left_arm_a7_lite_collision" mesh="arm_left_L1" />
              <body name="arm_left_L2_Link" pos="0.03125 0.0715 0">
                <inertial pos="-0.030894 9.2644E-05 -0.099437" mass="1.0659" fullinertia="0.001451 0.0012495 0.0010752 3.1371E-06 -1.519E-06 -1.1542E-05" />
                <joint name="arm_left_L2_Joint" type="hinge" axis="-1 0 0" range="-3.33 0.19" damping="20" frictionloss="0.0" armature="0.01" />
                <geom class="arm_left_arm_a7_lite_visual" mesh="arm_left_L2" />
                <geom class="arm_left_arm_a7_lite_collision" mesh="arm_left_L2" />
                <body name="arm_left_L3_Link" pos="-0.03125 0 -0.147">
                  <inertial pos="-5.9577E-05 0.001318 -0.078466" mass="1.2763" fullinertia="0.00078242 0.0010444 0.00063166 -2.9327E-07 7.1339E-06 -2.978E-07" />
                  <joint name="arm_left_L3_Joint" type="hinge" axis="0 0 1" range="-2.26 2.26" damping="20" frictionloss="0.0" armature="0.01" />
                  <geom class="arm_left_arm_a7_lite_visual" mesh="arm_left_L3" />
                  <geom class="arm_left_arm_a7_lite_collision" mesh="arm_left_L3" />
                  <body name="arm_left_L4_Link" pos="0 0.027 -0.126">
                    <inertial pos="1.6127E-05 -0.027094 -0.086199" mass="0.66812" fullinertia="0.00039892 0.00038456 0.00041366 5.379E-08 1.7668E-06 1.0506E-06" />
                    <joint name="arm_left_L4_Joint" type="hinge" axis="0 -1 0" range="-0.78 1.74" damping="20" frictionloss="0.0" armature="0.01" />
                    <geom class="arm_left_arm_a7_lite_visual" mesh="arm_left_L4" />
                    <geom class="arm_left_arm_a7_lite_collision" mesh="arm_left_L4" />
                    <body name="arm_left_L5_Link" pos="0 -0.027 -0.136">
                      <inertial pos="-0.00012977 0.0029474 -0.03886" mass="0.4439" fullinertia="0.00015511 0.00022136 0.00013737 -4.6133E-07 -2.6472E-06 -1.0454E-07" />
                      <joint name="arm_left_L5_Joint" type="hinge" axis="0 0 1" range="-2.96 2.96" damping="20" frictionloss="0.0" armature="0.01" />
                      <geom class="arm_left_arm_a7_lite_visual" mesh="arm_left_L5" />
                      <geom class="arm_left_arm_a7_lite_collision" mesh="arm_left_L5" />
                      <body name="arm_left_L6_Link" pos="0 0.028 -0.0435">
                        <inertial pos="0.0023746 -0.027691 -0.063927" mass="0.5193" fullinertia="0.00031746 0.00024364 0.00015858 -6.3455E-07 4.1005E-07 2.8635E-06" />
                        <joint name="arm_left_L6_Joint" type="hinge" axis="0 -1 0" range="-1.57 1.57" damping="20" frictionloss="0.0" armature="0.01" />
                        <geom class="arm_left_arm_a7_lite_visual" mesh="arm_left_L6" />
                        <geom class="arm_left_arm_a7_lite_collision" mesh="arm_left_L6" />
                        <body name="arm_left_L7_Link" pos="0.028 -0.028 -0.075">
                          <inertial pos="-0.026398 -6.6336E-15 -0.025801" mass="0.10175" fullinertia="4.5036E-05 3.8663E-05 3.0632E-05 -4.7046E-12 2.2349E-07 -1.9234E-20" />
                          <joint name="arm_left_L7_Joint" type="hinge" axis="-1 0 0" range="-1.57 1.57" damping="20" frictionloss="0.0" armature="0.01" />
                          <geom class="arm_left_arm_a7_lite_visual" mesh="arm_left_L7" />
                          <geom class="arm_left_arm_a7_lite_collision" mesh="arm_left_L7" />
                          <site name="arm_left_tool0" pos="0 0 0" />
                          <body name="hand_left_lh_hand_base_link" pos="-0.028 0 -0.052" euler="3.1416 0 -1.5708">
                            <inertial pos="-0.00378861347432373 0.000820204450131895 0.0805686615689543" mass="0.103652479414672" fullinertia="0.000193076183440551 0.000129262885172737 7.7154522927273e-05 1.28622350247875e-06 -2.06064564153793e-07 -2.33887125894354e-06" />
                            <geom class="hand_left_hand_linkerhand_l20lite_visual" mesh="hand_left_hand_base_link" />
                            <geom class="hand_left_hand_linkerhand_l20lite_collision" mesh="hand_left_hand_base_link" />
                            <site name="hand_left_wrist_mount" pos="0 0 0" />
                            <body name="hand_left_lh_thumb_metacarpals_base1" pos="-0.013419 -0.012551 0.060602">
                              <inertial pos="0.0284841419451473 0.0032328053117659 1.27102541975441e-05" mass="0.00840514828448049" fullinertia="1.40225690783513e-06 9.92532738625187e-07 7.25924523731736e-07 1.196162690714e-07 7.34629714950971e-09 -4.63982709938509e-08" />
                              <joint name="hand_left_lh_thumb_cmc_roll" class="hand_left_hand_linkerhand_l20lite_joint" type="hinge" axis="-0.99996 0 -0.0087265" range="0 1.03" />
                              <geom class="hand_left_hand_linkerhand_l20lite_visual" mesh="hand_left_thumb_metacarpals_base1" />
                              <geom class="hand_left_hand_linkerhand_l20lite_collision" mesh="hand_left_thumb_metacarpals_base1" />
                              <body name="hand_left_lh_thumb_metacarpals_base2" pos="0.035797 0.00065879 0.00045944" euler="0.13232 -0.0087266 0">
                                <inertial pos="0.00149333647480262 -0.00615813217507052 -0.000273768129351912" mass="0.00244725656099355" fullinertia="1.15757169903916e-07 9.88121769947347e-08 6.88506418885536e-08 -4.50060051446398e-09 -9.19744539328016e-10 3.81969206030993e-09" />
                                <joint name="hand_left_lh_thumb_cmc_yaw" class="hand_left_hand_linkerhand_l20lite_joint" type="hinge" axis="0 0.087156 0.99619" range="0 1.4" />
                                <geom class="hand_left_hand_linkerhand_l20lite_visual" mesh="hand_left_thumb_metacarpals_base2" />
                                <geom class="hand_left_hand_linkerhand_l20lite_collision" mesh="hand_left_thumb_metacarpals_base2" />
                                <body name="hand_left_lh_thumb_metacarpals" pos="0.0036974 -0.015398 -0.0019891" euler="0 -0.9163 1.8064">
                                  <inertial pos="0.00183663729904029 3.46162460989133e-06 0.026990412201572" mass="0.0152011788694593" fullinertia="2.95369587925714e-06 3.84770419198789e-06 1.32008560539723e-06 4.74536745194236e-11 -1.58087239939667e-07 4.13672896569864e-10" />
                                  <joint name="hand_left_lh_thumb_cmc_pitch" class="hand_left_hand_linkerhand_l20lite_joint" type="hinge" axis="0 1 0" range="0 0.52" />
                                  <geom class="hand_left_hand_linkerhand_l20lite_visual" mesh="hand_left_thumb_metacarpals" />
                                  <geom class="hand_left_hand_linkerhand_l20lite_collision" mesh="hand_left_thumb_metacarpals" />
                                  <body name="hand_left_lh_thumb_proximal" pos="0.0061722 0 0.047968">
                                    <inertial pos="0.00159260267405223 4.28988976902342e-06 0.0151572309111939" mass="0.00662225085289633" fullinertia="1.01526328949763e-06 9.10425089721739e-07 4.47462917464685e-07 -7.87460584199835e-12 -4.4224308859969e-08 2.81833762972893e-11" />
                                    <joint name="hand_left_lh_thumb_mcp" class="hand_left_hand_linkerhand_l20lite_joint" type="hinge" axis="0 1 0" range="0 0.72" />
                                    <geom class="hand_left_hand_linkerhand_l20lite_visual" mesh="hand_left_thumb_proximal" />
                                    <geom class="hand_left_hand_linkerhand_l20lite_collision" mesh="hand_left_thumb_proximal" />
                                    <body name="hand_left_lh_thumb_distal" pos="-0.00017064 0 0.038665">
                                      <inertial pos="-0.00138833978915306 -1.92768110708619e-06 0.0115764513296314" mass="0.00512798334000111" fullinertia="3.30808161248092e-07 3.2363078244428e-07 2.48875198442135e-07 -3.43833611720834e-10 -1.04696624534012e-07 -1.18697138701936e-10" />
                                      <joint name="hand_left_lh_thumb_ip" class="hand_left_hand_linkerhand_l20lite_joint" type="hinge" axis="0 1 0" range="0 0.78" />
                                      <geom class="hand_left_hand_linkerhand_l20lite_visual" mesh="hand_left_thumb_distal" />
                                      <geom class="hand_left_hand_linkerhand_l20lite_collision" mesh="hand_left_thumb_distal" />
                                    </body>
                                  </body>
                                </body>
                              </body>
                            </body>
                            <body name="hand_left_lh_index_metacarpals" pos="-0.0021643 -0.026654 0.13253" euler="0.027927 -0.0087198 -0.00024358">
                              <inertial pos="-0.00143091454702933 2.56878017135254e-07 0.0107040528609869" mass="0.0038877126435198" fullinertia="1.87149599832498e-07 2.75278147668716e-07 2.06866317113344e-07 3.67335498441413e-11 1.3415127653338e-08 2.44762951204078e-11" />
                              <joint name="hand_left_lh_index_mcp_roll" class="hand_left_hand_linkerhand_l20lite_joint" type="hinge" axis="1 0.00024367 0" range="0 0.19" />
                              <geom class="hand_left_hand_linkerhand_l20lite_visual" mesh="hand_left_index_metacarpals" />
                              <geom class="hand_left_hand_linkerhand_l20lite_collision" mesh="hand_left_index_metacarpals" />
                              <body name="hand_left_lh_index_proximal" pos="0.0022097 0 0.015275" euler="0 0 0.00024367">
                                <inertial pos="-0.00122347616770057 -2.04121170566118e-06 0.0182409893195748" mass="0.00316246584579941" fullinertia="3.57135128024094e-07 3.51905870436209e-07 1.40872561400322e-07 1.42036124901073e-11 -4.14209968733606e-08 -1.08557233942923e-10" />
                                <joint name="hand_left_lh_index_mcp_pitch" class="hand_left_hand_linkerhand_l20lite_joint" type="hinge" axis="0 1 0" range="0 1.36" />
                                <geom class="hand_left_hand_linkerhand_l20lite_visual" mesh="hand_left_index_proximal" />
                                <geom class="hand_left_hand_linkerhand_l20lite_collision" mesh="hand_left_index_proximal" />
                                <body name="hand_left_lh_index_middle" pos="-0.0010697 0 0.035634">
                                  <inertial pos="-0.00250309203564306 2.18945385091485e-06 0.0110397390913486" mass="0.00283043921422803" fullinertia="2.61037133593912e-07 2.33077518995487e-07 1.26543797445814e-07 5.76197451786318e-11 -4.0011060525121e-08 -2.86979503467821e-11" />
                                  <joint name="hand_left_lh_index_pip" class="hand_left_hand_linkerhand_l20lite_joint" type="hinge" axis="0 1 0" range="0 1.78" />
                                  <geom class="hand_left_hand_linkerhand_l20lite_visual" mesh="hand_left_index_middle" />
                                  <geom class="hand_left_hand_linkerhand_l20lite_collision" mesh="hand_left_index_middle" />
                                  <body name="hand_left_lh_index_distal" pos="-0.0052444 0 0.025711">
                                    <inertial pos="-0.000604509916724614 -4.77400032578013e-06 0.0121511111849248" mass="0.0031445375098231" fullinertia="1.64070673729839e-07 1.48362830813358e-07 9.7804088657243e-08 1.88963511473794e-11 -4.27776869144244e-08 -1.9734013143508e-10" />
                                    <joint name="hand_left_lh_index_dip" class="hand_left_hand_linkerhand_l20lite_joint" type="hinge" axis="0 1 0" range="0 0.62" />
                                    <geom class="hand_left_hand_linkerhand_l20lite_visual" mesh="hand_left_index_distal" />
                                    <geom class="hand_left_hand_linkerhand_l20lite_collision" mesh="hand_left_index_distal" />
                                  </body>
                                </body>
                              </body>
                            </body>
                            <body name="hand_left_lh_middle_proximal" pos="-0.0021316 -0.0076542 0.15281" euler="0 -0.0087266 0">
                              <inertial pos="-0.00123185150819907 -2.04476498746886e-06 0.0182404193627525" mass="0.00316246719662224" fullinertia="3.57097075648345e-07 3.51905920397223e-07 1.4091067749978e-07 1.43002807788619e-11 -4.15201646947523e-08 -1.08488557665733e-10" />
                              <joint name="hand_left_lh_middle_mcp_pitch" class="hand_left_hand_linkerhand_l20lite_joint" type="hinge" axis="0 1 0" range="0 1.36" />
                              <geom class="hand_left_hand_linkerhand_l20lite_visual" mesh="hand_left_middle_proximal" />
                              <geom class="hand_left_hand_linkerhand_l20lite_collision" mesh="hand_left_middle_proximal" />
                              <body name="hand_left_lh_middle_middle" pos="-0.0010861 0 0.035634">
                                <inertial pos="-0.00252079729924576 2.18964489481777e-06 0.0110357094277332" mass="0.00283043921858529" fullinertia="2.60908423355366e-07 2.33077520740401e-07 1.26672514044425e-07 5.76720293661014e-11 -4.02265908644236e-08 -2.86057758459882e-11" />
                                <joint name="hand_left_lh_middle_pip" class="hand_left_hand_linkerhand_l20lite_joint" type="hinge" axis="0 1 0" range="0 1.78" />
                                <geom class="hand_left_hand_linkerhand_l20lite_visual" mesh="hand_left_middle_middle" />
                                <geom class="hand_left_hand_linkerhand_l20lite_collision" mesh="hand_left_middle_middle" />
                                <body name="hand_left_lh_middle_distal" pos="-0.0052857 0 0.025703">
                                  <inertial pos="-0.000622397825955366 -4.75569749899818e-06 0.012150171418504" mass="0.00314452092964384" fullinertia="1.63942838563309e-07 1.48361296215111e-07 9.7929884595885e-08 1.9526841627913e-11 -4.28753645610842e-08 -1.96949597957508e-10" />
                                  <joint name="hand_left_lh_middle_dip" class="hand_left_hand_linkerhand_l20lite_joint" type="hinge" axis="0 1 0" range="0 0.62" />
                                  <geom class="hand_left_hand_linkerhand_l20lite_visual" mesh="hand_left_middle_distal" />
                                  <geom class="hand_left_hand_linkerhand_l20lite_collision" mesh="hand_left_middle_distal" />
                                </body>
                              </body>
                            </body>
                            <body name="hand_left_lh_ring_metacarpals" pos="-0.0021643 0.011346 0.13253" euler="-0.024435 -0.0087266 0">
                              <inertial pos="-0.00143091448892014 6.05495226457808e-07 0.0107040523320813" mass="0.00388771255966599" fullinertia="1.87149578481638e-07 2.75278155094349e-07 2.06866318930306e-07 1.52642675041227e-11 1.34151349601248e-08 2.12062463357117e-11" />
                              <joint name="hand_left_lh_ring_mcp_roll" class="hand_left_hand_linkerhand_l20lite_joint" type="hinge" axis="-1 0 0" range="0 0.2" />
                              <geom class="hand_left_hand_linkerhand_l20lite_visual" mesh="hand_left_ring_metacarpals" />
                              <geom class="hand_left_hand_linkerhand_l20lite_collision" mesh="hand_left_ring_metacarpals" />
                              <body name="hand_left_lh_ring_proximal" pos="0.0022097 0 0.015275">
                                <inertial pos="-0.00122347652312429 -2.0423407393888e-06 0.0182409875332818" mass="0.00316246660225829" fullinertia="3.5713512847731e-07 3.51905881089114e-07 1.40872582931496e-07 1.42130904393983e-11 -4.14209983311065e-08 -1.08576103054512e-10" />
                                <joint name="hand_left_lh_ring_mcp_pitch" class="hand_left_hand_linkerhand_l20lite_joint" type="hinge" axis="0 1 0" range="0 1.36" />
                                <geom class="hand_left_hand_linkerhand_l20lite_visual" mesh="hand_left_ring_proximal" />
                                <geom class="hand_left_hand_linkerhand_l20lite_collision" mesh="hand_left_ring_proximal" />
                                <body name="hand_left_lh_ring_middle" pos="-0.0010697 0 0.035634">
                                  <inertial pos="-0.00250309189885196 2.18959036171751e-06 0.0110397385966097" mass="0.00283043920090097" fullinertia="2.61037130501287e-07 2.33077521207674e-07 1.26543807918808e-07 5.76216047828233e-11 -4.00110582573436e-08 -2.86985395311388e-11" />
                                  <joint name="hand_left_lh_ring_pip" class="hand_left_hand_linkerhand_l20lite_joint" type="hinge" axis="0 1 0" range="0 1.78" />
                                  <geom class="hand_left_hand_linkerhand_l20lite_visual" mesh="hand_left_ring_middle" />
                                  <geom class="hand_left_hand_linkerhand_l20lite_collision" mesh="hand_left_ring_middle" />
                                  <body name="hand_left_lh_ring_distal" pos="-0.0052444 0 0.025711">
                                    <inertial pos="-0.000604497650389674 -4.73100652065295e-06 0.012151126431567" mass="0.00314454943731604" fullinertia="1.64071049652571e-07 1.48363091013624e-07 9.78042601257212e-08 1.94791513771428e-11 -4.27777374237679e-08 -1.96468435398403e-10" />
                                    <joint name="hand_left_lh_ring_dip" class="hand_left_hand_linkerhand_l20lite_joint" type="hinge" axis="0 1 0" range="0 0.62" />
                                    <geom class="hand_left_hand_linkerhand_l20lite_visual" mesh="hand_left_ring_distal" />
                                    <geom class="hand_left_hand_linkerhand_l20lite_collision" mesh="hand_left_ring_distal" />
                                  </body>
                                </body>
                              </body>
                            </body>
                            <body name="hand_left_lh_pinky_metacarpals" pos="-0.00012074 0.030346 0.12755" euler="-0.057596 -0.0087266 0">
                              <inertial pos="-0.00143091630673887 6.05311374107798e-07 0.010704049929046" mass="0.00388771229554929" fullinertia="1.87149536268889e-07 2.75278106047772e-07 2.06866328803883e-07 1.52679681737727e-11 1.34151204706615e-08 2.11967245454867e-11" />
                              <joint name="hand_left_lh_pinky_mcp_roll" class="hand_left_hand_linkerhand_l20lite_joint" type="hinge" axis="-1 0 0" range="0 0.3" />
                              <geom class="hand_left_hand_linkerhand_l20lite_visual" mesh="hand_left_pinky_metacarpals" />
                              <geom class="hand_left_hand_linkerhand_l20lite_collision" mesh="hand_left_pinky_metacarpals" />
                              <body name="hand_left_lh_pinky_proximal" pos="0.0022097 0 0.015275">
                                <inertial pos="-0.00122347805395697 -2.04329569369888e-06 0.0182409919418033" mass="0.00316246781629033" fullinertia="3.57135263144139e-07 3.5190602349514e-07 1.40872647811026e-07 1.42286998987323e-11 -4.14209901998364e-08 -1.08636442666922e-10" />
                                <joint name="hand_left_lh_pinky_mcp_pitch" class="hand_left_hand_linkerhand_l20lite_joint" type="hinge" axis="0 1 0" range="0 1.36" />
                                <geom class="hand_left_hand_linkerhand_l20lite_visual" mesh="hand_left_pinky_proximal" />
                                <geom class="hand_left_hand_linkerhand_l20lite_collision" mesh="hand_left_pinky_proximal" />
                                <body name="hand_left_lh_pinky_middle" pos="-0.0010697 0 0.035634">
                                  <inertial pos="-0.00250309214140259 2.1894783039933e-06 0.0110397383273556" mass="0.00283043906989622" fullinertia="2.61037124783617e-07 2.33077513229909e-07 1.2654380297458e-07 5.7617222079153e-11 -4.00110565109454e-08 -2.86988443315275e-11" />
                                  <joint name="hand_left_lh_pinky_pip" class="hand_left_hand_linkerhand_l20lite_joint" type="hinge" axis="0 1 0" range="0 1.78" />
                                  <geom class="hand_left_hand_linkerhand_l20lite_visual" mesh="hand_left_pinky_middle" />
                                  <geom class="hand_left_hand_linkerhand_l20lite_collision" mesh="hand_left_pinky_middle" />
                                  <body name="hand_left_lh_pinky_distal" pos="-0.0052444 0 0.025711">
                                    <inertial pos="-0.000604492895887754 -4.75263680191351e-06 0.0121511379180032" mass="0.00314455887032079" fullinertia="1.64071496633017e-07 1.48363675410427e-07 9.78043717695209e-08 1.95563986835622e-11 -4.27779200959899e-08 -1.9679860568024e-10" />
                                    <joint name="hand_left_lh_pinky_dip" class="hand_left_hand_linkerhand_l20lite_joint" type="hinge" axis="0 1 0" range="0 0.62" />
                                    <geom class="hand_left_hand_linkerhand_l20lite_visual" mesh="hand_left_pinky_distal" />
                                    <geom class="hand_left_hand_linkerhand_l20lite_collision" mesh="hand_left_pinky_distal" />
                                  </body>
                                </body>
                              </body>
                            </body>
                          </body>
                        </body>
                      </body>
                    </body>
                  </body>
                </body>
              </body>
            </body>
          </body>
        </body>
        <body name="base_arm_right_mount" pos="0.0062926 -0.1505 -0.022706">
          <site name="base_arm_right_mount" pos="0 0 0" />
          <body name="arm_right_R_arm_root" pos="0 0 0">
            <site name="arm_right_base_mount" pos="0 0 0" />
            <body name="arm_right_R1_Link" pos="0 0 0">
              <inertial pos="0.004598 -0.067915 0.00072736" mass="1.1899" fullinertia="0.0016082 0.00086157 0.00092788 -3.3435E-06 3.9187E-07 -6.5828E-06" />
              <joint name="arm_right_R1_Joint" type="hinge" axis="0 1 0" range="-3.75 2.18" damping="20" frictionloss="0.0" armature="0.01" />
              <geom class="arm_right_arm_a7_lite_visual" mesh="arm_right_R1" />
              <geom class="arm_right_arm_a7_lite_collision" mesh="arm_right_R1" />
              <body name="arm_right_R2_Link" pos="0.03125 -0.0715 0">
                <inertial pos="-0.031363 2.7784E-05 -0.099445" mass="1.0663" fullinertia="0.0014523 0.0012484 0.0010754 -8.9962E-07 -1.031E-06 1.1436E-05" />
                <joint name="arm_right_R2_Joint" type="hinge" axis="-1 0 0" range="-0.19 3.33" damping="20" frictionloss="0.0" armature="0.01" />
                <geom class="arm_right_arm_a7_lite_visual" mesh="arm_right_R2" />
                <geom class="arm_right_arm_a7_lite_collision" mesh="arm_right_R2" />
                <body name="arm_right_R3_Link" pos="-0.03125 0 -0.147">
                  <inertial pos="-2.2895E-05 -0.00123 -0.077166" mass="1.3517" fullinertia="0.00080502 0.0010686 0.00067469 2.8702E-07 7.1845E-06 -7.5659E-07" />
                  <joint name="arm_right_R3_Joint" type="hinge" axis="0 0 1" range="-2.26 2.26" damping="20" frictionloss="0.0" armature="0.01" />
                  <geom class="arm_right_arm_a7_lite_visual" mesh="arm_right_R3" />
                  <geom class="arm_right_arm_a7_lite_collision" mesh="arm_right_R3" />
                  <body name="arm_right_R4_Link" pos="0 -0.027 -0.126">
                    <inertial pos="1.2714E-05 0.024908 -0.082641" mass="0.69691" fullinertia="0.00041505 0.00041627 0.00043007 5.3251E-08 1.7254E-06 3.826E-07" />
                    <joint name="arm_right_R4_Joint" type="hinge" axis="0 1 0" range="-1.74 0.78" damping="20" frictionloss="0.0" armature="0.01" />
                    <geom class="arm_right_arm_a7_lite_visual" mesh="arm_right_R4" />
                    <geom class="arm_right_arm_a7_lite_collision" mesh="arm_right_R4" />
                    <body name="arm_right_R5_Link" pos="0 0.027 -0.136">
                      <inertial pos="0.00029153 -0.0027009 -0.035875" mass="0.48527" fullinertia="0.00016555 0.00022756 0.00015289 -5.747E-07 -2.6985E-06 -9.211E-07" />
                      <joint name="arm_right_R5_Joint" type="hinge" axis="0 0 1" range="-2.96 2.96" damping="20" frictionloss="0.0" armature="0.01" />
                      <geom class="arm_right_arm_a7_lite_visual" mesh="arm_right_R5" />
                      <geom class="arm_right_arm_a7_lite_collision" mesh="arm_right_R5" />
                      <body name="arm_right_R6_Link" pos="0 -0.028 -0.0435">
                        <inertial pos="0.0023746 0.027704 -0.063949" mass="0.5193" fullinertia="0.00031746 0.00024364 0.00015858 6.3467E-07 4.1001E-07 -2.8219E-06" />
                        <joint name="arm_right_R6_Joint" type="hinge" axis="0 1 0" range="-1.57 1.57" damping="20" frictionloss="0.0" armature="0.01" />
                        <geom class="arm_right_arm_a7_lite_visual" mesh="arm_right_R6" />
                        <geom class="arm_right_arm_a7_lite_collision" mesh="arm_right_R6" />
                        <body name="arm_right_R7_Link" pos="0.028 0.028 -0.075">
                          <inertial pos="-0.026598 3.7248E-14 -0.025801" mass="0.10175" fullinertia="4.5036E-05 3.8663E-05 3.0632E-05 -4.7046E-12 2.2349E-07 -1.5968E-20" />
                          <joint name="arm_right_R7_Joint" type="hinge" axis="-1 0 0" range="-1.57 1.57" damping="20" frictionloss="0.0" armature="0.01" />
                          <geom class="arm_right_arm_a7_lite_visual" mesh="arm_right_R7" />
                          <geom class="arm_right_arm_a7_lite_collision" mesh="arm_right_R7" />
                          <site name="arm_right_tool0" pos="0 0 0" />
                          <body name="hand_right_rh_hand_base_link" pos="-0.028 0 -0.052" euler="3.1416 0 1.5708">
                            <inertial pos="-0.00378572993475002 -0.00041583904893102 0.083639288361369" mass="0.108844276105116" fullinertia="0.000193454839560416 0.000129793182936331 7.75126657491833e-05 -1.28842682703635e-06 -1.97005632027442e-07 2.34961034039848e-06" />
                            <geom class="hand_right_hand_linkerhand_l20lite_visual" mesh="hand_right_hand_base_link" />
                            <geom class="hand_right_hand_linkerhand_l20lite_collision" mesh="hand_right_hand_base_link" />
                            <site name="hand_right_wrist_mount" pos="0 0 0" />
                            <body name="hand_right_rh_thumb_metacarpals_base1" pos="-0.013419 0.012551 0.060602">
                              <inertial pos="0.0284798868788809 -0.00318431295224701 1.02719477181115e-05" mass="0.0084581547726202" fullinertia="1.40243836130246e-06 9.92829395244375e-07 7.26110349167423e-07 -1.19619722062239e-07 7.34394052250468e-09 4.64162077403213e-08" />
                              <joint name="hand_right_rh_thumb_cmc_roll" class="hand_right_hand_linkerhand_l20lite_joint" type="hinge" axis="0.99996 0 -0.0087265" range="0 1.03" />
                              <geom class="hand_right_hand_linkerhand_l20lite_visual" mesh="hand_right_thumb_metacarpals_base1" />
                              <geom class="hand_right_hand_linkerhand_l20lite_collision" mesh="hand_right_thumb_metacarpals_base1" />
                              <body name="hand_right_rh_thumb_metacarpals_base2" pos="0.035798 -0.0006691 0.00040146" euler="-0.13233 -0.0085747 0.0011413">
                                <inertial pos="0.00174090957798892 0.00721482590041489 -0.000263313052030728" mass="0.00582711245702963" fullinertia="3.17303010997568e-07 2.73232268452871e-07 1.76908306988949e-07 1.12913904502057e-08 -2.63903919763792e-09 -1.09223121289568e-08" />
                                <joint name="hand_right_rh_thumb_cmc_yaw" class="hand_right_hand_linkerhand_l20lite_joint" type="hinge" axis="0 0 -1" range="0 1.4" />
                                <geom class="hand_right_hand_linkerhand_l20lite_visual" mesh="hand_right_thumb_metacarpals_base2" />
                                <geom class="hand_right_hand_linkerhand_l20lite_collision" mesh="hand_right_thumb_metacarpals_base2" />
                                <body name="hand_right_rh_thumb_metacarpals" pos="0.0037151 0.015396 -0.0019302" euler="0 -0.9163 -1.8076">
                                  <inertial pos="0.00183662400665177 -2.80439600631663e-06 0.0269904280709441" mass="0.0152012256765109" fullinertia="2.95371260447027e-06 3.8477229500142e-06 1.32007940012866e-06 -6.21178551021653e-11 -1.58082424321764e-07 -4.14758708520733e-10" />
                                  <joint name="hand_right_rh_thumb_cmc_pitch" class="hand_right_hand_linkerhand_l20lite_joint" type="hinge" axis="0 1 0" range="0 0.52" />
                                  <geom class="hand_right_hand_linkerhand_l20lite_visual" mesh="hand_right_thumb_metacarpals" />
                                  <geom class="hand_right_hand_linkerhand_l20lite_collision" mesh="hand_right_thumb_metacarpals" />
                                  <body name="hand_right_rh_thumb_proximal" pos="0.0061722 0 0.047968">
                                    <inertial pos="0.00159268252983606 -4.43643671124011e-06 0.015157363827759" mass="0.00662231923284161" fullinertia="1.01527279135723e-06 9.10434608488902e-07 4.47464440479559e-07 3.86298144933713e-12 -4.42245334725163e-08 -2.76864906314695e-11" />
                                    <joint name="hand_right_rh_thumb_mcp" class="hand_right_hand_linkerhand_l20lite_joint" type="hinge" axis="0 1 0" range="0 0.72" />
                                    <geom class="hand_right_hand_linkerhand_l20lite_visual" mesh="hand_right_thumb_proximal" />
                                    <geom class="hand_right_hand_linkerhand_l20lite_collision" mesh="hand_right_thumb_proximal" />
                                    <body name="hand_right_rh_thumb_distal" pos="-0.00017064 0 0.038665">
                                      <inertial pos="-0.00138929852568181 1.78258724357894e-06 0.0115789166085123" mass="0.00512919991432349" fullinertia="3.30966764284813e-07 3.23803379547457e-07 2.48897458436709e-07 3.4874903065333e-10 -1.0473713688836e-07 8.38797000457644e-11" />
                                      <joint name="hand_right_rh_thumb_ip" class="hand_right_hand_linkerhand_l20lite_joint" type="hinge" axis="0 1 0" range="0 0.78" />
                                      <geom class="hand_right_hand_linkerhand_l20lite_visual" mesh="hand_right_thumb_distal" />
                                      <geom class="hand_right_hand_linkerhand_l20lite_collision" mesh="hand_right_thumb_distal" />
                                    </body>
                                  </body>
                                </body>
                              </body>
                            </body>
                            <body name="hand_right_rh_index_metacarpals" pos="-0.0021643 0.026654 0.13253" euler="-0.027925 -0.0087266 0">
                              <inertial pos="-0.000394044300581899 -6.96524768268453e-07 0.00909446180986484" mass="0.00903700329493157" fullinertia="4.89554250283515e-07 7.37380385682221e-07 5.52862732336676e-07 -3.94697795521512e-11 2.73097237930781e-08 -6.33508384593073e-11" />
                              <joint name="hand_right_rh_index_mcp_roll" class="hand_right_hand_linkerhand_l20lite_joint" type="hinge" axis="-1 0 0" range="0 0.19" />
                              <geom class="hand_right_hand_linkerhand_l20lite_visual" mesh="hand_right_index_metacarpals" />
                              <geom class="hand_right_hand_linkerhand_l20lite_collision" mesh="hand_right_index_metacarpals" />
                              <body name="hand_right_rh_index_proximal" pos="0.00220968332188026 0 0.0152749792820048">
                                <inertial pos="-0.000129944380960653 1.17196171642124e-06 0.0104816955547003" mass="0.00654982235507964" fullinertia="4.43901400960209e-07 4.58697731369085e-07 1.74205815221237e-07 3.44400810155697e-12 -2.4814971446792e-08 8.51406115918214e-11" />
                                <joint name="hand_right_rh_index_mcp_pitch" class="hand_right_hand_linkerhand_l20lite_joint" type="hinge" axis="0 1 0" range="0 1.36" />
                                <geom class="hand_right_hand_linkerhand_l20lite_visual" mesh="hand_right_index_proximal" />
                                <geom class="hand_right_hand_linkerhand_l20lite_collision" mesh="hand_right_index_proximal" />
                                <body name="hand_right_rh_index_middle" pos="-0.0010697 0 0.035634">
                                  <inertial pos="-0.00250308175256513 -2.09528008505294e-06 0.0110397399346051" mass="0.00283043630937165" fullinertia="2.61037002532157e-07 2.33077671005604e-07 1.2654386429984e-07 -5.76553826316728e-11 -4.00111847827091e-08 2.97012055424732e-11" />
                                  <joint name="hand_right_rh_index_pip" class="hand_right_hand_linkerhand_l20lite_joint" type="hinge" axis="0 1 0" range="0 1.78" />
                                  <geom class="hand_right_hand_linkerhand_l20lite_visual" mesh="hand_right_index_middle" />
                                  <geom class="hand_right_hand_linkerhand_l20lite_collision" mesh="hand_right_index_middle" />
                                  <body name="hand_right_rh_index_distal" pos="-0.0052444 0 0.025711">
                                    <inertial pos="-0.000604588906740394 5.26099433146611e-06 0.0121514585299274" mass="0.0031446130611452" fullinertia="1.64075846532352e-07 1.48367877966466e-07 9.78063887942514e-08 -1.75219464852339e-11 -4.27797730478817e-08 2.03355501606508e-10" />
                                    <joint name="hand_right_rh_index_dip" class="hand_right_hand_linkerhand_l20lite_joint" type="hinge" axis="0 1 0" range="0 0.62" />
                                    <geom class="hand_right_hand_linkerhand_l20lite_visual" mesh="hand_right_index_distal" />
                                    <geom class="hand_right_hand_linkerhand_l20lite_collision" mesh="hand_right_index_distal" />
                                  </body>
                                </body>
                              </body>
                            </body>
                            <body name="hand_right_rh_middle_proximal" pos="-0.00213155528434806 0.00765417737818821 0.152810108410232">
                              <inertial pos="-0.000226219980586554 1.17216483217029e-06 0.0104800581470382" mass="0.00654982478226949" fullinertia="4.43422823045882e-07 4.58697754707373e-07 1.746844667607e-07 2.65801609334198e-12 -2.72879331079685e-08 8.52654749038393e-11" />
                              <joint name="hand_right_rh_middle_mcp_pitch" class="hand_right_hand_linkerhand_l20lite_joint" type="hinge" axis="0 1 0" range="0 1.36" />
                              <geom class="hand_right_hand_linkerhand_l20lite_visual" mesh="hand_right_middle_proximal" />
                              <geom class="hand_right_hand_linkerhand_l20lite_collision" mesh="hand_right_middle_proximal" />
                              <body name="hand_right_rh_middle_middle" pos="-0.00139702428111229 0 0.0356230829860553">
                                <inertial pos="-0.00261699473119731 -2.09526685194996e-06 0.0110132928110042" mass="0.00283043635504842" fullinertia="2.60196021834948e-07 2.33077669434872e-07 1.27384845266404e-07 -5.79547865424222e-11 -4.13919583593881e-08 2.9104841260857e-11" />
                                <joint name="hand_right_rh_middle_pip" class="hand_right_hand_linkerhand_l20lite_joint" type="hinge" axis="0 1 0" range="0 1.78" />
                                <geom class="hand_right_hand_linkerhand_l20lite_visual" mesh="hand_right_middle_middle" />
                                <geom class="hand_right_hand_linkerhand_l20lite_collision" mesh="hand_right_middle_middle" />
                                <body name="hand_right_rh_middle_distal" pos="-0.0055098 0 0.025656">
                                  <inertial pos="-0.000728492686371173 5.23463092580619e-06 0.0121446078355885" mass="0.00314458659113992" fullinertia="1.63194300204967e-07 1.48366133401819e-07 9.8685363448972e-08 -1.99064062210326e-11 -4.34469141576056e-08 2.02741720954809e-10" />
                                  <joint name="hand_right_rh_middle_dip" class="hand_right_hand_linkerhand_l20lite_joint" type="hinge" axis="0 1 0" range="0 0.62" />
                                  <geom class="hand_right_hand_linkerhand_l20lite_visual" mesh="hand_right_middle_distal" />
                                  <geom class="hand_right_hand_linkerhand_l20lite_collision" mesh="hand_right_middle_distal" />
                                </body>
                              </body>
                            </body>
                            <body name="hand_right_rh_ring_metacarpals" pos="-0.00216430029569533 -0.0113458226218121 0.132534071328313" euler="0.0244346095279086 -0.00872664625996829 0">
                              <inertial pos="-0.000394044453752051 -6.96464269499264e-07 0.00909446164305169" mass="0.00903700335356623" fullinertia="4.89554245950771e-07 7.37380377611045e-07 5.52862742016819e-07 -3.94741777907138e-11 2.73097253166787e-08 -6.33493307330511e-11" />
                              <joint name="hand_right_rh_ring_mcp_roll" class="hand_right_hand_linkerhand_l20lite_joint" type="hinge" axis="1 0 0" range="0 0.2" />
                              <geom class="hand_right_hand_linkerhand_l20lite_visual" mesh="hand_right_ring_metacarpals" />
                              <geom class="hand_right_hand_linkerhand_l20lite_collision" mesh="hand_right_ring_metacarpals" />
                              <body name="hand_right_rh_ring_proximal" pos="0.0022097 0 0.015275">
                                <inertial pos="-0.000129951741702268 1.17052693794986e-06 0.0104816759358435" mass="0.00654983629670871" fullinertia="4.43901586303392e-07 4.58698142287549e-07 1.74206152792307e-07 3.50295306689535e-12 -2.48148215954452e-08 8.52333703161162e-11" />
                                <joint name="hand_right_rh_ring_mcp_pitch" class="hand_right_hand_linkerhand_l20lite_joint" type="hinge" axis="0 1 0" range="0 1.36" />
                                <geom class="hand_right_hand_linkerhand_l20lite_visual" mesh="hand_right_ring_proximal" />
                                <geom class="hand_right_hand_linkerhand_l20lite_collision" mesh="hand_right_ring_proximal" />
                                <body name="hand_right_rh_ring_middle" pos="-0.00106974956301328 0 0.0356344124989653">
                                  <inertial pos="-0.00250308200880736 -2.09549542964232e-06 0.0110397403443072" mass="0.0028304363455826" fullinertia="2.610370084214e-07 2.3307766580208e-07 1.26543852008426e-07 -5.76575489930258e-11 -4.00111860002357e-08 2.97027542466601e-11" />
                                  <joint name="hand_right_rh_ring_pip" class="hand_right_hand_linkerhand_l20lite_joint" type="hinge" axis="0 1 0" range="0 1.78" />
                                  <geom class="hand_right_hand_linkerhand_l20lite_visual" mesh="hand_right_ring_middle" />
                                  <geom class="hand_right_hand_linkerhand_l20lite_collision" mesh="hand_right_ring_middle" />
                                  <body name="hand_right_rh_ring_distal" pos="-0.00524443259686075 0 0.0257114125710868" euler="0 0 -0.000213216385347256">
                                    <inertial pos="-0.00060459286126547 5.09148089232817e-06 0.0121514427640609" mass="0.00314460631735109" fullinertia="1.64075455538032e-07 1.48367698956355e-07 9.78062648939272e-08 -2.1468512857682e-11 -4.27798116117893e-08 1.93419127705868e-10" />
                                    <joint name="hand_right_rh_ring_dip" class="hand_right_hand_linkerhand_l20lite_joint" type="hinge" axis="0.000213099161 0.999450193 -0.0331551784" range="0 0.62" />
                                    <geom class="hand_right_hand_linkerhand_l20lite_visual" mesh="hand_right_ring_distal" />
                                    <geom class="hand_right_hand_linkerhand_l20lite_collision" mesh="hand_right_ring_distal" />
                                  </body>
                                </body>
                              </body>
                            </body>
                            <body name="hand_right_rh_pinky_metacarpals" pos="-0.00012074 -0.030346 0.12755" euler="0.057596 -0.0087266 0">
                              <inertial pos="-0.00039404522692532 -6.96240700731598e-07 0.00909446058676422" mass="0.00903700307878998" fullinertia="4.89554195779539e-07 7.37380317460272e-07 5.5286276236961e-07 -3.94817181132792e-11 2.7309708213456e-08 -6.33317017267926e-11" />
                              <joint name="hand_right_rh_pinky_mcp_roll" class="hand_right_hand_linkerhand_l20lite_joint" type="hinge" axis="1 0 0" range="0 0.3" />
                              <geom class="hand_right_hand_linkerhand_l20lite_visual" mesh="hand_right_pinky_metacarpals" />
                              <geom class="hand_right_hand_linkerhand_l20lite_collision" mesh="hand_right_pinky_metacarpals" />
                              <body name="hand_right_rh_pinky_proximal" pos="0.0022097 0 0.015275">
                                <inertial pos="-0.000129949532354408 1.17230680928004e-06 0.0104816807512055" mass="0.00654983474179372" fullinertia="4.43901730245286e-07 4.58698159687316e-07 1.74206088330646e-07 3.4507527836803e-12 -2.48149152090791e-08 8.52432689792127e-11" />
                                <joint name="hand_right_rh_pinky_mcp_pitch" class="hand_right_hand_linkerhand_l20lite_joint" type="hinge" axis="0 1 0" range="0 1.36" />
                                <geom class="hand_right_hand_linkerhand_l20lite_visual" mesh="hand_right_pinky_proximal" />
                                <geom class="hand_right_hand_linkerhand_l20lite_collision" mesh="hand_right_pinky_proximal" />
                                <body name="hand_right_rh_pinky_middle" pos="-0.0010697 0 0.035634">
                                  <inertial pos="-0.00250308414609457 -2.09612030866585e-06 0.0110397422037874" mass="0.00283043670305552" fullinertia="2.6103697292473e-07 2.33077589871973e-07 1.26543829688383e-07 -5.76245409160896e-11 -4.00111424508735e-08 2.96769001441938e-11" />
                                  <joint name="hand_right_rh_pinky_pip" class="hand_right_hand_linkerhand_l20lite_joint" type="hinge" axis="0 1 0" range="0 1.78" />
                                  <geom class="hand_right_hand_linkerhand_l20lite_visual" mesh="hand_right_pinky_middle" />
                                  <geom class="hand_right_hand_linkerhand_l20lite_collision" mesh="hand_right_pinky_middle" />
                                  <body name="hand_right_rh_pinky_distal" pos="-0.0052444 0 0.025711">
                                    <inertial pos="-0.000604482988543969 5.27153358490656e-06 0.0121512430050648" mass="0.00314457409502053" fullinertia="1.64068754964363e-07 1.48361079085349e-07 9.78068531228973e-08 -1.90437996173564e-11 -4.27789862984836e-08 2.05110113267167e-10" />
                                    <joint name="hand_right_rh_pinky_dip" class="hand_right_hand_linkerhand_l20lite_joint" type="hinge" axis="0 1 0" range="0 0.62" />
                                    <geom class="hand_right_hand_linkerhand_l20lite_visual" mesh="hand_right_pinky_distal" />
                                    <geom class="hand_right_hand_linkerhand_l20lite_collision" mesh="hand_right_pinky_distal" />
                                  </body>
                                </body>
                              </body>
                            </body>
                          </body>
                        </body>
                      </body>
                    </body>
                  </body>
                </body>
              </body>
            </body>
          </body>
        </body>
      </body>
    </body>
  </worldbody>
  <actuator>
    <position name="arm_left_L1_Joint_act" joint="arm_left_L1_Joint" kp="2000" kv="0" ctrlrange="-2.18 3.75" />
    <position name="arm_left_L2_Joint_act" joint="arm_left_L2_Joint" kp="2000" kv="0" ctrlrange="-3.33 0.19" />
    <position name="arm_left_L3_Joint_act" joint="arm_left_L3_Joint" kp="2000" kv="0" ctrlrange="-2.26 2.26" />
    <position name="arm_left_L4_Joint_act" joint="arm_left_L4_Joint" kp="2000" kv="0" ctrlrange="-0.78 1.74" />
    <position name="arm_left_L5_Joint_act" joint="arm_left_L5_Joint" kp="2000" kv="0" ctrlrange="-2.96 2.96" />
    <position name="arm_left_L6_Joint_act" joint="arm_left_L6_Joint" kp="2000" kv="0" ctrlrange="-1.57 1.57" />
    <position name="arm_left_L7_Joint_act" joint="arm_left_L7_Joint" kp="2000" kv="0" ctrlrange="-1.57 1.57" />
    <position name="arm_right_R1_Joint_act" joint="arm_right_R1_Joint" kp="2000" kv="0" ctrlrange="-3.75 2.18" />
    <position name="arm_right_R2_Joint_act" joint="arm_right_R2_Joint" kp="2000" kv="0" ctrlrange="-0.19 3.33" />
    <position name="arm_right_R3_Joint_act" joint="arm_right_R3_Joint" kp="2000" kv="0" ctrlrange="-2.26 2.26" />
    <position name="arm_right_R4_Joint_act" joint="arm_right_R4_Joint" kp="2000" kv="0" ctrlrange="-1.74 0.78" />
    <position name="arm_right_R5_Joint_act" joint="arm_right_R5_Joint" kp="2000" kv="0" ctrlrange="-2.96 2.96" />
    <position name="arm_right_R6_Joint_act" joint="arm_right_R6_Joint" kp="2000" kv="0" ctrlrange="-1.57 1.57" />
    <position name="arm_right_R7_Joint_act" joint="arm_right_R7_Joint" kp="2000" kv="0" ctrlrange="-1.57 1.57" />
    <position name="hand_left_lh_thumb_cmc_roll_act" joint="hand_left_lh_thumb_cmc_roll" kp="200" kv="0" ctrlrange="0 1.03" />
    <position name="hand_left_lh_thumb_cmc_yaw_act" joint="hand_left_lh_thumb_cmc_yaw" kp="200" kv="0" ctrlrange="0 1.4" />
    <position name="hand_left_lh_thumb_cmc_pitch_act" joint="hand_left_lh_thumb_cmc_pitch" kp="200" kv="0" ctrlrange="0 0.52" />
    <position name="hand_left_lh_index_mcp_roll_act" joint="hand_left_lh_index_mcp_roll" kp="200" kv="0" ctrlrange="0 0.19" />
    <position name="hand_left_lh_index_mcp_pitch_act" joint="hand_left_lh_index_mcp_pitch" kp="200" kv="0" ctrlrange="0 1.36" />
    <position name="hand_left_lh_middle_mcp_pitch_act" joint="hand_left_lh_middle_mcp_pitch" kp="200" kv="0" ctrlrange="0 1.36" />
    <position name="hand_left_lh_ring_mcp_roll_act" joint="hand_left_lh_ring_mcp_roll" kp="200" kv="0" ctrlrange="0 0.2" />
    <position name="hand_left_lh_ring_mcp_pitch_act" joint="hand_left_lh_ring_mcp_pitch" kp="200" kv="0" ctrlrange="0 1.36" />
    <position name="hand_left_lh_pinky_mcp_roll_act" joint="hand_left_lh_pinky_mcp_roll" kp="200" kv="0" ctrlrange="0 0.3" />
    <position name="hand_left_lh_pinky_mcp_pitch_act" joint="hand_left_lh_pinky_mcp_pitch" kp="200" kv="0" ctrlrange="0 1.36" />
    <position name="hand_right_rh_thumb_cmc_roll_act" joint="hand_right_rh_thumb_cmc_roll" kp="200" kv="0" ctrlrange="0 1.03" />
    <position name="hand_right_rh_thumb_cmc_yaw_act" joint="hand_right_rh_thumb_cmc_yaw" kp="200" kv="0" ctrlrange="0 1.4" />
    <position name="hand_right_rh_thumb_cmc_pitch_act" joint="hand_right_rh_thumb_cmc_pitch" kp="200" kv="0" ctrlrange="0 0.52" />
    <position name="hand_right_rh_index_mcp_roll_act" joint="hand_right_rh_index_mcp_roll" kp="200" kv="0" ctrlrange="0 0.19" />
    <position name="hand_right_rh_index_mcp_pitch_act" joint="hand_right_rh_index_mcp_pitch" kp="200" kv="0" ctrlrange="0 1.36" />
    <position name="hand_right_rh_middle_mcp_pitch_act" joint="hand_right_rh_middle_mcp_pitch" kp="200" kv="0" ctrlrange="0 1.36" />
    <position name="hand_right_rh_ring_mcp_roll_act" joint="hand_right_rh_ring_mcp_roll" kp="200" kv="0" ctrlrange="0 0.2" />
    <position name="hand_right_rh_ring_mcp_pitch_act" joint="hand_right_rh_ring_mcp_pitch" kp="200" kv="0" ctrlrange="0 1.36" />
    <position name="hand_right_rh_pinky_mcp_roll_act" joint="hand_right_rh_pinky_mcp_roll" kp="200" kv="0" ctrlrange="0 0.3" />
    <position name="hand_right_rh_pinky_mcp_pitch_act" joint="hand_right_rh_pinky_mcp_pitch" kp="200" kv="0" ctrlrange="0 1.36" />
  </actuator>
  <equality>
    <joint name="hand_left_lh_couple_thumb_mcp" joint1="hand_left_lh_thumb_mcp" joint2="hand_left_lh_thumb_cmc_pitch" polycoef="0 1.38 0 0 0" />
    <joint name="hand_left_lh_couple_thumb_ip" joint1="hand_left_lh_thumb_ip" joint2="hand_left_lh_thumb_cmc_pitch" polycoef="0 1.49 0 0 0" />
    <joint name="hand_left_lh_couple_index_pip" joint1="hand_left_lh_index_pip" joint2="hand_left_lh_index_mcp_pitch" polycoef="0 1.3 0 0 0" />
    <joint name="hand_left_lh_couple_index_dip" joint1="hand_left_lh_index_dip" joint2="hand_left_lh_index_mcp_pitch" polycoef="0 0.46 0 0 0" />
    <joint name="hand_left_lh_couple_middle_pip" joint1="hand_left_lh_middle_pip" joint2="hand_left_lh_middle_mcp_pitch" polycoef="0 1.3 0 0 0" />
    <joint name="hand_left_lh_couple_middle_dip" joint1="hand_left_lh_middle_dip" joint2="hand_left_lh_middle_mcp_pitch" polycoef="0 0.46 0 0 0" />
    <joint name="hand_left_lh_couple_ring_pip" joint1="hand_left_lh_ring_pip" joint2="hand_left_lh_ring_mcp_pitch" polycoef="0 1.3 0 0 0" />
    <joint name="hand_left_lh_couple_ring_dip" joint1="hand_left_lh_ring_dip" joint2="hand_left_lh_ring_mcp_pitch" polycoef="0 0.46 0 0 0" />
    <joint name="hand_left_lh_couple_pinky_pip" joint1="hand_left_lh_pinky_pip" joint2="hand_left_lh_pinky_mcp_pitch" polycoef="0 1.3 0 0 0" />
    <joint name="hand_left_lh_couple_pinky_dip" joint1="hand_left_lh_pinky_dip" joint2="hand_left_lh_pinky_mcp_pitch" polycoef="0 0.46 0 0 0" />
    <joint name="hand_right_rh_couple_thumb_mcp" joint1="hand_right_rh_thumb_mcp" joint2="hand_right_rh_thumb_cmc_pitch" polycoef="0 1.38 0 0 0" />
    <joint name="hand_right_rh_couple_thumb_ip" joint1="hand_right_rh_thumb_ip" joint2="hand_right_rh_thumb_cmc_pitch" polycoef="0 1.49 0 0 0" />
    <joint name="hand_right_rh_couple_index_pip" joint1="hand_right_rh_index_pip" joint2="hand_right_rh_index_mcp_pitch" polycoef="0 1.3 0 0 0" />
    <joint name="hand_right_rh_couple_index_dip" joint1="hand_right_rh_index_dip" joint2="hand_right_rh_index_mcp_pitch" polycoef="0 0.46 0 0 0" />
    <joint name="hand_right_rh_couple_middle_pip" joint1="hand_right_rh_middle_pip" joint2="hand_right_rh_middle_mcp_pitch" polycoef="0 1.3 0 0 0" />
    <joint name="hand_right_rh_couple_middle_dip" joint1="hand_right_rh_middle_dip" joint2="hand_right_rh_middle_mcp_pitch" polycoef="0 0.46 0 0 0" />
    <joint name="hand_right_rh_couple_ring_pip" joint1="hand_right_rh_ring_pip" joint2="hand_right_rh_ring_mcp_pitch" polycoef="0 1.34 0 0 0" />
    <joint name="hand_right_rh_couple_ring_dip" joint1="hand_right_rh_ring_dip" joint2="hand_right_rh_ring_mcp_pitch" polycoef="0 0.46 0 0 0" />
    <joint name="hand_right_rh_couple_pinky_pip" joint1="hand_right_rh_pinky_pip" joint2="hand_right_rh_pinky_mcp_pitch" polycoef="0 1.34 0 0 0" />
    <joint name="hand_right_rh_couple_pinky_dip" joint1="hand_right_rh_pinky_dip" joint2="hand_right_rh_pinky_mcp_pitch" polycoef="0 0.46 0 0 0" />
  </equality>
  <contact>
    <exclude body1="arm_left_L1_Link" body2="arm_left_L2_Link" />
    <exclude body1="arm_left_L2_Link" body2="arm_left_L3_Link" />
    <exclude body1="arm_left_L3_Link" body2="arm_left_L4_Link" />
    <exclude body1="arm_left_L4_Link" body2="arm_left_L5_Link" />
    <exclude body1="arm_left_L5_Link" body2="arm_left_L6_Link" />
    <exclude body1="arm_left_L6_Link" body2="arm_left_L7_Link" />
    <exclude body1="arm_right_R1_Link" body2="arm_right_R2_Link" />
    <exclude body1="arm_right_R2_Link" body2="arm_right_R3_Link" />
    <exclude body1="arm_right_R3_Link" body2="arm_right_R4_Link" />
    <exclude body1="arm_right_R4_Link" body2="arm_right_R5_Link" />
    <exclude body1="arm_right_R5_Link" body2="arm_right_R6_Link" />
    <exclude body1="arm_right_R6_Link" body2="arm_right_R7_Link" />
    <exclude body1="hand_left_lh_hand_base_link" body2="hand_left_lh_thumb_metacarpals_base1" />
    <exclude body1="hand_left_lh_thumb_metacarpals_base1" body2="hand_left_lh_thumb_metacarpals_base2" />
    <exclude body1="hand_left_lh_thumb_metacarpals_base2" body2="hand_left_lh_thumb_metacarpals" />
    <exclude body1="hand_left_lh_thumb_metacarpals" body2="hand_left_lh_thumb_proximal" />
    <exclude body1="hand_left_lh_thumb_proximal" body2="hand_left_lh_thumb_distal" />
    <exclude body1="hand_left_lh_hand_base_link" body2="hand_left_lh_index_metacarpals" />
    <exclude body1="hand_left_lh_index_metacarpals" body2="hand_left_lh_index_proximal" />
    <exclude body1="hand_left_lh_index_proximal" body2="hand_left_lh_index_middle" />
    <exclude body1="hand_left_lh_index_middle" body2="hand_left_lh_index_distal" />
    <exclude body1="hand_left_lh_hand_base_link" body2="hand_left_lh_middle_proximal" />
    <exclude body1="hand_left_lh_middle_proximal" body2="hand_left_lh_middle_middle" />
    <exclude body1="hand_left_lh_middle_middle" body2="hand_left_lh_middle_distal" />
    <exclude body1="hand_left_lh_hand_base_link" body2="hand_left_lh_ring_metacarpals" />
    <exclude body1="hand_left_lh_ring_metacarpals" body2="hand_left_lh_ring_proximal" />
    <exclude body1="hand_left_lh_ring_proximal" body2="hand_left_lh_ring_middle" />
    <exclude body1="hand_left_lh_ring_middle" body2="hand_left_lh_ring_distal" />
    <exclude body1="hand_left_lh_hand_base_link" body2="hand_left_lh_pinky_metacarpals" />
    <exclude body1="hand_left_lh_pinky_metacarpals" body2="hand_left_lh_pinky_proximal" />
    <exclude body1="hand_left_lh_pinky_proximal" body2="hand_left_lh_pinky_middle" />
    <exclude body1="hand_left_lh_pinky_middle" body2="hand_left_lh_pinky_distal" />
    <exclude body1="hand_left_lh_hand_base_link" body2="hand_left_lh_index_proximal" />
    <exclude body1="hand_left_lh_hand_base_link" body2="hand_left_lh_ring_proximal" />
    <exclude body1="hand_left_lh_hand_base_link" body2="hand_left_lh_pinky_proximal" />
    <exclude body1="hand_left_lh_hand_base_link" body2="hand_left_lh_thumb_metacarpals_base2" />
    <exclude body1="hand_left_lh_hand_base_link" body2="hand_left_lh_thumb_metacarpals" />
    <exclude body1="hand_left_lh_thumb_metacarpals" body2="hand_left_lh_thumb_metacarpals_base1" />
    <exclude body1="hand_right_rh_hand_base_link" body2="hand_right_rh_thumb_metacarpals_base1" />
    <exclude body1="hand_right_rh_thumb_metacarpals_base1" body2="hand_right_rh_thumb_metacarpals_base2" />
    <exclude body1="hand_right_rh_thumb_metacarpals_base2" body2="hand_right_rh_thumb_metacarpals" />
    <exclude body1="hand_right_rh_thumb_metacarpals" body2="hand_right_rh_thumb_proximal" />
    <exclude body1="hand_right_rh_thumb_proximal" body2="hand_right_rh_thumb_distal" />
    <exclude body1="hand_right_rh_hand_base_link" body2="hand_right_rh_index_metacarpals" />
    <exclude body1="hand_right_rh_index_metacarpals" body2="hand_right_rh_index_proximal" />
    <exclude body1="hand_right_rh_index_proximal" body2="hand_right_rh_index_middle" />
    <exclude body1="hand_right_rh_index_middle" body2="hand_right_rh_index_distal" />
    <exclude body1="hand_right_rh_hand_base_link" body2="hand_right_rh_middle_proximal" />
    <exclude body1="hand_right_rh_middle_proximal" body2="hand_right_rh_middle_middle" />
    <exclude body1="hand_right_rh_middle_middle" body2="hand_right_rh_middle_distal" />
    <exclude body1="hand_right_rh_hand_base_link" body2="hand_right_rh_ring_metacarpals" />
    <exclude body1="hand_right_rh_ring_metacarpals" body2="hand_right_rh_ring_proximal" />
    <exclude body1="hand_right_rh_ring_proximal" body2="hand_right_rh_ring_middle" />
    <exclude body1="hand_right_rh_ring_middle" body2="hand_right_rh_ring_distal" />
    <exclude body1="hand_right_rh_hand_base_link" body2="hand_right_rh_pinky_metacarpals" />
    <exclude body1="hand_right_rh_pinky_metacarpals" body2="hand_right_rh_pinky_proximal" />
    <exclude body1="hand_right_rh_pinky_proximal" body2="hand_right_rh_pinky_middle" />
    <exclude body1="hand_right_rh_pinky_middle" body2="hand_right_rh_pinky_distal" />
    <exclude body1="hand_right_rh_hand_base_link" body2="hand_right_rh_index_proximal" />
    <exclude body1="hand_right_rh_hand_base_link" body2="hand_right_rh_ring_proximal" />
    <exclude body1="hand_right_rh_hand_base_link" body2="hand_right_rh_pinky_proximal" />
    <exclude body1="hand_right_rh_hand_base_link" body2="hand_right_rh_thumb_metacarpals_base2" />
    <exclude body1="hand_right_rh_hand_base_link" body2="hand_right_rh_thumb_metacarpals" />
    <exclude body1="hand_right_rh_thumb_metacarpals" body2="hand_right_rh_thumb_metacarpals_base1" />
    <exclude body1="base_base_link" body2="arm_left_L1_Link" />
    <exclude body1="base_base_link" body2="arm_left_L2_Link" />
    <exclude body1="base_base_link" body2="arm_left_L3_Link" />
    <exclude body1="base_base_link" body2="arm_left_L4_Link" />
    <exclude body1="base_base_link" body2="arm_left_L5_Link" />
    <exclude body1="base_base_link" body2="arm_left_L6_Link" />
    <exclude body1="base_base_link" body2="arm_left_L7_Link" />
    <exclude body1="base_base_link" body2="arm_right_R1_Link" />
    <exclude body1="base_base_link" body2="arm_right_R2_Link" />
    <exclude body1="base_base_link" body2="arm_right_R3_Link" />
    <exclude body1="base_base_link" body2="arm_right_R4_Link" />
    <exclude body1="base_base_link" body2="arm_right_R5_Link" />
    <exclude body1="base_base_link" body2="arm_right_R6_Link" />
    <exclude body1="base_base_link" body2="arm_right_R7_Link" />
    <exclude body1="arm_left_L1_Link" body2="hand_left_lh_hand_base_link" />
    <exclude body1="arm_left_L1_Link" body2="hand_left_lh_thumb_metacarpals_base1" />
    <exclude body1="arm_left_L1_Link" body2="hand_left_lh_thumb_metacarpals_base2" />
    <exclude body1="arm_left_L1_Link" body2="hand_left_lh_thumb_metacarpals" />
    <exclude body1="arm_left_L1_Link" body2="hand_left_lh_thumb_proximal" />
    <exclude body1="arm_left_L1_Link" body2="hand_left_lh_thumb_distal" />
    <exclude body1="arm_left_L1_Link" body2="hand_left_lh_index_metacarpals" />
    <exclude body1="arm_left_L1_Link" body2="hand_left_lh_index_proximal" />
    <exclude body1="arm_left_L1_Link" body2="hand_left_lh_index_middle" />
    <exclude body1="arm_left_L1_Link" body2="hand_left_lh_index_distal" />
    <exclude body1="arm_left_L1_Link" body2="hand_left_lh_middle_proximal" />
    <exclude body1="arm_left_L1_Link" body2="hand_left_lh_middle_middle" />
    <exclude body1="arm_left_L1_Link" body2="hand_left_lh_middle_distal" />
    <exclude body1="arm_left_L1_Link" body2="hand_left_lh_ring_metacarpals" />
    <exclude body1="arm_left_L1_Link" body2="hand_left_lh_ring_proximal" />
    <exclude body1="arm_left_L1_Link" body2="hand_left_lh_ring_middle" />
    <exclude body1="arm_left_L1_Link" body2="hand_left_lh_ring_distal" />
    <exclude body1="arm_left_L1_Link" body2="hand_left_lh_pinky_metacarpals" />
    <exclude body1="arm_left_L1_Link" body2="hand_left_lh_pinky_proximal" />
    <exclude body1="arm_left_L1_Link" body2="hand_left_lh_pinky_middle" />
    <exclude body1="arm_left_L1_Link" body2="hand_left_lh_pinky_distal" />
    <exclude body1="arm_left_L2_Link" body2="hand_left_lh_hand_base_link" />
    <exclude body1="arm_left_L2_Link" body2="hand_left_lh_thumb_metacarpals_base1" />
    <exclude body1="arm_left_L2_Link" body2="hand_left_lh_thumb_metacarpals_base2" />
    <exclude body1="arm_left_L2_Link" body2="hand_left_lh_thumb_metacarpals" />
    <exclude body1="arm_left_L2_Link" body2="hand_left_lh_thumb_proximal" />
    <exclude body1="arm_left_L2_Link" body2="hand_left_lh_thumb_distal" />
    <exclude body1="arm_left_L2_Link" body2="hand_left_lh_index_metacarpals" />
    <exclude body1="arm_left_L2_Link" body2="hand_left_lh_index_proximal" />
    <exclude body1="arm_left_L2_Link" body2="hand_left_lh_index_middle" />
    <exclude body1="arm_left_L2_Link" body2="hand_left_lh_index_distal" />
    <exclude body1="arm_left_L2_Link" body2="hand_left_lh_middle_proximal" />
    <exclude body1="arm_left_L2_Link" body2="hand_left_lh_middle_middle" />
    <exclude body1="arm_left_L2_Link" body2="hand_left_lh_middle_distal" />
    <exclude body1="arm_left_L2_Link" body2="hand_left_lh_ring_metacarpals" />
    <exclude body1="arm_left_L2_Link" body2="hand_left_lh_ring_proximal" />
    <exclude body1="arm_left_L2_Link" body2="hand_left_lh_ring_middle" />
    <exclude body1="arm_left_L2_Link" body2="hand_left_lh_ring_distal" />
    <exclude body1="arm_left_L2_Link" body2="hand_left_lh_pinky_metacarpals" />
    <exclude body1="arm_left_L2_Link" body2="hand_left_lh_pinky_proximal" />
    <exclude body1="arm_left_L2_Link" body2="hand_left_lh_pinky_middle" />
    <exclude body1="arm_left_L2_Link" body2="hand_left_lh_pinky_distal" />
    <exclude body1="arm_left_L3_Link" body2="hand_left_lh_hand_base_link" />
    <exclude body1="arm_left_L3_Link" body2="hand_left_lh_thumb_metacarpals_base1" />
    <exclude body1="arm_left_L3_Link" body2="hand_left_lh_thumb_metacarpals_base2" />
    <exclude body1="arm_left_L3_Link" body2="hand_left_lh_thumb_metacarpals" />
    <exclude body1="arm_left_L3_Link" body2="hand_left_lh_thumb_proximal" />
    <exclude body1="arm_left_L3_Link" body2="hand_left_lh_thumb_distal" />
    <exclude body1="arm_left_L3_Link" body2="hand_left_lh_index_metacarpals" />
    <exclude body1="arm_left_L3_Link" body2="hand_left_lh_index_proximal" />
    <exclude body1="arm_left_L3_Link" body2="hand_left_lh_index_middle" />
    <exclude body1="arm_left_L3_Link" body2="hand_left_lh_index_distal" />
    <exclude body1="arm_left_L3_Link" body2="hand_left_lh_middle_proximal" />
    <exclude body1="arm_left_L3_Link" body2="hand_left_lh_middle_middle" />
    <exclude body1="arm_left_L3_Link" body2="hand_left_lh_middle_distal" />
    <exclude body1="arm_left_L3_Link" body2="hand_left_lh_ring_metacarpals" />
    <exclude body1="arm_left_L3_Link" body2="hand_left_lh_ring_proximal" />
    <exclude body1="arm_left_L3_Link" body2="hand_left_lh_ring_middle" />
    <exclude body1="arm_left_L3_Link" body2="hand_left_lh_ring_distal" />
    <exclude body1="arm_left_L3_Link" body2="hand_left_lh_pinky_metacarpals" />
    <exclude body1="arm_left_L3_Link" body2="hand_left_lh_pinky_proximal" />
    <exclude body1="arm_left_L3_Link" body2="hand_left_lh_pinky_middle" />
    <exclude body1="arm_left_L3_Link" body2="hand_left_lh_pinky_distal" />
    <exclude body1="arm_left_L4_Link" body2="hand_left_lh_hand_base_link" />
    <exclude body1="arm_left_L4_Link" body2="hand_left_lh_thumb_metacarpals_base1" />
    <exclude body1="arm_left_L4_Link" body2="hand_left_lh_thumb_metacarpals_base2" />
    <exclude body1="arm_left_L4_Link" body2="hand_left_lh_thumb_metacarpals" />
    <exclude body1="arm_left_L4_Link" body2="hand_left_lh_thumb_proximal" />
    <exclude body1="arm_left_L4_Link" body2="hand_left_lh_thumb_distal" />
    <exclude body1="arm_left_L4_Link" body2="hand_left_lh_index_metacarpals" />
    <exclude body1="arm_left_L4_Link" body2="hand_left_lh_index_proximal" />
    <exclude body1="arm_left_L4_Link" body2="hand_left_lh_index_middle" />
    <exclude body1="arm_left_L4_Link" body2="hand_left_lh_index_distal" />
    <exclude body1="arm_left_L4_Link" body2="hand_left_lh_middle_proximal" />
    <exclude body1="arm_left_L4_Link" body2="hand_left_lh_middle_middle" />
    <exclude body1="arm_left_L4_Link" body2="hand_left_lh_middle_distal" />
    <exclude body1="arm_left_L4_Link" body2="hand_left_lh_ring_metacarpals" />
    <exclude body1="arm_left_L4_Link" body2="hand_left_lh_ring_proximal" />
    <exclude body1="arm_left_L4_Link" body2="hand_left_lh_ring_middle" />
    <exclude body1="arm_left_L4_Link" body2="hand_left_lh_ring_distal" />
    <exclude body1="arm_left_L4_Link" body2="hand_left_lh_pinky_metacarpals" />
    <exclude body1="arm_left_L4_Link" body2="hand_left_lh_pinky_proximal" />
    <exclude body1="arm_left_L4_Link" body2="hand_left_lh_pinky_middle" />
    <exclude body1="arm_left_L4_Link" body2="hand_left_lh_pinky_distal" />
    <exclude body1="arm_left_L5_Link" body2="hand_left_lh_hand_base_link" />
    <exclude body1="arm_left_L5_Link" body2="hand_left_lh_thumb_metacarpals_base1" />
    <exclude body1="arm_left_L5_Link" body2="hand_left_lh_thumb_metacarpals_base2" />
    <exclude body1="arm_left_L5_Link" body2="hand_left_lh_thumb_metacarpals" />
    <exclude body1="arm_left_L5_Link" body2="hand_left_lh_thumb_proximal" />
    <exclude body1="arm_left_L5_Link" body2="hand_left_lh_thumb_distal" />
    <exclude body1="arm_left_L5_Link" body2="hand_left_lh_index_metacarpals" />
    <exclude body1="arm_left_L5_Link" body2="hand_left_lh_index_proximal" />
    <exclude body1="arm_left_L5_Link" body2="hand_left_lh_index_middle" />
    <exclude body1="arm_left_L5_Link" body2="hand_left_lh_index_distal" />
    <exclude body1="arm_left_L5_Link" body2="hand_left_lh_middle_proximal" />
    <exclude body1="arm_left_L5_Link" body2="hand_left_lh_middle_middle" />
    <exclude body1="arm_left_L5_Link" body2="hand_left_lh_middle_distal" />
    <exclude body1="arm_left_L5_Link" body2="hand_left_lh_ring_metacarpals" />
    <exclude body1="arm_left_L5_Link" body2="hand_left_lh_ring_proximal" />
    <exclude body1="arm_left_L5_Link" body2="hand_left_lh_ring_middle" />
    <exclude body1="arm_left_L5_Link" body2="hand_left_lh_ring_distal" />
    <exclude body1="arm_left_L5_Link" body2="hand_left_lh_pinky_metacarpals" />
    <exclude body1="arm_left_L5_Link" body2="hand_left_lh_pinky_proximal" />
    <exclude body1="arm_left_L5_Link" body2="hand_left_lh_pinky_middle" />
    <exclude body1="arm_left_L5_Link" body2="hand_left_lh_pinky_distal" />
    <exclude body1="arm_left_L6_Link" body2="hand_left_lh_hand_base_link" />
    <exclude body1="arm_left_L6_Link" body2="hand_left_lh_thumb_metacarpals_base1" />
    <exclude body1="arm_left_L6_Link" body2="hand_left_lh_thumb_metacarpals_base2" />
    <exclude body1="arm_left_L6_Link" body2="hand_left_lh_thumb_metacarpals" />
    <exclude body1="arm_left_L6_Link" body2="hand_left_lh_thumb_proximal" />
    <exclude body1="arm_left_L6_Link" body2="hand_left_lh_thumb_distal" />
    <exclude body1="arm_left_L6_Link" body2="hand_left_lh_index_metacarpals" />
    <exclude body1="arm_left_L6_Link" body2="hand_left_lh_index_proximal" />
    <exclude body1="arm_left_L6_Link" body2="hand_left_lh_index_middle" />
    <exclude body1="arm_left_L6_Link" body2="hand_left_lh_index_distal" />
    <exclude body1="arm_left_L6_Link" body2="hand_left_lh_middle_proximal" />
    <exclude body1="arm_left_L6_Link" body2="hand_left_lh_middle_middle" />
    <exclude body1="arm_left_L6_Link" body2="hand_left_lh_middle_distal" />
    <exclude body1="arm_left_L6_Link" body2="hand_left_lh_ring_metacarpals" />
    <exclude body1="arm_left_L6_Link" body2="hand_left_lh_ring_proximal" />
    <exclude body1="arm_left_L6_Link" body2="hand_left_lh_ring_middle" />
    <exclude body1="arm_left_L6_Link" body2="hand_left_lh_ring_distal" />
    <exclude body1="arm_left_L6_Link" body2="hand_left_lh_pinky_metacarpals" />
    <exclude body1="arm_left_L6_Link" body2="hand_left_lh_pinky_proximal" />
    <exclude body1="arm_left_L6_Link" body2="hand_left_lh_pinky_middle" />
    <exclude body1="arm_left_L6_Link" body2="hand_left_lh_pinky_distal" />
    <exclude body1="arm_left_L7_Link" body2="hand_left_lh_hand_base_link" />
    <exclude body1="arm_left_L7_Link" body2="hand_left_lh_thumb_metacarpals_base1" />
    <exclude body1="arm_left_L7_Link" body2="hand_left_lh_thumb_metacarpals_base2" />
    <exclude body1="arm_left_L7_Link" body2="hand_left_lh_thumb_metacarpals" />
    <exclude body1="arm_left_L7_Link" body2="hand_left_lh_thumb_proximal" />
    <exclude body1="arm_left_L7_Link" body2="hand_left_lh_thumb_distal" />
    <exclude body1="arm_left_L7_Link" body2="hand_left_lh_index_metacarpals" />
    <exclude body1="arm_left_L7_Link" body2="hand_left_lh_index_proximal" />
    <exclude body1="arm_left_L7_Link" body2="hand_left_lh_index_middle" />
    <exclude body1="arm_left_L7_Link" body2="hand_left_lh_index_distal" />
    <exclude body1="arm_left_L7_Link" body2="hand_left_lh_middle_proximal" />
    <exclude body1="arm_left_L7_Link" body2="hand_left_lh_middle_middle" />
    <exclude body1="arm_left_L7_Link" body2="hand_left_lh_middle_distal" />
    <exclude body1="arm_left_L7_Link" body2="hand_left_lh_ring_metacarpals" />
    <exclude body1="arm_left_L7_Link" body2="hand_left_lh_ring_proximal" />
    <exclude body1="arm_left_L7_Link" body2="hand_left_lh_ring_middle" />
    <exclude body1="arm_left_L7_Link" body2="hand_left_lh_ring_distal" />
    <exclude body1="arm_left_L7_Link" body2="hand_left_lh_pinky_metacarpals" />
    <exclude body1="arm_left_L7_Link" body2="hand_left_lh_pinky_proximal" />
    <exclude body1="arm_left_L7_Link" body2="hand_left_lh_pinky_middle" />
    <exclude body1="arm_left_L7_Link" body2="hand_left_lh_pinky_distal" />
    <exclude body1="base_base_link" body2="hand_left_lh_hand_base_link" />
    <exclude body1="base_base_link" body2="hand_left_lh_thumb_metacarpals_base1" />
    <exclude body1="base_base_link" body2="hand_left_lh_thumb_metacarpals_base2" />
    <exclude body1="base_base_link" body2="hand_left_lh_thumb_metacarpals" />
    <exclude body1="base_base_link" body2="hand_left_lh_thumb_proximal" />
    <exclude body1="base_base_link" body2="hand_left_lh_thumb_distal" />
    <exclude body1="base_base_link" body2="hand_left_lh_index_metacarpals" />
    <exclude body1="base_base_link" body2="hand_left_lh_index_proximal" />
    <exclude body1="base_base_link" body2="hand_left_lh_index_middle" />
    <exclude body1="base_base_link" body2="hand_left_lh_index_distal" />
    <exclude body1="base_base_link" body2="hand_left_lh_middle_proximal" />
    <exclude body1="base_base_link" body2="hand_left_lh_middle_middle" />
    <exclude body1="base_base_link" body2="hand_left_lh_middle_distal" />
    <exclude body1="base_base_link" body2="hand_left_lh_ring_metacarpals" />
    <exclude body1="base_base_link" body2="hand_left_lh_ring_proximal" />
    <exclude body1="base_base_link" body2="hand_left_lh_ring_middle" />
    <exclude body1="base_base_link" body2="hand_left_lh_ring_distal" />
    <exclude body1="base_base_link" body2="hand_left_lh_pinky_metacarpals" />
    <exclude body1="base_base_link" body2="hand_left_lh_pinky_proximal" />
    <exclude body1="base_base_link" body2="hand_left_lh_pinky_middle" />
    <exclude body1="base_base_link" body2="hand_left_lh_pinky_distal" />
    <exclude body1="arm_right_R1_Link" body2="hand_right_rh_hand_base_link" />
    <exclude body1="arm_right_R1_Link" body2="hand_right_rh_thumb_metacarpals_base1" />
    <exclude body1="arm_right_R1_Link" body2="hand_right_rh_thumb_metacarpals_base2" />
    <exclude body1="arm_right_R1_Link" body2="hand_right_rh_thumb_metacarpals" />
    <exclude body1="arm_right_R1_Link" body2="hand_right_rh_thumb_proximal" />
    <exclude body1="arm_right_R1_Link" body2="hand_right_rh_thumb_distal" />
    <exclude body1="arm_right_R1_Link" body2="hand_right_rh_index_metacarpals" />
    <exclude body1="arm_right_R1_Link" body2="hand_right_rh_index_proximal" />
    <exclude body1="arm_right_R1_Link" body2="hand_right_rh_index_middle" />
    <exclude body1="arm_right_R1_Link" body2="hand_right_rh_index_distal" />
    <exclude body1="arm_right_R1_Link" body2="hand_right_rh_middle_proximal" />
    <exclude body1="arm_right_R1_Link" body2="hand_right_rh_middle_middle" />
    <exclude body1="arm_right_R1_Link" body2="hand_right_rh_middle_distal" />
    <exclude body1="arm_right_R1_Link" body2="hand_right_rh_ring_metacarpals" />
    <exclude body1="arm_right_R1_Link" body2="hand_right_rh_ring_proximal" />
    <exclude body1="arm_right_R1_Link" body2="hand_right_rh_ring_middle" />
    <exclude body1="arm_right_R1_Link" body2="hand_right_rh_ring_distal" />
    <exclude body1="arm_right_R1_Link" body2="hand_right_rh_pinky_metacarpals" />
    <exclude body1="arm_right_R1_Link" body2="hand_right_rh_pinky_proximal" />
    <exclude body1="arm_right_R1_Link" body2="hand_right_rh_pinky_middle" />
    <exclude body1="arm_right_R1_Link" body2="hand_right_rh_pinky_distal" />
    <exclude body1="arm_right_R2_Link" body2="hand_right_rh_hand_base_link" />
    <exclude body1="arm_right_R2_Link" body2="hand_right_rh_thumb_metacarpals_base1" />
    <exclude body1="arm_right_R2_Link" body2="hand_right_rh_thumb_metacarpals_base2" />
    <exclude body1="arm_right_R2_Link" body2="hand_right_rh_thumb_metacarpals" />
    <exclude body1="arm_right_R2_Link" body2="hand_right_rh_thumb_proximal" />
    <exclude body1="arm_right_R2_Link" body2="hand_right_rh_thumb_distal" />
    <exclude body1="arm_right_R2_Link" body2="hand_right_rh_index_metacarpals" />
    <exclude body1="arm_right_R2_Link" body2="hand_right_rh_index_proximal" />
    <exclude body1="arm_right_R2_Link" body2="hand_right_rh_index_middle" />
    <exclude body1="arm_right_R2_Link" body2="hand_right_rh_index_distal" />
    <exclude body1="arm_right_R2_Link" body2="hand_right_rh_middle_proximal" />
    <exclude body1="arm_right_R2_Link" body2="hand_right_rh_middle_middle" />
    <exclude body1="arm_right_R2_Link" body2="hand_right_rh_middle_distal" />
    <exclude body1="arm_right_R2_Link" body2="hand_right_rh_ring_metacarpals" />
    <exclude body1="arm_right_R2_Link" body2="hand_right_rh_ring_proximal" />
    <exclude body1="arm_right_R2_Link" body2="hand_right_rh_ring_middle" />
    <exclude body1="arm_right_R2_Link" body2="hand_right_rh_ring_distal" />
    <exclude body1="arm_right_R2_Link" body2="hand_right_rh_pinky_metacarpals" />
    <exclude body1="arm_right_R2_Link" body2="hand_right_rh_pinky_proximal" />
    <exclude body1="arm_right_R2_Link" body2="hand_right_rh_pinky_middle" />
    <exclude body1="arm_right_R2_Link" body2="hand_right_rh_pinky_distal" />
    <exclude body1="arm_right_R3_Link" body2="hand_right_rh_hand_base_link" />
    <exclude body1="arm_right_R3_Link" body2="hand_right_rh_thumb_metacarpals_base1" />
    <exclude body1="arm_right_R3_Link" body2="hand_right_rh_thumb_metacarpals_base2" />
    <exclude body1="arm_right_R3_Link" body2="hand_right_rh_thumb_metacarpals" />
    <exclude body1="arm_right_R3_Link" body2="hand_right_rh_thumb_proximal" />
    <exclude body1="arm_right_R3_Link" body2="hand_right_rh_thumb_distal" />
    <exclude body1="arm_right_R3_Link" body2="hand_right_rh_index_metacarpals" />
    <exclude body1="arm_right_R3_Link" body2="hand_right_rh_index_proximal" />
    <exclude body1="arm_right_R3_Link" body2="hand_right_rh_index_middle" />
    <exclude body1="arm_right_R3_Link" body2="hand_right_rh_index_distal" />
    <exclude body1="arm_right_R3_Link" body2="hand_right_rh_middle_proximal" />
    <exclude body1="arm_right_R3_Link" body2="hand_right_rh_middle_middle" />
    <exclude body1="arm_right_R3_Link" body2="hand_right_rh_middle_distal" />
    <exclude body1="arm_right_R3_Link" body2="hand_right_rh_ring_metacarpals" />
    <exclude body1="arm_right_R3_Link" body2="hand_right_rh_ring_proximal" />
    <exclude body1="arm_right_R3_Link" body2="hand_right_rh_ring_middle" />
    <exclude body1="arm_right_R3_Link" body2="hand_right_rh_ring_distal" />
    <exclude body1="arm_right_R3_Link" body2="hand_right_rh_pinky_metacarpals" />
    <exclude body1="arm_right_R3_Link" body2="hand_right_rh_pinky_proximal" />
    <exclude body1="arm_right_R3_Link" body2="hand_right_rh_pinky_middle" />
    <exclude body1="arm_right_R3_Link" body2="hand_right_rh_pinky_distal" />
    <exclude body1="arm_right_R4_Link" body2="hand_right_rh_hand_base_link" />
    <exclude body1="arm_right_R4_Link" body2="hand_right_rh_thumb_metacarpals_base1" />
    <exclude body1="arm_right_R4_Link" body2="hand_right_rh_thumb_metacarpals_base2" />
    <exclude body1="arm_right_R4_Link" body2="hand_right_rh_thumb_metacarpals" />
    <exclude body1="arm_right_R4_Link" body2="hand_right_rh_thumb_proximal" />
    <exclude body1="arm_right_R4_Link" body2="hand_right_rh_thumb_distal" />
    <exclude body1="arm_right_R4_Link" body2="hand_right_rh_index_metacarpals" />
    <exclude body1="arm_right_R4_Link" body2="hand_right_rh_index_proximal" />
    <exclude body1="arm_right_R4_Link" body2="hand_right_rh_index_middle" />
    <exclude body1="arm_right_R4_Link" body2="hand_right_rh_index_distal" />
    <exclude body1="arm_right_R4_Link" body2="hand_right_rh_middle_proximal" />
    <exclude body1="arm_right_R4_Link" body2="hand_right_rh_middle_middle" />
    <exclude body1="arm_right_R4_Link" body2="hand_right_rh_middle_distal" />
    <exclude body1="arm_right_R4_Link" body2="hand_right_rh_ring_metacarpals" />
    <exclude body1="arm_right_R4_Link" body2="hand_right_rh_ring_proximal" />
    <exclude body1="arm_right_R4_Link" body2="hand_right_rh_ring_middle" />
    <exclude body1="arm_right_R4_Link" body2="hand_right_rh_ring_distal" />
    <exclude body1="arm_right_R4_Link" body2="hand_right_rh_pinky_metacarpals" />
    <exclude body1="arm_right_R4_Link" body2="hand_right_rh_pinky_proximal" />
    <exclude body1="arm_right_R4_Link" body2="hand_right_rh_pinky_middle" />
    <exclude body1="arm_right_R4_Link" body2="hand_right_rh_pinky_distal" />
    <exclude body1="arm_right_R5_Link" body2="hand_right_rh_hand_base_link" />
    <exclude body1="arm_right_R5_Link" body2="hand_right_rh_thumb_metacarpals_base1" />
    <exclude body1="arm_right_R5_Link" body2="hand_right_rh_thumb_metacarpals_base2" />
    <exclude body1="arm_right_R5_Link" body2="hand_right_rh_thumb_metacarpals" />
    <exclude body1="arm_right_R5_Link" body2="hand_right_rh_thumb_proximal" />
    <exclude body1="arm_right_R5_Link" body2="hand_right_rh_thumb_distal" />
    <exclude body1="arm_right_R5_Link" body2="hand_right_rh_index_metacarpals" />
    <exclude body1="arm_right_R5_Link" body2="hand_right_rh_index_proximal" />
    <exclude body1="arm_right_R5_Link" body2="hand_right_rh_index_middle" />
    <exclude body1="arm_right_R5_Link" body2="hand_right_rh_index_distal" />
    <exclude body1="arm_right_R5_Link" body2="hand_right_rh_middle_proximal" />
    <exclude body1="arm_right_R5_Link" body2="hand_right_rh_middle_middle" />
    <exclude body1="arm_right_R5_Link" body2="hand_right_rh_middle_distal" />
    <exclude body1="arm_right_R5_Link" body2="hand_right_rh_ring_metacarpals" />
    <exclude body1="arm_right_R5_Link" body2="hand_right_rh_ring_proximal" />
    <exclude body1="arm_right_R5_Link" body2="hand_right_rh_ring_middle" />
    <exclude body1="arm_right_R5_Link" body2="hand_right_rh_ring_distal" />
    <exclude body1="arm_right_R5_Link" body2="hand_right_rh_pinky_metacarpals" />
    <exclude body1="arm_right_R5_Link" body2="hand_right_rh_pinky_proximal" />
    <exclude body1="arm_right_R5_Link" body2="hand_right_rh_pinky_middle" />
    <exclude body1="arm_right_R5_Link" body2="hand_right_rh_pinky_distal" />
    <exclude body1="arm_right_R6_Link" body2="hand_right_rh_hand_base_link" />
    <exclude body1="arm_right_R6_Link" body2="hand_right_rh_thumb_metacarpals_base1" />
    <exclude body1="arm_right_R6_Link" body2="hand_right_rh_thumb_metacarpals_base2" />
    <exclude body1="arm_right_R6_Link" body2="hand_right_rh_thumb_metacarpals" />
    <exclude body1="arm_right_R6_Link" body2="hand_right_rh_thumb_proximal" />
    <exclude body1="arm_right_R6_Link" body2="hand_right_rh_thumb_distal" />
    <exclude body1="arm_right_R6_Link" body2="hand_right_rh_index_metacarpals" />
    <exclude body1="arm_right_R6_Link" body2="hand_right_rh_index_proximal" />
    <exclude body1="arm_right_R6_Link" body2="hand_right_rh_index_middle" />
    <exclude body1="arm_right_R6_Link" body2="hand_right_rh_index_distal" />
    <exclude body1="arm_right_R6_Link" body2="hand_right_rh_middle_proximal" />
    <exclude body1="arm_right_R6_Link" body2="hand_right_rh_middle_middle" />
    <exclude body1="arm_right_R6_Link" body2="hand_right_rh_middle_distal" />
    <exclude body1="arm_right_R6_Link" body2="hand_right_rh_ring_metacarpals" />
    <exclude body1="arm_right_R6_Link" body2="hand_right_rh_ring_proximal" />
    <exclude body1="arm_right_R6_Link" body2="hand_right_rh_ring_middle" />
    <exclude body1="arm_right_R6_Link" body2="hand_right_rh_ring_distal" />
    <exclude body1="arm_right_R6_Link" body2="hand_right_rh_pinky_metacarpals" />
    <exclude body1="arm_right_R6_Link" body2="hand_right_rh_pinky_proximal" />
    <exclude body1="arm_right_R6_Link" body2="hand_right_rh_pinky_middle" />
    <exclude body1="arm_right_R6_Link" body2="hand_right_rh_pinky_distal" />
    <exclude body1="arm_right_R7_Link" body2="hand_right_rh_hand_base_link" />
    <exclude body1="arm_right_R7_Link" body2="hand_right_rh_thumb_metacarpals_base1" />
    <exclude body1="arm_right_R7_Link" body2="hand_right_rh_thumb_metacarpals_base2" />
    <exclude body1="arm_right_R7_Link" body2="hand_right_rh_thumb_metacarpals" />
    <exclude body1="arm_right_R7_Link" body2="hand_right_rh_thumb_proximal" />
    <exclude body1="arm_right_R7_Link" body2="hand_right_rh_thumb_distal" />
    <exclude body1="arm_right_R7_Link" body2="hand_right_rh_index_metacarpals" />
    <exclude body1="arm_right_R7_Link" body2="hand_right_rh_index_proximal" />
    <exclude body1="arm_right_R7_Link" body2="hand_right_rh_index_middle" />
    <exclude body1="arm_right_R7_Link" body2="hand_right_rh_index_distal" />
    <exclude body1="arm_right_R7_Link" body2="hand_right_rh_middle_proximal" />
    <exclude body1="arm_right_R7_Link" body2="hand_right_rh_middle_middle" />
    <exclude body1="arm_right_R7_Link" body2="hand_right_rh_middle_distal" />
    <exclude body1="arm_right_R7_Link" body2="hand_right_rh_ring_metacarpals" />
    <exclude body1="arm_right_R7_Link" body2="hand_right_rh_ring_proximal" />
    <exclude body1="arm_right_R7_Link" body2="hand_right_rh_ring_middle" />
    <exclude body1="arm_right_R7_Link" body2="hand_right_rh_ring_distal" />
    <exclude body1="arm_right_R7_Link" body2="hand_right_rh_pinky_metacarpals" />
    <exclude body1="arm_right_R7_Link" body2="hand_right_rh_pinky_proximal" />
    <exclude body1="arm_right_R7_Link" body2="hand_right_rh_pinky_middle" />
    <exclude body1="arm_right_R7_Link" body2="hand_right_rh_pinky_distal" />
    <exclude body1="base_base_link" body2="hand_right_rh_hand_base_link" />
    <exclude body1="base_base_link" body2="hand_right_rh_thumb_metacarpals_base1" />
    <exclude body1="base_base_link" body2="hand_right_rh_thumb_metacarpals_base2" />
    <exclude body1="base_base_link" body2="hand_right_rh_thumb_metacarpals" />
    <exclude body1="base_base_link" body2="hand_right_rh_thumb_proximal" />
    <exclude body1="base_base_link" body2="hand_right_rh_thumb_distal" />
    <exclude body1="base_base_link" body2="hand_right_rh_index_metacarpals" />
    <exclude body1="base_base_link" body2="hand_right_rh_index_proximal" />
    <exclude body1="base_base_link" body2="hand_right_rh_index_middle" />
    <exclude body1="base_base_link" body2="hand_right_rh_index_distal" />
    <exclude body1="base_base_link" body2="hand_right_rh_middle_proximal" />
    <exclude body1="base_base_link" body2="hand_right_rh_middle_middle" />
    <exclude body1="base_base_link" body2="hand_right_rh_middle_distal" />
    <exclude body1="base_base_link" body2="hand_right_rh_ring_metacarpals" />
    <exclude body1="base_base_link" body2="hand_right_rh_ring_proximal" />
    <exclude body1="base_base_link" body2="hand_right_rh_ring_middle" />
    <exclude body1="base_base_link" body2="hand_right_rh_ring_distal" />
    <exclude body1="base_base_link" body2="hand_right_rh_pinky_metacarpals" />
    <exclude body1="base_base_link" body2="hand_right_rh_pinky_proximal" />
    <exclude body1="base_base_link" body2="hand_right_rh_pinky_middle" />
    <exclude body1="base_base_link" body2="hand_right_rh_pinky_distal" />
  </contact>
</mujoco>
