<?xml version='1.0' encoding='utf-8'?>
<robot name="hand">
  <link name="lh_hand_base_link">
    <inertial>
      <origin xyz="-0.00378861347432373 0.000820204450131895 0.0805686615689543" rpy="0 0 0" />
      <mass value="0.103652479414672" />
      <inertia ixx="0.000193076183440551" ixy="1.28622350247875e-06" ixz="-2.06064564153793e-07" iyy="0.000129262885172737" iyz="-2.33887125894354e-06" izz="7.7154522927273e-05" />
    </inertial>
    <visual>
      <origin xyz="0 0 0" rpy="0 0 0" />
      <geometry><mesh filename="meshes/hand_base_link.STL" /></geometry>
      <material name=""><color rgba="1 1 1 1" /></material>
    </visual>
    <collision>
      <origin xyz="0 0 0" rpy="0 0 0" />
      <geometry><mesh filename="meshes/hand_base_link.STL" /></geometry>
    </collision>
  </link>
  <link name="lh_thumb_metacarpals_base1">
    <inertial>
      <origin xyz="0.0284841419451473 0.0032328053117659 1.27102541975441e-05" rpy="0 0 0" />
      <mass value="0.00840514828448049" />
      <inertia ixx="1.40225690783513e-06" ixy="1.196162690714e-07" ixz="7.34629714950971e-09" iyy="9.92532738625187e-07" iyz="-4.63982709938509e-08" izz="7.25924523731736e-07" />
    </inertial>
    <visual>
      <origin xyz="0 0 0" rpy="0 0 0" />
      <geometry><mesh filename="meshes/thumb_metacarpals_base1.STL" /></geometry>
      <material name=""><color rgba="1 1 1 1" /></material>
    </visual>
    <collision>
      <origin xyz="0 0 0" rpy="0 0 0" />
      <geometry><mesh filename="meshes/thumb_metacarpals_base1.STL" /></geometry>
    </collision>
  </link>
  <link name="lh_thumb_metacarpals_base2">
    <inertial>
      <origin xyz="0.00149333647480262 -0.00615813217507052 -0.000273768129351912" rpy="0 0 0" />
      <mass value="0.00244725656099355" />
      <inertia ixx="1.15757169903916e-07" ixy="-4.50060051446398e-09" ixz="-9.19744539328016e-10" iyy="9.88121769947347e-08" iyz="3.81969206030993e-09" izz="6.88506418885536e-08" />
    </inertial>
    <visual>
      <origin xyz="0 0 0" rpy="0 0 0" />
      <geometry><mesh filename="meshes/thumb_metacarpals_base2.STL" /></geometry>
      <material name=""><color rgba="1 1 1 1" /></material>
    </visual>
    <collision>
      <origin xyz="0 0 0" rpy="0 0 0" />
      <geometry><mesh filename="meshes/thumb_metacarpals_base2.STL" /></geometry>
    </collision>
  </link>
  <link name="lh_thumb_metacarpals">
    <inertial>
      <origin xyz="0.00183663729904029 3.46162460989133e-06 0.026990412201572" rpy="0 0 0" />
      <mass value="0.0152011788694593" />
      <inertia ixx="2.95369587925714e-06" ixy="4.74536745194236e-11" ixz="-1.58087239939667e-07" iyy="3.84770419198789e-06" iyz="4.13672896569864e-10" izz="1.32008560539723e-06" />
    </inertial>
    <visual>
      <origin xyz="0 0 0" rpy="0 0 0" />
      <geometry><mesh filename="meshes/thumb_metacarpals.STL" /></geometry>
      <material name=""><color rgba="1 1 1 1" /></material>
    </visual>
    <collision>
      <origin xyz="0 0 0" rpy="0 0 0" />
      <geometry><mesh filename="meshes/thumb_metacarpals.STL" /></geometry>
    </collision>
  </link>
  <link name="lh_thumb_proximal">
    <inertial>
      <origin xyz="0.00159260267405223 4.28988976902342e-06 0.0151572309111939" rpy="0 0 0" />
      <mass value="0.00662225085289633" />
      <inertia ixx="1.01526328949763e-06" ixy="-7.87460584199835e-12" ixz="-4.4224308859969e-08" iyy="9.10425089721739e-07" iyz="2.81833762972893e-11" izz="4.47462917464685e-07" />
    </inertial>
    <visual>
      <origin xyz="0 0 0" rpy="0 0 0" />
      <geometry><mesh filename="meshes/thumb_proximal.STL" /></geometry>
      <material name=""><color rgba="1 1 1 1" /></material>
    </visual>
    <collision>
      <origin xyz="0 0 0" rpy="0 0 0" />
      <geometry><mesh filename="meshes/thumb_proximal.STL" /></geometry>
    </collision>
  </link>
  <link name="lh_thumb_distal">
    <inertial>
      <origin xyz="-0.00138833978915306 -1.92768110708619e-06 0.0115764513296314" rpy="0 0 0" />
      <mass value="0.00512798334000111" />
      <inertia ixx="3.30808161248092e-07" ixy="-3.43833611720834e-10" ixz="-1.04696624534012e-07" iyy="3.2363078244428e-07" iyz="-1.18697138701936e-10" izz="2.48875198442135e-07" />
    </inertial>
    <visual>
      <origin xyz="0 0 0" rpy="0 0 0" />
      <geometry><mesh filename="meshes/thumb_distal.STL" /></geometry>
      <material name=""><color rgba="1 1 1 1" /></material>
    </visual>
    <collision>
      <origin xyz="0 0 0" rpy="0 0 0" />
      <geometry><mesh filename="meshes/thumb_distal.STL" /></geometry>
    </collision>
  </link>
  <link name="lh_index_metacarpals">
    <inertial>
      <origin xyz="-0.00143091454702933 2.56878017135254e-07 0.0107040528609869" rpy="0 0 0" />
      <mass value="0.0038877126435198" />
      <inertia ixx="1.87149599832498e-07" ixy="3.67335498441413e-11" ixz="1.3415127653338e-08" iyy="2.75278147668716e-07" iyz="2.44762951204078e-11" izz="2.06866317113344e-07" />
    </inertial>
    <visual>
      <origin xyz="0 0 0" rpy="0 0 0" />
      <geometry><mesh filename="meshes/index_metacarpals.STL" /></geometry>
      <material name=""><color rgba="1 1 1 1" /></material>
    </visual>
    <collision>
      <origin xyz="0 0 0" rpy="0 0 0" />
      <geometry><mesh filename="meshes/index_metacarpals.STL" /></geometry>
    </collision>
  </link>
  <link name="lh_index_proximal">
    <inertial>
      <origin xyz="-0.00122347616770057 -2.04121170566118e-06 0.0182409893195748" rpy="0 0 0" />
      <mass value="0.00316246584579941" />
      <inertia ixx="3.57135128024094e-07" ixy="1.42036124901073e-11" ixz="-4.14209968733606e-08" iyy="3.51905870436209e-07" iyz="-1.08557233942923e-10" izz="1.40872561400322e-07" />
    </inertial>
    <visual>
      <origin xyz="0 0 0" rpy="0 0 0" />
      <geometry><mesh filename="meshes/index_proximal.STL" /></geometry>
      <material name=""><color rgba="1 1 1 1" /></material>
    </visual>
    <collision>
      <origin xyz="0 0 0" rpy="0 0 0" />
      <geometry><mesh filename="meshes/index_proximal.STL" /></geometry>
    </collision>
  </link>
  <link name="lh_index_middle">
    <inertial>
      <origin xyz="-0.00250309203564306 2.18945385091485e-06 0.0110397390913486" rpy="0 0 0" />
      <mass value="0.00283043921422803" />
      <inertia ixx="2.61037133593912e-07" ixy="5.76197451786318e-11" ixz="-4.0011060525121e-08" iyy="2.33077518995487e-07" iyz="-2.86979503467821e-11" izz="1.26543797445814e-07" />
    </inertial>
    <visual>
      <origin xyz="0 0 0" rpy="0 0 0" />
      <geometry><mesh filename="meshes/index_middle.STL" /></geometry>
      <material name=""><color rgba="1 1 1 1" /></material>
    </visual>
    <collision>
      <origin xyz="0 0 0" rpy="0 0 0" />
      <geometry><mesh filename="meshes/index_middle.STL" /></geometry>
    </collision>
  </link>
  <link name="lh_index_distal">
    <inertial>
      <origin xyz="-0.000604509916724614 -4.77400032578013e-06 0.0121511111849248" rpy="0 0 0" />
      <mass value="0.0031445375098231" />
      <inertia ixx="1.64070673729839e-07" ixy="1.88963511473794e-11" ixz="-4.27776869144244e-08" iyy="1.48362830813358e-07" iyz="-1.9734013143508e-10" izz="9.7804088657243e-08" />
    </inertial>
    <visual>
      <origin xyz="0 0 0" rpy="0 0 0" />
      <geometry><mesh filename="meshes/index_distal.STL" /></geometry>
      <material name=""><color rgba="1 1 1 1" /></material>
    </visual>
    <collision>
      <origin xyz="0 0 0" rpy="0 0 0" />
      <geometry><mesh filename="meshes/index_distal.STL" /></geometry>
    </collision>
  </link>
  <link name="lh_middle_proximal">
    <inertial>
      <origin xyz="-0.00123185150819907 -2.04476498746886e-06 0.0182404193627525" rpy="0 0 0" />
      <mass value="0.00316246719662224" />
      <inertia ixx="3.57097075648345e-07" ixy="1.43002807788619e-11" ixz="-4.15201646947523e-08" iyy="3.51905920397223e-07" iyz="-1.08488557665733e-10" izz="1.4091067749978e-07" />
    </inertial>
    <visual>
      <origin xyz="0 0 0" rpy="0 0 0" />
      <geometry><mesh filename="meshes/middle_proximal.STL" /></geometry>
      <material name=""><color rgba="1 1 1 1" /></material>
    </visual>
    <collision>
      <origin xyz="0 0 0" rpy="0 0 0" />
      <geometry><mesh filename="meshes/middle_proximal.STL" /></geometry>
    </collision>
  </link>
  <link name="lh_middle_middle">
    <inertial>
      <origin xyz="-0.00252079729924576 2.18964489481777e-06 0.0110357094277332" rpy="0 0 0" />
      <mass value="0.00283043921858529" />
      <inertia ixx="2.60908423355366e-07" ixy="5.76720293661014e-11" ixz="-4.02265908644236e-08" iyy="2.33077520740401e-07" iyz="-2.86057758459882e-11" izz="1.26672514044425e-07" />
    </inertial>
    <visual>
      <origin xyz="0 0 0" rpy="0 0 0" />
      <geometry><mesh filename="meshes/middle_middle.STL" /></geometry>
      <material name=""><color rgba="1 1 1 1" /></material>
    </visual>
    <collision>
      <origin xyz="0 0 0" rpy="0 0 0" />
      <geometry><mesh filename="meshes/middle_middle.STL" /></geometry>
    </collision>
  </link>
  <link name="lh_middle_distal">
    <inertial>
      <origin xyz="-0.000622397825955366 -4.75569749899818e-06 0.012150171418504" rpy="0 0 0" />
      <mass value="0.00314452092964384" />
      <inertia ixx="1.63942838563309e-07" ixy="1.9526841627913e-11" ixz="-4.28753645610842e-08" iyy="1.48361296215111e-07" iyz="-1.96949597957508e-10" izz="9.7929884595885e-08" />
    </inertial>
    <visual>
      <origin xyz="0 0 0" rpy="0 0 0" />
      <geometry><mesh filename="meshes/middle_distal.STL" /></geometry>
      <material name=""><color rgba="1 1 1 1" /></material>
    </visual>
    <collision>
      <origin xyz="0 0 0" rpy="0 0 0" />
      <geometry><mesh filename="meshes/middle_distal.STL" /></geometry>
    </collision>
  </link>
  <link name="lh_ring_metacarpals">
    <inertial>
      <origin xyz="-0.00143091448892014 6.05495226457808e-07 0.0107040523320813" rpy="0 0 0" />
      <mass value="0.00388771255966599" />
      <inertia ixx="1.87149578481638e-07" ixy="1.52642675041227e-11" ixz="1.34151349601248e-08" iyy="2.75278155094349e-07" iyz="2.12062463357117e-11" izz="2.06866318930306e-07" />
    </inertial>
    <visual>
      <origin xyz="0 0 0" rpy="0 0 0" />
      <geometry><mesh filename="meshes/ring_metacarpals.STL" /></geometry>
      <material name=""><color rgba="1 1 1 1" /></material>
    </visual>
    <collision>
      <origin xyz="0 0 0" rpy="0 0 0" />
      <geometry><mesh filename="meshes/ring_metacarpals.STL" /></geometry>
    </collision>
  </link>
  <link name="lh_ring_proximal">
    <inertial>
      <origin xyz="-0.00122347652312429 -2.0423407393888e-06 0.0182409875332818" rpy="0 0 0" />
      <mass value="0.00316246660225829" />
      <inertia ixx="3.5713512847731e-07" ixy="1.42130904393983e-11" ixz="-4.14209983311065e-08" iyy="3.51905881089114e-07" iyz="-1.08576103054512e-10" izz="1.40872582931496e-07" />
    </inertial>
    <visual>
      <origin xyz="0 0 0" rpy="0 0 0" />
      <geometry><mesh filename="meshes/ring_proximal.STL" /></geometry>
      <material name=""><color rgba="1 1 1 1" /></material>
    </visual>
    <collision>
      <origin xyz="0 0 0" rpy="0 0 0" />
      <geometry><mesh filename="meshes/ring_proximal.STL" /></geometry>
    </collision>
  </link>
  <link name="lh_ring_middle">
    <inertial>
      <origin xyz="-0.00250309189885196 2.18959036171751e-06 0.0110397385966097" rpy="0 0 0" />
      <mass value="0.00283043920090097" />
      <inertia ixx="2.61037130501287e-07" ixy="5.76216047828233e-11" ixz="-4.00110582573436e-08" iyy="2.33077521207674e-07" iyz="-2.86985395311388e-11" izz="1.26543807918808e-07" />
    </inertial>
    <visual>
      <origin xyz="0 0 0" rpy="0 0 0" />
      <geometry><mesh filename="meshes/ring_middle.STL" /></geometry>
      <material name=""><color rgba="1 1 1 1" /></material>
    </visual>
    <collision>
      <origin xyz="0 0 0" rpy="0 0 0" />
      <geometry><mesh filename="meshes/ring_middle.STL" /></geometry>
    </collision>
  </link>
  <link name="lh_ring_distal">
    <inertial>
      <origin xyz="-0.000604497650389674 -4.73100652065295e-06 0.012151126431567" rpy="0 0 0" />
      <mass value="0.00314454943731604" />
      <inertia ixx="1.64071049652571e-07" ixy="1.94791513771428e-11" ixz="-4.27777374237679e-08" iyy="1.48363091013624e-07" iyz="-1.96468435398403e-10" izz="9.78042601257212e-08" />
    </inertial>
    <visual>
      <origin xyz="0 0 0" rpy="0 0 0" />
      <geometry><mesh filename="meshes/ring_distal.STL" /></geometry>
      <material name=""><color rgba="1 1 1 1" /></material>
    </visual>
    <collision>
      <origin xyz="0 0 0" rpy="0 0 0" />
      <geometry><mesh filename="meshes/ring_distal.STL" /></geometry>
    </collision>
  </link>
  <link name="lh_pinky_metacarpals">
    <inertial>
      <origin xyz="-0.00143091630673887 6.05311374107798e-07 0.010704049929046" rpy="0 0 0" />
      <mass value="0.00388771229554929" />
      <inertia ixx="1.87149536268889e-07" ixy="1.52679681737727e-11" ixz="1.34151204706615e-08" iyy="2.75278106047772e-07" iyz="2.11967245454867e-11" izz="2.06866328803883e-07" />
    </inertial>
    <visual>
      <origin xyz="0 0 0" rpy="0 0 0" />
      <geometry><mesh filename="meshes/pinky_metacarpals.STL" /></geometry>
      <material name=""><color rgba="1 1 1 1" /></material>
    </visual>
    <collision>
      <origin xyz="0 0 0" rpy="0 0 0" />
      <geometry><mesh filename="meshes/pinky_metacarpals.STL" /></geometry>
    </collision>
  </link>
  <link name="lh_pinky_proximal">
    <inertial>
      <origin xyz="-0.00122347805395697 -2.04329569369888e-06 0.0182409919418033" rpy="0 0 0" />
      <mass value="0.00316246781629033" />
      <inertia ixx="3.57135263144139e-07" ixy="1.42286998987323e-11" ixz="-4.14209901998364e-08" iyy="3.5190602349514e-07" iyz="-1.08636442666922e-10" izz="1.40872647811026e-07" />
    </inertial>
    <visual>
      <origin xyz="0 0 0" rpy="0 0 0" />
      <geometry><mesh filename="meshes/pinky_proximal.STL" /></geometry>
      <material name=""><color rgba="1 1 1 1" /></material>
    </visual>
    <collision>
      <origin xyz="0 0 0" rpy="0 0 0" />
      <geometry><mesh filename="meshes/pinky_proximal.STL" /></geometry>
    </collision>
  </link>
  <link name="lh_pinky_middle">
    <inertial>
      <origin xyz="-0.00250309214140259 2.1894783039933e-06 0.0110397383273556" rpy="0 0 0" />
      <mass value="0.00283043906989622" />
      <inertia ixx="2.61037124783617e-07" ixy="5.7617222079153e-11" ixz="-4.00110565109454e-08" iyy="2.33077513229909e-07" iyz="-2.86988443315275e-11" izz="1.2654380297458e-07" />
    </inertial>
    <visual>
      <origin xyz="0 0 0" rpy="0 0 0" />
      <geometry><mesh filename="meshes/pinky_middle.STL" /></geometry>
      <material name=""><color rgba="1 1 1 1" /></material>
    </visual>
    <collision>
      <origin xyz="0 0 0" rpy="0 0 0" />
      <geometry><mesh filename="meshes/pinky_middle.STL" /></geometry>
    </collision>
  </link>
  <link name="lh_pinky_distal">
    <inertial>
      <origin xyz="-0.000604492895887754 -4.75263680191351e-06 0.0121511379180032" rpy="0 0 0" />
      <mass value="0.00314455887032079" />
      <inertia ixx="1.64071496633017e-07" ixy="1.95563986835622e-11" ixz="-4.27779200959899e-08" iyy="1.48363675410427e-07" iyz="-1.9679860568024e-10" izz="9.78043717695209e-08" />
    </inertial>
    <visual>
      <origin xyz="0 0 0" rpy="0 0 0" />
      <geometry><mesh filename="meshes/pinky_distal.STL" /></geometry>
      <material name=""><color rgba="1 1 1 1" /></material>
    </visual>
    <collision>
      <origin xyz="0 0 0" rpy="0 0 0" />
      <geometry><mesh filename="meshes/pinky_distal.STL" /></geometry>
    </collision>
  </link>
  <joint name="lh_thumb_cmc_roll" type="revolute">
    <origin xyz="-0.013419 -0.012551 0.060602" rpy="0 0 0" />
    <parent link="lh_hand_base_link" />
    <child link="lh_thumb_metacarpals_base1" />
    <axis xyz="-0.99996 0 -0.0087265" />
    <limit lower="0" upper="1.03" effort="4.8" velocity="1" />
  </joint>
  <joint name="lh_thumb_cmc_yaw" type="revolute">
    <origin xyz="0.035797 0.00065879 0.00045944" rpy="0.13232 -0.0087266 0" />
    <parent link="lh_thumb_metacarpals_base1" />
    <child link="lh_thumb_metacarpals_base2" />
    <axis xyz="0 0.087156 0.99619" />
    <limit lower="0" upper="1.4" effort="4.8" velocity="1" />
  </joint>
  <joint name="lh_thumb_cmc_pitch" type="revolute">
    <origin xyz="0.0036974 -0.015398 -0.0019891" rpy="0 -0.9163 1.8064" />
    <parent link="lh_thumb_metacarpals_base2" />
    <child link="lh_thumb_metacarpals" />
    <axis xyz="0 1 0" />
    <limit lower="0" upper="0.52" effort="4.8" velocity="1" />
  </joint>
  <joint name="lh_thumb_mcp" type="revolute">
    <origin xyz="0.0061722 0 0.047968" rpy="0 0 0" />
    <parent link="lh_thumb_metacarpals" />
    <child link="lh_thumb_proximal" />
    <axis xyz="0 1 0" />
    <limit lower="0" upper="0.72" effort="3.7" velocity="1" />
    <mimic joint="lh_thumb_cmc_pitch" multiplier="1.38" offset="0" />
  </joint>
  <joint name="lh_thumb_ip" type="revolute">
    <origin xyz="-0.00017064 0 0.038665" rpy="0 0 0" />
    <parent link="lh_thumb_proximal" />
    <child link="lh_thumb_distal" />
    <axis xyz="0 1 0" />
    <limit lower="0" upper="0.78" effort="3.36" velocity="1" />
    <mimic joint="lh_thumb_cmc_pitch" multiplier="1.49" offset="0" />
  </joint>
  <joint name="lh_index_mcp_roll" type="revolute">
    <origin xyz="-0.0021643 -0.026654 0.13253" rpy="0.027927 -0.0087198 -0.00024358" />
    <parent link="lh_hand_base_link" />
    <child link="lh_index_metacarpals" />
    <axis xyz="1 0.00024367 0" />
    <limit lower="0" upper="0.19" effort="4.29" velocity="1" />
  </joint>
  <joint name="lh_index_mcp_pitch" type="revolute">
    <origin xyz="0.0022097 0 0.015275" rpy="0 0 0.00024367" />
    <parent link="lh_index_metacarpals" />
    <child link="lh_index_proximal" />
    <axis xyz="0 1 0" />
    <limit lower="0" upper="1.36" effort="4.8" velocity="1" />
  </joint>
  <joint name="lh_index_pip" type="revolute">
    <origin xyz="-0.0010697 0 0.035634" rpy="0 0 0" />
    <parent link="lh_index_proximal" />
    <child link="lh_index_middle" />
    <axis xyz="0 1 0" />
    <limit lower="0" upper="1.78" effort="3.7" velocity="1" />
    <mimic joint="lh_index_mcp_pitch" multiplier="1.3" offset="0" />
  </joint>
  <joint name="lh_index_dip" type="revolute">
    <origin xyz="-0.0052444 0 0.025711" rpy="0 0 0" />
    <parent link="lh_index_middle" />
    <child link="lh_index_distal" />
    <axis xyz="0 1 0" />
    <limit lower="0" upper="0.62" effort="10.43" velocity="1" />
    <mimic joint="lh_index_mcp_pitch" multiplier="0.46" offset="0" />
  </joint>
  <joint name="lh_middle_mcp_pitch" type="revolute">
    <origin xyz="-0.0021316 -0.0076542 0.15281" rpy="0 -0.0087266 0" />
    <parent link="lh_hand_base_link" />
    <child link="lh_middle_proximal" />
    <axis xyz="0 1 0" />
    <limit lower="0" upper="1.36" effort="4.8" velocity="1" />
  </joint>
  <joint name="lh_middle_pip" type="revolute">
    <origin xyz="-0.0010861 0 0.035634" rpy="0 0 0" />
    <parent link="lh_middle_proximal" />
    <child link="lh_middle_middle" />
    <axis xyz="0 1 0" />
    <limit lower="0" upper="1.78" effort="3.7" velocity="1" />
    <mimic joint="lh_middle_mcp_pitch" multiplier="1.3" offset="0" />
  </joint>
  <joint name="lh_middle_dip" type="revolute">
    <origin xyz="-0.0052857 0 0.025703" rpy="0 0 0" />
    <parent link="lh_middle_middle" />
    <child link="lh_middle_distal" />
    <axis xyz="0 1 0" />
    <limit lower="0" upper="0.62" effort="10.43" velocity="1" />
    <mimic joint="lh_middle_mcp_pitch" multiplier="0.46" offset="0" />
  </joint>
  <joint name="lh_ring_mcp_roll" type="revolute">
    <origin xyz="-0.0021643 0.011346 0.13253" rpy="-0.024435 -0.0087266 0" />
    <parent link="lh_hand_base_link" />
    <child link="lh_ring_metacarpals" />
    <axis xyz="-1 0 0" />
    <limit lower="0" upper="0.2" effort="4.29" velocity="1" />
  </joint>
  <joint name="lh_ring_mcp_pitch" type="revolute">
    <origin xyz="0.0022097 0 0.015275" rpy="0 0 0" />
    <parent link="lh_ring_metacarpals" />
    <child link="lh_ring_proximal" />
    <axis xyz="0 1 0" />
    <limit lower="0" upper="1.36" effort="4.8" velocity="1" />
  </joint>
  <joint name="lh_ring_pip" type="revolute">
    <origin xyz="-0.0010697 0 0.035634" rpy="0 0 0" />
    <parent link="lh_ring_proximal" />
    <child link="lh_ring_middle" />
    <axis xyz="0 1 0" />
    <limit lower="0" upper="1.78" effort="3.7" velocity="1" />
    <mimic joint="lh_ring_mcp_pitch" multiplier="1.3" offset="0" />
  </joint>
  <joint name="lh_ring_dip" type="revolute">
    <origin xyz="-0.0052444 0 0.025711" rpy="0 0 0" />
    <parent link="lh_ring_middle" />
    <child link="lh_ring_distal" />
    <axis xyz="0 1 0" />
    <limit lower="0" upper="0.62" effort="10.43" velocity="1" />
    <mimic joint="lh_ring_mcp_pitch" multiplier="0.46" offset="0" />
  </joint>
  <joint name="lh_pinky_mcp_roll" type="revolute">
    <origin xyz="-0.00012074 0.030346 0.12755" rpy="-0.057596 -0.0087266 0" />
    <parent link="lh_hand_base_link" />
    <child link="lh_pinky_metacarpals" />
    <axis xyz="-1 0 0" />
    <limit lower="0" upper="0.3" effort="4.29" velocity="1" />
  </joint>
  <joint name="lh_pinky_mcp_pitch" type="revolute">
    <origin xyz="0.0022097 0 0.015275" rpy="0 0 0" />
    <parent link="lh_pinky_metacarpals" />
    <child link="lh_pinky_proximal" />
    <axis xyz="0 1 0" />
    <limit lower="0" upper="1.36" effort="4.8" velocity="1" />
  </joint>
  <joint name="lh_pinky_pip" type="revolute">
    <origin xyz="-0.0010697 0 0.035634" rpy="0 0 0" />
    <parent link="lh_pinky_proximal" />
    <child link="lh_pinky_middle" />
    <axis xyz="0 1 0" />
    <limit lower="0" upper="1.78" effort="3.7" velocity="1" />
    <mimic joint="lh_pinky_mcp_pitch" multiplier="1.3" offset="0" />
  </joint>
  <joint name="lh_pinky_dip" type="revolute">
    <origin xyz="-0.0052444 0 0.025711" rpy="0 0 0" />
    <parent link="lh_pinky_middle" />
    <child link="lh_pinky_distal" />
    <axis xyz="0 1 0" />
    <limit lower="0" upper="0.62" effort="10.43" velocity="1" />
    <mimic joint="lh_pinky_mcp_pitch" multiplier="0.46" offset="0" />
  </joint>
</robot>
