<?xml version="1.0" encoding="UTF-8"?>
<!-- Generated by tools/composer (version 0.1.0). Workstation: lkls73_i1_bimanual. Recipe sha256: cf521bd5c786fac04d2135e2dfe0bc68ba929431ddd9c0664adff9bd48e0788b. Do not edit by hand; re-run `python -m tools.composer.compose <workstation>`. -->
<robot name="lkls73_i1_bimanual">
  <link name="world" />
  <material name="hand_left_black">
    <color rgba="0.0 0.0 0.0 1.0" />
  </material>
  <material name="hand_left_blue">
    <color rgba="0.0 0.0 0.8 1.0" />
  </material>
  <material name="hand_left_green">
    <color rgba="0.0 0.8 0.0 1.0" />
  </material>
  <material name="hand_left_grey">
    <color rgba="0.2 0.2 0.2 1.0" />
  </material>
  <material name="hand_left_orange">
    <color rgba="1.0 0.423529411765 0.0392156862745 1.0" />
  </material>
  <material name="hand_left_brown">
    <color rgba="0.870588235294 0.811764705882 0.764705882353 1.0" />
  </material>
  <material name="hand_left_red">
    <color rgba="0.8 0.0 0.0 1.0" />
  </material>
  <material name="hand_left_white">
    <color rgba="1.0 1.0 1.0 1.0" />
  </material>
  <material name="hand_left_Beige">
    <color rgba="1.0 0.784 0.5765 1.0" />
  </material>
  <material name="hand_right_black">
    <color rgba="0.0 0.0 0.0 1.0" />
  </material>
  <material name="hand_right_blue">
    <color rgba="0.0 0.0 0.8 1.0" />
  </material>
  <material name="hand_right_green">
    <color rgba="0.0 0.8 0.0 1.0" />
  </material>
  <material name="hand_right_grey">
    <color rgba="0.2 0.2 0.2 1.0" />
  </material>
  <material name="hand_right_orange">
    <color rgba="1.0 0.423529411765 0.0392156862745 1.0" />
  </material>
  <material name="hand_right_brown">
    <color rgba="0.870588235294 0.811764705882 0.764705882353 1.0" />
  </material>
  <material name="hand_right_red">
    <color rgba="0.8 0.0 0.0 1.0" />
  </material>
  <material name="hand_right_white">
    <color rgba="1.0 1.0 1.0 1.0" />
  </material>
  <material name="hand_right_Beige">
    <color rgba="1.0 0.784 0.5765 1.0" />
  </material>
  <link name="base_torso_root" />
  <link name="base_base_link">
    <inertial>
      <origin xyz="5.75109188e-05 1.44120839e-05 -0.489174317" rpy="0 0 0" />
      <mass value="10.8067081992573" />
      <inertia ixx="0.192527915393298" ixy="-1.67956043663548E-08" ixz="-3.68569447484118E-08" iyy="0.191539752328327" iyz="6.60319145138974E-08" izz="0.103049415034787" />
    </inertial>
    <visual>
      <origin xyz="0 0 0" rpy="0 0 0" />
      <geometry>
        <mesh filename="../../components/bases/lkls73_torso/variants/default/meshes/base_link.STL" />
      </geometry>
      <material name="base_lkls73_torso_gray">
        <color rgba="0.752941176470588 0.752941176470588 0.752941176470588 1" />
      </material>
    </visual>
    <collision>
      <origin xyz="0 0 0" rpy="0 0 0" />
      <geometry>
        <mesh filename="../../components/bases/lkls73_torso/variants/default/meshes/base_link.STL" />
      </geometry>
    </collision>
  </link>
  <link name="base_arm_left_mount" />
  <link name="base_arm_right_mount" />
  <link name="arm_left_L_arm_root" />
  <link name="arm_left_L1_Link">
    <inertial>
      <origin xyz="0.00235600061 0.0538143182 0.000104521982" rpy="0 0 0" />
      <mass value="1.3997199601261" />
      <inertia ixx="0.00114445383866051" ixy="-2.33503672142218E-06" ixz="-9.94413789148138E-09" iyy="0.000654874787984474" iyz="1.05907637546798E-06" izz="0.000691494366096022" />
    </inertial>
    <visual>
      <origin xyz="0 0 0" rpy="0 0 0" />
      <geometry>
        <mesh filename="../../components/arms/lkls73_arm/variants/left/meshes/L1_Link.STL" />
      </geometry>
      <material name="">
        <color rgba="0.752941176470588 0.752941176470588 0.752941176470588 1" />
      </material>
    </visual>
    <collision>
      <origin xyz="0 0 0" rpy="0 0 0" />
      <geometry>
        <mesh filename="../../components/arms/lkls73_arm/variants/left/meshes/L1_Link.STL" />
      </geometry>
    </collision>
  </link>
  <link name="arm_left_L2_Link">
    <inertial>
      <origin xyz="0.00161841973 8.17586539e-06 -0.0795739675" rpy="0 0 0" />
      <mass value="1.14210487960353" />
      <inertia ixx="0.000999259952314694" ixy="4.38390447469883E-06" ixz="-1.34113970553355E-06" iyy="0.000929597687983869" iyz="2.7922699166407E-07" izz="0.000490873838603504" />
    </inertial>
    <visual>
      <origin xyz="0 0 0" rpy="0 0 0" />
      <geometry>
        <mesh filename="../../components/arms/lkls73_arm/variants/left/meshes/L2_Link.STL" />
      </geometry>
      <material name="">
        <color rgba="0.752941176470588 0.752941176470588 0.752941176470588 1" />
      </material>
    </visual>
    <collision>
      <origin xyz="0 0 0" rpy="0 0 0" />
      <geometry>
        <mesh filename="../../components/arms/lkls73_arm/variants/left/meshes/L2_Link.STL" />
      </geometry>
    </collision>
  </link>
  <link name="arm_left_L3_Link">
    <inertial>
      <origin xyz="0.000181280976 0.00124930562 -0.128548942" rpy="0 0 0" />
      <mass value="1.2798435287888" />
      <inertia ixx="0.00158095142201815" ixy="7.74063763820645E-07" ixz="-8.68119829913453E-07" iyy="0.00163152743924312" iyz="-2.41539579836192E-06" izz="0.000344148864762278" />
    </inertial>
    <visual>
      <origin xyz="0 0 0" rpy="0 0 0" />
      <geometry>
        <mesh filename="../../components/arms/lkls73_arm/variants/left/meshes/L3_Link.STL" />
      </geometry>
      <material name="">
        <color rgba="0.752941176470588 0.752941176470588 0.752941176470588 1" />
      </material>
    </visual>
    <collision>
      <origin xyz="0 0 0" rpy="0 0 0" />
      <geometry>
        <mesh filename="../../components/arms/lkls73_arm/variants/left/meshes/L3_Link.STL" />
      </geometry>
    </collision>
  </link>
  <link name="arm_left_L4_Link">
    <inertial>
      <origin xyz="-3.38229166e-06 0.000778423705 -0.0846001164" rpy="0 0 0" />
      <mass value="0.935504485205333" />
      <inertia ixx="0.000508246005403967" ixy="-4.123494432482E-06" ixz="-1.601236457745E-07" iyy="0.000524130562919452" iyz="-3.45757221458974E-07" izz="0.000333983371716017" />
    </inertial>
    <visual>
      <origin xyz="0 0 0" rpy="0 0 0" />
      <geometry>
        <mesh filename="../../components/arms/lkls73_arm/variants/left/meshes/L4_Link.STL" />
      </geometry>
      <material name="">
        <color rgba="0.752941176470588 0.752941176470588 0.752941176470588 1" />
      </material>
    </visual>
    <collision>
      <origin xyz="0 0 0" rpy="0 0 0" />
      <geometry>
        <mesh filename="../../components/arms/lkls73_arm/variants/left/meshes/L4_Link.STL" />
      </geometry>
    </collision>
  </link>
  <link name="arm_left_L5_Link">
    <inertial>
      <origin xyz="-7.89671091e-05 0.00127705818 -0.0361222642" rpy="0 0 0" />
      <mass value="0.298012293033296" />
      <inertia ixx="0.000356324975203863" ixy="8.49346343481351E-07" ixz="-1.06208641170066E-06" iyy="0.000385006059216245" iyz="2.16302454958746E-06" izz="0.000101746640600842" />
    </inertial>
    <visual>
      <origin xyz="0 0 0" rpy="0 0 0" />
      <geometry>
        <mesh filename="../../components/arms/lkls73_arm/variants/left/meshes/L5_Link.STL" />
      </geometry>
      <material name="">
        <color rgba="0.752941176470588 0.752941176470588 0.752941176470588 1" />
      </material>
    </visual>
    <collision>
      <origin xyz="0 0 0" rpy="0 0 0" />
      <geometry>
        <mesh filename="../../components/arms/lkls73_arm/variants/left/meshes/L5_Link.STL" />
      </geometry>
    </collision>
  </link>
  <link name="arm_left_L6_Link">
    <inertial>
      <origin xyz="0.00423270789 -0.00438646585 -0.0324823655" rpy="0 0 0" />
      <mass value="0.344326210144814" />
      <inertia ixx="0.000194396852170226" ixy="1.34053122918212E-06" ixz="9.47054882668167E-06" iyy="0.000233882186601331" iyz="2.86885239016126E-07" izz="0.000101458599044909" />
    </inertial>
    <visual>
      <origin xyz="0 0 0" rpy="0 0 0" />
      <geometry>
        <mesh filename="../../components/arms/lkls73_arm/variants/left/meshes/L6_Link.STL" />
      </geometry>
      <material name="">
        <color rgba="0.752941176470588 0.752941176470588 0.752941176470588 1" />
      </material>
    </visual>
    <collision>
      <origin xyz="0 0 0" rpy="0 0 0" />
      <geometry>
        <mesh filename="../../components/arms/lkls73_arm/variants/left/meshes/L6_Link.STL" />
      </geometry>
    </collision>
  </link>
  <link name="arm_left_L7_Link">
    <inertial>
      <origin xyz="-0.0033066755 2.71957338e-07 -0.020243018" rpy="0 0 0" />
      <mass value="0.143310943627726" />
      <inertia ixx="6.98168229201036E-05" ixy="2.70503363331007E-07" ixz="-3.17975733412514E-08" iyy="5.48675476764208E-05" iyz="1.01362000675163E-12" izz="4.4020607930097E-05" />
    </inertial>
    <visual>
      <origin xyz="0 0 0" rpy="0 0 0" />
      <geometry>
        <mesh filename="../../components/arms/lkls73_arm/variants/left/meshes/L7_Link.STL" />
      </geometry>
      <material name="">
        <color rgba="0.752941176470588 0.752941176470588 0.752941176470588 1" />
      </material>
    </visual>
    <collision>
      <origin xyz="0 0 0" rpy="0 0 0" />
      <geometry>
        <mesh filename="../../components/arms/lkls73_arm/variants/left/meshes/L7_Link.STL" />
      </geometry>
    </collision>
  </link>
  <link name="arm_left_L8_Link">
    <inertial>
      <origin xyz="1.08546552e-10 -1.13853899e-09 0.0005" rpy="0 0 0" />
      <mass value="6.05149284897746E-05" />
      <inertia ixx="8.49604381443617E-09" ixy="8.31968496153617E-22" ixz="-7.81277944440306E-15" iyy="8.49604381442905E-09" iyz="-9.03653480952828E-16" izz="1.69820018074357E-08" />
    </inertial>
    <visual>
      <origin xyz="0 0 0" rpy="0 0 0" />
      <geometry>
        <mesh filename="../../components/arms/lkls73_arm/variants/left/meshes/L8_Link.STL" />
      </geometry>
      <material name="">
        <color rgba="0.780392156862745 0.972549019607843 0.956862745098039 1" />
      </material>
    </visual>
    <collision>
      <origin xyz="0 0 0" rpy="0 0 0" />
      <geometry>
        <mesh filename="../../components/arms/lkls73_arm/variants/left/meshes/L8_Link.STL" />
      </geometry>
    </collision>
  </link>
  <link name="arm_right_R_arm_root" />
  <link name="arm_right_R1_Link">
    <inertial>
      <origin xyz="-0.00238919608 -0.0538157456 0.00010452196" rpy="0 0 0" />
      <mass value="1.39972022686362" />
      <inertia ixx="0.00114445390268402" ixy="-2.33503672059843E-06" ixz="9.94413679130844E-09" iyy="0.000654874566780468" iyz="-1.0590763545097E-06" izz="0.000691494652521253" />
    </inertial>
    <visual>
      <origin xyz="0 0 0" rpy="0 0 0" />
      <geometry>
        <mesh filename="../../components/arms/lkls73_arm/variants/right/meshes/R1_Link.STL" />
      </geometry>
      <material name="">
        <color rgba="0.752941176470588 0.752941176470588 0.752941176470588 1" />
      </material>
    </visual>
    <collision>
      <origin xyz="0 0 0" rpy="0 0 0" />
      <geometry>
        <mesh filename="../../components/arms/lkls73_arm/variants/right/meshes/R1_Link.STL" />
      </geometry>
    </collision>
  </link>
  <link name="arm_right_R2_Link">
    <inertial>
      <origin xyz="-0.00161840436 -8.198522e-06 -0.0795740267" rpy="0 0 0" />
      <mass value="1.14210467744301" />
      <inertia ixx="0.00099926032712546" ixy="4.38390428673455E-06" ixz="1.34112399215467E-06" iyy="0.000929597930299551" iyz="-2.7915125849712E-07" izz="0.000490873969400915" />
    </inertial>
    <visual>
      <origin xyz="0 0 0" rpy="0 0 0" />
      <geometry>
        <mesh filename="../../components/arms/lkls73_arm/variants/right/meshes/R2_Link.STL" />
      </geometry>
      <material name="">
        <color rgba="0.752941176470588 0.752941176470588 0.752941176470588 1" />
      </material>
    </visual>
    <collision>
      <origin xyz="0 0 0" rpy="0 0 0" />
      <geometry>
        <mesh filename="../../components/arms/lkls73_arm/variants/right/meshes/R2_Link.STL" />
      </geometry>
    </collision>
  </link>
  <link name="arm_right_R3_Link">
    <inertial>
      <origin xyz="-0.000181281047 -0.00124930021 -0.128548942" rpy="0 0 0" />
      <mass value="1.27984352653686" />
      <inertia ixx="0.00158095142360156" ixy="7.74064683830126E-07" ixz="8.68119825601561E-07" iyy="0.00163152744277086" iyz="2.41539423740222E-06" izz="0.000344148863355523" />
    </inertial>
    <visual>
      <origin xyz="0 0 0" rpy="0 0 0" />
      <geometry>
        <mesh filename="../../components/arms/lkls73_arm/variants/right/meshes/R3_Link.STL" />
      </geometry>
      <material name="">
        <color rgba="0.752941176470588 0.752941176470588 0.752941176470588 1" />
      </material>
    </visual>
    <collision>
      <origin xyz="0 0 0" rpy="0 0 0" />
      <geometry>
        <mesh filename="../../components/arms/lkls73_arm/variants/right/meshes/R3_Link.STL" />
      </geometry>
    </collision>
  </link>
  <link name="arm_right_R4_Link">
    <inertial>
      <origin xyz="4.42383386e-06 -0.000778418114 -0.0846001183" rpy="0 0 0" />
      <mass value="0.935504488206621" />
      <inertia ixx="0.00050824600575807" ixy="-4.12349458829714E-06" ixz="1.60122816329668E-07" iyy="0.000524130564978714" iyz="3.4575721962879E-07" izz="0.000333983373234424" />
    </inertial>
    <visual>
      <origin xyz="0 0 0" rpy="0 0 0" />
      <geometry>
        <mesh filename="../../components/arms/lkls73_arm/variants/right/meshes/R4_Link.STL" />
      </geometry>
      <material name="">
        <color rgba="0.752941176470588 0.752941176470588 0.752941176470588 1" />
      </material>
    </visual>
    <collision>
      <origin xyz="0 0 0" rpy="0 0 0" />
      <geometry>
        <mesh filename="../../components/arms/lkls73_arm/variants/right/meshes/R4_Link.STL" />
      </geometry>
    </collision>
  </link>
  <link name="arm_right_R5_Link">
    <inertial>
      <origin xyz="7.89161129e-05 -0.00127720103 -0.0361226258" rpy="0 0 0" />
      <mass value="0.298013716041534" />
      <inertia ixx="0.000356325710016729" ixy="8.49345579615723E-07" ixz="1.06208408022809E-06" iyy="0.000385006832605378" iyz="-2.16308499009301E-06" izz="0.000101746689163179" />
    </inertial>
    <visual>
      <origin xyz="0 0 0" rpy="0 0 0" />
      <geometry>
        <mesh filename="../../components/arms/lkls73_arm/variants/right/meshes/R5_Link.STL" />
      </geometry>
      <material name="">
        <color rgba="0.752941176470588 0.752941176470588 0.752941176470588 1" />
      </material>
    </visual>
    <collision>
      <origin xyz="0 0 0" rpy="0 0 0" />
      <geometry>
        <mesh filename="../../components/arms/lkls73_arm/variants/right/meshes/R5_Link.STL" />
      </geometry>
    </collision>
  </link>
  <link name="arm_right_R6_Link">
    <inertial>
      <origin xyz="-0.00423362801 0.00438647669 -0.0324823687" rpy="0 0 0" />
      <mass value="0.344326135276304" />
      <inertia ixx="0.000194396918256628" ixy="1.34060453386023E-06" ixz="-9.47065531650411E-06" iyy="0.000233882313857475" iyz="-2.86903332334497E-07" izz="0.00010145861997438" />
    </inertial>
    <visual>
      <origin xyz="0 0 0" rpy="0 0 0" />
      <geometry>
        <mesh filename="../../components/arms/lkls73_arm/variants/right/meshes/R6_Link.STL" />
      </geometry>
      <material name="">
        <color rgba="0.752941176470588 0.752941176470588 0.752941176470588 1" />
      </material>
    </visual>
    <collision>
      <origin xyz="0 0 0" rpy="0 0 0" />
      <geometry>
        <mesh filename="../../components/arms/lkls73_arm/variants/right/meshes/R6_Link.STL" />
      </geometry>
    </collision>
  </link>
  <link name="arm_right_R7_Link">
    <inertial>
      <origin xyz="0.0033066755 -1.18809317e-06 -0.020243018" rpy="0 0 0" />
      <mass value="0.143310943627727" />
      <inertia ixx="6.98168229201036E-05" ixy="2.70503363330993E-07" ixz="3.17975733407385E-08" iyy="5.48675476764227E-05" iyz="-1.01361997649667E-12" izz="4.4020607930099E-05" />
    </inertial>
    <visual>
      <origin xyz="0 0 0" rpy="0 0 0" />
      <geometry>
        <mesh filename="../../components/arms/lkls73_arm/variants/right/meshes/R7_Link.STL" />
      </geometry>
      <material name="">
        <color rgba="0.752941176470588 0.752941176470588 0.752941176470588 1" />
      </material>
    </visual>
    <collision>
      <origin xyz="0 0 0" rpy="0 0 0" />
      <geometry>
        <mesh filename="../../components/arms/lkls73_arm/variants/right/meshes/R7_Link.STL" />
      </geometry>
    </collision>
  </link>
  <link name="arm_right_R8_Link">
    <inertial>
      <origin xyz="-1.03808181e-10 5.33808553e-11 0.0005" rpy="0 0 0" />
      <mass value="6.05149284897743E-05" />
      <inertia ixx="8.49604381443613E-09" ixy="8.31967629121856E-22" ixz="7.81277954468574E-15" iyy="8.49604381442903E-09" iyz="9.03653481925555E-16" izz="1.69820018074356E-08" />
    </inertial>
    <visual>
      <origin xyz="0 0 0" rpy="0 0 0" />
      <geometry>
        <mesh filename="../../components/arms/lkls73_arm/variants/right/meshes/R8_Link.STL" />
      </geometry>
      <material name="">
        <color rgba="0.780392156862745 0.972549019607843 0.956862745098039 1" />
      </material>
    </visual>
    <collision>
      <origin xyz="0 0 0" rpy="0 0 0" />
      <geometry>
        <mesh filename="../../components/arms/lkls73_arm/variants/right/meshes/R8_Link.STL" />
      </geometry>
    </collision>
  </link>
  <link name="hand_left_lh_hand_base_link">
    <inertial>
      <origin xyz="0.00199 -0.00091 0.058381" rpy="0 0 0" />
      <mass value="0.4185" />
      <inertia ixx="0.0004998" ixy="0.000012853" ixz="-0.000008317" iyy="0.0003567" iyz="0.000010354" izz="0.0002301" />
    </inertial>
    <visual>
      <origin xyz="0 0 0" rpy="0 0 0" />
      <geometry>
        <mesh filename="../../components/hands/linkerhand_l6/variants/left/meshes/hand_base_link.STL" />
      </geometry>
      <material name="">
        <color rgba="0.796078431372549 0.823529411764706 0.937254901960784 1" />
      </material>
    </visual>
    <collision>
      <origin xyz="0 0 0" rpy="0 0 0" />
      <geometry>
        <mesh filename="../../components/hands/linkerhand_l6/variants/left/meshes/hand_base_link.STL" />
      </geometry>
    </collision>
  </link>
  <link name="hand_left_lh_thumb_metacarpals_base1">
    <inertial>
      <origin xyz="0.0018663 -0.0066406 0.001533" rpy="0 0 0" />
      <mass value="0.01" />
      <inertia ixx="3.3724E-07" ixy="1.11E-07" ixz="-3.6039E-08" iyy="2.9457E-07" iyz="5.7181E-08" izz="4.903E-07" />
    </inertial>
    <visual>
      <origin xyz="0 0 0" rpy="0 0 0" />
      <geometry>
        <mesh filename="../../components/hands/linkerhand_l6/variants/left/meshes/thumb_metacarpals_base1.STL" />
      </geometry>
      <material name="">
        <color rgba="0.796078431372549 0.823529411764706 0.937254901960784 1" />
      </material>
    </visual>
    <collision>
      <origin xyz="0 0 0" rpy="0 0 0" />
      <geometry>
        <mesh filename="../../components/hands/linkerhand_l6/variants/left/meshes/thumb_metacarpals_base1.STL" />
      </geometry>
    </collision>
  </link>
  <link name="hand_left_lh_thumb_metacarpals">
    <inertial>
      <origin xyz="0.00769270907 0.0859662185 0.0235283087" rpy="0 0 0" />
      <mass value="0.065" />
      <inertia ixx="8.407E-06" ixy="-1.1338E-09" ixz="1.1136E-08" iyy="8.3899E-06" iyz="3.1171E-07" izz="2.0091E-06" />
    </inertial>
    <visual>
      <origin xyz="0 0 0" rpy="0 0 0" />
      <geometry>
        <mesh filename="../../components/hands/linkerhand_l6/variants/left/meshes/thumb_metacarpals.STL" />
      </geometry>
      <material name="">
        <color rgba="0.796078431372549 0.823529411764706 0.937254901960784 1" />
      </material>
    </visual>
    <collision>
      <origin xyz="0 0 0" rpy="0 0 0" />
      <geometry>
        <mesh filename="../../components/hands/linkerhand_l6/variants/left/meshes/thumb_metacarpals.STL" />
      </geometry>
    </collision>
  </link>
  <link name="hand_left_lh_thumb_distal">
    <inertial>
      <origin xyz="0.00769270907 0.0798662185 -0.0591716913" rpy="0 0 0" />
      <mass value="0.018" />
      <inertia ixx="1.5546E-06" ixy="2.4423E-09" ixz="2.8147E-09" iyy="1.7108E-06" iyz="-7.2756E-08" izz="9.1709E-07" />
    </inertial>
    <visual>
      <origin xyz="0 0 0" rpy="0 0 0" />
      <geometry>
        <mesh filename="../../components/hands/linkerhand_l6/variants/left/meshes/thumb_distal.STL" />
      </geometry>
      <material name="">
        <color rgba="0.796078431372549 0.823529411764706 0.937254901960784 1" />
      </material>
    </visual>
    <collision>
      <origin xyz="0 0 0" rpy="0 0 0" />
      <geometry>
        <mesh filename="../../components/hands/linkerhand_l6/variants/left/meshes/thumb_distal.STL" />
      </geometry>
    </collision>
  </link>
  <link name="hand_left_lh_thumb_tip">
    <visual>
      <origin xyz="0 0 0" rpy="0 0 0" />
      <geometry>
        <box size="0.0001 0.0001 0.0001" />
      </geometry>
      <material name="hand_left_white" />
    </visual>
    <collision>
      <origin xyz="0 0 0" rpy="0 0 0" />
      <geometry>
        <box size="0.0001 0.0001 0.0001" />
      </geometry>
    </collision>
    <inertial>
      <origin xyz="0 0 0" rpy="0 0 0" />
      <mass value="1e-06" />
      <inertia ixx="1e-09" ixy="0" ixz="0" iyy="1e-09" iyz="0" izz="1e-09" />
    </inertial>
  </link>
  <link name="hand_left_lh_index_proximal">
    <inertial>
      <origin xyz="0.001776 -0.00011 0.012556" rpy="0 0 0" />
      <mass value="0.008553" />
      <inertia ixx="0.000000797543" ixy="-0.000000001275" ixz="0.000000138601" iyy="0.000000800499" iyz="0.000000000939" izz="0.000000357001" />
    </inertial>
    <visual>
      <origin xyz="0 0 0" rpy="0 0 0" />
      <geometry>
        <mesh filename="../../components/hands/linkerhand_l6/variants/left/meshes/index_proximal.STL" />
      </geometry>
      <material name="">
        <color rgba="0.796078431372549 0.823529411764706 0.937254901960784 1" />
      </material>
    </visual>
    <collision>
      <origin xyz="0 0 0" rpy="0 0 0" />
      <geometry>
        <mesh filename="../../components/hands/linkerhand_l6/variants/left/meshes/index_proximal.STL" />
      </geometry>
    </collision>
  </link>
  <link name="hand_left_lh_index_distal">
    <inertial>
      <origin xyz="0.0134 0.002262 0.016992" rpy="0 0 0" />
      <mass value="0.018408" />
      <inertia ixx="0.000002488712" ixy="0.000000008249" ixz="-0.000001523059" iyy="0.000003723754" iyz="0.000000014019" izz="0.000001813582" />
    </inertial>
    <visual>
      <origin xyz="0 0 0" rpy="0 0 0" />
      <geometry>
        <mesh filename="../../components/hands/linkerhand_l6/variants/left/meshes/index_distal.STL" />
      </geometry>
      <material name="">
        <color rgba="0.796078431372549 0.823529411764706 0.937254901960784 1" />
      </material>
    </visual>
    <collision>
      <origin xyz="0 0 0" rpy="0 0 0" />
      <geometry>
        <mesh filename="../../components/hands/linkerhand_l6/variants/left/meshes/index_distal.STL" />
      </geometry>
    </collision>
  </link>
  <link name="hand_left_lh_index_tip">
    <visual>
      <origin xyz="0 0 0" rpy="0 0 0" />
      <geometry>
        <box size="0.0001 0.0001 0.0001" />
      </geometry>
      <material name="hand_left_white" />
    </visual>
    <collision>
      <origin xyz="0 0 0" rpy="0 0 0" />
      <geometry>
        <box size="0.0001 0.0001 0.0001" />
      </geometry>
    </collision>
    <inertial>
      <origin xyz="0 0 0" rpy="0 0 0" />
      <mass value="1e-06" />
      <inertia ixx="1e-09" ixy="0" ixz="0" iyy="1e-09" iyz="0" izz="1e-09" />
    </inertial>
  </link>
  <link name="hand_left_lh_middle_proximal">
    <inertial>
      <origin xyz="0.001776 -0.00011 0.012556" rpy="0 0 0" />
      <mass value="0.008553" />
      <inertia ixx="0.000000797543" ixy="-0.000000001275" ixz="0.000000138601" iyy="0.000000800499" iyz="0.000000000939" izz="0.000000357001" />
    </inertial>
    <visual>
      <origin xyz="0 0 0" rpy="0 0 0" />
      <geometry>
        <mesh filename="../../components/hands/linkerhand_l6/variants/left/meshes/middle_proximal.STL" />
      </geometry>
      <material name="">
        <color rgba="0.796078431372549 0.823529411764706 0.937254901960784 1" />
      </material>
    </visual>
    <collision>
      <origin xyz="0 0 0" rpy="0 0 0" />
      <geometry>
        <mesh filename="../../components/hands/linkerhand_l6/variants/left/meshes/middle_proximal.STL" />
      </geometry>
    </collision>
  </link>
  <link name="hand_left_lh_middle_distal">
    <inertial>
      <origin xyz="0.0134 0.002262 0.016992" rpy="0 0 0" />
      <mass value="0.018408" />
      <inertia ixx="0.000002488712" ixy="0.000000008249" ixz="-0.000001523059" iyy="0.000003723754" iyz="0.000000014019" izz="0.000001813582" />
    </inertial>
    <visual>
      <origin xyz="0 0 0" rpy="0 0 0" />
      <geometry>
        <mesh filename="../../components/hands/linkerhand_l6/variants/left/meshes/middle_distal.STL" />
      </geometry>
      <material name="">
        <color rgba="0.796078431372549 0.823529411764706 0.937254901960784 1" />
      </material>
    </visual>
    <collision>
      <origin xyz="0 0 0" rpy="0 0 0" />
      <geometry>
        <mesh filename="../../components/hands/linkerhand_l6/variants/left/meshes/middle_distal.STL" />
      </geometry>
    </collision>
  </link>
  <link name="hand_left_lh_middle_tip">
    <visual>
      <origin xyz="0 0 0" rpy="0 0 0" />
      <geometry>
        <box size="0.0001 0.0001 0.0001" />
      </geometry>
      <material name="hand_left_white" />
    </visual>
    <collision>
      <origin xyz="0 0 0" rpy="0 0 0" />
      <geometry>
        <box size="0.0001 0.0001 0.0001" />
      </geometry>
    </collision>
    <inertial>
      <origin xyz="0 0 0" rpy="0 0 0" />
      <mass value="1e-06" />
      <inertia ixx="1e-09" ixy="0" ixz="0" iyy="1e-09" iyz="0" izz="1e-09" />
    </inertial>
  </link>
  <link name="hand_left_lh_ring_proximal">
    <inertial>
      <origin xyz="0.001776 -0.00011 0.012556" rpy="0 0 0" />
      <mass value="0.008553" />
      <inertia ixx="0.000000797543" ixy="-0.000000001275" ixz="0.000000138601" iyy="0.000000800499" iyz="0.000000000939" izz="0.000000357001" />
    </inertial>
    <visual>
      <origin xyz="0 0 0" rpy="0 0 0" />
      <geometry>
        <mesh filename="../../components/hands/linkerhand_l6/variants/left/meshes/ring_proximal.STL" />
      </geometry>
      <material name="">
        <color rgba="0.796078431372549 0.823529411764706 0.937254901960784 1" />
      </material>
    </visual>
    <collision>
      <origin xyz="0 0 0" rpy="0 0 0" />
      <geometry>
        <mesh filename="../../components/hands/linkerhand_l6/variants/left/meshes/ring_proximal.STL" />
      </geometry>
    </collision>
  </link>
  <link name="hand_left_lh_ring_distal">
    <inertial>
      <origin xyz="0.0134 0.002262 0.016992" rpy="0 0 0" />
      <mass value="0.018408" />
      <inertia ixx="0.000002488712" ixy="0.000000008249" ixz="-0.000001523059" iyy="0.000003723754" iyz="0.000000014019" izz="0.000001813582" />
    </inertial>
    <visual>
      <origin xyz="0 0 0" rpy="0 0 0" />
      <geometry>
        <mesh filename="../../components/hands/linkerhand_l6/variants/left/meshes/ring_distal.STL" />
      </geometry>
      <material name="">
        <color rgba="0.796078431372549 0.823529411764706 0.937254901960784 1" />
      </material>
    </visual>
    <collision>
      <origin xyz="0 0 0" rpy="0 0 0" />
      <geometry>
        <mesh filename="../../components/hands/linkerhand_l6/variants/left/meshes/ring_distal.STL" />
      </geometry>
    </collision>
  </link>
  <link name="hand_left_lh_ring_tip">
    <visual>
      <origin xyz="0 0 0" rpy="0 0 0" />
      <geometry>
        <box size="0.0001 0.0001 0.0001" />
      </geometry>
      <material name="hand_left_white" />
    </visual>
    <collision>
      <origin xyz="0 0 0" rpy="0 0 0" />
      <geometry>
        <box size="0.0001 0.0001 0.0001" />
      </geometry>
    </collision>
    <inertial>
      <origin xyz="0 0 0" rpy="0 0 0" />
      <mass value="1e-06" />
      <inertia ixx="1e-09" ixy="0" ixz="0" iyy="1e-09" iyz="0" izz="1e-09" />
    </inertial>
  </link>
  <link name="hand_left_lh_pinky_proximal">
    <inertial>
      <origin xyz="0.001776 -0.00011 0.012556" rpy="0 0 0" />
      <mass value="0.008553" />
      <inertia ixx="0.000000797543" ixy="-0.000000001275" ixz="0.000000138601" iyy="0.000000800499" iyz="0.000000000939" izz="0.000000357001" />
    </inertial>
    <visual>
      <origin xyz="0 0 0" rpy="0 0 0" />
      <geometry>
        <mesh filename="../../components/hands/linkerhand_l6/variants/left/meshes/pinky_proximal.STL" />
      </geometry>
      <material name="">
        <color rgba="0.796078431372549 0.823529411764706 0.937254901960784 1" />
      </material>
    </visual>
    <collision>
      <origin xyz="0 0 0" rpy="0 0 0" />
      <geometry>
        <mesh filename="../../components/hands/linkerhand_l6/variants/left/meshes/pinky_proximal.STL" />
      </geometry>
    </collision>
  </link>
  <link name="hand_left_lh_pinky_distal">
    <inertial>
      <origin xyz="0.0134 0.002262 0.016992" rpy="0 0 0" />
      <mass value="0.018408" />
      <inertia ixx="0.000002488712" ixy="0.000000008249" ixz="-0.000001523059" iyy="0.000003723754" iyz="0.000000014019" izz="0.000001813582" />
    </inertial>
    <visual>
      <origin xyz="0 0 0" rpy="0 0 0" />
      <geometry>
        <mesh filename="../../components/hands/linkerhand_l6/variants/left/meshes/pinky_distal.STL" />
      </geometry>
      <material name="">
        <color rgba="0.796078431372549 0.823529411764706 0.937254901960784 1" />
      </material>
    </visual>
    <collision>
      <origin xyz="0 0 0" rpy="0 0 0" />
      <geometry>
        <mesh filename="../../components/hands/linkerhand_l6/variants/left/meshes/pinky_distal.STL" />
      </geometry>
    </collision>
  </link>
  <link name="hand_left_lh_pinky_tip">
    <visual>
      <origin xyz="0 0 0" rpy="0 0 0" />
      <geometry>
        <box size="0.0001 0.0001 0.0001" />
      </geometry>
      <material name="hand_left_white" />
    </visual>
    <collision>
      <origin xyz="0 0 0" rpy="0 0 0" />
      <geometry>
        <box size="0.0001 0.0001 0.0001" />
      </geometry>
    </collision>
    <inertial>
      <origin xyz="0 0 0" rpy="0 0 0" />
      <mass value="1e-06" />
      <inertia ixx="1e-09" ixy="0" ixz="0" iyy="1e-09" iyz="0" izz="1e-09" />
    </inertial>
  </link>
  <link name="hand_right_rh_hand_base_link">
    <inertial>
      <origin xyz="0.00199 0.00091 0.058381" rpy="0 0 0" />
      <mass value="0.4185" />
      <inertia ixx="0.0004998" ixy="-1.2853e-05" ixz="-8.317e-06" iyy="0.0003567" iyz="-1.0354e-05" izz="0.0002301" />
    </inertial>
    <visual>
      <origin xyz="0 0 0" rpy="0 0 0" />
      <geometry>
        <mesh filename="../../components/hands/linkerhand_l6/variants/right/meshes/hand_base_link.STL" />
      </geometry>
      <material name="">
        <color rgba="0.796078431372549 0.823529411764706 0.937254901960784 1" />
      </material>
    </visual>
    <collision>
      <origin xyz="0 0 0" rpy="0 0 0" />
      <geometry>
        <mesh filename="../../components/hands/linkerhand_l6/variants/right/meshes/hand_base_link.STL" />
      </geometry>
    </collision>
  </link>
  <link name="hand_right_rh_thumb_metacarpals_base1">
    <inertial>
      <origin xyz="0.0018663 0.0066406 0.001533" rpy="0 0 0" />
      <mass value="0.01" />
      <inertia ixx="3.3724e-07" ixy="-1.11e-07" ixz="-3.6039e-08" iyy="2.9457e-07" iyz="-5.7181e-08" izz="4.903e-07" />
    </inertial>
    <visual>
      <origin xyz="0 0 0" rpy="0 0 0" />
      <geometry>
        <mesh filename="../../components/hands/linkerhand_l6/variants/right/meshes/thumb_metacarpals_base1.STL" />
      </geometry>
      <material name="">
        <color rgba="0.796078431372549 0.823529411764706 0.937254901960784 1" />
      </material>
    </visual>
    <collision>
      <origin xyz="0 0 0" rpy="0 0 0" />
      <geometry>
        <mesh filename="../../components/hands/linkerhand_l6/variants/right/meshes/thumb_metacarpals_base1.STL" />
      </geometry>
    </collision>
  </link>
  <link name="hand_right_rh_thumb_metacarpals">
    <inertial>
      <origin xyz="0.0076927091 -0.0859662185 0.0235283087" rpy="0 0 0" />
      <mass value="0.065" />
      <inertia ixx="8.407e-06" ixy="1.1338e-09" ixz="1.1136e-08" iyy="8.3899e-06" iyz="-3.1171e-07" izz="2.0091e-06" />
    </inertial>
    <visual>
      <origin xyz="0 0 0" rpy="0 0 0" />
      <geometry>
        <mesh filename="../../components/hands/linkerhand_l6/variants/right/meshes/thumb_metacarpals.STL" />
      </geometry>
      <material name="">
        <color rgba="0.796078431372549 0.823529411764706 0.937254901960784 1" />
      </material>
    </visual>
    <collision>
      <origin xyz="0 0 0" rpy="0 0 0" />
      <geometry>
        <mesh filename="../../components/hands/linkerhand_l6/variants/right/meshes/thumb_metacarpals.STL" />
      </geometry>
    </collision>
  </link>
  <link name="hand_right_rh_thumb_distal">
    <inertial>
      <origin xyz="0.0076927091 -0.0798662185 -0.0591716913" rpy="0 0 0" />
      <mass value="0.018" />
      <inertia ixx="1.5546e-06" ixy="-2.4423e-09" ixz="2.8147e-09" iyy="1.7108e-06" iyz="7.2756e-08" izz="9.1709e-07" />
    </inertial>
    <visual>
      <origin xyz="0 0 0" rpy="0 0 0" />
      <geometry>
        <mesh filename="../../components/hands/linkerhand_l6/variants/right/meshes/thumb_distal.STL" />
      </geometry>
      <material name="">
        <color rgba="0.796078431372549 0.823529411764706 0.937254901960784 1" />
      </material>
    </visual>
    <collision>
      <origin xyz="0 0 0" rpy="0 0 0" />
      <geometry>
        <mesh filename="../../components/hands/linkerhand_l6/variants/right/meshes/thumb_distal.STL" />
      </geometry>
    </collision>
  </link>
  <link name="hand_right_rh_thumb_tip">
    <visual>
      <origin xyz="0 0 0" rpy="0 0 0" />
      <geometry>
        <box size="0.0001 0.0001 0.0001" />
      </geometry>
      <material name="hand_right_white" />
    </visual>
    <collision>
      <origin xyz="0 0 0" rpy="0 0 0" />
      <geometry>
        <box size="0.0001 0.0001 0.0001" />
      </geometry>
    </collision>
    <inertial>
      <origin xyz="0 0 0" rpy="0 0 0" />
      <mass value="1e-06" />
      <inertia ixx="1e-09" ixy="0" ixz="0" iyy="1e-09" iyz="0" izz="1e-09" />
    </inertial>
  </link>
  <link name="hand_right_rh_index_proximal">
    <inertial>
      <origin xyz="0.001776 0.00011 0.012556" rpy="0 0 0" />
      <mass value="0.008553" />
      <inertia ixx="7.97543e-07" ixy="1.275e-09" ixz="1.38601e-07" iyy="8.00499e-07" iyz="-9.39e-10" izz="3.57001e-07" />
    </inertial>
    <visual>
      <origin xyz="0 0 0" rpy="0 0 0" />
      <geometry>
        <mesh filename="../../components/hands/linkerhand_l6/variants/right/meshes/index_proximal.STL" />
      </geometry>
      <material name="">
        <color rgba="0.796078431372549 0.823529411764706 0.937254901960784 1" />
      </material>
    </visual>
    <collision>
      <origin xyz="0 0 0" rpy="0 0 0" />
      <geometry>
        <mesh filename="../../components/hands/linkerhand_l6/variants/right/meshes/index_proximal.STL" />
      </geometry>
    </collision>
  </link>
  <link name="hand_right_rh_index_distal">
    <inertial>
      <origin xyz="0.0134 -0.002262 0.016992" rpy="0 0 0" />
      <mass value="0.018408" />
      <inertia ixx="2.488712e-06" ixy="-8.249e-09" ixz="-1.523059e-06" iyy="3.723754e-06" iyz="-1.4019e-08" izz="1.813582e-06" />
    </inertial>
    <visual>
      <origin xyz="0 0 0" rpy="0 0 0" />
      <geometry>
        <mesh filename="../../components/hands/linkerhand_l6/variants/right/meshes/index_distal.STL" />
      </geometry>
      <material name="">
        <color rgba="0.796078431372549 0.823529411764706 0.937254901960784 1" />
      </material>
    </visual>
    <collision>
      <origin xyz="0 0 0" rpy="0 0 0" />
      <geometry>
        <mesh filename="../../components/hands/linkerhand_l6/variants/right/meshes/index_distal.STL" />
      </geometry>
    </collision>
  </link>
  <link name="hand_right_rh_index_tip">
    <visual>
      <origin xyz="0 0 0" rpy="0 0 0" />
      <geometry>
        <box size="0.0001 0.0001 0.0001" />
      </geometry>
      <material name="hand_right_white" />
    </visual>
    <collision>
      <origin xyz="0 0 0" rpy="0 0 0" />
      <geometry>
        <box size="0.0001 0.0001 0.0001" />
      </geometry>
    </collision>
    <inertial>
      <origin xyz="0 0 0" rpy="0 0 0" />
      <mass value="1e-06" />
      <inertia ixx="1e-09" ixy="0" ixz="0" iyy="1e-09" iyz="0" izz="1e-09" />
    </inertial>
  </link>
  <link name="hand_right_rh_middle_proximal">
    <inertial>
      <origin xyz="0.001776 0.00011 0.012556" rpy="0 0 0" />
      <mass value="0.008553" />
      <inertia ixx="7.97543e-07" ixy="1.275e-09" ixz="1.38601e-07" iyy="8.00499e-07" iyz="-9.39e-10" izz="3.57001e-07" />
    </inertial>
    <visual>
      <origin xyz="0 0 0" rpy="0 0 0" />
      <geometry>
        <mesh filename="../../components/hands/linkerhand_l6/variants/right/meshes/middle_proximal.STL" />
      </geometry>
      <material name="">
        <color rgba="0.796078431372549 0.823529411764706 0.937254901960784 1" />
      </material>
    </visual>
    <collision>
      <origin xyz="0 0 0" rpy="0 0 0" />
      <geometry>
        <mesh filename="../../components/hands/linkerhand_l6/variants/right/meshes/middle_proximal.STL" />
      </geometry>
    </collision>
  </link>
  <link name="hand_right_rh_middle_distal">
    <inertial>
      <origin xyz="0.0134 -0.002262 0.016992" rpy="0 0 0" />
      <mass value="0.018408" />
      <inertia ixx="2.488712e-06" ixy="-8.249e-09" ixz="-1.523059e-06" iyy="3.723754e-06" iyz="-1.4019e-08" izz="1.813582e-06" />
    </inertial>
    <visual>
      <origin xyz="0 0 0" rpy="0 0 0" />
      <geometry>
        <mesh filename="../../components/hands/linkerhand_l6/variants/right/meshes/middle_distal.STL" />
      </geometry>
      <material name="">
        <color rgba="0.796078431372549 0.823529411764706 0.937254901960784 1" />
      </material>
    </visual>
    <collision>
      <origin xyz="0 0 0" rpy="0 0 0" />
      <geometry>
        <mesh filename="../../components/hands/linkerhand_l6/variants/right/meshes/middle_distal.STL" />
      </geometry>
    </collision>
  </link>
  <link name="hand_right_rh_middle_tip">
    <visual>
      <origin xyz="0 0 0" rpy="0 0 0" />
      <geometry>
        <box size="0.0001 0.0001 0.0001" />
      </geometry>
      <material name="hand_right_white" />
    </visual>
    <collision>
      <origin xyz="0 0 0" rpy="0 0 0" />
      <geometry>
        <box size="0.0001 0.0001 0.0001" />
      </geometry>
    </collision>
    <inertial>
      <origin xyz="0 0 0" rpy="0 0 0" />
      <mass value="1e-06" />
      <inertia ixx="1e-09" ixy="0" ixz="0" iyy="1e-09" iyz="0" izz="1e-09" />
    </inertial>
  </link>
  <link name="hand_right_rh_ring_proximal">
    <inertial>
      <origin xyz="0.001776 0.00011 0.012556" rpy="0 0 0" />
      <mass value="0.008553" />
      <inertia ixx="7.97543e-07" ixy="1.275e-09" ixz="1.38601e-07" iyy="8.00499e-07" iyz="-9.39e-10" izz="3.57001e-07" />
    </inertial>
    <visual>
      <origin xyz="0 0 0" rpy="0 0 0" />
      <geometry>
        <mesh filename="../../components/hands/linkerhand_l6/variants/right/meshes/ring_proximal.STL" />
      </geometry>
      <material name="">
        <color rgba="0.796078431372549 0.823529411764706 0.937254901960784 1" />
      </material>
    </visual>
    <collision>
      <origin xyz="0 0 0" rpy="0 0 0" />
      <geometry>
        <mesh filename="../../components/hands/linkerhand_l6/variants/right/meshes/ring_proximal.STL" />
      </geometry>
    </collision>
  </link>
  <link name="hand_right_rh_ring_distal">
    <inertial>
      <origin xyz="0.0134 -0.002262 0.016992" rpy="0 0 0" />
      <mass value="0.018408" />
      <inertia ixx="2.488712e-06" ixy="-8.249e-09" ixz="-1.523059e-06" iyy="3.723754e-06" iyz="-1.4019e-08" izz="1.813582e-06" />
    </inertial>
    <visual>
      <origin xyz="0 0 0" rpy="0 0 0" />
      <geometry>
        <mesh filename="../../components/hands/linkerhand_l6/variants/right/meshes/ring_distal.STL" />
      </geometry>
      <material name="">
        <color rgba="0.796078431372549 0.823529411764706 0.937254901960784 1" />
      </material>
    </visual>
    <collision>
      <origin xyz="0 0 0" rpy="0 0 0" />
      <geometry>
        <mesh filename="../../components/hands/linkerhand_l6/variants/right/meshes/ring_distal.STL" />
      </geometry>
    </collision>
  </link>
  <link name="hand_right_rh_ring_tip">
    <visual>
      <origin xyz="0 0 0" rpy="0 0 0" />
      <geometry>
        <box size="0.0001 0.0001 0.0001" />
      </geometry>
      <material name="hand_right_white" />
    </visual>
    <collision>
      <origin xyz="0 0 0" rpy="0 0 0" />
      <geometry>
        <box size="0.0001 0.0001 0.0001" />
      </geometry>
    </collision>
    <inertial>
      <origin xyz="0 0 0" rpy="0 0 0" />
      <mass value="1e-06" />
      <inertia ixx="1e-09" ixy="0" ixz="0" iyy="1e-09" iyz="0" izz="1e-09" />
    </inertial>
  </link>
  <link name="hand_right_rh_pinky_proximal">
    <inertial>
      <origin xyz="0.001776 0.00011 0.012556" rpy="0 0 0" />
      <mass value="0.008553" />
      <inertia ixx="7.97543e-07" ixy="1.275e-09" ixz="1.38601e-07" iyy="8.00499e-07" iyz="-9.39e-10" izz="3.57001e-07" />
    </inertial>
    <visual>
      <origin xyz="0 0 0" rpy="0 0 0" />
      <geometry>
        <mesh filename="../../components/hands/linkerhand_l6/variants/right/meshes/pinky_proximal.STL" />
      </geometry>
      <material name="">
        <color rgba="0.796078431372549 0.823529411764706 0.937254901960784 1" />
      </material>
    </visual>
    <collision>
      <origin xyz="0 0 0" rpy="0 0 0" />
      <geometry>
        <mesh filename="../../components/hands/linkerhand_l6/variants/right/meshes/pinky_proximal.STL" />
      </geometry>
    </collision>
  </link>
  <link name="hand_right_rh_pinky_distal">
    <inertial>
      <origin xyz="0.0134 -0.002262 0.016992" rpy="0 0 0" />
      <mass value="0.018408" />
      <inertia ixx="2.488712e-06" ixy="-8.249e-09" ixz="-1.523059e-06" iyy="3.723754e-06" iyz="-1.4019e-08" izz="1.813582e-06" />
    </inertial>
    <visual>
      <origin xyz="0 0 0" rpy="0 0 0" />
      <geometry>
        <mesh filename="../../components/hands/linkerhand_l6/variants/right/meshes/pinky_distal.STL" />
      </geometry>
      <material name="">
        <color rgba="0.796078431372549 0.823529411764706 0.937254901960784 1" />
      </material>
    </visual>
    <collision>
      <origin xyz="0 0 0" rpy="0 0 0" />
      <geometry>
        <mesh filename="../../components/hands/linkerhand_l6/variants/right/meshes/pinky_distal.STL" />
      </geometry>
    </collision>
  </link>
  <link name="hand_right_rh_pinky_tip">
    <visual>
      <origin xyz="0 0 0" rpy="0 0 0" />
      <geometry>
        <box size="0.0001 0.0001 0.0001" />
      </geometry>
      <material name="hand_right_white" />
    </visual>
    <collision>
      <origin xyz="0 0 0" rpy="0 0 0" />
      <geometry>
        <box size="0.0001 0.0001 0.0001" />
      </geometry>
    </collision>
    <inertial>
      <origin xyz="0 0 0" rpy="0 0 0" />
      <mass value="1e-06" />
      <inertia ixx="1e-09" ixy="0" ixz="0" iyy="1e-09" iyz="0" izz="1e-09" />
    </inertial>
  </link>
  <joint name="base_torso_stand" type="fixed">
    <origin xyz="0 0 1.2" rpy="0 0 0" />
    <parent link="base_torso_root" />
    <child link="base_base_link" />
  </joint>
  <joint name="base_weld_arm_left_mount" type="fixed">
    <origin xyz="0 0.164 0" rpy="0 0 0" />
    <parent link="base_base_link" />
    <child link="base_arm_left_mount" />
  </joint>
  <joint name="base_weld_arm_right_mount" type="fixed">
    <origin xyz="3.32e-05 -0.164 0" rpy="0 0 0" />
    <parent link="base_base_link" />
    <child link="base_arm_right_mount" />
  </joint>
  <joint name="arm_left_L1_Joint" type="revolute">
    <origin xyz="0 0 0" rpy="0 0 0" />
    <parent link="arm_left_L_arm_root" />
    <child link="arm_left_L1_Link" />
    <axis xyz="0 -1 0" />
    <limit lower="-2.91" upper="2.91" effort="80" velocity="10.47" />
  </joint>
  <joint name="arm_left_L2_Joint" type="revolute">
    <origin xyz="0 0.058 0" rpy="0 0 0" />
    <parent link="arm_left_L1_Link" />
    <child link="arm_left_L2_Link" />
    <axis xyz="-1 0 0" />
    <limit lower="-3.2" upper="0.07" effort="80" velocity="10.47" />
  </joint>
  <joint name="arm_left_L3_Joint" type="revolute">
    <origin xyz="-2.5018e-05 0 -0.123" rpy="0 0 0" />
    <parent link="arm_left_L2_Link" />
    <child link="arm_left_L3_Link" />
    <axis xyz="0 0 1" />
    <limit lower="-2.69" upper="2.69" effort="36" velocity="9.1" />
  </joint>
  <joint name="arm_left_L4_Joint" type="revolute">
    <origin xyz="2.4267e-05 0 -0.1621" rpy="0 0 0" />
    <parent link="arm_left_L3_Link" />
    <child link="arm_left_L4_Link" />
    <axis xyz="0 -1 0" />
    <limit lower="-2.05" upper="2.05" effort="36" velocity="9.1" />
  </joint>
  <joint name="arm_left_L5_Joint" type="revolute">
    <origin xyz="0 0 -0.124" rpy="0 0 0" />
    <parent link="arm_left_L4_Link" />
    <child link="arm_left_L5_Link" />
    <axis xyz="0 0 1" />
    <limit lower="-2.69" upper="2.69" effort="36" velocity="9.1" />
  </joint>
  <joint name="arm_left_L6_Joint" type="revolute">
    <origin xyz="0 0 -0.0881" rpy="0 0 0" />
    <parent link="arm_left_L5_Link" />
    <child link="arm_left_L6_Link" />
    <axis xyz="0 -1 0" />
    <limit lower="-1.59" upper="1.59" effort="18" velocity="7.33" />
  </joint>
  <joint name="arm_left_L7_Joint" type="revolute">
    <origin xyz="-2.6563e-05 0 -0.0655" rpy="0 0 0" />
    <parent link="arm_left_L6_Link" />
    <child link="arm_left_L7_Link" />
    <axis xyz="-1 0 0" />
    <limit lower="-1.59" upper="1.59" effort="18" velocity="7.33" />
  </joint>
  <joint name="arm_left_L8_Joint" type="fixed">
    <origin xyz="2.5732e-05 0 -0.0455" rpy="0 0 0" />
    <parent link="arm_left_L7_Link" />
    <child link="arm_left_L8_Link" />
    <axis xyz="0 0 0" />
  </joint>
  <joint name="arm_right_R1_Joint" type="revolute">
    <origin xyz="0 0 0" rpy="0 0 0" />
    <parent link="arm_right_R_arm_root" />
    <child link="arm_right_R1_Link" />
    <axis xyz="0 1 0" />
    <limit lower="-2.91" upper="2.91" effort="80" velocity="10.47" />
  </joint>
  <joint name="arm_right_R2_Joint" type="revolute">
    <origin xyz="-3.32e-05 -0.058001 0" rpy="0 0 0" />
    <parent link="arm_right_R1_Link" />
    <child link="arm_right_R2_Link" />
    <axis xyz="-1 0 0" />
    <limit lower="-0.07" upper="3.2" effort="80" velocity="10.47" />
  </joint>
  <joint name="arm_right_R3_Joint" type="revolute">
    <origin xyz="2.5018e-05 0 -0.123" rpy="0 0 0" />
    <parent link="arm_right_R2_Link" />
    <child link="arm_right_R3_Link" />
    <axis xyz="0 0 1" />
    <limit lower="-2.69" upper="2.69" effort="36" velocity="9.1" />
  </joint>
  <joint name="arm_right_R4_Joint" type="revolute">
    <origin xyz="-2.5308e-05 0 -0.1621" rpy="0 0 0" />
    <parent link="arm_right_R3_Link" />
    <child link="arm_right_R4_Link" />
    <axis xyz="0 1 0" />
    <limit lower="-2.05" upper="2.05" effort="36" velocity="9.1" />
  </joint>
  <joint name="arm_right_R5_Joint" type="revolute">
    <origin xyz="0 0 -0.124" rpy="0 0 0" />
    <parent link="arm_right_R4_Link" />
    <child link="arm_right_R5_Link" />
    <axis xyz="0 0 1" />
    <limit lower="-2.69" upper="2.69" effort="36" velocity="9.1" />
  </joint>
  <joint name="arm_right_R6_Joint" type="revolute">
    <origin xyz="0 0 -0.0881" rpy="0 0 0" />
    <parent link="arm_right_R5_Link" />
    <child link="arm_right_R6_Link" />
    <axis xyz="0 1 0" />
    <limit lower="-1.59" upper="1.59" effort="18" velocity="7.33" />
  </joint>
  <joint name="arm_right_R7_Joint" type="revolute">
    <origin xyz="2.5631e-05 0 -0.0655" rpy="0 0 0" />
    <parent link="arm_right_R6_Link" />
    <child link="arm_right_R7_Link" />
    <axis xyz="-1 0 0" />
    <limit lower="-1.59" upper="1.59" effort="18" velocity="7.33" />
  </joint>
  <joint name="arm_right_R8_Joint" type="fixed">
    <origin xyz="-2.5732e-05 0 -0.0455" rpy="0 0 0" />
    <parent link="arm_right_R7_Link" />
    <child link="arm_right_R8_Link" />
    <axis xyz="0 0 0" />
  </joint>
  <joint name="hand_left_lh_thumb_cmc_roll" type="revolute">
    <origin xyz="0.0078133 -0.029898 0.026692" rpy="-0.034907 0 0" />
    <parent link="hand_left_lh_hand_base_link" />
    <child link="hand_left_lh_thumb_metacarpals_base1" />
    <axis xyz="0 0 1" />
    <limit lower="-0.087266" upper="1.256637" effort="0.588" velocity="5.95" />
    <dynamics damping="0.02" friction="0.05416667" />
  </joint>
  <joint name="hand_left_lh_thumb_cmc_pitch" type="revolute">
    <origin xyz="0.0057298 -0.01332 0.0027456" rpy="1.1083 0 0.40143" />
    <parent link="hand_left_lh_thumb_metacarpals_base1" />
    <child link="hand_left_lh_thumb_metacarpals" />
    <axis xyz="-1 0 0" />
    <limit lower="0" upper="0.837758" effort="1.008" velocity="3.47" />
    <dynamics damping="0.02" friction="0.0375" />
  </joint>
  <joint name="hand_left_lh_thumb_tip_fixed" type="fixed">
    <origin xyz="0 0.0035 0.026" rpy="0 0 1.5708" />
    <parent link="hand_left_lh_thumb_distal" />
    <child link="hand_left_lh_thumb_tip" />
  </joint>
  <joint name="hand_left_lh_thumb_dip" type="revolute">
    <origin xyz="0 0.0061 0.0827" rpy="0 0 0" />
    <parent link="hand_left_lh_thumb_metacarpals" />
    <child link="hand_left_lh_thumb_distal" />
    <axis xyz="-1 0 0" />
    <limit lower="0" upper="0.963287" effort="0" velocity="1.7" />
    <mimic joint="hand_left_lh_thumb_cmc_pitch" multiplier="1.226495" offset="0" />
  </joint>
  <joint name="hand_left_lh_index_mcp_pitch" type="revolute">
    <origin xyz="-0.00066821 -0.028967 0.11722" rpy="0 0 0" />
    <parent link="hand_left_lh_hand_base_link" />
    <child link="hand_left_lh_index_proximal" />
    <axis xyz="0 1 0" />
    <limit lower="0" upper="1.134464" effort="0.574" velocity="6.10" />
    <dynamics damping="0.01" friction="0.04" />
  </joint>
  <joint name="hand_left_lh_index_tip_fixed" type="fixed">
    <origin xyz="0.0341 0 0.034" rpy="0 0 0" />
    <parent link="hand_left_lh_index_distal" />
    <child link="hand_left_lh_index_tip" />
  </joint>
  <joint name="hand_left_lh_index_dip" type="revolute">
    <origin xyz="0.00093749 0 0.028002" rpy="0 0 0" />
    <parent link="hand_left_lh_index_proximal" />
    <child link="hand_left_lh_index_distal" />
    <axis xyz="0 1 0" />
    <limit lower="0" upper="1.277039" effort="0" velocity="3.1" />
    <mimic joint="hand_left_lh_index_mcp_pitch" multiplier="1.125676" offset="0" />
  </joint>
  <joint name="hand_left_lh_middle_mcp_pitch" type="revolute">
    <origin xyz="-0.00066821 -0.0089013 0.12322" rpy="0 0 0" />
    <parent link="hand_left_lh_hand_base_link" />
    <child link="hand_left_lh_middle_proximal" />
    <axis xyz="0 1 0" />
    <limit lower="0" upper="1.134464" effort="0.574" velocity="6.10" />
    <dynamics damping="0.01" friction="0.02708333" />
  </joint>
  <joint name="hand_left_lh_middle_tip_fixed" type="fixed">
    <origin xyz="0.0341 0 0.034" rpy="0 0 0" />
    <parent link="hand_left_lh_middle_distal" />
    <child link="hand_left_lh_middle_tip" />
  </joint>
  <joint name="hand_left_lh_middle_dip" type="revolute">
    <origin xyz="0.00093749 0 0.028002" rpy="0 0 0" />
    <parent link="hand_left_lh_middle_proximal" />
    <child link="hand_left_lh_middle_distal" />
    <axis xyz="0 1 0" />
    <limit lower="0" upper="1.277039" effort="0" velocity="3.1" />
    <mimic joint="hand_left_lh_middle_mcp_pitch" multiplier="1.125676" offset="0" />
  </joint>
  <joint name="hand_left_lh_ring_mcp_pitch" type="revolute">
    <origin xyz="-0.00067368 0.010717 0.11822" rpy="0 0 0" />
    <parent link="hand_left_lh_hand_base_link" />
    <child link="hand_left_lh_ring_proximal" />
    <axis xyz="0 1 0" />
    <limit lower="0" upper="1.134464" effort="0.574" velocity="6.10" />
    <dynamics damping="0.01" friction="0.02291667" />
  </joint>
  <joint name="hand_left_lh_ring_tip_fixed" type="fixed">
    <origin xyz="0.0341 0 0.034" rpy="0 0 0" />
    <parent link="hand_left_lh_ring_distal" />
    <child link="hand_left_lh_ring_tip" />
  </joint>
  <joint name="hand_left_lh_ring_dip" type="revolute">
    <origin xyz="0.00093749 0 0.028002" rpy="0 0 0" />
    <parent link="hand_left_lh_ring_proximal" />
    <child link="hand_left_lh_ring_distal" />
    <axis xyz="0 1 0" />
    <limit lower="0" upper="1.277039" effort="0" velocity="3.1" />
    <mimic joint="hand_left_lh_ring_mcp_pitch" multiplier="1.125676" offset="0" />
  </joint>
  <joint name="hand_left_lh_pinky_mcp_pitch" type="revolute">
    <origin xyz="-0.00067852 0.029814 0.11424" rpy="0 0 0" />
    <parent link="hand_left_lh_hand_base_link" />
    <child link="hand_left_lh_pinky_proximal" />
    <axis xyz="0 1 0" />
    <limit lower="0" upper="1.134464" effort="0.574" velocity="6.10" />
    <dynamics damping="0.01" friction="0.01" />
  </joint>
  <joint name="hand_left_lh_pinky_tip_fixed" type="fixed">
    <origin xyz="0.0341 0 0.034" rpy="0 0 0" />
    <parent link="hand_left_lh_pinky_distal" />
    <child link="hand_left_lh_pinky_tip" />
  </joint>
  <joint name="hand_left_lh_pinky_dip" type="revolute">
    <origin xyz="0.00093749 0 0.028002" rpy="0 0 0" />
    <parent link="hand_left_lh_pinky_proximal" />
    <child link="hand_left_lh_pinky_distal" />
    <axis xyz="0 1 0" />
    <limit lower="0" upper="1.277039" effort="0" velocity="3.1" />
    <mimic joint="hand_left_lh_pinky_mcp_pitch" multiplier="1.125676" offset="0" />
  </joint>
  <joint name="hand_right_rh_thumb_cmc_roll" type="revolute">
    <origin xyz="0.0078133 0.030812 0.025678" rpy="-0.034907 0 0" />
    <parent link="hand_right_rh_hand_base_link" />
    <child link="hand_right_rh_thumb_metacarpals_base1" />
    <axis xyz="0 0.034899 -0.99939" />
    <limit lower="-0.087266" upper="1.256637" effort="0.588" velocity="5.95" />
    <dynamics damping="0.02" friction="0.05416667" />
  </joint>
  <joint name="hand_right_rh_thumb_cmc_pitch" type="revolute">
    <origin xyz="0.0054997 0.013314 0.0032166" rpy="-1.0762 0.013637 -0.40121" />
    <parent link="hand_right_rh_thumb_metacarpals_base1" />
    <child link="hand_right_rh_thumb_metacarpals" />
    <axis xyz="1 0 0" />
    <limit lower="0" upper="0.837758" effort="1.008" velocity="3.47" />
    <dynamics damping="0.02" friction="0.0375" />
  </joint>
  <joint name="hand_right_rh_thumb_tip_fixed" type="fixed">
    <origin xyz="0 -0.0035 0.026" rpy="0 0 -1.5708" />
    <parent link="hand_right_rh_thumb_distal" />
    <child link="hand_right_rh_thumb_tip" />
  </joint>
  <joint name="hand_right_rh_thumb_dip" type="revolute">
    <origin xyz="0 -0.0061 0.0827" rpy="0 0 0" />
    <parent link="hand_right_rh_thumb_metacarpals" />
    <child link="hand_right_rh_thumb_distal" />
    <axis xyz="1 0 0" />
    <limit lower="0" upper="0.963287" effort="0" velocity="1.7" />
    <mimic joint="hand_right_rh_thumb_cmc_pitch" multiplier="1.226495" offset="0" />
  </joint>
  <joint name="hand_right_rh_index_mcp_pitch" type="revolute">
    <origin xyz="-0.00066821 0.033467 0.11622" rpy="-0.087266 0 0" />
    <parent link="hand_right_rh_hand_base_link" />
    <child link="hand_right_rh_index_proximal" />
    <axis xyz="0 1 0" />
    <limit lower="0" upper="1.134464" effort="0.574" velocity="6.10" />
    <dynamics damping="0.01" friction="0.04" />
  </joint>
  <joint name="hand_right_rh_index_tip_fixed" type="fixed">
    <origin xyz="0.0341 0 0.034" rpy="0 0 0" />
    <parent link="hand_right_rh_index_distal" />
    <child link="hand_right_rh_index_tip" />
  </joint>
  <joint name="hand_right_rh_index_dip" type="revolute">
    <origin xyz="0.0009359 0 0.028002" rpy="0 0 0" />
    <parent link="hand_right_rh_index_proximal" />
    <child link="hand_right_rh_index_distal" />
    <axis xyz="0 1 0" />
    <limit lower="0" upper="1.277039" effort="0" velocity="3.1" />
    <mimic joint="hand_right_rh_index_mcp_pitch" multiplier="1.125676" offset="0" />
  </joint>
  <joint name="hand_right_rh_middle_mcp_pitch" type="revolute">
    <origin xyz="-0.00066821 0.0134013 0.12272" rpy="-0.034907 0 0" />
    <parent link="hand_right_rh_hand_base_link" />
    <child link="hand_right_rh_middle_proximal" />
    <axis xyz="0 1 0" />
    <limit lower="0" upper="1.134464" effort="0.574" velocity="6.10" />
    <dynamics damping="0.01" friction="0.02708333" />
  </joint>
  <joint name="hand_right_rh_middle_tip_fixed" type="fixed">
    <origin xyz="0.0341 0 0.034" rpy="0 0 0" />
    <parent link="hand_right_rh_middle_distal" />
    <child link="hand_right_rh_middle_tip" />
  </joint>
  <joint name="hand_right_rh_middle_dip" type="revolute">
    <origin xyz="0.0009359 0 0.028002" rpy="0 0 0" />
    <parent link="hand_right_rh_middle_proximal" />
    <child link="hand_right_rh_middle_distal" />
    <axis xyz="0 1 0" />
    <limit lower="0" upper="1.277039" effort="0" velocity="3.1" />
    <mimic joint="hand_right_rh_middle_mcp_pitch" multiplier="1.125676" offset="0" />
  </joint>
  <joint name="hand_right_rh_ring_mcp_pitch" type="revolute">
    <origin xyz="-0.00067368 -0.006217 0.11872" rpy="0.017453 0 0" />
    <parent link="hand_right_rh_hand_base_link" />
    <child link="hand_right_rh_ring_proximal" />
    <axis xyz="0 1 0" />
    <limit lower="0" upper="1.134464" effort="0.574" velocity="6.10" />
    <dynamics damping="0.01" friction="0.02291667" />
  </joint>
  <joint name="hand_right_rh_ring_tip_fixed" type="fixed">
    <origin xyz="0.0341 0 0.034" rpy="0 0 0" />
    <parent link="hand_right_rh_ring_distal" />
    <child link="hand_right_rh_ring_tip" />
  </joint>
  <joint name="hand_right_rh_ring_dip" type="revolute">
    <origin xyz="0.0009359 0 0.028002" rpy="0 0 0" />
    <parent link="hand_right_rh_ring_proximal" />
    <child link="hand_right_rh_ring_distal" />
    <axis xyz="0 1 0" />
    <limit lower="0" upper="1.277039" effort="0" velocity="3.1" />
    <mimic joint="hand_right_rh_ring_mcp_pitch" multiplier="1.125676" offset="0" />
  </joint>
  <joint name="hand_right_rh_pinky_mcp_pitch" type="revolute">
    <origin xyz="-0.00067852 -0.025314 0.11474" rpy="0.05236 0 0" />
    <parent link="hand_right_rh_hand_base_link" />
    <child link="hand_right_rh_pinky_proximal" />
    <axis xyz="0 1 0" />
    <limit lower="0" upper="1.134464" effort="0.574" velocity="6.10" />
    <dynamics damping="0.01" friction="0.01" />
  </joint>
  <joint name="hand_right_rh_pinky_tip_fixed" type="fixed">
    <origin xyz="0.0341 0 0.034" rpy="0 0 0" />
    <parent link="hand_right_rh_pinky_distal" />
    <child link="hand_right_rh_pinky_tip" />
  </joint>
  <joint name="hand_right_rh_pinky_dip" type="revolute">
    <origin xyz="0.0009359 0 0.028002" rpy="0 0 0" />
    <parent link="hand_right_rh_pinky_proximal" />
    <child link="hand_right_rh_pinky_distal" />
    <axis xyz="0 1 0" />
    <limit lower="0" upper="1.277039" effort="0" velocity="3.1" />
    <mimic joint="hand_right_rh_pinky_mcp_pitch" multiplier="1.125676" offset="0" />
  </joint>
  <transmission name="hand_left_trans_thumb_cmc_roll">
    <type>transmission_interface/SimpleTransmission</type>
    <joint name="hand_left_lh_thumb_cmc_roll">
      <hardwareInterface>hardware_interface/EffortJointInterface</hardwareInterface>
    </joint>
    <actuator name="motor_thumb_cmc_roll">
      <hardwareInterface>hardware_interface/EffortJointInterface</hardwareInterface>
      <mechanicalReduction>0.0084</mechanicalReduction>
    </actuator>
  </transmission>
  <transmission name="hand_left_trans_index_mcp_pitch">
    <type>transmission_interface/SimpleTransmission</type>
    <joint name="hand_left_lh_index_mcp_pitch">
      <hardwareInterface>hardware_interface/EffortJointInterface</hardwareInterface>
    </joint>
    <actuator name="motor_index_mcp_pitch">
      <hardwareInterface>hardware_interface/EffortJointInterface</hardwareInterface>
      <mechanicalReduction>0.0082</mechanicalReduction>
    </actuator>
  </transmission>
  <transmission name="hand_left_trans_middle_mcp_pitch">
    <type>transmission_interface/SimpleTransmission</type>
    <joint name="hand_left_lh_middle_mcp_pitch">
      <hardwareInterface>hardware_interface/EffortJointInterface</hardwareInterface>
    </joint>
    <actuator name="motor_middle_mcp_pitch">
      <hardwareInterface>hardware_interface/EffortJointInterface</hardwareInterface>
      <mechanicalReduction>0.0082</mechanicalReduction>
    </actuator>
  </transmission>
  <transmission name="hand_left_trans_ring_mcp_pitch">
    <type>transmission_interface/SimpleTransmission</type>
    <joint name="hand_left_lh_ring_mcp_pitch">
      <hardwareInterface>hardware_interface/EffortJointInterface</hardwareInterface>
    </joint>
    <actuator name="motor_ring_mcp_pitch">
      <hardwareInterface>hardware_interface/EffortJointInterface</hardwareInterface>
      <mechanicalReduction>0.0082</mechanicalReduction>
    </actuator>
  </transmission>
  <transmission name="hand_left_trans_pinky_mcp_pitch">
    <type>transmission_interface/SimpleTransmission</type>
    <joint name="hand_left_lh_pinky_mcp_pitch">
      <hardwareInterface>hardware_interface/EffortJointInterface</hardwareInterface>
    </joint>
    <actuator name="motor_pinky_mcp_pitch">
      <hardwareInterface>hardware_interface/EffortJointInterface</hardwareInterface>
      <mechanicalReduction>0.0082</mechanicalReduction>
    </actuator>
  </transmission>
  <transmission name="hand_left_trans_thumb_cmc_pitch">
    <type>transmission_interface/SimpleTransmission</type>
    <joint name="hand_left_lh_thumb_cmc_pitch">
      <hardwareInterface>hardware_interface/EffortJointInterface</hardwareInterface>
    </joint>
    <actuator name="motor_thumb_cmc_pitch">
      <hardwareInterface>hardware_interface/EffortJointInterface</hardwareInterface>
      <mechanicalReduction>0.0144</mechanicalReduction>
    </actuator>
  </transmission>
  <transmission name="hand_right_trans_thumb_cmc_roll">
    <type>transmission_interface/SimpleTransmission</type>
    <joint name="hand_right_rh_thumb_cmc_roll">
      <hardwareInterface>hardware_interface/EffortJointInterface</hardwareInterface>
    </joint>
    <actuator name="motor_thumb_cmc_roll">
      <hardwareInterface>hardware_interface/EffortJointInterface</hardwareInterface>
      <mechanicalReduction>0.0084</mechanicalReduction>
    </actuator>
  </transmission>
  <transmission name="hand_right_trans_index_mcp_pitch">
    <type>transmission_interface/SimpleTransmission</type>
    <joint name="hand_right_rh_index_mcp_pitch">
      <hardwareInterface>hardware_interface/EffortJointInterface</hardwareInterface>
    </joint>
    <actuator name="motor_index_mcp_pitch">
      <hardwareInterface>hardware_interface/EffortJointInterface</hardwareInterface>
      <mechanicalReduction>0.0082</mechanicalReduction>
    </actuator>
  </transmission>
  <transmission name="hand_right_trans_middle_mcp_pitch">
    <type>transmission_interface/SimpleTransmission</type>
    <joint name="hand_right_rh_middle_mcp_pitch">
      <hardwareInterface>hardware_interface/EffortJointInterface</hardwareInterface>
    </joint>
    <actuator name="motor_middle_mcp_pitch">
      <hardwareInterface>hardware_interface/EffortJointInterface</hardwareInterface>
      <mechanicalReduction>0.0082</mechanicalReduction>
    </actuator>
  </transmission>
  <transmission name="hand_right_trans_ring_mcp_pitch">
    <type>transmission_interface/SimpleTransmission</type>
    <joint name="hand_right_rh_ring_mcp_pitch">
      <hardwareInterface>hardware_interface/EffortJointInterface</hardwareInterface>
    </joint>
    <actuator name="motor_ring_mcp_pitch">
      <hardwareInterface>hardware_interface/EffortJointInterface</hardwareInterface>
      <mechanicalReduction>0.0082</mechanicalReduction>
    </actuator>
  </transmission>
  <transmission name="hand_right_trans_pinky_mcp_pitch">
    <type>transmission_interface/SimpleTransmission</type>
    <joint name="hand_right_rh_pinky_mcp_pitch">
      <hardwareInterface>hardware_interface/EffortJointInterface</hardwareInterface>
    </joint>
    <actuator name="motor_pinky_mcp_pitch">
      <hardwareInterface>hardware_interface/EffortJointInterface</hardwareInterface>
      <mechanicalReduction>0.0082</mechanicalReduction>
    </actuator>
  </transmission>
  <transmission name="hand_right_trans_thumb_cmc_pitch">
    <type>transmission_interface/SimpleTransmission</type>
    <joint name="hand_right_rh_thumb_cmc_pitch">
      <hardwareInterface>hardware_interface/EffortJointInterface</hardwareInterface>
    </joint>
    <actuator name="motor_thumb_cmc_pitch">
      <hardwareInterface>hardware_interface/EffortJointInterface</hardwareInterface>
      <mechanicalReduction>0.0144</mechanicalReduction>
    </actuator>
  </transmission>
  <joint name="mount_arm_left_to_base_base_mount" type="fixed">
    <origin xyz="0 0 0" rpy="0 0 0" />
    <parent link="base_arm_left_mount" />
    <child link="arm_left_L_arm_root" />
  </joint>
  <joint name="mount_arm_right_to_base_base_mount" type="fixed">
    <origin xyz="0 0 0" rpy="0 0 0" />
    <parent link="base_arm_right_mount" />
    <child link="arm_right_R_arm_root" />
  </joint>
  <joint name="mount_hand_left_to_arm_left_wrist_mount" type="fixed">
    <origin xyz="0 0 0" rpy="3.1416 0 -1.5708" />
    <parent link="arm_left_L8_Link" />
    <child link="hand_left_lh_hand_base_link" />
  </joint>
  <joint name="mount_hand_right_to_arm_right_wrist_mount" type="fixed">
    <origin xyz="0 0 0" rpy="3.1416 0 1.5708" />
    <parent link="arm_right_R8_Link" />
    <child link="hand_right_rh_hand_base_link" />
  </joint>
  <joint name="mount_world_to_base" type="fixed">
    <origin xyz="0 0 0" rpy="0 0 0" />
    <parent link="world" />
    <child link="base_torso_root" />
  </joint>
  <mujoco>
    <compiler meshdir="meshes/" balanceinertia="true" discardvisual="false" />
    <default>
      <joint armature="3.4707e-08" damping="5.0" frictionloss="0.5" />
    </default>
    <equality>
      <joint name="hand_left_lh_couple_index" joint1="hand_left_lh_index_dip" joint2="hand_left_lh_index_mcp_pitch" polycoef="0 1.125676 0 0 0 0" />
      <joint name="hand_left_lh_couple_middle" joint1="hand_left_lh_middle_dip" joint2="hand_left_lh_middle_mcp_pitch" polycoef="0 1.125676 0 0 0 0" />
      <joint name="hand_left_lh_couple_ring" joint1="hand_left_lh_ring_dip" joint2="hand_left_lh_ring_mcp_pitch" polycoef="0 1.125676 0 0 0 0" />
      <joint name="hand_left_lh_couple_pinky" joint1="hand_left_lh_pinky_dip" joint2="hand_left_lh_pinky_mcp_pitch" polycoef="0 1.125676 0 0 0 0" />
      <joint name="hand_left_lh_couple_thumb" joint1="hand_left_lh_thumb_dip" joint2="hand_left_lh_thumb_cmc_pitch" polycoef="0 1.226495 0 0 0 0" />
    </equality>
  </mujoco>
  <mujoco>
    <default>
      <joint armature="3.4707e-08" damping="5.0" frictionloss="0.5" />
    </default>
    <equality>
      <joint name="hand_right_rh_couple_index" joint1="hand_right_rh_index_dip" joint2="hand_right_rh_index_mcp_pitch" polycoef="0 1.125676 0 0 0 0" />
      <joint name="hand_right_rh_couple_middle" joint1="hand_right_rh_middle_dip" joint2="hand_right_rh_middle_mcp_pitch" polycoef="0 1.125676 0 0 0 0" />
      <joint name="hand_right_rh_couple_ring" joint1="hand_right_rh_ring_dip" joint2="hand_right_rh_ring_mcp_pitch" polycoef="0 1.125676 0 0 0 0" />
      <joint name="hand_right_rh_couple_pinky" joint1="hand_right_rh_pinky_dip" joint2="hand_right_rh_pinky_mcp_pitch" polycoef="0 1.125676 0 0 0 0" />
      <joint name="hand_right_rh_couple_thumb" joint1="hand_right_rh_thumb_dip" joint2="hand_right_rh_thumb_cmc_pitch" polycoef="0 1.226495 0 0 0 0" />
    </equality>
  </mujoco>
</robot>
