<?xml version="1.0" encoding="UTF-8"?>
<!-- Generated by tools/composer (version 0.1.0). Workstation: lkls73_i1_bimanual. Recipe sha256: cf521bd5c786fac04d2135e2dfe0bc68ba929431ddd9c0664adff9bd48e0788b. Do not edit by hand; re-run `python -m tools.composer.compose <workstation>`. -->
<mujoco model="lkls73_i1_bimanual">
  <compiler discardvisual="false" autolimits="true" angle="radian" eulerseq="XYZ" />
  <option />
  <default>
    <default class="base_base_lkls73_torso_visual">
      <geom type="mesh" contype="0" conaffinity="0" group="1" />
    </default>
    <default class="base_base_lkls73_torso_collision">
      <geom type="mesh" contype="1" conaffinity="1" group="3" />
    </default>
    <default class="arm_left_arm_lkls73_arm_visual">
      <geom type="mesh" contype="0" conaffinity="0" group="1" />
    </default>
    <default class="arm_left_arm_lkls73_arm_collision">
      <geom type="mesh" contype="1" conaffinity="1" group="3" />
    </default>
    <default class="arm_right_arm_lkls73_arm_visual">
      <geom type="mesh" contype="0" conaffinity="0" group="1" />
    </default>
    <default class="arm_right_arm_lkls73_arm_collision">
      <geom type="mesh" contype="1" conaffinity="1" group="3" />
    </default>
    <default class="hand_left_hand_linkerhand_l6_visual">
      <geom type="mesh" contype="0" conaffinity="0" group="1" />
    </default>
    <default class="hand_left_hand_linkerhand_l6_collision">
      <geom type="mesh" contype="1" conaffinity="1" group="3" />
    </default>
    <default class="hand_left_hand_linkerhand_l6_joint">
      <joint armature="3.4707e-08" damping="5.0" frictionloss="0.5" />
    </default>
    <default class="hand_right_hand_linkerhand_l6_visual">
      <geom type="mesh" contype="0" conaffinity="0" group="1" />
    </default>
    <default class="hand_right_hand_linkerhand_l6_collision">
      <geom type="mesh" contype="1" conaffinity="1" group="3" />
    </default>
    <default class="hand_right_hand_linkerhand_l6_joint">
      <joint armature="3.4707e-08" damping="5.0" frictionloss="0.5" />
    </default>
  </default>
  <asset>
    <mesh name="base_torso_base_link" file="../../components/bases/lkls73_torso/variants/default/meshes/base_link.STL" />
    <mesh name="arm_left_L1" file="../../components/arms/lkls73_arm/variants/left/meshes/L1_Link.STL" />
    <mesh name="arm_left_L2" file="../../components/arms/lkls73_arm/variants/left/meshes/L2_Link.STL" />
    <mesh name="arm_left_L3" file="../../components/arms/lkls73_arm/variants/left/meshes/L3_Link.STL" />
    <mesh name="arm_left_L4" file="../../components/arms/lkls73_arm/variants/left/meshes/L4_Link.STL" />
    <mesh name="arm_left_L5" file="../../components/arms/lkls73_arm/variants/left/meshes/L5_Link.STL" />
    <mesh name="arm_left_L6" file="../../components/arms/lkls73_arm/variants/left/meshes/L6_Link.STL" />
    <mesh name="arm_left_L7" file="../../components/arms/lkls73_arm/variants/left/meshes/L7_Link.STL" />
    <mesh name="arm_left_L8" file="../../components/arms/lkls73_arm/variants/left/meshes/L8_Link.STL" />
    <mesh name="arm_right_R1" file="../../components/arms/lkls73_arm/variants/right/meshes/R1_Link.STL" />
    <mesh name="arm_right_R2" file="../../components/arms/lkls73_arm/variants/right/meshes/R2_Link.STL" />
    <mesh name="arm_right_R3" file="../../components/arms/lkls73_arm/variants/right/meshes/R3_Link.STL" />
    <mesh name="arm_right_R4" file="../../components/arms/lkls73_arm/variants/right/meshes/R4_Link.STL" />
    <mesh name="arm_right_R5" file="../../components/arms/lkls73_arm/variants/right/meshes/R5_Link.STL" />
    <mesh name="arm_right_R6" file="../../components/arms/lkls73_arm/variants/right/meshes/R6_Link.STL" />
    <mesh name="arm_right_R7" file="../../components/arms/lkls73_arm/variants/right/meshes/R7_Link.STL" />
    <mesh name="arm_right_R8" file="../../components/arms/lkls73_arm/variants/right/meshes/R8_Link.STL" />
    <mesh name="hand_left_hand_base" file="../../components/hands/linkerhand_l6/variants/left/meshes/hand_base_link.STL" />
    <mesh name="hand_left_thumb_metacarpals_base1" file="../../components/hands/linkerhand_l6/variants/left/meshes/thumb_metacarpals_base1.STL" />
    <mesh name="hand_left_thumb_metacarpals" file="../../components/hands/linkerhand_l6/variants/left/meshes/thumb_metacarpals.STL" />
    <mesh name="hand_left_thumb_distal" file="../../components/hands/linkerhand_l6/variants/left/meshes/thumb_distal.STL" />
    <mesh name="hand_left_index_proximal" file="../../components/hands/linkerhand_l6/variants/left/meshes/index_proximal.STL" />
    <mesh name="hand_left_index_distal" file="../../components/hands/linkerhand_l6/variants/left/meshes/index_distal.STL" />
    <mesh name="hand_left_middle_proximal" file="../../components/hands/linkerhand_l6/variants/left/meshes/middle_proximal.STL" />
    <mesh name="hand_left_middle_distal" file="../../components/hands/linkerhand_l6/variants/left/meshes/middle_distal.STL" />
    <mesh name="hand_left_ring_proximal" file="../../components/hands/linkerhand_l6/variants/left/meshes/ring_proximal.STL" />
    <mesh name="hand_left_ring_distal" file="../../components/hands/linkerhand_l6/variants/left/meshes/ring_distal.STL" />
    <mesh name="hand_left_pinky_proximal" file="../../components/hands/linkerhand_l6/variants/left/meshes/pinky_proximal.STL" />
    <mesh name="hand_left_pinky_distal" file="../../components/hands/linkerhand_l6/variants/left/meshes/pinky_distal.STL" />
    <mesh name="hand_right_hand_base" file="../../components/hands/linkerhand_l6/variants/right/meshes/hand_base_link.STL" />
    <mesh name="hand_right_thumb_metacarpals_base1" file="../../components/hands/linkerhand_l6/variants/right/meshes/thumb_metacarpals_base1.STL" />
    <mesh name="hand_right_thumb_metacarpals" file="../../components/hands/linkerhand_l6/variants/right/meshes/thumb_metacarpals.STL" />
    <mesh name="hand_right_thumb_distal" file="../../components/hands/linkerhand_l6/variants/right/meshes/thumb_distal.STL" />
    <mesh name="hand_right_index_proximal" file="../../components/hands/linkerhand_l6/variants/right/meshes/index_proximal.STL" />
    <mesh name="hand_right_index_distal" file="../../components/hands/linkerhand_l6/variants/right/meshes/index_distal.STL" />
    <mesh name="hand_right_middle_proximal" file="../../components/hands/linkerhand_l6/variants/right/meshes/middle_proximal.STL" />
    <mesh name="hand_right_middle_distal" file="../../components/hands/linkerhand_l6/variants/right/meshes/middle_distal.STL" />
    <mesh name="hand_right_ring_proximal" file="../../components/hands/linkerhand_l6/variants/right/meshes/ring_proximal.STL" />
    <mesh name="hand_right_ring_distal" file="../../components/hands/linkerhand_l6/variants/right/meshes/ring_distal.STL" />
    <mesh name="hand_right_pinky_proximal" file="../../components/hands/linkerhand_l6/variants/right/meshes/pinky_proximal.STL" />
    <mesh name="hand_right_pinky_distal" file="../../components/hands/linkerhand_l6/variants/right/meshes/pinky_distal.STL" />
  </asset>
  <worldbody>
    <body name="base_torso_root" pos="0 0 0">
      <body name="base_base_link" pos="0 0 1.2">
        <inertial pos="5.75109188383945E-05 1.44120839455095E-05 -0.489174317245241" mass="10.8067081992573" fullinertia="0.192527915393298 0.191539752328327 0.103049415034787 -1.67956043663548E-08 -3.68569447484118E-08 6.60319145138974E-08" />
        <geom class="base_base_lkls73_torso_visual" mesh="base_torso_base_link" />
        <geom class="base_base_lkls73_torso_collision" mesh="base_torso_base_link" />
        <body name="base_arm_left_mount" pos="0 0.164 0">
          <site name="base_arm_left_mount" pos="0 0 0" />
          <body name="arm_left_L_arm_root" pos="0 0 0">
            <site name="arm_left_base_mount" pos="0 0 0" />
            <body name="arm_left_L1_Link" pos="0 0 0">
              <inertial pos="0.00235600060651345 0.0538143182293528 0.00010452198160641" mass="1.3997199601261" fullinertia="0.00114445383866051 0.000654874787984474 0.000691494366096022 -2.33503672142218E-06 -9.94413789148138E-09 1.05907637546798E-06" />
              <joint name="arm_left_L1_Joint" type="hinge" axis="0 -1 0" range="-2.91 2.91" damping="4" frictionloss="0.0" armature="0.01" />
              <geom class="arm_left_arm_lkls73_arm_visual" mesh="arm_left_L1" />
              <geom class="arm_left_arm_lkls73_arm_collision" mesh="arm_left_L1" />
              <body name="arm_left_L2_Link" pos="0 0.058 0">
                <inertial pos="0.001618419731441 8.17586538826021E-06 -0.0795739675465699" mass="1.14210487960353" fullinertia="0.000999259952314694 0.000929597687983869 0.000490873838603504 4.38390447469883E-06 -1.34113970553355E-06 2.7922699166407E-07" />
                <joint name="arm_left_L2_Joint" type="hinge" axis="-1 0 0" range="-3.2 0.07" damping="4" frictionloss="0.0" armature="0.01" />
                <geom class="arm_left_arm_lkls73_arm_visual" mesh="arm_left_L2" />
                <geom class="arm_left_arm_lkls73_arm_collision" mesh="arm_left_L2" />
                <body name="arm_left_L3_Link" pos="-2.5018E-05 0 -0.123">
                  <inertial pos="0.000181280975708543 0.0012493056236523 -0.128548942292033" mass="1.2798435287888" fullinertia="0.00158095142201815 0.00163152743924312 0.000344148864762278 7.74063763820645E-07 -8.68119829913453E-07 -2.41539579836192E-06" />
                  <joint name="arm_left_L3_Joint" type="hinge" axis="0 0 1" range="-2.69 2.69" damping="4" frictionloss="0.0" armature="0.01" />
                  <geom class="arm_left_arm_lkls73_arm_visual" mesh="arm_left_L3" />
                  <geom class="arm_left_arm_lkls73_arm_collision" mesh="arm_left_L3" />
                  <body name="arm_left_L4_Link" pos="2.4267E-05 0 -0.1621">
                    <inertial pos="-3.38229166406629E-06 0.00077842370454409 -0.08460011635447" mass="0.935504485205333" fullinertia="0.000508246005403967 0.000524130562919452 0.000333983371716017 -4.123494432482E-06 -1.601236457745E-07 -3.45757221458974E-07" />
                    <joint name="arm_left_L4_Joint" type="hinge" axis="0 -1 0" range="-2.05 2.05" damping="4" frictionloss="0.0" armature="0.01" />
                    <geom class="arm_left_arm_lkls73_arm_visual" mesh="arm_left_L4" />
                    <geom class="arm_left_arm_lkls73_arm_collision" mesh="arm_left_L4" />
                    <body name="arm_left_L5_Link" pos="0 0 -0.124">
                      <inertial pos="-7.8967109106414E-05 0.00127705818106172 -0.0361222642165061" mass="0.298012293033296" fullinertia="0.000356324975203863 0.000385006059216245 0.000101746640600842 8.49346343481351E-07 -1.06208641170066E-06 2.16302454958746E-06" />
                      <joint name="arm_left_L5_Joint" type="hinge" axis="0 0 1" range="-2.69 2.69" damping="4" frictionloss="0.0" armature="0.01" />
                      <geom class="arm_left_arm_lkls73_arm_visual" mesh="arm_left_L5" />
                      <geom class="arm_left_arm_lkls73_arm_collision" mesh="arm_left_L5" />
                      <body name="arm_left_L6_Link" pos="0 0 -0.0881">
                        <inertial pos="0.00423270788750624 -0.00438646585481159 -0.0324823655341541" mass="0.344326210144814" fullinertia="0.000194396852170226 0.000233882186601331 0.000101458599044909 1.34053122918212E-06 9.47054882668167E-06 2.86885239016126E-07" />
                        <joint name="arm_left_L6_Joint" type="hinge" axis="0 -1 0" range="-1.59 1.59" damping="4" frictionloss="0.0" armature="0.01" />
                        <geom class="arm_left_arm_lkls73_arm_visual" mesh="arm_left_L6" />
                        <geom class="arm_left_arm_lkls73_arm_collision" mesh="arm_left_L6" />
                        <body name="arm_left_L7_Link" pos="-2.6563E-05 0 -0.0655">
                          <inertial pos="-0.00330667550396703 2.7195733834362E-07 -0.0202430179985484" mass="0.143310943627726" fullinertia="6.98168229201036E-05 5.48675476764208E-05 4.4020607930097E-05 2.70503363331007E-07 -3.17975733412514E-08 1.01362000675163E-12" />
                          <joint name="arm_left_L7_Joint" type="hinge" axis="-1 0 0" range="-1.59 1.59" damping="4" frictionloss="0.0" armature="0.01" />
                          <geom class="arm_left_arm_lkls73_arm_visual" mesh="arm_left_L7" />
                          <geom class="arm_left_arm_lkls73_arm_collision" mesh="arm_left_L7" />
                          <body name="arm_left_L8_Link" pos="2.5732E-05 0 -0.0455">
                            <inertial pos="1.08546552465473E-10 -1.13853898531247E-09 0.000500000000024592" mass="6.05149284897746E-05" fullinertia="8.49604381443617E-09 8.49604381442905E-09 1.69820018074357E-08 8.31968496153617E-22 -7.81277944440306E-15 -9.03653480952828E-16" />
                            <geom class="arm_left_arm_lkls73_arm_visual" mesh="arm_left_L8" />
                            <geom class="arm_left_arm_lkls73_arm_collision" mesh="arm_left_L8" />
                            <site name="arm_left_tool0" pos="0 0 0" />
                            <body name="hand_left_lh_hand_base_link" pos="0 0 0" euler="3.1416 0 -1.5708">
                              <inertial pos="0.00199 -0.00091 0.058381" mass="0.4185" fullinertia="0.0004998 0.0003567 0.0002301 0.000012853 -0.000008317 0.000010354" />
                              <geom class="hand_left_hand_linkerhand_l6_visual" mesh="hand_left_hand_base" />
                              <geom class="hand_left_hand_linkerhand_l6_collision" mesh="hand_left_hand_base" />
                              <site name="hand_left_wrist_mount" pos="0 0 0" />
                              <body name="hand_left_lh_thumb_metacarpals_base1" pos="0.0078133 -0.029898 0.026692" euler="-0.034907 0 0">
                                <inertial pos="0.0018663 -0.0066406 0.001533" mass="0.01" fullinertia="3.3724E-07 2.9457E-07 4.903E-07 1.11E-07 -3.6039E-08 5.7181E-08" />
                                <joint name="hand_left_lh_thumb_cmc_roll" class="hand_left_hand_linkerhand_l6_joint" type="hinge" axis="0 0 1" range="-0.087266 1.256637" />
                                <geom class="hand_left_hand_linkerhand_l6_visual" mesh="hand_left_thumb_metacarpals_base1" />
                                <geom class="hand_left_hand_linkerhand_l6_collision" mesh="hand_left_thumb_metacarpals_base1" />
                                <body name="hand_left_lh_thumb_metacarpals" pos="0.0057298 -0.01332 0.0027456" euler="1.1083 0 0.40143">
                                  <inertial pos="0.00769270907060086 0.0859662184722988 0.0235283086675235" mass="0.065" fullinertia="8.407E-06 8.3899E-06 2.0091E-06 -1.1338E-09 1.1136E-08 3.1171E-07" />
                                  <joint name="hand_left_lh_thumb_cmc_pitch" class="hand_left_hand_linkerhand_l6_joint" type="hinge" axis="-1 0 0" range="0 0.837758" />
                                  <geom class="hand_left_hand_linkerhand_l6_visual" mesh="hand_left_thumb_metacarpals" />
                                  <geom class="hand_left_hand_linkerhand_l6_collision" mesh="hand_left_thumb_metacarpals" />
                                  <body name="hand_left_lh_thumb_distal" pos="0 0.0061 0.0827">
                                    <inertial pos="0.00769270907081708 0.0798662184721594 -0.0591716913325555" mass="0.018" fullinertia="1.5546E-06 1.7108E-06 9.1709E-07 2.4423E-09 2.8147E-09 -7.2756E-08" />
                                    <joint name="hand_left_lh_thumb_dip" class="hand_left_hand_linkerhand_l6_joint" type="hinge" axis="-1 0 0" range="0 0.963287" />
                                    <geom class="hand_left_hand_linkerhand_l6_visual" mesh="hand_left_thumb_distal" />
                                    <geom class="hand_left_hand_linkerhand_l6_collision" mesh="hand_left_thumb_distal" />
                                    <body name="hand_left_lh_thumb_tip" pos="0 0.0035 0.026" euler="0 0 1.5708">
                                      <inertial pos="0 0 0" mass="1e-06" fullinertia="1e-09 1e-09 1e-09 0 0 0" />
                                    </body>
                                  </body>
                                </body>
                              </body>
                              <body name="hand_left_lh_index_proximal" pos="-0.00066821 -0.028967 0.11722">
                                <inertial pos="0.001776 -0.00011 0.012556" mass="0.008553" fullinertia="0.000000797543 0.000000800499 0.000000357001 -0.000000001275 0.000000138601 0.000000000939" />
                                <joint name="hand_left_lh_index_mcp_pitch" class="hand_left_hand_linkerhand_l6_joint" type="hinge" axis="0 1 0" range="0 1.134464" />
                                <geom class="hand_left_hand_linkerhand_l6_visual" mesh="hand_left_index_proximal" />
                                <geom class="hand_left_hand_linkerhand_l6_collision" mesh="hand_left_index_proximal" />
                                <body name="hand_left_lh_index_distal" pos="0.00093749 0 0.028002">
                                  <inertial pos="0.0134 0.002262 0.016992" mass="0.018408" fullinertia="0.000002488712 0.000003723754 0.000001813582 0.000000008249 -0.000001523059 0.000000014019" />
                                  <joint name="hand_left_lh_index_dip" class="hand_left_hand_linkerhand_l6_joint" type="hinge" axis="0 1 0" range="0 1.277039" />
                                  <geom class="hand_left_hand_linkerhand_l6_visual" mesh="hand_left_index_distal" />
                                  <geom class="hand_left_hand_linkerhand_l6_collision" mesh="hand_left_index_distal" />
                                  <body name="hand_left_lh_index_tip" pos="0.0341 0 0.034">
                                    <inertial pos="0 0 0" mass="1e-06" fullinertia="1e-09 1e-09 1e-09 0 0 0" />
                                  </body>
                                </body>
                              </body>
                              <body name="hand_left_lh_middle_proximal" pos="-0.00066821 -0.0089013 0.12322">
                                <inertial pos="0.001776 -0.00011 0.012556" mass="0.008553" fullinertia="0.000000797543 0.000000800499 0.000000357001 -0.000000001275 0.000000138601 0.000000000939" />
                                <joint name="hand_left_lh_middle_mcp_pitch" class="hand_left_hand_linkerhand_l6_joint" type="hinge" axis="0 1 0" range="0 1.134464" />
                                <geom class="hand_left_hand_linkerhand_l6_visual" mesh="hand_left_middle_proximal" />
                                <geom class="hand_left_hand_linkerhand_l6_collision" mesh="hand_left_middle_proximal" />
                                <body name="hand_left_lh_middle_distal" pos="0.00093749 0 0.028002">
                                  <inertial pos="0.0134 0.002262 0.016992" mass="0.018408" fullinertia="0.000002488712 0.000003723754 0.000001813582 0.000000008249 -0.000001523059 0.000000014019" />
                                  <joint name="hand_left_lh_middle_dip" class="hand_left_hand_linkerhand_l6_joint" type="hinge" axis="0 1 0" range="0 1.277039" />
                                  <geom class="hand_left_hand_linkerhand_l6_visual" mesh="hand_left_middle_distal" />
                                  <geom class="hand_left_hand_linkerhand_l6_collision" mesh="hand_left_middle_distal" />
                                  <body name="hand_left_lh_middle_tip" pos="0.0341 0 0.034">
                                    <inertial pos="0 0 0" mass="1e-06" fullinertia="1e-09 1e-09 1e-09 0 0 0" />
                                  </body>
                                </body>
                              </body>
                              <body name="hand_left_lh_ring_proximal" pos="-0.00067368 0.010717 0.11822">
                                <inertial pos="0.001776 -0.00011 0.012556" mass="0.008553" fullinertia="0.000000797543 0.000000800499 0.000000357001 -0.000000001275 0.000000138601 0.000000000939" />
                                <joint name="hand_left_lh_ring_mcp_pitch" class="hand_left_hand_linkerhand_l6_joint" type="hinge" axis="0 1 0" range="0 1.134464" />
                                <geom class="hand_left_hand_linkerhand_l6_visual" mesh="hand_left_ring_proximal" />
                                <geom class="hand_left_hand_linkerhand_l6_collision" mesh="hand_left_ring_proximal" />
                                <body name="hand_left_lh_ring_distal" pos="0.00093749 0 0.028002">
                                  <inertial pos="0.0134 0.002262 0.016992" mass="0.018408" fullinertia="0.000002488712 0.000003723754 0.000001813582 0.000000008249 -0.000001523059 0.000000014019" />
                                  <joint name="hand_left_lh_ring_dip" class="hand_left_hand_linkerhand_l6_joint" type="hinge" axis="0 1 0" range="0 1.277039" />
                                  <geom class="hand_left_hand_linkerhand_l6_visual" mesh="hand_left_ring_distal" />
                                  <geom class="hand_left_hand_linkerhand_l6_collision" mesh="hand_left_ring_distal" />
                                  <body name="hand_left_lh_ring_tip" pos="0.0341 0 0.034">
                                    <inertial pos="0 0 0" mass="1e-06" fullinertia="1e-09 1e-09 1e-09 0 0 0" />
                                  </body>
                                </body>
                              </body>
                              <body name="hand_left_lh_pinky_proximal" pos="-0.00067852 0.029814 0.11424">
                                <inertial pos="0.001776 -0.00011 0.012556" mass="0.008553" fullinertia="0.000000797543 0.000000800499 0.000000357001 -0.000000001275 0.000000138601 0.000000000939" />
                                <joint name="hand_left_lh_pinky_mcp_pitch" class="hand_left_hand_linkerhand_l6_joint" type="hinge" axis="0 1 0" range="0 1.134464" />
                                <geom class="hand_left_hand_linkerhand_l6_visual" mesh="hand_left_pinky_proximal" />
                                <geom class="hand_left_hand_linkerhand_l6_collision" mesh="hand_left_pinky_proximal" />
                                <body name="hand_left_lh_pinky_distal" pos="0.00093749 0 0.028002">
                                  <inertial pos="0.0134 0.002262 0.016992" mass="0.018408" fullinertia="0.000002488712 0.000003723754 0.000001813582 0.000000008249 -0.000001523059 0.000000014019" />
                                  <joint name="hand_left_lh_pinky_dip" class="hand_left_hand_linkerhand_l6_joint" type="hinge" axis="0 1 0" range="0 1.277039" />
                                  <geom class="hand_left_hand_linkerhand_l6_visual" mesh="hand_left_pinky_distal" />
                                  <geom class="hand_left_hand_linkerhand_l6_collision" mesh="hand_left_pinky_distal" />
                                  <body name="hand_left_lh_pinky_tip" pos="0.0341 0 0.034">
                                    <inertial pos="0 0 0" mass="1e-06" fullinertia="1e-09 1e-09 1e-09 0 0 0" />
                                  </body>
                                </body>
                              </body>
                            </body>
                          </body>
                        </body>
                      </body>
                    </body>
                  </body>
                </body>
              </body>
            </body>
          </body>
        </body>
        <body name="base_arm_right_mount" pos="3.32E-05 -0.164 0">
          <site name="base_arm_right_mount" pos="0 0 0" />
          <body name="arm_right_R_arm_root" pos="0 0 0">
            <site name="arm_right_base_mount" pos="0 0 0" />
            <body name="arm_right_R1_Link" pos="0 0 0">
              <inertial pos="-0.00238919607727967 -0.0538157456440336 0.00010452196048521" mass="1.39972022686362" fullinertia="0.00114445390268402 0.000654874566780468 0.000691494652521253 -2.33503672059843E-06 9.94413679130844E-09 -1.0590763545097E-06" />
              <joint name="arm_right_R1_Joint" type="hinge" axis="0 1 0" range="-2.91 2.91" damping="4" frictionloss="0.0" armature="0.01" />
              <geom class="arm_right_arm_lkls73_arm_visual" mesh="arm_right_R1" />
              <geom class="arm_right_arm_lkls73_arm_collision" mesh="arm_right_R1" />
              <body name="arm_right_R2_Link" pos="-3.32E-05 -0.058001 0">
                <inertial pos="-0.00161840435618426 -8.19852199768212E-06 -0.0795740266968583" mass="1.14210467744301" fullinertia="0.00099926032712546 0.000929597930299551 0.000490873969400915 4.38390428673455E-06 1.34112399215467E-06 -2.7915125849712E-07" />
                <joint name="arm_right_R2_Joint" type="hinge" axis="-1 0 0" range="-0.07 3.2" damping="4" frictionloss="0.0" armature="0.01" />
                <geom class="arm_right_arm_lkls73_arm_visual" mesh="arm_right_R2" />
                <geom class="arm_right_arm_lkls73_arm_collision" mesh="arm_right_R2" />
                <body name="arm_right_R3_Link" pos="2.5018E-05 0 -0.123">
                  <inertial pos="-0.000181281046893987 -0.00124930020984915 -0.128548942421424" mass="1.27984352653686" fullinertia="0.00158095142360156 0.00163152744277086 0.000344148863355523 7.74064683830126E-07 8.68119825601561E-07 2.41539423740222E-06" />
                  <joint name="arm_right_R3_Joint" type="hinge" axis="0 0 1" range="-2.69 2.69" damping="4" frictionloss="0.0" armature="0.01" />
                  <geom class="arm_right_arm_lkls73_arm_visual" mesh="arm_right_R3" />
                  <geom class="arm_right_arm_lkls73_arm_collision" mesh="arm_right_R3" />
                  <body name="arm_right_R4_Link" pos="-2.5308E-05 0 -0.1621">
                    <inertial pos="4.42383386005531E-06 -0.000778418113624724 -0.0846001182728231" mass="0.935504488206621" fullinertia="0.00050824600575807 0.000524130564978714 0.000333983373234424 -4.12349458829714E-06 1.60122816329668E-07 3.4575721962879E-07" />
                    <joint name="arm_right_R4_Joint" type="hinge" axis="0 1 0" range="-2.05 2.05" damping="4" frictionloss="0.0" armature="0.01" />
                    <geom class="arm_right_arm_lkls73_arm_visual" mesh="arm_right_R4" />
                    <geom class="arm_right_arm_lkls73_arm_collision" mesh="arm_right_R4" />
                    <body name="arm_right_R5_Link" pos="0 0 -0.124">
                      <inertial pos="7.89161129038714E-05 -0.00127720103461224 -0.0361226257678754" mass="0.298013716041534" fullinertia="0.000356325710016729 0.000385006832605378 0.000101746689163179 8.49345579615723E-07 1.06208408022809E-06 -2.16308499009301E-06" />
                      <joint name="arm_right_R5_Joint" type="hinge" axis="0 0 1" range="-2.69 2.69" damping="4" frictionloss="0.0" armature="0.01" />
                      <geom class="arm_right_arm_lkls73_arm_visual" mesh="arm_right_R5" />
                      <geom class="arm_right_arm_lkls73_arm_collision" mesh="arm_right_R5" />
                      <body name="arm_right_R6_Link" pos="0 0 -0.0881">
                        <inertial pos="-0.00423362800835291 0.00438647668797748 -0.0324823687491156" mass="0.344326135276304" fullinertia="0.000194396918256628 0.000233882313857475 0.00010145861997438 1.34060453386023E-06 -9.47065531650411E-06 -2.86903332334497E-07" />
                        <joint name="arm_right_R6_Joint" type="hinge" axis="0 1 0" range="-1.59 1.59" damping="4" frictionloss="0.0" armature="0.01" />
                        <geom class="arm_right_arm_lkls73_arm_visual" mesh="arm_right_R6" />
                        <geom class="arm_right_arm_lkls73_arm_collision" mesh="arm_right_R6" />
                        <body name="arm_right_R7_Link" pos="2.5631E-05 0 -0.0655">
                          <inertial pos="0.00330667550394679 -1.18809317478652E-06 -0.0202430179967651" mass="0.143310943627727" fullinertia="6.98168229201036E-05 5.48675476764227E-05 4.4020607930099E-05 2.70503363330993E-07 3.17975733407385E-08 -1.01361997649667E-12" />
                          <joint name="arm_right_R7_Joint" type="hinge" axis="-1 0 0" range="-1.59 1.59" damping="4" frictionloss="0.0" armature="0.01" />
                          <geom class="arm_right_arm_lkls73_arm_visual" mesh="arm_right_R7" />
                          <geom class="arm_right_arm_lkls73_arm_collision" mesh="arm_right_R7" />
                          <body name="arm_right_R8_Link" pos="-2.5732E-05 0 -0.0455">
                            <inertial pos="-1.03808180585258E-10 5.33808552916071E-11 0.000499999999999834" mass="6.05149284897743E-05" fullinertia="8.49604381443613E-09 8.49604381442903E-09 1.69820018074356E-08 8.31967629121856E-22 7.81277954468574E-15 9.03653481925555E-16" />
                            <geom class="arm_right_arm_lkls73_arm_visual" mesh="arm_right_R8" />
                            <geom class="arm_right_arm_lkls73_arm_collision" mesh="arm_right_R8" />
                            <site name="arm_right_tool0" pos="0 0 0" />
                            <body name="hand_right_rh_hand_base_link" pos="0 0 0" euler="3.1416 0 1.5708">
                              <inertial pos="0.0019900000 0.0009100000 0.0583810000" mass="0.4185" fullinertia="0.0004998 0.0003567 0.0002301 -1.2853e-05 -8.317e-06 -1.0354e-05" />
                              <geom class="hand_right_hand_linkerhand_l6_visual" mesh="hand_right_hand_base" />
                              <geom class="hand_right_hand_linkerhand_l6_collision" mesh="hand_right_hand_base" />
                              <site name="hand_right_wrist_mount" pos="0 0 0" />
                              <body name="hand_right_rh_thumb_metacarpals_base1" pos="0.0078133 0.030812 0.025678" euler="-0.034907 0 0">
                                <inertial pos="0.0018663000 0.0066406000 0.0015330000" mass="0.01" fullinertia="3.3724e-07 2.9457e-07 4.903e-07 -1.11e-07 -3.6039e-08 -5.7181e-08" />
                                <joint name="hand_right_rh_thumb_cmc_roll" class="hand_right_hand_linkerhand_l6_joint" type="hinge" axis="0 0.034899 -0.99939" range="-0.087266 1.256637" />
                                <geom class="hand_right_hand_linkerhand_l6_visual" mesh="hand_right_thumb_metacarpals_base1" />
                                <geom class="hand_right_hand_linkerhand_l6_collision" mesh="hand_right_thumb_metacarpals_base1" />
                                <body name="hand_right_rh_thumb_metacarpals" pos="0.0054997 0.013314 0.0032166" euler="-1.0762 0.013637 -0.40121">
                                  <inertial pos="0.0076927091 -0.0859662185 0.0235283087" mass="0.065" fullinertia="8.407e-06 8.3899e-06 2.0091e-06 1.1338e-09 1.1136e-08 -3.1171e-07" />
                                  <joint name="hand_right_rh_thumb_cmc_pitch" class="hand_right_hand_linkerhand_l6_joint" type="hinge" axis="1 0 0" range="0 0.837758" />
                                  <geom class="hand_right_hand_linkerhand_l6_visual" mesh="hand_right_thumb_metacarpals" />
                                  <geom class="hand_right_hand_linkerhand_l6_collision" mesh="hand_right_thumb_metacarpals" />
                                  <body name="hand_right_rh_thumb_distal" pos="0 -0.0061 0.0827">
                                    <inertial pos="0.0076927091 -0.0798662185 -0.0591716913" mass="0.018" fullinertia="1.5546e-06 1.7108e-06 9.1709e-07 -2.4423e-09 2.8147e-09 7.2756e-08" />
                                    <joint name="hand_right_rh_thumb_dip" class="hand_right_hand_linkerhand_l6_joint" type="hinge" axis="1 0 0" range="0 0.963287" />
                                    <geom class="hand_right_hand_linkerhand_l6_visual" mesh="hand_right_thumb_distal" />
                                    <geom class="hand_right_hand_linkerhand_l6_collision" mesh="hand_right_thumb_distal" />
                                    <body name="hand_right_rh_thumb_tip" pos="0 -0.0035 0.026" euler="0 0 -1.5708">
                                      <inertial pos="0 0 0" mass="1e-06" fullinertia="1e-09 1e-09 1e-09 0 0 0" />
                                    </body>
                                  </body>
                                </body>
                              </body>
                              <body name="hand_right_rh_index_proximal" pos="-0.00066821 0.033467 0.11622" euler="-0.087266 0 0">
                                <inertial pos="0.0017760000 0.0001100000 0.0125560000" mass="0.008553" fullinertia="7.97543e-07 8.00499e-07 3.57001e-07 1.275e-09 1.38601e-07 -9.39e-10" />
                                <joint name="hand_right_rh_index_mcp_pitch" class="hand_right_hand_linkerhand_l6_joint" type="hinge" axis="0 1 0" range="0 1.134464" />
                                <geom class="hand_right_hand_linkerhand_l6_visual" mesh="hand_right_index_proximal" />
                                <geom class="hand_right_hand_linkerhand_l6_collision" mesh="hand_right_index_proximal" />
                                <body name="hand_right_rh_index_distal" pos="0.0009359 0 0.028002">
                                  <inertial pos="0.0134000000 -0.0022620000 0.0169920000" mass="0.018408" fullinertia="2.488712e-06 3.723754e-06 1.813582e-06 -8.249e-09 -1.523059e-06 -1.4019e-08" />
                                  <joint name="hand_right_rh_index_dip" class="hand_right_hand_linkerhand_l6_joint" type="hinge" axis="0 1 0" range="0 1.277039" />
                                  <geom class="hand_right_hand_linkerhand_l6_visual" mesh="hand_right_index_distal" />
                                  <geom class="hand_right_hand_linkerhand_l6_collision" mesh="hand_right_index_distal" />
                                  <body name="hand_right_rh_index_tip" pos="0.0341 0 0.034">
                                    <inertial pos="0 0 0" mass="1e-06" fullinertia="1e-09 1e-09 1e-09 0 0 0" />
                                  </body>
                                </body>
                              </body>
                              <body name="hand_right_rh_middle_proximal" pos="-0.00066821 0.0134013 0.12272" euler="-0.034907 0 0">
                                <inertial pos="0.0017760000 0.0001100000 0.0125560000" mass="0.008553" fullinertia="7.97543e-07 8.00499e-07 3.57001e-07 1.275e-09 1.38601e-07 -9.39e-10" />
                                <joint name="hand_right_rh_middle_mcp_pitch" class="hand_right_hand_linkerhand_l6_joint" type="hinge" axis="0 1 0" range="0 1.134464" />
                                <geom class="hand_right_hand_linkerhand_l6_visual" mesh="hand_right_middle_proximal" />
                                <geom class="hand_right_hand_linkerhand_l6_collision" mesh="hand_right_middle_proximal" />
                                <body name="hand_right_rh_middle_distal" pos="0.0009359 0 0.028002">
                                  <inertial pos="0.0134000000 -0.0022620000 0.0169920000" mass="0.018408" fullinertia="2.488712e-06 3.723754e-06 1.813582e-06 -8.249e-09 -1.523059e-06 -1.4019e-08" />
                                  <joint name="hand_right_rh_middle_dip" class="hand_right_hand_linkerhand_l6_joint" type="hinge" axis="0 1 0" range="0 1.277039" />
                                  <geom class="hand_right_hand_linkerhand_l6_visual" mesh="hand_right_middle_distal" />
                                  <geom class="hand_right_hand_linkerhand_l6_collision" mesh="hand_right_middle_distal" />
                                  <body name="hand_right_rh_middle_tip" pos="0.0341 0 0.034">
                                    <inertial pos="0 0 0" mass="1e-06" fullinertia="1e-09 1e-09 1e-09 0 0 0" />
                                  </body>
                                </body>
                              </body>
                              <body name="hand_right_rh_ring_proximal" pos="-0.00067368 -0.006217 0.11872" euler="0.017453 0 0">
                                <inertial pos="0.0017760000 0.0001100000 0.0125560000" mass="0.008553" fullinertia="7.97543e-07 8.00499e-07 3.57001e-07 1.275e-09 1.38601e-07 -9.39e-10" />
                                <joint name="hand_right_rh_ring_mcp_pitch" class="hand_right_hand_linkerhand_l6_joint" type="hinge" axis="0 1 0" range="0 1.134464" />
                                <geom class="hand_right_hand_linkerhand_l6_visual" mesh="hand_right_ring_proximal" />
                                <geom class="hand_right_hand_linkerhand_l6_collision" mesh="hand_right_ring_proximal" />
                                <body name="hand_right_rh_ring_distal" pos="0.0009359 0 0.028002">
                                  <inertial pos="0.0134000000 -0.0022620000 0.0169920000" mass="0.018408" fullinertia="2.488712e-06 3.723754e-06 1.813582e-06 -8.249e-09 -1.523059e-06 -1.4019e-08" />
                                  <joint name="hand_right_rh_ring_dip" class="hand_right_hand_linkerhand_l6_joint" type="hinge" axis="0 1 0" range="0 1.277039" />
                                  <geom class="hand_right_hand_linkerhand_l6_visual" mesh="hand_right_ring_distal" />
                                  <geom class="hand_right_hand_linkerhand_l6_collision" mesh="hand_right_ring_distal" />
                                  <body name="hand_right_rh_ring_tip" pos="0.0341 0 0.034">
                                    <inertial pos="0 0 0" mass="1e-06" fullinertia="1e-09 1e-09 1e-09 0 0 0" />
                                  </body>
                                </body>
                              </body>
                              <body name="hand_right_rh_pinky_proximal" pos="-0.00067852 -0.025314 0.11474" euler="0.05236 0 0">
                                <inertial pos="0.0017760000 0.0001100000 0.0125560000" mass="0.008553" fullinertia="7.97543e-07 8.00499e-07 3.57001e-07 1.275e-09 1.38601e-07 -9.39e-10" />
                                <joint name="hand_right_rh_pinky_mcp_pitch" class="hand_right_hand_linkerhand_l6_joint" type="hinge" axis="0 1 0" range="0 1.134464" />
                                <geom class="hand_right_hand_linkerhand_l6_visual" mesh="hand_right_pinky_proximal" />
                                <geom class="hand_right_hand_linkerhand_l6_collision" mesh="hand_right_pinky_proximal" />
                                <body name="hand_right_rh_pinky_distal" pos="0.0009359 0 0.028002">
                                  <inertial pos="0.0134000000 -0.0022620000 0.0169920000" mass="0.018408" fullinertia="2.488712e-06 3.723754e-06 1.813582e-06 -8.249e-09 -1.523059e-06 -1.4019e-08" />
                                  <joint name="hand_right_rh_pinky_dip" class="hand_right_hand_linkerhand_l6_joint" type="hinge" axis="0 1 0" range="0 1.277039" />
                                  <geom class="hand_right_hand_linkerhand_l6_visual" mesh="hand_right_pinky_distal" />
                                  <geom class="hand_right_hand_linkerhand_l6_collision" mesh="hand_right_pinky_distal" />
                                  <body name="hand_right_rh_pinky_tip" pos="0.0341 0 0.034">
                                    <inertial pos="0 0 0" mass="1e-06" fullinertia="1e-09 1e-09 1e-09 0 0 0" />
                                  </body>
                                </body>
                              </body>
                            </body>
                          </body>
                        </body>
                      </body>
                    </body>
                  </body>
                </body>
              </body>
            </body>
          </body>
        </body>
      </body>
    </body>
  </worldbody>
  <actuator>
    <position name="arm_left_L1_Joint_act" joint="arm_left_L1_Joint" kp="1000" kv="0" ctrlrange="-2.91 2.91" />
    <position name="arm_left_L2_Joint_act" joint="arm_left_L2_Joint" kp="1000" kv="0" ctrlrange="-3.2 0.07" />
    <position name="arm_left_L3_Joint_act" joint="arm_left_L3_Joint" kp="1000" kv="0" ctrlrange="-2.69 2.69" />
    <position name="arm_left_L4_Joint_act" joint="arm_left_L4_Joint" kp="1000" kv="0" ctrlrange="-2.05 2.05" />
    <position name="arm_left_L5_Joint_act" joint="arm_left_L5_Joint" kp="1000" kv="0" ctrlrange="-2.69 2.69" />
    <position name="arm_left_L6_Joint_act" joint="arm_left_L6_Joint" kp="1000" kv="0" ctrlrange="-1.59 1.59" />
    <position name="arm_left_L7_Joint_act" joint="arm_left_L7_Joint" kp="1000" kv="0" ctrlrange="-1.59 1.59" />
    <position name="arm_right_R1_Joint_act" joint="arm_right_R1_Joint" kp="1000" kv="0" ctrlrange="-2.91 2.91" />
    <position name="arm_right_R2_Joint_act" joint="arm_right_R2_Joint" kp="1000" kv="0" ctrlrange="-0.07 3.2" />
    <position name="arm_right_R3_Joint_act" joint="arm_right_R3_Joint" kp="1000" kv="0" ctrlrange="-2.69 2.69" />
    <position name="arm_right_R4_Joint_act" joint="arm_right_R4_Joint" kp="1000" kv="0" ctrlrange="-2.05 2.05" />
    <position name="arm_right_R5_Joint_act" joint="arm_right_R5_Joint" kp="1000" kv="0" ctrlrange="-2.69 2.69" />
    <position name="arm_right_R6_Joint_act" joint="arm_right_R6_Joint" kp="1000" kv="0" ctrlrange="-1.59 1.59" />
    <position name="arm_right_R7_Joint_act" joint="arm_right_R7_Joint" kp="1000" kv="0" ctrlrange="-1.59 1.59" />
    <position name="hand_left_lh_thumb_cmc_roll_act" joint="hand_left_lh_thumb_cmc_roll" kp="20" kv="2" ctrlrange="-0.087266 1.256637" />
    <position name="hand_left_lh_thumb_cmc_pitch_act" joint="hand_left_lh_thumb_cmc_pitch" kp="20" kv="2" ctrlrange="0 0.837758" />
    <position name="hand_left_lh_index_mcp_pitch_act" joint="hand_left_lh_index_mcp_pitch" kp="20" kv="2" ctrlrange="0 1.134464" />
    <position name="hand_left_lh_middle_mcp_pitch_act" joint="hand_left_lh_middle_mcp_pitch" kp="20" kv="2" ctrlrange="0 1.134464" />
    <position name="hand_left_lh_ring_mcp_pitch_act" joint="hand_left_lh_ring_mcp_pitch" kp="20" kv="2" ctrlrange="0 1.134464" />
    <position name="hand_left_lh_pinky_mcp_pitch_act" joint="hand_left_lh_pinky_mcp_pitch" kp="20" kv="2" ctrlrange="0 1.134464" />
    <position name="hand_right_rh_thumb_cmc_roll_act" joint="hand_right_rh_thumb_cmc_roll" kp="20" kv="2" ctrlrange="-0.087266 1.256637" />
    <position name="hand_right_rh_thumb_cmc_pitch_act" joint="hand_right_rh_thumb_cmc_pitch" kp="20" kv="2" ctrlrange="0 0.837758" />
    <position name="hand_right_rh_index_mcp_pitch_act" joint="hand_right_rh_index_mcp_pitch" kp="20" kv="2" ctrlrange="0 1.134464" />
    <position name="hand_right_rh_middle_mcp_pitch_act" joint="hand_right_rh_middle_mcp_pitch" kp="20" kv="2" ctrlrange="0 1.134464" />
    <position name="hand_right_rh_ring_mcp_pitch_act" joint="hand_right_rh_ring_mcp_pitch" kp="20" kv="2" ctrlrange="0 1.134464" />
    <position name="hand_right_rh_pinky_mcp_pitch_act" joint="hand_right_rh_pinky_mcp_pitch" kp="20" kv="2" ctrlrange="0 1.134464" />
  </actuator>
  <equality>
    <joint name="hand_left_lh_couple_index" joint1="hand_left_lh_index_dip" joint2="hand_left_lh_index_mcp_pitch" polycoef="0 1.125676 0 0 0" />
    <joint name="hand_left_lh_couple_middle" joint1="hand_left_lh_middle_dip" joint2="hand_left_lh_middle_mcp_pitch" polycoef="0 1.125676 0 0 0" />
    <joint name="hand_left_lh_couple_ring" joint1="hand_left_lh_ring_dip" joint2="hand_left_lh_ring_mcp_pitch" polycoef="0 1.125676 0 0 0" />
    <joint name="hand_left_lh_couple_pinky" joint1="hand_left_lh_pinky_dip" joint2="hand_left_lh_pinky_mcp_pitch" polycoef="0 1.125676 0 0 0" />
    <joint name="hand_left_lh_couple_thumb" joint1="hand_left_lh_thumb_dip" joint2="hand_left_lh_thumb_cmc_pitch" polycoef="0 1.226495 0 0 0" />
    <joint name="hand_right_rh_couple_index" joint1="hand_right_rh_index_dip" joint2="hand_right_rh_index_mcp_pitch" polycoef="0 1.125676 0 0 0" />
    <joint name="hand_right_rh_couple_middle" joint1="hand_right_rh_middle_dip" joint2="hand_right_rh_middle_mcp_pitch" polycoef="0 1.125676 0 0 0" />
    <joint name="hand_right_rh_couple_ring" joint1="hand_right_rh_ring_dip" joint2="hand_right_rh_ring_mcp_pitch" polycoef="0 1.125676 0 0 0" />
    <joint name="hand_right_rh_couple_pinky" joint1="hand_right_rh_pinky_dip" joint2="hand_right_rh_pinky_mcp_pitch" polycoef="0 1.125676 0 0 0" />
    <joint name="hand_right_rh_couple_thumb" joint1="hand_right_rh_thumb_dip" joint2="hand_right_rh_thumb_cmc_pitch" polycoef="0 1.226495 0 0 0" />
  </equality>
  <contact>
    <exclude body1="arm_left_L1_Link" body2="arm_left_L2_Link" />
    <exclude body1="arm_left_L2_Link" body2="arm_left_L3_Link" />
    <exclude body1="arm_left_L3_Link" body2="arm_left_L4_Link" />
    <exclude body1="arm_left_L4_Link" body2="arm_left_L5_Link" />
    <exclude body1="arm_left_L5_Link" body2="arm_left_L6_Link" />
    <exclude body1="arm_left_L6_Link" body2="arm_left_L7_Link" />
    <exclude body1="arm_left_L7_Link" body2="arm_left_L8_Link" />
    <exclude body1="arm_right_R1_Link" body2="arm_right_R2_Link" />
    <exclude body1="arm_right_R2_Link" body2="arm_right_R3_Link" />
    <exclude body1="arm_right_R3_Link" body2="arm_right_R4_Link" />
    <exclude body1="arm_right_R4_Link" body2="arm_right_R5_Link" />
    <exclude body1="arm_right_R5_Link" body2="arm_right_R6_Link" />
    <exclude body1="arm_right_R6_Link" body2="arm_right_R7_Link" />
    <exclude body1="arm_right_R7_Link" body2="arm_right_R8_Link" />
    <exclude body1="hand_left_lh_hand_base_link" body2="hand_left_lh_thumb_metacarpals_base1" />
    <exclude body1="hand_left_lh_thumb_metacarpals_base1" body2="hand_left_lh_thumb_metacarpals" />
    <exclude body1="hand_left_lh_thumb_metacarpals" body2="hand_left_lh_thumb_distal" />
    <exclude body1="hand_left_lh_hand_base_link" body2="hand_left_lh_index_proximal" />
    <exclude body1="hand_left_lh_index_proximal" body2="hand_left_lh_index_distal" />
    <exclude body1="hand_left_lh_hand_base_link" body2="hand_left_lh_middle_proximal" />
    <exclude body1="hand_left_lh_middle_proximal" body2="hand_left_lh_middle_distal" />
    <exclude body1="hand_left_lh_hand_base_link" body2="hand_left_lh_ring_proximal" />
    <exclude body1="hand_left_lh_ring_proximal" body2="hand_left_lh_ring_distal" />
    <exclude body1="hand_left_lh_hand_base_link" body2="hand_left_lh_pinky_proximal" />
    <exclude body1="hand_left_lh_pinky_proximal" body2="hand_left_lh_pinky_distal" />
    <exclude body1="hand_right_rh_hand_base_link" body2="hand_right_rh_thumb_metacarpals_base1" />
    <exclude body1="hand_right_rh_thumb_metacarpals_base1" body2="hand_right_rh_thumb_metacarpals" />
    <exclude body1="hand_right_rh_thumb_metacarpals" body2="hand_right_rh_thumb_distal" />
    <exclude body1="hand_right_rh_hand_base_link" body2="hand_right_rh_index_proximal" />
    <exclude body1="hand_right_rh_index_proximal" body2="hand_right_rh_index_distal" />
    <exclude body1="hand_right_rh_hand_base_link" body2="hand_right_rh_middle_proximal" />
    <exclude body1="hand_right_rh_middle_proximal" body2="hand_right_rh_middle_distal" />
    <exclude body1="hand_right_rh_hand_base_link" body2="hand_right_rh_ring_proximal" />
    <exclude body1="hand_right_rh_ring_proximal" body2="hand_right_rh_ring_distal" />
    <exclude body1="hand_right_rh_hand_base_link" body2="hand_right_rh_pinky_proximal" />
    <exclude body1="hand_right_rh_pinky_proximal" body2="hand_right_rh_pinky_distal" />
    <exclude body1="base_base_link" body2="arm_left_L1_Link" />
    <exclude body1="base_base_link" body2="arm_left_L2_Link" />
    <exclude body1="base_base_link" body2="arm_left_L3_Link" />
    <exclude body1="base_base_link" body2="arm_left_L4_Link" />
    <exclude body1="base_base_link" body2="arm_left_L5_Link" />
    <exclude body1="base_base_link" body2="arm_left_L6_Link" />
    <exclude body1="base_base_link" body2="arm_left_L7_Link" />
    <exclude body1="base_base_link" body2="arm_left_L8_Link" />
    <exclude body1="base_base_link" body2="arm_right_R1_Link" />
    <exclude body1="base_base_link" body2="arm_right_R2_Link" />
    <exclude body1="base_base_link" body2="arm_right_R3_Link" />
    <exclude body1="base_base_link" body2="arm_right_R4_Link" />
    <exclude body1="base_base_link" body2="arm_right_R5_Link" />
    <exclude body1="base_base_link" body2="arm_right_R6_Link" />
    <exclude body1="base_base_link" body2="arm_right_R7_Link" />
    <exclude body1="base_base_link" body2="arm_right_R8_Link" />
    <exclude body1="arm_left_L1_Link" body2="hand_left_lh_hand_base_link" />
    <exclude body1="arm_left_L1_Link" body2="hand_left_lh_thumb_metacarpals_base1" />
    <exclude body1="arm_left_L1_Link" body2="hand_left_lh_thumb_metacarpals" />
    <exclude body1="arm_left_L1_Link" body2="hand_left_lh_thumb_distal" />
    <exclude body1="arm_left_L1_Link" body2="hand_left_lh_index_proximal" />
    <exclude body1="arm_left_L1_Link" body2="hand_left_lh_index_distal" />
    <exclude body1="arm_left_L1_Link" body2="hand_left_lh_middle_proximal" />
    <exclude body1="arm_left_L1_Link" body2="hand_left_lh_middle_distal" />
    <exclude body1="arm_left_L1_Link" body2="hand_left_lh_ring_proximal" />
    <exclude body1="arm_left_L1_Link" body2="hand_left_lh_ring_distal" />
    <exclude body1="arm_left_L1_Link" body2="hand_left_lh_pinky_proximal" />
    <exclude body1="arm_left_L1_Link" body2="hand_left_lh_pinky_distal" />
    <exclude body1="arm_left_L2_Link" body2="hand_left_lh_hand_base_link" />
    <exclude body1="arm_left_L2_Link" body2="hand_left_lh_thumb_metacarpals_base1" />
    <exclude body1="arm_left_L2_Link" body2="hand_left_lh_thumb_metacarpals" />
    <exclude body1="arm_left_L2_Link" body2="hand_left_lh_thumb_distal" />
    <exclude body1="arm_left_L2_Link" body2="hand_left_lh_index_proximal" />
    <exclude body1="arm_left_L2_Link" body2="hand_left_lh_index_distal" />
    <exclude body1="arm_left_L2_Link" body2="hand_left_lh_middle_proximal" />
    <exclude body1="arm_left_L2_Link" body2="hand_left_lh_middle_distal" />
    <exclude body1="arm_left_L2_Link" body2="hand_left_lh_ring_proximal" />
    <exclude body1="arm_left_L2_Link" body2="hand_left_lh_ring_distal" />
    <exclude body1="arm_left_L2_Link" body2="hand_left_lh_pinky_proximal" />
    <exclude body1="arm_left_L2_Link" body2="hand_left_lh_pinky_distal" />
    <exclude body1="arm_left_L3_Link" body2="hand_left_lh_hand_base_link" />
    <exclude body1="arm_left_L3_Link" body2="hand_left_lh_thumb_metacarpals_base1" />
    <exclude body1="arm_left_L3_Link" body2="hand_left_lh_thumb_metacarpals" />
    <exclude body1="arm_left_L3_Link" body2="hand_left_lh_thumb_distal" />
    <exclude body1="arm_left_L3_Link" body2="hand_left_lh_index_proximal" />
    <exclude body1="arm_left_L3_Link" body2="hand_left_lh_index_distal" />
    <exclude body1="arm_left_L3_Link" body2="hand_left_lh_middle_proximal" />
    <exclude body1="arm_left_L3_Link" body2="hand_left_lh_middle_distal" />
    <exclude body1="arm_left_L3_Link" body2="hand_left_lh_ring_proximal" />
    <exclude body1="arm_left_L3_Link" body2="hand_left_lh_ring_distal" />
    <exclude body1="arm_left_L3_Link" body2="hand_left_lh_pinky_proximal" />
    <exclude body1="arm_left_L3_Link" body2="hand_left_lh_pinky_distal" />
    <exclude body1="arm_left_L4_Link" body2="hand_left_lh_hand_base_link" />
    <exclude body1="arm_left_L4_Link" body2="hand_left_lh_thumb_metacarpals_base1" />
    <exclude body1="arm_left_L4_Link" body2="hand_left_lh_thumb_metacarpals" />
    <exclude body1="arm_left_L4_Link" body2="hand_left_lh_thumb_distal" />
    <exclude body1="arm_left_L4_Link" body2="hand_left_lh_index_proximal" />
    <exclude body1="arm_left_L4_Link" body2="hand_left_lh_index_distal" />
    <exclude body1="arm_left_L4_Link" body2="hand_left_lh_middle_proximal" />
    <exclude body1="arm_left_L4_Link" body2="hand_left_lh_middle_distal" />
    <exclude body1="arm_left_L4_Link" body2="hand_left_lh_ring_proximal" />
    <exclude body1="arm_left_L4_Link" body2="hand_left_lh_ring_distal" />
    <exclude body1="arm_left_L4_Link" body2="hand_left_lh_pinky_proximal" />
    <exclude body1="arm_left_L4_Link" body2="hand_left_lh_pinky_distal" />
    <exclude body1="arm_left_L5_Link" body2="hand_left_lh_hand_base_link" />
    <exclude body1="arm_left_L5_Link" body2="hand_left_lh_thumb_metacarpals_base1" />
    <exclude body1="arm_left_L5_Link" body2="hand_left_lh_thumb_metacarpals" />
    <exclude body1="arm_left_L5_Link" body2="hand_left_lh_thumb_distal" />
    <exclude body1="arm_left_L5_Link" body2="hand_left_lh_index_proximal" />
    <exclude body1="arm_left_L5_Link" body2="hand_left_lh_index_distal" />
    <exclude body1="arm_left_L5_Link" body2="hand_left_lh_middle_proximal" />
    <exclude body1="arm_left_L5_Link" body2="hand_left_lh_middle_distal" />
    <exclude body1="arm_left_L5_Link" body2="hand_left_lh_ring_proximal" />
    <exclude body1="arm_left_L5_Link" body2="hand_left_lh_ring_distal" />
    <exclude body1="arm_left_L5_Link" body2="hand_left_lh_pinky_proximal" />
    <exclude body1="arm_left_L5_Link" body2="hand_left_lh_pinky_distal" />
    <exclude body1="arm_left_L6_Link" body2="hand_left_lh_hand_base_link" />
    <exclude body1="arm_left_L6_Link" body2="hand_left_lh_thumb_metacarpals_base1" />
    <exclude body1="arm_left_L6_Link" body2="hand_left_lh_thumb_metacarpals" />
    <exclude body1="arm_left_L6_Link" body2="hand_left_lh_thumb_distal" />
    <exclude body1="arm_left_L6_Link" body2="hand_left_lh_index_proximal" />
    <exclude body1="arm_left_L6_Link" body2="hand_left_lh_index_distal" />
    <exclude body1="arm_left_L6_Link" body2="hand_left_lh_middle_proximal" />
    <exclude body1="arm_left_L6_Link" body2="hand_left_lh_middle_distal" />
    <exclude body1="arm_left_L6_Link" body2="hand_left_lh_ring_proximal" />
    <exclude body1="arm_left_L6_Link" body2="hand_left_lh_ring_distal" />
    <exclude body1="arm_left_L6_Link" body2="hand_left_lh_pinky_proximal" />
    <exclude body1="arm_left_L6_Link" body2="hand_left_lh_pinky_distal" />
    <exclude body1="arm_left_L7_Link" body2="hand_left_lh_hand_base_link" />
    <exclude body1="arm_left_L7_Link" body2="hand_left_lh_thumb_metacarpals_base1" />
    <exclude body1="arm_left_L7_Link" body2="hand_left_lh_thumb_metacarpals" />
    <exclude body1="arm_left_L7_Link" body2="hand_left_lh_thumb_distal" />
    <exclude body1="arm_left_L7_Link" body2="hand_left_lh_index_proximal" />
    <exclude body1="arm_left_L7_Link" body2="hand_left_lh_index_distal" />
    <exclude body1="arm_left_L7_Link" body2="hand_left_lh_middle_proximal" />
    <exclude body1="arm_left_L7_Link" body2="hand_left_lh_middle_distal" />
    <exclude body1="arm_left_L7_Link" body2="hand_left_lh_ring_proximal" />
    <exclude body1="arm_left_L7_Link" body2="hand_left_lh_ring_distal" />
    <exclude body1="arm_left_L7_Link" body2="hand_left_lh_pinky_proximal" />
    <exclude body1="arm_left_L7_Link" body2="hand_left_lh_pinky_distal" />
    <exclude body1="arm_left_L8_Link" body2="hand_left_lh_hand_base_link" />
    <exclude body1="arm_left_L8_Link" body2="hand_left_lh_thumb_metacarpals_base1" />
    <exclude body1="arm_left_L8_Link" body2="hand_left_lh_thumb_metacarpals" />
    <exclude body1="arm_left_L8_Link" body2="hand_left_lh_thumb_distal" />
    <exclude body1="arm_left_L8_Link" body2="hand_left_lh_index_proximal" />
    <exclude body1="arm_left_L8_Link" body2="hand_left_lh_index_distal" />
    <exclude body1="arm_left_L8_Link" body2="hand_left_lh_middle_proximal" />
    <exclude body1="arm_left_L8_Link" body2="hand_left_lh_middle_distal" />
    <exclude body1="arm_left_L8_Link" body2="hand_left_lh_ring_proximal" />
    <exclude body1="arm_left_L8_Link" body2="hand_left_lh_ring_distal" />
    <exclude body1="arm_left_L8_Link" body2="hand_left_lh_pinky_proximal" />
    <exclude body1="arm_left_L8_Link" body2="hand_left_lh_pinky_distal" />
    <exclude body1="base_base_link" body2="hand_left_lh_hand_base_link" />
    <exclude body1="base_base_link" body2="hand_left_lh_thumb_metacarpals_base1" />
    <exclude body1="base_base_link" body2="hand_left_lh_thumb_metacarpals" />
    <exclude body1="base_base_link" body2="hand_left_lh_thumb_distal" />
    <exclude body1="base_base_link" body2="hand_left_lh_index_proximal" />
    <exclude body1="base_base_link" body2="hand_left_lh_index_distal" />
    <exclude body1="base_base_link" body2="hand_left_lh_middle_proximal" />
    <exclude body1="base_base_link" body2="hand_left_lh_middle_distal" />
    <exclude body1="base_base_link" body2="hand_left_lh_ring_proximal" />
    <exclude body1="base_base_link" body2="hand_left_lh_ring_distal" />
    <exclude body1="base_base_link" body2="hand_left_lh_pinky_proximal" />
    <exclude body1="base_base_link" body2="hand_left_lh_pinky_distal" />
    <exclude body1="arm_right_R1_Link" body2="hand_right_rh_hand_base_link" />
    <exclude body1="arm_right_R1_Link" body2="hand_right_rh_thumb_metacarpals_base1" />
    <exclude body1="arm_right_R1_Link" body2="hand_right_rh_thumb_metacarpals" />
    <exclude body1="arm_right_R1_Link" body2="hand_right_rh_thumb_distal" />
    <exclude body1="arm_right_R1_Link" body2="hand_right_rh_index_proximal" />
    <exclude body1="arm_right_R1_Link" body2="hand_right_rh_index_distal" />
    <exclude body1="arm_right_R1_Link" body2="hand_right_rh_middle_proximal" />
    <exclude body1="arm_right_R1_Link" body2="hand_right_rh_middle_distal" />
    <exclude body1="arm_right_R1_Link" body2="hand_right_rh_ring_proximal" />
    <exclude body1="arm_right_R1_Link" body2="hand_right_rh_ring_distal" />
    <exclude body1="arm_right_R1_Link" body2="hand_right_rh_pinky_proximal" />
    <exclude body1="arm_right_R1_Link" body2="hand_right_rh_pinky_distal" />
    <exclude body1="arm_right_R2_Link" body2="hand_right_rh_hand_base_link" />
    <exclude body1="arm_right_R2_Link" body2="hand_right_rh_thumb_metacarpals_base1" />
    <exclude body1="arm_right_R2_Link" body2="hand_right_rh_thumb_metacarpals" />
    <exclude body1="arm_right_R2_Link" body2="hand_right_rh_thumb_distal" />
    <exclude body1="arm_right_R2_Link" body2="hand_right_rh_index_proximal" />
    <exclude body1="arm_right_R2_Link" body2="hand_right_rh_index_distal" />
    <exclude body1="arm_right_R2_Link" body2="hand_right_rh_middle_proximal" />
    <exclude body1="arm_right_R2_Link" body2="hand_right_rh_middle_distal" />
    <exclude body1="arm_right_R2_Link" body2="hand_right_rh_ring_proximal" />
    <exclude body1="arm_right_R2_Link" body2="hand_right_rh_ring_distal" />
    <exclude body1="arm_right_R2_Link" body2="hand_right_rh_pinky_proximal" />
    <exclude body1="arm_right_R2_Link" body2="hand_right_rh_pinky_distal" />
    <exclude body1="arm_right_R3_Link" body2="hand_right_rh_hand_base_link" />
    <exclude body1="arm_right_R3_Link" body2="hand_right_rh_thumb_metacarpals_base1" />
    <exclude body1="arm_right_R3_Link" body2="hand_right_rh_thumb_metacarpals" />
    <exclude body1="arm_right_R3_Link" body2="hand_right_rh_thumb_distal" />
    <exclude body1="arm_right_R3_Link" body2="hand_right_rh_index_proximal" />
    <exclude body1="arm_right_R3_Link" body2="hand_right_rh_index_distal" />
    <exclude body1="arm_right_R3_Link" body2="hand_right_rh_middle_proximal" />
    <exclude body1="arm_right_R3_Link" body2="hand_right_rh_middle_distal" />
    <exclude body1="arm_right_R3_Link" body2="hand_right_rh_ring_proximal" />
    <exclude body1="arm_right_R3_Link" body2="hand_right_rh_ring_distal" />
    <exclude body1="arm_right_R3_Link" body2="hand_right_rh_pinky_proximal" />
    <exclude body1="arm_right_R3_Link" body2="hand_right_rh_pinky_distal" />
    <exclude body1="arm_right_R4_Link" body2="hand_right_rh_hand_base_link" />
    <exclude body1="arm_right_R4_Link" body2="hand_right_rh_thumb_metacarpals_base1" />
    <exclude body1="arm_right_R4_Link" body2="hand_right_rh_thumb_metacarpals" />
    <exclude body1="arm_right_R4_Link" body2="hand_right_rh_thumb_distal" />
    <exclude body1="arm_right_R4_Link" body2="hand_right_rh_index_proximal" />
    <exclude body1="arm_right_R4_Link" body2="hand_right_rh_index_distal" />
    <exclude body1="arm_right_R4_Link" body2="hand_right_rh_middle_proximal" />
    <exclude body1="arm_right_R4_Link" body2="hand_right_rh_middle_distal" />
    <exclude body1="arm_right_R4_Link" body2="hand_right_rh_ring_proximal" />
    <exclude body1="arm_right_R4_Link" body2="hand_right_rh_ring_distal" />
    <exclude body1="arm_right_R4_Link" body2="hand_right_rh_pinky_proximal" />
    <exclude body1="arm_right_R4_Link" body2="hand_right_rh_pinky_distal" />
    <exclude body1="arm_right_R5_Link" body2="hand_right_rh_hand_base_link" />
    <exclude body1="arm_right_R5_Link" body2="hand_right_rh_thumb_metacarpals_base1" />
    <exclude body1="arm_right_R5_Link" body2="hand_right_rh_thumb_metacarpals" />
    <exclude body1="arm_right_R5_Link" body2="hand_right_rh_thumb_distal" />
    <exclude body1="arm_right_R5_Link" body2="hand_right_rh_index_proximal" />
    <exclude body1="arm_right_R5_Link" body2="hand_right_rh_index_distal" />
    <exclude body1="arm_right_R5_Link" body2="hand_right_rh_middle_proximal" />
    <exclude body1="arm_right_R5_Link" body2="hand_right_rh_middle_distal" />
    <exclude body1="arm_right_R5_Link" body2="hand_right_rh_ring_proximal" />
    <exclude body1="arm_right_R5_Link" body2="hand_right_rh_ring_distal" />
    <exclude body1="arm_right_R5_Link" body2="hand_right_rh_pinky_proximal" />
    <exclude body1="arm_right_R5_Link" body2="hand_right_rh_pinky_distal" />
    <exclude body1="arm_right_R6_Link" body2="hand_right_rh_hand_base_link" />
    <exclude body1="arm_right_R6_Link" body2="hand_right_rh_thumb_metacarpals_base1" />
    <exclude body1="arm_right_R6_Link" body2="hand_right_rh_thumb_metacarpals" />
    <exclude body1="arm_right_R6_Link" body2="hand_right_rh_thumb_distal" />
    <exclude body1="arm_right_R6_Link" body2="hand_right_rh_index_proximal" />
    <exclude body1="arm_right_R6_Link" body2="hand_right_rh_index_distal" />
    <exclude body1="arm_right_R6_Link" body2="hand_right_rh_middle_proximal" />
    <exclude body1="arm_right_R6_Link" body2="hand_right_rh_middle_distal" />
    <exclude body1="arm_right_R6_Link" body2="hand_right_rh_ring_proximal" />
    <exclude body1="arm_right_R6_Link" body2="hand_right_rh_ring_distal" />
    <exclude body1="arm_right_R6_Link" body2="hand_right_rh_pinky_proximal" />
    <exclude body1="arm_right_R6_Link" body2="hand_right_rh_pinky_distal" />
    <exclude body1="arm_right_R7_Link" body2="hand_right_rh_hand_base_link" />
    <exclude body1="arm_right_R7_Link" body2="hand_right_rh_thumb_metacarpals_base1" />
    <exclude body1="arm_right_R7_Link" body2="hand_right_rh_thumb_metacarpals" />
    <exclude body1="arm_right_R7_Link" body2="hand_right_rh_thumb_distal" />
    <exclude body1="arm_right_R7_Link" body2="hand_right_rh_index_proximal" />
    <exclude body1="arm_right_R7_Link" body2="hand_right_rh_index_distal" />
    <exclude body1="arm_right_R7_Link" body2="hand_right_rh_middle_proximal" />
    <exclude body1="arm_right_R7_Link" body2="hand_right_rh_middle_distal" />
    <exclude body1="arm_right_R7_Link" body2="hand_right_rh_ring_proximal" />
    <exclude body1="arm_right_R7_Link" body2="hand_right_rh_ring_distal" />
    <exclude body1="arm_right_R7_Link" body2="hand_right_rh_pinky_proximal" />
    <exclude body1="arm_right_R7_Link" body2="hand_right_rh_pinky_distal" />
    <exclude body1="arm_right_R8_Link" body2="hand_right_rh_hand_base_link" />
    <exclude body1="arm_right_R8_Link" body2="hand_right_rh_thumb_metacarpals_base1" />
    <exclude body1="arm_right_R8_Link" body2="hand_right_rh_thumb_metacarpals" />
    <exclude body1="arm_right_R8_Link" body2="hand_right_rh_thumb_distal" />
    <exclude body1="arm_right_R8_Link" body2="hand_right_rh_index_proximal" />
    <exclude body1="arm_right_R8_Link" body2="hand_right_rh_index_distal" />
    <exclude body1="arm_right_R8_Link" body2="hand_right_rh_middle_proximal" />
    <exclude body1="arm_right_R8_Link" body2="hand_right_rh_middle_distal" />
    <exclude body1="arm_right_R8_Link" body2="hand_right_rh_ring_proximal" />
    <exclude body1="arm_right_R8_Link" body2="hand_right_rh_ring_distal" />
    <exclude body1="arm_right_R8_Link" body2="hand_right_rh_pinky_proximal" />
    <exclude body1="arm_right_R8_Link" body2="hand_right_rh_pinky_distal" />
    <exclude body1="base_base_link" body2="hand_right_rh_hand_base_link" />
    <exclude body1="base_base_link" body2="hand_right_rh_thumb_metacarpals_base1" />
    <exclude body1="base_base_link" body2="hand_right_rh_thumb_metacarpals" />
    <exclude body1="base_base_link" body2="hand_right_rh_thumb_distal" />
    <exclude body1="base_base_link" body2="hand_right_rh_index_proximal" />
    <exclude body1="base_base_link" body2="hand_right_rh_index_distal" />
    <exclude body1="base_base_link" body2="hand_right_rh_middle_proximal" />
    <exclude body1="base_base_link" body2="hand_right_rh_middle_distal" />
    <exclude body1="base_base_link" body2="hand_right_rh_ring_proximal" />
    <exclude body1="base_base_link" body2="hand_right_rh_ring_distal" />
    <exclude body1="base_base_link" body2="hand_right_rh_pinky_proximal" />
    <exclude body1="base_base_link" body2="hand_right_rh_pinky_distal" />
  </contact>
</mujoco>
