<?xml version="1.0" encoding="UTF-8"?>
<!-- Generated by linker_robot_assets.composer (version 0.1.0). Workstation: ar5_l25_bench_bimanual. Recipe sha256: 4efed38a679f1ace49ebc4efe9685f0cb63c580dd622199cb6f1d84a8b9cfc37. Do not edit by hand; re-run `python -m linker_robot_assets.composer.compose <workstation>`. -->
<robot name="ar5_l25_bench_bimanual">
  <link name="world" />
  <material name="arm_left_black">
    <color rgba="0.0 0.0 0.0 1.0" />
  </material>
  <material name="arm_left_blue">
    <color rgba="0.0 0.0 0.8 1.0" />
  </material>
  <material name="arm_left_green">
    <color rgba="0.0 0.8 0.0 1.0" />
  </material>
  <material name="arm_left_grey">
    <color rgba="0.2 0.2 0.2 1.0" />
  </material>
  <material name="arm_left_orange">
    <color rgba="1.0 0.423529411765 0.0392156862745 1.0" />
  </material>
  <material name="arm_left_brown">
    <color rgba="0.870588235294 0.811764705882 0.764705882353 1.0" />
  </material>
  <material name="arm_left_red">
    <color rgba="0.8 0.0 0.0 1.0" />
  </material>
  <material name="arm_left_white">
    <color rgba="1.0 1.0 1.0 1.0" />
  </material>
  <material name="arm_left_Beige">
    <color rgba="1.0 0.784 0.5765 1.0" />
  </material>
  <material name="arm_right_black">
    <color rgba="0.0 0.0 0.0 1.0" />
  </material>
  <material name="arm_right_blue">
    <color rgba="0.0 0.0 0.8 1.0" />
  </material>
  <material name="arm_right_green">
    <color rgba="0.0 0.8 0.0 1.0" />
  </material>
  <material name="arm_right_grey">
    <color rgba="0.2 0.2 0.2 1.0" />
  </material>
  <material name="arm_right_orange">
    <color rgba="1.0 0.423529411765 0.0392156862745 1.0" />
  </material>
  <material name="arm_right_brown">
    <color rgba="0.870588235294 0.811764705882 0.764705882353 1.0" />
  </material>
  <material name="arm_right_red">
    <color rgba="0.8 0.0 0.0 1.0" />
  </material>
  <material name="arm_right_white">
    <color rgba="1.0 1.0 1.0 1.0" />
  </material>
  <material name="arm_right_Beige">
    <color rgba="1.0 0.784 0.5765 1.0" />
  </material>
  <link name="base_workstation_link">
    <visual>
      <origin xyz="0 0 0" rpy="0 0 0" />
      <geometry>
        <mesh filename="../../components/bases/bench_table/variants/default/meshes/workstation.STL" />
      </geometry>
      <material name="base_workstation_gray">
        <color rgba="0.6 0.6 0.6 1.0" />
      </material>
    </visual>
    <collision>
      <origin xyz="0 0 0" rpy="0 0 0" />
      <geometry>
        <mesh filename="../../components/bases/bench_table/variants/default/meshes/workstation.STL" />
      </geometry>
    </collision>
    <inertial>
      <origin xyz="0 0 0" rpy="0 0 0" />
      <mass value="50.0" />
      <inertia ixx="1.0" ixy="0.0" ixz="0.0" iyy="1.0" iyz="0.0" izz="1.0" />
    </inertial>
  </link>
  <link name="base_camera_base_link">
    <inertial>
      <origin xyz="0.0538773695 0.0404431717 0.0338436904" rpy="0 0 0" />
      <mass value="0.120253078965696" />
      <inertia ixx="0.00024086634809874" ixy="1.11484097335586E-05" ixz="3.07915341770146E-05" iyy="0.000340317013404989" iyz="-5.88336477049719E-05" izz="0.000187914824387855" />
    </inertial>
    <visual>
      <origin xyz="0 0 0" rpy="0 0 0" />
      <geometry>
        <mesh filename="../../components/bases/bench_table/variants/default/meshes/camera_base_link.STL" />
      </geometry>
      <material name="">
        <color rgba="0.792156862745098 0.819607843137255 0.933333333333333 1" />
      </material>
    </visual>
    <collision>
      <origin xyz="0 0 0" rpy="0 0 0" />
      <geometry>
        <mesh filename="../../components/bases/bench_table/variants/default/meshes/camera_base_link.STL" />
      </geometry>
    </collision>
  </link>
  <link name="base_camera">
    <inertial>
      <origin xyz="0.435583907 -0.11451791 -0.00087379797" rpy="0 0 0" />
      <mass value="0.170230158191785" />
      <inertia ixx="0.000388607098441677" ixy="-3.21389374232659E-06" ixz="1.01075980515721E-06" iyy="0.000353185511381015" iyz="-0.000100865226288639" izz="6.42979907249093E-05" />
    </inertial>
    <visual>
      <origin xyz="0 0 0" rpy="0 0 0" />
      <geometry>
        <mesh filename="../../components/bases/bench_table/variants/default/meshes/camera.STL" />
      </geometry>
      <material name="">
        <color rgba="0.792156862745098 0.819607843137255 0.933333333333333 1" />
      </material>
    </visual>
    <collision>
      <origin xyz="0 0 0" rpy="0 0 0" />
      <geometry>
        <mesh filename="../../components/bases/bench_table/variants/default/meshes/camera.STL" />
      </geometry>
    </collision>
  </link>
  <link name="base_workstation_arm_left_mount" />
  <link name="base_workstation_arm_right_mount" />
  <link name="arm_left_AR5_5_07L_W4C4A2_base">
    <visual>
      <geometry>
        <mesh filename="../../components/arms/ar5/variants/left/meshes/AR5_5_07L_W4C4A2_base.stl" scale="0.001 0.001 0.001" />
      </geometry>
      <origin rpy="0 0 0" xyz="0 0 0" />
      <material name="arm_left_white" />
    </visual>
    <collision>
      <geometry>
        <mesh filename="../../components/arms/ar5/variants/left/meshes/AR5_5_07L_W4C4A2_base.stl" scale="0.001 0.001 0.001" />
      </geometry>
      <origin rpy="0 0 0" xyz="0 0 0" />
    </collision>
  </link>
  <link name="arm_left_AR5_5_07L_W4C4A2_link1">
    <visual>
      <geometry>
        <mesh filename="../../components/arms/ar5/variants/left/meshes/AR5_5_07L_W4C4A2_link1.stl" scale="0.001 0.001 0.001" />
      </geometry>
      <origin rpy="0 0 0" xyz="0 0 0" />
      <material name="arm_left_white" />
    </visual>
    <inertial>
      <mass value="2.683" />
      <inertia ixx="0.00493673" ixy="0.00000160" ixz="0.00000198" iyy="0.00452344" iyz="-0.00000020" izz="0.00432910" />
      <origin rpy="0 0 0" xyz="1e-06 -0.000621 0.167909" />
    </inertial>
    <collision>
      <geometry>
        <mesh filename="../../components/arms/ar5/variants/left/meshes/AR5_5_07L_W4C4A2_link1.stl" scale="0.001 0.001 0.001" />
      </geometry>
      <origin rpy="0 0 0" xyz="0 0 0" />
    </collision>
  </link>
  <link name="arm_left_AR5_5_07L_W4C4A2_link2">
    <visual>
      <geometry>
        <mesh filename="../../components/arms/ar5/variants/left/meshes/AR5_5_07L_W4C4A2_link2.stl" scale="0.001 0.001 0.001" />
      </geometry>
      <origin rpy="0 0 0" xyz="0 0 0" />
      <material name="arm_left_white" />
    </visual>
    <inertial>
      <mass value="2.3" />
      <inertia ixx="0.01151906" ixy="0.00000246" ixz="-0.00000055" iyy="0.00993335" iyz="0.00082477" izz="0.00435237" />
      <origin rpy="0 0 0" xyz="-2e-05 -0.003081 0.102986" />
    </inertial>
    <collision>
      <geometry>
        <mesh filename="../../components/arms/ar5/variants/left/meshes/AR5_5_07L_W4C4A2_link2.stl" scale="0.001 0.001 0.001" />
      </geometry>
      <origin rpy="0 0 0" xyz="0 0 0" />
    </collision>
  </link>
  <link name="arm_left_AR5_5_07L_W4C4A2_link3">
    <visual>
      <geometry>
        <mesh filename="../../components/arms/ar5/variants/left/meshes/AR5_5_07L_W4C4A2_link3.stl" scale="0.001 0.001 0.001" />
      </geometry>
      <origin rpy="0 0 0" xyz="0 0 0" />
      <material name="arm_left_white" />
    </visual>
    <inertial>
      <mass value="1.862" />
      <inertia ixx="0.00519681" ixy="0.00001208" ixz="0.00035761" iyy="0.00470446" iyz="0.00003430" izz="0.00266752" />
      <origin rpy="0 0 0" xyz="0.007097 -0.000659 -0.016531" />
    </inertial>
    <collision>
      <geometry>
        <mesh filename="../../components/arms/ar5/variants/left/meshes/AR5_5_07L_W4C4A2_link3.stl" scale="0.001 0.001 0.001" />
      </geometry>
      <origin rpy="0 0 0" xyz="0 0 0" />
    </collision>
  </link>
  <link name="arm_left_AR5_5_07L_W4C4A2_link4">
    <visual>
      <geometry>
        <mesh filename="../../components/arms/ar5/variants/left/meshes/AR5_5_07L_W4C4A2_link4.stl" scale="0.001 0.001 0.001" />
      </geometry>
      <origin rpy="0 0 0" xyz="0 0 0" />
      <material name="arm_left_white" />
    </visual>
    <inertial>
      <mass value="1.234" />
      <inertia ixx="0.00389590" ixy="-0.00004577" ixz="-0.00017280" iyy="0.00308657" iyz="0.00046679" izz="0.00188364" />
      <origin rpy="0 0 0" xyz="-0.007826 -0.004207 0.073404" />
    </inertial>
    <collision>
      <geometry>
        <mesh filename="../../components/arms/ar5/variants/left/meshes/AR5_5_07L_W4C4A2_link4.stl" scale="0.001 0.001 0.001" />
      </geometry>
      <origin rpy="0 0 0" xyz="0 0 0" />
    </collision>
  </link>
  <link name="arm_left_AR5_5_07L_W4C4A2_link5">
    <visual>
      <geometry>
        <mesh filename="../../components/arms/ar5/variants/left/meshes/AR5_5_07L_W4C4A2_link5.stl" scale="0.001 0.001 0.001" />
      </geometry>
      <origin rpy="0 0 0" xyz="0 0 0" />
      <material name="arm_left_white" />
    </visual>
    <inertial>
      <mass value="1.329" />
      <inertia ixx="0.00281562" ixy="0.00001782" ixz="0.00001650" iyy="0.00221084" iyz="0.00002100" izz="0.00182169" />
      <origin rpy="0 0 0" xyz="0.000284 0.001651 -0.084133" />
    </inertial>
    <collision>
      <geometry>
        <mesh filename="../../components/arms/ar5/variants/left/meshes/AR5_5_07L_W4C4A2_link5.stl" scale="0.001 0.001 0.001" />
      </geometry>
      <origin rpy="0 0 0" xyz="0 0 0" />
    </collision>
  </link>
  <link name="arm_left_AR5_5_07L_W4C4A2_link6">
    <visual>
      <geometry>
        <mesh filename="../../components/arms/ar5/variants/left/meshes/AR5_5_07L_W4C4A2_link6.stl" scale="0.001 0.001 0.001" />
      </geometry>
      <origin rpy="0 0 0" xyz="0 0 0" />
      <material name="arm_left_white" />
    </visual>
    <inertial>
      <mass value="0.93" />
      <inertia ixx="0.00072078" ixy="-0.00000217" ixz="0.00000108" iyy="0.00085153" iyz="0.00000048" izz="0.00090205" />
      <origin rpy="0 0 0" xyz="0.005406 0.000612 -3.9e-05" />
    </inertial>
    <collision>
      <geometry>
        <mesh filename="../../components/arms/ar5/variants/left/meshes/AR5_5_07L_W4C4A2_link6.stl" scale="0.001 0.001 0.001" />
      </geometry>
      <origin rpy="0 0 0" xyz="0 0 0" />
    </collision>
  </link>
  <link name="arm_left_AR5_5_07L_W4C4A2_link7">
    <visual>
      <geometry>
        <mesh filename="../../components/arms/ar5/variants/left/meshes/AR5_5_07L_W4C4A2_link7.stl" scale="0.001 0.001 0.001" />
      </geometry>
      <origin rpy="0 0 0" xyz="0 0 0" />
      <material name="arm_left_white" />
    </visual>
    <inertial>
      <mass value="0.33" />
      <inertia ixx="0.00051942" ixy="-0.00000052" ixz="0.00003721" iyy="0.00079132" iyz="0.00000265" izz="0.00045886" />
      <origin rpy="0 0 0" xyz="-0.00277 0.000316 0.054881" />
    </inertial>
    <collision>
      <geometry>
        <mesh filename="../../components/arms/ar5/variants/left/meshes/AR5_5_07L_W4C4A2_link7.stl" scale="0.001 0.001 0.001" />
      </geometry>
      <origin rpy="0 0 0" xyz="0 0 0" />
    </collision>
  </link>
  <link name="arm_left_AR5_5_07L_W4C4A2_tcp">
    <visual>
      <origin xyz="0 0 0" rpy="0 0 0" />
      <geometry>
        <box size="0.0001 0.0001 0.0001" />
      </geometry>
      <material name="arm_left_white" />
    </visual>
    <collision>
      <origin xyz="0 0 0" rpy="0 0 0" />
      <geometry>
        <box size="0.0001 0.0001 0.0001" />
      </geometry>
    </collision>
    <inertial>
      <mass value="0.0" />
      <inertia ixx="1e-6" ixy="0" ixz="0" iyy="1e-6" iyz="0" izz="1e-6" />
    </inertial>
  </link>
  <link name="arm_right_AR5_5_07R_W4C4A2_base">
    <visual>
      <geometry>
        <mesh filename="../../components/arms/ar5/variants/right/meshes/AR5_5_07R_W4C4A2_base.stl" scale="0.001 0.001 0.001" />
      </geometry>
      <origin rpy="0 0 0" xyz="0 0 0" />
      <material name="arm_right_white" />
    </visual>
    <collision>
      <geometry>
        <mesh filename="../../components/arms/ar5/variants/right/meshes/AR5_5_07R_W4C4A2_base.stl" scale="0.001 0.001 0.001" />
      </geometry>
      <origin rpy="0 0 0" xyz="0 0 0" />
    </collision>
  </link>
  <link name="arm_right_AR5_5_07R_W4C4A2_link1">
    <visual>
      <geometry>
        <mesh filename="../../components/arms/ar5/variants/right/meshes/AR5_5_07R_W4C4A2_link1.stl" scale="0.001 0.001 0.001" />
      </geometry>
      <origin rpy="0 0 0" xyz="0 0 0" />
      <material name="arm_right_white" />
    </visual>
    <inertial>
      <mass value="2.683" />
      <inertia ixx="0.00493673" ixy="0.00000160" ixz="-0.00000198" iyy="0.00452344" iyz="0.00000020" izz="0.00432910" />
      <origin rpy="0 0 0" xyz="-1e-06 0.000621 0.167909" />
    </inertial>
    <collision>
      <geometry>
        <mesh filename="../../components/arms/ar5/variants/right/meshes/AR5_5_07R_W4C4A2_link1.stl" scale="0.001 0.001 0.001" />
      </geometry>
      <origin rpy="0 0 0" xyz="0 0 0" />
    </collision>
  </link>
  <link name="arm_right_AR5_5_07R_W4C4A2_link2">
    <visual>
      <geometry>
        <mesh filename="../../components/arms/ar5/variants/right/meshes/AR5_5_07R_W4C4A2_link2.stl" scale="0.001 0.001 0.001" />
      </geometry>
      <origin rpy="0 0 0" xyz="0 0 0" />
      <material name="arm_right_white" />
    </visual>
    <inertial>
      <mass value="2.3" />
      <inertia ixx="0.01151906" ixy="0.00000246" ixz="0.00000055" iyy="0.00993335" iyz="-0.00082477" izz="0.00435237" />
      <origin rpy="0 0 0" xyz="2e-05 0.003081 0.102986" />
    </inertial>
    <collision>
      <geometry>
        <mesh filename="../../components/arms/ar5/variants/right/meshes/AR5_5_07R_W4C4A2_link2.stl" scale="0.001 0.001 0.001" />
      </geometry>
      <origin rpy="0 0 0" xyz="0 0 0" />
    </collision>
  </link>
  <link name="arm_right_AR5_5_07R_W4C4A2_link3">
    <visual>
      <geometry>
        <mesh filename="../../components/arms/ar5/variants/right/meshes/AR5_5_07R_W4C4A2_link3.stl" scale="0.001 0.001 0.001" />
      </geometry>
      <origin rpy="0 0 0" xyz="0 0 0" />
      <material name="arm_right_white" />
    </visual>
    <inertial>
      <mass value="1.862" />
      <inertia ixx="0.00519617" ixy="-0.00001270" ixz="0.00035675" iyy="0.00470378" iyz="-0.00003329" izz="0.00266768" />
      <origin rpy="0 0 0" xyz="0.007089 0.000655 -0.016514" />
    </inertial>
    <collision>
      <geometry>
        <mesh filename="../../components/arms/ar5/variants/right/meshes/AR5_5_07R_W4C4A2_link3.stl" scale="0.001 0.001 0.001" />
      </geometry>
      <origin rpy="0 0 0" xyz="0 0 0" />
    </collision>
  </link>
  <link name="arm_right_AR5_5_07R_W4C4A2_link4">
    <visual>
      <geometry>
        <mesh filename="../../components/arms/ar5/variants/right/meshes/AR5_5_07R_W4C4A2_link4.stl" scale="0.001 0.001 0.001" />
      </geometry>
      <origin rpy="0 0 0" xyz="0 0 0" />
      <material name="arm_right_white" />
    </visual>
    <inertial>
      <mass value="1.234" />
      <inertia ixx="0.00389593" ixy="0.00004675" ixz="-0.00016955" iyy="0.00308688" iyz="-0.00046659" izz="0.00188378" />
      <origin rpy="0 0 0" xyz="-0.007832 0.004209 0.073402" />
    </inertial>
    <collision>
      <geometry>
        <mesh filename="../../components/arms/ar5/variants/right/meshes/AR5_5_07R_W4C4A2_link4.stl" scale="0.001 0.001 0.001" />
      </geometry>
      <origin rpy="0 0 0" xyz="0 0 0" />
    </collision>
  </link>
  <link name="arm_right_AR5_5_07R_W4C4A2_link5">
    <visual>
      <geometry>
        <mesh filename="../../components/arms/ar5/variants/right/meshes/AR5_5_07R_W4C4A2_link5.stl" scale="0.001 0.001 0.001" />
      </geometry>
      <origin rpy="0 0 0" xyz="0 0 0" />
      <material name="arm_right_white" />
    </visual>
    <inertial>
      <mass value="1.328" />
      <inertia ixx="0.00284294" ixy="-0.00001276" ixz="0.00001949" iyy="0.00221035" iyz="-0.00002134" izz="0.00185120" />
      <origin rpy="0 0 0" xyz="0.000268 -0.001475 -0.084143" />
    </inertial>
    <collision>
      <geometry>
        <mesh filename="../../components/arms/ar5/variants/right/meshes/AR5_5_07R_W4C4A2_link5.stl" scale="0.001 0.001 0.001" />
      </geometry>
      <origin rpy="0 0 0" xyz="0 0 0" />
    </collision>
  </link>
  <link name="arm_right_AR5_5_07R_W4C4A2_link6">
    <visual>
      <geometry>
        <mesh filename="../../components/arms/ar5/variants/right/meshes/AR5_5_07R_W4C4A2_link6.stl" scale="0.001 0.001 0.001" />
      </geometry>
      <origin rpy="0 0 0" xyz="0 0 0" />
      <material name="arm_right_white" />
    </visual>
    <inertial>
      <mass value="0.93" />
      <inertia ixx="0.00072274" ixy="0.00000186" ixz="-0.00000123" iyy="0.00087867" iyz="0.00000057" izz="0.00092938" />
      <origin rpy="0 0 0" xyz="0.005172 -0.000614 5.5e-05" />
    </inertial>
    <collision>
      <geometry>
        <mesh filename="../../components/arms/ar5/variants/right/meshes/AR5_5_07R_W4C4A2_link6.stl" scale="0.001 0.001 0.001" />
      </geometry>
      <origin rpy="0 0 0" xyz="0 0 0" />
    </collision>
  </link>
  <link name="arm_right_AR5_5_07R_W4C4A2_link7">
    <visual>
      <geometry>
        <mesh filename="../../components/arms/ar5/variants/right/meshes/AR5_5_07R_W4C4A2_link7.stl" scale="0.001 0.001 0.001" />
      </geometry>
      <origin rpy="0 0 0" xyz="0 0 0" />
      <material name="arm_right_white" />
    </visual>
    <inertial>
      <mass value="0.332" />
      <inertia ixx="0.00052121" ixy="0.00000020" ixz="0.00003808" iyy="0.00079394" iyz="0.00000098" izz="0.00045990" />
      <origin rpy="0 0 0" xyz="-0.002716 3.1e-05 0.054983" />
    </inertial>
    <collision>
      <geometry>
        <mesh filename="../../components/arms/ar5/variants/right/meshes/AR5_5_07R_W4C4A2_link7.stl" scale="0.001 0.001 0.001" />
      </geometry>
      <origin rpy="0 0 0" xyz="0 0 0" />
    </collision>
  </link>
  <link name="arm_right_AR5_5_07R_W4C4A2_tcp">
    <visual>
      <origin xyz="0 0 0" rpy="0 0 0" />
      <geometry>
        <box size="0.0001 0.0001 0.0001" />
      </geometry>
      <material name="arm_right_white" />
    </visual>
    <collision>
      <origin xyz="0 0 0" rpy="0 0 0" />
      <geometry>
        <box size="0.0001 0.0001 0.0001" />
      </geometry>
    </collision>
    <inertial>
      <mass value="0.0" />
      <inertia ixx="1e-6" ixy="0" ixz="0" iyy="1e-6" iyz="0" izz="1e-6" />
    </inertial>
  </link>
  <link name="hand_left_lh_hand_base_link">
    <inertial>
      <origin xyz="-0.000986417037 0.000268049028 0.0773798471" rpy="0 0 0" />
      <mass value="0.110373495507463" />
      <inertia ixx="0.000264402778830212" ixy="4.59263483005334e-07" ixz="1.32798258678817e-06" iyy="0.000159680177760236" iyz="-4.78660406501498e-06" izz="0.000118075546031988" />
    </inertial>
    <visual>
      <origin xyz="0 0 0" rpy="0 0 0" />
      <geometry>
        <mesh filename="../../components/hands/linkerhand_l25/variants/left/meshes/hand_base_link.STL" />
      </geometry>
      <material name="">
        <color rgba="1 1 1 1" />
      </material>
    </visual>
    <collision>
      <origin xyz="0 0 0" rpy="0 0 0" />
      <geometry>
        <mesh filename="../../components/hands/linkerhand_l25/variants/left/meshes/hand_base_link.STL" />
      </geometry>
    </collision>
  </link>
  <link name="hand_left_lh_thumb_metacarpals_base1">
    <inertial>
      <origin xyz="0.0115155126 0.00398068847 0.000272888251" rpy="0 0 0" />
      <mass value="0.0160351802817401" />
      <inertia ixx="4.043875385429e-06" ixy="1.31113365770736e-07" ixz="-7.54220071752833e-09" iyy="2.42762975209742e-06" iyz="-1.4815076502312e-07" izz="2.08582778122043e-06" />
    </inertial>
    <visual>
      <origin xyz="0 0 0" rpy="0 0 0" />
      <geometry>
        <mesh filename="../../components/hands/linkerhand_l25/variants/left/meshes/thumb_metacarpals_base1.STL" />
      </geometry>
      <material name="">
        <color rgba="1 1 1 1" />
      </material>
    </visual>
    <collision>
      <origin xyz="0 0 0" rpy="0 0 0" />
      <geometry>
        <mesh filename="../../components/hands/linkerhand_l25/variants/left/meshes/thumb_metacarpals_base1.STL" />
      </geometry>
    </collision>
  </link>
  <link name="hand_left_lh_thumb_metacarpals_base2">
    <inertial>
      <origin xyz="0.0028671461 -0.00615726534 0.00472605265" rpy="0 0 0" />
      <mass value="0.00183264554882498" />
      <inertia ixx="2.1115156606816047e-07" ixy="-4.9133152227129e-08" ixz="-1.35746007921721e-08" iyy="9.889251334189997e-08" iyz="4.75450167610941e-08" izz="1.8061586053999446e-07" />
    </inertial>
    <visual>
      <origin xyz="0 0 0" rpy="0 0 0" />
      <geometry>
        <mesh filename="../../components/hands/linkerhand_l25/variants/left/meshes/thumb_metacarpals_base2.STL" />
      </geometry>
      <material name="">
        <color rgba="1 1 1 1" />
      </material>
    </visual>
    <collision>
      <origin xyz="0 0 0" rpy="0 0 0" />
      <geometry>
        <mesh filename="../../components/hands/linkerhand_l25/variants/left/meshes/thumb_metacarpals_base2.STL" />
      </geometry>
    </collision>
  </link>
  <link name="hand_left_lh_thumb_metacarpals">
    <inertial>
      <origin xyz="0.00670657874 8.60758971e-05 0.033141293" rpy="0 0 0" />
      <mass value="0.0287160359417969" />
      <inertia ixx="1.13355944686632e-05" ixy="-1.18725063259997e-08" ixz="5.09011416528365e-08" iyy="1.3528651001113e-05" iyz="2.41236037965108e-08" izz="3.37809997040935e-06" />
    </inertial>
    <visual>
      <origin xyz="0 0 0" rpy="0 0 0" />
      <geometry>
        <mesh filename="../../components/hands/linkerhand_l25/variants/left/meshes/thumb_metacarpals.STL" />
      </geometry>
      <material name="">
        <color rgba="1 1 1 1" />
      </material>
    </visual>
    <collision>
      <origin xyz="0 0 0" rpy="0 0 0" />
      <geometry>
        <mesh filename="../../components/hands/linkerhand_l25/variants/left/meshes/thumb_metacarpals.STL" />
      </geometry>
    </collision>
  </link>
  <link name="hand_left_lh_thumb_proximal">
    <inertial>
      <origin xyz="-0.00268734411 0.000568244522 0.0118501723" rpy="0 0 0" />
      <mass value="0.00549015507433734" />
      <inertia ixx="4.78372237673962e-07" ixy="4.56375652569348e-11" ixz="5.41461160604729e-08" iyy="6.23208954846975e-07" iyz="5.1129105291147e-09" izz="2.34934736039565e-07" />
    </inertial>
    <visual>
      <origin xyz="0 0 0" rpy="0 0 0" />
      <geometry>
        <mesh filename="../../components/hands/linkerhand_l25/variants/left/meshes/thumb_proximal.STL" />
      </geometry>
      <material name="">
        <color rgba="1 1 1 1" />
      </material>
    </visual>
    <collision>
      <origin xyz="0 0 0" rpy="0 0 0" />
      <geometry>
        <mesh filename="../../components/hands/linkerhand_l25/variants/left/meshes/thumb_proximal.STL" />
      </geometry>
    </collision>
  </link>
  <link name="hand_left_lh_thumb_distal">
    <inertial>
      <origin xyz="-0.000710021799 -0.00267575921 0.0124762661" rpy="0 0 0" />
      <mass value="0.00382046638843239" />
      <inertia ixx="2.12120816159448e-07" ixy="-2.9588372102787e-09" ixz="-7.35950751454791e-08" iyy="2.67878295781821e-07" iyz="6.04616706384983e-09" izz="1.24571609570411e-07" />
    </inertial>
    <visual>
      <origin xyz="0 0 0" rpy="0 0 0" />
      <geometry>
        <mesh filename="../../components/hands/linkerhand_l25/variants/left/meshes/thumb_distal.STL" />
      </geometry>
      <material name="">
        <color rgba="1 1 1 1" />
      </material>
    </visual>
    <collision>
      <origin xyz="0 0 0" rpy="0 0 0" />
      <geometry>
        <mesh filename="../../components/hands/linkerhand_l25/variants/left/meshes/thumb_distal.STL" />
      </geometry>
    </collision>
  </link>
  <link name="hand_left_lh_index_metacarpals">
    <inertial>
      <origin xyz="-0.00794299654 -2.93673969e-07 0.00220106027" rpy="0 0 0" />
      <mass value="0.000895516429792169" />
      <inertia ixx="3.46279728013563e-08" ixy="-3.91962517308058e-13" ixz="5.91029152662012e-09" iyy="2.85435471088518e-08" iyz="-5.30377507775974e-13" izz="4.38102133125935e-08" />
    </inertial>
    <visual>
      <origin xyz="0 0 0" rpy="0 0 0" />
      <geometry>
        <mesh filename="../../components/hands/linkerhand_l25/variants/left/meshes/index_metacarpals.STL" />
      </geometry>
      <material name="">
        <color rgba="1 1 1 1" />
      </material>
    </visual>
    <collision>
      <origin xyz="0 0 0" rpy="0 0 0" />
      <geometry>
        <mesh filename="../../components/hands/linkerhand_l25/variants/left/meshes/index_metacarpals.STL" />
      </geometry>
    </collision>
  </link>
  <link name="hand_left_lh_index_proximal">
    <inertial>
      <origin xyz="-0.00114185485 3.47315752e-05 0.0228928405" rpy="0 0 0" />
      <mass value="0.00450921353606138" />
      <inertia ixx="6.66673080974796e-07" ixy="-1.07185172336921e-11" ixz="-2.53143396223457e-08" iyy="6.74195867168963e-07" iyz="-1.59054321114837e-10" izz="1.3575909170439e-07" />
    </inertial>
    <visual>
      <origin xyz="0 0 0" rpy="0 0 0" />
      <geometry>
        <mesh filename="../../components/hands/linkerhand_l25/variants/left/meshes/index_proximal.STL" />
      </geometry>
      <material name="">
        <color rgba="1 1 1 1" />
      </material>
    </visual>
    <collision>
      <origin xyz="0 0 0" rpy="0 0 0" />
      <geometry>
        <mesh filename="../../components/hands/linkerhand_l25/variants/left/meshes/index_proximal.STL" />
      </geometry>
    </collision>
  </link>
  <link name="hand_left_lh_index_middle">
    <inertial>
      <origin xyz="-0.000206991936 2.6061706e-06 0.0167065329" rpy="0 0 0" />
      <mass value="0.00237827499847615" />
      <inertia ixx="2.2953872847051e-07" ixy="2.23609392315326e-12" ixz="-1.4734008024399e-08" iyy="1.76761332719485e-07" iyz="1.15917246584962e-11" izz="9.62798051827835e-08" />
    </inertial>
    <visual>
      <origin xyz="0 0 0" rpy="0 0 0" />
      <geometry>
        <mesh filename="../../components/hands/linkerhand_l25/variants/left/meshes/index_middle.STL" />
      </geometry>
      <material name="">
        <color rgba="1 1 1 1" />
      </material>
    </visual>
    <collision>
      <origin xyz="0 0 0" rpy="0 0 0" />
      <geometry>
        <mesh filename="../../components/hands/linkerhand_l25/variants/left/meshes/index_middle.STL" />
      </geometry>
    </collision>
  </link>
  <link name="hand_left_lh_index_distal">
    <inertial>
      <origin xyz="-0.00816246518 2.27058914e-05 0.00811806505" rpy="0 0 0" />
      <mass value="0.00334170259772608" />
      <inertia ixx="1.59570744991572e-07" ixy="1.51458653099843e-10" ixz="-5.9429168549018e-08" iyy="1.78095631426193e-07" iyz="-1.24842727205631e-10" izz="1.34141383450165e-07" />
    </inertial>
    <visual>
      <origin xyz="0 0 0" rpy="0 0 0" />
      <geometry>
        <mesh filename="../../components/hands/linkerhand_l25/variants/left/meshes/index_distal.STL" />
      </geometry>
      <material name="">
        <color rgba="1 1 1 1" />
      </material>
    </visual>
    <collision>
      <origin xyz="0 0 0" rpy="0 0 0" />
      <geometry>
        <mesh filename="../../components/hands/linkerhand_l25/variants/left/meshes/index_distal.STL" />
      </geometry>
    </collision>
  </link>
  <link name="hand_left_lh_middle_metacarpals">
    <inertial>
      <origin xyz="-0.00794299618 -2.9300666e-07 0.0022010633" rpy="0 0 0" />
      <mass value="0.000895516947435045" />
      <inertia ixx="3.46279958583857e-08" ixy="-3.91785866285381e-13" ixz="5.91029262290692e-09" iyy="2.85435605322585e-08" iyz="-5.27457529869591e-13" izz="4.38102218629515e-08" />
    </inertial>
    <visual>
      <origin xyz="0 0 0" rpy="0 0 0" />
      <geometry>
        <mesh filename="../../components/hands/linkerhand_l25/variants/left/meshes/middle_metacarpals.STL" />
      </geometry>
      <material name="">
        <color rgba="1 1 1 1" />
      </material>
    </visual>
    <collision>
      <origin xyz="0 0 0" rpy="0 0 0" />
      <geometry>
        <mesh filename="../../components/hands/linkerhand_l25/variants/left/meshes/middle_metacarpals.STL" />
      </geometry>
    </collision>
  </link>
  <link name="hand_left_lh_middle_proximal">
    <inertial>
      <origin xyz="-0.00114185485 3.47315749e-05 0.0228928405" rpy="0 0 0" />
      <mass value="0.00450921353536659" />
      <inertia ixx="6.6667308094129e-07" ixy="-1.07185191777588e-11" ixz="-2.53143396278864e-08" iyy="6.74195867139795e-07" iyz="-1.59054330697635e-10" izz="1.3575909169764e-07" />
    </inertial>
    <visual>
      <origin xyz="0 0 0" rpy="0 0 0" />
      <geometry>
        <mesh filename="../../components/hands/linkerhand_l25/variants/left/meshes/middle_proximal.STL" />
      </geometry>
      <material name="">
        <color rgba="1 1 1 1" />
      </material>
    </visual>
    <collision>
      <origin xyz="0 0 0" rpy="0 0 0" />
      <geometry>
        <mesh filename="../../components/hands/linkerhand_l25/variants/left/meshes/middle_proximal.STL" />
      </geometry>
    </collision>
  </link>
  <link name="hand_left_lh_middle_middle">
    <inertial>
      <origin xyz="-0.000206991893 2.60624979e-06 0.0167065331" rpy="0 0 0" />
      <mass value="0.00237827502274046" />
      <inertia ixx="2.29538732170979e-07" ixy="2.23722006830829e-12" ixz="-1.47340061868536e-08" iyy="1.7676133625496e-07" iyz="1.15938574397121e-11" izz="9.62798057458164e-08" />
    </inertial>
    <visual>
      <origin xyz="0 0 0" rpy="0 0 0" />
      <geometry>
        <mesh filename="../../components/hands/linkerhand_l25/variants/left/meshes/middle_middle.STL" />
      </geometry>
      <material name="">
        <color rgba="1 1 1 1" />
      </material>
    </visual>
    <collision>
      <origin xyz="0 0 0" rpy="0 0 0" />
      <geometry>
        <mesh filename="../../components/hands/linkerhand_l25/variants/left/meshes/middle_middle.STL" />
      </geometry>
    </collision>
  </link>
  <link name="hand_left_lh_middle_distal">
    <inertial>
      <origin xyz="-0.00816246585 2.27058557e-05 0.00811806605" rpy="0 0 0" />
      <mass value="0.00334170288968694" />
      <inertia ixx="1.59570753478215e-07" ixy="1.51460233550071e-10" ixz="-5.94291827952622e-08" iyy="1.78095663702073e-07" iyz="-1.24843061161549e-10" izz="1.34141410190336e-07" />
    </inertial>
    <visual>
      <origin xyz="0 0 0" rpy="0 0 0" />
      <geometry>
        <mesh filename="../../components/hands/linkerhand_l25/variants/left/meshes/middle_distal.STL" />
      </geometry>
      <material name="">
        <color rgba="1 1 1 1" />
      </material>
    </visual>
    <collision>
      <origin xyz="0 0 0" rpy="0 0 0" />
      <geometry>
        <mesh filename="../../components/hands/linkerhand_l25/variants/left/meshes/middle_distal.STL" />
      </geometry>
    </collision>
  </link>
  <link name="hand_left_lh_ring_metacarpals">
    <inertial>
      <origin xyz="-0.00794299638 -2.94513099e-07 0.00220106138" rpy="0 0 0" />
      <mass value="0.000895516612684195" />
      <inertia ixx="3.46279813761428e-08" ixy="-3.92590701616938e-13" ixz="5.91029201975386e-09" iyy="2.854355219638e-08" iyz="-5.34642787239736e-13" izz="4.38102164225122e-08" />
    </inertial>
    <visual>
      <origin xyz="0 0 0" rpy="0 0 0" />
      <geometry>
        <mesh filename="../../components/hands/linkerhand_l25/variants/left/meshes/ring_metacarpals.STL" />
      </geometry>
      <material name="">
        <color rgba="1 1 1 1" />
      </material>
    </visual>
    <collision>
      <origin xyz="0 0 0" rpy="0 0 0" />
      <geometry>
        <mesh filename="../../components/hands/linkerhand_l25/variants/left/meshes/ring_metacarpals.STL" />
      </geometry>
    </collision>
  </link>
  <link name="hand_left_lh_ring_proximal">
    <inertial>
      <origin xyz="-0.00114185484 3.47315809e-05 0.0228928405" rpy="0 0 0" />
      <mass value="0.00450921353946778" />
      <inertia ixx="6.66673081759646e-07" ixy="-1.07184694208142e-11" ixz="-2.53143399406658e-08" iyy="6.74195868060947e-07" iyz="-1.59054446512071e-10" izz="1.3575909184966e-07" />
    </inertial>
    <visual>
      <origin xyz="0 0 0" rpy="0 0 0" />
      <geometry>
        <mesh filename="../../components/hands/linkerhand_l25/variants/left/meshes/ring_proximal.STL" />
      </geometry>
      <material name="">
        <color rgba="1 1 1 1" />
      </material>
    </visual>
    <collision>
      <origin xyz="0 0 0" rpy="0 0 0" />
      <geometry>
        <mesh filename="../../components/hands/linkerhand_l25/variants/left/meshes/ring_proximal.STL" />
      </geometry>
    </collision>
  </link>
  <link name="hand_left_lh_ring_middle">
    <inertial>
      <origin xyz="-0.000206993215 2.60746917e-06 0.0167065327" rpy="0 0 0" />
      <mass value="0.00237827433282015" />
      <inertia ixx="2.29538714144179e-07" ixy="2.25259718797087e-12" ixz="-1.47340121880382e-08" iyy="1.76761312824203e-07" iyz="1.15994674932479e-11" izz="9.62797743780677e-08" />
    </inertial>
    <visual>
      <origin xyz="0 0 0" rpy="0 0 0" />
      <geometry>
        <mesh filename="../../components/hands/linkerhand_l25/variants/left/meshes/ring_middle.STL" />
      </geometry>
      <material name="">
        <color rgba="1 1 1 1" />
      </material>
    </visual>
    <collision>
      <origin xyz="0 0 0" rpy="0 0 0" />
      <geometry>
        <mesh filename="../../components/hands/linkerhand_l25/variants/left/meshes/ring_middle.STL" />
      </geometry>
    </collision>
  </link>
  <link name="hand_left_lh_ring_distal">
    <inertial>
      <origin xyz="-0.00816246552 2.27057325e-05 0.00811806561" rpy="0 0 0" />
      <mass value="0.00334170280386792" />
      <inertia ixx="1.59570757957895e-07" ixy="1.51461030930522e-10" ixz="-5.94291750853635e-08" iyy="1.78095650648522e-07" iyz="-1.2484716714453e-10" izz="1.34141394018405e-07" />
    </inertial>
    <visual>
      <origin xyz="0 0 0" rpy="0 0 0" />
      <geometry>
        <mesh filename="../../components/hands/linkerhand_l25/variants/left/meshes/ring_distal.STL" />
      </geometry>
      <material name="">
        <color rgba="1 1 1 1" />
      </material>
    </visual>
    <collision>
      <origin xyz="0 0 0" rpy="0 0 0" />
      <geometry>
        <mesh filename="../../components/hands/linkerhand_l25/variants/left/meshes/ring_distal.STL" />
      </geometry>
    </collision>
  </link>
  <link name="hand_left_lh_pinky_metacarpals">
    <inertial>
      <origin xyz="-0.00794299617 -2.93006863e-07 0.0022010633" rpy="0 0 0" />
      <mass value="0.000895516947513541" />
      <inertia ixx="3.46279958591138e-08" ixy="-3.91785473098584e-13" ixz="5.91029262259818e-09" iyy="2.85435605328821e-08" iyz="-5.27457876763101e-13" izz="4.38102218637476e-08" />
    </inertial>
    <visual>
      <origin xyz="0 0 0" rpy="0 0 0" />
      <geometry>
        <mesh filename="../../components/hands/linkerhand_l25/variants/left/meshes/pinky_metacarpals.STL" />
      </geometry>
      <material name="">
        <color rgba="1 1 1 1" />
      </material>
    </visual>
    <collision>
      <origin xyz="0 0 0" rpy="0 0 0" />
      <geometry>
        <mesh filename="../../components/hands/linkerhand_l25/variants/left/meshes/pinky_metacarpals.STL" />
      </geometry>
    </collision>
  </link>
  <link name="hand_left_lh_pinky_proximal">
    <inertial>
      <origin xyz="-0.00114185484 3.4731581e-05 0.0228928405" rpy="0 0 0" />
      <mass value="0.00450921353949741" />
      <inertia ixx="6.66673081761478e-07" ixy="-1.07184692555283e-11" ixz="-2.53143399404374e-08" iyy="6.74195868062215e-07" iyz="-1.59054445649156e-10" izz="1.35759091850319e-07" />
    </inertial>
    <visual>
      <origin xyz="0 0 0" rpy="0 0 0" />
      <geometry>
        <mesh filename="../../components/hands/linkerhand_l25/variants/left/meshes/pinky_proximal.STL" />
      </geometry>
      <material name="">
        <color rgba="1 1 1 1" />
      </material>
    </visual>
    <collision>
      <origin xyz="0 0 0" rpy="0 0 0" />
      <geometry>
        <mesh filename="../../components/hands/linkerhand_l25/variants/left/meshes/pinky_proximal.STL" />
      </geometry>
    </collision>
  </link>
  <link name="hand_left_lh_pinky_middle">
    <inertial>
      <origin xyz="-0.000206993249 2.60748984e-06 0.0167065327" rpy="0 0 0" />
      <mass value="0.00237827431921004" />
      <inertia ixx="2.29538713829186e-07" ixy="2.25292379523651e-12" ixz="-1.47340119230773e-08" iyy="1.76761312133621e-07" iyz="1.15993142153177e-11" izz="9.62797736254209e-08" />
    </inertial>
    <visual>
      <origin xyz="0 0 0" rpy="0 0 0" />
      <geometry>
        <mesh filename="../../components/hands/linkerhand_l25/variants/left/meshes/pinky_middle.STL" />
      </geometry>
      <material name="">
        <color rgba="1 1 1 1" />
      </material>
    </visual>
    <collision>
      <origin xyz="0 0 0" rpy="0 0 0" />
      <geometry>
        <mesh filename="../../components/hands/linkerhand_l25/variants/left/meshes/pinky_middle.STL" />
      </geometry>
    </collision>
  </link>
  <link name="hand_left_lh_pinky_distal">
    <inertial>
      <origin xyz="-0.00816246615 2.27054189e-05 0.00811806634" rpy="0 0 0" />
      <mass value="0.00334170283969146" />
      <inertia ixx="1.59570758932551e-07" ixy="1.51458416419677e-10" ixz="-5.94291815262966e-08" iyy="1.7809566305509e-07" iyz="-1.24846982879422e-10" izz="1.34141398854287e-07" />
    </inertial>
    <visual>
      <origin xyz="0 0 0" rpy="0 0 0" />
      <geometry>
        <mesh filename="../../components/hands/linkerhand_l25/variants/left/meshes/pinky_distal.STL" />
      </geometry>
      <material name="">
        <color rgba="1 1 1 1" />
      </material>
    </visual>
    <collision>
      <origin xyz="0 0 0" rpy="0 0 0" />
      <geometry>
        <mesh filename="../../components/hands/linkerhand_l25/variants/left/meshes/pinky_distal.STL" />
      </geometry>
    </collision>
  </link>
  <link name="hand_right_rh_hand_base_link">
    <inertial>
      <origin xyz="-0.00235533266 -0.000476950677 0.0840274681" rpy="0 0 0" />
      <mass value="0.130043890829375" />
      <inertia ixx="0.000269869493590648" ixy="-5.66836728555976e-07" ixz="1.0791938448155e-06" iyy="0.000164906210534713" iyz="4.94586055862009e-06" izz="0.000118834524369526" />
    </inertial>
    <visual>
      <origin xyz="0 0 0" rpy="0 0 0" />
      <geometry>
        <mesh filename="../../components/hands/linkerhand_l25/variants/right/meshes/hand_base_link.STL" />
      </geometry>
      <material name="">
        <color rgba="1 1 1 1" />
      </material>
    </visual>
    <collision>
      <origin xyz="0 0 0" rpy="0 0 0" />
      <geometry>
        <mesh filename="../../components/hands/linkerhand_l25/variants/right/meshes/hand_base_link.STL" />
      </geometry>
    </collision>
  </link>
  <link name="hand_right_rh_thumb_metacarpals_base1">
    <inertial>
      <origin xyz="0.0121300686 -0.00368626402 0.000253013805" rpy="0 0 0" />
      <mass value="0.0173128324517923" />
      <inertia ixx="4.04974890264239e-06" ixy="-1.31074266242452e-07" ixz="-7.53905165403527e-09" iyy="2.43513754798381e-06" iyz="1.46366596393199e-07" izz="2.09347392894973e-06" />
    </inertial>
    <visual>
      <origin xyz="0 0 0" rpy="0 0 0" />
      <geometry>
        <mesh filename="../../components/hands/linkerhand_l25/variants/right/meshes/thumb_metacarpals_base1.STL" />
      </geometry>
      <material name="">
        <color rgba="1 1 1 1" />
      </material>
    </visual>
    <collision>
      <origin xyz="0 0 0" rpy="0 0 0" />
      <geometry>
        <mesh filename="../../components/hands/linkerhand_l25/variants/right/meshes/thumb_metacarpals_base1.STL" />
      </geometry>
    </collision>
  </link>
  <link name="hand_right_rh_thumb_metacarpals_base2">
    <inertial>
      <origin xyz="0.00274804892 0.00768600825 0.00362008971" rpy="0 0 0" />
      <mass value="0.0129293097380942" />
      <inertia ixx="1.760752912378147e-06" ixy="3.5029507180292e-07" ixz="-1.32342776895603e-07" iyy="7.758748827283011e-07" iyz="-3.69293599975358e-07" izz="1.450608374471467e-06" />
    </inertial>
    <visual>
      <origin xyz="0 0 0" rpy="0 0 0" />
      <geometry>
        <mesh filename="../../components/hands/linkerhand_l25/variants/right/meshes/thumb_metacarpals_base2.STL" />
      </geometry>
      <material name="">
        <color rgba="1 1 1 1" />
      </material>
    </visual>
    <collision>
      <origin xyz="0 0 0" rpy="0 0 0" />
      <geometry>
        <mesh filename="../../components/hands/linkerhand_l25/variants/right/meshes/thumb_metacarpals_base2.STL" />
      </geometry>
    </collision>
  </link>
  <link name="hand_right_rh_thumb_metacarpals">
    <inertial>
      <origin xyz="0.00680467489 -0.000348945979 0.0329029974" rpy="0 0 0" />
      <mass value="0.0311449727019751" />
      <inertia ixx="1.14965619264847e-05" ixy="-1.14093661337383e-08" ixz="5.08562599330683e-08" iyy="1.37913772817647e-05" iyz="2.39355105126118e-08" izz="3.56917509196916e-06" />
    </inertial>
    <visual>
      <origin xyz="0 0 0" rpy="0 0 0" />
      <geometry>
        <mesh filename="../../components/hands/linkerhand_l25/variants/right/meshes/thumb_metacarpals.STL" />
      </geometry>
      <material name="">
        <color rgba="1 1 1 1" />
      </material>
    </visual>
    <collision>
      <origin xyz="0 0 0" rpy="0 0 0" />
      <geometry>
        <mesh filename="../../components/hands/linkerhand_l25/variants/right/meshes/thumb_metacarpals.STL" />
      </geometry>
    </collision>
  </link>
  <link name="hand_right_rh_thumb_proximal">
    <inertial>
      <origin xyz="-0.00268743345 0.00056829098 0.0118503607" rpy="0 0 0" />
      <mass value="0.00549015851204037" />
      <inertia ixx="4.78349857032437e-07" ixy="4.61712014179472e-11" ixz="5.4113877466635e-08" iyy="6.23171205283375e-07" iyz="5.11556682719536e-09" izz="2.34919130274949e-07" />
    </inertial>
    <visual>
      <origin xyz="0 0 0" rpy="0 0 0" />
      <geometry>
        <mesh filename="../../components/hands/linkerhand_l25/variants/right/meshes/thumb_proximal.STL" />
      </geometry>
      <material name="">
        <color rgba="1 1 1 1" />
      </material>
    </visual>
    <collision>
      <origin xyz="0 0 0" rpy="0 0 0" />
      <geometry>
        <mesh filename="../../components/hands/linkerhand_l25/variants/right/meshes/thumb_proximal.STL" />
      </geometry>
    </collision>
  </link>
  <link name="hand_right_rh_thumb_distal">
    <inertial>
      <origin xyz="-0.000650482106 2.41300573e-05 0.0111942838" rpy="0 0 0" />
      <mass value="0.00585464206993151" />
      <inertia ixx="3.37157269656711e-07" ixy="3.69307135027908e-10" ixz="-1.12308316041907e-07" iyy="4.37703462647265e-07" iyz="-9.3624675389561e-10" izz="1.85639673847353e-07" />
    </inertial>
    <visual>
      <origin xyz="0 0 0" rpy="0 0 0" />
      <geometry>
        <mesh filename="../../components/hands/linkerhand_l25/variants/right/meshes/thumb_distal.STL" />
      </geometry>
      <material name="">
        <color rgba="1 1 1 1" />
      </material>
    </visual>
    <collision>
      <origin xyz="0 0 0" rpy="0 0 0" />
      <geometry>
        <mesh filename="../../components/hands/linkerhand_l25/variants/right/meshes/thumb_distal.STL" />
      </geometry>
    </collision>
  </link>
  <link name="hand_right_rh_index_metacarpals">
    <inertial>
      <origin xyz="-0.00794297217 3.01910608e-07 0.00220112291" rpy="0 0 0" />
      <mass value="0.000895533942236676" />
      <inertia ixx="3.46286808249453e-08" ixy="5.20721113539202e-13" ixz="5.91055676999344e-09" iyy="2.85439868980493e-08" iyz="6.15915602928681e-13" izz="4.38105935701441e-08" />
    </inertial>
    <visual>
      <origin xyz="0 0 0" rpy="0 0 0" />
      <geometry>
        <mesh filename="../../components/hands/linkerhand_l25/variants/right/meshes/index_metacarpals.STL" />
      </geometry>
      <material name="">
        <color rgba="1 1 1 1" />
      </material>
    </visual>
    <collision>
      <origin xyz="0 0 0" rpy="0 0 0" />
      <geometry>
        <mesh filename="../../components/hands/linkerhand_l25/variants/right/meshes/index_metacarpals.STL" />
      </geometry>
    </collision>
  </link>
  <link name="hand_right_rh_index_proximal">
    <inertial>
      <origin xyz="-0.0011416589 -3.47779025e-05 0.0228930741" rpy="0 0 0" />
      <mass value="0.00450935628154297" />
      <inertia ixx="6.66693338335738e-07" ixy="1.00781853152623e-11" ixz="-2.53156876802064e-08" iyy="6.74214594716538e-07" iyz="1.59197443844205e-10" izz="1.3576088799113e-07" />
    </inertial>
    <visual>
      <origin xyz="0 0 0" rpy="0 0 0" />
      <geometry>
        <mesh filename="../../components/hands/linkerhand_l25/variants/right/meshes/index_proximal.STL" />
      </geometry>
      <material name="">
        <color rgba="1 1 1 1" />
      </material>
    </visual>
    <collision>
      <origin xyz="0 0 0" rpy="0 0 0" />
      <geometry>
        <mesh filename="../../components/hands/linkerhand_l25/variants/right/meshes/index_proximal.STL" />
      </geometry>
    </collision>
  </link>
  <link name="hand_right_rh_index_middle">
    <inertial>
      <origin xyz="-0.000206830315 -2.69762827e-06 0.0167055565" rpy="0 0 0" />
      <mass value="0.00237861824163327" />
      <inertia ixx="2.29584431475404e-07" ixy="-3.79527882007371e-12" ixz="-1.47269516053005e-08" iyy="1.76802239049368e-07" iyz="3.59871792473524e-13" izz="9.62875380319572e-08" />
    </inertial>
    <visual>
      <origin xyz="0 0 0" rpy="0 0 0" />
      <geometry>
        <mesh filename="../../components/hands/linkerhand_l25/variants/right/meshes/index_middle.STL" />
      </geometry>
      <material name="">
        <color rgba="1 1 1 1" />
      </material>
    </visual>
    <collision>
      <origin xyz="0 0 0" rpy="0 0 0" />
      <geometry>
        <mesh filename="../../components/hands/linkerhand_l25/variants/right/meshes/index_middle.STL" />
      </geometry>
    </collision>
  </link>
  <link name="hand_right_rh_index_distal">
    <inertial>
      <origin xyz="-0.00816260402 -2.26721604e-05 0.00811819723" rpy="0 0 0" />
      <mass value="0.00334176238570705" />
      <inertia ixx="1.59568900399119e-07" ixy="-1.52271643281661e-10" ixz="-5.94266141046017e-08" iyy="1.78096631602274e-07" iyz="1.23981970768957e-10" izz="1.34139906914153e-07" />
    </inertial>
    <visual>
      <origin xyz="0 0 0" rpy="0 0 0" />
      <geometry>
        <mesh filename="../../components/hands/linkerhand_l25/variants/right/meshes/index_distal.STL" />
      </geometry>
      <material name="">
        <color rgba="1 1 1 1" />
      </material>
    </visual>
    <collision>
      <origin xyz="0 0 0" rpy="0 0 0" />
      <geometry>
        <mesh filename="../../components/hands/linkerhand_l25/variants/right/meshes/index_distal.STL" />
      </geometry>
    </collision>
  </link>
  <link name="hand_right_rh_middle_metacarpals">
    <inertial>
      <origin xyz="-0.00794297217 3.01910608e-07 0.00220112291" rpy="0 0 0" />
      <mass value="0.000895533942236672" />
      <inertia ixx="3.46286808249452e-08" ixy="5.20721113361698e-13" ixz="5.91055676999347e-09" iyy="2.85439868980493e-08" iyz="6.15915602825396e-13" izz="4.3810593570144e-08" />
    </inertial>
    <visual>
      <origin xyz="0 0 0" rpy="0 0 0" />
      <geometry>
        <mesh filename="../../components/hands/linkerhand_l25/variants/right/meshes/middle_metacarpals.STL" />
      </geometry>
      <material name="">
        <color rgba="1 1 1 1" />
      </material>
    </visual>
    <collision>
      <origin xyz="0 0 0" rpy="0 0 0" />
      <geometry>
        <mesh filename="../../components/hands/linkerhand_l25/variants/right/meshes/middle_metacarpals.STL" />
      </geometry>
    </collision>
  </link>
  <link name="hand_right_rh_middle_proximal">
    <inertial>
      <origin xyz="-0.0011416589 -3.47779025e-05 0.0228930741" rpy="0 0 0" />
      <mass value="0.00450935628154299" />
      <inertia ixx="6.66693338335741e-07" ixy="1.00781853158879e-11" ixz="-2.53156876802067e-08" iyy="6.74214594716535e-07" iyz="1.59197443844791e-10" izz="1.35760887991121e-07" />
    </inertial>
    <visual>
      <origin xyz="0 0 0" rpy="0 0 0" />
      <geometry>
        <mesh filename="../../components/hands/linkerhand_l25/variants/right/meshes/middle_proximal.STL" />
      </geometry>
      <material name="">
        <color rgba="1 1 1 1" />
      </material>
    </visual>
    <collision>
      <origin xyz="0 0 0" rpy="0 0 0" />
      <geometry>
        <mesh filename="../../components/hands/linkerhand_l25/variants/right/meshes/middle_proximal.STL" />
      </geometry>
    </collision>
  </link>
  <link name="hand_right_rh_middle_middle">
    <inertial>
      <origin xyz="-0.000206830311 -2.69763201e-06 0.0167055565" rpy="0 0 0" />
      <mass value="0.00237861824399121" />
      <inertia ixx="2.2958443176697e-07" ixy="-3.79531728857531e-12" ixz="-1.47269515025648e-08" iyy="1.76802239346606e-07" iyz="3.59776198217398e-13" izz="9.62875381090068e-08" />
    </inertial>
    <visual>
      <origin xyz="0 0 0" rpy="0 0 0" />
      <geometry>
        <mesh filename="../../components/hands/linkerhand_l25/variants/right/meshes/middle_middle.STL" />
      </geometry>
      <material name="">
        <color rgba="1 1 1 1" />
      </material>
    </visual>
    <collision>
      <origin xyz="0 0 0" rpy="0 0 0" />
      <geometry>
        <mesh filename="../../components/hands/linkerhand_l25/variants/right/meshes/middle_middle.STL" />
      </geometry>
    </collision>
  </link>
  <link name="hand_right_rh_middle_distal">
    <inertial>
      <origin xyz="-0.00816260402 -2.26721613e-05 0.00811819723" rpy="0 0 0" />
      <mass value="0.0033417623857295" />
      <inertia ixx="1.59568900407287e-07" ixy="-1.52271672185911e-10" ixz="-5.94266141070478e-08" iyy="1.78096631550001e-07" iyz="1.23981962913402e-10" izz="1.34139906932954e-07" />
    </inertial>
    <visual>
      <origin xyz="0 0 0" rpy="0 0 0" />
      <geometry>
        <mesh filename="../../components/hands/linkerhand_l25/variants/right/meshes/middle_distal.STL" />
      </geometry>
      <material name="">
        <color rgba="1 1 1 1" />
      </material>
    </visual>
    <collision>
      <origin xyz="0 0 0" rpy="0 0 0" />
      <geometry>
        <mesh filename="../../components/hands/linkerhand_l25/variants/right/meshes/middle_distal.STL" />
      </geometry>
    </collision>
  </link>
  <link name="hand_right_rh_ring_metacarpals">
    <inertial>
      <origin xyz="-0.00794297218 3.01910608e-07 0.00220112291" rpy="0 0 0" />
      <mass value="0.00089553394223667" />
      <inertia ixx="3.4628680824945e-08" ixy="5.2072111337213e-13" ixz="5.91055676999336e-09" iyy="2.8543986898049e-08" iyz="6.15915602738524e-13" izz="4.38105935701438e-08" />
    </inertial>
    <visual>
      <origin xyz="0 0 0" rpy="0 0 0" />
      <geometry>
        <mesh filename="../../components/hands/linkerhand_l25/variants/right/meshes/ring_metacarpals.STL" />
      </geometry>
      <material name="">
        <color rgba="1 1 1 1" />
      </material>
    </visual>
    <collision>
      <origin xyz="0 0 0" rpy="0 0 0" />
      <geometry>
        <mesh filename="../../components/hands/linkerhand_l25/variants/right/meshes/ring_metacarpals.STL" />
      </geometry>
    </collision>
  </link>
  <link name="hand_right_rh_ring_proximal">
    <inertial>
      <origin xyz="-0.0011416589 -3.47779025e-05 0.0228930741" rpy="0 0 0" />
      <mass value="0.00450935628154299" />
      <inertia ixx="6.66693338335738e-07" ixy="1.00781853170701e-11" ixz="-2.53156876802064e-08" iyy="6.74214594716548e-07" iyz="1.59197443843837e-10" izz="1.3576088799114e-07" />
    </inertial>
    <visual>
      <origin xyz="0 0 0" rpy="0 0 0" />
      <geometry>
        <mesh filename="../../components/hands/linkerhand_l25/variants/right/meshes/ring_proximal.STL" />
      </geometry>
      <material name="">
        <color rgba="1 1 1 1" />
      </material>
    </visual>
    <collision>
      <origin xyz="0 0 0" rpy="0 0 0" />
      <geometry>
        <mesh filename="../../components/hands/linkerhand_l25/variants/right/meshes/ring_proximal.STL" />
      </geometry>
    </collision>
  </link>
  <link name="hand_right_rh_ring_middle">
    <inertial>
      <origin xyz="-0.000206830315 -2.69762827e-06 0.0167055565" rpy="0 0 0" />
      <mass value="0.00237861824163314" />
      <inertia ixx="2.29584431475388e-07" ixy="-3.79527881056473e-12" ixz="-1.47269516053097e-08" iyy="1.76802239049448e-07" iyz="3.59871797815951e-13" izz="9.62875380320043e-08" />
    </inertial>
    <visual>
      <origin xyz="0 0 0" rpy="0 0 0" />
      <geometry>
        <mesh filename="../../components/hands/linkerhand_l25/variants/right/meshes/ring_middle.STL" />
      </geometry>
      <material name="">
        <color rgba="1 1 1 1" />
      </material>
    </visual>
    <collision>
      <origin xyz="0 0 0" rpy="0 0 0" />
      <geometry>
        <mesh filename="../../components/hands/linkerhand_l25/variants/right/meshes/ring_middle.STL" />
      </geometry>
    </collision>
  </link>
  <link name="hand_right_rh_ring_distal">
    <inertial>
      <origin xyz="-0.00816260402 -2.26723442e-05 0.00811819723" rpy="0 0 0" />
      <mass value="0.00334176238553782" />
      <inertia ixx="1.59568900413529e-07" ixy="-1.5226555011147e-10" ixz="-5.9426614092103e-08" iyy="1.78096631554275e-07" iyz="1.23978578539056e-10" izz="1.34139906897543e-07" />
    </inertial>
    <visual>
      <origin xyz="0 0 0" rpy="0 0 0" />
      <geometry>
        <mesh filename="../../components/hands/linkerhand_l25/variants/right/meshes/ring_distal.STL" />
      </geometry>
      <material name="">
        <color rgba="1 1 1 1" />
      </material>
    </visual>
    <collision>
      <origin xyz="0 0 0" rpy="0 0 0" />
      <geometry>
        <mesh filename="../../components/hands/linkerhand_l25/variants/right/meshes/ring_distal.STL" />
      </geometry>
    </collision>
  </link>
  <link name="hand_right_rh_pinky_metacarpals">
    <inertial>
      <origin xyz="-0.00794297218 3.01910608e-07 0.00220112291" rpy="0 0 0" />
      <mass value="0.000895533942236661" />
      <inertia ixx="3.46286808249448e-08" ixy="5.20721113385638e-13" ixz="5.91055676999334e-09" iyy="2.85439868980489e-08" iyz="6.15915602787648e-13" izz="4.38105935701437e-08" />
    </inertial>
    <visual>
      <origin xyz="0 0 0" rpy="0 0 0" />
      <geometry>
        <mesh filename="../../components/hands/linkerhand_l25/variants/right/meshes/pinky_metacarpals.STL" />
      </geometry>
      <material name="">
        <color rgba="1 1 1 1" />
      </material>
    </visual>
    <collision>
      <origin xyz="0 0 0" rpy="0 0 0" />
      <geometry>
        <mesh filename="../../components/hands/linkerhand_l25/variants/right/meshes/pinky_metacarpals.STL" />
      </geometry>
    </collision>
  </link>
  <link name="hand_right_rh_pinky_proximal">
    <inertial>
      <origin xyz="-0.0011416589 -3.47779084e-05 0.0228930741" rpy="0 0 0" />
      <mass value="0.00450935627773312" />
      <inertia ixx="6.6669333754323e-07" ixy="1.00781372651744e-11" ixz="-2.53156873668278e-08" iyy="6.74214593816853e-07" iyz="1.59197565505674e-10" izz="1.35760887844139e-07" />
    </inertial>
    <visual>
      <origin xyz="0 0 0" rpy="0 0 0" />
      <geometry>
        <mesh filename="../../components/hands/linkerhand_l25/variants/right/meshes/pinky_proximal.STL" />
      </geometry>
      <material name="">
        <color rgba="1 1 1 1" />
      </material>
    </visual>
    <collision>
      <origin xyz="0 0 0" rpy="0 0 0" />
      <geometry>
        <mesh filename="../../components/hands/linkerhand_l25/variants/right/meshes/pinky_proximal.STL" />
      </geometry>
    </collision>
  </link>
  <link name="hand_right_rh_pinky_middle">
    <inertial>
      <origin xyz="-0.000206830315 -2.69762827e-06 0.0167055565" rpy="0 0 0" />
      <mass value="0.0023786182416333" />
      <inertia ixx="2.29584431475459e-07" ixy="-3.79527884680841e-12" ixz="-1.47269516053079e-08" iyy="1.76802239049466e-07" iyz="3.5987180643017e-13" izz="9.62875380320415e-08" />
    </inertial>
    <visual>
      <origin xyz="0 0 0" rpy="0 0 0" />
      <geometry>
        <mesh filename="../../components/hands/linkerhand_l25/variants/right/meshes/pinky_middle.STL" />
      </geometry>
      <material name="">
        <color rgba="1 1 1 1" />
      </material>
    </visual>
    <collision>
      <origin xyz="0 0 0" rpy="0 0 0" />
      <geometry>
        <mesh filename="../../components/hands/linkerhand_l25/variants/right/meshes/pinky_middle.STL" />
      </geometry>
    </collision>
  </link>
  <link name="hand_right_rh_pinky_distal">
    <inertial>
      <origin xyz="-0.00816260391 -2.26722056e-05 0.00811819704" rpy="0 0 0" />
      <mass value="0.00334176233214274" />
      <inertia ixx="1.59568898336975e-07" ixy="-1.52270106341856e-10" ixz="-5.94266114992739e-08" iyy="1.78096625944569e-07" iyz="1.23981107883524e-10" izz="1.3413990252827e-07" />
    </inertial>
    <visual>
      <origin xyz="0 0 0" rpy="0 0 0" />
      <geometry>
        <mesh filename="../../components/hands/linkerhand_l25/variants/right/meshes/pinky_distal.STL" />
      </geometry>
      <material name="">
        <color rgba="1 1 1 1" />
      </material>
    </visual>
    <collision>
      <origin xyz="0 0 0" rpy="0 0 0" />
      <geometry>
        <mesh filename="../../components/hands/linkerhand_l25/variants/right/meshes/pinky_distal.STL" />
      </geometry>
    </collision>
  </link>
  <joint name="base_cameraBase" type="fixed">
    <origin xyz="0.0335 0.67 1.2974" rpy="-1.5708 0 -1.5708" />
    <parent link="base_workstation_link" />
    <child link="base_camera_base_link" />
    <axis xyz="0 0 0" />
  </joint>
  <joint name="base_cameraJoint" type="fixed">
    <origin xyz="0.0802 0.193139854 -0.275851476" rpy="-1.26599038 -0.643554018 -1.57079633" />
    <parent link="base_camera_base_link" />
    <child link="base_camera" />
    <axis xyz="0 0 0" />
  </joint>
  <joint name="base_weld_workstation_arm_left_mount" type="fixed">
    <origin xyz="0.0637 0.719 1.267" rpy="0 1.57079633 1.57079633" />
    <parent link="base_workstation_link" />
    <child link="base_workstation_arm_left_mount" />
  </joint>
  <joint name="base_weld_workstation_arm_right_mount" type="fixed">
    <origin xyz="0.0637 0.536 1.267" rpy="0 1.57079633 -1.57079633" />
    <parent link="base_workstation_link" />
    <child link="base_workstation_arm_right_mount" />
  </joint>
  <joint name="arm_left_AR5_5_07L_W4C4A2_joint_1" type="revolute">
    <parent link="arm_left_AR5_5_07L_W4C4A2_base" />
    <child link="arm_left_AR5_5_07L_W4C4A2_link1" />
    <limit effort="108" lower="-3.1067" upper="3.1067" velocity="3.0543261909900763" />
    <dynamics damping="14.22378" friction="1.234293" />
    <axis xyz="0 0 1" />
    <origin rpy="0 0 0" xyz="0 0 0" />
  </joint>
  <joint name="arm_left_AR5_5_07L_W4C4A2_joint_2" type="revolute">
    <parent link="arm_left_AR5_5_07L_W4C4A2_link1" />
    <child link="arm_left_AR5_5_07L_W4C4A2_link2" />
    <limit effort="108" lower="-2.0944" upper="2.0944" velocity="3.0543261909900763" />
    <dynamics damping="13.710972" friction="3.073299" />
    <axis xyz="0 1 0" />
    <origin rpy="0 0 0" xyz="0 0 0.1745" />
  </joint>
  <joint name="arm_left_AR5_5_07L_W4C4A2_joint_3" type="revolute">
    <parent link="arm_left_AR5_5_07L_W4C4A2_link2" />
    <child link="arm_left_AR5_5_07L_W4C4A2_link3" />
    <limit effort="66" lower="-3.1067" upper="3.1067" velocity="4.71238898038469" />
    <dynamics damping="3.791042" friction="0.352159" />
    <axis xyz="0 0 1" />
    <origin rpy="0 0 0" xyz="0 0 0.314" />
  </joint>
  <joint name="arm_left_AR5_5_07L_W4C4A2_joint_4" type="revolute">
    <parent link="arm_left_AR5_5_07L_W4C4A2_link3" />
    <child link="arm_left_AR5_5_07L_W4C4A2_link4" />
    <limit effort="66" lower="-1.0472" upper="2.5307" velocity="5.235987755982989" />
    <dynamics damping="0.333154" friction="1.926179" />
    <axis xyz="0 1 0" />
    <origin rpy="0 0 0" xyz="0.01 0 0" />
  </joint>
  <joint name="arm_left_AR5_5_07L_W4C4A2_joint_5" type="revolute">
    <parent link="arm_left_AR5_5_07L_W4C4A2_link4" />
    <child link="arm_left_AR5_5_07L_W4C4A2_link5" />
    <limit effort="19" lower="-3.1067" upper="3.1067" velocity="4.1887902047863905" />
    <dynamics damping="4.136716" friction="0.295156" />
    <axis xyz="0 0 1" />
    <origin rpy="0 0 0" xyz="-0.01 0 0.272" />
  </joint>
  <joint name="arm_left_AR5_5_07L_W4C4A2_joint_6" type="revolute">
    <parent link="arm_left_AR5_5_07L_W4C4A2_link5" />
    <child link="arm_left_AR5_5_07L_W4C4A2_link6" />
    <limit effort="19" lower="-1.0472" upper="1.0472" velocity="4.1887902047863905" />
    <dynamics damping="4.748679" friction="1.322494" />
    <axis xyz="0 1 0" />
    <origin rpy="0 0 0" xyz="0 0 0" />
  </joint>
  <joint name="arm_left_AR5_5_07L_W4C4A2_joint_7" type="revolute">
    <parent link="arm_left_AR5_5_07L_W4C4A2_link6" />
    <child link="arm_left_AR5_5_07L_W4C4A2_link7" />
    <limit effort="19" lower="-1.0472" upper="1.0472" velocity="4.1887902047863905" />
    <dynamics damping="3.667978" friction="0.926051" />
    <axis xyz="1 0 0" />
    <origin rpy="0 0 0" xyz="0 0 0" />
  </joint>
  <joint name="arm_left_AR5_5_07L_W4C4A2_tcp_joint" type="fixed">
    <parent link="arm_left_AR5_5_07L_W4C4A2_link7" />
    <child link="arm_left_AR5_5_07L_W4C4A2_tcp" />
    <origin rpy="0 0 0" xyz="0 0 0.097" />
  </joint>
  <joint name="arm_right_AR5_5_07R_W4C4A2_joint_1" type="revolute">
    <parent link="arm_right_AR5_5_07R_W4C4A2_base" />
    <child link="arm_right_AR5_5_07R_W4C4A2_link1" />
    <limit effort="108" lower="-3.1067" upper="3.1067" velocity="3.0543261909900763" />
    <dynamics damping="14.22378" friction="1.234293" />
    <axis xyz="0 0 1" />
    <origin rpy="0 0 0" xyz="0 0 0" />
  </joint>
  <joint name="arm_right_AR5_5_07R_W4C4A2_joint_2" type="revolute">
    <parent link="arm_right_AR5_5_07R_W4C4A2_link1" />
    <child link="arm_right_AR5_5_07R_W4C4A2_link2" />
    <limit effort="108" lower="-2.0944" upper="2.0944" velocity="3.0543261909900763" />
    <dynamics damping="13.710972" friction="3.073299" />
    <axis xyz="0 1 0" />
    <origin rpy="0 0 0" xyz="0 0 0.1745" />
  </joint>
  <joint name="arm_right_AR5_5_07R_W4C4A2_joint_3" type="revolute">
    <parent link="arm_right_AR5_5_07R_W4C4A2_link2" />
    <child link="arm_right_AR5_5_07R_W4C4A2_link3" />
    <limit effort="66" lower="-3.1067" upper="3.1067" velocity="4.71238898038469" />
    <dynamics damping="3.791042" friction="0.352159" />
    <axis xyz="0 0 1" />
    <origin rpy="0 0 0" xyz="0 0 0.314" />
  </joint>
  <joint name="arm_right_AR5_5_07R_W4C4A2_joint_4" type="revolute">
    <parent link="arm_right_AR5_5_07R_W4C4A2_link3" />
    <child link="arm_right_AR5_5_07R_W4C4A2_link4" />
    <limit effort="66" lower="-1.0472" upper="2.5307" velocity="5.235987755982989" />
    <dynamics damping="0.333154" friction="1.926179" />
    <axis xyz="0 1 0" />
    <origin rpy="0 0 0" xyz="0.01 0 0" />
  </joint>
  <joint name="arm_right_AR5_5_07R_W4C4A2_joint_5" type="revolute">
    <parent link="arm_right_AR5_5_07R_W4C4A2_link4" />
    <child link="arm_right_AR5_5_07R_W4C4A2_link5" />
    <limit effort="19" lower="-3.1067" upper="3.1067" velocity="4.1887902047863905" />
    <dynamics damping="4.136716" friction="0.295156" />
    <axis xyz="0 0 1" />
    <origin rpy="0 0 0" xyz="-0.01 0 0.272" />
  </joint>
  <joint name="arm_right_AR5_5_07R_W4C4A2_joint_6" type="revolute">
    <parent link="arm_right_AR5_5_07R_W4C4A2_link5" />
    <child link="arm_right_AR5_5_07R_W4C4A2_link6" />
    <limit effort="19" lower="-1.0472" upper="1.0472" velocity="4.1887902047863905" />
    <dynamics damping="4.748679" friction="1.322494" />
    <axis xyz="0 1 0" />
    <origin rpy="0 0 0" xyz="0 0 0" />
  </joint>
  <joint name="arm_right_AR5_5_07R_W4C4A2_joint_7" type="revolute">
    <parent link="arm_right_AR5_5_07R_W4C4A2_link6" />
    <child link="arm_right_AR5_5_07R_W4C4A2_link7" />
    <limit effort="19" lower="-1.0472" upper="1.0472" velocity="4.1887902047863905" />
    <dynamics damping="3.667978" friction="0.926051" />
    <axis xyz="1 0 0" />
    <origin rpy="0 0 0" xyz="0 0 0" />
  </joint>
  <joint name="arm_right_AR5_5_07R_W4C4A2_tcp_joint" type="fixed">
    <parent link="arm_right_AR5_5_07R_W4C4A2_link7" />
    <child link="arm_right_AR5_5_07R_W4C4A2_tcp" />
    <origin rpy="0 0 0" xyz="0 0 0.097" />
  </joint>
  <joint name="hand_left_lh_thumb_cmc_roll" type="revolute">
    <origin xyz="0.01916 -0.01 0.0436" rpy="0 0 0" />
    <parent link="hand_left_lh_hand_base_link" />
    <child link="hand_left_lh_thumb_metacarpals_base1" />
    <axis xyz="-1 0 0" />
    <limit lower="0" upper="1.309" effort="100" velocity="1" />
  </joint>
  <joint name="hand_left_lh_thumb_cmc_yaw" type="revolute">
    <origin xyz="0.019845 0 0" rpy="0.77165 0 0" />
    <parent link="hand_left_lh_thumb_metacarpals_base1" />
    <child link="hand_left_lh_thumb_metacarpals_base2" />
    <axis xyz="0 0 1" />
    <limit lower="0" upper="1.5882" effort="100" velocity="1" />
  </joint>
  <joint name="hand_left_lh_thumb_cmc_pitch" type="revolute">
    <origin xyz="0.0088218 -0.024245 0.0005" rpy="0 -0.91 1.9199" />
    <parent link="hand_left_lh_thumb_metacarpals_base2" />
    <child link="hand_left_lh_thumb_metacarpals" />
    <axis xyz="0 1 0" />
    <limit lower="0" upper="0.7854" effort="100" velocity="1" />
  </joint>
  <joint name="hand_left_lh_thumb_mcp" type="revolute">
    <origin xyz="0.0127018248 0 0.0627256157" rpy="0 0 0" />
    <parent link="hand_left_lh_thumb_metacarpals" />
    <child link="hand_left_lh_thumb_proximal" />
    <axis xyz="0 1 0" />
    <limit lower="0" upper="1.2217" effort="100" velocity="1" />
  </joint>
  <joint name="hand_left_lh_thumb_dip" type="revolute">
    <origin xyz="-0.00483652209 0 0.0342226492" rpy="0 0 0" />
    <parent link="hand_left_lh_thumb_proximal" />
    <child link="hand_left_lh_thumb_distal" />
    <axis xyz="0 1 0" />
    <limit lower="0" upper="1.2392" effort="100" velocity="1" />
    <mimic joint="hand_left_lh_thumb_mcp" multiplier="1.0142" offset="0" />
  </joint>
  <joint name="hand_left_lh_index_mcp_roll" type="revolute">
    <origin xyz="0.0038 -0.03525 0.1481" rpy="0 0 0" />
    <parent link="hand_left_lh_hand_base_link" />
    <child link="hand_left_lh_index_metacarpals" />
    <axis xyz="-1 0 0" />
    <limit lower="-0.2269" upper="0.2269" effort="100" velocity="1" />
  </joint>
  <joint name="hand_left_lh_index_mcp_pitch" type="revolute">
    <origin xyz="-0.0021302 0 0" rpy="0 0 0" />
    <parent link="hand_left_lh_index_metacarpals" />
    <child link="hand_left_lh_index_proximal" />
    <axis xyz="0 1 0" />
    <limit lower="0" upper="1.2217" effort="100" velocity="1" />
  </joint>
  <joint name="hand_left_lh_index_pip" type="revolute">
    <origin xyz="-0.0041946 0 0.044819" rpy="0 0 0" />
    <parent link="hand_left_lh_index_proximal" />
    <child link="hand_left_lh_index_middle" />
    <axis xyz="0 1 0" />
    <limit lower="0" upper="1.7279" effort="100" velocity="1" />
  </joint>
  <joint name="hand_left_lh_index_dip" type="revolute">
    <origin xyz="0.0028245 0 0.031696" rpy="0 0 0" />
    <parent link="hand_left_lh_index_middle" />
    <child link="hand_left_lh_index_distal" />
    <axis xyz="0 1 0" />
    <limit lower="0" upper="1.3614" effort="100" velocity="1" />
    <mimic joint="hand_left_lh_index_pip" multiplier="0.7879" offset="0" />
  </joint>
  <joint name="hand_left_lh_middle_mcp_roll" type="revolute">
    <origin xyz="0.00379999999 -0.01175 0.1526" rpy="0 0 0" />
    <parent link="hand_left_lh_hand_base_link" />
    <child link="hand_left_lh_middle_metacarpals" />
    <axis xyz="-1 0 0" />
    <limit lower="-0.23" upper="0.23" effort="100" velocity="1" />
  </joint>
  <joint name="hand_left_lh_middle_mcp_pitch" type="revolute">
    <origin xyz="-0.0021302 0 0" rpy="0 0 0" />
    <parent link="hand_left_lh_middle_metacarpals" />
    <child link="hand_left_lh_middle_proximal" />
    <axis xyz="0 1 0" />
    <limit lower="0" upper="1.2217" effort="100" velocity="1" />
  </joint>
  <joint name="hand_left_lh_middle_pip" type="revolute">
    <origin xyz="-0.00419457746 0 0.0448194332" rpy="0 0 0" />
    <parent link="hand_left_lh_middle_proximal" />
    <child link="hand_left_lh_middle_middle" />
    <axis xyz="0 1 0" />
    <limit lower="0" upper="1.7279" effort="100" velocity="1" />
  </joint>
  <joint name="hand_left_lh_middle_dip" type="revolute">
    <origin xyz="0.0028245 0 0.031696" rpy="0 0 0" />
    <parent link="hand_left_lh_middle_middle" />
    <child link="hand_left_lh_middle_distal" />
    <axis xyz="0 1 0" />
    <limit lower="0" upper="1.3614" effort="100" velocity="1" />
    <mimic joint="hand_left_lh_middle_pip" multiplier="0.7879" offset="0" />
  </joint>
  <joint name="hand_left_lh_ring_mcp_roll" type="revolute">
    <origin xyz="0.0038 0.01175 0.1481" rpy="0 0 0" />
    <parent link="hand_left_lh_hand_base_link" />
    <child link="hand_left_lh_ring_metacarpals" />
    <axis xyz="-1 0 0" />
    <limit lower="-0.23" upper="0.23" effort="100" velocity="1" />
  </joint>
  <joint name="hand_left_lh_ring_mcp_pitch" type="revolute">
    <origin xyz="-0.0021302 0 0" rpy="0 0 0" />
    <parent link="hand_left_lh_ring_metacarpals" />
    <child link="hand_left_lh_ring_proximal" />
    <axis xyz="0 1 0" />
    <limit lower="0" upper="1.2217" effort="100" velocity="1" />
  </joint>
  <joint name="hand_left_lh_ring_pip" type="revolute">
    <origin xyz="-0.00419457746 0 0.0448194332" rpy="0 0 0" />
    <parent link="hand_left_lh_ring_proximal" />
    <child link="hand_left_lh_ring_middle" />
    <axis xyz="0 1 0" />
    <limit lower="0" upper="1.7279" effort="100" velocity="1" />
  </joint>
  <joint name="hand_left_lh_ring_dip" type="revolute">
    <origin xyz="0.0028245 0 0.031696" rpy="0 0 0" />
    <parent link="hand_left_lh_ring_middle" />
    <child link="hand_left_lh_ring_distal" />
    <axis xyz="0 1 0" />
    <limit lower="0" upper="1.3614" effort="100" velocity="1" />
    <mimic joint="hand_left_lh_ring_pip" multiplier="0.7879" offset="0" />
  </joint>
  <joint name="hand_left_lh_pinky_mcp_roll" type="revolute">
    <origin xyz="0.0038 0.03525 0.1436" rpy="0 0 0" />
    <parent link="hand_left_lh_hand_base_link" />
    <child link="hand_left_lh_pinky_metacarpals" />
    <axis xyz="-1 0 0" />
    <limit lower="-0.23" upper="0.23" effort="100" velocity="1" />
  </joint>
  <joint name="hand_left_lh_pinky_mcp_pitch" type="revolute">
    <origin xyz="-0.0021302 0 0" rpy="0 0 0" />
    <parent link="hand_left_lh_pinky_metacarpals" />
    <child link="hand_left_lh_pinky_proximal" />
    <axis xyz="0 1 0" />
    <limit lower="0" upper="1.2217" effort="100" velocity="1" />
  </joint>
  <joint name="hand_left_lh_pinky_pip" type="revolute">
    <origin xyz="-0.0041946 0 0.044819" rpy="0 0 0" />
    <parent link="hand_left_lh_pinky_proximal" />
    <child link="hand_left_lh_pinky_middle" />
    <axis xyz="0 1 0" />
    <limit lower="0" upper="1.7279" effort="100" velocity="1" />
  </joint>
  <joint name="hand_left_lh_pinky_dip" type="revolute">
    <origin xyz="0.0028245 0 0.031696" rpy="0 0 0" />
    <parent link="hand_left_lh_pinky_middle" />
    <child link="hand_left_lh_pinky_distal" />
    <axis xyz="0 1 0" />
    <limit lower="0" upper="1.3614" effort="100" velocity="1" />
    <mimic joint="hand_left_lh_pinky_pip" multiplier="0.7879" offset="0" />
  </joint>
  <joint name="hand_right_rh_thumb_cmc_roll" type="revolute">
    <origin xyz="0.01916 0.01 0.0436" rpy="0 0 0" />
    <parent link="hand_right_rh_hand_base_link" />
    <child link="hand_right_rh_thumb_metacarpals_base1" />
    <axis xyz="1 0 0" />
    <limit lower="0" upper="1.309" effort="1" velocity="100" />
  </joint>
  <joint name="hand_right_rh_thumb_cmc_yaw" type="revolute">
    <origin xyz="0.019845 0 0" rpy="-0.77165 0 0" />
    <parent link="hand_right_rh_thumb_metacarpals_base1" />
    <child link="hand_right_rh_thumb_metacarpals_base2" />
    <axis xyz="0 0 -1" />
    <limit lower="0" upper="1.5882" effort="1" velocity="100" />
  </joint>
  <joint name="hand_right_rh_thumb_cmc_pitch" type="revolute">
    <origin xyz="0.0088264 0.024243 0.0005" rpy="0 -0.91 -1.9199" />
    <parent link="hand_right_rh_thumb_metacarpals_base2" />
    <child link="hand_right_rh_thumb_metacarpals" />
    <axis xyz="0 1 0" />
    <limit lower="0" upper="0.7854" effort="1" velocity="100" />
  </joint>
  <joint name="hand_right_rh_thumb_mcp" type="revolute">
    <origin xyz="0.012702 0 0.062726" rpy="0 0 0" />
    <parent link="hand_right_rh_thumb_metacarpals" />
    <child link="hand_right_rh_thumb_proximal" />
    <axis xyz="0 1 0" />
    <limit lower="0" upper="1.2217" effort="1" velocity="100" />
  </joint>
  <joint name="hand_right_rh_thumb_dip" type="revolute">
    <origin xyz="-0.0048365 0 0.034223" rpy="0 0 0" />
    <parent link="hand_right_rh_thumb_proximal" />
    <child link="hand_right_rh_thumb_distal" />
    <axis xyz="0 1 0" />
    <limit lower="0" upper="1.2392" effort="1" velocity="100" />
    <mimic joint="hand_right_rh_thumb_mcp" multiplier="1.0142" offset="0" />
  </joint>
  <joint name="hand_right_rh_index_mcp_roll" type="revolute">
    <origin xyz="0.0038 0.03525 0.1481" rpy="0 0 0" />
    <parent link="hand_right_rh_hand_base_link" />
    <child link="hand_right_rh_index_metacarpals" />
    <axis xyz="-1 0 0" />
    <limit lower="-0.2269" upper="0.2269" effort="1" velocity="100" />
  </joint>
  <joint name="hand_right_rh_index_mcp_pitch" type="revolute">
    <origin xyz="-0.0021302 0 0" rpy="0 0 0" />
    <parent link="hand_right_rh_index_metacarpals" />
    <child link="hand_right_rh_index_proximal" />
    <axis xyz="0 1 0" />
    <limit lower="0" upper="1.2217" effort="1" velocity="100" />
  </joint>
  <joint name="hand_right_rh_index_pip" type="revolute">
    <origin xyz="-0.0041946 0 0.044819" rpy="0 0 0" />
    <parent link="hand_right_rh_index_proximal" />
    <child link="hand_right_rh_index_middle" />
    <axis xyz="0 1 0" />
    <limit lower="0" upper="1.7279" effort="1" velocity="100" />
  </joint>
  <joint name="hand_right_rh_index_dip" type="revolute">
    <origin xyz="0.0028245 0 0.031696" rpy="0 0 0" />
    <parent link="hand_right_rh_index_middle" />
    <child link="hand_right_rh_index_distal" />
    <axis xyz="0 1 0" />
    <limit lower="0" upper="1.3614" effort="1" velocity="100" />
    <mimic joint="hand_right_rh_index_pip" multiplier="0.7879" offset="0" />
  </joint>
  <joint name="hand_right_rh_middle_mcp_roll" type="revolute">
    <origin xyz="0.0038 0.01175 0.1526" rpy="0 0 0" />
    <parent link="hand_right_rh_hand_base_link" />
    <child link="hand_right_rh_middle_metacarpals" />
    <axis xyz="-1 0 0" />
    <limit lower="-0.23" upper="0.23" effort="1" velocity="100" />
  </joint>
  <joint name="hand_right_rh_middle_mcp_pitch" type="revolute">
    <origin xyz="-0.0021302 0 0" rpy="0 0 0" />
    <parent link="hand_right_rh_middle_metacarpals" />
    <child link="hand_right_rh_middle_proximal" />
    <axis xyz="0 1 0" />
    <limit lower="0" upper="1.2217" effort="1" velocity="100" />
  </joint>
  <joint name="hand_right_rh_middle_pip" type="revolute">
    <origin xyz="-0.0041946 0 0.044819" rpy="0 0 0" />
    <parent link="hand_right_rh_middle_proximal" />
    <child link="hand_right_rh_middle_middle" />
    <axis xyz="0 1 0" />
    <limit lower="0" upper="1.7279" effort="1" velocity="100" />
  </joint>
  <joint name="hand_right_rh_middle_dip" type="revolute">
    <origin xyz="0.0028245 0 0.031696" rpy="0 0 0" />
    <parent link="hand_right_rh_middle_middle" />
    <child link="hand_right_rh_middle_distal" />
    <axis xyz="0 1 0" />
    <limit lower="0" upper="1.3614" effort="1" velocity="100" />
    <mimic joint="hand_right_rh_middle_pip" multiplier="0.7879" offset="0" />
  </joint>
  <joint name="hand_right_rh_ring_mcp_roll" type="revolute">
    <origin xyz="0.0038 -0.01175 0.1481" rpy="0 0 0" />
    <parent link="hand_right_rh_hand_base_link" />
    <child link="hand_right_rh_ring_metacarpals" />
    <axis xyz="-1 0 0" />
    <limit lower="-0.23" upper="0.23" effort="1" velocity="100" />
  </joint>
  <joint name="hand_right_rh_ring_mcp_pitch" type="revolute">
    <origin xyz="-0.0021302 0 0" rpy="0 0 0" />
    <parent link="hand_right_rh_ring_metacarpals" />
    <child link="hand_right_rh_ring_proximal" />
    <axis xyz="0 1 0" />
    <limit lower="0" upper="1.2217" effort="1" velocity="100" />
  </joint>
  <joint name="hand_right_rh_ring_pip" type="revolute">
    <origin xyz="-0.0041946 0 0.044819" rpy="0 0 0" />
    <parent link="hand_right_rh_ring_proximal" />
    <child link="hand_right_rh_ring_middle" />
    <axis xyz="0 1 0" />
    <limit lower="0" upper="1.7279" effort="1" velocity="100" />
  </joint>
  <joint name="hand_right_rh_ring_dip" type="revolute">
    <origin xyz="0.0028245 0 0.031696" rpy="0 0 0" />
    <parent link="hand_right_rh_ring_middle" />
    <child link="hand_right_rh_ring_distal" />
    <axis xyz="0 1 0" />
    <limit lower="0" upper="1.3614" effort="1" velocity="100" />
    <mimic joint="hand_right_rh_ring_pip" multiplier="0.7879" offset="0" />
  </joint>
  <joint name="hand_right_rh_pinky_mcp_roll" type="revolute">
    <origin xyz="0.0038 -0.03525 0.1436" rpy="0 0 0" />
    <parent link="hand_right_rh_hand_base_link" />
    <child link="hand_right_rh_pinky_metacarpals" />
    <axis xyz="-1 0 0" />
    <limit lower="-0.23" upper="0.23" effort="1" velocity="100" />
  </joint>
  <joint name="hand_right_rh_pinky_mcp_pitch" type="revolute">
    <origin xyz="-0.0021302 0 0" rpy="0 0 0" />
    <parent link="hand_right_rh_pinky_metacarpals" />
    <child link="hand_right_rh_pinky_proximal" />
    <axis xyz="0 1 0" />
    <limit lower="0" upper="1.2217" effort="1" velocity="100" />
  </joint>
  <joint name="hand_right_rh_pinky_pip" type="revolute">
    <origin xyz="-0.0041946 0 0.044819" rpy="0 0 0" />
    <parent link="hand_right_rh_pinky_proximal" />
    <child link="hand_right_rh_pinky_middle" />
    <axis xyz="0 1 0" />
    <limit lower="0" upper="1.7279" effort="1" velocity="100" />
  </joint>
  <joint name="hand_right_rh_pinky_dip" type="revolute">
    <origin xyz="0.0028245 0 0.031696" rpy="0 0 0" />
    <parent link="hand_right_rh_pinky_middle" />
    <child link="hand_right_rh_pinky_distal" />
    <axis xyz="0 1 0" />
    <limit lower="0" upper="1.3614" effort="1" velocity="100" />
    <mimic joint="hand_right_rh_pinky_pip" multiplier="0.7879" offset="0" />
  </joint>
  <transmission name="arm_left_tran1">
    <type>transmission_interface/SimpleTransmission</type>
    <joint name="arm_left_AR5_5_07L_W4C4A2_joint_8">
      <hardwareInterface>EffortJointInterface</hardwareInterface>
    </joint>
    <actuator name="motor1">
      <hardwareInterface>EffortJointInterface</hardwareInterface>
      <mechanicalReduction>1</mechanicalReduction>
    </actuator>
  </transmission>
  <transmission name="arm_left_tran2">
    <type>transmission_interface/SimpleTransmission</type>
    <joint name="arm_left_xmate_joint_2">
      <hardwareInterface>EffortJointInterface</hardwareInterface>
    </joint>
    <actuator name="motor2">
      <hardwareInterface>EffortJointInterface</hardwareInterface>
      <mechanicalReduction>1</mechanicalReduction>
    </actuator>
  </transmission>
  <transmission name="arm_left_tran3">
    <type>transmission_interface/SimpleTransmission</type>
    <joint name="arm_left_xmate_joint_3">
      <hardwareInterface>EffortJointInterface</hardwareInterface>
    </joint>
    <actuator name="motor3">
      <hardwareInterface>EffortJointInterface</hardwareInterface>
      <mechanicalReduction>1</mechanicalReduction>
    </actuator>
  </transmission>
  <transmission name="arm_left_tran4">
    <type>transmission_interface/SimpleTransmission</type>
    <joint name="arm_left_xmate_joint_4">
      <hardwareInterface>EffortJointInterface</hardwareInterface>
    </joint>
    <actuator name="motor4">
      <hardwareInterface>EffortJointInterface</hardwareInterface>
      <mechanicalReduction>1</mechanicalReduction>
    </actuator>
  </transmission>
  <transmission name="arm_left_tran5">
    <type>transmission_interface/SimpleTransmission</type>
    <joint name="arm_left_xmate_joint_5">
      <hardwareInterface>EffortJointInterface</hardwareInterface>
    </joint>
    <actuator name="motor5">
      <hardwareInterface>EffortJointInterface</hardwareInterface>
      <mechanicalReduction>1</mechanicalReduction>
    </actuator>
  </transmission>
  <transmission name="arm_left_tran6">
    <type>transmission_interface/SimpleTransmission</type>
    <joint name="arm_left_xmate_joint_6">
      <hardwareInterface>EffortJointInterface</hardwareInterface>
    </joint>
    <actuator name="motor6">
      <hardwareInterface>EffortJointInterface</hardwareInterface>
      <mechanicalReduction>1</mechanicalReduction>
    </actuator>
  </transmission>
  <transmission name="arm_left_tran7">
    <type>transmission_interface/SimpleTransmission</type>
    <joint name="arm_left_xmate_joint_7">
      <hardwareInterface>EffortJointInterface</hardwareInterface>
    </joint>
    <actuator name="motor7">
      <hardwareInterface>EffortJointInterface</hardwareInterface>
      <mechanicalReduction>1</mechanicalReduction>
    </actuator>
  </transmission>
  <transmission name="arm_right_tran1">
    <type>transmission_interface/SimpleTransmission</type>
    <joint name="arm_right_AR5_5_07R_W4C4A2_joint_8">
      <hardwareInterface>EffortJointInterface</hardwareInterface>
    </joint>
    <actuator name="motor1">
      <hardwareInterface>EffortJointInterface</hardwareInterface>
      <mechanicalReduction>1</mechanicalReduction>
    </actuator>
  </transmission>
  <transmission name="arm_right_tran2">
    <type>transmission_interface/SimpleTransmission</type>
    <joint name="arm_right_xmate_joint_2">
      <hardwareInterface>EffortJointInterface</hardwareInterface>
    </joint>
    <actuator name="motor2">
      <hardwareInterface>EffortJointInterface</hardwareInterface>
      <mechanicalReduction>1</mechanicalReduction>
    </actuator>
  </transmission>
  <transmission name="arm_right_tran3">
    <type>transmission_interface/SimpleTransmission</type>
    <joint name="arm_right_xmate_joint_3">
      <hardwareInterface>EffortJointInterface</hardwareInterface>
    </joint>
    <actuator name="motor3">
      <hardwareInterface>EffortJointInterface</hardwareInterface>
      <mechanicalReduction>1</mechanicalReduction>
    </actuator>
  </transmission>
  <transmission name="arm_right_tran4">
    <type>transmission_interface/SimpleTransmission</type>
    <joint name="arm_right_xmate_joint_4">
      <hardwareInterface>EffortJointInterface</hardwareInterface>
    </joint>
    <actuator name="motor4">
      <hardwareInterface>EffortJointInterface</hardwareInterface>
      <mechanicalReduction>1</mechanicalReduction>
    </actuator>
  </transmission>
  <transmission name="arm_right_tran5">
    <type>transmission_interface/SimpleTransmission</type>
    <joint name="arm_right_xmate_joint_5">
      <hardwareInterface>EffortJointInterface</hardwareInterface>
    </joint>
    <actuator name="motor5">
      <hardwareInterface>EffortJointInterface</hardwareInterface>
      <mechanicalReduction>1</mechanicalReduction>
    </actuator>
  </transmission>
  <transmission name="arm_right_tran6">
    <type>transmission_interface/SimpleTransmission</type>
    <joint name="arm_right_xmate_joint_6">
      <hardwareInterface>EffortJointInterface</hardwareInterface>
    </joint>
    <actuator name="motor6">
      <hardwareInterface>EffortJointInterface</hardwareInterface>
      <mechanicalReduction>1</mechanicalReduction>
    </actuator>
  </transmission>
  <transmission name="arm_right_tran7">
    <type>transmission_interface/SimpleTransmission</type>
    <joint name="arm_right_xmate_joint_7">
      <hardwareInterface>EffortJointInterface</hardwareInterface>
    </joint>
    <actuator name="motor7">
      <hardwareInterface>EffortJointInterface</hardwareInterface>
      <mechanicalReduction>1</mechanicalReduction>
    </actuator>
  </transmission>
  <joint name="mount_arm_left_to_base_base_mount" type="fixed">
    <origin xyz="0 0 0" rpy="0 0 0" />
    <parent link="base_workstation_arm_left_mount" />
    <child link="arm_left_AR5_5_07L_W4C4A2_base" />
  </joint>
  <joint name="mount_arm_right_to_base_base_mount" type="fixed">
    <origin xyz="0 0 0" rpy="0 0 0" />
    <parent link="base_workstation_arm_right_mount" />
    <child link="arm_right_AR5_5_07R_W4C4A2_base" />
  </joint>
  <joint name="mount_hand_left_to_arm_left_wrist_mount" type="fixed">
    <origin xyz="0 0 0.03" rpy="0 0 1.5708" />
    <parent link="arm_left_AR5_5_07L_W4C4A2_tcp" />
    <child link="hand_left_lh_hand_base_link" />
  </joint>
  <joint name="mount_hand_right_to_arm_right_wrist_mount" type="fixed">
    <origin xyz="0 0 0.03" rpy="0 0 -1.5708" />
    <parent link="arm_right_AR5_5_07R_W4C4A2_tcp" />
    <child link="hand_right_rh_hand_base_link" />
  </joint>
  <joint name="mount_world_to_base" type="fixed">
    <origin xyz="0 0 0" rpy="0 0 0" />
    <parent link="world" />
    <child link="base_workstation_link" />
  </joint>
</robot>
