<?xml version="1.0" encoding="UTF-8"?>
<!-- Generated by linker_robot_assets.composer (version 0.1.0). Workstation: a7_lite_l6_dc. Recipe sha256: 8cc907a988fef2ef9455cec3b09fe25baef7b33edaec06689a0e3518664fb096. Do not edit by hand; re-run `python -m linker_robot_assets.composer.compose <workstation>`. -->
<robot name="a7_lite_l6_dc">
  <link name="world" />
  <material name="hand_left_black">
    <color rgba="0.0 0.0 0.0 1.0" />
  </material>
  <material name="hand_left_blue">
    <color rgba="0.0 0.0 0.8 1.0" />
  </material>
  <material name="hand_left_green">
    <color rgba="0.0 0.8 0.0 1.0" />
  </material>
  <material name="hand_left_grey">
    <color rgba="0.2 0.2 0.2 1.0" />
  </material>
  <material name="hand_left_orange">
    <color rgba="1.0 0.423529411765 0.0392156862745 1.0" />
  </material>
  <material name="hand_left_brown">
    <color rgba="0.870588235294 0.811764705882 0.764705882353 1.0" />
  </material>
  <material name="hand_left_red">
    <color rgba="0.8 0.0 0.0 1.0" />
  </material>
  <material name="hand_left_white">
    <color rgba="1.0 1.0 1.0 1.0" />
  </material>
  <material name="hand_left_Beige">
    <color rgba="1.0 0.784 0.5765 1.0" />
  </material>
  <material name="hand_right_black">
    <color rgba="0.0 0.0 0.0 1.0" />
  </material>
  <material name="hand_right_blue">
    <color rgba="0.0 0.0 0.8 1.0" />
  </material>
  <material name="hand_right_green">
    <color rgba="0.0 0.8 0.0 1.0" />
  </material>
  <material name="hand_right_grey">
    <color rgba="0.2 0.2 0.2 1.0" />
  </material>
  <material name="hand_right_orange">
    <color rgba="1.0 0.423529411765 0.0392156862745 1.0" />
  </material>
  <material name="hand_right_brown">
    <color rgba="0.870588235294 0.811764705882 0.764705882353 1.0" />
  </material>
  <material name="hand_right_red">
    <color rgba="0.8 0.0 0.0 1.0" />
  </material>
  <material name="hand_right_white">
    <color rgba="1.0 1.0 1.0 1.0" />
  </material>
  <material name="hand_right_Beige">
    <color rgba="1.0 0.784 0.5765 1.0" />
  </material>
  <link name="base_torso_root" />
  <link name="base_base_link">
    <inertial>
      <origin xyz="0.0044493 9.5996e-07 -0.58827" rpy="0 0 0" />
      <mass value="8.6616" />
      <inertia ixx="0.19297" ixy="1.6977E-06" ixz="0.00086704" iyy="0.19297" iyz="4.1272E-08" izz="0.072594" />
    </inertial>
    <visual>
      <origin xyz="0 0 0" rpy="0 0 0" />
      <geometry>
        <mesh filename="../../components/bases/a7_lite_torso/variants/default/meshes/base_link.STL" />
      </geometry>
      <material name="base_a7_lite_torso_gray">
        <color rgba="0.75294 0.75294 0.75294 1" />
      </material>
    </visual>
    <collision>
      <origin xyz="0 0 0" rpy="0 0 0" />
      <geometry>
        <mesh filename="../../components/bases/a7_lite_torso/variants/default/meshes/base_link.STL" />
      </geometry>
    </collision>
  </link>
  <link name="base_arm_left_mount" />
  <link name="base_arm_right_mount" />
  <link name="arm_left_L_arm_root" />
  <link name="arm_left_L1_Link">
    <inertial>
      <origin xyz="0.0045974 0.067978 0.00066635" rpy="0 0 0" />
      <mass value="1.1899" />
      <inertia ixx="0.0016082" ixy="3.5266E-06" ixz="2.0532E-07" iyy="0.00086283" iyz="6.5642E-06" izz="0.00092662" />
    </inertial>
    <visual>
      <origin xyz="0 0 0" rpy="0 0 0" />
      <geometry>
        <mesh filename="../../components/arms/a7_lite/variants/left/meshes/L1_Link.STL" />
      </geometry>
      <material name="">
        <color rgba="0.75294 0.75294 0.75294 1" />
      </material>
    </visual>
    <collision>
      <origin xyz="0 0 0" rpy="0 0 0" />
      <geometry>
        <mesh filename="../../components/arms/a7_lite/variants/left/meshes/L1_Link.STL" />
      </geometry>
    </collision>
  </link>
  <link name="arm_left_L2_Link">
    <inertial>
      <origin xyz="-0.030894 9.2644e-05 -0.099437" rpy="0 0 0" />
      <mass value="1.0659" />
      <inertia ixx="0.001451" ixy="3.1371E-06" ixz="-1.519E-06" iyy="0.0012495" iyz="-1.1542E-05" izz="0.0010752" />
    </inertial>
    <visual>
      <origin xyz="0 0 0" rpy="0 0 0" />
      <geometry>
        <mesh filename="../../components/arms/a7_lite/variants/left/meshes/L2_Link.STL" />
      </geometry>
      <material name="">
        <color rgba="0.75294 0.75294 0.75294 1" />
      </material>
    </visual>
    <collision>
      <origin xyz="0 0 0" rpy="0 0 0" />
      <geometry>
        <mesh filename="../../components/arms/a7_lite/variants/left/meshes/L2_Link.STL" />
      </geometry>
    </collision>
  </link>
  <link name="arm_left_L3_Link">
    <inertial>
      <origin xyz="-5.9577e-05 0.001318 -0.078466" rpy="0 0 0" />
      <mass value="1.2763" />
      <inertia ixx="0.00078242" ixy="-2.9327E-07" ixz="7.1339E-06" iyy="0.0010444" iyz="-2.978E-07" izz="0.00063166" />
    </inertial>
    <visual>
      <origin xyz="0 0 0" rpy="0 0 0" />
      <geometry>
        <mesh filename="../../components/arms/a7_lite/variants/left/meshes/L3_Link.STL" />
      </geometry>
      <material name="">
        <color rgba="0.75294 0.75294 0.75294 1" />
      </material>
    </visual>
    <collision>
      <origin xyz="0 0 0" rpy="0 0 0" />
      <geometry>
        <mesh filename="../../components/arms/a7_lite/variants/left/meshes/L3_Link.STL" />
      </geometry>
    </collision>
  </link>
  <link name="arm_left_L4_Link">
    <inertial>
      <origin xyz="1.6127e-05 -0.027094 -0.086199" rpy="0 0 0" />
      <mass value="0.66812" />
      <inertia ixx="0.00039892" ixy="5.379E-08" ixz="1.7668E-06" iyy="0.00038456" iyz="1.0506E-06" izz="0.00041366" />
    </inertial>
    <visual>
      <origin xyz="0 0 0" rpy="0 0 0" />
      <geometry>
        <mesh filename="../../components/arms/a7_lite/variants/left/meshes/L4_Link.STL" />
      </geometry>
      <material name="">
        <color rgba="0.75294 0.75294 0.75294 1" />
      </material>
    </visual>
    <collision>
      <origin xyz="0 0 0" rpy="0 0 0" />
      <geometry>
        <mesh filename="../../components/arms/a7_lite/variants/left/meshes/L4_Link.STL" />
      </geometry>
    </collision>
  </link>
  <link name="arm_left_L5_Link">
    <inertial>
      <origin xyz="-0.00012977 0.0029474 -0.03886" rpy="0 0 0" />
      <mass value="0.4439" />
      <inertia ixx="0.00015511" ixy="-4.6133E-07" ixz="-2.6472E-06" iyy="0.00022136" iyz="-1.0454E-07" izz="0.00013737" />
    </inertial>
    <visual>
      <origin xyz="0 0 0" rpy="0 0 0" />
      <geometry>
        <mesh filename="../../components/arms/a7_lite/variants/left/meshes/L5_Link.STL" />
      </geometry>
      <material name="">
        <color rgba="0.75294 0.75294 0.75294 1" />
      </material>
    </visual>
    <collision>
      <origin xyz="0 0 0" rpy="0 0 0" />
      <geometry>
        <mesh filename="../../components/arms/a7_lite/variants/left/meshes/L5_Link.STL" />
      </geometry>
    </collision>
  </link>
  <link name="arm_left_L6_Link">
    <inertial>
      <origin xyz="0.0023746 -0.027691 -0.063927" rpy="0 0 0" />
      <mass value="0.5193" />
      <inertia ixx="0.00031746" ixy="-6.3455E-07" ixz="4.1005E-07" iyy="0.00024364" iyz="2.8635E-06" izz="0.00015858" />
    </inertial>
    <visual>
      <origin xyz="0 0 0" rpy="0 0 0" />
      <geometry>
        <mesh filename="../../components/arms/a7_lite/variants/left/meshes/L6_Link.STL" />
      </geometry>
      <material name="">
        <color rgba="0.75294 0.75294 0.75294 1" />
      </material>
    </visual>
    <collision>
      <origin xyz="0 0 0" rpy="0 0 0" />
      <geometry>
        <mesh filename="../../components/arms/a7_lite/variants/left/meshes/L6_Link.STL" />
      </geometry>
    </collision>
  </link>
  <link name="arm_left_L7_Link">
    <inertial>
      <origin xyz="-0.026398 -6.6336e-15 -0.025801" rpy="0 0 0" />
      <mass value="0.10175" />
      <inertia ixx="4.5036E-05" ixy="-4.7046E-12" ixz="2.2349E-07" iyy="3.8663E-05" iyz="-1.9234E-20" izz="3.0632E-05" />
    </inertial>
    <visual>
      <origin xyz="0 0 0" rpy="0 0 0" />
      <geometry>
        <mesh filename="../../components/arms/a7_lite/variants/left/meshes/L7_Link.STL" />
      </geometry>
      <material name="">
        <color rgba="0.75294 0.75294 0.75294 1" />
      </material>
    </visual>
    <collision>
      <origin xyz="0 0 0" rpy="0 0 0" />
      <geometry>
        <mesh filename="../../components/arms/a7_lite/variants/left/meshes/L7_Link.STL" />
      </geometry>
    </collision>
  </link>
  <link name="arm_right_R_arm_root" />
  <link name="arm_right_R1_Link">
    <inertial>
      <origin xyz="0.004598 -0.067915 0.00072736" rpy="0 0 0" />
      <mass value="1.1899" />
      <inertia ixx="0.0016082" ixy="-3.3435E-06" ixz="3.9187E-07" iyy="0.00086157" iyz="-6.5828E-06" izz="0.00092788" />
    </inertial>
    <visual>
      <origin xyz="0 0 0" rpy="0 0 0" />
      <geometry>
        <mesh filename="../../components/arms/a7_lite/variants/right/meshes/R1_Link.STL" />
      </geometry>
      <material name="">
        <color rgba="0.75294 0.75294 0.75294 1" />
      </material>
    </visual>
    <collision>
      <origin xyz="0 0 0" rpy="0 0 0" />
      <geometry>
        <mesh filename="../../components/arms/a7_lite/variants/right/meshes/R1_Link.STL" />
      </geometry>
    </collision>
  </link>
  <link name="arm_right_R2_Link">
    <inertial>
      <origin xyz="-0.031363 2.7784e-05 -0.099445" rpy="0 0 0" />
      <mass value="1.0663" />
      <inertia ixx="0.0014523" ixy="-8.9962E-07" ixz="-1.031E-06" iyy="0.0012484" iyz="1.1436E-05" izz="0.0010754" />
    </inertial>
    <visual>
      <origin xyz="0 0 0" rpy="0 0 0" />
      <geometry>
        <mesh filename="../../components/arms/a7_lite/variants/right/meshes/R2_Link.STL" />
      </geometry>
      <material name="">
        <color rgba="0.75294 0.75294 0.75294 1" />
      </material>
    </visual>
    <collision>
      <origin xyz="0 0 0" rpy="0 0 0" />
      <geometry>
        <mesh filename="../../components/arms/a7_lite/variants/right/meshes/R2_Link.STL" />
      </geometry>
    </collision>
  </link>
  <link name="arm_right_R3_Link">
    <inertial>
      <origin xyz="-2.2895e-05 -0.00123 -0.077166" rpy="0 0 0" />
      <mass value="1.3517" />
      <inertia ixx="0.00080502" ixy="2.8702E-07" ixz="7.1845E-06" iyy="0.0010686" iyz="-7.5659E-07" izz="0.00067469" />
    </inertial>
    <visual>
      <origin xyz="0 0 0" rpy="0 0 0" />
      <geometry>
        <mesh filename="../../components/arms/a7_lite/variants/right/meshes/R3_Link.STL" />
      </geometry>
      <material name="">
        <color rgba="0.75294 0.75294 0.75294 1" />
      </material>
    </visual>
    <collision>
      <origin xyz="0 0 0" rpy="0 0 0" />
      <geometry>
        <mesh filename="../../components/arms/a7_lite/variants/right/meshes/R3_Link.STL" />
      </geometry>
    </collision>
  </link>
  <link name="arm_right_R4_Link">
    <inertial>
      <origin xyz="1.2714e-05 0.024908 -0.082641" rpy="0 0 0" />
      <mass value="0.69691" />
      <inertia ixx="0.00041505" ixy="5.3251E-08" ixz="1.7254E-06" iyy="0.00041627" iyz="3.826E-07" izz="0.00043007" />
    </inertial>
    <visual>
      <origin xyz="0 0 0" rpy="0 0 0" />
      <geometry>
        <mesh filename="../../components/arms/a7_lite/variants/right/meshes/R4_Link.STL" />
      </geometry>
      <material name="">
        <color rgba="0.75294 0.75294 0.75294 1" />
      </material>
    </visual>
    <collision>
      <origin xyz="0 0 0" rpy="0 0 0" />
      <geometry>
        <mesh filename="../../components/arms/a7_lite/variants/right/meshes/R4_Link.STL" />
      </geometry>
    </collision>
  </link>
  <link name="arm_right_R5_Link">
    <inertial>
      <origin xyz="0.00029153 -0.0027009 -0.035875" rpy="0 0 0" />
      <mass value="0.48527" />
      <inertia ixx="0.00016555" ixy="-5.747E-07" ixz="-2.6985E-06" iyy="0.00022756" iyz="-9.211E-07" izz="0.00015289" />
    </inertial>
    <visual>
      <origin xyz="0 0 0" rpy="0 0 0" />
      <geometry>
        <mesh filename="../../components/arms/a7_lite/variants/right/meshes/R5_Link.STL" />
      </geometry>
      <material name="">
        <color rgba="0.75294 0.75294 0.75294 1" />
      </material>
    </visual>
    <collision>
      <origin xyz="0 0 0" rpy="0 0 0" />
      <geometry>
        <mesh filename="../../components/arms/a7_lite/variants/right/meshes/R5_Link.STL" />
      </geometry>
    </collision>
  </link>
  <link name="arm_right_R6_Link">
    <inertial>
      <origin xyz="0.0023746 0.027704 -0.063949" rpy="0 0 0" />
      <mass value="0.5193" />
      <inertia ixx="0.00031746" ixy="6.3467E-07" ixz="4.1001E-07" iyy="0.00024364" iyz="-2.8219E-06" izz="0.00015858" />
    </inertial>
    <visual>
      <origin xyz="0 0 0" rpy="0 0 0" />
      <geometry>
        <mesh filename="../../components/arms/a7_lite/variants/right/meshes/R6_Link.STL" />
      </geometry>
      <material name="">
        <color rgba="0.75294 0.75294 0.75294 1" />
      </material>
    </visual>
    <collision>
      <origin xyz="0 0 0" rpy="0 0 0" />
      <geometry>
        <mesh filename="../../components/arms/a7_lite/variants/right/meshes/R6_Link.STL" />
      </geometry>
    </collision>
  </link>
  <link name="arm_right_R7_Link">
    <inertial>
      <origin xyz="-0.026598 3.7248e-14 -0.025801" rpy="0 0 0" />
      <mass value="0.10175" />
      <inertia ixx="4.5036E-05" ixy="-4.7046E-12" ixz="2.2349E-07" iyy="3.8663E-05" iyz="-1.5968E-20" izz="3.0632E-05" />
    </inertial>
    <visual>
      <origin xyz="0 0 0" rpy="0 0 0" />
      <geometry>
        <mesh filename="../../components/arms/a7_lite/variants/right/meshes/R7_Link.STL" />
      </geometry>
      <material name="">
        <color rgba="0.75294 0.75294 0.75294 1" />
      </material>
    </visual>
    <collision>
      <origin xyz="0 0 0" rpy="0 0 0" />
      <geometry>
        <mesh filename="../../components/arms/a7_lite/variants/right/meshes/R7_Link.STL" />
      </geometry>
    </collision>
  </link>
  <link name="hand_left_lh_hand_base_link">
    <inertial>
      <origin xyz="0.00199 -0.00091 0.058381" rpy="0 0 0" />
      <mass value="0.4185" />
      <inertia ixx="0.0004998" ixy="0.000012853" ixz="-0.000008317" iyy="0.0003567" iyz="0.000010354" izz="0.0002301" />
    </inertial>
    <visual>
      <origin xyz="0 0 0" rpy="0 0 0" />
      <geometry>
        <mesh filename="../../components/hands/linkerhand_l6/variants/left/meshes/hand_base_link.STL" />
      </geometry>
      <material name="">
        <color rgba="0.796078431372549 0.823529411764706 0.937254901960784 1" />
      </material>
    </visual>
    <collision>
      <origin xyz="0 0 0" rpy="0 0 0" />
      <geometry>
        <mesh filename="../../components/hands/linkerhand_l6/variants/left/meshes/hand_base_link.STL" />
      </geometry>
    </collision>
  </link>
  <link name="hand_left_lh_thumb_metacarpals_base1">
    <inertial>
      <origin xyz="0.0018663 -0.0066406 0.001533" rpy="0 0 0" />
      <mass value="0.01" />
      <inertia ixx="3.3724E-07" ixy="1.11E-07" ixz="-3.6039E-08" iyy="2.9457E-07" iyz="5.7181E-08" izz="4.903E-07" />
    </inertial>
    <visual>
      <origin xyz="0 0 0" rpy="0 0 0" />
      <geometry>
        <mesh filename="../../components/hands/linkerhand_l6/variants/left/meshes/thumb_metacarpals_base1.STL" />
      </geometry>
      <material name="">
        <color rgba="0.796078431372549 0.823529411764706 0.937254901960784 1" />
      </material>
    </visual>
    <collision>
      <origin xyz="0 0 0" rpy="0 0 0" />
      <geometry>
        <mesh filename="../../components/hands/linkerhand_l6/variants/left/meshes/thumb_metacarpals_base1.STL" />
      </geometry>
    </collision>
  </link>
  <link name="hand_left_lh_thumb_metacarpals">
    <inertial>
      <origin xyz="0.00769270907 0.0859662185 0.0235283087" rpy="0 0 0" />
      <mass value="0.065" />
      <inertia ixx="8.407E-06" ixy="-1.1338E-09" ixz="1.1136E-08" iyy="8.3899E-06" iyz="3.1171E-07" izz="2.0091E-06" />
    </inertial>
    <visual>
      <origin xyz="0 0 0" rpy="0 0 0" />
      <geometry>
        <mesh filename="../../components/hands/linkerhand_l6/variants/left/meshes/thumb_metacarpals.STL" />
      </geometry>
      <material name="">
        <color rgba="0.796078431372549 0.823529411764706 0.937254901960784 1" />
      </material>
    </visual>
    <collision>
      <origin xyz="0 0 0" rpy="0 0 0" />
      <geometry>
        <mesh filename="../../components/hands/linkerhand_l6/variants/left/meshes/thumb_metacarpals.STL" />
      </geometry>
    </collision>
  </link>
  <link name="hand_left_lh_thumb_distal">
    <inertial>
      <origin xyz="0.00769270907 0.0798662185 -0.0591716913" rpy="0 0 0" />
      <mass value="0.018" />
      <inertia ixx="1.5546E-06" ixy="2.4423E-09" ixz="2.8147E-09" iyy="1.7108E-06" iyz="-7.2756E-08" izz="9.1709E-07" />
    </inertial>
    <visual>
      <origin xyz="0 0 0" rpy="0 0 0" />
      <geometry>
        <mesh filename="../../components/hands/linkerhand_l6/variants/left/meshes/thumb_distal.STL" />
      </geometry>
      <material name="">
        <color rgba="0.796078431372549 0.823529411764706 0.937254901960784 1" />
      </material>
    </visual>
    <collision>
      <origin xyz="0 0 0" rpy="0 0 0" />
      <geometry>
        <mesh filename="../../components/hands/linkerhand_l6/variants/left/meshes/thumb_distal.STL" />
      </geometry>
    </collision>
  </link>
  <link name="hand_left_lh_thumb_tip">
    <visual>
      <origin xyz="0 0 0" rpy="0 0 0" />
      <geometry>
        <box size="0.0001 0.0001 0.0001" />
      </geometry>
      <material name="hand_left_white" />
    </visual>
    <collision>
      <origin xyz="0 0 0" rpy="0 0 0" />
      <geometry>
        <box size="0.0001 0.0001 0.0001" />
      </geometry>
    </collision>
    <inertial>
      <origin xyz="0 0 0" rpy="0 0 0" />
      <mass value="1e-06" />
      <inertia ixx="1e-09" ixy="0" ixz="0" iyy="1e-09" iyz="0" izz="1e-09" />
    </inertial>
  </link>
  <link name="hand_left_lh_index_proximal">
    <inertial>
      <origin xyz="0.001776 -0.00011 0.012556" rpy="0 0 0" />
      <mass value="0.008553" />
      <inertia ixx="0.000000797543" ixy="-0.000000001275" ixz="0.000000138601" iyy="0.000000800499" iyz="0.000000000939" izz="0.000000357001" />
    </inertial>
    <visual>
      <origin xyz="0 0 0" rpy="0 0 0" />
      <geometry>
        <mesh filename="../../components/hands/linkerhand_l6/variants/left/meshes/index_proximal.STL" />
      </geometry>
      <material name="">
        <color rgba="0.796078431372549 0.823529411764706 0.937254901960784 1" />
      </material>
    </visual>
    <collision>
      <origin xyz="0 0 0" rpy="0 0 0" />
      <geometry>
        <mesh filename="../../components/hands/linkerhand_l6/variants/left/meshes/index_proximal.STL" />
      </geometry>
    </collision>
  </link>
  <link name="hand_left_lh_index_distal">
    <inertial>
      <origin xyz="0.0134 0.002262 0.016992" rpy="0 0 0" />
      <mass value="0.018408" />
      <inertia ixx="0.000002488712" ixy="0.000000008249" ixz="-0.000001523059" iyy="0.000003723754" iyz="0.000000014019" izz="0.000001813582" />
    </inertial>
    <visual>
      <origin xyz="0 0 0" rpy="0 0 0" />
      <geometry>
        <mesh filename="../../components/hands/linkerhand_l6/variants/left/meshes/index_distal.STL" />
      </geometry>
      <material name="">
        <color rgba="0.796078431372549 0.823529411764706 0.937254901960784 1" />
      </material>
    </visual>
    <collision>
      <origin xyz="0 0 0" rpy="0 0 0" />
      <geometry>
        <mesh filename="../../components/hands/linkerhand_l6/variants/left/meshes/index_distal.STL" />
      </geometry>
    </collision>
  </link>
  <link name="hand_left_lh_index_tip">
    <visual>
      <origin xyz="0 0 0" rpy="0 0 0" />
      <geometry>
        <box size="0.0001 0.0001 0.0001" />
      </geometry>
      <material name="hand_left_white" />
    </visual>
    <collision>
      <origin xyz="0 0 0" rpy="0 0 0" />
      <geometry>
        <box size="0.0001 0.0001 0.0001" />
      </geometry>
    </collision>
    <inertial>
      <origin xyz="0 0 0" rpy="0 0 0" />
      <mass value="1e-06" />
      <inertia ixx="1e-09" ixy="0" ixz="0" iyy="1e-09" iyz="0" izz="1e-09" />
    </inertial>
  </link>
  <link name="hand_left_lh_middle_proximal">
    <inertial>
      <origin xyz="0.001776 -0.00011 0.012556" rpy="0 0 0" />
      <mass value="0.008553" />
      <inertia ixx="0.000000797543" ixy="-0.000000001275" ixz="0.000000138601" iyy="0.000000800499" iyz="0.000000000939" izz="0.000000357001" />
    </inertial>
    <visual>
      <origin xyz="0 0 0" rpy="0 0 0" />
      <geometry>
        <mesh filename="../../components/hands/linkerhand_l6/variants/left/meshes/middle_proximal.STL" />
      </geometry>
      <material name="">
        <color rgba="0.796078431372549 0.823529411764706 0.937254901960784 1" />
      </material>
    </visual>
    <collision>
      <origin xyz="0 0 0" rpy="0 0 0" />
      <geometry>
        <mesh filename="../../components/hands/linkerhand_l6/variants/left/meshes/middle_proximal.STL" />
      </geometry>
    </collision>
  </link>
  <link name="hand_left_lh_middle_distal">
    <inertial>
      <origin xyz="0.0134 0.002262 0.016992" rpy="0 0 0" />
      <mass value="0.018408" />
      <inertia ixx="0.000002488712" ixy="0.000000008249" ixz="-0.000001523059" iyy="0.000003723754" iyz="0.000000014019" izz="0.000001813582" />
    </inertial>
    <visual>
      <origin xyz="0 0 0" rpy="0 0 0" />
      <geometry>
        <mesh filename="../../components/hands/linkerhand_l6/variants/left/meshes/middle_distal.STL" />
      </geometry>
      <material name="">
        <color rgba="0.796078431372549 0.823529411764706 0.937254901960784 1" />
      </material>
    </visual>
    <collision>
      <origin xyz="0 0 0" rpy="0 0 0" />
      <geometry>
        <mesh filename="../../components/hands/linkerhand_l6/variants/left/meshes/middle_distal.STL" />
      </geometry>
    </collision>
  </link>
  <link name="hand_left_lh_middle_tip">
    <visual>
      <origin xyz="0 0 0" rpy="0 0 0" />
      <geometry>
        <box size="0.0001 0.0001 0.0001" />
      </geometry>
      <material name="hand_left_white" />
    </visual>
    <collision>
      <origin xyz="0 0 0" rpy="0 0 0" />
      <geometry>
        <box size="0.0001 0.0001 0.0001" />
      </geometry>
    </collision>
    <inertial>
      <origin xyz="0 0 0" rpy="0 0 0" />
      <mass value="1e-06" />
      <inertia ixx="1e-09" ixy="0" ixz="0" iyy="1e-09" iyz="0" izz="1e-09" />
    </inertial>
  </link>
  <link name="hand_left_lh_ring_proximal">
    <inertial>
      <origin xyz="0.001776 -0.00011 0.012556" rpy="0 0 0" />
      <mass value="0.008553" />
      <inertia ixx="0.000000797543" ixy="-0.000000001275" ixz="0.000000138601" iyy="0.000000800499" iyz="0.000000000939" izz="0.000000357001" />
    </inertial>
    <visual>
      <origin xyz="0 0 0" rpy="0 0 0" />
      <geometry>
        <mesh filename="../../components/hands/linkerhand_l6/variants/left/meshes/ring_proximal.STL" />
      </geometry>
      <material name="">
        <color rgba="0.796078431372549 0.823529411764706 0.937254901960784 1" />
      </material>
    </visual>
    <collision>
      <origin xyz="0 0 0" rpy="0 0 0" />
      <geometry>
        <mesh filename="../../components/hands/linkerhand_l6/variants/left/meshes/ring_proximal.STL" />
      </geometry>
    </collision>
  </link>
  <link name="hand_left_lh_ring_distal">
    <inertial>
      <origin xyz="0.0134 0.002262 0.016992" rpy="0 0 0" />
      <mass value="0.018408" />
      <inertia ixx="0.000002488712" ixy="0.000000008249" ixz="-0.000001523059" iyy="0.000003723754" iyz="0.000000014019" izz="0.000001813582" />
    </inertial>
    <visual>
      <origin xyz="0 0 0" rpy="0 0 0" />
      <geometry>
        <mesh filename="../../components/hands/linkerhand_l6/variants/left/meshes/ring_distal.STL" />
      </geometry>
      <material name="">
        <color rgba="0.796078431372549 0.823529411764706 0.937254901960784 1" />
      </material>
    </visual>
    <collision>
      <origin xyz="0 0 0" rpy="0 0 0" />
      <geometry>
        <mesh filename="../../components/hands/linkerhand_l6/variants/left/meshes/ring_distal.STL" />
      </geometry>
    </collision>
  </link>
  <link name="hand_left_lh_ring_tip">
    <visual>
      <origin xyz="0 0 0" rpy="0 0 0" />
      <geometry>
        <box size="0.0001 0.0001 0.0001" />
      </geometry>
      <material name="hand_left_white" />
    </visual>
    <collision>
      <origin xyz="0 0 0" rpy="0 0 0" />
      <geometry>
        <box size="0.0001 0.0001 0.0001" />
      </geometry>
    </collision>
    <inertial>
      <origin xyz="0 0 0" rpy="0 0 0" />
      <mass value="1e-06" />
      <inertia ixx="1e-09" ixy="0" ixz="0" iyy="1e-09" iyz="0" izz="1e-09" />
    </inertial>
  </link>
  <link name="hand_left_lh_pinky_proximal">
    <inertial>
      <origin xyz="0.001776 -0.00011 0.012556" rpy="0 0 0" />
      <mass value="0.008553" />
      <inertia ixx="0.000000797543" ixy="-0.000000001275" ixz="0.000000138601" iyy="0.000000800499" iyz="0.000000000939" izz="0.000000357001" />
    </inertial>
    <visual>
      <origin xyz="0 0 0" rpy="0 0 0" />
      <geometry>
        <mesh filename="../../components/hands/linkerhand_l6/variants/left/meshes/pinky_proximal.STL" />
      </geometry>
      <material name="">
        <color rgba="0.796078431372549 0.823529411764706 0.937254901960784 1" />
      </material>
    </visual>
    <collision>
      <origin xyz="0 0 0" rpy="0 0 0" />
      <geometry>
        <mesh filename="../../components/hands/linkerhand_l6/variants/left/meshes/pinky_proximal.STL" />
      </geometry>
    </collision>
  </link>
  <link name="hand_left_lh_pinky_distal">
    <inertial>
      <origin xyz="0.0134 0.002262 0.016992" rpy="0 0 0" />
      <mass value="0.018408" />
      <inertia ixx="0.000002488712" ixy="0.000000008249" ixz="-0.000001523059" iyy="0.000003723754" iyz="0.000000014019" izz="0.000001813582" />
    </inertial>
    <visual>
      <origin xyz="0 0 0" rpy="0 0 0" />
      <geometry>
        <mesh filename="../../components/hands/linkerhand_l6/variants/left/meshes/pinky_distal.STL" />
      </geometry>
      <material name="">
        <color rgba="0.796078431372549 0.823529411764706 0.937254901960784 1" />
      </material>
    </visual>
    <collision>
      <origin xyz="0 0 0" rpy="0 0 0" />
      <geometry>
        <mesh filename="../../components/hands/linkerhand_l6/variants/left/meshes/pinky_distal.STL" />
      </geometry>
    </collision>
  </link>
  <link name="hand_left_lh_pinky_tip">
    <visual>
      <origin xyz="0 0 0" rpy="0 0 0" />
      <geometry>
        <box size="0.0001 0.0001 0.0001" />
      </geometry>
      <material name="hand_left_white" />
    </visual>
    <collision>
      <origin xyz="0 0 0" rpy="0 0 0" />
      <geometry>
        <box size="0.0001 0.0001 0.0001" />
      </geometry>
    </collision>
    <inertial>
      <origin xyz="0 0 0" rpy="0 0 0" />
      <mass value="1e-06" />
      <inertia ixx="1e-09" ixy="0" ixz="0" iyy="1e-09" iyz="0" izz="1e-09" />
    </inertial>
  </link>
  <link name="hand_right_rh_hand_base_link">
    <inertial>
      <origin xyz="0.00199 0.00091 0.058381" rpy="0 0 0" />
      <mass value="0.4185" />
      <inertia ixx="0.0004998" ixy="-1.2853e-05" ixz="-8.317e-06" iyy="0.0003567" iyz="-1.0354e-05" izz="0.0002301" />
    </inertial>
    <visual>
      <origin xyz="0 0 0" rpy="0 0 0" />
      <geometry>
        <mesh filename="../../components/hands/linkerhand_l6/variants/right/meshes/hand_base_link.STL" />
      </geometry>
      <material name="">
        <color rgba="0.796078431372549 0.823529411764706 0.937254901960784 1" />
      </material>
    </visual>
    <collision>
      <origin xyz="0 0 0" rpy="0 0 0" />
      <geometry>
        <mesh filename="../../components/hands/linkerhand_l6/variants/right/meshes/hand_base_link.STL" />
      </geometry>
    </collision>
  </link>
  <link name="hand_right_rh_thumb_metacarpals_base1">
    <inertial>
      <origin xyz="0.0018663 0.0066406 0.001533" rpy="0 0 0" />
      <mass value="0.01" />
      <inertia ixx="3.3724e-07" ixy="-1.11e-07" ixz="-3.6039e-08" iyy="2.9457e-07" iyz="-5.7181e-08" izz="4.903e-07" />
    </inertial>
    <visual>
      <origin xyz="0 0 0" rpy="0 0 0" />
      <geometry>
        <mesh filename="../../components/hands/linkerhand_l6/variants/right/meshes/thumb_metacarpals_base1.STL" />
      </geometry>
      <material name="">
        <color rgba="0.796078431372549 0.823529411764706 0.937254901960784 1" />
      </material>
    </visual>
    <collision>
      <origin xyz="0 0 0" rpy="0 0 0" />
      <geometry>
        <mesh filename="../../components/hands/linkerhand_l6/variants/right/meshes/thumb_metacarpals_base1.STL" />
      </geometry>
    </collision>
  </link>
  <link name="hand_right_rh_thumb_metacarpals">
    <inertial>
      <origin xyz="0.0076927091 -0.0859662185 0.0235283087" rpy="0 0 0" />
      <mass value="0.065" />
      <inertia ixx="8.407e-06" ixy="1.1338e-09" ixz="1.1136e-08" iyy="8.3899e-06" iyz="-3.1171e-07" izz="2.0091e-06" />
    </inertial>
    <visual>
      <origin xyz="0 0 0" rpy="0 0 0" />
      <geometry>
        <mesh filename="../../components/hands/linkerhand_l6/variants/right/meshes/thumb_metacarpals.STL" />
      </geometry>
      <material name="">
        <color rgba="0.796078431372549 0.823529411764706 0.937254901960784 1" />
      </material>
    </visual>
    <collision>
      <origin xyz="0 0 0" rpy="0 0 0" />
      <geometry>
        <mesh filename="../../components/hands/linkerhand_l6/variants/right/meshes/thumb_metacarpals.STL" />
      </geometry>
    </collision>
  </link>
  <link name="hand_right_rh_thumb_distal">
    <inertial>
      <origin xyz="0.0076927091 -0.0798662185 -0.0591716913" rpy="0 0 0" />
      <mass value="0.018" />
      <inertia ixx="1.5546e-06" ixy="-2.4423e-09" ixz="2.8147e-09" iyy="1.7108e-06" iyz="7.2756e-08" izz="9.1709e-07" />
    </inertial>
    <visual>
      <origin xyz="0 0 0" rpy="0 0 0" />
      <geometry>
        <mesh filename="../../components/hands/linkerhand_l6/variants/right/meshes/thumb_distal.STL" />
      </geometry>
      <material name="">
        <color rgba="0.796078431372549 0.823529411764706 0.937254901960784 1" />
      </material>
    </visual>
    <collision>
      <origin xyz="0 0 0" rpy="0 0 0" />
      <geometry>
        <mesh filename="../../components/hands/linkerhand_l6/variants/right/meshes/thumb_distal.STL" />
      </geometry>
    </collision>
  </link>
  <link name="hand_right_rh_thumb_tip">
    <visual>
      <origin xyz="0 0 0" rpy="0 0 0" />
      <geometry>
        <box size="0.0001 0.0001 0.0001" />
      </geometry>
      <material name="hand_right_white" />
    </visual>
    <collision>
      <origin xyz="0 0 0" rpy="0 0 0" />
      <geometry>
        <box size="0.0001 0.0001 0.0001" />
      </geometry>
    </collision>
    <inertial>
      <origin xyz="0 0 0" rpy="0 0 0" />
      <mass value="1e-06" />
      <inertia ixx="1e-09" ixy="0" ixz="0" iyy="1e-09" iyz="0" izz="1e-09" />
    </inertial>
  </link>
  <link name="hand_right_rh_index_proximal">
    <inertial>
      <origin xyz="0.001776 0.00011 0.012556" rpy="0 0 0" />
      <mass value="0.008553" />
      <inertia ixx="7.97543e-07" ixy="1.275e-09" ixz="1.38601e-07" iyy="8.00499e-07" iyz="-9.39e-10" izz="3.57001e-07" />
    </inertial>
    <visual>
      <origin xyz="0 0 0" rpy="0 0 0" />
      <geometry>
        <mesh filename="../../components/hands/linkerhand_l6/variants/right/meshes/index_proximal.STL" />
      </geometry>
      <material name="">
        <color rgba="0.796078431372549 0.823529411764706 0.937254901960784 1" />
      </material>
    </visual>
    <collision>
      <origin xyz="0 0 0" rpy="0 0 0" />
      <geometry>
        <mesh filename="../../components/hands/linkerhand_l6/variants/right/meshes/index_proximal.STL" />
      </geometry>
    </collision>
  </link>
  <link name="hand_right_rh_index_distal">
    <inertial>
      <origin xyz="0.0134 -0.002262 0.016992" rpy="0 0 0" />
      <mass value="0.018408" />
      <inertia ixx="2.488712e-06" ixy="-8.249e-09" ixz="-1.523059e-06" iyy="3.723754e-06" iyz="-1.4019e-08" izz="1.813582e-06" />
    </inertial>
    <visual>
      <origin xyz="0 0 0" rpy="0 0 0" />
      <geometry>
        <mesh filename="../../components/hands/linkerhand_l6/variants/right/meshes/index_distal.STL" />
      </geometry>
      <material name="">
        <color rgba="0.796078431372549 0.823529411764706 0.937254901960784 1" />
      </material>
    </visual>
    <collision>
      <origin xyz="0 0 0" rpy="0 0 0" />
      <geometry>
        <mesh filename="../../components/hands/linkerhand_l6/variants/right/meshes/index_distal.STL" />
      </geometry>
    </collision>
  </link>
  <link name="hand_right_rh_index_tip">
    <visual>
      <origin xyz="0 0 0" rpy="0 0 0" />
      <geometry>
        <box size="0.0001 0.0001 0.0001" />
      </geometry>
      <material name="hand_right_white" />
    </visual>
    <collision>
      <origin xyz="0 0 0" rpy="0 0 0" />
      <geometry>
        <box size="0.0001 0.0001 0.0001" />
      </geometry>
    </collision>
    <inertial>
      <origin xyz="0 0 0" rpy="0 0 0" />
      <mass value="1e-06" />
      <inertia ixx="1e-09" ixy="0" ixz="0" iyy="1e-09" iyz="0" izz="1e-09" />
    </inertial>
  </link>
  <link name="hand_right_rh_middle_proximal">
    <inertial>
      <origin xyz="0.001776 0.00011 0.012556" rpy="0 0 0" />
      <mass value="0.008553" />
      <inertia ixx="7.97543e-07" ixy="1.275e-09" ixz="1.38601e-07" iyy="8.00499e-07" iyz="-9.39e-10" izz="3.57001e-07" />
    </inertial>
    <visual>
      <origin xyz="0 0 0" rpy="0 0 0" />
      <geometry>
        <mesh filename="../../components/hands/linkerhand_l6/variants/right/meshes/middle_proximal.STL" />
      </geometry>
      <material name="">
        <color rgba="0.796078431372549 0.823529411764706 0.937254901960784 1" />
      </material>
    </visual>
    <collision>
      <origin xyz="0 0 0" rpy="0 0 0" />
      <geometry>
        <mesh filename="../../components/hands/linkerhand_l6/variants/right/meshes/middle_proximal.STL" />
      </geometry>
    </collision>
  </link>
  <link name="hand_right_rh_middle_distal">
    <inertial>
      <origin xyz="0.0134 -0.002262 0.016992" rpy="0 0 0" />
      <mass value="0.018408" />
      <inertia ixx="2.488712e-06" ixy="-8.249e-09" ixz="-1.523059e-06" iyy="3.723754e-06" iyz="-1.4019e-08" izz="1.813582e-06" />
    </inertial>
    <visual>
      <origin xyz="0 0 0" rpy="0 0 0" />
      <geometry>
        <mesh filename="../../components/hands/linkerhand_l6/variants/right/meshes/middle_distal.STL" />
      </geometry>
      <material name="">
        <color rgba="0.796078431372549 0.823529411764706 0.937254901960784 1" />
      </material>
    </visual>
    <collision>
      <origin xyz="0 0 0" rpy="0 0 0" />
      <geometry>
        <mesh filename="../../components/hands/linkerhand_l6/variants/right/meshes/middle_distal.STL" />
      </geometry>
    </collision>
  </link>
  <link name="hand_right_rh_middle_tip">
    <visual>
      <origin xyz="0 0 0" rpy="0 0 0" />
      <geometry>
        <box size="0.0001 0.0001 0.0001" />
      </geometry>
      <material name="hand_right_white" />
    </visual>
    <collision>
      <origin xyz="0 0 0" rpy="0 0 0" />
      <geometry>
        <box size="0.0001 0.0001 0.0001" />
      </geometry>
    </collision>
    <inertial>
      <origin xyz="0 0 0" rpy="0 0 0" />
      <mass value="1e-06" />
      <inertia ixx="1e-09" ixy="0" ixz="0" iyy="1e-09" iyz="0" izz="1e-09" />
    </inertial>
  </link>
  <link name="hand_right_rh_ring_proximal">
    <inertial>
      <origin xyz="0.001776 0.00011 0.012556" rpy="0 0 0" />
      <mass value="0.008553" />
      <inertia ixx="7.97543e-07" ixy="1.275e-09" ixz="1.38601e-07" iyy="8.00499e-07" iyz="-9.39e-10" izz="3.57001e-07" />
    </inertial>
    <visual>
      <origin xyz="0 0 0" rpy="0 0 0" />
      <geometry>
        <mesh filename="../../components/hands/linkerhand_l6/variants/right/meshes/ring_proximal.STL" />
      </geometry>
      <material name="">
        <color rgba="0.796078431372549 0.823529411764706 0.937254901960784 1" />
      </material>
    </visual>
    <collision>
      <origin xyz="0 0 0" rpy="0 0 0" />
      <geometry>
        <mesh filename="../../components/hands/linkerhand_l6/variants/right/meshes/ring_proximal.STL" />
      </geometry>
    </collision>
  </link>
  <link name="hand_right_rh_ring_distal">
    <inertial>
      <origin xyz="0.0134 -0.002262 0.016992" rpy="0 0 0" />
      <mass value="0.018408" />
      <inertia ixx="2.488712e-06" ixy="-8.249e-09" ixz="-1.523059e-06" iyy="3.723754e-06" iyz="-1.4019e-08" izz="1.813582e-06" />
    </inertial>
    <visual>
      <origin xyz="0 0 0" rpy="0 0 0" />
      <geometry>
        <mesh filename="../../components/hands/linkerhand_l6/variants/right/meshes/ring_distal.STL" />
      </geometry>
      <material name="">
        <color rgba="0.796078431372549 0.823529411764706 0.937254901960784 1" />
      </material>
    </visual>
    <collision>
      <origin xyz="0 0 0" rpy="0 0 0" />
      <geometry>
        <mesh filename="../../components/hands/linkerhand_l6/variants/right/meshes/ring_distal.STL" />
      </geometry>
    </collision>
  </link>
  <link name="hand_right_rh_ring_tip">
    <visual>
      <origin xyz="0 0 0" rpy="0 0 0" />
      <geometry>
        <box size="0.0001 0.0001 0.0001" />
      </geometry>
      <material name="hand_right_white" />
    </visual>
    <collision>
      <origin xyz="0 0 0" rpy="0 0 0" />
      <geometry>
        <box size="0.0001 0.0001 0.0001" />
      </geometry>
    </collision>
    <inertial>
      <origin xyz="0 0 0" rpy="0 0 0" />
      <mass value="1e-06" />
      <inertia ixx="1e-09" ixy="0" ixz="0" iyy="1e-09" iyz="0" izz="1e-09" />
    </inertial>
  </link>
  <link name="hand_right_rh_pinky_proximal">
    <inertial>
      <origin xyz="0.001776 0.00011 0.012556" rpy="0 0 0" />
      <mass value="0.008553" />
      <inertia ixx="7.97543e-07" ixy="1.275e-09" ixz="1.38601e-07" iyy="8.00499e-07" iyz="-9.39e-10" izz="3.57001e-07" />
    </inertial>
    <visual>
      <origin xyz="0 0 0" rpy="0 0 0" />
      <geometry>
        <mesh filename="../../components/hands/linkerhand_l6/variants/right/meshes/pinky_proximal.STL" />
      </geometry>
      <material name="">
        <color rgba="0.796078431372549 0.823529411764706 0.937254901960784 1" />
      </material>
    </visual>
    <collision>
      <origin xyz="0 0 0" rpy="0 0 0" />
      <geometry>
        <mesh filename="../../components/hands/linkerhand_l6/variants/right/meshes/pinky_proximal.STL" />
      </geometry>
    </collision>
  </link>
  <link name="hand_right_rh_pinky_distal">
    <inertial>
      <origin xyz="0.0134 -0.002262 0.016992" rpy="0 0 0" />
      <mass value="0.018408" />
      <inertia ixx="2.488712e-06" ixy="-8.249e-09" ixz="-1.523059e-06" iyy="3.723754e-06" iyz="-1.4019e-08" izz="1.813582e-06" />
    </inertial>
    <visual>
      <origin xyz="0 0 0" rpy="0 0 0" />
      <geometry>
        <mesh filename="../../components/hands/linkerhand_l6/variants/right/meshes/pinky_distal.STL" />
      </geometry>
      <material name="">
        <color rgba="0.796078431372549 0.823529411764706 0.937254901960784 1" />
      </material>
    </visual>
    <collision>
      <origin xyz="0 0 0" rpy="0 0 0" />
      <geometry>
        <mesh filename="../../components/hands/linkerhand_l6/variants/right/meshes/pinky_distal.STL" />
      </geometry>
    </collision>
  </link>
  <link name="hand_right_rh_pinky_tip">
    <visual>
      <origin xyz="0 0 0" rpy="0 0 0" />
      <geometry>
        <box size="0.0001 0.0001 0.0001" />
      </geometry>
      <material name="hand_right_white" />
    </visual>
    <collision>
      <origin xyz="0 0 0" rpy="0 0 0" />
      <geometry>
        <box size="0.0001 0.0001 0.0001" />
      </geometry>
    </collision>
    <inertial>
      <origin xyz="0 0 0" rpy="0 0 0" />
      <mass value="1e-06" />
      <inertia ixx="1e-09" ixy="0" ixz="0" iyy="1e-09" iyz="0" izz="1e-09" />
    </inertial>
  </link>
  <joint name="base_torso_stand" type="fixed">
    <origin xyz="0 0 1.2" rpy="0 0 0" />
    <parent link="base_torso_root" />
    <child link="base_base_link" />
  </joint>
  <joint name="base_weld_arm_left_mount" type="fixed">
    <origin xyz="0.0062932 0.1505 -0.022706" rpy="0 0 0" />
    <parent link="base_base_link" />
    <child link="base_arm_left_mount" />
  </joint>
  <joint name="base_weld_arm_right_mount" type="fixed">
    <origin xyz="0.0062926 -0.1505 -0.022706" rpy="0 0 0" />
    <parent link="base_base_link" />
    <child link="base_arm_right_mount" />
  </joint>
  <joint name="arm_left_L1_Joint" type="revolute">
    <origin xyz="0 0 0" rpy="0 0 0" />
    <parent link="arm_left_L_arm_root" />
    <child link="arm_left_L1_Link" />
    <axis xyz="0 -1 0" />
    <limit lower="-2.18" upper="3.75" effort="60" velocity="18.84" />
  </joint>
  <joint name="arm_left_L2_Joint" type="revolute">
    <origin xyz="0.03125 0.0715 0" rpy="0 0 0" />
    <parent link="arm_left_L1_Link" />
    <child link="arm_left_L2_Link" />
    <axis xyz="-1 0 0" />
    <limit lower="-3.33" upper="0.19" effort="60" velocity="18.84" />
  </joint>
  <joint name="arm_left_L3_Joint" type="revolute">
    <origin xyz="-0.03125 0 -0.147" rpy="0 0 0" />
    <parent link="arm_left_L2_Link" />
    <child link="arm_left_L3_Link" />
    <axis xyz="0 0 1" />
    <limit lower="-2.26" upper="2.26" effort="17" velocity="137.68" />
  </joint>
  <joint name="arm_left_L4_Joint" type="revolute">
    <origin xyz="0 0.027 -0.126" rpy="0 0 0" />
    <parent link="arm_left_L3_Link" />
    <child link="arm_left_L4_Link" />
    <axis xyz="0 -1 0" />
    <limit lower="-0.78" upper="1.74" effort="36" velocity="10.47" />
  </joint>
  <joint name="arm_left_L5_Joint" type="revolute">
    <origin xyz="0 -0.027 -0.136" rpy="0 0 0" />
    <parent link="arm_left_L4_Link" />
    <child link="arm_left_L5_Link" />
    <axis xyz="0 0 1" />
    <limit lower="-2.96" upper="2.96" effort="14" velocity="27.21" />
  </joint>
  <joint name="arm_left_L6_Joint" type="revolute">
    <origin xyz="0 0.028 -0.0435" rpy="0 0 0" />
    <parent link="arm_left_L5_Link" />
    <child link="arm_left_L6_Link" />
    <axis xyz="0 -1 0" />
    <limit lower="-1.57" upper="1.57" effort="14" velocity="27.21" />
  </joint>
  <joint name="arm_left_L7_Joint" type="revolute">
    <origin xyz="0.028 -0.028 -0.075" rpy="0 0 0" />
    <parent link="arm_left_L6_Link" />
    <child link="arm_left_L7_Link" />
    <axis xyz="-1 0 0" />
    <limit lower="-1.57" upper="1.57" effort="14" velocity="27.21" />
  </joint>
  <joint name="arm_right_R1_Joint" type="revolute">
    <origin xyz="0 0 0" rpy="0 0 0" />
    <parent link="arm_right_R_arm_root" />
    <child link="arm_right_R1_Link" />
    <axis xyz="0 1 0" />
    <limit lower="-3.75" upper="2.18" effort="60" velocity="18.84" />
  </joint>
  <joint name="arm_right_R2_Joint" type="revolute">
    <origin xyz="0.03125 -0.0715 0" rpy="0 0 0" />
    <parent link="arm_right_R1_Link" />
    <child link="arm_right_R2_Link" />
    <axis xyz="-1 0 0" />
    <limit lower="-0.19" upper="3.33" effort="60" velocity="18.84" />
  </joint>
  <joint name="arm_right_R3_Joint" type="revolute">
    <origin xyz="-0.03125 0 -0.147" rpy="0 0 0" />
    <parent link="arm_right_R2_Link" />
    <child link="arm_right_R3_Link" />
    <axis xyz="0 0 1" />
    <limit lower="-2.26" upper="2.26" effort="17" velocity="37.68" />
  </joint>
  <joint name="arm_right_R4_Joint" type="revolute">
    <origin xyz="0 -0.027 -0.126" rpy="0 0 0" />
    <parent link="arm_right_R3_Link" />
    <child link="arm_right_R4_Link" />
    <axis xyz="0 1 0" />
    <limit lower="-1.74" upper="0.78" effort="36" velocity="10.47" />
  </joint>
  <joint name="arm_right_R5_Joint" type="revolute">
    <origin xyz="0 0.027 -0.136" rpy="0 0 0" />
    <parent link="arm_right_R4_Link" />
    <child link="arm_right_R5_Link" />
    <axis xyz="0 0 1" />
    <limit lower="-2.96" upper="2.96" effort="14" velocity="27.21" />
  </joint>
  <joint name="arm_right_R6_Joint" type="revolute">
    <origin xyz="0 -0.028 -0.0435" rpy="0 0 0" />
    <parent link="arm_right_R5_Link" />
    <child link="arm_right_R6_Link" />
    <axis xyz="0 1 0" />
    <limit lower="-1.57" upper="1.57" effort="14" velocity="27.21" />
  </joint>
  <joint name="arm_right_R7_Joint" type="revolute">
    <origin xyz="0.028 0.028 -0.075" rpy="0 0 0" />
    <parent link="arm_right_R6_Link" />
    <child link="arm_right_R7_Link" />
    <axis xyz="-1 0 0" />
    <limit lower="-1.57" upper="1.57" effort="14" velocity="27.21" />
  </joint>
  <joint name="hand_left_lh_thumb_cmc_roll" type="revolute">
    <origin xyz="0.0078133 -0.029898 0.026692" rpy="-0.034907 0 0" />
    <parent link="hand_left_lh_hand_base_link" />
    <child link="hand_left_lh_thumb_metacarpals_base1" />
    <axis xyz="0 0 1" />
    <limit lower="-0.087266" upper="1.256637" effort="0.588" velocity="5.95" />
    <dynamics damping="0.02" friction="0.05416667" />
  </joint>
  <joint name="hand_left_lh_thumb_cmc_pitch" type="revolute">
    <origin xyz="0.0057298 -0.01332 0.0027456" rpy="1.1083 0 0.40143" />
    <parent link="hand_left_lh_thumb_metacarpals_base1" />
    <child link="hand_left_lh_thumb_metacarpals" />
    <axis xyz="-1 0 0" />
    <limit lower="0" upper="0.837758" effort="1.008" velocity="3.47" />
    <dynamics damping="0.02" friction="0.0375" />
  </joint>
  <joint name="hand_left_lh_thumb_tip_fixed" type="fixed">
    <origin xyz="0 0.0035 0.026" rpy="0 0 1.5708" />
    <parent link="hand_left_lh_thumb_distal" />
    <child link="hand_left_lh_thumb_tip" />
  </joint>
  <joint name="hand_left_lh_thumb_dip" type="revolute">
    <origin xyz="0 0.0061 0.0827" rpy="0 0 0" />
    <parent link="hand_left_lh_thumb_metacarpals" />
    <child link="hand_left_lh_thumb_distal" />
    <axis xyz="-1 0 0" />
    <limit lower="0" upper="0.963287" effort="0" velocity="1.7" />
    <mimic joint="hand_left_lh_thumb_cmc_pitch" multiplier="1.226495" offset="0" />
  </joint>
  <joint name="hand_left_lh_index_mcp_pitch" type="revolute">
    <origin xyz="-0.00066821 -0.028967 0.11722" rpy="0 0 0" />
    <parent link="hand_left_lh_hand_base_link" />
    <child link="hand_left_lh_index_proximal" />
    <axis xyz="0 1 0" />
    <limit lower="0" upper="1.134464" effort="0.574" velocity="6.10" />
    <dynamics damping="0.01" friction="0.04" />
  </joint>
  <joint name="hand_left_lh_index_tip_fixed" type="fixed">
    <origin xyz="0.0341 0 0.034" rpy="0 0 0" />
    <parent link="hand_left_lh_index_distal" />
    <child link="hand_left_lh_index_tip" />
  </joint>
  <joint name="hand_left_lh_index_dip" type="revolute">
    <origin xyz="0.00093749 0 0.028002" rpy="0 0 0" />
    <parent link="hand_left_lh_index_proximal" />
    <child link="hand_left_lh_index_distal" />
    <axis xyz="0 1 0" />
    <limit lower="0" upper="1.277039" effort="0" velocity="3.1" />
    <mimic joint="hand_left_lh_index_mcp_pitch" multiplier="1.125676" offset="0" />
  </joint>
  <joint name="hand_left_lh_middle_mcp_pitch" type="revolute">
    <origin xyz="-0.00066821 -0.0089013 0.12322" rpy="0 0 0" />
    <parent link="hand_left_lh_hand_base_link" />
    <child link="hand_left_lh_middle_proximal" />
    <axis xyz="0 1 0" />
    <limit lower="0" upper="1.134464" effort="0.574" velocity="6.10" />
    <dynamics damping="0.01" friction="0.02708333" />
  </joint>
  <joint name="hand_left_lh_middle_tip_fixed" type="fixed">
    <origin xyz="0.0341 0 0.034" rpy="0 0 0" />
    <parent link="hand_left_lh_middle_distal" />
    <child link="hand_left_lh_middle_tip" />
  </joint>
  <joint name="hand_left_lh_middle_dip" type="revolute">
    <origin xyz="0.00093749 0 0.028002" rpy="0 0 0" />
    <parent link="hand_left_lh_middle_proximal" />
    <child link="hand_left_lh_middle_distal" />
    <axis xyz="0 1 0" />
    <limit lower="0" upper="1.277039" effort="0" velocity="3.1" />
    <mimic joint="hand_left_lh_middle_mcp_pitch" multiplier="1.125676" offset="0" />
  </joint>
  <joint name="hand_left_lh_ring_mcp_pitch" type="revolute">
    <origin xyz="-0.00067368 0.010717 0.11822" rpy="0 0 0" />
    <parent link="hand_left_lh_hand_base_link" />
    <child link="hand_left_lh_ring_proximal" />
    <axis xyz="0 1 0" />
    <limit lower="0" upper="1.134464" effort="0.574" velocity="6.10" />
    <dynamics damping="0.01" friction="0.02291667" />
  </joint>
  <joint name="hand_left_lh_ring_tip_fixed" type="fixed">
    <origin xyz="0.0341 0 0.034" rpy="0 0 0" />
    <parent link="hand_left_lh_ring_distal" />
    <child link="hand_left_lh_ring_tip" />
  </joint>
  <joint name="hand_left_lh_ring_dip" type="revolute">
    <origin xyz="0.00093749 0 0.028002" rpy="0 0 0" />
    <parent link="hand_left_lh_ring_proximal" />
    <child link="hand_left_lh_ring_distal" />
    <axis xyz="0 1 0" />
    <limit lower="0" upper="1.277039" effort="0" velocity="3.1" />
    <mimic joint="hand_left_lh_ring_mcp_pitch" multiplier="1.125676" offset="0" />
  </joint>
  <joint name="hand_left_lh_pinky_mcp_pitch" type="revolute">
    <origin xyz="-0.00067852 0.029814 0.11424" rpy="0 0 0" />
    <parent link="hand_left_lh_hand_base_link" />
    <child link="hand_left_lh_pinky_proximal" />
    <axis xyz="0 1 0" />
    <limit lower="0" upper="1.134464" effort="0.574" velocity="6.10" />
    <dynamics damping="0.01" friction="0.01" />
  </joint>
  <joint name="hand_left_lh_pinky_tip_fixed" type="fixed">
    <origin xyz="0.0341 0 0.034" rpy="0 0 0" />
    <parent link="hand_left_lh_pinky_distal" />
    <child link="hand_left_lh_pinky_tip" />
  </joint>
  <joint name="hand_left_lh_pinky_dip" type="revolute">
    <origin xyz="0.00093749 0 0.028002" rpy="0 0 0" />
    <parent link="hand_left_lh_pinky_proximal" />
    <child link="hand_left_lh_pinky_distal" />
    <axis xyz="0 1 0" />
    <limit lower="0" upper="1.277039" effort="0" velocity="3.1" />
    <mimic joint="hand_left_lh_pinky_mcp_pitch" multiplier="1.125676" offset="0" />
  </joint>
  <joint name="hand_right_rh_thumb_cmc_roll" type="revolute">
    <origin xyz="0.0078133 0.030812 0.025678" rpy="-0.034907 0 0" />
    <parent link="hand_right_rh_hand_base_link" />
    <child link="hand_right_rh_thumb_metacarpals_base1" />
    <axis xyz="0 0.034899 -0.99939" />
    <limit lower="-0.087266" upper="1.256637" effort="0.588" velocity="5.95" />
    <dynamics damping="0.02" friction="0.05416667" />
  </joint>
  <joint name="hand_right_rh_thumb_cmc_pitch" type="revolute">
    <origin xyz="0.0054997 0.013314 0.0032166" rpy="-1.0762 0.013637 -0.40121" />
    <parent link="hand_right_rh_thumb_metacarpals_base1" />
    <child link="hand_right_rh_thumb_metacarpals" />
    <axis xyz="1 0 0" />
    <limit lower="0" upper="0.837758" effort="1.008" velocity="3.47" />
    <dynamics damping="0.02" friction="0.0375" />
  </joint>
  <joint name="hand_right_rh_thumb_tip_fixed" type="fixed">
    <origin xyz="0 -0.0035 0.026" rpy="0 0 -1.5708" />
    <parent link="hand_right_rh_thumb_distal" />
    <child link="hand_right_rh_thumb_tip" />
  </joint>
  <joint name="hand_right_rh_thumb_dip" type="revolute">
    <origin xyz="0 -0.0061 0.0827" rpy="0 0 0" />
    <parent link="hand_right_rh_thumb_metacarpals" />
    <child link="hand_right_rh_thumb_distal" />
    <axis xyz="1 0 0" />
    <limit lower="0" upper="0.963287" effort="0" velocity="1.7" />
    <mimic joint="hand_right_rh_thumb_cmc_pitch" multiplier="1.226495" offset="0" />
  </joint>
  <joint name="hand_right_rh_index_mcp_pitch" type="revolute">
    <origin xyz="-0.00066821 0.033467 0.11622" rpy="-0.087266 0 0" />
    <parent link="hand_right_rh_hand_base_link" />
    <child link="hand_right_rh_index_proximal" />
    <axis xyz="0 1 0" />
    <limit lower="0" upper="1.134464" effort="0.574" velocity="6.10" />
    <dynamics damping="0.01" friction="0.04" />
  </joint>
  <joint name="hand_right_rh_index_tip_fixed" type="fixed">
    <origin xyz="0.0341 0 0.034" rpy="0 0 0" />
    <parent link="hand_right_rh_index_distal" />
    <child link="hand_right_rh_index_tip" />
  </joint>
  <joint name="hand_right_rh_index_dip" type="revolute">
    <origin xyz="0.0009359 0 0.028002" rpy="0 0 0" />
    <parent link="hand_right_rh_index_proximal" />
    <child link="hand_right_rh_index_distal" />
    <axis xyz="0 1 0" />
    <limit lower="0" upper="1.277039" effort="0" velocity="3.1" />
    <mimic joint="hand_right_rh_index_mcp_pitch" multiplier="1.125676" offset="0" />
  </joint>
  <joint name="hand_right_rh_middle_mcp_pitch" type="revolute">
    <origin xyz="-0.00066821 0.0134013 0.12272" rpy="-0.034907 0 0" />
    <parent link="hand_right_rh_hand_base_link" />
    <child link="hand_right_rh_middle_proximal" />
    <axis xyz="0 1 0" />
    <limit lower="0" upper="1.134464" effort="0.574" velocity="6.10" />
    <dynamics damping="0.01" friction="0.02708333" />
  </joint>
  <joint name="hand_right_rh_middle_tip_fixed" type="fixed">
    <origin xyz="0.0341 0 0.034" rpy="0 0 0" />
    <parent link="hand_right_rh_middle_distal" />
    <child link="hand_right_rh_middle_tip" />
  </joint>
  <joint name="hand_right_rh_middle_dip" type="revolute">
    <origin xyz="0.0009359 0 0.028002" rpy="0 0 0" />
    <parent link="hand_right_rh_middle_proximal" />
    <child link="hand_right_rh_middle_distal" />
    <axis xyz="0 1 0" />
    <limit lower="0" upper="1.277039" effort="0" velocity="3.1" />
    <mimic joint="hand_right_rh_middle_mcp_pitch" multiplier="1.125676" offset="0" />
  </joint>
  <joint name="hand_right_rh_ring_mcp_pitch" type="revolute">
    <origin xyz="-0.00067368 -0.006217 0.11872" rpy="0.017453 0 0" />
    <parent link="hand_right_rh_hand_base_link" />
    <child link="hand_right_rh_ring_proximal" />
    <axis xyz="0 1 0" />
    <limit lower="0" upper="1.134464" effort="0.574" velocity="6.10" />
    <dynamics damping="0.01" friction="0.02291667" />
  </joint>
  <joint name="hand_right_rh_ring_tip_fixed" type="fixed">
    <origin xyz="0.0341 0 0.034" rpy="0 0 0" />
    <parent link="hand_right_rh_ring_distal" />
    <child link="hand_right_rh_ring_tip" />
  </joint>
  <joint name="hand_right_rh_ring_dip" type="revolute">
    <origin xyz="0.0009359 0 0.028002" rpy="0 0 0" />
    <parent link="hand_right_rh_ring_proximal" />
    <child link="hand_right_rh_ring_distal" />
    <axis xyz="0 1 0" />
    <limit lower="0" upper="1.277039" effort="0" velocity="3.1" />
    <mimic joint="hand_right_rh_ring_mcp_pitch" multiplier="1.125676" offset="0" />
  </joint>
  <joint name="hand_right_rh_pinky_mcp_pitch" type="revolute">
    <origin xyz="-0.00067852 -0.025314 0.11474" rpy="0.05236 0 0" />
    <parent link="hand_right_rh_hand_base_link" />
    <child link="hand_right_rh_pinky_proximal" />
    <axis xyz="0 1 0" />
    <limit lower="0" upper="1.134464" effort="0.574" velocity="6.10" />
    <dynamics damping="0.01" friction="0.01" />
  </joint>
  <joint name="hand_right_rh_pinky_tip_fixed" type="fixed">
    <origin xyz="0.0341 0 0.034" rpy="0 0 0" />
    <parent link="hand_right_rh_pinky_distal" />
    <child link="hand_right_rh_pinky_tip" />
  </joint>
  <joint name="hand_right_rh_pinky_dip" type="revolute">
    <origin xyz="0.0009359 0 0.028002" rpy="0 0 0" />
    <parent link="hand_right_rh_pinky_proximal" />
    <child link="hand_right_rh_pinky_distal" />
    <axis xyz="0 1 0" />
    <limit lower="0" upper="1.277039" effort="0" velocity="3.1" />
    <mimic joint="hand_right_rh_pinky_mcp_pitch" multiplier="1.125676" offset="0" />
  </joint>
  <transmission name="hand_left_trans_thumb_cmc_roll">
    <type>transmission_interface/SimpleTransmission</type>
    <joint name="hand_left_lh_thumb_cmc_roll">
      <hardwareInterface>hardware_interface/EffortJointInterface</hardwareInterface>
    </joint>
    <actuator name="motor_thumb_cmc_roll">
      <hardwareInterface>hardware_interface/EffortJointInterface</hardwareInterface>
      <mechanicalReduction>0.0084</mechanicalReduction>
    </actuator>
  </transmission>
  <transmission name="hand_left_trans_index_mcp_pitch">
    <type>transmission_interface/SimpleTransmission</type>
    <joint name="hand_left_lh_index_mcp_pitch">
      <hardwareInterface>hardware_interface/EffortJointInterface</hardwareInterface>
    </joint>
    <actuator name="motor_index_mcp_pitch">
      <hardwareInterface>hardware_interface/EffortJointInterface</hardwareInterface>
      <mechanicalReduction>0.0082</mechanicalReduction>
    </actuator>
  </transmission>
  <transmission name="hand_left_trans_middle_mcp_pitch">
    <type>transmission_interface/SimpleTransmission</type>
    <joint name="hand_left_lh_middle_mcp_pitch">
      <hardwareInterface>hardware_interface/EffortJointInterface</hardwareInterface>
    </joint>
    <actuator name="motor_middle_mcp_pitch">
      <hardwareInterface>hardware_interface/EffortJointInterface</hardwareInterface>
      <mechanicalReduction>0.0082</mechanicalReduction>
    </actuator>
  </transmission>
  <transmission name="hand_left_trans_ring_mcp_pitch">
    <type>transmission_interface/SimpleTransmission</type>
    <joint name="hand_left_lh_ring_mcp_pitch">
      <hardwareInterface>hardware_interface/EffortJointInterface</hardwareInterface>
    </joint>
    <actuator name="motor_ring_mcp_pitch">
      <hardwareInterface>hardware_interface/EffortJointInterface</hardwareInterface>
      <mechanicalReduction>0.0082</mechanicalReduction>
    </actuator>
  </transmission>
  <transmission name="hand_left_trans_pinky_mcp_pitch">
    <type>transmission_interface/SimpleTransmission</type>
    <joint name="hand_left_lh_pinky_mcp_pitch">
      <hardwareInterface>hardware_interface/EffortJointInterface</hardwareInterface>
    </joint>
    <actuator name="motor_pinky_mcp_pitch">
      <hardwareInterface>hardware_interface/EffortJointInterface</hardwareInterface>
      <mechanicalReduction>0.0082</mechanicalReduction>
    </actuator>
  </transmission>
  <transmission name="hand_left_trans_thumb_cmc_pitch">
    <type>transmission_interface/SimpleTransmission</type>
    <joint name="hand_left_lh_thumb_cmc_pitch">
      <hardwareInterface>hardware_interface/EffortJointInterface</hardwareInterface>
    </joint>
    <actuator name="motor_thumb_cmc_pitch">
      <hardwareInterface>hardware_interface/EffortJointInterface</hardwareInterface>
      <mechanicalReduction>0.0144</mechanicalReduction>
    </actuator>
  </transmission>
  <transmission name="hand_right_trans_thumb_cmc_roll">
    <type>transmission_interface/SimpleTransmission</type>
    <joint name="hand_right_rh_thumb_cmc_roll">
      <hardwareInterface>hardware_interface/EffortJointInterface</hardwareInterface>
    </joint>
    <actuator name="motor_thumb_cmc_roll">
      <hardwareInterface>hardware_interface/EffortJointInterface</hardwareInterface>
      <mechanicalReduction>0.0084</mechanicalReduction>
    </actuator>
  </transmission>
  <transmission name="hand_right_trans_index_mcp_pitch">
    <type>transmission_interface/SimpleTransmission</type>
    <joint name="hand_right_rh_index_mcp_pitch">
      <hardwareInterface>hardware_interface/EffortJointInterface</hardwareInterface>
    </joint>
    <actuator name="motor_index_mcp_pitch">
      <hardwareInterface>hardware_interface/EffortJointInterface</hardwareInterface>
      <mechanicalReduction>0.0082</mechanicalReduction>
    </actuator>
  </transmission>
  <transmission name="hand_right_trans_middle_mcp_pitch">
    <type>transmission_interface/SimpleTransmission</type>
    <joint name="hand_right_rh_middle_mcp_pitch">
      <hardwareInterface>hardware_interface/EffortJointInterface</hardwareInterface>
    </joint>
    <actuator name="motor_middle_mcp_pitch">
      <hardwareInterface>hardware_interface/EffortJointInterface</hardwareInterface>
      <mechanicalReduction>0.0082</mechanicalReduction>
    </actuator>
  </transmission>
  <transmission name="hand_right_trans_ring_mcp_pitch">
    <type>transmission_interface/SimpleTransmission</type>
    <joint name="hand_right_rh_ring_mcp_pitch">
      <hardwareInterface>hardware_interface/EffortJointInterface</hardwareInterface>
    </joint>
    <actuator name="motor_ring_mcp_pitch">
      <hardwareInterface>hardware_interface/EffortJointInterface</hardwareInterface>
      <mechanicalReduction>0.0082</mechanicalReduction>
    </actuator>
  </transmission>
  <transmission name="hand_right_trans_pinky_mcp_pitch">
    <type>transmission_interface/SimpleTransmission</type>
    <joint name="hand_right_rh_pinky_mcp_pitch">
      <hardwareInterface>hardware_interface/EffortJointInterface</hardwareInterface>
    </joint>
    <actuator name="motor_pinky_mcp_pitch">
      <hardwareInterface>hardware_interface/EffortJointInterface</hardwareInterface>
      <mechanicalReduction>0.0082</mechanicalReduction>
    </actuator>
  </transmission>
  <transmission name="hand_right_trans_thumb_cmc_pitch">
    <type>transmission_interface/SimpleTransmission</type>
    <joint name="hand_right_rh_thumb_cmc_pitch">
      <hardwareInterface>hardware_interface/EffortJointInterface</hardwareInterface>
    </joint>
    <actuator name="motor_thumb_cmc_pitch">
      <hardwareInterface>hardware_interface/EffortJointInterface</hardwareInterface>
      <mechanicalReduction>0.0144</mechanicalReduction>
    </actuator>
  </transmission>
  <joint name="mount_arm_left_to_base_base_mount" type="fixed">
    <origin xyz="0 0 0" rpy="0 0 0" />
    <parent link="base_arm_left_mount" />
    <child link="arm_left_L_arm_root" />
  </joint>
  <joint name="mount_arm_right_to_base_base_mount" type="fixed">
    <origin xyz="0 0 0" rpy="0 0 0" />
    <parent link="base_arm_right_mount" />
    <child link="arm_right_R_arm_root" />
  </joint>
  <joint name="mount_hand_left_to_arm_left_wrist_mount" type="fixed">
    <origin xyz="-0.028 0 -0.052" rpy="3.1416 0 -1.5708" />
    <parent link="arm_left_L7_Link" />
    <child link="hand_left_lh_hand_base_link" />
  </joint>
  <joint name="mount_hand_right_to_arm_right_wrist_mount" type="fixed">
    <origin xyz="-0.028 0 -0.052" rpy="3.1416 0 1.5708" />
    <parent link="arm_right_R7_Link" />
    <child link="hand_right_rh_hand_base_link" />
  </joint>
  <joint name="mount_world_to_base" type="fixed">
    <origin xyz="0 0 0" rpy="0 0 0" />
    <parent link="world" />
    <child link="base_torso_root" />
  </joint>
  <mujoco>
    <compiler meshdir="meshes/" balanceinertia="true" discardvisual="false" />
    <default>
      <joint armature="3.4707e-08" damping="5.0" frictionloss="0.5" />
    </default>
    <equality>
      <joint name="hand_left_lh_couple_index" joint1="hand_left_lh_index_dip" joint2="hand_left_lh_index_mcp_pitch" polycoef="0 1.125676 0 0 0 0" />
      <joint name="hand_left_lh_couple_middle" joint1="hand_left_lh_middle_dip" joint2="hand_left_lh_middle_mcp_pitch" polycoef="0 1.125676 0 0 0 0" />
      <joint name="hand_left_lh_couple_ring" joint1="hand_left_lh_ring_dip" joint2="hand_left_lh_ring_mcp_pitch" polycoef="0 1.125676 0 0 0 0" />
      <joint name="hand_left_lh_couple_pinky" joint1="hand_left_lh_pinky_dip" joint2="hand_left_lh_pinky_mcp_pitch" polycoef="0 1.125676 0 0 0 0" />
      <joint name="hand_left_lh_couple_thumb" joint1="hand_left_lh_thumb_dip" joint2="hand_left_lh_thumb_cmc_pitch" polycoef="0 1.226495 0 0 0 0" />
    </equality>
  </mujoco>
  <mujoco>
    <default>
      <joint armature="3.4707e-08" damping="5.0" frictionloss="0.5" />
    </default>
    <equality>
      <joint name="hand_right_rh_couple_index" joint1="hand_right_rh_index_dip" joint2="hand_right_rh_index_mcp_pitch" polycoef="0 1.125676 0 0 0 0" />
      <joint name="hand_right_rh_couple_middle" joint1="hand_right_rh_middle_dip" joint2="hand_right_rh_middle_mcp_pitch" polycoef="0 1.125676 0 0 0 0" />
      <joint name="hand_right_rh_couple_ring" joint1="hand_right_rh_ring_dip" joint2="hand_right_rh_ring_mcp_pitch" polycoef="0 1.125676 0 0 0 0" />
      <joint name="hand_right_rh_couple_pinky" joint1="hand_right_rh_pinky_dip" joint2="hand_right_rh_pinky_mcp_pitch" polycoef="0 1.125676 0 0 0 0" />
      <joint name="hand_right_rh_couple_thumb" joint1="hand_right_rh_thumb_dip" joint2="hand_right_rh_thumb_cmc_pitch" polycoef="0 1.226495 0 0 0 0" />
    </equality>
  </mujoco>
</robot>
