<mujoco model="linkerhand_l20lite_right">
  <compiler meshdir="meshes" discardvisual="false" autolimits="true" angle="radian" eulerseq="XYZ"/>
  <option/>

  <default>
    <default class="hand_linkerhand_l20lite_visual">
      <geom type="mesh" contype="0" conaffinity="0" group="1"/>
    </default>
    <default class="hand_linkerhand_l20lite_collision">
      <geom type="mesh" contype="1" conaffinity="1" group="3"/>
    </default>
    <default class="hand_linkerhand_l20lite_joint">
      <joint armature="3.4707e-08" damping="4.0" frictionloss="0.5"/>
    </default>
  </default>

  <asset>
    <mesh name="hand_base_link" file="hand_base_link.STL"/>
    <mesh name="thumb_metacarpals_base1" file="thumb_metacarpals_base1.STL"/>
    <mesh name="thumb_metacarpals_base2" file="thumb_metacarpals_base2.STL"/>
    <mesh name="thumb_metacarpals" file="thumb_metacarpals.STL"/>
    <mesh name="thumb_proximal" file="thumb_proximal.STL"/>
    <mesh name="thumb_distal" file="thumb_distal.STL"/>
    <mesh name="index_metacarpals" file="index_metacarpals.STL"/>
    <mesh name="index_proximal" file="index_proximal.STL"/>
    <mesh name="index_middle" file="index_middle.STL"/>
    <mesh name="index_distal" file="index_distal.STL"/>
    <mesh name="middle_proximal" file="middle_proximal.STL"/>
    <mesh name="middle_middle" file="middle_middle.STL"/>
    <mesh name="middle_distal" file="middle_distal.STL"/>
    <mesh name="ring_metacarpals" file="ring_metacarpals.STL"/>
    <mesh name="ring_proximal" file="ring_proximal.STL"/>
    <mesh name="ring_middle" file="ring_middle.STL"/>
    <mesh name="ring_distal" file="ring_distal.STL"/>
    <mesh name="pinky_metacarpals" file="pinky_metacarpals.STL"/>
    <mesh name="pinky_proximal" file="pinky_proximal.STL"/>
    <mesh name="pinky_middle" file="pinky_middle.STL"/>
    <mesh name="pinky_distal" file="pinky_distal.STL"/>
  </asset>

  <worldbody>
    <body name="rh_hand_base_link" pos="0 0 0">
      <inertial pos="-0.00378572993475002 -0.00041583904893102 0.083639288361369" mass="0.108844276105116" fullinertia="0.000193454839560416 0.000129793182936331 7.75126657491833e-05 -1.28842682703635e-06 -1.97005632027442e-07 2.34961034039848e-06"/>
      <geom class="hand_linkerhand_l20lite_visual" mesh="hand_base_link"/>
      <geom class="hand_linkerhand_l20lite_collision" mesh="hand_base_link"/>
      <site name="wrist_mount" pos="0 0 0"/>
      <body name="rh_thumb_metacarpals_base1" pos="-0.013419 0.012551 0.060602">
        <inertial pos="0.0284798868788809 -0.00318431295224701 1.02719477181115e-05" mass="0.0084581547726202" fullinertia="1.40243836130246e-06 9.92829395244375e-07 7.26110349167423e-07 -1.19619722062239e-07 7.34394052250468e-09 4.64162077403213e-08"/>
        <joint name="rh_thumb_cmc_roll" class="hand_linkerhand_l20lite_joint" type="hinge" axis="0.99996 0 -0.0087265" range="0 1.03"/>
        <geom class="hand_linkerhand_l20lite_visual" mesh="thumb_metacarpals_base1"/>
        <geom class="hand_linkerhand_l20lite_collision" mesh="thumb_metacarpals_base1"/>
        <body name="rh_thumb_metacarpals_base2" pos="0.035798 -0.0006691 0.00040146" euler="-0.13233 -0.0085747 0.0011413">
          <inertial pos="0.00174090957798892 0.00721482590041489 -0.000263313052030728" mass="0.00582711245702963" fullinertia="3.17303010997568e-07 2.73232268452871e-07 1.76908306988949e-07 1.12913904502057e-08 -2.63903919763792e-09 -1.09223121289568e-08"/>
          <joint name="rh_thumb_cmc_yaw" class="hand_linkerhand_l20lite_joint" type="hinge" axis="0 0 -1" range="0 1.4"/>
          <geom class="hand_linkerhand_l20lite_visual" mesh="thumb_metacarpals_base2"/>
          <geom class="hand_linkerhand_l20lite_collision" mesh="thumb_metacarpals_base2"/>
          <body name="rh_thumb_metacarpals" pos="0.0037151 0.015396 -0.0019302" euler="0 -0.9163 -1.8076">
            <inertial pos="0.00183662400665177 -2.80439600631663e-06 0.0269904280709441" mass="0.0152012256765109" fullinertia="2.95371260447027e-06 3.8477229500142e-06 1.32007940012866e-06 -6.21178551021653e-11 -1.58082424321764e-07 -4.14758708520733e-10"/>
            <joint name="rh_thumb_cmc_pitch" class="hand_linkerhand_l20lite_joint" type="hinge" axis="0 1 0" range="0 0.52"/>
            <geom class="hand_linkerhand_l20lite_visual" mesh="thumb_metacarpals"/>
            <geom class="hand_linkerhand_l20lite_collision" mesh="thumb_metacarpals"/>
            <body name="rh_thumb_proximal" pos="0.0061722 0 0.047968">
              <inertial pos="0.00159268252983606 -4.43643671124011e-06 0.015157363827759" mass="0.00662231923284161" fullinertia="1.01527279135723e-06 9.10434608488902e-07 4.47464440479559e-07 3.86298144933713e-12 -4.42245334725163e-08 -2.76864906314695e-11"/>
              <joint name="rh_thumb_mcp" class="hand_linkerhand_l20lite_joint" type="hinge" axis="0 1 0" range="0 0.72"/>
              <geom class="hand_linkerhand_l20lite_visual" mesh="thumb_proximal"/>
              <geom class="hand_linkerhand_l20lite_collision" mesh="thumb_proximal"/>
              <body name="rh_thumb_distal" pos="-0.00017064 0 0.038665">
                <inertial pos="-0.00138929852568181 1.78258724357894e-06 0.0115789166085123" mass="0.00512919991432349" fullinertia="3.30966764284813e-07 3.23803379547457e-07 2.48897458436709e-07 3.4874903065333e-10 -1.0473713688836e-07 8.38797000457644e-11"/>
                <joint name="rh_thumb_ip" class="hand_linkerhand_l20lite_joint" type="hinge" axis="0 1 0" range="0 0.78"/>
                <geom class="hand_linkerhand_l20lite_visual" mesh="thumb_distal"/>
                <geom class="hand_linkerhand_l20lite_collision" mesh="thumb_distal"/>
              </body>
            </body>
          </body>
        </body>
      </body>
      <body name="rh_index_metacarpals" pos="-0.0021643 0.026654 0.13253" euler="-0.027925 -0.0087266 0">
        <inertial pos="-0.000394044300581899 -6.96524768268453e-07 0.00909446180986484" mass="0.00903700329493157" fullinertia="4.89554250283515e-07 7.37380385682221e-07 5.52862732336676e-07 -3.94697795521512e-11 2.73097237930781e-08 -6.33508384593073e-11"/>
        <joint name="rh_index_mcp_roll" class="hand_linkerhand_l20lite_joint" type="hinge" axis="-1 0 0" range="0 0.19"/>
        <geom class="hand_linkerhand_l20lite_visual" mesh="index_metacarpals"/>
        <geom class="hand_linkerhand_l20lite_collision" mesh="index_metacarpals"/>
        <body name="rh_index_proximal" pos="0.00220968332188026 0 0.0152749792820048">
          <inertial pos="-0.000129944380960653 1.17196171642124e-06 0.0104816955547003" mass="0.00654982235507964" fullinertia="4.43901400960209e-07 4.58697731369085e-07 1.74205815221237e-07 3.44400810155697e-12 -2.4814971446792e-08 8.51406115918214e-11"/>
          <joint name="rh_index_mcp_pitch" class="hand_linkerhand_l20lite_joint" type="hinge" axis="0 1 0" range="0 1.36"/>
          <geom class="hand_linkerhand_l20lite_visual" mesh="index_proximal"/>
          <geom class="hand_linkerhand_l20lite_collision" mesh="index_proximal"/>
          <body name="rh_index_middle" pos="-0.0010697 0 0.035634">
            <inertial pos="-0.00250308175256513 -2.09528008505294e-06 0.0110397399346051" mass="0.00283043630937165" fullinertia="2.61037002532157e-07 2.33077671005604e-07 1.2654386429984e-07 -5.76553826316728e-11 -4.00111847827091e-08 2.97012055424732e-11"/>
            <joint name="rh_index_pip" class="hand_linkerhand_l20lite_joint" type="hinge" axis="0 1 0" range="0 1.78"/>
            <geom class="hand_linkerhand_l20lite_visual" mesh="index_middle"/>
            <geom class="hand_linkerhand_l20lite_collision" mesh="index_middle"/>
            <body name="rh_index_distal" pos="-0.0052444 0 0.025711">
              <inertial pos="-0.000604588906740394 5.26099433146611e-06 0.0121514585299274" mass="0.0031446130611452" fullinertia="1.64075846532352e-07 1.48367877966466e-07 9.78063887942514e-08 -1.75219464852339e-11 -4.27797730478817e-08 2.03355501606508e-10"/>
              <joint name="rh_index_dip" class="hand_linkerhand_l20lite_joint" type="hinge" axis="0 1 0" range="0 0.62"/>
              <geom class="hand_linkerhand_l20lite_visual" mesh="index_distal"/>
              <geom class="hand_linkerhand_l20lite_collision" mesh="index_distal"/>
            </body>
          </body>
        </body>
      </body>
      <body name="rh_middle_proximal" pos="-0.00213155528434806 0.00765417737818821 0.152810108410232">
        <inertial pos="-0.000226219980586554 1.17216483217029e-06 0.0104800581470382" mass="0.00654982478226949" fullinertia="4.43422823045882e-07 4.58697754707373e-07 1.746844667607e-07 2.65801609334198e-12 -2.72879331079685e-08 8.52654749038393e-11"/>
        <joint name="rh_middle_mcp_pitch" class="hand_linkerhand_l20lite_joint" type="hinge" axis="0 1 0" range="0 1.36"/>
        <geom class="hand_linkerhand_l20lite_visual" mesh="middle_proximal"/>
        <geom class="hand_linkerhand_l20lite_collision" mesh="middle_proximal"/>
        <body name="rh_middle_middle" pos="-0.00139702428111229 0 0.0356230829860553">
          <inertial pos="-0.00261699473119731 -2.09526685194996e-06 0.0110132928110042" mass="0.00283043635504842" fullinertia="2.60196021834948e-07 2.33077669434872e-07 1.27384845266404e-07 -5.79547865424222e-11 -4.13919583593881e-08 2.9104841260857e-11"/>
          <joint name="rh_middle_pip" class="hand_linkerhand_l20lite_joint" type="hinge" axis="0 1 0" range="0 1.78"/>
          <geom class="hand_linkerhand_l20lite_visual" mesh="middle_middle"/>
          <geom class="hand_linkerhand_l20lite_collision" mesh="middle_middle"/>
          <body name="rh_middle_distal" pos="-0.0055098 0 0.025656">
            <inertial pos="-0.000728492686371173 5.23463092580619e-06 0.0121446078355885" mass="0.00314458659113992" fullinertia="1.63194300204967e-07 1.48366133401819e-07 9.8685363448972e-08 -1.99064062210326e-11 -4.34469141576056e-08 2.02741720954809e-10"/>
            <joint name="rh_middle_dip" class="hand_linkerhand_l20lite_joint" type="hinge" axis="0 1 0" range="0 0.62"/>
            <geom class="hand_linkerhand_l20lite_visual" mesh="middle_distal"/>
            <geom class="hand_linkerhand_l20lite_collision" mesh="middle_distal"/>
          </body>
        </body>
      </body>
      <body name="rh_ring_metacarpals" pos="-0.00216430029569533 -0.0113458226218121 0.132534071328313" euler="0.0244346095279086 -0.00872664625996829 0">
        <inertial pos="-0.000394044453752051 -6.96464269499264e-07 0.00909446164305169" mass="0.00903700335356623" fullinertia="4.89554245950771e-07 7.37380377611045e-07 5.52862742016819e-07 -3.94741777907138e-11 2.73097253166787e-08 -6.33493307330511e-11"/>
        <joint name="rh_ring_mcp_roll" class="hand_linkerhand_l20lite_joint" type="hinge" axis="1 0 0" range="0 0.2"/>
        <geom class="hand_linkerhand_l20lite_visual" mesh="ring_metacarpals"/>
        <geom class="hand_linkerhand_l20lite_collision" mesh="ring_metacarpals"/>
        <body name="rh_ring_proximal" pos="0.0022097 0 0.015275">
          <inertial pos="-0.000129951741702268 1.17052693794986e-06 0.0104816759358435" mass="0.00654983629670871" fullinertia="4.43901586303392e-07 4.58698142287549e-07 1.74206152792307e-07 3.50295306689535e-12 -2.48148215954452e-08 8.52333703161162e-11"/>
          <joint name="rh_ring_mcp_pitch" class="hand_linkerhand_l20lite_joint" type="hinge" axis="0 1 0" range="0 1.36"/>
          <geom class="hand_linkerhand_l20lite_visual" mesh="ring_proximal"/>
          <geom class="hand_linkerhand_l20lite_collision" mesh="ring_proximal"/>
          <body name="rh_ring_middle" pos="-0.00106974956301328 0 0.0356344124989653">
            <inertial pos="-0.00250308200880736 -2.09549542964232e-06 0.0110397403443072" mass="0.0028304363455826" fullinertia="2.610370084214e-07 2.3307766580208e-07 1.26543852008426e-07 -5.76575489930258e-11 -4.00111860002357e-08 2.97027542466601e-11"/>
            <joint name="rh_ring_pip" class="hand_linkerhand_l20lite_joint" type="hinge" axis="0 1 0" range="0 1.78"/>
            <geom class="hand_linkerhand_l20lite_visual" mesh="ring_middle"/>
            <geom class="hand_linkerhand_l20lite_collision" mesh="ring_middle"/>
            <body name="rh_ring_distal" pos="-0.00524443259686075 0 0.0257114125710868" euler="0 0 -0.000213216385347256">
              <inertial pos="-0.00060459286126547 5.09148089232817e-06 0.0121514427640609" mass="0.00314460631735109" fullinertia="1.64075455538032e-07 1.48367698956355e-07 9.78062648939272e-08 -2.1468512857682e-11 -4.27798116117893e-08 1.93419127705868e-10"/>
              <joint name="rh_ring_dip" class="hand_linkerhand_l20lite_joint" type="hinge" axis="0.000213099161087669 0.999450193223668 -0.033155178387707" range="0 0.62"/>
              <geom class="hand_linkerhand_l20lite_visual" mesh="ring_distal"/>
              <geom class="hand_linkerhand_l20lite_collision" mesh="ring_distal"/>
            </body>
          </body>
        </body>
      </body>
      <body name="rh_pinky_metacarpals" pos="-0.00012074 -0.030346 0.12755" euler="0.057596 -0.0087266 0">
        <inertial pos="-0.00039404522692532 -6.96240700731598e-07 0.00909446058676422" mass="0.00903700307878998" fullinertia="4.89554195779539e-07 7.37380317460272e-07 5.5286276236961e-07 -3.94817181132792e-11 2.7309708213456e-08 -6.33317017267926e-11"/>
        <joint name="rh_pinky_mcp_roll" class="hand_linkerhand_l20lite_joint" type="hinge" axis="1 0 0" range="0 0.3"/>
        <geom class="hand_linkerhand_l20lite_visual" mesh="pinky_metacarpals"/>
        <geom class="hand_linkerhand_l20lite_collision" mesh="pinky_metacarpals"/>
        <body name="rh_pinky_proximal" pos="0.0022097 0 0.015275">
          <inertial pos="-0.000129949532354408 1.17230680928004e-06 0.0104816807512055" mass="0.00654983474179372" fullinertia="4.43901730245286e-07 4.58698159687316e-07 1.74206088330646e-07 3.4507527836803e-12 -2.48149152090791e-08 8.52432689792127e-11"/>
          <joint name="rh_pinky_mcp_pitch" class="hand_linkerhand_l20lite_joint" type="hinge" axis="0 1 0" range="0 1.36"/>
          <geom class="hand_linkerhand_l20lite_visual" mesh="pinky_proximal"/>
          <geom class="hand_linkerhand_l20lite_collision" mesh="pinky_proximal"/>
          <body name="rh_pinky_middle" pos="-0.0010697 0 0.035634">
            <inertial pos="-0.00250308414609457 -2.09612030866585e-06 0.0110397422037874" mass="0.00283043670305552" fullinertia="2.6103697292473e-07 2.33077589871973e-07 1.26543829688383e-07 -5.76245409160896e-11 -4.00111424508735e-08 2.96769001441938e-11"/>
            <joint name="rh_pinky_pip" class="hand_linkerhand_l20lite_joint" type="hinge" axis="0 1 0" range="0 1.78"/>
            <geom class="hand_linkerhand_l20lite_visual" mesh="pinky_middle"/>
            <geom class="hand_linkerhand_l20lite_collision" mesh="pinky_middle"/>
            <body name="rh_pinky_distal" pos="-0.0052444 0 0.025711">
              <inertial pos="-0.000604482988543969 5.27153358490656e-06 0.0121512430050648" mass="0.00314457409502053" fullinertia="1.64068754964363e-07 1.48361079085349e-07 9.78068531228973e-08 -1.90437996173564e-11 -4.27789862984836e-08 2.05110113267167e-10"/>
              <joint name="rh_pinky_dip" class="hand_linkerhand_l20lite_joint" type="hinge" axis="0 1 0" range="0 0.62"/>
              <geom class="hand_linkerhand_l20lite_visual" mesh="pinky_distal"/>
              <geom class="hand_linkerhand_l20lite_collision" mesh="pinky_distal"/>
            </body>
          </body>
        </body>
      </body>
    </body>
  </worldbody>

  <actuator>
    <position name="rh_thumb_cmc_roll_act" joint="rh_thumb_cmc_roll" kp="200" kv="0" ctrlrange="0 1.03"/>
    <position name="rh_thumb_cmc_yaw_act" joint="rh_thumb_cmc_yaw" kp="200" kv="0" ctrlrange="0 1.4"/>
    <position name="rh_thumb_cmc_pitch_act" joint="rh_thumb_cmc_pitch" kp="200" kv="0" ctrlrange="0 0.52"/>
    <position name="rh_index_mcp_roll_act" joint="rh_index_mcp_roll" kp="200" kv="0" ctrlrange="0 0.19"/>
    <position name="rh_index_mcp_pitch_act" joint="rh_index_mcp_pitch" kp="200" kv="0" ctrlrange="0 1.36"/>
    <position name="rh_middle_mcp_pitch_act" joint="rh_middle_mcp_pitch" kp="200" kv="0" ctrlrange="0 1.36"/>
    <position name="rh_ring_mcp_roll_act" joint="rh_ring_mcp_roll" kp="200" kv="0" ctrlrange="0 0.2"/>
    <position name="rh_ring_mcp_pitch_act" joint="rh_ring_mcp_pitch" kp="200" kv="0" ctrlrange="0 1.36"/>
    <position name="rh_pinky_mcp_roll_act" joint="rh_pinky_mcp_roll" kp="200" kv="0" ctrlrange="0 0.3"/>
    <position name="rh_pinky_mcp_pitch_act" joint="rh_pinky_mcp_pitch" kp="200" kv="0" ctrlrange="0 1.36"/>
  </actuator>

  <equality>
    <joint name="rh_couple_thumb_mcp" joint1="rh_thumb_mcp" joint2="rh_thumb_cmc_pitch" polycoef="0 1.38 0 0 0"/>
    <joint name="rh_couple_thumb_ip" joint1="rh_thumb_ip" joint2="rh_thumb_cmc_pitch" polycoef="0 1.49 0 0 0"/>
    <joint name="rh_couple_index_pip" joint1="rh_index_pip" joint2="rh_index_mcp_pitch" polycoef="0 1.3 0 0 0"/>
    <joint name="rh_couple_index_dip" joint1="rh_index_dip" joint2="rh_index_mcp_pitch" polycoef="0 0.46 0 0 0"/>
    <joint name="rh_couple_middle_pip" joint1="rh_middle_pip" joint2="rh_middle_mcp_pitch" polycoef="0 1.3 0 0 0"/>
    <joint name="rh_couple_middle_dip" joint1="rh_middle_dip" joint2="rh_middle_mcp_pitch" polycoef="0 0.46 0 0 0"/>
    <joint name="rh_couple_ring_pip" joint1="rh_ring_pip" joint2="rh_ring_mcp_pitch" polycoef="0 1.34 0 0 0"/>
    <joint name="rh_couple_ring_dip" joint1="rh_ring_dip" joint2="rh_ring_mcp_pitch" polycoef="0 0.46 0 0 0"/>
    <joint name="rh_couple_pinky_pip" joint1="rh_pinky_pip" joint2="rh_pinky_mcp_pitch" polycoef="0 1.34 0 0 0"/>
    <joint name="rh_couple_pinky_dip" joint1="rh_pinky_dip" joint2="rh_pinky_mcp_pitch" polycoef="0 0.46 0 0 0"/>
  </equality>

  <contact>
    <exclude body1="rh_hand_base_link" body2="rh_thumb_metacarpals_base1"/>
    <exclude body1="rh_thumb_metacarpals_base1" body2="rh_thumb_metacarpals_base2"/>
    <exclude body1="rh_thumb_metacarpals_base2" body2="rh_thumb_metacarpals"/>
    <exclude body1="rh_thumb_metacarpals" body2="rh_thumb_proximal"/>
    <exclude body1="rh_thumb_proximal" body2="rh_thumb_distal"/>
    <exclude body1="rh_hand_base_link" body2="rh_index_metacarpals"/>
    <exclude body1="rh_index_metacarpals" body2="rh_index_proximal"/>
    <exclude body1="rh_index_proximal" body2="rh_index_middle"/>
    <exclude body1="rh_index_middle" body2="rh_index_distal"/>
    <exclude body1="rh_hand_base_link" body2="rh_middle_proximal"/>
    <exclude body1="rh_middle_proximal" body2="rh_middle_middle"/>
    <exclude body1="rh_middle_middle" body2="rh_middle_distal"/>
    <exclude body1="rh_hand_base_link" body2="rh_ring_metacarpals"/>
    <exclude body1="rh_ring_metacarpals" body2="rh_ring_proximal"/>
    <exclude body1="rh_ring_proximal" body2="rh_ring_middle"/>
    <exclude body1="rh_ring_middle" body2="rh_ring_distal"/>
    <exclude body1="rh_hand_base_link" body2="rh_pinky_metacarpals"/>
    <exclude body1="rh_pinky_metacarpals" body2="rh_pinky_proximal"/>
    <exclude body1="rh_pinky_proximal" body2="rh_pinky_middle"/>
    <exclude body1="rh_pinky_middle" body2="rh_pinky_distal"/>
    <exclude body1="rh_hand_base_link" body2="rh_index_proximal"/>
    <exclude body1="rh_hand_base_link" body2="rh_ring_proximal"/>
    <exclude body1="rh_hand_base_link" body2="rh_pinky_proximal"/>
    <exclude body1="rh_hand_base_link" body2="rh_thumb_metacarpals_base2"/>
    <exclude body1="rh_hand_base_link" body2="rh_thumb_metacarpals"/>
    <exclude body1="rh_thumb_metacarpals" body2="rh_thumb_metacarpals_base1"/>
  </contact>
</mujoco>
