<?xml version='1.0' encoding='utf-8'?>
<robot name="hand">
  <link name="rh_hand_base_link">
    <inertial>
      <origin xyz="-0.00378572993475002 -0.00041583904893102 0.083639288361369" rpy="0 0 0" />
      <mass value="0.108844276105116" />
      <inertia ixx="0.000193454839560416" ixy="-1.28842682703635e-06" ixz="-1.97005632027442e-07" iyy="0.000129793182936331" iyz="2.34961034039848e-06" izz="7.75126657491833e-05" />
    </inertial>
    <visual>
      <origin xyz="0 0 0" rpy="0 0 0" />
      <geometry><mesh filename="meshes/hand_base_link.STL" /></geometry>
      <material name=""><color rgba="1 1 1 1" /></material>
    </visual>
    <collision>
      <origin xyz="0 0 0" rpy="0 0 0" />
      <geometry><mesh filename="meshes/hand_base_link.STL" /></geometry>
    </collision>
  </link>
  <link name="rh_thumb_metacarpals_base1">
    <inertial>
      <origin xyz="0.0284798868788809 -0.00318431295224701 1.02719477181115e-05" rpy="0 0 0" />
      <mass value="0.0084581547726202" />
      <inertia ixx="1.40243836130246e-06" ixy="-1.19619722062239e-07" ixz="7.34394052250468e-09" iyy="9.92829395244375e-07" iyz="4.64162077403213e-08" izz="7.26110349167423e-07" />
    </inertial>
    <visual>
      <origin xyz="0 0 0" rpy="0 0 0" />
      <geometry><mesh filename="meshes/thumb_metacarpals_base1.STL" /></geometry>
      <material name=""><color rgba="1 1 1 1" /></material>
    </visual>
    <collision>
      <origin xyz="0 0 0" rpy="0 0 0" />
      <geometry><mesh filename="meshes/thumb_metacarpals_base1.STL" /></geometry>
    </collision>
  </link>
  <link name="rh_thumb_metacarpals_base2">
    <inertial>
      <origin xyz="0.00174090957798892 0.00721482590041489 -0.000263313052030728" rpy="0 0 0" />
      <mass value="0.00582711245702963" />
      <inertia ixx="3.17303010997568e-07" ixy="1.12913904502057e-08" ixz="-2.63903919763792e-09" iyy="2.73232268452871e-07" iyz="-1.09223121289568e-08" izz="1.76908306988949e-07" />
    </inertial>
    <visual>
      <origin xyz="0 0 0" rpy="0 0 0" />
      <geometry><mesh filename="meshes/thumb_metacarpals_base2.STL" /></geometry>
      <material name=""><color rgba="1 1 1 1" /></material>
    </visual>
    <collision>
      <origin xyz="0 0 0" rpy="0 0 0" />
      <geometry><mesh filename="meshes/thumb_metacarpals_base2.STL" /></geometry>
    </collision>
  </link>
  <link name="rh_thumb_metacarpals">
    <inertial>
      <origin xyz="0.00183662400665177 -2.80439600631663e-06 0.0269904280709441" rpy="0 0 0" />
      <mass value="0.0152012256765109" />
      <inertia ixx="2.95371260447027e-06" ixy="-6.21178551021653e-11" ixz="-1.58082424321764e-07" iyy="3.8477229500142e-06" iyz="-4.14758708520733e-10" izz="1.32007940012866e-06" />
    </inertial>
    <visual>
      <origin xyz="0 0 0" rpy="0 0 0" />
      <geometry><mesh filename="meshes/thumb_metacarpals.STL" /></geometry>
      <material name=""><color rgba="1 1 1 1" /></material>
    </visual>
    <collision>
      <origin xyz="0 0 0" rpy="0 0 0" />
      <geometry><mesh filename="meshes/thumb_metacarpals.STL" /></geometry>
    </collision>
  </link>
  <link name="rh_thumb_proximal">
    <inertial>
      <origin xyz="0.00159268252983606 -4.43643671124011e-06 0.015157363827759" rpy="0 0 0" />
      <mass value="0.00662231923284161" />
      <inertia ixx="1.01527279135723e-06" ixy="3.86298144933713e-12" ixz="-4.42245334725163e-08" iyy="9.10434608488902e-07" iyz="-2.76864906314695e-11" izz="4.47464440479559e-07" />
    </inertial>
    <visual>
      <origin xyz="0 0 0" rpy="0 0 0" />
      <geometry><mesh filename="meshes/thumb_proximal.STL" /></geometry>
      <material name=""><color rgba="1 1 1 1" /></material>
    </visual>
    <collision>
      <origin xyz="0 0 0" rpy="0 0 0" />
      <geometry><mesh filename="meshes/thumb_proximal.STL" /></geometry>
    </collision>
  </link>
  <link name="rh_thumb_distal">
    <inertial>
      <origin xyz="-0.00138929852568181 1.78258724357894e-06 0.0115789166085123" rpy="0 0 0" />
      <mass value="0.00512919991432349" />
      <inertia ixx="3.30966764284813e-07" ixy="3.4874903065333e-10" ixz="-1.0473713688836e-07" iyy="3.23803379547457e-07" iyz="8.38797000457644e-11" izz="2.48897458436709e-07" />
    </inertial>
    <visual>
      <origin xyz="0 0 0" rpy="0 0 0" />
      <geometry><mesh filename="meshes/thumb_distal.STL" /></geometry>
      <material name=""><color rgba="1 1 1 1" /></material>
    </visual>
    <collision>
      <origin xyz="0 0 0" rpy="0 0 0" />
      <geometry><mesh filename="meshes/thumb_distal.STL" /></geometry>
    </collision>
  </link>
  <link name="rh_index_metacarpals">
    <inertial>
      <origin xyz="-0.000394044300581899 -6.96524768268453e-07 0.00909446180986484" rpy="0 0 0" />
      <mass value="0.00903700329493157" />
      <inertia ixx="4.89554250283515e-07" ixy="-3.94697795521512e-11" ixz="2.73097237930781e-08" iyy="7.37380385682221e-07" iyz="-6.33508384593073e-11" izz="5.52862732336676e-07" />
    </inertial>
    <visual>
      <origin xyz="0 0 0" rpy="0 0 0" />
      <geometry><mesh filename="meshes/index_metacarpals.STL" /></geometry>
      <material name=""><color rgba="1 1 1 1" /></material>
    </visual>
    <collision>
      <origin xyz="0 0 0" rpy="0 0 0" />
      <geometry><mesh filename="meshes/index_metacarpals.STL" /></geometry>
    </collision>
  </link>
  <link name="rh_index_proximal">
    <inertial>
      <origin xyz="-0.000129944380960653 1.17196171642124e-06 0.0104816955547003" rpy="0 0 0" />
      <mass value="0.00654982235507964" />
      <inertia ixx="4.43901400960209e-07" ixy="3.44400810155697e-12" ixz="-2.4814971446792e-08" iyy="4.58697731369085e-07" iyz="8.51406115918214e-11" izz="1.74205815221237e-07" />
    </inertial>
    <visual>
      <origin xyz="0 0 0" rpy="0 0 0" />
      <geometry><mesh filename="meshes/index_proximal.STL" /></geometry>
      <material name=""><color rgba="1 1 1 1" /></material>
    </visual>
    <collision>
      <origin xyz="0 0 0" rpy="0 0 0" />
      <geometry><mesh filename="meshes/index_proximal.STL" /></geometry>
    </collision>
  </link>
  <link name="rh_index_middle">
    <inertial>
      <origin xyz="-0.00250308175256513 -2.09528008505294e-06 0.0110397399346051" rpy="0 0 0" />
      <mass value="0.00283043630937165" />
      <inertia ixx="2.61037002532157e-07" ixy="-5.76553826316728e-11" ixz="-4.00111847827091e-08" iyy="2.33077671005604e-07" iyz="2.97012055424732e-11" izz="1.2654386429984e-07" />
    </inertial>
    <visual>
      <origin xyz="0 0 0" rpy="0 0 0" />
      <geometry><mesh filename="meshes/index_middle.STL" /></geometry>
      <material name=""><color rgba="1 1 1 1" /></material>
    </visual>
    <collision>
      <origin xyz="0 0 0" rpy="0 0 0" />
      <geometry><mesh filename="meshes/index_middle.STL" /></geometry>
    </collision>
  </link>
  <link name="rh_index_distal">
    <inertial>
      <origin xyz="-0.000604588906740394 5.26099433146611e-06 0.0121514585299274" rpy="0 0 0" />
      <mass value="0.0031446130611452" />
      <inertia ixx="1.64075846532352e-07" ixy="-1.75219464852339e-11" ixz="-4.27797730478817e-08" iyy="1.48367877966466e-07" iyz="2.03355501606508e-10" izz="9.78063887942514e-08" />
    </inertial>
    <visual>
      <origin xyz="0 0 0" rpy="0 0 0" />
      <geometry><mesh filename="meshes/index_distal.STL" /></geometry>
      <material name=""><color rgba="1 1 1 1" /></material>
    </visual>
    <collision>
      <origin xyz="0 0 0" rpy="0 0 0" />
      <geometry><mesh filename="meshes/index_distal.STL" /></geometry>
    </collision>
  </link>
  <link name="rh_middle_proximal">
    <inertial>
      <origin xyz="-0.000226219980586554 1.17216483217029e-06 0.0104800581470382" rpy="0 0 0" />
      <mass value="0.00654982478226949" />
      <inertia ixx="4.43422823045882e-07" ixy="2.65801609334198e-12" ixz="-2.72879331079685e-08" iyy="4.58697754707373e-07" iyz="8.52654749038393e-11" izz="1.746844667607e-07" />
    </inertial>
    <visual>
      <origin xyz="0 0 0" rpy="0 0 0" />
      <geometry><mesh filename="meshes/middle_proximal.STL" /></geometry>
      <material name=""><color rgba="1 1 1 1" /></material>
    </visual>
    <collision>
      <origin xyz="0 0 0" rpy="0 0 0" />
      <geometry><mesh filename="meshes/middle_proximal.STL" /></geometry>
    </collision>
  </link>
  <link name="rh_middle_middle">
    <inertial>
      <origin xyz="-0.00261699473119731 -2.09526685194996e-06 0.0110132928110042" rpy="0 0 0" />
      <mass value="0.00283043635504842" />
      <inertia ixx="2.60196021834948e-07" ixy="-5.79547865424222e-11" ixz="-4.13919583593881e-08" iyy="2.33077669434872e-07" iyz="2.9104841260857e-11" izz="1.27384845266404e-07" />
    </inertial>
    <visual>
      <origin xyz="0 0 0" rpy="0 0 0" />
      <geometry><mesh filename="meshes/middle_middle.STL" /></geometry>
      <material name=""><color rgba="1 1 1 1" /></material>
    </visual>
    <collision>
      <origin xyz="0 0 0" rpy="0 0 0" />
      <geometry><mesh filename="meshes/middle_middle.STL" /></geometry>
    </collision>
  </link>
  <link name="rh_middle_distal">
    <inertial>
      <origin xyz="-0.000728492686371173 5.23463092580619e-06 0.0121446078355885" rpy="0 0 0" />
      <mass value="0.00314458659113992" />
      <inertia ixx="1.63194300204967e-07" ixy="-1.99064062210326e-11" ixz="-4.34469141576056e-08" iyy="1.48366133401819e-07" iyz="2.02741720954809e-10" izz="9.8685363448972e-08" />
    </inertial>
    <visual>
      <origin xyz="0 0 0" rpy="0 0 0" />
      <geometry><mesh filename="meshes/middle_distal.STL" /></geometry>
      <material name=""><color rgba="1 1 1 1" /></material>
    </visual>
    <collision>
      <origin xyz="0 0 0" rpy="0 0 0" />
      <geometry><mesh filename="meshes/middle_distal.STL" /></geometry>
    </collision>
  </link>
  <link name="rh_ring_metacarpals">
    <inertial>
      <origin xyz="-0.000394044453752051 -6.96464269499264e-07 0.00909446164305169" rpy="0 0 0" />
      <mass value="0.00903700335356623" />
      <inertia ixx="4.89554245950771e-07" ixy="-3.94741777907138e-11" ixz="2.73097253166787e-08" iyy="7.37380377611045e-07" iyz="-6.33493307330511e-11" izz="5.52862742016819e-07" />
    </inertial>
    <visual>
      <origin xyz="0 0 0" rpy="0 0 0" />
      <geometry><mesh filename="meshes/ring_metacarpals.STL" /></geometry>
      <material name=""><color rgba="1 1 1 1" /></material>
    </visual>
    <collision>
      <origin xyz="0 0 0" rpy="0 0 0" />
      <geometry><mesh filename="meshes/ring_metacarpals.STL" /></geometry>
    </collision>
  </link>
  <link name="rh_ring_proximal">
    <inertial>
      <origin xyz="-0.000129951741702268 1.17052693794986e-06 0.0104816759358435" rpy="0 0 0" />
      <mass value="0.00654983629670871" />
      <inertia ixx="4.43901586303392e-07" ixy="3.50295306689535e-12" ixz="-2.48148215954452e-08" iyy="4.58698142287549e-07" iyz="8.52333703161162e-11" izz="1.74206152792307e-07" />
    </inertial>
    <visual>
      <origin xyz="0 0 0" rpy="0 0 0" />
      <geometry><mesh filename="meshes/ring_proximal.STL" /></geometry>
      <material name=""><color rgba="1 1 1 1" /></material>
    </visual>
    <collision>
      <origin xyz="0 0 0" rpy="0 0 0" />
      <geometry><mesh filename="meshes/ring_proximal.STL" /></geometry>
    </collision>
  </link>
  <link name="rh_ring_middle">
    <inertial>
      <origin xyz="-0.00250308200880736 -2.09549542964232e-06 0.0110397403443072" rpy="0 0 0" />
      <mass value="0.0028304363455826" />
      <inertia ixx="2.610370084214e-07" ixy="-5.76575489930258e-11" ixz="-4.00111860002357e-08" iyy="2.3307766580208e-07" iyz="2.97027542466601e-11" izz="1.26543852008426e-07" />
    </inertial>
    <visual>
      <origin xyz="0 0 0" rpy="0 0 0" />
      <geometry><mesh filename="meshes/ring_middle.STL" /></geometry>
      <material name=""><color rgba="1 1 1 1" /></material>
    </visual>
    <collision>
      <origin xyz="0 0 0" rpy="0 0 0" />
      <geometry><mesh filename="meshes/ring_middle.STL" /></geometry>
    </collision>
  </link>
  <link name="rh_ring_distal">
    <inertial>
      <origin xyz="-0.00060459286126547 5.09148089232817e-06 0.0121514427640609" rpy="0 0 0" />
      <mass value="0.00314460631735109" />
      <inertia ixx="1.64075455538032e-07" ixy="-2.1468512857682e-11" ixz="-4.27798116117893e-08" iyy="1.48367698956355e-07" iyz="1.93419127705868e-10" izz="9.78062648939272e-08" />
    </inertial>
    <visual>
      <origin xyz="0 0 0" rpy="0 0 0" />
      <geometry><mesh filename="meshes/ring_distal.STL" /></geometry>
      <material name=""><color rgba="1 1 1 1" /></material>
    </visual>
    <collision>
      <origin xyz="0 0 0" rpy="0 0 0" />
      <geometry><mesh filename="meshes/ring_distal.STL" /></geometry>
    </collision>
  </link>
  <link name="rh_pinky_metacarpals">
    <inertial>
      <origin xyz="-0.00039404522692532 -6.96240700731598e-07 0.00909446058676422" rpy="0 0 0" />
      <mass value="0.00903700307878998" />
      <inertia ixx="4.89554195779539e-07" ixy="-3.94817181132792e-11" ixz="2.7309708213456e-08" iyy="7.37380317460272e-07" iyz="-6.33317017267926e-11" izz="5.5286276236961e-07" />
    </inertial>
    <visual>
      <origin xyz="0 0 0" rpy="0 0 0" />
      <geometry><mesh filename="meshes/pinky_metacarpals.STL" /></geometry>
      <material name=""><color rgba="1 1 1 1" /></material>
    </visual>
    <collision>
      <origin xyz="0 0 0" rpy="0 0 0" />
      <geometry><mesh filename="meshes/pinky_metacarpals.STL" /></geometry>
    </collision>
  </link>
  <link name="rh_pinky_proximal">
    <inertial>
      <origin xyz="-0.000129949532354408 1.17230680928004e-06 0.0104816807512055" rpy="0 0 0" />
      <mass value="0.00654983474179372" />
      <inertia ixx="4.43901730245286e-07" ixy="3.4507527836803e-12" ixz="-2.48149152090791e-08" iyy="4.58698159687316e-07" iyz="8.52432689792127e-11" izz="1.74206088330646e-07" />
    </inertial>
    <visual>
      <origin xyz="0 0 0" rpy="0 0 0" />
      <geometry><mesh filename="meshes/pinky_proximal.STL" /></geometry>
      <material name=""><color rgba="1 1 1 1" /></material>
    </visual>
    <collision>
      <origin xyz="0 0 0" rpy="0 0 0" />
      <geometry><mesh filename="meshes/pinky_proximal.STL" /></geometry>
    </collision>
  </link>
  <link name="rh_pinky_middle">
    <inertial>
      <origin xyz="-0.00250308414609457 -2.09612030866585e-06 0.0110397422037874" rpy="0 0 0" />
      <mass value="0.00283043670305552" />
      <inertia ixx="2.6103697292473e-07" ixy="-5.76245409160896e-11" ixz="-4.00111424508735e-08" iyy="2.33077589871973e-07" iyz="2.96769001441938e-11" izz="1.26543829688383e-07" />
    </inertial>
    <visual>
      <origin xyz="0 0 0" rpy="0 0 0" />
      <geometry><mesh filename="meshes/pinky_middle.STL" /></geometry>
      <material name=""><color rgba="1 1 1 1" /></material>
    </visual>
    <collision>
      <origin xyz="0 0 0" rpy="0 0 0" />
      <geometry><mesh filename="meshes/pinky_middle.STL" /></geometry>
    </collision>
  </link>
  <link name="rh_pinky_distal">
    <inertial>
      <origin xyz="-0.000604482988543969 5.27153358490656e-06 0.0121512430050648" rpy="0 0 0" />
      <mass value="0.00314457409502053" />
      <inertia ixx="1.64068754964363e-07" ixy="-1.90437996173564e-11" ixz="-4.27789862984836e-08" iyy="1.48361079085349e-07" iyz="2.05110113267167e-10" izz="9.78068531228973e-08" />
    </inertial>
    <visual>
      <origin xyz="0 0 0" rpy="0 0 0" />
      <geometry><mesh filename="meshes/pinky_distal.STL" /></geometry>
      <material name=""><color rgba="1 1 1 1" /></material>
    </visual>
    <collision>
      <origin xyz="0 0 0" rpy="0 0 0" />
      <geometry><mesh filename="meshes/pinky_distal.STL" /></geometry>
    </collision>
  </link>
  <joint name="rh_thumb_cmc_roll" type="revolute">
    <origin xyz="-0.013419 0.012551 0.060602" rpy="0 0 0" />
    <parent link="rh_hand_base_link" />
    <child link="rh_thumb_metacarpals_base1" />
    <axis xyz="0.99996 0 -0.0087265" />
    <limit lower="0" upper="1.03" effort="4.8" velocity="1" />
  </joint>
  <joint name="rh_thumb_cmc_yaw" type="revolute">
    <origin xyz="0.035798 -0.0006691 0.00040146" rpy="-0.13233 -0.0085747 0.0011413" />
    <parent link="rh_thumb_metacarpals_base1" />
    <child link="rh_thumb_metacarpals_base2" />
    <axis xyz="0 0 -1" />
    <limit lower="0" upper="1.4" effort="4.8" velocity="1" />
  </joint>
  <joint name="rh_thumb_cmc_pitch" type="revolute">
    <origin xyz="0.0037151 0.015396 -0.0019302" rpy="0 -0.9163 -1.8076" />
    <parent link="rh_thumb_metacarpals_base2" />
    <child link="rh_thumb_metacarpals" />
    <axis xyz="0 1 0" />
    <limit lower="0" upper="0.52" effort="4.8" velocity="1" />
  </joint>
  <joint name="rh_thumb_mcp" type="revolute">
    <origin xyz="0.0061722 0 0.047968" rpy="0 0 0" />
    <parent link="rh_thumb_metacarpals" />
    <child link="rh_thumb_proximal" />
    <axis xyz="0 1 0" />
    <limit lower="0" upper="0.72" effort="3.7" velocity="1" />
    <mimic joint="rh_thumb_cmc_pitch" multiplier="1.38" offset="0" />
  </joint>
  <joint name="rh_thumb_ip" type="revolute">
    <origin xyz="-0.00017064 0 0.038665" rpy="0 0 0" />
    <parent link="rh_thumb_proximal" />
    <child link="rh_thumb_distal" />
    <axis xyz="0 1 0" />
    <limit lower="0" upper="0.78" effort="3.36" velocity="1" />
    <mimic joint="rh_thumb_cmc_pitch" multiplier="1.49" offset="0" />
  </joint>
  <joint name="rh_index_mcp_roll" type="revolute">
    <origin xyz="-0.0021643 0.026654 0.13253" rpy="-0.027925 -0.0087266 0" />
    <parent link="rh_hand_base_link" />
    <child link="rh_index_metacarpals" />
    <axis xyz="-1 0 0" />
    <limit lower="0" upper="0.19" effort="100" velocity="1" />
  </joint>
  <joint name="rh_index_mcp_pitch" type="revolute">
    <origin xyz="0.00220968332188026 0 0.0152749792820048" rpy="0 0 0" />
    <parent link="rh_index_metacarpals" />
    <child link="rh_index_proximal" />
    <axis xyz="0 1 0" />
    <limit lower="0" upper="1.36" effort="4.8" velocity="1" />
  </joint>
  <joint name="rh_index_pip" type="revolute">
    <origin xyz="-0.0010697 0 0.035634" rpy="0 0 0" />
    <parent link="rh_index_proximal" />
    <child link="rh_index_middle" />
    <axis xyz="0 1 0" />
    <limit lower="0" upper="1.78" effort="3.7" velocity="1" />
    <mimic joint="rh_index_mcp_pitch" multiplier="1.3" offset="0" />
  </joint>
  <joint name="rh_index_dip" type="revolute">
    <origin xyz="-0.0052444 0 0.025711" rpy="0 0 0" />
    <parent link="rh_index_middle" />
    <child link="rh_index_distal" />
    <axis xyz="0 1 0" />
    <limit lower="0" upper="0.62" effort="10.43" velocity="1" />
    <mimic joint="rh_index_mcp_pitch" multiplier="0.46" offset="0" />
  </joint>
  <joint name="rh_middle_mcp_pitch" type="revolute">
    <origin xyz="-0.00213155528434806 0.00765417737818821 0.152810108410232" rpy="0 0 0" />
    <parent link="rh_hand_base_link" />
    <child link="rh_middle_proximal" />
    <axis xyz="0 1 0" />
    <limit lower="0" upper="1.36" effort="100" velocity="1" />
  </joint>
  <joint name="rh_middle_pip" type="revolute">
    <origin xyz="-0.00139702428111229 0 0.0356230829860553" rpy="0 0 0" />
    <parent link="rh_middle_proximal" />
    <child link="rh_middle_middle" />
    <axis xyz="0 1 0" />
    <limit lower="0" upper="1.78" effort="3.7" velocity="1" />
    <mimic joint="rh_middle_mcp_pitch" multiplier="1.3" offset="0" />
  </joint>
  <joint name="rh_middle_dip" type="revolute">
    <origin xyz="-0.0055098 0 0.025656" rpy="0 0 0" />
    <parent link="rh_middle_middle" />
    <child link="rh_middle_distal" />
    <axis xyz="0 1 0" />
    <limit lower="0" upper="0.62" effort="10.43" velocity="1" />
    <mimic joint="rh_middle_mcp_pitch" multiplier="0.46" offset="0" />
  </joint>
  <joint name="rh_ring_mcp_roll" type="revolute">
    <origin xyz="-0.00216430029569533 -0.0113458226218121 0.132534071328313" rpy="0.0244346095279086 -0.00872664625996829 0" />
    <parent link="rh_hand_base_link" />
    <child link="rh_ring_metacarpals" />
    <axis xyz="1 0 0" />
    <limit lower="0" upper="0.2" effort="4.29" velocity="1" />
  </joint>
  <joint name="rh_ring_mcp_pitch" type="revolute">
    <origin xyz="0.0022097 0 0.015275" rpy="0 0 0" />
    <parent link="rh_ring_metacarpals" />
    <child link="rh_ring_proximal" />
    <axis xyz="0 1 0" />
    <limit lower="0" upper="1.36" effort="4.8" velocity="1" />
  </joint>
  <joint name="rh_ring_pip" type="revolute">
    <origin xyz="-0.00106974956301328 0 0.0356344124989653" rpy="0 0 0" />
    <parent link="rh_ring_proximal" />
    <child link="rh_ring_middle" />
    <axis xyz="0 1 0" />
    <limit lower="0" upper="1.78" effort="3.7" velocity="1" />
    <mimic joint="rh_ring_mcp_pitch" multiplier="1.34" offset="0" />
  </joint>
  <joint name="rh_ring_dip" type="revolute">
    <origin xyz="-0.00524443259686075 0 0.0257114125710868" rpy="0 0 -0.000213216385347256" />
    <parent link="rh_ring_middle" />
    <child link="rh_ring_distal" />
    <axis xyz="0.000213099161087669 0.999450193223668 -0.033155178387707" />
    <limit lower="0" upper="0.62" effort="10.43" velocity="1" />
    <mimic joint="rh_ring_mcp_pitch" multiplier="0.46" offset="0" />
  </joint>
  <joint name="rh_pinky_mcp_roll" type="revolute">
    <origin xyz="-0.00012074 -0.030346 0.12755" rpy="0.057596 -0.0087266 0" />
    <parent link="rh_hand_base_link" />
    <child link="rh_pinky_metacarpals" />
    <axis xyz="1 0 0" />
    <limit lower="0" upper="0.3" effort="4.29" velocity="1" />
  </joint>
  <joint name="rh_pinky_mcp_pitch" type="revolute">
    <origin xyz="0.0022097 0 0.015275" rpy="0 0 0" />
    <parent link="rh_pinky_metacarpals" />
    <child link="rh_pinky_proximal" />
    <axis xyz="0 1 0" />
    <limit lower="0" upper="1.36" effort="4.8" velocity="1" />
  </joint>
  <joint name="rh_pinky_pip" type="revolute">
    <origin xyz="-0.0010697 0 0.035634" rpy="0 0 0" />
    <parent link="rh_pinky_proximal" />
    <child link="rh_pinky_middle" />
    <axis xyz="0 1 0" />
    <limit lower="0" upper="1.78" effort="3.7" velocity="1" />
    <mimic joint="rh_pinky_mcp_pitch" multiplier="1.34" offset="0" />
  </joint>
  <joint name="rh_pinky_dip" type="revolute">
    <origin xyz="-0.0052444 0 0.025711" rpy="0 0 0" />
    <parent link="rh_pinky_middle" />
    <child link="rh_pinky_distal" />
    <axis xyz="0 1 0" />
    <limit lower="0" upper="0.62" effort="10.43" velocity="1" />
    <mimic joint="rh_pinky_mcp_pitch" multiplier="0.46" offset="0" />
  </joint>
</robot>
